Using properties file: /home/ubuntu/spark-2.0.0/conf/spark-defaults.conf
Adding default property: spark.driver.extraJavaOptions=-XX:+PrintGCDetails -XX:+PrintGCTimeStamps -Xms4000m -Dlog4j.configuration=file:///home/ubuntu/spark-2.0.0/conf/log4j.properties
Adding default property: spark.executor.extraJavaOptions=-XX:+PrintGCDetails -XX:+PrintGCTimeStamps -Xms4000m -Dlog4j.configuration=file:///home/ubuntu/spark-2.0.0/conf/log4j.properties
Parsed arguments:
  master                  spark://euca-10-1-2-152:7077
  deployMode              client
  executorMemory          4000m
  executorCores           null
  totalExecutorCores      null
  propertiesFile          /home/ubuntu/spark-2.0.0/conf/spark-defaults.conf
  driverMemory            4000m
  driverCores             null
  driverExtraClassPath    null
  driverExtraLibraryPath  null
  driverExtraJavaOptions  -XX:+PrintGCDetails -XX:+PrintGCTimeStamps -Xms4000m -Dlog4j.configuration=file:///home/ubuntu/spark-2.0.0/conf/log4j.properties
  supervise               false
  queue                   null
  numExecutors            8
  files                   null
  pyFiles                 null
  archives                null
  mainClass               LogRegExplicitParallelism
  primaryResource         file:///home/ubuntu/jars/log-reg-explicit-parallelism_2.11-1.0.jar
  name                    LogRegExplicitParallelism
  childArgs               [cluster 18 euca-10-1-2-152 9000 susy_0_exp 5 32]
  jars                    null
  packages                null
  packagesExclusions      null
  repositories            null
  verbose                 true

Spark properties used, including those specified through
 --conf and those from the properties file /home/ubuntu/spark-2.0.0/conf/spark-defaults.conf:
  spark.default.parallelism -> 32
  spark.driver.memory -> 4000m
  spark.executor.extraJavaOptions -> -XX:+PrintGCDetails -XX:+PrintGCTimeStamps -Xms4000m -Dlog4j.configuration=file:///home/ubuntu/spark-2.0.0/conf/log4j.properties
  spark.driver.extraJavaOptions -> -XX:+PrintGCDetails -XX:+PrintGCTimeStamps -Xms4000m -Dlog4j.configuration=file:///home/ubuntu/spark-2.0.0/conf/log4j.properties
  spark.shuffle.spill -> false

    
Main class:
LogRegExplicitParallelism
Arguments:
cluster
18
euca-10-1-2-152
9000
susy_0_exp
5
32
System properties:
spark.default.parallelism -> 32
spark.executor.memory -> 4000m
spark.driver.memory -> 4000m
SPARK_SUBMIT -> true
spark.executor.extraJavaOptions -> -XX:+PrintGCDetails -XX:+PrintGCTimeStamps -Xms4000m -Dlog4j.configuration=file:///home/ubuntu/spark-2.0.0/conf/log4j.properties
spark.app.name -> LogRegExplicitParallelism
spark.shuffle.spill -> false
spark.driver.extraJavaOptions -> -XX:+PrintGCDetails -XX:+PrintGCTimeStamps -Xms4000m -Dlog4j.configuration=file:///home/ubuntu/spark-2.0.0/conf/log4j.properties
spark.jars -> file:///home/ubuntu/jars/log-reg-explicit-parallelism_2.11-1.0.jar
spark.submit.deployMode -> client
spark.master -> spark://euca-10-1-2-152:7077
Classpath elements:
file:///home/ubuntu/jars/log-reg-explicit-parallelism_2.11-1.0.jar


17/01/29 15:07:27,290 INFO SparkContext: Running Spark version 2.0.0
17/01/29 15:07:27,619 WARN NativeCodeLoader: Unable to load native-hadoop library for your platform... using builtin-java classes where applicable
17/01/29 15:07:27,776 INFO SecurityManager: Changing view acls to: ubuntu
17/01/29 15:07:27,776 INFO SecurityManager: Changing modify acls to: ubuntu
17/01/29 15:07:27,777 INFO SecurityManager: Changing view acls groups to: 
17/01/29 15:07:27,777 INFO SecurityManager: Changing modify acls groups to: 
17/01/29 15:07:27,778 INFO SecurityManager: SecurityManager: authentication disabled; ui acls disabled; users  with view permissions: Set(ubuntu); groups with view permissions: Set(); users  with modify permissions: Set(ubuntu); groups with modify permissions: Set()
17/01/29 15:07:31,042 WARN ThreadLocalRandom: Failed to generate a seed from SecureRandom within 3 seconds. Not enough entrophy?
17/01/29 15:07:31,090 INFO Utils: Successfully started service 'sparkDriver' on port 44507.
17/01/29 15:07:31,108 INFO SparkEnv: Registering MapOutputTracker
17/01/29 15:07:31,114 WARN SortShuffleManager: spark.shuffle.spill was set to false, but this configuration is ignored as of Spark 1.6+. Shuffle will continue to spill to disk when necessary.
17/01/29 15:07:31,126 INFO SparkEnv: Registering BlockManagerMaster
17/01/29 15:07:31,138 INFO DiskBlockManager: Created local directory at /tmp/blockmgr-716fa660-7450-46c2-aeb2-f6c8051cfdfa
17/01/29 15:07:31,159 INFO MemoryStore: MemoryStore started with capacity 2.1 GB
17/01/29 15:07:31,221 INFO SparkEnv: Registering OutputCommitCoordinator
17/01/29 15:07:31,421 INFO Utils: Successfully started service 'SparkUI' on port 4040.
17/01/29 15:07:31,423 INFO SparkUI: Bound SparkUI to 10.1.2.152, and started at http://10.1.2.152:4040
17/01/29 15:07:31,455 INFO SparkContext: Added JAR file:///home/ubuntu/jars/log-reg-explicit-parallelism_2.11-1.0.jar at spark://10.1.2.152:44507/jars/log-reg-explicit-parallelism_2.11-1.0.jar with timestamp 1485702451454
17/01/29 15:07:31,532 INFO StandaloneAppClient$ClientEndpoint: Connecting to master spark://euca-10-1-2-152:7077...
17/01/29 15:07:31,583 INFO TransportClientFactory: Successfully created connection to euca-10-1-2-152/10.1.2.152:7077 after 24 ms (0 ms spent in bootstraps)
17/01/29 15:07:31,677 INFO StandaloneSchedulerBackend: Connected to Spark cluster with app ID app-20170129150731-0000
17/01/29 15:07:31,682 INFO Utils: Successfully started service 'org.apache.spark.network.netty.NettyBlockTransferService' on port 37100.
17/01/29 15:07:31,683 INFO NettyBlockTransferService: Server created on 10.1.2.152:37100
17/01/29 15:07:31,684 INFO BlockManagerMaster: Registering BlockManager BlockManagerId(driver, 10.1.2.152, 37100)
17/01/29 15:07:31,686 INFO BlockManagerMasterEndpoint: Registering block manager 10.1.2.152:37100 with 2.1 GB RAM, BlockManagerId(driver, 10.1.2.152, 37100)
17/01/29 15:07:31,689 INFO BlockManagerMaster: Registered BlockManager BlockManagerId(driver, 10.1.2.152, 37100)
17/01/29 15:07:31,706 INFO StandaloneAppClient$ClientEndpoint: Executor added: app-20170129150731-0000/0 on worker-20170129150707-10.1.2.65-36815 (10.1.2.65:36815) with 4 cores
17/01/29 15:07:31,708 INFO StandaloneSchedulerBackend: Granted executor ID app-20170129150731-0000/0 on hostPort 10.1.2.65:36815 with 4 cores, 3.9 GB RAM
17/01/29 15:07:31,716 INFO StandaloneAppClient$ClientEndpoint: Executor added: app-20170129150731-0000/1 on worker-20170129150707-10.1.2.28-44552 (10.1.2.28:44552) with 4 cores
17/01/29 15:07:31,717 INFO StandaloneSchedulerBackend: Granted executor ID app-20170129150731-0000/1 on hostPort 10.1.2.28:44552 with 4 cores, 3.9 GB RAM
17/01/29 15:07:31,718 INFO StandaloneAppClient$ClientEndpoint: Executor added: app-20170129150731-0000/2 on worker-20170129150707-10.1.2.176-36191 (10.1.2.176:36191) with 4 cores
17/01/29 15:07:31,719 INFO StandaloneSchedulerBackend: Granted executor ID app-20170129150731-0000/2 on hostPort 10.1.2.176:36191 with 4 cores, 3.9 GB RAM
17/01/29 15:07:31,720 INFO StandaloneAppClient$ClientEndpoint: Executor added: app-20170129150731-0000/3 on worker-20170129150707-10.1.2.66-34683 (10.1.2.66:34683) with 4 cores
17/01/29 15:07:31,720 INFO StandaloneSchedulerBackend: Granted executor ID app-20170129150731-0000/3 on hostPort 10.1.2.66:34683 with 4 cores, 3.9 GB RAM
17/01/29 15:07:31,722 INFO StandaloneAppClient$ClientEndpoint: Executor added: app-20170129150731-0000/4 on worker-20170129150707-10.1.2.224-43128 (10.1.2.224:43128) with 4 cores
17/01/29 15:07:31,722 INFO StandaloneSchedulerBackend: Granted executor ID app-20170129150731-0000/4 on hostPort 10.1.2.224:43128 with 4 cores, 3.9 GB RAM
17/01/29 15:07:31,724 INFO StandaloneAppClient$ClientEndpoint: Executor added: app-20170129150731-0000/5 on worker-20170129150707-10.1.2.38-46650 (10.1.2.38:46650) with 4 cores
17/01/29 15:07:31,724 INFO StandaloneSchedulerBackend: Granted executor ID app-20170129150731-0000/5 on hostPort 10.1.2.38:46650 with 4 cores, 3.9 GB RAM
17/01/29 15:07:31,725 INFO StandaloneAppClient$ClientEndpoint: Executor added: app-20170129150731-0000/6 on worker-20170129150707-10.1.2.191-44033 (10.1.2.191:44033) with 4 cores
17/01/29 15:07:31,725 INFO StandaloneSchedulerBackend: Granted executor ID app-20170129150731-0000/6 on hostPort 10.1.2.191:44033 with 4 cores, 3.9 GB RAM
17/01/29 15:07:31,728 INFO StandaloneAppClient$ClientEndpoint: Executor added: app-20170129150731-0000/7 on worker-20170129150707-10.1.2.139-35322 (10.1.2.139:35322) with 4 cores
17/01/29 15:07:31,729 INFO StandaloneSchedulerBackend: Granted executor ID app-20170129150731-0000/7 on hostPort 10.1.2.139:35322 with 4 cores, 3.9 GB RAM
17/01/29 15:07:31,771 INFO StandaloneAppClient$ClientEndpoint: Executor updated: app-20170129150731-0000/2 is now RUNNING
17/01/29 15:07:31,773 INFO StandaloneAppClient$ClientEndpoint: Executor updated: app-20170129150731-0000/3 is now RUNNING
17/01/29 15:07:31,776 INFO StandaloneAppClient$ClientEndpoint: Executor updated: app-20170129150731-0000/6 is now RUNNING
17/01/29 15:07:31,779 INFO StandaloneAppClient$ClientEndpoint: Executor updated: app-20170129150731-0000/0 is now RUNNING
17/01/29 15:07:31,782 INFO StandaloneAppClient$ClientEndpoint: Executor updated: app-20170129150731-0000/4 is now RUNNING
17/01/29 15:07:31,786 INFO StandaloneAppClient$ClientEndpoint: Executor updated: app-20170129150731-0000/5 is now RUNNING
17/01/29 15:07:31,789 INFO StandaloneAppClient$ClientEndpoint: Executor updated: app-20170129150731-0000/7 is now RUNNING
17/01/29 15:07:31,792 INFO StandaloneAppClient$ClientEndpoint: Executor updated: app-20170129150731-0000/1 is now RUNNING
17/01/29 15:07:31,868 INFO StandaloneSchedulerBackend: SchedulerBackend is ready for scheduling beginning after reached minRegisteredResourcesRatio: 0.0
17/01/29 15:07:32,214 INFO MemoryStore: Block broadcast_0 stored as values in memory (estimated size 130.8 KB, free 2.1 GB)
17/01/29 15:07:32,271 INFO MemoryStore: Block broadcast_0_piece0 stored as bytes in memory (estimated size 16.5 KB, free 2.1 GB)
17/01/29 15:07:32,273 INFO BlockManagerInfo: Added broadcast_0_piece0 in memory on 10.1.2.152:37100 (size: 16.5 KB, free: 2.1 GB)
17/01/29 15:07:32,280 INFO SparkContext: Created broadcast 0 from textFile at MLUtils.scala:99
17/01/29 15:07:32,866 INFO FileInputFormat: Total input paths to process : 1
17/01/29 15:07:32,898 INFO NetworkTopology: Adding a new node: /default-rack/10.1.2.224:50010
17/01/29 15:07:32,898 INFO NetworkTopology: Adding a new node: /default-rack/10.1.2.66:50010
17/01/29 15:07:32,898 INFO NetworkTopology: Adding a new node: /default-rack/10.1.2.38:50010
17/01/29 15:07:32,898 INFO NetworkTopology: Adding a new node: /default-rack/10.1.2.28:50010
17/01/29 15:07:32,899 INFO NetworkTopology: Adding a new node: /default-rack/10.1.2.176:50010
17/01/29 15:07:32,899 INFO NetworkTopology: Adding a new node: /default-rack/10.1.2.65:50010
17/01/29 15:07:32,900 INFO NetworkTopology: Adding a new node: /default-rack/10.1.2.139:50010
17/01/29 15:07:32,900 INFO NetworkTopology: Adding a new node: /default-rack/10.1.2.191:50010
17/01/29 15:07:32,938 INFO SparkContext: Starting job: first at GeneralizedLinearAlgorithm.scala:246
17/01/29 15:07:32,950 INFO DAGScheduler: Got job 0 (first at GeneralizedLinearAlgorithm.scala:246) with 1 output partitions
17/01/29 15:07:32,950 INFO DAGScheduler: Final stage: ResultStage 0 (first at GeneralizedLinearAlgorithm.scala:246)
17/01/29 15:07:32,951 INFO DAGScheduler: Parents of final stage: List()
17/01/29 15:07:32,955 INFO DAGScheduler: Missing parents: List()
17/01/29 15:07:32,963 INFO DAGScheduler: Submitting ResultStage 0 (MapPartitionsRDD[6] at map at GeneralizedLinearAlgorithm.scala:246), which has no missing parents
17/01/29 15:07:32,985 INFO MemoryStore: Block broadcast_1 stored as values in memory (estimated size 4.2 KB, free 2.1 GB)
17/01/29 15:07:32,989 INFO MemoryStore: Block broadcast_1_piece0 stored as bytes in memory (estimated size 2.4 KB, free 2.1 GB)
17/01/29 15:07:32,990 INFO BlockManagerInfo: Added broadcast_1_piece0 in memory on 10.1.2.152:37100 (size: 2.4 KB, free: 2.1 GB)
17/01/29 15:07:32,991 INFO SparkContext: Created broadcast 1 from broadcast at DAGScheduler.scala:1012
17/01/29 15:07:32,993 INFO DAGScheduler: Submitting 1 missing tasks from ResultStage 0 (MapPartitionsRDD[6] at map at GeneralizedLinearAlgorithm.scala:246)
17/01/29 15:07:32,995 INFO TaskSchedulerImpl: Adding task set 0.0 with 1 tasks
17/01/29 15:07:36,591 INFO CoarseGrainedSchedulerBackend$DriverEndpoint: Registered executor NettyRpcEndpointRef(null) (10.1.2.65:44914) with ID 0
17/01/29 15:07:36,617 INFO TaskSetManager: Starting task 0.0 in stage 0.0 (TID 0, 10.1.2.65, partition 0, ANY, 5455 bytes)
17/01/29 15:07:36,621 INFO CoarseGrainedSchedulerBackend$DriverEndpoint: Launching task 0 on executor id: 0 hostname: 10.1.2.65.
17/01/29 15:07:36,637 INFO CoarseGrainedSchedulerBackend$DriverEndpoint: Registered executor NettyRpcEndpointRef(null) (10.1.2.224:60234) with ID 4
17/01/29 15:07:36,642 INFO BlockManagerMasterEndpoint: Registering block manager 10.1.2.65:40765 with 2.1 GB RAM, BlockManagerId(0, 10.1.2.65, 40765)
17/01/29 15:07:36,660 INFO CoarseGrainedSchedulerBackend$DriverEndpoint: Registered executor NettyRpcEndpointRef(null) (10.1.2.191:58866) with ID 6
17/01/29 15:07:36,677 INFO CoarseGrainedSchedulerBackend$DriverEndpoint: Registered executor NettyRpcEndpointRef(null) (10.1.2.28:48890) with ID 1
17/01/29 15:07:36,679 INFO CoarseGrainedSchedulerBackend$DriverEndpoint: Registered executor NettyRpcEndpointRef(null) (10.1.2.38:54406) with ID 5
17/01/29 15:07:36,690 INFO BlockManagerMasterEndpoint: Registering block manager 10.1.2.224:37049 with 2.1 GB RAM, BlockManagerId(4, 10.1.2.224, 37049)
17/01/29 15:07:36,714 INFO BlockManagerMasterEndpoint: Registering block manager 10.1.2.191:37280 with 2.1 GB RAM, BlockManagerId(6, 10.1.2.191, 37280)
17/01/29 15:07:36,723 INFO BlockManagerMasterEndpoint: Registering block manager 10.1.2.28:41859 with 2.1 GB RAM, BlockManagerId(1, 10.1.2.28, 41859)
17/01/29 15:07:36,727 INFO BlockManagerMasterEndpoint: Registering block manager 10.1.2.38:34256 with 2.1 GB RAM, BlockManagerId(5, 10.1.2.38, 34256)
17/01/29 15:07:36,770 INFO CoarseGrainedSchedulerBackend$DriverEndpoint: Registered executor NettyRpcEndpointRef(null) (10.1.2.66:50926) with ID 3
17/01/29 15:07:36,776 INFO CoarseGrainedSchedulerBackend$DriverEndpoint: Registered executor NettyRpcEndpointRef(null) (10.1.2.139:36836) with ID 7
17/01/29 15:07:36,790 INFO CoarseGrainedSchedulerBackend$DriverEndpoint: Registered executor NettyRpcEndpointRef(null) (10.1.2.176:36584) with ID 2
17/01/29 15:07:36,823 INFO BlockManagerMasterEndpoint: Registering block manager 10.1.2.66:43551 with 2.1 GB RAM, BlockManagerId(3, 10.1.2.66, 43551)
17/01/29 15:07:36,837 INFO BlockManagerMasterEndpoint: Registering block manager 10.1.2.139:33712 with 2.1 GB RAM, BlockManagerId(7, 10.1.2.139, 33712)
17/01/29 15:07:36,843 INFO BlockManagerMasterEndpoint: Registering block manager 10.1.2.176:35238 with 2.1 GB RAM, BlockManagerId(2, 10.1.2.176, 35238)
17/01/29 15:07:36,914 INFO BlockManagerInfo: Added broadcast_1_piece0 in memory on 10.1.2.65:40765 (size: 2.4 KB, free: 2.1 GB)
17/01/29 15:07:37,063 INFO BlockManagerInfo: Added broadcast_0_piece0 in memory on 10.1.2.65:40765 (size: 16.5 KB, free: 2.1 GB)
17/01/29 15:07:41,812 INFO BlockManagerInfo: Added rdd_5_0 in memory on 10.1.2.65:40765 (size: 44.3 MB, free: 2.0 GB)
17/01/29 15:07:41,862 INFO TaskSetManager: Finished task 0.0 in stage 0.0 (TID 0) in 5265 ms on 10.1.2.65 (1/1)
17/01/29 15:07:41,863 INFO TaskSchedulerImpl: Removed TaskSet 0.0, whose tasks have all completed, from pool 
17/01/29 15:07:41,867 INFO DAGScheduler: ResultStage 0 (first at GeneralizedLinearAlgorithm.scala:246) finished in 8.861 s
17/01/29 15:07:41,874 INFO DAGScheduler: Job 0 finished: first at GeneralizedLinearAlgorithm.scala:246, took 8.935478 s
17/01/29 15:07:41,888 INFO SparkContext: Starting job: count at DataValidators.scala:40
17/01/29 15:07:41,890 INFO DAGScheduler: Got job 1 (count at DataValidators.scala:40) with 32 output partitions
17/01/29 15:07:41,890 INFO DAGScheduler: Final stage: ResultStage 1 (count at DataValidators.scala:40)
17/01/29 15:07:41,890 INFO DAGScheduler: Parents of final stage: List()
17/01/29 15:07:41,892 INFO DAGScheduler: Missing parents: List()
17/01/29 15:07:41,892 INFO DAGScheduler: Submitting ResultStage 1 (MapPartitionsRDD[7] at filter at DataValidators.scala:40), which has no missing parents
17/01/29 15:07:41,908 INFO MemoryStore: Block broadcast_2 stored as values in memory (estimated size 3.9 KB, free 2.1 GB)
17/01/29 15:07:41,910 INFO MemoryStore: Block broadcast_2_piece0 stored as bytes in memory (estimated size 2.2 KB, free 2.1 GB)
17/01/29 15:07:41,911 INFO BlockManagerInfo: Added broadcast_2_piece0 in memory on 10.1.2.152:37100 (size: 2.2 KB, free: 2.1 GB)
17/01/29 15:07:41,912 INFO SparkContext: Created broadcast 2 from broadcast at DAGScheduler.scala:1012
17/01/29 15:07:41,913 INFO DAGScheduler: Submitting 32 missing tasks from ResultStage 1 (MapPartitionsRDD[7] at filter at DataValidators.scala:40)
17/01/29 15:07:41,913 INFO TaskSchedulerImpl: Adding task set 1.0 with 32 tasks
17/01/29 15:07:41,918 INFO TaskSetManager: Starting task 0.0 in stage 1.0 (TID 1, 10.1.2.65, partition 0, PROCESS_LOCAL, 5373 bytes)
17/01/29 15:07:41,921 INFO TaskSetManager: Starting task 1.0 in stage 1.0 (TID 2, 10.1.2.38, partition 1, NODE_LOCAL, 5373 bytes)
17/01/29 15:07:41,923 INFO TaskSetManager: Starting task 3.0 in stage 1.0 (TID 3, 10.1.2.65, partition 3, NODE_LOCAL, 5373 bytes)
17/01/29 15:07:41,925 INFO TaskSetManager: Starting task 8.0 in stage 1.0 (TID 4, 10.1.2.139, partition 8, NODE_LOCAL, 5373 bytes)
17/01/29 15:07:41,927 INFO TaskSetManager: Starting task 5.0 in stage 1.0 (TID 5, 10.1.2.66, partition 5, NODE_LOCAL, 5373 bytes)
17/01/29 15:07:41,930 INFO TaskSetManager: Starting task 6.0 in stage 1.0 (TID 6, 10.1.2.28, partition 6, NODE_LOCAL, 5373 bytes)
17/01/29 15:07:41,932 INFO TaskSetManager: Starting task 12.0 in stage 1.0 (TID 7, 10.1.2.191, partition 12, NODE_LOCAL, 5373 bytes)
17/01/29 15:07:41,935 INFO TaskSetManager: Starting task 10.0 in stage 1.0 (TID 8, 10.1.2.224, partition 10, NODE_LOCAL, 5373 bytes)
17/01/29 15:07:41,937 INFO TaskSetManager: Starting task 15.0 in stage 1.0 (TID 9, 10.1.2.176, partition 15, NODE_LOCAL, 5373 bytes)
17/01/29 15:07:41,939 INFO TaskSetManager: Starting task 17.0 in stage 1.0 (TID 10, 10.1.2.38, partition 17, NODE_LOCAL, 5373 bytes)
17/01/29 15:07:41,942 INFO TaskSetManager: Starting task 19.0 in stage 1.0 (TID 11, 10.1.2.65, partition 19, NODE_LOCAL, 5373 bytes)
17/01/29 15:07:41,944 INFO TaskSetManager: Starting task 13.0 in stage 1.0 (TID 12, 10.1.2.139, partition 13, NODE_LOCAL, 5373 bytes)
17/01/29 15:07:41,947 INFO TaskSetManager: Starting task 22.0 in stage 1.0 (TID 13, 10.1.2.66, partition 22, NODE_LOCAL, 5373 bytes)
17/01/29 15:07:41,948 INFO TaskSetManager: Starting task 20.0 in stage 1.0 (TID 14, 10.1.2.28, partition 20, NODE_LOCAL, 5373 bytes)
17/01/29 15:07:41,950 INFO TaskSetManager: Starting task 24.0 in stage 1.0 (TID 15, 10.1.2.191, partition 24, NODE_LOCAL, 5373 bytes)
17/01/29 15:07:41,952 INFO TaskSetManager: Starting task 26.0 in stage 1.0 (TID 16, 10.1.2.224, partition 26, NODE_LOCAL, 5373 bytes)
17/01/29 15:07:41,953 INFO TaskSetManager: Starting task 29.0 in stage 1.0 (TID 17, 10.1.2.176, partition 29, NODE_LOCAL, 5373 bytes)
17/01/29 15:07:41,955 INFO TaskSetManager: Starting task 27.0 in stage 1.0 (TID 18, 10.1.2.38, partition 27, NODE_LOCAL, 5373 bytes)
17/01/29 15:07:41,958 INFO TaskSetManager: Starting task 31.0 in stage 1.0 (TID 19, 10.1.2.65, partition 31, NODE_LOCAL, 5373 bytes)
17/01/29 15:07:41,960 INFO CoarseGrainedSchedulerBackend$DriverEndpoint: Launching task 2 on executor id: 5 hostname: 10.1.2.38.
17/01/29 15:07:41,961 INFO CoarseGrainedSchedulerBackend$DriverEndpoint: Launching task 10 on executor id: 5 hostname: 10.1.2.38.
17/01/29 15:07:41,962 INFO CoarseGrainedSchedulerBackend$DriverEndpoint: Launching task 18 on executor id: 5 hostname: 10.1.2.38.
17/01/29 15:07:41,962 INFO CoarseGrainedSchedulerBackend$DriverEndpoint: Launching task 1 on executor id: 0 hostname: 10.1.2.65.
17/01/29 15:07:41,965 INFO CoarseGrainedSchedulerBackend$DriverEndpoint: Launching task 3 on executor id: 0 hostname: 10.1.2.65.
17/01/29 15:07:41,965 INFO CoarseGrainedSchedulerBackend$DriverEndpoint: Launching task 11 on executor id: 0 hostname: 10.1.2.65.
17/01/29 15:07:41,966 INFO CoarseGrainedSchedulerBackend$DriverEndpoint: Launching task 19 on executor id: 0 hostname: 10.1.2.65.
17/01/29 15:07:41,966 INFO CoarseGrainedSchedulerBackend$DriverEndpoint: Launching task 4 on executor id: 7 hostname: 10.1.2.139.
17/01/29 15:07:41,967 INFO CoarseGrainedSchedulerBackend$DriverEndpoint: Launching task 12 on executor id: 7 hostname: 10.1.2.139.
17/01/29 15:07:41,968 INFO CoarseGrainedSchedulerBackend$DriverEndpoint: Launching task 5 on executor id: 3 hostname: 10.1.2.66.
17/01/29 15:07:41,968 INFO CoarseGrainedSchedulerBackend$DriverEndpoint: Launching task 13 on executor id: 3 hostname: 10.1.2.66.
17/01/29 15:07:41,969 INFO CoarseGrainedSchedulerBackend$DriverEndpoint: Launching task 6 on executor id: 1 hostname: 10.1.2.28.
17/01/29 15:07:41,970 INFO CoarseGrainedSchedulerBackend$DriverEndpoint: Launching task 14 on executor id: 1 hostname: 10.1.2.28.
17/01/29 15:07:41,970 INFO CoarseGrainedSchedulerBackend$DriverEndpoint: Launching task 7 on executor id: 6 hostname: 10.1.2.191.
17/01/29 15:07:41,971 INFO CoarseGrainedSchedulerBackend$DriverEndpoint: Launching task 15 on executor id: 6 hostname: 10.1.2.191.
17/01/29 15:07:41,972 INFO CoarseGrainedSchedulerBackend$DriverEndpoint: Launching task 8 on executor id: 4 hostname: 10.1.2.224.
17/01/29 15:07:41,972 INFO CoarseGrainedSchedulerBackend$DriverEndpoint: Launching task 16 on executor id: 4 hostname: 10.1.2.224.
17/01/29 15:07:41,973 INFO CoarseGrainedSchedulerBackend$DriverEndpoint: Launching task 9 on executor id: 2 hostname: 10.1.2.176.
17/01/29 15:07:41,973 INFO CoarseGrainedSchedulerBackend$DriverEndpoint: Launching task 17 on executor id: 2 hostname: 10.1.2.176.
17/01/29 15:07:42,000 INFO BlockManagerInfo: Added broadcast_2_piece0 in memory on 10.1.2.65:40765 (size: 2.2 KB, free: 2.0 GB)
17/01/29 15:07:42,137 INFO TaskSetManager: Finished task 0.0 in stage 1.0 (TID 1) in 221 ms on 10.1.2.65 (1/32)
15.614: [GC [PSYoungGen: 1024512K->140613K(1195008K)] 1024512K->140685K(3926016K), 0.0457300 secs] [Times: user=0.10 sys=0.03, real=0.04 secs] 
17/01/29 15:07:42,314 INFO BlockManagerInfo: Added broadcast_2_piece0 in memory on 10.1.2.38:34256 (size: 2.2 KB, free: 2.1 GB)
17/01/29 15:07:42,318 INFO BlockManagerInfo: Added broadcast_2_piece0 in memory on 10.1.2.224:37049 (size: 2.2 KB, free: 2.1 GB)
17/01/29 15:07:42,322 INFO BlockManagerInfo: Added broadcast_2_piece0 in memory on 10.1.2.28:41859 (size: 2.2 KB, free: 2.1 GB)
17/01/29 15:07:42,330 INFO BlockManagerInfo: Added broadcast_2_piece0 in memory on 10.1.2.176:35238 (size: 2.2 KB, free: 2.1 GB)
17/01/29 15:07:42,331 INFO BlockManagerInfo: Added broadcast_2_piece0 in memory on 10.1.2.139:33712 (size: 2.2 KB, free: 2.1 GB)
17/01/29 15:07:42,354 INFO BlockManagerInfo: Added broadcast_2_piece0 in memory on 10.1.2.66:43551 (size: 2.2 KB, free: 2.1 GB)
17/01/29 15:07:42,355 INFO BlockManagerInfo: Added broadcast_2_piece0 in memory on 10.1.2.191:37280 (size: 2.2 KB, free: 2.1 GB)
17/01/29 15:07:42,357 INFO BlockManagerInfo: Removed broadcast_1_piece0 on 10.1.2.152:37100 in memory (size: 2.4 KB, free: 2.1 GB)
17/01/29 15:07:42,369 INFO BlockManagerInfo: Removed broadcast_1_piece0 on 10.1.2.65:40765 in memory (size: 2.4 KB, free: 2.0 GB)
17/01/29 15:07:42,490 INFO BlockManagerInfo: Added broadcast_0_piece0 in memory on 10.1.2.38:34256 (size: 16.5 KB, free: 2.1 GB)
17/01/29 15:07:42,496 INFO BlockManagerInfo: Added broadcast_0_piece0 in memory on 10.1.2.224:37049 (size: 16.5 KB, free: 2.1 GB)
17/01/29 15:07:42,498 INFO BlockManagerInfo: Added broadcast_0_piece0 in memory on 10.1.2.28:41859 (size: 16.5 KB, free: 2.1 GB)
17/01/29 15:07:42,500 INFO BlockManagerInfo: Added broadcast_0_piece0 in memory on 10.1.2.176:35238 (size: 16.5 KB, free: 2.1 GB)
17/01/29 15:07:42,507 INFO BlockManagerInfo: Added broadcast_0_piece0 in memory on 10.1.2.139:33712 (size: 16.5 KB, free: 2.1 GB)
17/01/29 15:07:42,563 INFO BlockManagerInfo: Added broadcast_0_piece0 in memory on 10.1.2.191:37280 (size: 16.5 KB, free: 2.1 GB)
17/01/29 15:07:42,580 INFO BlockManagerInfo: Added broadcast_0_piece0 in memory on 10.1.2.66:43551 (size: 16.5 KB, free: 2.1 GB)
17/01/29 15:07:45,525 INFO TaskSetManager: Starting task 2.0 in stage 1.0 (TID 20, 10.1.2.38, partition 2, ANY, 5373 bytes)
17/01/29 15:07:45,528 INFO TaskSetManager: Starting task 4.0 in stage 1.0 (TID 21, 10.1.2.28, partition 4, ANY, 5373 bytes)
17/01/29 15:07:45,529 INFO TaskSetManager: Starting task 7.0 in stage 1.0 (TID 22, 10.1.2.66, partition 7, ANY, 5373 bytes)
17/01/29 15:07:45,531 INFO TaskSetManager: Starting task 9.0 in stage 1.0 (TID 23, 10.1.2.139, partition 9, ANY, 5373 bytes)
17/01/29 15:07:45,533 INFO TaskSetManager: Starting task 11.0 in stage 1.0 (TID 24, 10.1.2.224, partition 11, ANY, 5373 bytes)
17/01/29 15:07:45,535 INFO TaskSetManager: Starting task 14.0 in stage 1.0 (TID 25, 10.1.2.65, partition 14, ANY, 5373 bytes)
17/01/29 15:07:45,536 INFO TaskSetManager: Starting task 16.0 in stage 1.0 (TID 26, 10.1.2.176, partition 16, ANY, 5373 bytes)
17/01/29 15:07:45,538 INFO TaskSetManager: Starting task 18.0 in stage 1.0 (TID 27, 10.1.2.191, partition 18, ANY, 5373 bytes)
17/01/29 15:07:45,540 INFO TaskSetManager: Starting task 21.0 in stage 1.0 (TID 28, 10.1.2.28, partition 21, ANY, 5373 bytes)
17/01/29 15:07:45,542 INFO TaskSetManager: Starting task 23.0 in stage 1.0 (TID 29, 10.1.2.66, partition 23, ANY, 5373 bytes)
17/01/29 15:07:45,543 INFO TaskSetManager: Starting task 25.0 in stage 1.0 (TID 30, 10.1.2.139, partition 25, ANY, 5373 bytes)
17/01/29 15:07:45,545 INFO TaskSetManager: Starting task 28.0 in stage 1.0 (TID 31, 10.1.2.224, partition 28, ANY, 5373 bytes)
17/01/29 15:07:45,546 INFO TaskSetManager: Starting task 30.0 in stage 1.0 (TID 32, 10.1.2.176, partition 30, ANY, 5373 bytes)
17/01/29 15:07:45,547 INFO CoarseGrainedSchedulerBackend$DriverEndpoint: Launching task 20 on executor id: 5 hostname: 10.1.2.38.
17/01/29 15:07:45,548 INFO CoarseGrainedSchedulerBackend$DriverEndpoint: Launching task 21 on executor id: 1 hostname: 10.1.2.28.
17/01/29 15:07:45,548 INFO CoarseGrainedSchedulerBackend$DriverEndpoint: Launching task 28 on executor id: 1 hostname: 10.1.2.28.
17/01/29 15:07:45,549 INFO CoarseGrainedSchedulerBackend$DriverEndpoint: Launching task 22 on executor id: 3 hostname: 10.1.2.66.
17/01/29 15:07:45,550 INFO CoarseGrainedSchedulerBackend$DriverEndpoint: Launching task 29 on executor id: 3 hostname: 10.1.2.66.
17/01/29 15:07:45,551 INFO CoarseGrainedSchedulerBackend$DriverEndpoint: Launching task 23 on executor id: 7 hostname: 10.1.2.139.
17/01/29 15:07:45,552 INFO CoarseGrainedSchedulerBackend$DriverEndpoint: Launching task 30 on executor id: 7 hostname: 10.1.2.139.
17/01/29 15:07:45,552 INFO CoarseGrainedSchedulerBackend$DriverEndpoint: Launching task 24 on executor id: 4 hostname: 10.1.2.224.
17/01/29 15:07:45,553 INFO CoarseGrainedSchedulerBackend$DriverEndpoint: Launching task 31 on executor id: 4 hostname: 10.1.2.224.
17/01/29 15:07:45,554 INFO CoarseGrainedSchedulerBackend$DriverEndpoint: Launching task 25 on executor id: 0 hostname: 10.1.2.65.
17/01/29 15:07:45,571 INFO CoarseGrainedSchedulerBackend$DriverEndpoint: Launching task 26 on executor id: 2 hostname: 10.1.2.176.
17/01/29 15:07:45,571 INFO CoarseGrainedSchedulerBackend$DriverEndpoint: Launching task 32 on executor id: 2 hostname: 10.1.2.176.
17/01/29 15:07:45,572 INFO CoarseGrainedSchedulerBackend$DriverEndpoint: Launching task 27 on executor id: 6 hostname: 10.1.2.191.
17/01/29 15:07:49,659 INFO BlockManagerInfo: Added rdd_5_12 in memory on 10.1.2.191:37280 (size: 44.4 MB, free: 2.0 GB)
17/01/29 15:07:49,711 INFO BlockManagerInfo: Added rdd_5_24 in memory on 10.1.2.191:37280 (size: 44.4 MB, free: 2031.6 MB)
17/01/29 15:07:49,743 INFO TaskSetManager: Finished task 12.0 in stage 1.0 (TID 7) in 7812 ms on 10.1.2.191 (2/32)
17/01/29 15:07:49,745 INFO TaskSetManager: Finished task 24.0 in stage 1.0 (TID 15) in 7796 ms on 10.1.2.191 (3/32)
17/01/29 15:07:51,062 INFO BlockManagerInfo: Added rdd_5_18 in memory on 10.1.2.191:37280 (size: 44.3 MB, free: 1987.2 MB)
17/01/29 15:07:51,090 INFO TaskSetManager: Finished task 18.0 in stage 1.0 (TID 27) in 5553 ms on 10.1.2.191 (4/32)
17/01/29 15:07:51,847 INFO BlockManagerInfo: Added rdd_5_20 in memory on 10.1.2.28:41859 (size: 44.4 MB, free: 2.0 GB)
17/01/29 15:07:51,926 INFO TaskSetManager: Finished task 20.0 in stage 1.0 (TID 14) in 9979 ms on 10.1.2.28 (5/32)
17/01/29 15:07:51,927 INFO BlockManagerInfo: Added rdd_5_26 in memory on 10.1.2.224:37049 (size: 44.4 MB, free: 2.0 GB)
17/01/29 15:07:51,949 INFO BlockManagerInfo: Added rdd_5_10 in memory on 10.1.2.224:37049 (size: 44.4 MB, free: 2031.6 MB)
17/01/29 15:07:52,045 INFO TaskSetManager: Finished task 10.0 in stage 1.0 (TID 8) in 10111 ms on 10.1.2.224 (6/32)
17/01/29 15:07:52,066 INFO TaskSetManager: Finished task 26.0 in stage 1.0 (TID 16) in 10115 ms on 10.1.2.224 (7/32)
17/01/29 15:07:53,047 INFO BlockManagerInfo: Added rdd_5_6 in memory on 10.1.2.28:41859 (size: 44.4 MB, free: 2031.7 MB)
17/01/29 15:07:53,073 INFO TaskSetManager: Finished task 6.0 in stage 1.0 (TID 6) in 11146 ms on 10.1.2.28 (8/32)
17/01/29 15:07:53,587 INFO BlockManagerInfo: Added rdd_5_1 in memory on 10.1.2.38:34256 (size: 44.4 MB, free: 2.0 GB)
17/01/29 15:07:53,637 INFO BlockManagerInfo: Added rdd_5_17 in memory on 10.1.2.38:34256 (size: 44.4 MB, free: 2031.5 MB)
17/01/29 15:07:53,668 INFO TaskSetManager: Finished task 17.0 in stage 1.0 (TID 10) in 11729 ms on 10.1.2.38 (9/32)
17/01/29 15:07:53,669 INFO TaskSetManager: Finished task 1.0 in stage 1.0 (TID 2) in 11749 ms on 10.1.2.38 (10/32)
17/01/29 15:07:53,706 INFO BlockManagerInfo: Added rdd_5_27 in memory on 10.1.2.38:34256 (size: 44.4 MB, free: 1987.1 MB)
17/01/29 15:07:53,736 INFO TaskSetManager: Finished task 27.0 in stage 1.0 (TID 18) in 11782 ms on 10.1.2.38 (11/32)
17/01/29 15:07:53,737 INFO BlockManagerInfo: Added rdd_5_11 in memory on 10.1.2.224:37049 (size: 44.4 MB, free: 1987.2 MB)
17/01/29 15:07:53,756 INFO TaskSetManager: Finished task 11.0 in stage 1.0 (TID 24) in 8224 ms on 10.1.2.224 (12/32)
17/01/29 15:07:53,785 INFO BlockManagerInfo: Added rdd_5_8 in memory on 10.1.2.139:33712 (size: 44.4 MB, free: 2.0 GB)
17/01/29 15:07:53,852 INFO TaskSetManager: Finished task 8.0 in stage 1.0 (TID 4) in 11929 ms on 10.1.2.139 (13/32)
17/01/29 15:07:53,880 INFO BlockManagerInfo: Added rdd_5_29 in memory on 10.1.2.176:35238 (size: 44.4 MB, free: 2.0 GB)
17/01/29 15:07:53,940 INFO TaskSetManager: Finished task 29.0 in stage 1.0 (TID 17) in 11988 ms on 10.1.2.176 (14/32)
17/01/29 15:07:53,963 INFO BlockManagerInfo: Added rdd_5_28 in memory on 10.1.2.224:37049 (size: 44.4 MB, free: 1942.8 MB)
17/01/29 15:07:53,964 INFO BlockManagerInfo: Added rdd_5_13 in memory on 10.1.2.139:33712 (size: 44.4 MB, free: 2031.7 MB)
17/01/29 15:07:53,981 INFO TaskSetManager: Finished task 13.0 in stage 1.0 (TID 12) in 12038 ms on 10.1.2.139 (15/32)
17/01/29 15:07:53,983 INFO TaskSetManager: Finished task 28.0 in stage 1.0 (TID 31) in 8440 ms on 10.1.2.224 (16/32)
17/01/29 15:07:53,993 INFO BlockManagerInfo: Added rdd_5_15 in memory on 10.1.2.176:35238 (size: 44.4 MB, free: 2031.6 MB)
17/01/29 15:07:54,015 INFO TaskSetManager: Finished task 15.0 in stage 1.0 (TID 9) in 12079 ms on 10.1.2.176 (17/32)
17/01/29 15:07:54,792 INFO BlockManagerInfo: Added rdd_5_2 in memory on 10.1.2.38:34256 (size: 44.4 MB, free: 1942.7 MB)
17/01/29 15:07:54,810 INFO TaskSetManager: Finished task 2.0 in stage 1.0 (TID 20) in 9287 ms on 10.1.2.38 (18/32)
17/01/29 15:07:55,112 INFO BlockManagerInfo: Added rdd_5_4 in memory on 10.1.2.28:41859 (size: 44.4 MB, free: 1987.3 MB)
17/01/29 15:07:55,123 INFO BlockManagerInfo: Added rdd_5_22 in memory on 10.1.2.66:43551 (size: 44.3 MB, free: 2.0 GB)
17/01/29 15:07:55,130 INFO TaskSetManager: Finished task 4.0 in stage 1.0 (TID 21) in 9605 ms on 10.1.2.28 (19/32)
17/01/29 15:07:55,148 INFO BlockManagerInfo: Added rdd_5_21 in memory on 10.1.2.28:41859 (size: 44.4 MB, free: 1942.9 MB)
17/01/29 15:07:55,164 INFO TaskSetManager: Finished task 21.0 in stage 1.0 (TID 28) in 9626 ms on 10.1.2.28 (20/32)
17/01/29 15:07:55,192 INFO TaskSetManager: Finished task 22.0 in stage 1.0 (TID 13) in 13247 ms on 10.1.2.66 (21/32)
17/01/29 15:07:55,621 INFO BlockManagerInfo: Added rdd_5_25 in memory on 10.1.2.139:33712 (size: 44.3 MB, free: 1987.3 MB)
17/01/29 15:07:55,646 INFO TaskSetManager: Finished task 25.0 in stage 1.0 (TID 30) in 10103 ms on 10.1.2.139 (22/32)
17/01/29 15:07:55,715 INFO BlockManagerInfo: Added rdd_5_9 in memory on 10.1.2.139:33712 (size: 44.4 MB, free: 1942.9 MB)
17/01/29 15:07:55,721 INFO BlockManagerInfo: Added rdd_5_5 in memory on 10.1.2.66:43551 (size: 44.3 MB, free: 2031.7 MB)
17/01/29 15:07:55,735 INFO TaskSetManager: Finished task 9.0 in stage 1.0 (TID 23) in 10204 ms on 10.1.2.139 (23/32)
17/01/29 15:07:55,741 INFO TaskSetManager: Finished task 5.0 in stage 1.0 (TID 5) in 13816 ms on 10.1.2.66 (24/32)
17/01/29 15:07:55,765 INFO BlockManagerInfo: Added rdd_5_3 in memory on 10.1.2.65:40765 (size: 44.4 MB, free: 2031.7 MB)
17/01/29 15:07:55,798 INFO TaskSetManager: Finished task 3.0 in stage 1.0 (TID 3) in 13877 ms on 10.1.2.65 (25/32)
17/01/29 15:07:55,799 INFO BlockManagerInfo: Added rdd_5_19 in memory on 10.1.2.65:40765 (size: 44.4 MB, free: 1987.2 MB)
17/01/29 15:07:55,832 INFO TaskSetManager: Finished task 19.0 in stage 1.0 (TID 11) in 13891 ms on 10.1.2.65 (26/32)
17/01/29 15:07:55,884 INFO BlockManagerInfo: Added rdd_5_16 in memory on 10.1.2.176:35238 (size: 44.4 MB, free: 1987.2 MB)
17/01/29 15:07:55,886 INFO BlockManagerInfo: Added rdd_5_31 in memory on 10.1.2.65:40765 (size: 44.3 MB, free: 1942.9 MB)
17/01/29 15:07:55,908 INFO TaskSetManager: Finished task 16.0 in stage 1.0 (TID 26) in 10373 ms on 10.1.2.176 (27/32)
17/01/29 15:07:55,913 INFO TaskSetManager: Finished task 31.0 in stage 1.0 (TID 19) in 13958 ms on 10.1.2.65 (28/32)
17/01/29 15:07:55,960 INFO BlockManagerInfo: Added rdd_5_30 in memory on 10.1.2.176:35238 (size: 44.4 MB, free: 1942.8 MB)
17/01/29 15:07:55,977 INFO TaskSetManager: Finished task 30.0 in stage 1.0 (TID 32) in 10432 ms on 10.1.2.176 (29/32)
17/01/29 15:07:56,649 INFO BlockManagerInfo: Added rdd_5_14 in memory on 10.1.2.65:40765 (size: 44.4 MB, free: 1898.5 MB)
17/01/29 15:07:56,667 INFO TaskSetManager: Finished task 14.0 in stage 1.0 (TID 25) in 11133 ms on 10.1.2.65 (30/32)
17/01/29 15:07:56,699 INFO BlockManagerInfo: Added rdd_5_7 in memory on 10.1.2.66:43551 (size: 44.4 MB, free: 1987.4 MB)
17/01/29 15:07:56,727 INFO TaskSetManager: Finished task 7.0 in stage 1.0 (TID 22) in 11198 ms on 10.1.2.66 (31/32)
17/01/29 15:07:56,980 INFO BlockManagerInfo: Added rdd_5_23 in memory on 10.1.2.66:43551 (size: 44.3 MB, free: 1943.0 MB)
17/01/29 15:07:57,000 INFO TaskSetManager: Finished task 23.0 in stage 1.0 (TID 29) in 11459 ms on 10.1.2.66 (32/32)
17/01/29 15:07:57,000 INFO TaskSchedulerImpl: Removed TaskSet 1.0, whose tasks have all completed, from pool 
17/01/29 15:07:57,000 INFO DAGScheduler: ResultStage 1 (count at DataValidators.scala:40) finished in 15.082 s
17/01/29 15:07:57,001 INFO DAGScheduler: Job 1 finished: count at DataValidators.scala:40, took 15.112564 s
17/01/29 15:07:57,012 INFO SparkContext: Starting job: count at GradientDescent.scala:209
17/01/29 15:07:57,013 INFO DAGScheduler: Got job 2 (count at GradientDescent.scala:209) with 32 output partitions
17/01/29 15:07:57,013 INFO DAGScheduler: Final stage: ResultStage 2 (count at GradientDescent.scala:209)
17/01/29 15:07:57,013 INFO DAGScheduler: Parents of final stage: List()
17/01/29 15:07:57,016 INFO DAGScheduler: Missing parents: List()
17/01/29 15:07:57,016 INFO DAGScheduler: Submitting ResultStage 2 (MapPartitionsRDD[8] at map at GeneralizedLinearAlgorithm.scala:297), which has no missing parents
17/01/29 15:07:57,021 INFO MemoryStore: Block broadcast_3 stored as values in memory (estimated size 3.9 KB, free 2.1 GB)
17/01/29 15:07:57,023 INFO MemoryStore: Block broadcast_3_piece0 stored as bytes in memory (estimated size 2.2 KB, free 2.1 GB)
17/01/29 15:07:57,024 INFO BlockManagerInfo: Added broadcast_3_piece0 in memory on 10.1.2.152:37100 (size: 2.2 KB, free: 2.1 GB)
17/01/29 15:07:57,025 INFO SparkContext: Created broadcast 3 from broadcast at DAGScheduler.scala:1012
17/01/29 15:07:57,026 INFO DAGScheduler: Submitting 32 missing tasks from ResultStage 2 (MapPartitionsRDD[8] at map at GeneralizedLinearAlgorithm.scala:297)
17/01/29 15:07:57,026 INFO TaskSchedulerImpl: Adding task set 2.0 with 32 tasks
17/01/29 15:07:57,029 INFO TaskSetManager: Starting task 4.0 in stage 2.0 (TID 33, 10.1.2.28, partition 4, PROCESS_LOCAL, 5373 bytes)
17/01/29 15:07:57,030 INFO TaskSetManager: Starting task 5.0 in stage 2.0 (TID 34, 10.1.2.66, partition 5, PROCESS_LOCAL, 5373 bytes)
17/01/29 15:07:57,032 INFO TaskSetManager: Starting task 15.0 in stage 2.0 (TID 35, 10.1.2.176, partition 15, PROCESS_LOCAL, 5373 bytes)
17/01/29 15:07:57,038 INFO TaskSetManager: Starting task 10.0 in stage 2.0 (TID 36, 10.1.2.224, partition 10, PROCESS_LOCAL, 5373 bytes)
17/01/29 15:07:57,039 INFO TaskSetManager: Starting task 1.0 in stage 2.0 (TID 37, 10.1.2.38, partition 1, PROCESS_LOCAL, 5373 bytes)
17/01/29 15:07:57,040 INFO TaskSetManager: Starting task 0.0 in stage 2.0 (TID 38, 10.1.2.65, partition 0, PROCESS_LOCAL, 5373 bytes)
17/01/29 15:07:57,046 INFO TaskSetManager: Starting task 8.0 in stage 2.0 (TID 39, 10.1.2.139, partition 8, PROCESS_LOCAL, 5373 bytes)
17/01/29 15:07:57,047 INFO TaskSetManager: Starting task 12.0 in stage 2.0 (TID 40, 10.1.2.191, partition 12, PROCESS_LOCAL, 5373 bytes)
17/01/29 15:07:57,048 INFO TaskSetManager: Starting task 6.0 in stage 2.0 (TID 41, 10.1.2.28, partition 6, PROCESS_LOCAL, 5373 bytes)
17/01/29 15:07:57,049 INFO TaskSetManager: Starting task 7.0 in stage 2.0 (TID 42, 10.1.2.66, partition 7, PROCESS_LOCAL, 5373 bytes)
17/01/29 15:07:57,050 INFO TaskSetManager: Starting task 16.0 in stage 2.0 (TID 43, 10.1.2.176, partition 16, PROCESS_LOCAL, 5373 bytes)
17/01/29 15:07:57,051 INFO TaskSetManager: Starting task 11.0 in stage 2.0 (TID 44, 10.1.2.224, partition 11, PROCESS_LOCAL, 5373 bytes)
17/01/29 15:07:57,052 INFO TaskSetManager: Starting task 2.0 in stage 2.0 (TID 45, 10.1.2.38, partition 2, PROCESS_LOCAL, 5373 bytes)
17/01/29 15:07:57,054 INFO TaskSetManager: Starting task 3.0 in stage 2.0 (TID 46, 10.1.2.65, partition 3, PROCESS_LOCAL, 5373 bytes)
17/01/29 15:07:57,055 INFO TaskSetManager: Starting task 9.0 in stage 2.0 (TID 47, 10.1.2.139, partition 9, PROCESS_LOCAL, 5373 bytes)
17/01/29 15:07:57,056 INFO TaskSetManager: Starting task 18.0 in stage 2.0 (TID 48, 10.1.2.191, partition 18, PROCESS_LOCAL, 5373 bytes)
17/01/29 15:07:57,057 INFO TaskSetManager: Starting task 20.0 in stage 2.0 (TID 49, 10.1.2.28, partition 20, PROCESS_LOCAL, 5373 bytes)
17/01/29 15:07:57,058 INFO TaskSetManager: Starting task 22.0 in stage 2.0 (TID 50, 10.1.2.66, partition 22, PROCESS_LOCAL, 5373 bytes)
17/01/29 15:07:57,060 INFO TaskSetManager: Starting task 29.0 in stage 2.0 (TID 51, 10.1.2.176, partition 29, PROCESS_LOCAL, 5373 bytes)
17/01/29 15:07:57,061 INFO TaskSetManager: Starting task 26.0 in stage 2.0 (TID 52, 10.1.2.224, partition 26, PROCESS_LOCAL, 5373 bytes)
17/01/29 15:07:57,062 INFO TaskSetManager: Starting task 17.0 in stage 2.0 (TID 53, 10.1.2.38, partition 17, PROCESS_LOCAL, 5373 bytes)
17/01/29 15:07:57,063 INFO TaskSetManager: Starting task 14.0 in stage 2.0 (TID 54, 10.1.2.65, partition 14, PROCESS_LOCAL, 5373 bytes)
17/01/29 15:07:57,065 INFO TaskSetManager: Starting task 13.0 in stage 2.0 (TID 55, 10.1.2.139, partition 13, PROCESS_LOCAL, 5373 bytes)
17/01/29 15:07:57,066 INFO TaskSetManager: Starting task 24.0 in stage 2.0 (TID 56, 10.1.2.191, partition 24, PROCESS_LOCAL, 5373 bytes)
17/01/29 15:07:57,067 INFO TaskSetManager: Starting task 21.0 in stage 2.0 (TID 57, 10.1.2.28, partition 21, PROCESS_LOCAL, 5373 bytes)
17/01/29 15:07:57,068 INFO TaskSetManager: Starting task 23.0 in stage 2.0 (TID 58, 10.1.2.66, partition 23, PROCESS_LOCAL, 5373 bytes)
17/01/29 15:07:57,069 INFO TaskSetManager: Starting task 30.0 in stage 2.0 (TID 59, 10.1.2.176, partition 30, PROCESS_LOCAL, 5373 bytes)
17/01/29 15:07:57,070 INFO TaskSetManager: Starting task 28.0 in stage 2.0 (TID 60, 10.1.2.224, partition 28, PROCESS_LOCAL, 5373 bytes)
17/01/29 15:07:57,072 INFO TaskSetManager: Starting task 27.0 in stage 2.0 (TID 61, 10.1.2.38, partition 27, PROCESS_LOCAL, 5373 bytes)
17/01/29 15:07:57,073 INFO TaskSetManager: Starting task 19.0 in stage 2.0 (TID 62, 10.1.2.65, partition 19, PROCESS_LOCAL, 5373 bytes)
17/01/29 15:07:57,074 INFO TaskSetManager: Starting task 25.0 in stage 2.0 (TID 63, 10.1.2.139, partition 25, PROCESS_LOCAL, 5373 bytes)
17/01/29 15:07:57,074 INFO CoarseGrainedSchedulerBackend$DriverEndpoint: Launching task 33 on executor id: 1 hostname: 10.1.2.28.
17/01/29 15:07:57,075 INFO CoarseGrainedSchedulerBackend$DriverEndpoint: Launching task 41 on executor id: 1 hostname: 10.1.2.28.
17/01/29 15:07:57,075 INFO CoarseGrainedSchedulerBackend$DriverEndpoint: Launching task 49 on executor id: 1 hostname: 10.1.2.28.
17/01/29 15:07:57,076 INFO CoarseGrainedSchedulerBackend$DriverEndpoint: Launching task 57 on executor id: 1 hostname: 10.1.2.28.
17/01/29 15:07:57,076 INFO CoarseGrainedSchedulerBackend$DriverEndpoint: Launching task 34 on executor id: 3 hostname: 10.1.2.66.
17/01/29 15:07:57,076 INFO CoarseGrainedSchedulerBackend$DriverEndpoint: Launching task 42 on executor id: 3 hostname: 10.1.2.66.
17/01/29 15:07:57,077 INFO CoarseGrainedSchedulerBackend$DriverEndpoint: Launching task 50 on executor id: 3 hostname: 10.1.2.66.
17/01/29 15:07:57,077 INFO CoarseGrainedSchedulerBackend$DriverEndpoint: Launching task 58 on executor id: 3 hostname: 10.1.2.66.
17/01/29 15:07:57,077 INFO CoarseGrainedSchedulerBackend$DriverEndpoint: Launching task 35 on executor id: 2 hostname: 10.1.2.176.
17/01/29 15:07:57,078 INFO CoarseGrainedSchedulerBackend$DriverEndpoint: Launching task 43 on executor id: 2 hostname: 10.1.2.176.
17/01/29 15:07:57,078 INFO CoarseGrainedSchedulerBackend$DriverEndpoint: Launching task 51 on executor id: 2 hostname: 10.1.2.176.
17/01/29 15:07:57,078 INFO CoarseGrainedSchedulerBackend$DriverEndpoint: Launching task 59 on executor id: 2 hostname: 10.1.2.176.
17/01/29 15:07:57,079 INFO CoarseGrainedSchedulerBackend$DriverEndpoint: Launching task 36 on executor id: 4 hostname: 10.1.2.224.
17/01/29 15:07:57,079 INFO CoarseGrainedSchedulerBackend$DriverEndpoint: Launching task 44 on executor id: 4 hostname: 10.1.2.224.
17/01/29 15:07:57,080 INFO CoarseGrainedSchedulerBackend$DriverEndpoint: Launching task 52 on executor id: 4 hostname: 10.1.2.224.
17/01/29 15:07:57,080 INFO CoarseGrainedSchedulerBackend$DriverEndpoint: Launching task 60 on executor id: 4 hostname: 10.1.2.224.
17/01/29 15:07:57,080 INFO CoarseGrainedSchedulerBackend$DriverEndpoint: Launching task 37 on executor id: 5 hostname: 10.1.2.38.
17/01/29 15:07:57,081 INFO CoarseGrainedSchedulerBackend$DriverEndpoint: Launching task 45 on executor id: 5 hostname: 10.1.2.38.
17/01/29 15:07:57,081 INFO CoarseGrainedSchedulerBackend$DriverEndpoint: Launching task 53 on executor id: 5 hostname: 10.1.2.38.
17/01/29 15:07:57,081 INFO CoarseGrainedSchedulerBackend$DriverEndpoint: Launching task 61 on executor id: 5 hostname: 10.1.2.38.
17/01/29 15:07:57,082 INFO CoarseGrainedSchedulerBackend$DriverEndpoint: Launching task 38 on executor id: 0 hostname: 10.1.2.65.
17/01/29 15:07:57,082 INFO CoarseGrainedSchedulerBackend$DriverEndpoint: Launching task 46 on executor id: 0 hostname: 10.1.2.65.
17/01/29 15:07:57,083 INFO CoarseGrainedSchedulerBackend$DriverEndpoint: Launching task 54 on executor id: 0 hostname: 10.1.2.65.
17/01/29 15:07:57,083 INFO CoarseGrainedSchedulerBackend$DriverEndpoint: Launching task 62 on executor id: 0 hostname: 10.1.2.65.
17/01/29 15:07:57,083 INFO CoarseGrainedSchedulerBackend$DriverEndpoint: Launching task 39 on executor id: 7 hostname: 10.1.2.139.
17/01/29 15:07:57,084 INFO CoarseGrainedSchedulerBackend$DriverEndpoint: Launching task 47 on executor id: 7 hostname: 10.1.2.139.
17/01/29 15:07:57,084 INFO CoarseGrainedSchedulerBackend$DriverEndpoint: Launching task 55 on executor id: 7 hostname: 10.1.2.139.
17/01/29 15:07:57,084 INFO CoarseGrainedSchedulerBackend$DriverEndpoint: Launching task 63 on executor id: 7 hostname: 10.1.2.139.
17/01/29 15:07:57,085 INFO CoarseGrainedSchedulerBackend$DriverEndpoint: Launching task 40 on executor id: 6 hostname: 10.1.2.191.
17/01/29 15:07:57,085 INFO CoarseGrainedSchedulerBackend$DriverEndpoint: Launching task 48 on executor id: 6 hostname: 10.1.2.191.
17/01/29 15:07:57,085 INFO CoarseGrainedSchedulerBackend$DriverEndpoint: Launching task 56 on executor id: 6 hostname: 10.1.2.191.
17/01/29 15:07:57,097 INFO BlockManagerInfo: Added broadcast_3_piece0 in memory on 10.1.2.66:43551 (size: 2.2 KB, free: 1943.0 MB)
17/01/29 15:07:57,108 INFO BlockManagerInfo: Added broadcast_3_piece0 in memory on 10.1.2.176:35238 (size: 2.2 KB, free: 1942.8 MB)
17/01/29 15:07:57,108 INFO BlockManagerInfo: Added broadcast_3_piece0 in memory on 10.1.2.191:37280 (size: 2.2 KB, free: 1987.2 MB)
17/01/29 15:07:57,114 INFO BlockManagerInfo: Added broadcast_3_piece0 in memory on 10.1.2.224:37049 (size: 2.2 KB, free: 1942.8 MB)
17/01/29 15:07:57,118 INFO BlockManagerInfo: Added broadcast_3_piece0 in memory on 10.1.2.28:41859 (size: 2.2 KB, free: 1942.9 MB)
17/01/29 15:07:57,123 INFO BlockManagerInfo: Added broadcast_3_piece0 in memory on 10.1.2.139:33712 (size: 2.2 KB, free: 1942.9 MB)
17/01/29 15:07:57,146 INFO TaskSetManager: Finished task 24.0 in stage 2.0 (TID 56) in 80 ms on 10.1.2.191 (1/32)
17/01/29 15:07:57,146 INFO TaskSetManager: Finished task 29.0 in stage 2.0 (TID 51) in 88 ms on 10.1.2.176 (2/32)
17/01/29 15:07:57,153 INFO TaskSetManager: Finished task 28.0 in stage 2.0 (TID 60) in 84 ms on 10.1.2.224 (3/32)
17/01/29 15:07:57,155 INFO TaskSetManager: Finished task 11.0 in stage 2.0 (TID 44) in 105 ms on 10.1.2.224 (4/32)
17/01/29 15:07:57,157 INFO BlockManagerInfo: Added broadcast_3_piece0 in memory on 10.1.2.38:34256 (size: 2.2 KB, free: 1942.7 MB)
17/01/29 15:07:57,159 INFO TaskSetManager: Finished task 10.0 in stage 2.0 (TID 36) in 126 ms on 10.1.2.224 (5/32)
17/01/29 15:07:57,161 INFO TaskSetManager: Finished task 12.0 in stage 2.0 (TID 40) in 115 ms on 10.1.2.191 (6/32)
17/01/29 15:07:57,162 INFO TaskSetManager: Finished task 26.0 in stage 2.0 (TID 52) in 102 ms on 10.1.2.224 (7/32)
17/01/29 15:07:57,163 INFO BlockManagerInfo: Added broadcast_3_piece0 in memory on 10.1.2.65:40765 (size: 2.2 KB, free: 1898.5 MB)
17/01/29 15:07:57,165 INFO TaskSetManager: Finished task 18.0 in stage 2.0 (TID 48) in 110 ms on 10.1.2.191 (8/32)
17/01/29 15:07:57,169 INFO TaskSetManager: Finished task 4.0 in stage 2.0 (TID 33) in 141 ms on 10.1.2.28 (9/32)
17/01/29 15:07:57,171 INFO TaskSetManager: Finished task 22.0 in stage 2.0 (TID 50) in 114 ms on 10.1.2.66 (10/32)
17/01/29 15:07:57,173 INFO TaskSetManager: Finished task 23.0 in stage 2.0 (TID 58) in 105 ms on 10.1.2.66 (11/32)
17/01/29 15:07:57,174 INFO TaskSetManager: Finished task 7.0 in stage 2.0 (TID 42) in 126 ms on 10.1.2.66 (12/32)
17/01/29 15:07:57,182 INFO TaskSetManager: Finished task 30.0 in stage 2.0 (TID 59) in 113 ms on 10.1.2.176 (13/32)
17/01/29 15:07:57,190 INFO TaskSetManager: Finished task 20.0 in stage 2.0 (TID 49) in 134 ms on 10.1.2.28 (14/32)
17/01/29 15:07:57,194 INFO TaskSetManager: Starting task 31.0 in stage 2.0 (TID 64, 10.1.2.65, partition 31, PROCESS_LOCAL, 5373 bytes)
17/01/29 15:07:57,195 INFO CoarseGrainedSchedulerBackend$DriverEndpoint: Launching task 64 on executor id: 0 hostname: 10.1.2.65.
17/01/29 15:07:57,195 INFO TaskSetManager: Finished task 19.0 in stage 2.0 (TID 62) in 123 ms on 10.1.2.65 (15/32)
17/01/29 15:07:57,196 INFO TaskSetManager: Finished task 14.0 in stage 2.0 (TID 54) in 134 ms on 10.1.2.65 (16/32)
17/01/29 15:07:57,197 INFO TaskSetManager: Finished task 2.0 in stage 2.0 (TID 45) in 146 ms on 10.1.2.38 (17/32)
17/01/29 15:07:57,197 INFO TaskSetManager: Finished task 5.0 in stage 2.0 (TID 34) in 168 ms on 10.1.2.66 (18/32)
17/01/29 15:07:57,199 INFO TaskSetManager: Finished task 1.0 in stage 2.0 (TID 37) in 161 ms on 10.1.2.38 (19/32)
17/01/29 15:07:57,199 INFO TaskSetManager: Finished task 0.0 in stage 2.0 (TID 38) in 160 ms on 10.1.2.65 (20/32)
17/01/29 15:07:57,202 INFO TaskSetManager: Finished task 3.0 in stage 2.0 (TID 46) in 149 ms on 10.1.2.65 (21/32)
17/01/29 15:07:57,205 INFO TaskSetManager: Finished task 6.0 in stage 2.0 (TID 41) in 158 ms on 10.1.2.28 (22/32)
17/01/29 15:07:57,208 INFO TaskSetManager: Finished task 17.0 in stage 2.0 (TID 53) in 147 ms on 10.1.2.38 (23/32)
17/01/29 15:07:57,210 INFO TaskSetManager: Finished task 21.0 in stage 2.0 (TID 57) in 144 ms on 10.1.2.28 (24/32)
17/01/29 15:07:57,210 INFO TaskSetManager: Finished task 25.0 in stage 2.0 (TID 63) in 137 ms on 10.1.2.139 (25/32)
17/01/29 15:07:57,214 INFO TaskSetManager: Finished task 8.0 in stage 2.0 (TID 39) in 169 ms on 10.1.2.139 (26/32)
17/01/29 15:07:57,218 INFO TaskSetManager: Finished task 13.0 in stage 2.0 (TID 55) in 155 ms on 10.1.2.139 (27/32)
17/01/29 15:07:57,219 INFO TaskSetManager: Finished task 16.0 in stage 2.0 (TID 43) in 170 ms on 10.1.2.176 (28/32)
17/01/29 15:07:57,226 INFO TaskSetManager: Finished task 31.0 in stage 2.0 (TID 64) in 33 ms on 10.1.2.65 (29/32)
17/01/29 15:07:57,229 INFO TaskSetManager: Finished task 9.0 in stage 2.0 (TID 47) in 175 ms on 10.1.2.139 (30/32)
17/01/29 15:07:57,347 INFO TaskSetManager: Finished task 27.0 in stage 2.0 (TID 61) in 277 ms on 10.1.2.38 (31/32)
17/01/29 15:07:57,365 INFO TaskSetManager: Finished task 15.0 in stage 2.0 (TID 35) in 335 ms on 10.1.2.176 (32/32)
17/01/29 15:07:57,365 INFO TaskSchedulerImpl: Removed TaskSet 2.0, whose tasks have all completed, from pool 
17/01/29 15:07:57,365 INFO DAGScheduler: ResultStage 2 (count at GradientDescent.scala:209) finished in 0.313 s
17/01/29 15:07:57,366 INFO DAGScheduler: Job 2 finished: count at GradientDescent.scala:209, took 0.353857 s
17/01/29 15:07:57,617 WARN BLAS: Failed to load implementation from: com.github.fommil.netlib.NativeSystemBLAS
17/01/29 15:07:57,618 WARN BLAS: Failed to load implementation from: com.github.fommil.netlib.NativeRefBLAS
17/01/29 15:07:57,644 INFO MemoryStore: Block broadcast_4 stored as values in memory (estimated size 200.0 B, free 2.1 GB)
17/01/29 15:07:57,648 INFO MemoryStore: Block broadcast_4_piece0 stored as bytes in memory (estimated size 153.0 B, free 2.1 GB)
17/01/29 15:07:57,649 INFO BlockManagerInfo: Added broadcast_4_piece0 in memory on 10.1.2.152:37100 (size: 153.0 B, free: 2.1 GB)
17/01/29 15:07:57,650 INFO SparkContext: Created broadcast 4 from broadcast at GradientDescent.scala:235
17/01/29 15:07:57,708 INFO SparkContext: Starting job: treeAggregate at GradientDescent.scala:239
17/01/29 15:07:57,719 INFO DAGScheduler: Registering RDD 11 (treeAggregate at GradientDescent.scala:239)
17/01/29 15:07:57,720 INFO DAGScheduler: Got job 3 (treeAggregate at GradientDescent.scala:239) with 5 output partitions
17/01/29 15:07:57,721 INFO DAGScheduler: Final stage: ResultStage 4 (treeAggregate at GradientDescent.scala:239)
17/01/29 15:07:57,721 INFO DAGScheduler: Parents of final stage: List(ShuffleMapStage 3)
17/01/29 15:07:57,721 INFO DAGScheduler: Missing parents: List(ShuffleMapStage 3)
17/01/29 15:07:57,724 INFO DAGScheduler: Submitting ShuffleMapStage 3 (MapPartitionsRDD[11] at treeAggregate at GradientDescent.scala:239), which has no missing parents
17/01/29 15:07:57,740 INFO MemoryStore: Block broadcast_5 stored as values in memory (estimated size 7.1 KB, free 2.1 GB)
17/01/29 15:07:57,742 INFO MemoryStore: Block broadcast_5_piece0 stored as bytes in memory (estimated size 3.7 KB, free 2.1 GB)
17/01/29 15:07:57,742 INFO BlockManagerInfo: Added broadcast_5_piece0 in memory on 10.1.2.152:37100 (size: 3.7 KB, free: 2.1 GB)
17/01/29 15:07:57,743 INFO SparkContext: Created broadcast 5 from broadcast at DAGScheduler.scala:1012
17/01/29 15:07:57,745 INFO DAGScheduler: Submitting 32 missing tasks from ShuffleMapStage 3 (MapPartitionsRDD[11] at treeAggregate at GradientDescent.scala:239)
17/01/29 15:07:57,746 INFO TaskSchedulerImpl: Adding task set 3.0 with 32 tasks
17/01/29 15:07:57,750 INFO TaskSetManager: Starting task 5.0 in stage 3.0 (TID 65, 10.1.2.66, partition 5, PROCESS_LOCAL, 5562 bytes)
17/01/29 15:07:57,750 INFO TaskSetManager: Starting task 12.0 in stage 3.0 (TID 66, 10.1.2.191, partition 12, PROCESS_LOCAL, 5562 bytes)
17/01/29 15:07:57,751 INFO TaskSetManager: Starting task 1.0 in stage 3.0 (TID 67, 10.1.2.38, partition 1, PROCESS_LOCAL, 5562 bytes)
17/01/29 15:07:57,751 INFO TaskSetManager: Starting task 0.0 in stage 3.0 (TID 68, 10.1.2.65, partition 0, PROCESS_LOCAL, 5562 bytes)
17/01/29 15:07:57,752 INFO TaskSetManager: Starting task 8.0 in stage 3.0 (TID 69, 10.1.2.139, partition 8, PROCESS_LOCAL, 5562 bytes)
17/01/29 15:07:57,752 INFO TaskSetManager: Starting task 4.0 in stage 3.0 (TID 70, 10.1.2.28, partition 4, PROCESS_LOCAL, 5562 bytes)
17/01/29 15:07:57,753 INFO TaskSetManager: Starting task 10.0 in stage 3.0 (TID 71, 10.1.2.224, partition 10, PROCESS_LOCAL, 5562 bytes)
17/01/29 15:07:57,753 INFO TaskSetManager: Starting task 15.0 in stage 3.0 (TID 72, 10.1.2.176, partition 15, PROCESS_LOCAL, 5562 bytes)
17/01/29 15:07:57,754 INFO TaskSetManager: Starting task 7.0 in stage 3.0 (TID 73, 10.1.2.66, partition 7, PROCESS_LOCAL, 5562 bytes)
17/01/29 15:07:57,755 INFO TaskSetManager: Starting task 18.0 in stage 3.0 (TID 74, 10.1.2.191, partition 18, PROCESS_LOCAL, 5562 bytes)
17/01/29 15:07:57,755 INFO TaskSetManager: Starting task 2.0 in stage 3.0 (TID 75, 10.1.2.38, partition 2, PROCESS_LOCAL, 5562 bytes)
17/01/29 15:07:57,756 INFO TaskSetManager: Starting task 3.0 in stage 3.0 (TID 76, 10.1.2.65, partition 3, PROCESS_LOCAL, 5562 bytes)
17/01/29 15:07:57,756 INFO TaskSetManager: Starting task 9.0 in stage 3.0 (TID 77, 10.1.2.139, partition 9, PROCESS_LOCAL, 5562 bytes)
17/01/29 15:07:57,761 INFO TaskSetManager: Starting task 6.0 in stage 3.0 (TID 78, 10.1.2.28, partition 6, PROCESS_LOCAL, 5562 bytes)
17/01/29 15:07:57,762 INFO TaskSetManager: Starting task 11.0 in stage 3.0 (TID 79, 10.1.2.224, partition 11, PROCESS_LOCAL, 5562 bytes)
17/01/29 15:07:57,762 INFO TaskSetManager: Starting task 16.0 in stage 3.0 (TID 80, 10.1.2.176, partition 16, PROCESS_LOCAL, 5562 bytes)
17/01/29 15:07:57,763 INFO TaskSetManager: Starting task 22.0 in stage 3.0 (TID 81, 10.1.2.66, partition 22, PROCESS_LOCAL, 5562 bytes)
17/01/29 15:07:57,764 INFO TaskSetManager: Starting task 24.0 in stage 3.0 (TID 82, 10.1.2.191, partition 24, PROCESS_LOCAL, 5562 bytes)
17/01/29 15:07:57,765 INFO TaskSetManager: Starting task 17.0 in stage 3.0 (TID 83, 10.1.2.38, partition 17, PROCESS_LOCAL, 5562 bytes)
17/01/29 15:07:57,766 INFO TaskSetManager: Starting task 14.0 in stage 3.0 (TID 84, 10.1.2.65, partition 14, PROCESS_LOCAL, 5562 bytes)
17/01/29 15:07:57,767 INFO TaskSetManager: Starting task 13.0 in stage 3.0 (TID 85, 10.1.2.139, partition 13, PROCESS_LOCAL, 5562 bytes)
17/01/29 15:07:57,768 INFO TaskSetManager: Starting task 20.0 in stage 3.0 (TID 86, 10.1.2.28, partition 20, PROCESS_LOCAL, 5562 bytes)
17/01/29 15:07:57,768 INFO TaskSetManager: Starting task 26.0 in stage 3.0 (TID 87, 10.1.2.224, partition 26, PROCESS_LOCAL, 5562 bytes)
17/01/29 15:07:57,769 INFO TaskSetManager: Starting task 29.0 in stage 3.0 (TID 88, 10.1.2.176, partition 29, PROCESS_LOCAL, 5562 bytes)
17/01/29 15:07:57,770 INFO TaskSetManager: Starting task 23.0 in stage 3.0 (TID 89, 10.1.2.66, partition 23, PROCESS_LOCAL, 5562 bytes)
17/01/29 15:07:57,771 INFO TaskSetManager: Starting task 27.0 in stage 3.0 (TID 90, 10.1.2.38, partition 27, PROCESS_LOCAL, 5562 bytes)
17/01/29 15:07:57,772 INFO TaskSetManager: Starting task 19.0 in stage 3.0 (TID 91, 10.1.2.65, partition 19, PROCESS_LOCAL, 5562 bytes)
17/01/29 15:07:57,772 INFO TaskSetManager: Starting task 25.0 in stage 3.0 (TID 92, 10.1.2.139, partition 25, PROCESS_LOCAL, 5562 bytes)
17/01/29 15:07:57,773 INFO TaskSetManager: Starting task 21.0 in stage 3.0 (TID 93, 10.1.2.28, partition 21, PROCESS_LOCAL, 5562 bytes)
17/01/29 15:07:57,774 INFO TaskSetManager: Starting task 28.0 in stage 3.0 (TID 94, 10.1.2.224, partition 28, PROCESS_LOCAL, 5562 bytes)
17/01/29 15:07:57,775 INFO TaskSetManager: Starting task 30.0 in stage 3.0 (TID 95, 10.1.2.176, partition 30, PROCESS_LOCAL, 5562 bytes)
17/01/29 15:07:57,776 INFO CoarseGrainedSchedulerBackend$DriverEndpoint: Launching task 65 on executor id: 3 hostname: 10.1.2.66.
17/01/29 15:07:57,776 INFO CoarseGrainedSchedulerBackend$DriverEndpoint: Launching task 73 on executor id: 3 hostname: 10.1.2.66.
17/01/29 15:07:57,776 INFO CoarseGrainedSchedulerBackend$DriverEndpoint: Launching task 81 on executor id: 3 hostname: 10.1.2.66.
17/01/29 15:07:57,776 INFO CoarseGrainedSchedulerBackend$DriverEndpoint: Launching task 89 on executor id: 3 hostname: 10.1.2.66.
17/01/29 15:07:57,776 INFO CoarseGrainedSchedulerBackend$DriverEndpoint: Launching task 66 on executor id: 6 hostname: 10.1.2.191.
17/01/29 15:07:57,777 INFO CoarseGrainedSchedulerBackend$DriverEndpoint: Launching task 74 on executor id: 6 hostname: 10.1.2.191.
17/01/29 15:07:57,777 INFO CoarseGrainedSchedulerBackend$DriverEndpoint: Launching task 82 on executor id: 6 hostname: 10.1.2.191.
17/01/29 15:07:57,777 INFO CoarseGrainedSchedulerBackend$DriverEndpoint: Launching task 67 on executor id: 5 hostname: 10.1.2.38.
17/01/29 15:07:57,777 INFO CoarseGrainedSchedulerBackend$DriverEndpoint: Launching task 75 on executor id: 5 hostname: 10.1.2.38.
17/01/29 15:07:57,778 INFO CoarseGrainedSchedulerBackend$DriverEndpoint: Launching task 83 on executor id: 5 hostname: 10.1.2.38.
17/01/29 15:07:57,778 INFO CoarseGrainedSchedulerBackend$DriverEndpoint: Launching task 90 on executor id: 5 hostname: 10.1.2.38.
17/01/29 15:07:57,778 INFO CoarseGrainedSchedulerBackend$DriverEndpoint: Launching task 68 on executor id: 0 hostname: 10.1.2.65.
17/01/29 15:07:57,778 INFO CoarseGrainedSchedulerBackend$DriverEndpoint: Launching task 76 on executor id: 0 hostname: 10.1.2.65.
17/01/29 15:07:57,778 INFO CoarseGrainedSchedulerBackend$DriverEndpoint: Launching task 84 on executor id: 0 hostname: 10.1.2.65.
17/01/29 15:07:57,779 INFO CoarseGrainedSchedulerBackend$DriverEndpoint: Launching task 91 on executor id: 0 hostname: 10.1.2.65.
17/01/29 15:07:57,779 INFO CoarseGrainedSchedulerBackend$DriverEndpoint: Launching task 69 on executor id: 7 hostname: 10.1.2.139.
17/01/29 15:07:57,779 INFO CoarseGrainedSchedulerBackend$DriverEndpoint: Launching task 77 on executor id: 7 hostname: 10.1.2.139.
17/01/29 15:07:57,779 INFO CoarseGrainedSchedulerBackend$DriverEndpoint: Launching task 85 on executor id: 7 hostname: 10.1.2.139.
17/01/29 15:07:57,779 INFO CoarseGrainedSchedulerBackend$DriverEndpoint: Launching task 92 on executor id: 7 hostname: 10.1.2.139.
17/01/29 15:07:57,780 INFO CoarseGrainedSchedulerBackend$DriverEndpoint: Launching task 70 on executor id: 1 hostname: 10.1.2.28.
17/01/29 15:07:57,780 INFO CoarseGrainedSchedulerBackend$DriverEndpoint: Launching task 78 on executor id: 1 hostname: 10.1.2.28.
17/01/29 15:07:57,780 INFO CoarseGrainedSchedulerBackend$DriverEndpoint: Launching task 86 on executor id: 1 hostname: 10.1.2.28.
17/01/29 15:07:57,780 INFO CoarseGrainedSchedulerBackend$DriverEndpoint: Launching task 93 on executor id: 1 hostname: 10.1.2.28.
17/01/29 15:07:57,781 INFO CoarseGrainedSchedulerBackend$DriverEndpoint: Launching task 71 on executor id: 4 hostname: 10.1.2.224.
17/01/29 15:07:57,781 INFO CoarseGrainedSchedulerBackend$DriverEndpoint: Launching task 79 on executor id: 4 hostname: 10.1.2.224.
17/01/29 15:07:57,781 INFO CoarseGrainedSchedulerBackend$DriverEndpoint: Launching task 87 on executor id: 4 hostname: 10.1.2.224.
17/01/29 15:07:57,781 INFO CoarseGrainedSchedulerBackend$DriverEndpoint: Launching task 94 on executor id: 4 hostname: 10.1.2.224.
17/01/29 15:07:57,781 INFO CoarseGrainedSchedulerBackend$DriverEndpoint: Launching task 72 on executor id: 2 hostname: 10.1.2.176.
17/01/29 15:07:57,782 INFO CoarseGrainedSchedulerBackend$DriverEndpoint: Launching task 80 on executor id: 2 hostname: 10.1.2.176.
17/01/29 15:07:57,782 INFO CoarseGrainedSchedulerBackend$DriverEndpoint: Launching task 88 on executor id: 2 hostname: 10.1.2.176.
17/01/29 15:07:57,782 INFO CoarseGrainedSchedulerBackend$DriverEndpoint: Launching task 95 on executor id: 2 hostname: 10.1.2.176.
17/01/29 15:07:57,808 INFO BlockManagerInfo: Added broadcast_5_piece0 in memory on 10.1.2.38:34256 (size: 3.7 KB, free: 1942.7 MB)
17/01/29 15:07:57,809 INFO BlockManagerInfo: Added broadcast_5_piece0 in memory on 10.1.2.191:37280 (size: 3.7 KB, free: 1987.2 MB)
17/01/29 15:07:57,811 INFO BlockManagerInfo: Added broadcast_5_piece0 in memory on 10.1.2.65:40765 (size: 3.7 KB, free: 1898.5 MB)
17/01/29 15:07:57,814 INFO BlockManagerInfo: Added broadcast_5_piece0 in memory on 10.1.2.139:33712 (size: 3.7 KB, free: 1942.9 MB)
17/01/29 15:07:57,815 INFO BlockManagerInfo: Added broadcast_5_piece0 in memory on 10.1.2.66:43551 (size: 3.7 KB, free: 1943.0 MB)
17/01/29 15:07:57,815 INFO BlockManagerInfo: Added broadcast_5_piece0 in memory on 10.1.2.224:37049 (size: 3.7 KB, free: 1942.8 MB)
17/01/29 15:07:57,816 INFO BlockManagerInfo: Added broadcast_5_piece0 in memory on 10.1.2.176:35238 (size: 3.7 KB, free: 1942.8 MB)
17/01/29 15:07:57,860 INFO BlockManagerInfo: Added broadcast_5_piece0 in memory on 10.1.2.28:41859 (size: 3.7 KB, free: 1942.9 MB)
17/01/29 15:07:58,100 INFO BlockManagerInfo: Added broadcast_4_piece0 in memory on 10.1.2.65:40765 (size: 153.0 B, free: 1898.5 MB)
17/01/29 15:07:58,102 INFO BlockManagerInfo: Added broadcast_4_piece0 in memory on 10.1.2.38:34256 (size: 153.0 B, free: 1942.7 MB)
17/01/29 15:07:58,105 INFO BlockManagerInfo: Added broadcast_4_piece0 in memory on 10.1.2.191:37280 (size: 153.0 B, free: 1987.2 MB)
17/01/29 15:07:58,117 INFO BlockManagerInfo: Added broadcast_4_piece0 in memory on 10.1.2.224:37049 (size: 153.0 B, free: 1942.8 MB)
17/01/29 15:07:58,120 INFO BlockManagerInfo: Added broadcast_4_piece0 in memory on 10.1.2.66:43551 (size: 153.0 B, free: 1943.0 MB)
17/01/29 15:07:58,169 INFO BlockManagerInfo: Added broadcast_4_piece0 in memory on 10.1.2.139:33712 (size: 153.0 B, free: 1942.9 MB)
17/01/29 15:07:58,180 INFO BlockManagerInfo: Added broadcast_4_piece0 in memory on 10.1.2.176:35238 (size: 153.0 B, free: 1942.8 MB)
17/01/29 15:07:58,193 INFO BlockManagerInfo: Added broadcast_4_piece0 in memory on 10.1.2.28:41859 (size: 153.0 B, free: 1942.9 MB)
17/01/29 15:07:58,266 INFO TaskSetManager: Starting task 31.0 in stage 3.0 (TID 96, 10.1.2.65, partition 31, PROCESS_LOCAL, 5562 bytes)
17/01/29 15:07:58,266 INFO CoarseGrainedSchedulerBackend$DriverEndpoint: Launching task 96 on executor id: 0 hostname: 10.1.2.65.
17/01/29 15:07:58,268 INFO TaskSetManager: Finished task 0.0 in stage 3.0 (TID 68) in 517 ms on 10.1.2.65 (1/32)
17/01/29 15:07:58,269 INFO TaskSetManager: Finished task 3.0 in stage 3.0 (TID 76) in 513 ms on 10.1.2.65 (2/32)
17/01/29 15:07:58,270 INFO TaskSetManager: Finished task 14.0 in stage 3.0 (TID 84) in 505 ms on 10.1.2.65 (3/32)
17/01/29 15:07:58,274 INFO TaskSetManager: Finished task 19.0 in stage 3.0 (TID 91) in 502 ms on 10.1.2.65 (4/32)
17/01/29 15:07:58,276 INFO TaskSetManager: Finished task 17.0 in stage 3.0 (TID 83) in 511 ms on 10.1.2.38 (5/32)
17/01/29 15:07:58,276 INFO TaskSetManager: Finished task 27.0 in stage 3.0 (TID 90) in 506 ms on 10.1.2.38 (6/32)
17/01/29 15:07:58,279 INFO TaskSetManager: Finished task 2.0 in stage 3.0 (TID 75) in 524 ms on 10.1.2.38 (7/32)
17/01/29 15:07:58,280 INFO TaskSetManager: Finished task 18.0 in stage 3.0 (TID 74) in 525 ms on 10.1.2.191 (8/32)
17/01/29 15:07:58,280 INFO TaskSetManager: Finished task 12.0 in stage 3.0 (TID 66) in 530 ms on 10.1.2.191 (9/32)
17/01/29 15:07:58,280 INFO TaskSetManager: Finished task 1.0 in stage 3.0 (TID 67) in 530 ms on 10.1.2.38 (10/32)
17/01/29 15:07:58,281 INFO TaskSetManager: Finished task 24.0 in stage 3.0 (TID 82) in 518 ms on 10.1.2.191 (11/32)
17/01/29 15:07:58,287 INFO TaskSetManager: Finished task 10.0 in stage 3.0 (TID 71) in 535 ms on 10.1.2.224 (12/32)
17/01/29 15:07:58,288 INFO TaskSetManager: Finished task 26.0 in stage 3.0 (TID 87) in 520 ms on 10.1.2.224 (13/32)
17/01/29 15:07:58,290 INFO TaskSetManager: Finished task 11.0 in stage 3.0 (TID 79) in 528 ms on 10.1.2.224 (14/32)
17/01/29 15:07:58,291 INFO TaskSetManager: Finished task 28.0 in stage 3.0 (TID 94) in 518 ms on 10.1.2.224 (15/32)
17/01/29 15:07:58,298 INFO TaskSetManager: Finished task 5.0 in stage 3.0 (TID 65) in 551 ms on 10.1.2.66 (16/32)
17/01/29 15:07:58,299 INFO TaskSetManager: Finished task 23.0 in stage 3.0 (TID 89) in 529 ms on 10.1.2.66 (17/32)
17/01/29 15:07:58,300 INFO TaskSetManager: Finished task 22.0 in stage 3.0 (TID 81) in 537 ms on 10.1.2.66 (18/32)
17/01/29 15:07:58,302 INFO TaskSetManager: Finished task 7.0 in stage 3.0 (TID 73) in 548 ms on 10.1.2.66 (19/32)
17/01/29 15:07:58,339 INFO TaskSetManager: Finished task 31.0 in stage 3.0 (TID 96) in 74 ms on 10.1.2.65 (20/32)
17/01/29 15:07:58,341 INFO TaskSetManager: Finished task 16.0 in stage 3.0 (TID 80) in 579 ms on 10.1.2.176 (21/32)
17/01/29 15:07:58,342 INFO TaskSetManager: Finished task 30.0 in stage 3.0 (TID 95) in 568 ms on 10.1.2.176 (22/32)
17/01/29 15:07:58,343 INFO TaskSetManager: Finished task 29.0 in stage 3.0 (TID 88) in 575 ms on 10.1.2.176 (23/32)
17/01/29 15:07:58,344 INFO TaskSetManager: Finished task 15.0 in stage 3.0 (TID 72) in 590 ms on 10.1.2.176 (24/32)
17/01/29 15:07:58,345 INFO TaskSetManager: Finished task 25.0 in stage 3.0 (TID 92) in 572 ms on 10.1.2.139 (25/32)
17/01/29 15:07:58,345 INFO TaskSetManager: Finished task 9.0 in stage 3.0 (TID 77) in 589 ms on 10.1.2.139 (26/32)
17/01/29 15:07:58,346 INFO TaskSetManager: Finished task 13.0 in stage 3.0 (TID 85) in 580 ms on 10.1.2.139 (27/32)
17/01/29 15:07:58,347 INFO TaskSetManager: Finished task 8.0 in stage 3.0 (TID 69) in 596 ms on 10.1.2.139 (28/32)
17/01/29 15:07:58,361 INFO TaskSetManager: Finished task 6.0 in stage 3.0 (TID 78) in 601 ms on 10.1.2.28 (29/32)
17/01/29 15:07:58,362 INFO TaskSetManager: Finished task 20.0 in stage 3.0 (TID 86) in 594 ms on 10.1.2.28 (30/32)
17/01/29 15:07:58,362 INFO TaskSetManager: Finished task 4.0 in stage 3.0 (TID 70) in 610 ms on 10.1.2.28 (31/32)
17/01/29 15:07:58,363 INFO TaskSetManager: Finished task 21.0 in stage 3.0 (TID 93) in 591 ms on 10.1.2.28 (32/32)
17/01/29 15:07:58,363 INFO TaskSchedulerImpl: Removed TaskSet 3.0, whose tasks have all completed, from pool 
17/01/29 15:07:58,364 INFO DAGScheduler: ShuffleMapStage 3 (treeAggregate at GradientDescent.scala:239) finished in 0.608 s
17/01/29 15:07:58,365 INFO DAGScheduler: looking for newly runnable stages
17/01/29 15:07:58,365 INFO DAGScheduler: running: Set()
17/01/29 15:07:58,366 INFO DAGScheduler: waiting: Set(ResultStage 4)
17/01/29 15:07:58,366 INFO DAGScheduler: failed: Set()
17/01/29 15:07:58,368 INFO DAGScheduler: Submitting ResultStage 4 (MapPartitionsRDD[13] at treeAggregate at GradientDescent.scala:239), which has no missing parents
17/01/29 15:07:58,373 INFO MemoryStore: Block broadcast_6 stored as values in memory (estimated size 3.1 KB, free 2.1 GB)
17/01/29 15:07:58,375 INFO MemoryStore: Block broadcast_6_piece0 stored as bytes in memory (estimated size 1890.0 B, free 2.1 GB)
17/01/29 15:07:58,376 INFO BlockManagerInfo: Added broadcast_6_piece0 in memory on 10.1.2.152:37100 (size: 1890.0 B, free: 2.1 GB)
17/01/29 15:07:58,377 INFO SparkContext: Created broadcast 6 from broadcast at DAGScheduler.scala:1012
17/01/29 15:07:58,377 INFO DAGScheduler: Submitting 5 missing tasks from ResultStage 4 (MapPartitionsRDD[13] at treeAggregate at GradientDescent.scala:239)
17/01/29 15:07:58,377 INFO TaskSchedulerImpl: Adding task set 4.0 with 5 tasks
17/01/29 15:07:58,379 INFO TaskSetManager: Starting task 2.0 in stage 4.0 (TID 97, 10.1.2.66, partition 2, NODE_LOCAL, 5228 bytes)
17/01/29 15:07:58,380 INFO TaskSetManager: Starting task 1.0 in stage 4.0 (TID 98, 10.1.2.224, partition 1, NODE_LOCAL, 5228 bytes)
17/01/29 15:07:58,381 INFO TaskSetManager: Starting task 4.0 in stage 4.0 (TID 99, 10.1.2.65, partition 4, NODE_LOCAL, 5228 bytes)
17/01/29 15:07:58,381 INFO TaskSetManager: Starting task 0.0 in stage 4.0 (TID 100, 10.1.2.176, partition 0, NODE_LOCAL, 5228 bytes)
17/01/29 15:07:58,382 INFO TaskSetManager: Starting task 3.0 in stage 4.0 (TID 101, 10.1.2.139, partition 3, NODE_LOCAL, 5228 bytes)
17/01/29 15:07:58,382 INFO CoarseGrainedSchedulerBackend$DriverEndpoint: Launching task 97 on executor id: 3 hostname: 10.1.2.66.
17/01/29 15:07:58,383 INFO CoarseGrainedSchedulerBackend$DriverEndpoint: Launching task 98 on executor id: 4 hostname: 10.1.2.224.
17/01/29 15:07:58,383 INFO CoarseGrainedSchedulerBackend$DriverEndpoint: Launching task 99 on executor id: 0 hostname: 10.1.2.65.
17/01/29 15:07:58,383 INFO CoarseGrainedSchedulerBackend$DriverEndpoint: Launching task 100 on executor id: 2 hostname: 10.1.2.176.
17/01/29 15:07:58,383 INFO CoarseGrainedSchedulerBackend$DriverEndpoint: Launching task 101 on executor id: 7 hostname: 10.1.2.139.
17/01/29 15:07:58,398 INFO BlockManagerInfo: Added broadcast_6_piece0 in memory on 10.1.2.66:43551 (size: 1890.0 B, free: 1943.0 MB)
17/01/29 15:07:58,399 INFO BlockManagerInfo: Added broadcast_6_piece0 in memory on 10.1.2.65:40765 (size: 1890.0 B, free: 1898.5 MB)
17/01/29 15:07:58,400 INFO BlockManagerInfo: Added broadcast_6_piece0 in memory on 10.1.2.176:35238 (size: 1890.0 B, free: 1942.8 MB)
17/01/29 15:07:58,402 INFO BlockManagerInfo: Added broadcast_6_piece0 in memory on 10.1.2.139:33712 (size: 1890.0 B, free: 1942.9 MB)
17/01/29 15:07:58,415 INFO MapOutputTrackerMasterEndpoint: Asked to send map output locations for shuffle 0 to 10.1.2.66:50926
17/01/29 15:07:58,415 INFO MapOutputTrackerMasterEndpoint: Asked to send map output locations for shuffle 0 to 10.1.2.65:44914
17/01/29 15:07:58,418 INFO MapOutputTrackerMasterEndpoint: Asked to send map output locations for shuffle 0 to 10.1.2.176:36584
17/01/29 15:07:58,421 INFO MapOutputTrackerMaster: Size of output statuses for shuffle 0 is 333 bytes
17/01/29 15:07:58,421 INFO MapOutputTrackerMasterEndpoint: Asked to send map output locations for shuffle 0 to 10.1.2.139:36836
17/01/29 15:07:58,433 INFO BlockManagerInfo: Added broadcast_6_piece0 in memory on 10.1.2.224:37049 (size: 1890.0 B, free: 1942.8 MB)
17/01/29 15:07:58,453 INFO MapOutputTrackerMasterEndpoint: Asked to send map output locations for shuffle 0 to 10.1.2.224:60234
17/01/29 15:07:58,492 INFO TaskSetManager: Finished task 2.0 in stage 4.0 (TID 97) in 113 ms on 10.1.2.66 (1/5)
17/01/29 15:07:58,495 INFO TaskSetManager: Finished task 4.0 in stage 4.0 (TID 99) in 115 ms on 10.1.2.65 (2/5)
17/01/29 15:07:58,496 INFO TaskSetManager: Finished task 3.0 in stage 4.0 (TID 101) in 115 ms on 10.1.2.139 (3/5)
17/01/29 15:07:58,507 INFO TaskSetManager: Finished task 0.0 in stage 4.0 (TID 100) in 126 ms on 10.1.2.176 (4/5)
17/01/29 15:07:58,520 INFO TaskSetManager: Finished task 1.0 in stage 4.0 (TID 98) in 139 ms on 10.1.2.224 (5/5)
17/01/29 15:07:58,520 INFO TaskSchedulerImpl: Removed TaskSet 4.0, whose tasks have all completed, from pool 
17/01/29 15:07:58,520 INFO DAGScheduler: ResultStage 4 (treeAggregate at GradientDescent.scala:239) finished in 0.140 s
17/01/29 15:07:58,521 INFO DAGScheduler: Job 3 finished: treeAggregate at GradientDescent.scala:239, took 0.811854 s
17/01/29 15:07:58,523 INFO MemoryStore: Block broadcast_7 stored as values in memory (estimated size 200.0 B, free 2.1 GB)
17/01/29 15:07:58,525 INFO MemoryStore: Block broadcast_7_piece0 stored as bytes in memory (estimated size 285.0 B, free 2.1 GB)
17/01/29 15:07:58,526 INFO BlockManagerInfo: Added broadcast_7_piece0 in memory on 10.1.2.152:37100 (size: 285.0 B, free: 2.1 GB)
17/01/29 15:07:58,527 INFO SparkContext: Created broadcast 7 from broadcast at GradientDescent.scala:235
17/01/29 15:07:58,545 INFO SparkContext: Starting job: treeAggregate at GradientDescent.scala:239
17/01/29 15:07:58,546 INFO DAGScheduler: Registering RDD 16 (treeAggregate at GradientDescent.scala:239)
17/01/29 15:07:58,547 INFO DAGScheduler: Got job 4 (treeAggregate at GradientDescent.scala:239) with 5 output partitions
17/01/29 15:07:58,547 INFO DAGScheduler: Final stage: ResultStage 6 (treeAggregate at GradientDescent.scala:239)
17/01/29 15:07:58,547 INFO DAGScheduler: Parents of final stage: List(ShuffleMapStage 5)
17/01/29 15:07:58,547 INFO DAGScheduler: Missing parents: List(ShuffleMapStage 5)
17/01/29 15:07:58,549 INFO DAGScheduler: Submitting ShuffleMapStage 5 (MapPartitionsRDD[16] at treeAggregate at GradientDescent.scala:239), which has no missing parents
17/01/29 15:07:58,555 INFO MemoryStore: Block broadcast_8 stored as values in memory (estimated size 7.1 KB, free 2.1 GB)
17/01/29 15:07:58,557 INFO MemoryStore: Block broadcast_8_piece0 stored as bytes in memory (estimated size 3.7 KB, free 2.1 GB)
17/01/29 15:07:58,558 INFO BlockManagerInfo: Added broadcast_8_piece0 in memory on 10.1.2.152:37100 (size: 3.7 KB, free: 2.1 GB)
17/01/29 15:07:58,558 INFO SparkContext: Created broadcast 8 from broadcast at DAGScheduler.scala:1012
17/01/29 15:07:58,559 INFO DAGScheduler: Submitting 32 missing tasks from ShuffleMapStage 5 (MapPartitionsRDD[16] at treeAggregate at GradientDescent.scala:239)
17/01/29 15:07:58,560 INFO TaskSchedulerImpl: Adding task set 5.0 with 32 tasks
17/01/29 15:07:58,562 INFO TaskSetManager: Starting task 0.0 in stage 5.0 (TID 102, 10.1.2.65, partition 0, PROCESS_LOCAL, 5562 bytes)
17/01/29 15:07:58,562 INFO TaskSetManager: Starting task 1.0 in stage 5.0 (TID 103, 10.1.2.38, partition 1, PROCESS_LOCAL, 5562 bytes)
17/01/29 15:07:58,563 INFO TaskSetManager: Starting task 5.0 in stage 5.0 (TID 104, 10.1.2.66, partition 5, PROCESS_LOCAL, 5562 bytes)
17/01/29 15:07:58,563 INFO TaskSetManager: Starting task 8.0 in stage 5.0 (TID 105, 10.1.2.139, partition 8, PROCESS_LOCAL, 5562 bytes)
17/01/29 15:07:58,564 INFO TaskSetManager: Starting task 10.0 in stage 5.0 (TID 106, 10.1.2.224, partition 10, PROCESS_LOCAL, 5562 bytes)
17/01/29 15:07:58,564 INFO TaskSetManager: Starting task 12.0 in stage 5.0 (TID 107, 10.1.2.191, partition 12, PROCESS_LOCAL, 5562 bytes)
17/01/29 15:07:58,565 INFO TaskSetManager: Starting task 4.0 in stage 5.0 (TID 108, 10.1.2.28, partition 4, PROCESS_LOCAL, 5562 bytes)
17/01/29 15:07:58,565 INFO TaskSetManager: Starting task 15.0 in stage 5.0 (TID 109, 10.1.2.176, partition 15, PROCESS_LOCAL, 5562 bytes)
17/01/29 15:07:58,566 INFO TaskSetManager: Starting task 3.0 in stage 5.0 (TID 110, 10.1.2.65, partition 3, PROCESS_LOCAL, 5562 bytes)
17/01/29 15:07:58,566 INFO TaskSetManager: Starting task 2.0 in stage 5.0 (TID 111, 10.1.2.38, partition 2, PROCESS_LOCAL, 5562 bytes)
17/01/29 15:07:58,567 INFO TaskSetManager: Starting task 7.0 in stage 5.0 (TID 112, 10.1.2.66, partition 7, PROCESS_LOCAL, 5562 bytes)
17/01/29 15:07:58,567 INFO TaskSetManager: Starting task 9.0 in stage 5.0 (TID 113, 10.1.2.139, partition 9, PROCESS_LOCAL, 5562 bytes)
17/01/29 15:07:58,568 INFO TaskSetManager: Starting task 11.0 in stage 5.0 (TID 114, 10.1.2.224, partition 11, PROCESS_LOCAL, 5562 bytes)
17/01/29 15:07:58,568 INFO TaskSetManager: Starting task 18.0 in stage 5.0 (TID 115, 10.1.2.191, partition 18, PROCESS_LOCAL, 5562 bytes)
17/01/29 15:07:58,569 INFO TaskSetManager: Starting task 6.0 in stage 5.0 (TID 116, 10.1.2.28, partition 6, PROCESS_LOCAL, 5562 bytes)
17/01/29 15:07:58,569 INFO TaskSetManager: Starting task 16.0 in stage 5.0 (TID 117, 10.1.2.176, partition 16, PROCESS_LOCAL, 5562 bytes)
17/01/29 15:07:58,570 INFO TaskSetManager: Starting task 14.0 in stage 5.0 (TID 118, 10.1.2.65, partition 14, PROCESS_LOCAL, 5562 bytes)
17/01/29 15:07:58,570 INFO TaskSetManager: Starting task 17.0 in stage 5.0 (TID 119, 10.1.2.38, partition 17, PROCESS_LOCAL, 5562 bytes)
17/01/29 15:07:58,571 INFO TaskSetManager: Starting task 22.0 in stage 5.0 (TID 120, 10.1.2.66, partition 22, PROCESS_LOCAL, 5562 bytes)
17/01/29 15:07:58,571 INFO TaskSetManager: Starting task 13.0 in stage 5.0 (TID 121, 10.1.2.139, partition 13, PROCESS_LOCAL, 5562 bytes)
17/01/29 15:07:58,572 INFO TaskSetManager: Starting task 26.0 in stage 5.0 (TID 122, 10.1.2.224, partition 26, PROCESS_LOCAL, 5562 bytes)
17/01/29 15:07:58,573 INFO TaskSetManager: Starting task 24.0 in stage 5.0 (TID 123, 10.1.2.191, partition 24, PROCESS_LOCAL, 5562 bytes)
17/01/29 15:07:58,573 INFO TaskSetManager: Starting task 20.0 in stage 5.0 (TID 124, 10.1.2.28, partition 20, PROCESS_LOCAL, 5562 bytes)
17/01/29 15:07:58,573 INFO TaskSetManager: Starting task 29.0 in stage 5.0 (TID 125, 10.1.2.176, partition 29, PROCESS_LOCAL, 5562 bytes)
17/01/29 15:07:58,574 INFO TaskSetManager: Starting task 19.0 in stage 5.0 (TID 126, 10.1.2.65, partition 19, PROCESS_LOCAL, 5562 bytes)
17/01/29 15:07:58,574 INFO TaskSetManager: Starting task 27.0 in stage 5.0 (TID 127, 10.1.2.38, partition 27, PROCESS_LOCAL, 5562 bytes)
17/01/29 15:07:58,575 INFO TaskSetManager: Starting task 23.0 in stage 5.0 (TID 128, 10.1.2.66, partition 23, PROCESS_LOCAL, 5562 bytes)
17/01/29 15:07:58,575 INFO TaskSetManager: Starting task 25.0 in stage 5.0 (TID 129, 10.1.2.139, partition 25, PROCESS_LOCAL, 5562 bytes)
17/01/29 15:07:58,576 INFO TaskSetManager: Starting task 28.0 in stage 5.0 (TID 130, 10.1.2.224, partition 28, PROCESS_LOCAL, 5562 bytes)
17/01/29 15:07:58,576 INFO TaskSetManager: Starting task 21.0 in stage 5.0 (TID 131, 10.1.2.28, partition 21, PROCESS_LOCAL, 5562 bytes)
17/01/29 15:07:58,576 INFO TaskSetManager: Starting task 30.0 in stage 5.0 (TID 132, 10.1.2.176, partition 30, PROCESS_LOCAL, 5562 bytes)
17/01/29 15:07:58,577 INFO CoarseGrainedSchedulerBackend$DriverEndpoint: Launching task 102 on executor id: 0 hostname: 10.1.2.65.
17/01/29 15:07:58,578 INFO CoarseGrainedSchedulerBackend$DriverEndpoint: Launching task 110 on executor id: 0 hostname: 10.1.2.65.
17/01/29 15:07:58,578 INFO CoarseGrainedSchedulerBackend$DriverEndpoint: Launching task 118 on executor id: 0 hostname: 10.1.2.65.
17/01/29 15:07:58,579 INFO CoarseGrainedSchedulerBackend$DriverEndpoint: Launching task 126 on executor id: 0 hostname: 10.1.2.65.
17/01/29 15:07:58,579 INFO CoarseGrainedSchedulerBackend$DriverEndpoint: Launching task 103 on executor id: 5 hostname: 10.1.2.38.
17/01/29 15:07:58,579 INFO CoarseGrainedSchedulerBackend$DriverEndpoint: Launching task 111 on executor id: 5 hostname: 10.1.2.38.
17/01/29 15:07:58,579 INFO CoarseGrainedSchedulerBackend$DriverEndpoint: Launching task 119 on executor id: 5 hostname: 10.1.2.38.
17/01/29 15:07:58,580 INFO CoarseGrainedSchedulerBackend$DriverEndpoint: Launching task 127 on executor id: 5 hostname: 10.1.2.38.
17/01/29 15:07:58,580 INFO CoarseGrainedSchedulerBackend$DriverEndpoint: Launching task 104 on executor id: 3 hostname: 10.1.2.66.
17/01/29 15:07:58,580 INFO CoarseGrainedSchedulerBackend$DriverEndpoint: Launching task 112 on executor id: 3 hostname: 10.1.2.66.
17/01/29 15:07:58,581 INFO CoarseGrainedSchedulerBackend$DriverEndpoint: Launching task 120 on executor id: 3 hostname: 10.1.2.66.
17/01/29 15:07:58,581 INFO CoarseGrainedSchedulerBackend$DriverEndpoint: Launching task 128 on executor id: 3 hostname: 10.1.2.66.
17/01/29 15:07:58,582 INFO CoarseGrainedSchedulerBackend$DriverEndpoint: Launching task 105 on executor id: 7 hostname: 10.1.2.139.
17/01/29 15:07:58,582 INFO CoarseGrainedSchedulerBackend$DriverEndpoint: Launching task 113 on executor id: 7 hostname: 10.1.2.139.
17/01/29 15:07:58,582 INFO CoarseGrainedSchedulerBackend$DriverEndpoint: Launching task 121 on executor id: 7 hostname: 10.1.2.139.
17/01/29 15:07:58,582 INFO CoarseGrainedSchedulerBackend$DriverEndpoint: Launching task 129 on executor id: 7 hostname: 10.1.2.139.
17/01/29 15:07:58,583 INFO CoarseGrainedSchedulerBackend$DriverEndpoint: Launching task 106 on executor id: 4 hostname: 10.1.2.224.
17/01/29 15:07:58,583 INFO CoarseGrainedSchedulerBackend$DriverEndpoint: Launching task 114 on executor id: 4 hostname: 10.1.2.224.
17/01/29 15:07:58,584 INFO CoarseGrainedSchedulerBackend$DriverEndpoint: Launching task 122 on executor id: 4 hostname: 10.1.2.224.
17/01/29 15:07:58,584 INFO CoarseGrainedSchedulerBackend$DriverEndpoint: Launching task 130 on executor id: 4 hostname: 10.1.2.224.
17/01/29 15:07:58,584 INFO CoarseGrainedSchedulerBackend$DriverEndpoint: Launching task 107 on executor id: 6 hostname: 10.1.2.191.
17/01/29 15:07:58,585 INFO CoarseGrainedSchedulerBackend$DriverEndpoint: Launching task 115 on executor id: 6 hostname: 10.1.2.191.
17/01/29 15:07:58,587 INFO CoarseGrainedSchedulerBackend$DriverEndpoint: Launching task 123 on executor id: 6 hostname: 10.1.2.191.
17/01/29 15:07:58,591 INFO CoarseGrainedSchedulerBackend$DriverEndpoint: Launching task 108 on executor id: 1 hostname: 10.1.2.28.
17/01/29 15:07:58,591 INFO CoarseGrainedSchedulerBackend$DriverEndpoint: Launching task 116 on executor id: 1 hostname: 10.1.2.28.
17/01/29 15:07:58,592 INFO CoarseGrainedSchedulerBackend$DriverEndpoint: Launching task 124 on executor id: 1 hostname: 10.1.2.28.
17/01/29 15:07:58,592 INFO CoarseGrainedSchedulerBackend$DriverEndpoint: Launching task 131 on executor id: 1 hostname: 10.1.2.28.
17/01/29 15:07:58,592 INFO CoarseGrainedSchedulerBackend$DriverEndpoint: Launching task 109 on executor id: 2 hostname: 10.1.2.176.
17/01/29 15:07:58,592 INFO CoarseGrainedSchedulerBackend$DriverEndpoint: Launching task 117 on executor id: 2 hostname: 10.1.2.176.
17/01/29 15:07:58,593 INFO CoarseGrainedSchedulerBackend$DriverEndpoint: Launching task 125 on executor id: 2 hostname: 10.1.2.176.
17/01/29 15:07:58,593 INFO CoarseGrainedSchedulerBackend$DriverEndpoint: Launching task 132 on executor id: 2 hostname: 10.1.2.176.
17/01/29 15:07:58,598 INFO BlockManagerInfo: Added broadcast_8_piece0 in memory on 10.1.2.65:40765 (size: 3.7 KB, free: 1898.5 MB)
17/01/29 15:07:58,600 INFO BlockManagerInfo: Added broadcast_8_piece0 in memory on 10.1.2.66:43551 (size: 3.7 KB, free: 1943.0 MB)
17/01/29 15:07:58,602 INFO BlockManagerInfo: Added broadcast_8_piece0 in memory on 10.1.2.224:37049 (size: 3.7 KB, free: 1942.8 MB)
17/01/29 15:07:58,605 INFO BlockManagerInfo: Added broadcast_8_piece0 in memory on 10.1.2.38:34256 (size: 3.7 KB, free: 1942.7 MB)
17/01/29 15:07:58,605 INFO BlockManagerInfo: Added broadcast_8_piece0 in memory on 10.1.2.139:33712 (size: 3.7 KB, free: 1942.9 MB)
17/01/29 15:07:58,606 INFO BlockManagerInfo: Added broadcast_8_piece0 in memory on 10.1.2.191:37280 (size: 3.7 KB, free: 1987.2 MB)
17/01/29 15:07:58,612 INFO BlockManagerInfo: Added broadcast_8_piece0 in memory on 10.1.2.176:35238 (size: 3.7 KB, free: 1942.8 MB)
17/01/29 15:07:58,618 INFO BlockManagerInfo: Added broadcast_7_piece0 in memory on 10.1.2.65:40765 (size: 285.0 B, free: 1898.5 MB)
17/01/29 15:07:58,619 INFO BlockManagerInfo: Added broadcast_7_piece0 in memory on 10.1.2.224:37049 (size: 285.0 B, free: 1942.8 MB)
17/01/29 15:07:58,620 INFO BlockManagerInfo: Added broadcast_7_piece0 in memory on 10.1.2.66:43551 (size: 285.0 B, free: 1943.0 MB)
17/01/29 15:07:58,622 INFO BlockManagerInfo: Added broadcast_8_piece0 in memory on 10.1.2.28:41859 (size: 3.7 KB, free: 1942.9 MB)
17/01/29 15:07:58,624 INFO BlockManagerInfo: Added broadcast_7_piece0 in memory on 10.1.2.139:33712 (size: 285.0 B, free: 1942.9 MB)
17/01/29 15:07:58,625 INFO BlockManagerInfo: Added broadcast_7_piece0 in memory on 10.1.2.38:34256 (size: 285.0 B, free: 1942.7 MB)
17/01/29 15:07:58,627 INFO BlockManagerInfo: Added broadcast_7_piece0 in memory on 10.1.2.191:37280 (size: 285.0 B, free: 1987.2 MB)
17/01/29 15:07:58,632 INFO BlockManagerInfo: Added broadcast_7_piece0 in memory on 10.1.2.176:35238 (size: 285.0 B, free: 1942.8 MB)
17/01/29 15:07:58,641 INFO BlockManagerInfo: Added broadcast_7_piece0 in memory on 10.1.2.28:41859 (size: 285.0 B, free: 1942.9 MB)
17/01/29 15:07:58,693 INFO TaskSetManager: Starting task 31.0 in stage 5.0 (TID 133, 10.1.2.65, partition 31, PROCESS_LOCAL, 5562 bytes)
17/01/29 15:07:58,693 INFO CoarseGrainedSchedulerBackend$DriverEndpoint: Launching task 133 on executor id: 0 hostname: 10.1.2.65.
17/01/29 15:07:58,694 INFO TaskSetManager: Finished task 19.0 in stage 5.0 (TID 126) in 120 ms on 10.1.2.65 (1/32)
17/01/29 15:07:58,711 INFO TaskSetManager: Finished task 20.0 in stage 5.0 (TID 124) in 138 ms on 10.1.2.28 (2/32)
17/01/29 15:07:58,718 INFO TaskSetManager: Finished task 6.0 in stage 5.0 (TID 116) in 150 ms on 10.1.2.28 (3/32)
17/01/29 15:07:58,722 INFO TaskSetManager: Finished task 21.0 in stage 5.0 (TID 131) in 145 ms on 10.1.2.28 (4/32)
17/01/29 15:07:58,730 INFO TaskSetManager: Finished task 7.0 in stage 5.0 (TID 112) in 164 ms on 10.1.2.66 (5/32)
17/01/29 15:07:58,734 INFO TaskSetManager: Finished task 22.0 in stage 5.0 (TID 120) in 164 ms on 10.1.2.66 (6/32)
17/01/29 15:07:58,734 INFO TaskSetManager: Finished task 4.0 in stage 5.0 (TID 108) in 169 ms on 10.1.2.28 (7/32)
17/01/29 15:07:58,735 INFO TaskSetManager: Finished task 12.0 in stage 5.0 (TID 107) in 171 ms on 10.1.2.191 (8/32)
17/01/29 15:07:58,735 INFO TaskSetManager: Finished task 5.0 in stage 5.0 (TID 104) in 172 ms on 10.1.2.66 (9/32)
17/01/29 15:07:58,737 INFO TaskSetManager: Finished task 13.0 in stage 5.0 (TID 121) in 166 ms on 10.1.2.139 (10/32)
17/01/29 15:07:58,738 INFO TaskSetManager: Finished task 18.0 in stage 5.0 (TID 115) in 169 ms on 10.1.2.191 (11/32)
17/01/29 15:07:58,738 INFO TaskSetManager: Finished task 23.0 in stage 5.0 (TID 128) in 164 ms on 10.1.2.66 (12/32)
17/01/29 15:07:58,740 INFO TaskSetManager: Finished task 9.0 in stage 5.0 (TID 113) in 173 ms on 10.1.2.139 (13/32)
17/01/29 15:07:58,741 INFO TaskSetManager: Finished task 24.0 in stage 5.0 (TID 123) in 169 ms on 10.1.2.191 (14/32)
17/01/29 15:07:58,742 INFO TaskSetManager: Finished task 16.0 in stage 5.0 (TID 117) in 173 ms on 10.1.2.176 (15/32)
17/01/29 15:07:58,743 INFO TaskSetManager: Finished task 8.0 in stage 5.0 (TID 105) in 180 ms on 10.1.2.139 (16/32)
17/01/29 15:07:58,743 INFO TaskSetManager: Finished task 15.0 in stage 5.0 (TID 109) in 178 ms on 10.1.2.176 (17/32)
17/01/29 15:07:58,745 INFO TaskSetManager: Finished task 25.0 in stage 5.0 (TID 129) in 170 ms on 10.1.2.139 (18/32)
17/01/29 15:07:58,746 INFO TaskSetManager: Finished task 3.0 in stage 5.0 (TID 110) in 179 ms on 10.1.2.65 (19/32)
17/01/29 15:07:58,747 INFO TaskSetManager: Finished task 0.0 in stage 5.0 (TID 102) in 185 ms on 10.1.2.65 (20/32)
17/01/29 15:07:58,748 INFO TaskSetManager: Finished task 30.0 in stage 5.0 (TID 132) in 171 ms on 10.1.2.176 (21/32)
17/01/29 15:07:58,749 INFO TaskSetManager: Finished task 14.0 in stage 5.0 (TID 118) in 180 ms on 10.1.2.65 (22/32)
17/01/29 15:07:58,751 INFO TaskSetManager: Finished task 29.0 in stage 5.0 (TID 125) in 178 ms on 10.1.2.176 (23/32)
17/01/29 15:07:58,792 INFO TaskSetManager: Finished task 31.0 in stage 5.0 (TID 133) in 99 ms on 10.1.2.65 (24/32)
17/01/29 15:07:58,802 INFO TaskSetManager: Finished task 1.0 in stage 5.0 (TID 103) in 240 ms on 10.1.2.38 (25/32)
17/01/29 15:07:58,803 INFO TaskSetManager: Finished task 2.0 in stage 5.0 (TID 111) in 237 ms on 10.1.2.38 (26/32)
17/01/29 15:07:58,818 INFO TaskSetManager: Finished task 27.0 in stage 5.0 (TID 127) in 244 ms on 10.1.2.38 (27/32)
17/01/29 15:07:58,818 INFO TaskSetManager: Finished task 17.0 in stage 5.0 (TID 119) in 248 ms on 10.1.2.38 (28/32)
17/01/29 15:07:58,828 INFO TaskSetManager: Finished task 28.0 in stage 5.0 (TID 130) in 253 ms on 10.1.2.224 (29/32)
17/01/29 15:07:58,830 INFO TaskSetManager: Finished task 10.0 in stage 5.0 (TID 106) in 266 ms on 10.1.2.224 (30/32)
17/01/29 15:07:58,834 INFO TaskSetManager: Finished task 11.0 in stage 5.0 (TID 114) in 267 ms on 10.1.2.224 (31/32)
17/01/29 15:07:58,837 INFO TaskSetManager: Finished task 26.0 in stage 5.0 (TID 122) in 266 ms on 10.1.2.224 (32/32)
17/01/29 15:07:58,838 INFO TaskSchedulerImpl: Removed TaskSet 5.0, whose tasks have all completed, from pool 
17/01/29 15:07:58,838 INFO DAGScheduler: ShuffleMapStage 5 (treeAggregate at GradientDescent.scala:239) finished in 0.277 s
17/01/29 15:07:58,838 INFO DAGScheduler: looking for newly runnable stages
17/01/29 15:07:58,838 INFO DAGScheduler: running: Set()
17/01/29 15:07:58,838 INFO DAGScheduler: waiting: Set(ResultStage 6)
17/01/29 15:07:58,838 INFO DAGScheduler: failed: Set()
17/01/29 15:07:58,839 INFO DAGScheduler: Submitting ResultStage 6 (MapPartitionsRDD[18] at treeAggregate at GradientDescent.scala:239), which has no missing parents
17/01/29 15:07:58,841 INFO MemoryStore: Block broadcast_9 stored as values in memory (estimated size 3.1 KB, free 2.1 GB)
17/01/29 15:07:58,843 INFO MemoryStore: Block broadcast_9_piece0 stored as bytes in memory (estimated size 1889.0 B, free 2.1 GB)
17/01/29 15:07:58,844 INFO BlockManagerInfo: Added broadcast_9_piece0 in memory on 10.1.2.152:37100 (size: 1889.0 B, free: 2.1 GB)
17/01/29 15:07:58,845 INFO SparkContext: Created broadcast 9 from broadcast at DAGScheduler.scala:1012
17/01/29 15:07:58,845 INFO DAGScheduler: Submitting 5 missing tasks from ResultStage 6 (MapPartitionsRDD[18] at treeAggregate at GradientDescent.scala:239)
17/01/29 15:07:58,845 INFO TaskSchedulerImpl: Adding task set 6.0 with 5 tasks
17/01/29 15:07:58,847 INFO TaskSetManager: Starting task 0.0 in stage 6.0 (TID 134, 10.1.2.176, partition 0, NODE_LOCAL, 5228 bytes)
17/01/29 15:07:58,847 INFO TaskSetManager: Starting task 1.0 in stage 6.0 (TID 135, 10.1.2.28, partition 1, NODE_LOCAL, 5228 bytes)
17/01/29 15:07:58,848 INFO TaskSetManager: Starting task 2.0 in stage 6.0 (TID 136, 10.1.2.38, partition 2, NODE_LOCAL, 5228 bytes)
17/01/29 15:07:58,848 INFO TaskSetManager: Starting task 4.0 in stage 6.0 (TID 137, 10.1.2.65, partition 4, NODE_LOCAL, 5228 bytes)
17/01/29 15:07:58,849 INFO TaskSetManager: Starting task 3.0 in stage 6.0 (TID 138, 10.1.2.139, partition 3, NODE_LOCAL, 5228 bytes)
17/01/29 15:07:58,849 INFO CoarseGrainedSchedulerBackend$DriverEndpoint: Launching task 134 on executor id: 2 hostname: 10.1.2.176.
17/01/29 15:07:58,850 INFO CoarseGrainedSchedulerBackend$DriverEndpoint: Launching task 135 on executor id: 1 hostname: 10.1.2.28.
17/01/29 15:07:58,850 INFO CoarseGrainedSchedulerBackend$DriverEndpoint: Launching task 136 on executor id: 5 hostname: 10.1.2.38.
17/01/29 15:07:58,851 INFO CoarseGrainedSchedulerBackend$DriverEndpoint: Launching task 137 on executor id: 0 hostname: 10.1.2.65.
17/01/29 15:07:58,851 INFO CoarseGrainedSchedulerBackend$DriverEndpoint: Launching task 138 on executor id: 7 hostname: 10.1.2.139.
17/01/29 15:07:58,865 INFO BlockManagerInfo: Added broadcast_9_piece0 in memory on 10.1.2.65:40765 (size: 1889.0 B, free: 1898.5 MB)
17/01/29 15:07:58,867 INFO BlockManagerInfo: Added broadcast_9_piece0 in memory on 10.1.2.38:34256 (size: 1889.0 B, free: 1942.7 MB)
17/01/29 15:07:58,868 INFO BlockManagerInfo: Added broadcast_9_piece0 in memory on 10.1.2.28:41859 (size: 1889.0 B, free: 1942.9 MB)
17/01/29 15:07:58,868 INFO BlockManagerInfo: Added broadcast_9_piece0 in memory on 10.1.2.139:33712 (size: 1889.0 B, free: 1942.9 MB)
17/01/29 15:07:58,869 INFO BlockManagerInfo: Added broadcast_9_piece0 in memory on 10.1.2.176:35238 (size: 1889.0 B, free: 1942.8 MB)
17/01/29 15:07:58,871 INFO MapOutputTrackerMasterEndpoint: Asked to send map output locations for shuffle 1 to 10.1.2.65:44914
17/01/29 15:07:58,872 INFO MapOutputTrackerMaster: Size of output statuses for shuffle 1 is 333 bytes
17/01/29 15:07:58,875 INFO MapOutputTrackerMasterEndpoint: Asked to send map output locations for shuffle 1 to 10.1.2.139:36836
17/01/29 15:07:58,875 INFO MapOutputTrackerMasterEndpoint: Asked to send map output locations for shuffle 1 to 10.1.2.176:36584
17/01/29 15:07:58,883 INFO MapOutputTrackerMasterEndpoint: Asked to send map output locations for shuffle 1 to 10.1.2.38:54406
17/01/29 15:07:58,884 INFO MapOutputTrackerMasterEndpoint: Asked to send map output locations for shuffle 1 to 10.1.2.28:48890
17/01/29 15:07:58,890 INFO TaskSetManager: Finished task 4.0 in stage 6.0 (TID 137) in 42 ms on 10.1.2.65 (1/5)
17/01/29 15:07:58,896 INFO TaskSetManager: Finished task 3.0 in stage 6.0 (TID 138) in 48 ms on 10.1.2.139 (2/5)
17/01/29 15:07:58,899 INFO TaskSetManager: Finished task 0.0 in stage 6.0 (TID 134) in 53 ms on 10.1.2.176 (3/5)
17/01/29 15:07:58,927 INFO TaskSetManager: Finished task 2.0 in stage 6.0 (TID 136) in 80 ms on 10.1.2.38 (4/5)
17/01/29 15:07:58,938 INFO TaskSetManager: Finished task 1.0 in stage 6.0 (TID 135) in 91 ms on 10.1.2.28 (5/5)
17/01/29 15:07:58,938 INFO TaskSchedulerImpl: Removed TaskSet 6.0, whose tasks have all completed, from pool 
17/01/29 15:07:58,938 INFO DAGScheduler: ResultStage 6 (treeAggregate at GradientDescent.scala:239) finished in 0.092 s
17/01/29 15:07:58,939 INFO DAGScheduler: Job 4 finished: treeAggregate at GradientDescent.scala:239, took 0.394131 s
17/01/29 15:07:58,947 INFO MemoryStore: Block broadcast_10 stored as values in memory (estimated size 200.0 B, free 2.1 GB)
17/01/29 15:07:58,948 INFO MemoryStore: Block broadcast_10_piece0 stored as bytes in memory (estimated size 285.0 B, free 2.1 GB)
17/01/29 15:07:58,949 INFO BlockManagerInfo: Added broadcast_10_piece0 in memory on 10.1.2.152:37100 (size: 285.0 B, free: 2.1 GB)
17/01/29 15:07:58,950 INFO SparkContext: Created broadcast 10 from broadcast at GradientDescent.scala:235
17/01/29 15:07:58,968 INFO SparkContext: Starting job: treeAggregate at GradientDescent.scala:239
17/01/29 15:07:58,969 INFO DAGScheduler: Registering RDD 21 (treeAggregate at GradientDescent.scala:239)
17/01/29 15:07:58,970 INFO DAGScheduler: Got job 5 (treeAggregate at GradientDescent.scala:239) with 5 output partitions
17/01/29 15:07:58,970 INFO DAGScheduler: Final stage: ResultStage 8 (treeAggregate at GradientDescent.scala:239)
17/01/29 15:07:58,970 INFO DAGScheduler: Parents of final stage: List(ShuffleMapStage 7)
17/01/29 15:07:58,970 INFO DAGScheduler: Missing parents: List(ShuffleMapStage 7)
17/01/29 15:07:58,972 INFO DAGScheduler: Submitting ShuffleMapStage 7 (MapPartitionsRDD[21] at treeAggregate at GradientDescent.scala:239), which has no missing parents
17/01/29 15:07:58,978 INFO MemoryStore: Block broadcast_11 stored as values in memory (estimated size 7.1 KB, free 2.1 GB)
17/01/29 15:07:58,979 INFO MemoryStore: Block broadcast_11_piece0 stored as bytes in memory (estimated size 3.7 KB, free 2.1 GB)
17/01/29 15:07:58,980 INFO BlockManagerInfo: Added broadcast_11_piece0 in memory on 10.1.2.152:37100 (size: 3.7 KB, free: 2.1 GB)
17/01/29 15:07:58,981 INFO SparkContext: Created broadcast 11 from broadcast at DAGScheduler.scala:1012
17/01/29 15:07:58,981 INFO DAGScheduler: Submitting 32 missing tasks from ShuffleMapStage 7 (MapPartitionsRDD[21] at treeAggregate at GradientDescent.scala:239)
17/01/29 15:07:58,982 INFO TaskSchedulerImpl: Adding task set 7.0 with 32 tasks
17/01/29 15:07:58,984 INFO TaskSetManager: Starting task 8.0 in stage 7.0 (TID 139, 10.1.2.139, partition 8, PROCESS_LOCAL, 5562 bytes)
17/01/29 15:07:58,984 INFO TaskSetManager: Starting task 12.0 in stage 7.0 (TID 140, 10.1.2.191, partition 12, PROCESS_LOCAL, 5562 bytes)
17/01/29 15:07:58,985 INFO TaskSetManager: Starting task 0.0 in stage 7.0 (TID 141, 10.1.2.65, partition 0, PROCESS_LOCAL, 5562 bytes)
17/01/29 15:07:58,985 INFO TaskSetManager: Starting task 15.0 in stage 7.0 (TID 142, 10.1.2.176, partition 15, PROCESS_LOCAL, 5562 bytes)
17/01/29 15:07:58,986 INFO TaskSetManager: Starting task 1.0 in stage 7.0 (TID 143, 10.1.2.38, partition 1, PROCESS_LOCAL, 5562 bytes)
17/01/29 15:07:58,986 INFO TaskSetManager: Starting task 4.0 in stage 7.0 (TID 144, 10.1.2.28, partition 4, PROCESS_LOCAL, 5562 bytes)
17/01/29 15:07:58,987 INFO TaskSetManager: Starting task 10.0 in stage 7.0 (TID 145, 10.1.2.224, partition 10, PROCESS_LOCAL, 5562 bytes)
17/01/29 15:07:58,987 INFO TaskSetManager: Starting task 5.0 in stage 7.0 (TID 146, 10.1.2.66, partition 5, PROCESS_LOCAL, 5562 bytes)
17/01/29 15:07:58,988 INFO TaskSetManager: Starting task 9.0 in stage 7.0 (TID 147, 10.1.2.139, partition 9, PROCESS_LOCAL, 5562 bytes)
17/01/29 15:07:58,988 INFO TaskSetManager: Starting task 18.0 in stage 7.0 (TID 148, 10.1.2.191, partition 18, PROCESS_LOCAL, 5562 bytes)
17/01/29 15:07:58,989 INFO TaskSetManager: Starting task 3.0 in stage 7.0 (TID 149, 10.1.2.65, partition 3, PROCESS_LOCAL, 5562 bytes)
17/01/29 15:07:58,989 INFO TaskSetManager: Starting task 16.0 in stage 7.0 (TID 150, 10.1.2.176, partition 16, PROCESS_LOCAL, 5562 bytes)
17/01/29 15:07:58,990 INFO TaskSetManager: Starting task 2.0 in stage 7.0 (TID 151, 10.1.2.38, partition 2, PROCESS_LOCAL, 5562 bytes)
17/01/29 15:07:58,990 INFO TaskSetManager: Starting task 6.0 in stage 7.0 (TID 152, 10.1.2.28, partition 6, PROCESS_LOCAL, 5562 bytes)
17/01/29 15:07:58,991 INFO TaskSetManager: Starting task 11.0 in stage 7.0 (TID 153, 10.1.2.224, partition 11, PROCESS_LOCAL, 5562 bytes)
17/01/29 15:07:58,991 INFO TaskSetManager: Starting task 7.0 in stage 7.0 (TID 154, 10.1.2.66, partition 7, PROCESS_LOCAL, 5562 bytes)
17/01/29 15:07:58,991 INFO TaskSetManager: Starting task 13.0 in stage 7.0 (TID 155, 10.1.2.139, partition 13, PROCESS_LOCAL, 5562 bytes)
17/01/29 15:07:58,992 INFO TaskSetManager: Starting task 24.0 in stage 7.0 (TID 156, 10.1.2.191, partition 24, PROCESS_LOCAL, 5562 bytes)
17/01/29 15:07:58,992 INFO TaskSetManager: Starting task 14.0 in stage 7.0 (TID 157, 10.1.2.65, partition 14, PROCESS_LOCAL, 5562 bytes)
17/01/29 15:07:58,993 INFO TaskSetManager: Starting task 29.0 in stage 7.0 (TID 158, 10.1.2.176, partition 29, PROCESS_LOCAL, 5562 bytes)
17/01/29 15:07:58,993 INFO TaskSetManager: Starting task 17.0 in stage 7.0 (TID 159, 10.1.2.38, partition 17, PROCESS_LOCAL, 5562 bytes)
17/01/29 15:07:58,994 INFO TaskSetManager: Starting task 20.0 in stage 7.0 (TID 160, 10.1.2.28, partition 20, PROCESS_LOCAL, 5562 bytes)
17/01/29 15:07:58,994 INFO TaskSetManager: Starting task 26.0 in stage 7.0 (TID 161, 10.1.2.224, partition 26, PROCESS_LOCAL, 5562 bytes)
17/01/29 15:07:58,995 INFO TaskSetManager: Starting task 22.0 in stage 7.0 (TID 162, 10.1.2.66, partition 22, PROCESS_LOCAL, 5562 bytes)
17/01/29 15:07:58,995 INFO TaskSetManager: Starting task 25.0 in stage 7.0 (TID 163, 10.1.2.139, partition 25, PROCESS_LOCAL, 5562 bytes)
17/01/29 15:07:58,995 INFO TaskSetManager: Starting task 19.0 in stage 7.0 (TID 164, 10.1.2.65, partition 19, PROCESS_LOCAL, 5562 bytes)
17/01/29 15:07:59,002 INFO TaskSetManager: Starting task 30.0 in stage 7.0 (TID 165, 10.1.2.176, partition 30, PROCESS_LOCAL, 5562 bytes)
17/01/29 15:07:59,002 INFO TaskSetManager: Starting task 27.0 in stage 7.0 (TID 166, 10.1.2.38, partition 27, PROCESS_LOCAL, 5562 bytes)
17/01/29 15:07:59,003 INFO TaskSetManager: Starting task 21.0 in stage 7.0 (TID 167, 10.1.2.28, partition 21, PROCESS_LOCAL, 5562 bytes)
17/01/29 15:07:59,003 INFO TaskSetManager: Starting task 28.0 in stage 7.0 (TID 168, 10.1.2.224, partition 28, PROCESS_LOCAL, 5562 bytes)
17/01/29 15:07:59,004 INFO TaskSetManager: Starting task 23.0 in stage 7.0 (TID 169, 10.1.2.66, partition 23, PROCESS_LOCAL, 5562 bytes)
