Using properties file: /home/ubuntu/spark-2.0.0/conf/spark-defaults.conf
Adding default property: spark.driver.extraJavaOptions=-XX:+PrintGCDetails -XX:+PrintGCTimeStamps -Xms4000m -Dlog4j.configuration=file:///home/ubuntu/spark-2.0.0/conf/log4j.properties
Adding default property: spark.executor.extraJavaOptions=-XX:+PrintGCDetails -XX:+PrintGCTimeStamps -Xms4000m -Dlog4j.configuration=file:///home/ubuntu/spark-2.0.0/conf/log4j.properties
Parsed arguments:
  master                  spark://euca-10-1-2-152:7077
  deployMode              client
  executorMemory          4000m
  executorCores           null
  totalExecutorCores      null
  propertiesFile          /home/ubuntu/spark-2.0.0/conf/spark-defaults.conf
  driverMemory            4000m
  driverCores             null
  driverExtraClassPath    null
  driverExtraLibraryPath  null
  driverExtraJavaOptions  -XX:+PrintGCDetails -XX:+PrintGCTimeStamps -Xms4000m -Dlog4j.configuration=file:///home/ubuntu/spark-2.0.0/conf/log4j.properties
  supervise               false
  queue                   null
  numExecutors            8
  files                   null
  pyFiles                 null
  archives                null
  mainClass               LogRegExplicitParallelism
  primaryResource         file:///home/ubuntu/jars/log-reg-explicit-parallelism_2.11-1.0.jar
  name                    LogRegExplicitParallelism
  childArgs               [cluster 18 euca-10-1-2-152 9000 susy_0_exp 5 32]
  jars                    null
  packages                null
  packagesExclusions      null
  repositories            null
  verbose                 true

Spark properties used, including those specified through
 --conf and those from the properties file /home/ubuntu/spark-2.0.0/conf/spark-defaults.conf:
  spark.default.parallelism -> 32
  spark.driver.memory -> 4000m
  spark.executor.extraJavaOptions -> -XX:+PrintGCDetails -XX:+PrintGCTimeStamps -Xms4000m -Dlog4j.configuration=file:///home/ubuntu/spark-2.0.0/conf/log4j.properties
  spark.driver.extraJavaOptions -> -XX:+PrintGCDetails -XX:+PrintGCTimeStamps -Xms4000m -Dlog4j.configuration=file:///home/ubuntu/spark-2.0.0/conf/log4j.properties
  spark.shuffle.spill -> false

    
Main class:
LogRegExplicitParallelism
Arguments:
cluster
18
euca-10-1-2-152
9000
susy_0_exp
5
32
System properties:
spark.default.parallelism -> 32
spark.executor.memory -> 4000m
spark.driver.memory -> 4000m
SPARK_SUBMIT -> true
spark.executor.extraJavaOptions -> -XX:+PrintGCDetails -XX:+PrintGCTimeStamps -Xms4000m -Dlog4j.configuration=file:///home/ubuntu/spark-2.0.0/conf/log4j.properties
spark.app.name -> LogRegExplicitParallelism
spark.shuffle.spill -> false
spark.driver.extraJavaOptions -> -XX:+PrintGCDetails -XX:+PrintGCTimeStamps -Xms4000m -Dlog4j.configuration=file:///home/ubuntu/spark-2.0.0/conf/log4j.properties
spark.jars -> file:///home/ubuntu/jars/log-reg-explicit-parallelism_2.11-1.0.jar
spark.submit.deployMode -> client
spark.master -> spark://euca-10-1-2-152:7077
Classpath elements:
file:///home/ubuntu/jars/log-reg-explicit-parallelism_2.11-1.0.jar


17/01/29 15:14:59,146 INFO SparkContext: Running Spark version 2.0.0
17/01/29 15:14:59,504 WARN NativeCodeLoader: Unable to load native-hadoop library for your platform... using builtin-java classes where applicable
17/01/29 15:14:59,659 INFO SecurityManager: Changing view acls to: ubuntu
17/01/29 15:14:59,659 INFO SecurityManager: Changing modify acls to: ubuntu
17/01/29 15:14:59,660 INFO SecurityManager: Changing view acls groups to: 
17/01/29 15:14:59,660 INFO SecurityManager: Changing modify acls groups to: 
17/01/29 15:14:59,661 INFO SecurityManager: SecurityManager: authentication disabled; ui acls disabled; users  with view permissions: Set(ubuntu); groups with view permissions: Set(); users  with modify permissions: Set(ubuntu); groups with modify permissions: Set()
17/01/29 15:15:02,914 WARN ThreadLocalRandom: Failed to generate a seed from SecureRandom within 3 seconds. Not enough entrophy?
17/01/29 15:15:02,972 INFO Utils: Successfully started service 'sparkDriver' on port 41608.
17/01/29 15:15:02,991 INFO SparkEnv: Registering MapOutputTracker
17/01/29 15:15:02,997 WARN SortShuffleManager: spark.shuffle.spill was set to false, but this configuration is ignored as of Spark 1.6+. Shuffle will continue to spill to disk when necessary.
17/01/29 15:15:03,008 INFO SparkEnv: Registering BlockManagerMaster
17/01/29 15:15:03,022 INFO DiskBlockManager: Created local directory at /tmp/blockmgr-5d6937c2-dd9a-4308-88ac-e671afa631fe
17/01/29 15:15:03,043 INFO MemoryStore: MemoryStore started with capacity 2.1 GB
17/01/29 15:15:03,099 INFO SparkEnv: Registering OutputCommitCoordinator
17/01/29 15:15:03,300 INFO Utils: Successfully started service 'SparkUI' on port 4040.
17/01/29 15:15:03,302 INFO SparkUI: Bound SparkUI to 10.1.2.152, and started at http://10.1.2.152:4040
17/01/29 15:15:03,331 INFO SparkContext: Added JAR file:///home/ubuntu/jars/log-reg-explicit-parallelism_2.11-1.0.jar at spark://10.1.2.152:41608/jars/log-reg-explicit-parallelism_2.11-1.0.jar with timestamp 1485702903331
17/01/29 15:15:03,412 INFO StandaloneAppClient$ClientEndpoint: Connecting to master spark://euca-10-1-2-152:7077...
17/01/29 15:15:03,464 INFO TransportClientFactory: Successfully created connection to euca-10-1-2-152/10.1.2.152:7077 after 27 ms (0 ms spent in bootstraps)
17/01/29 15:15:03,560 INFO StandaloneSchedulerBackend: Connected to Spark cluster with app ID app-20170129151503-0000
17/01/29 15:15:03,566 INFO Utils: Successfully started service 'org.apache.spark.network.netty.NettyBlockTransferService' on port 36982.
17/01/29 15:15:03,566 INFO NettyBlockTransferService: Server created on 10.1.2.152:36982
17/01/29 15:15:03,568 INFO BlockManagerMaster: Registering BlockManager BlockManagerId(driver, 10.1.2.152, 36982)
17/01/29 15:15:03,571 INFO BlockManagerMasterEndpoint: Registering block manager 10.1.2.152:36982 with 2.1 GB RAM, BlockManagerId(driver, 10.1.2.152, 36982)
17/01/29 15:15:03,573 INFO BlockManagerMaster: Registered BlockManager BlockManagerId(driver, 10.1.2.152, 36982)
17/01/29 15:15:03,591 INFO StandaloneAppClient$ClientEndpoint: Executor added: app-20170129151503-0000/0 on worker-20170129151439-10.1.2.139-39786 (10.1.2.139:39786) with 4 cores
17/01/29 15:15:03,593 INFO StandaloneSchedulerBackend: Granted executor ID app-20170129151503-0000/0 on hostPort 10.1.2.139:39786 with 4 cores, 3.9 GB RAM
17/01/29 15:15:03,596 INFO StandaloneAppClient$ClientEndpoint: Executor added: app-20170129151503-0000/1 on worker-20170129151439-10.1.2.191-42520 (10.1.2.191:42520) with 4 cores
17/01/29 15:15:03,596 INFO StandaloneSchedulerBackend: Granted executor ID app-20170129151503-0000/1 on hostPort 10.1.2.191:42520 with 4 cores, 3.9 GB RAM
17/01/29 15:15:03,598 INFO StandaloneAppClient$ClientEndpoint: Executor added: app-20170129151503-0000/2 on worker-20170129151439-10.1.2.65-36007 (10.1.2.65:36007) with 4 cores
17/01/29 15:15:03,598 INFO StandaloneSchedulerBackend: Granted executor ID app-20170129151503-0000/2 on hostPort 10.1.2.65:36007 with 4 cores, 3.9 GB RAM
17/01/29 15:15:03,599 INFO StandaloneAppClient$ClientEndpoint: Executor added: app-20170129151503-0000/3 on worker-20170129151439-10.1.2.66-38769 (10.1.2.66:38769) with 4 cores
17/01/29 15:15:03,599 INFO StandaloneSchedulerBackend: Granted executor ID app-20170129151503-0000/3 on hostPort 10.1.2.66:38769 with 4 cores, 3.9 GB RAM
17/01/29 15:15:03,601 INFO StandaloneAppClient$ClientEndpoint: Executor added: app-20170129151503-0000/4 on worker-20170129151439-10.1.2.224-33731 (10.1.2.224:33731) with 4 cores
17/01/29 15:15:03,601 INFO StandaloneSchedulerBackend: Granted executor ID app-20170129151503-0000/4 on hostPort 10.1.2.224:33731 with 4 cores, 3.9 GB RAM
17/01/29 15:15:03,603 INFO StandaloneAppClient$ClientEndpoint: Executor added: app-20170129151503-0000/5 on worker-20170129151439-10.1.2.176-33938 (10.1.2.176:33938) with 4 cores
17/01/29 15:15:03,603 INFO StandaloneSchedulerBackend: Granted executor ID app-20170129151503-0000/5 on hostPort 10.1.2.176:33938 with 4 cores, 3.9 GB RAM
17/01/29 15:15:03,605 INFO StandaloneAppClient$ClientEndpoint: Executor added: app-20170129151503-0000/6 on worker-20170129151439-10.1.2.38-33379 (10.1.2.38:33379) with 4 cores
17/01/29 15:15:03,605 INFO StandaloneSchedulerBackend: Granted executor ID app-20170129151503-0000/6 on hostPort 10.1.2.38:33379 with 4 cores, 3.9 GB RAM
17/01/29 15:15:03,606 INFO StandaloneAppClient$ClientEndpoint: Executor added: app-20170129151503-0000/7 on worker-20170129151439-10.1.2.28-41851 (10.1.2.28:41851) with 4 cores
17/01/29 15:15:03,606 INFO StandaloneSchedulerBackend: Granted executor ID app-20170129151503-0000/7 on hostPort 10.1.2.28:41851 with 4 cores, 3.9 GB RAM
17/01/29 15:15:03,677 INFO StandaloneAppClient$ClientEndpoint: Executor updated: app-20170129151503-0000/1 is now RUNNING
17/01/29 15:15:03,684 INFO StandaloneAppClient$ClientEndpoint: Executor updated: app-20170129151503-0000/2 is now RUNNING
17/01/29 15:15:03,687 INFO StandaloneAppClient$ClientEndpoint: Executor updated: app-20170129151503-0000/6 is now RUNNING
17/01/29 15:15:03,690 INFO StandaloneAppClient$ClientEndpoint: Executor updated: app-20170129151503-0000/5 is now RUNNING
17/01/29 15:15:03,692 INFO StandaloneAppClient$ClientEndpoint: Executor updated: app-20170129151503-0000/0 is now RUNNING
17/01/29 15:15:03,695 INFO StandaloneAppClient$ClientEndpoint: Executor updated: app-20170129151503-0000/4 is now RUNNING
17/01/29 15:15:03,699 INFO StandaloneAppClient$ClientEndpoint: Executor updated: app-20170129151503-0000/3 is now RUNNING
17/01/29 15:15:03,701 INFO StandaloneAppClient$ClientEndpoint: Executor updated: app-20170129151503-0000/7 is now RUNNING
17/01/29 15:15:03,765 INFO StandaloneSchedulerBackend: SchedulerBackend is ready for scheduling beginning after reached minRegisteredResourcesRatio: 0.0
17/01/29 15:15:04,175 INFO MemoryStore: Block broadcast_0 stored as values in memory (estimated size 130.8 KB, free 2.1 GB)
17/01/29 15:15:04,262 INFO MemoryStore: Block broadcast_0_piece0 stored as bytes in memory (estimated size 16.5 KB, free 2.1 GB)
17/01/29 15:15:04,264 INFO BlockManagerInfo: Added broadcast_0_piece0 in memory on 10.1.2.152:36982 (size: 16.5 KB, free: 2.1 GB)
17/01/29 15:15:04,271 INFO SparkContext: Created broadcast 0 from textFile at MLUtils.scala:99
17/01/29 15:15:04,885 INFO FileInputFormat: Total input paths to process : 1
17/01/29 15:15:04,920 INFO NetworkTopology: Adding a new node: /default-rack/10.1.2.224:50010
17/01/29 15:15:04,920 INFO NetworkTopology: Adding a new node: /default-rack/10.1.2.38:50010
17/01/29 15:15:04,921 INFO NetworkTopology: Adding a new node: /default-rack/10.1.2.66:50010
17/01/29 15:15:04,921 INFO NetworkTopology: Adding a new node: /default-rack/10.1.2.176:50010
17/01/29 15:15:04,921 INFO NetworkTopology: Adding a new node: /default-rack/10.1.2.28:50010
17/01/29 15:15:04,922 INFO NetworkTopology: Adding a new node: /default-rack/10.1.2.65:50010
17/01/29 15:15:04,922 INFO NetworkTopology: Adding a new node: /default-rack/10.1.2.139:50010
17/01/29 15:15:04,923 INFO NetworkTopology: Adding a new node: /default-rack/10.1.2.191:50010
17/01/29 15:15:04,962 INFO SparkContext: Starting job: first at GeneralizedLinearAlgorithm.scala:246
17/01/29 15:15:04,973 INFO DAGScheduler: Got job 0 (first at GeneralizedLinearAlgorithm.scala:246) with 1 output partitions
17/01/29 15:15:04,974 INFO DAGScheduler: Final stage: ResultStage 0 (first at GeneralizedLinearAlgorithm.scala:246)
17/01/29 15:15:04,974 INFO DAGScheduler: Parents of final stage: List()
17/01/29 15:15:04,979 INFO DAGScheduler: Missing parents: List()
17/01/29 15:15:04,992 INFO DAGScheduler: Submitting ResultStage 0 (MapPartitionsRDD[6] at map at GeneralizedLinearAlgorithm.scala:246), which has no missing parents
17/01/29 15:15:05,015 INFO MemoryStore: Block broadcast_1 stored as values in memory (estimated size 4.2 KB, free 2.1 GB)
17/01/29 15:15:05,018 INFO MemoryStore: Block broadcast_1_piece0 stored as bytes in memory (estimated size 2.4 KB, free 2.1 GB)
17/01/29 15:15:05,019 INFO BlockManagerInfo: Added broadcast_1_piece0 in memory on 10.1.2.152:36982 (size: 2.4 KB, free: 2.1 GB)
17/01/29 15:15:05,020 INFO SparkContext: Created broadcast 1 from broadcast at DAGScheduler.scala:1012
17/01/29 15:15:05,023 INFO DAGScheduler: Submitting 1 missing tasks from ResultStage 0 (MapPartitionsRDD[6] at map at GeneralizedLinearAlgorithm.scala:246)
17/01/29 15:15:05,025 INFO TaskSchedulerImpl: Adding task set 0.0 with 1 tasks
17/01/29 15:15:08,486 INFO CoarseGrainedSchedulerBackend$DriverEndpoint: Registered executor NettyRpcEndpointRef(null) (10.1.2.224:41220) with ID 4
17/01/29 15:15:08,512 INFO TaskSetManager: Starting task 0.0 in stage 0.0 (TID 0, 10.1.2.224, partition 0, ANY, 5455 bytes)
17/01/29 15:15:08,520 INFO CoarseGrainedSchedulerBackend$DriverEndpoint: Launching task 0 on executor id: 4 hostname: 10.1.2.224.
17/01/29 15:15:08,522 INFO CoarseGrainedSchedulerBackend$DriverEndpoint: Registered executor NettyRpcEndpointRef(null) (10.1.2.38:51050) with ID 6
17/01/29 15:15:08,545 INFO BlockManagerMasterEndpoint: Registering block manager 10.1.2.224:33482 with 2.1 GB RAM, BlockManagerId(4, 10.1.2.224, 33482)
17/01/29 15:15:08,579 INFO BlockManagerMasterEndpoint: Registering block manager 10.1.2.38:44632 with 2.1 GB RAM, BlockManagerId(6, 10.1.2.38, 44632)
17/01/29 15:15:08,598 INFO CoarseGrainedSchedulerBackend$DriverEndpoint: Registered executor NettyRpcEndpointRef(null) (10.1.2.28:52520) with ID 7
17/01/29 15:15:08,600 INFO CoarseGrainedSchedulerBackend$DriverEndpoint: Registered executor NettyRpcEndpointRef(null) (10.1.2.191:44068) with ID 1
17/01/29 15:15:08,608 INFO CoarseGrainedSchedulerBackend$DriverEndpoint: Registered executor NettyRpcEndpointRef(null) (10.1.2.65:58668) with ID 2
17/01/29 15:15:08,645 INFO BlockManagerMasterEndpoint: Registering block manager 10.1.2.28:35923 with 2.1 GB RAM, BlockManagerId(7, 10.1.2.28, 35923)
17/01/29 15:15:08,659 INFO BlockManagerMasterEndpoint: Registering block manager 10.1.2.65:41459 with 2.1 GB RAM, BlockManagerId(2, 10.1.2.65, 41459)
17/01/29 15:15:08,669 INFO BlockManagerMasterEndpoint: Registering block manager 10.1.2.191:36335 with 2.1 GB RAM, BlockManagerId(1, 10.1.2.191, 36335)
17/01/29 15:15:08,692 INFO CoarseGrainedSchedulerBackend$DriverEndpoint: Registered executor NettyRpcEndpointRef(null) (10.1.2.66:59764) with ID 3
17/01/29 15:15:08,751 INFO BlockManagerMasterEndpoint: Registering block manager 10.1.2.66:39959 with 2.1 GB RAM, BlockManagerId(3, 10.1.2.66, 39959)
17/01/29 15:15:08,782 INFO CoarseGrainedSchedulerBackend$DriverEndpoint: Registered executor NettyRpcEndpointRef(null) (10.1.2.139:47550) with ID 0
17/01/29 15:15:08,783 INFO CoarseGrainedSchedulerBackend$DriverEndpoint: Registered executor NettyRpcEndpointRef(null) (10.1.2.176:36220) with ID 5
17/01/29 15:15:08,831 INFO BlockManagerInfo: Added broadcast_1_piece0 in memory on 10.1.2.224:33482 (size: 2.4 KB, free: 2.1 GB)
17/01/29 15:15:08,833 INFO BlockManagerMasterEndpoint: Registering block manager 10.1.2.139:38077 with 2.1 GB RAM, BlockManagerId(0, 10.1.2.139, 38077)
17/01/29 15:15:08,840 INFO BlockManagerMasterEndpoint: Registering block manager 10.1.2.176:33908 with 2.1 GB RAM, BlockManagerId(5, 10.1.2.176, 33908)
17/01/29 15:15:08,975 INFO BlockManagerInfo: Added broadcast_0_piece0 in memory on 10.1.2.224:33482 (size: 16.5 KB, free: 2.1 GB)
17/01/29 15:15:13,741 INFO BlockManagerInfo: Added rdd_5_0 in memory on 10.1.2.224:33482 (size: 44.3 MB, free: 2.0 GB)
17/01/29 15:15:13,796 INFO TaskSetManager: Finished task 0.0 in stage 0.0 (TID 0) in 5304 ms on 10.1.2.224 (1/1)
17/01/29 15:15:13,800 INFO DAGScheduler: ResultStage 0 (first at GeneralizedLinearAlgorithm.scala:246) finished in 8.764 s
17/01/29 15:15:13,798 INFO TaskSchedulerImpl: Removed TaskSet 0.0, whose tasks have all completed, from pool 
17/01/29 15:15:13,805 INFO DAGScheduler: Job 0 finished: first at GeneralizedLinearAlgorithm.scala:246, took 8.842950 s
17/01/29 15:15:13,816 INFO SparkContext: Starting job: count at DataValidators.scala:40
17/01/29 15:15:13,817 INFO DAGScheduler: Got job 1 (count at DataValidators.scala:40) with 32 output partitions
17/01/29 15:15:13,818 INFO DAGScheduler: Final stage: ResultStage 1 (count at DataValidators.scala:40)
17/01/29 15:15:13,818 INFO DAGScheduler: Parents of final stage: List()
17/01/29 15:15:13,820 INFO DAGScheduler: Missing parents: List()
17/01/29 15:15:13,820 INFO DAGScheduler: Submitting ResultStage 1 (MapPartitionsRDD[7] at filter at DataValidators.scala:40), which has no missing parents
17/01/29 15:15:13,834 INFO MemoryStore: Block broadcast_2 stored as values in memory (estimated size 3.9 KB, free 2.1 GB)
17/01/29 15:15:13,836 INFO MemoryStore: Block broadcast_2_piece0 stored as bytes in memory (estimated size 2.2 KB, free 2.1 GB)
17/01/29 15:15:13,837 INFO BlockManagerInfo: Added broadcast_2_piece0 in memory on 10.1.2.152:36982 (size: 2.2 KB, free: 2.1 GB)
17/01/29 15:15:13,838 INFO SparkContext: Created broadcast 2 from broadcast at DAGScheduler.scala:1012
17/01/29 15:15:13,839 INFO DAGScheduler: Submitting 32 missing tasks from ResultStage 1 (MapPartitionsRDD[7] at filter at DataValidators.scala:40)
17/01/29 15:15:13,839 INFO TaskSchedulerImpl: Adding task set 1.0 with 32 tasks
17/01/29 15:15:13,845 INFO TaskSetManager: Starting task 0.0 in stage 1.0 (TID 1, 10.1.2.224, partition 0, PROCESS_LOCAL, 5373 bytes)
17/01/29 15:15:13,848 INFO TaskSetManager: Starting task 1.0 in stage 1.0 (TID 2, 10.1.2.38, partition 1, NODE_LOCAL, 5373 bytes)
17/01/29 15:15:13,850 INFO TaskSetManager: Starting task 3.0 in stage 1.0 (TID 3, 10.1.2.65, partition 3, NODE_LOCAL, 5373 bytes)
17/01/29 15:15:13,852 INFO TaskSetManager: Starting task 10.0 in stage 1.0 (TID 4, 10.1.2.224, partition 10, NODE_LOCAL, 5373 bytes)
17/01/29 15:15:13,856 INFO TaskSetManager: Starting task 5.0 in stage 1.0 (TID 5, 10.1.2.66, partition 5, NODE_LOCAL, 5373 bytes)
17/01/29 15:15:13,858 INFO TaskSetManager: Starting task 12.0 in stage 1.0 (TID 6, 10.1.2.191, partition 12, NODE_LOCAL, 5373 bytes)
17/01/29 15:15:13,860 INFO TaskSetManager: Starting task 6.0 in stage 1.0 (TID 7, 10.1.2.28, partition 6, NODE_LOCAL, 5373 bytes)
17/01/29 15:15:13,861 INFO TaskSetManager: Starting task 8.0 in stage 1.0 (TID 8, 10.1.2.139, partition 8, NODE_LOCAL, 5373 bytes)
17/01/29 15:15:13,863 INFO TaskSetManager: Starting task 15.0 in stage 1.0 (TID 9, 10.1.2.176, partition 15, NODE_LOCAL, 5373 bytes)
17/01/29 15:15:13,865 INFO TaskSetManager: Starting task 17.0 in stage 1.0 (TID 10, 10.1.2.38, partition 17, NODE_LOCAL, 5373 bytes)
17/01/29 15:15:13,867 INFO TaskSetManager: Starting task 19.0 in stage 1.0 (TID 11, 10.1.2.65, partition 19, NODE_LOCAL, 5373 bytes)
17/01/29 15:15:13,869 INFO TaskSetManager: Starting task 20.0 in stage 1.0 (TID 12, 10.1.2.224, partition 20, NODE_LOCAL, 5373 bytes)
17/01/29 15:15:13,871 INFO TaskSetManager: Starting task 22.0 in stage 1.0 (TID 13, 10.1.2.66, partition 22, NODE_LOCAL, 5373 bytes)
17/01/29 15:15:13,873 INFO TaskSetManager: Starting task 13.0 in stage 1.0 (TID 14, 10.1.2.191, partition 13, NODE_LOCAL, 5373 bytes)
17/01/29 15:15:13,875 INFO TaskSetManager: Starting task 26.0 in stage 1.0 (TID 15, 10.1.2.28, partition 26, NODE_LOCAL, 5373 bytes)
17/01/29 15:15:13,876 INFO TaskSetManager: Starting task 24.0 in stage 1.0 (TID 16, 10.1.2.176, partition 24, NODE_LOCAL, 5373 bytes)
17/01/29 15:15:13,878 INFO TaskSetManager: Starting task 27.0 in stage 1.0 (TID 17, 10.1.2.38, partition 27, NODE_LOCAL, 5373 bytes)
17/01/29 15:15:13,880 INFO TaskSetManager: Starting task 31.0 in stage 1.0 (TID 18, 10.1.2.65, partition 31, NODE_LOCAL, 5373 bytes)
17/01/29 15:15:13,883 INFO TaskSetManager: Starting task 29.0 in stage 1.0 (TID 19, 10.1.2.66, partition 29, NODE_LOCAL, 5373 bytes)
17/01/29 15:15:13,884 INFO CoarseGrainedSchedulerBackend$DriverEndpoint: Launching task 2 on executor id: 6 hostname: 10.1.2.38.
17/01/29 15:15:13,885 INFO CoarseGrainedSchedulerBackend$DriverEndpoint: Launching task 10 on executor id: 6 hostname: 10.1.2.38.
17/01/29 15:15:13,885 INFO CoarseGrainedSchedulerBackend$DriverEndpoint: Launching task 17 on executor id: 6 hostname: 10.1.2.38.
17/01/29 15:15:13,886 INFO CoarseGrainedSchedulerBackend$DriverEndpoint: Launching task 3 on executor id: 2 hostname: 10.1.2.65.
17/01/29 15:15:13,887 INFO CoarseGrainedSchedulerBackend$DriverEndpoint: Launching task 11 on executor id: 2 hostname: 10.1.2.65.
17/01/29 15:15:13,887 INFO CoarseGrainedSchedulerBackend$DriverEndpoint: Launching task 18 on executor id: 2 hostname: 10.1.2.65.
17/01/29 15:15:13,888 INFO CoarseGrainedSchedulerBackend$DriverEndpoint: Launching task 1 on executor id: 4 hostname: 10.1.2.224.
17/01/29 15:15:13,889 INFO CoarseGrainedSchedulerBackend$DriverEndpoint: Launching task 4 on executor id: 4 hostname: 10.1.2.224.
17/01/29 15:15:13,890 INFO CoarseGrainedSchedulerBackend$DriverEndpoint: Launching task 12 on executor id: 4 hostname: 10.1.2.224.
17/01/29 15:15:13,890 INFO CoarseGrainedSchedulerBackend$DriverEndpoint: Launching task 5 on executor id: 3 hostname: 10.1.2.66.
17/01/29 15:15:13,891 INFO CoarseGrainedSchedulerBackend$DriverEndpoint: Launching task 13 on executor id: 3 hostname: 10.1.2.66.
17/01/29 15:15:13,892 INFO CoarseGrainedSchedulerBackend$DriverEndpoint: Launching task 19 on executor id: 3 hostname: 10.1.2.66.
17/01/29 15:15:13,892 INFO CoarseGrainedSchedulerBackend$DriverEndpoint: Launching task 6 on executor id: 1 hostname: 10.1.2.191.
17/01/29 15:15:13,893 INFO CoarseGrainedSchedulerBackend$DriverEndpoint: Launching task 14 on executor id: 1 hostname: 10.1.2.191.
17/01/29 15:15:13,893 INFO CoarseGrainedSchedulerBackend$DriverEndpoint: Launching task 7 on executor id: 7 hostname: 10.1.2.28.
17/01/29 15:15:13,894 INFO CoarseGrainedSchedulerBackend$DriverEndpoint: Launching task 15 on executor id: 7 hostname: 10.1.2.28.
17/01/29 15:15:13,894 INFO CoarseGrainedSchedulerBackend$DriverEndpoint: Launching task 8 on executor id: 0 hostname: 10.1.2.139.
17/01/29 15:15:13,895 INFO CoarseGrainedSchedulerBackend$DriverEndpoint: Launching task 9 on executor id: 5 hostname: 10.1.2.176.
17/01/29 15:15:13,895 INFO CoarseGrainedSchedulerBackend$DriverEndpoint: Launching task 16 on executor id: 5 hostname: 10.1.2.176.
17/01/29 15:15:13,971 INFO BlockManagerInfo: Added broadcast_2_piece0 in memory on 10.1.2.224:33482 (size: 2.2 KB, free: 2.0 GB)
17/01/29 15:15:14,036 INFO TaskSetManager: Finished task 0.0 in stage 1.0 (TID 1) in 192 ms on 10.1.2.224 (1/32)
15.695: [GC [PSYoungGen: 1024512K->140364K(1195008K)] 1024512K->140436K(3926016K), 0.0573630 secs] [Times: user=0.07 sys=0.03, real=0.06 secs] 
17/01/29 15:15:14,228 INFO BlockManagerInfo: Added broadcast_2_piece0 in memory on 10.1.2.176:33908 (size: 2.2 KB, free: 2.1 GB)
17/01/29 15:15:14,229 INFO BlockManagerInfo: Added broadcast_2_piece0 in memory on 10.1.2.191:36335 (size: 2.2 KB, free: 2.1 GB)
17/01/29 15:15:14,230 INFO BlockManagerInfo: Added broadcast_2_piece0 in memory on 10.1.2.139:38077 (size: 2.2 KB, free: 2.1 GB)
17/01/29 15:15:14,273 INFO BlockManagerInfo: Added broadcast_2_piece0 in memory on 10.1.2.28:35923 (size: 2.2 KB, free: 2.1 GB)
17/01/29 15:15:14,282 INFO BlockManagerInfo: Removed broadcast_1_piece0 on 10.1.2.152:36982 in memory (size: 2.4 KB, free: 2.1 GB)
17/01/29 15:15:14,285 INFO BlockManagerInfo: Removed broadcast_1_piece0 on 10.1.2.224:33482 in memory (size: 2.4 KB, free: 2.0 GB)
17/01/29 15:15:14,289 INFO BlockManagerInfo: Added broadcast_2_piece0 in memory on 10.1.2.65:41459 (size: 2.2 KB, free: 2.1 GB)
17/01/29 15:15:14,296 INFO BlockManagerInfo: Added broadcast_2_piece0 in memory on 10.1.2.66:39959 (size: 2.2 KB, free: 2.1 GB)
17/01/29 15:15:14,331 INFO BlockManagerInfo: Added broadcast_2_piece0 in memory on 10.1.2.38:44632 (size: 2.2 KB, free: 2.1 GB)
17/01/29 15:15:14,394 INFO BlockManagerInfo: Added broadcast_0_piece0 in memory on 10.1.2.191:36335 (size: 16.5 KB, free: 2.1 GB)
17/01/29 15:15:14,409 INFO BlockManagerInfo: Added broadcast_0_piece0 in memory on 10.1.2.176:33908 (size: 16.5 KB, free: 2.1 GB)
17/01/29 15:15:14,445 INFO BlockManagerInfo: Added broadcast_0_piece0 in memory on 10.1.2.28:35923 (size: 16.5 KB, free: 2.1 GB)
17/01/29 15:15:14,447 INFO BlockManagerInfo: Added broadcast_0_piece0 in memory on 10.1.2.139:38077 (size: 16.5 KB, free: 2.1 GB)
17/01/29 15:15:14,464 INFO BlockManagerInfo: Added broadcast_0_piece0 in memory on 10.1.2.65:41459 (size: 16.5 KB, free: 2.1 GB)
17/01/29 15:15:14,503 INFO BlockManagerInfo: Added broadcast_0_piece0 in memory on 10.1.2.66:39959 (size: 16.5 KB, free: 2.1 GB)
17/01/29 15:15:14,565 INFO BlockManagerInfo: Added broadcast_0_piece0 in memory on 10.1.2.38:44632 (size: 16.5 KB, free: 2.1 GB)
17/01/29 15:15:17,403 INFO TaskSetManager: Starting task 2.0 in stage 1.0 (TID 20, 10.1.2.176, partition 2, ANY, 5373 bytes)
17/01/29 15:15:17,406 INFO TaskSetManager: Starting task 4.0 in stage 1.0 (TID 21, 10.1.2.38, partition 4, ANY, 5373 bytes)
17/01/29 15:15:17,408 INFO TaskSetManager: Starting task 7.0 in stage 1.0 (TID 22, 10.1.2.139, partition 7, ANY, 5373 bytes)
17/01/29 15:15:17,411 INFO TaskSetManager: Starting task 9.0 in stage 1.0 (TID 23, 10.1.2.66, partition 9, ANY, 5373 bytes)
17/01/29 15:15:17,413 INFO TaskSetManager: Starting task 11.0 in stage 1.0 (TID 24, 10.1.2.224, partition 11, ANY, 5373 bytes)
17/01/29 15:15:17,414 INFO TaskSetManager: Starting task 14.0 in stage 1.0 (TID 25, 10.1.2.191, partition 14, ANY, 5373 bytes)
17/01/29 15:15:17,417 INFO TaskSetManager: Starting task 16.0 in stage 1.0 (TID 26, 10.1.2.65, partition 16, ANY, 5373 bytes)
17/01/29 15:15:17,418 INFO TaskSetManager: Starting task 18.0 in stage 1.0 (TID 27, 10.1.2.28, partition 18, ANY, 5373 bytes)
17/01/29 15:15:17,420 INFO TaskSetManager: Starting task 21.0 in stage 1.0 (TID 28, 10.1.2.176, partition 21, ANY, 5373 bytes)
17/01/29 15:15:17,422 INFO TaskSetManager: Starting task 23.0 in stage 1.0 (TID 29, 10.1.2.139, partition 23, ANY, 5373 bytes)
17/01/29 15:15:17,424 INFO TaskSetManager: Starting task 25.0 in stage 1.0 (TID 30, 10.1.2.224, partition 25, ANY, 5373 bytes)
17/01/29 15:15:17,426 INFO TaskSetManager: Starting task 28.0 in stage 1.0 (TID 31, 10.1.2.191, partition 28, ANY, 5373 bytes)
17/01/29 15:15:17,428 INFO TaskSetManager: Starting task 30.0 in stage 1.0 (TID 32, 10.1.2.28, partition 30, ANY, 5373 bytes)
17/01/29 15:15:17,428 INFO CoarseGrainedSchedulerBackend$DriverEndpoint: Launching task 20 on executor id: 5 hostname: 10.1.2.176.
17/01/29 15:15:17,429 INFO CoarseGrainedSchedulerBackend$DriverEndpoint: Launching task 28 on executor id: 5 hostname: 10.1.2.176.
17/01/29 15:15:17,429 INFO CoarseGrainedSchedulerBackend$DriverEndpoint: Launching task 21 on executor id: 6 hostname: 10.1.2.38.
17/01/29 15:15:17,430 INFO CoarseGrainedSchedulerBackend$DriverEndpoint: Launching task 22 on executor id: 0 hostname: 10.1.2.139.
17/01/29 15:15:17,430 INFO CoarseGrainedSchedulerBackend$DriverEndpoint: Launching task 29 on executor id: 0 hostname: 10.1.2.139.
17/01/29 15:15:17,430 INFO CoarseGrainedSchedulerBackend$DriverEndpoint: Launching task 23 on executor id: 3 hostname: 10.1.2.66.
17/01/29 15:15:17,431 INFO CoarseGrainedSchedulerBackend$DriverEndpoint: Launching task 24 on executor id: 4 hostname: 10.1.2.224.
17/01/29 15:15:17,432 INFO CoarseGrainedSchedulerBackend$DriverEndpoint: Launching task 30 on executor id: 4 hostname: 10.1.2.224.
17/01/29 15:15:17,432 INFO CoarseGrainedSchedulerBackend$DriverEndpoint: Launching task 25 on executor id: 1 hostname: 10.1.2.191.
17/01/29 15:15:17,433 INFO CoarseGrainedSchedulerBackend$DriverEndpoint: Launching task 31 on executor id: 1 hostname: 10.1.2.191.
17/01/29 15:15:17,433 INFO CoarseGrainedSchedulerBackend$DriverEndpoint: Launching task 26 on executor id: 2 hostname: 10.1.2.65.
17/01/29 15:15:17,434 INFO CoarseGrainedSchedulerBackend$DriverEndpoint: Launching task 27 on executor id: 7 hostname: 10.1.2.28.
17/01/29 15:15:17,434 INFO CoarseGrainedSchedulerBackend$DriverEndpoint: Launching task 32 on executor id: 7 hostname: 10.1.2.28.
17/01/29 15:15:22,157 INFO BlockManagerInfo: Added rdd_5_10 in memory on 10.1.2.224:33482 (size: 44.4 MB, free: 2031.7 MB)
17/01/29 15:15:22,185 INFO TaskSetManager: Finished task 10.0 in stage 1.0 (TID 4) in 8335 ms on 10.1.2.224 (2/32)
17/01/29 15:15:23,006 INFO BlockManagerInfo: Added rdd_5_20 in memory on 10.1.2.224:33482 (size: 44.4 MB, free: 1987.3 MB)
17/01/29 15:15:23,029 INFO TaskSetManager: Finished task 20.0 in stage 1.0 (TID 12) in 9161 ms on 10.1.2.224 (3/32)
17/01/29 15:15:23,220 INFO BlockManagerInfo: Added rdd_5_8 in memory on 10.1.2.139:38077 (size: 44.4 MB, free: 2.0 GB)
17/01/29 15:15:23,300 INFO TaskSetManager: Finished task 8.0 in stage 1.0 (TID 8) in 9439 ms on 10.1.2.139 (4/32)
17/01/29 15:15:24,737 INFO BlockManagerInfo: Added rdd_5_15 in memory on 10.1.2.176:33908 (size: 44.4 MB, free: 2.0 GB)
17/01/29 15:15:24,806 INFO TaskSetManager: Finished task 15.0 in stage 1.0 (TID 9) in 10945 ms on 10.1.2.176 (5/32)
17/01/29 15:15:24,919 INFO BlockManagerInfo: Added rdd_5_24 in memory on 10.1.2.176:33908 (size: 44.4 MB, free: 2031.6 MB)
17/01/29 15:15:24,941 INFO TaskSetManager: Finished task 24.0 in stage 1.0 (TID 16) in 11066 ms on 10.1.2.176 (6/32)
17/01/29 15:15:25,368 INFO BlockManagerInfo: Added rdd_5_12 in memory on 10.1.2.191:36335 (size: 44.4 MB, free: 2.0 GB)
17/01/29 15:15:25,453 INFO TaskSetManager: Finished task 12.0 in stage 1.0 (TID 6) in 11597 ms on 10.1.2.191 (7/32)
17/01/29 15:15:25,557 INFO BlockManagerInfo: Added rdd_5_7 in memory on 10.1.2.139:38077 (size: 44.4 MB, free: 2031.7 MB)
17/01/29 15:15:25,574 INFO TaskSetManager: Finished task 7.0 in stage 1.0 (TID 22) in 8167 ms on 10.1.2.139 (8/32)
17/01/29 15:15:25,683 INFO BlockManagerInfo: Added rdd_5_23 in memory on 10.1.2.139:38077 (size: 44.3 MB, free: 1987.3 MB)
17/01/29 15:15:25,713 INFO TaskSetManager: Finished task 23.0 in stage 1.0 (TID 29) in 8292 ms on 10.1.2.139 (9/32)
17/01/29 15:15:25,932 INFO BlockManagerInfo: Added rdd_5_25 in memory on 10.1.2.224:33482 (size: 44.3 MB, free: 1943.0 MB)
17/01/29 15:15:25,957 INFO TaskSetManager: Finished task 25.0 in stage 1.0 (TID 30) in 8534 ms on 10.1.2.224 (10/32)
17/01/29 15:15:25,991 INFO BlockManagerInfo: Added rdd_5_11 in memory on 10.1.2.224:33482 (size: 44.4 MB, free: 1898.6 MB)
17/01/29 15:15:26,012 INFO TaskSetManager: Finished task 11.0 in stage 1.0 (TID 24) in 8601 ms on 10.1.2.224 (11/32)
17/01/29 15:15:26,454 INFO BlockManagerInfo: Added rdd_5_21 in memory on 10.1.2.176:33908 (size: 44.4 MB, free: 1987.2 MB)
17/01/29 15:15:26,482 INFO TaskSetManager: Finished task 21.0 in stage 1.0 (TID 28) in 9062 ms on 10.1.2.176 (12/32)
17/01/29 15:15:26,552 INFO BlockManagerInfo: Added rdd_5_2 in memory on 10.1.2.176:33908 (size: 44.4 MB, free: 1942.8 MB)
17/01/29 15:15:26,573 INFO TaskSetManager: Finished task 2.0 in stage 1.0 (TID 20) in 9171 ms on 10.1.2.176 (13/32)
17/01/29 15:15:26,576 INFO BlockManagerInfo: Added rdd_5_13 in memory on 10.1.2.191:36335 (size: 44.4 MB, free: 2031.6 MB)
17/01/29 15:15:26,595 INFO TaskSetManager: Finished task 13.0 in stage 1.0 (TID 14) in 12724 ms on 10.1.2.191 (14/32)
17/01/29 15:15:26,627 INFO BlockManagerInfo: Added rdd_5_26 in memory on 10.1.2.28:35923 (size: 44.4 MB, free: 2.0 GB)
17/01/29 15:15:26,695 INFO TaskSetManager: Finished task 26.0 in stage 1.0 (TID 15) in 12822 ms on 10.1.2.28 (15/32)
17/01/29 15:15:26,760 INFO BlockManagerInfo: Added rdd_5_6 in memory on 10.1.2.28:35923 (size: 44.4 MB, free: 2031.6 MB)
17/01/29 15:15:26,778 INFO TaskSetManager: Finished task 6.0 in stage 1.0 (TID 7) in 12920 ms on 10.1.2.28 (16/32)
17/01/29 15:15:27,470 INFO BlockManagerInfo: Added rdd_5_1 in memory on 10.1.2.38:44632 (size: 44.4 MB, free: 2.0 GB)
17/01/29 15:15:27,532 INFO TaskSetManager: Finished task 1.0 in stage 1.0 (TID 2) in 13685 ms on 10.1.2.38 (17/32)
17/01/29 15:15:27,667 INFO BlockManagerInfo: Added rdd_5_27 in memory on 10.1.2.38:44632 (size: 44.4 MB, free: 2031.6 MB)
17/01/29 15:15:27,691 INFO TaskSetManager: Finished task 27.0 in stage 1.0 (TID 17) in 13815 ms on 10.1.2.38 (18/32)
17/01/29 15:15:27,860 INFO BlockManagerInfo: Added rdd_5_14 in memory on 10.1.2.191:36335 (size: 44.4 MB, free: 1987.2 MB)
17/01/29 15:15:27,861 INFO BlockManagerInfo: Added rdd_5_29 in memory on 10.1.2.66:39959 (size: 44.4 MB, free: 2.0 GB)
17/01/29 15:15:27,879 INFO BlockManagerInfo: Added rdd_5_17 in memory on 10.1.2.38:44632 (size: 44.4 MB, free: 1987.1 MB)
17/01/29 15:15:27,882 INFO TaskSetManager: Finished task 14.0 in stage 1.0 (TID 25) in 10469 ms on 10.1.2.191 (19/32)
17/01/29 15:15:27,898 INFO TaskSetManager: Finished task 17.0 in stage 1.0 (TID 10) in 14035 ms on 10.1.2.38 (20/32)
17/01/29 15:15:27,918 INFO TaskSetManager: Finished task 29.0 in stage 1.0 (TID 19) in 14038 ms on 10.1.2.66 (21/32)
17/01/29 15:15:28,288 INFO BlockManagerInfo: Added rdd_5_4 in memory on 10.1.2.38:44632 (size: 44.4 MB, free: 1942.7 MB)
17/01/29 15:15:28,304 INFO TaskSetManager: Finished task 4.0 in stage 1.0 (TID 21) in 10900 ms on 10.1.2.38 (22/32)
17/01/29 15:15:28,370 INFO BlockManagerInfo: Added rdd_5_22 in memory on 10.1.2.66:39959 (size: 44.3 MB, free: 2031.7 MB)
17/01/29 15:15:28,395 INFO TaskSetManager: Finished task 22.0 in stage 1.0 (TID 13) in 14525 ms on 10.1.2.66 (23/32)
17/01/29 15:15:28,429 INFO BlockManagerInfo: Added rdd_5_3 in memory on 10.1.2.65:41459 (size: 44.4 MB, free: 2.0 GB)
17/01/29 15:15:28,533 INFO TaskSetManager: Finished task 3.0 in stage 1.0 (TID 3) in 14685 ms on 10.1.2.65 (24/32)
17/01/29 15:15:28,548 INFO BlockManagerInfo: Added rdd_5_5 in memory on 10.1.2.66:39959 (size: 44.3 MB, free: 1987.4 MB)
17/01/29 15:15:28,567 INFO TaskSetManager: Finished task 5.0 in stage 1.0 (TID 5) in 14714 ms on 10.1.2.66 (25/32)
17/01/29 15:15:28,600 INFO BlockManagerInfo: Added rdd_5_28 in memory on 10.1.2.191:36335 (size: 44.4 MB, free: 1942.8 MB)
17/01/29 15:15:28,619 INFO TaskSetManager: Finished task 28.0 in stage 1.0 (TID 31) in 11194 ms on 10.1.2.191 (26/32)
17/01/29 15:15:28,676 INFO BlockManagerInfo: Added rdd_5_31 in memory on 10.1.2.65:41459 (size: 44.3 MB, free: 2031.7 MB)
17/01/29 15:15:28,701 INFO BlockManagerInfo: Added rdd_5_19 in memory on 10.1.2.65:41459 (size: 44.4 MB, free: 1987.2 MB)
17/01/29 15:15:28,702 INFO TaskSetManager: Finished task 31.0 in stage 1.0 (TID 18) in 14824 ms on 10.1.2.65 (27/32)
17/01/29 15:15:28,730 INFO TaskSetManager: Finished task 19.0 in stage 1.0 (TID 11) in 14865 ms on 10.1.2.65 (28/32)
17/01/29 15:15:28,851 INFO BlockManagerInfo: Added rdd_5_18 in memory on 10.1.2.28:35923 (size: 44.3 MB, free: 1987.3 MB)
17/01/29 15:15:28,909 INFO TaskSetManager: Finished task 18.0 in stage 1.0 (TID 27) in 11491 ms on 10.1.2.28 (29/32)
17/01/29 15:15:29,020 INFO BlockManagerInfo: Added rdd_5_30 in memory on 10.1.2.28:35923 (size: 44.4 MB, free: 1942.9 MB)
17/01/29 15:15:29,026 INFO BlockManagerInfo: Added rdd_5_9 in memory on 10.1.2.66:39959 (size: 44.4 MB, free: 1943.0 MB)
17/01/29 15:15:29,037 INFO TaskSetManager: Finished task 30.0 in stage 1.0 (TID 32) in 11611 ms on 10.1.2.28 (30/32)
17/01/29 15:15:29,043 INFO TaskSetManager: Finished task 9.0 in stage 1.0 (TID 23) in 11634 ms on 10.1.2.66 (31/32)
17/01/29 15:15:29,241 INFO BlockManagerInfo: Added rdd_5_16 in memory on 10.1.2.65:41459 (size: 44.4 MB, free: 1942.8 MB)
17/01/29 15:15:29,256 INFO TaskSetManager: Finished task 16.0 in stage 1.0 (TID 26) in 11841 ms on 10.1.2.65 (32/32)
17/01/29 15:15:29,256 INFO TaskSchedulerImpl: Removed TaskSet 1.0, whose tasks have all completed, from pool 
17/01/29 15:15:29,256 INFO DAGScheduler: ResultStage 1 (count at DataValidators.scala:40) finished in 15.415 s
17/01/29 15:15:29,257 INFO DAGScheduler: Job 1 finished: count at DataValidators.scala:40, took 15.440844 s
17/01/29 15:15:29,266 INFO SparkContext: Starting job: count at GradientDescent.scala:209
17/01/29 15:15:29,268 INFO DAGScheduler: Got job 2 (count at GradientDescent.scala:209) with 32 output partitions
17/01/29 15:15:29,268 INFO DAGScheduler: Final stage: ResultStage 2 (count at GradientDescent.scala:209)
17/01/29 15:15:29,268 INFO DAGScheduler: Parents of final stage: List()
17/01/29 15:15:29,270 INFO DAGScheduler: Missing parents: List()
17/01/29 15:15:29,271 INFO DAGScheduler: Submitting ResultStage 2 (MapPartitionsRDD[8] at map at GeneralizedLinearAlgorithm.scala:297), which has no missing parents
17/01/29 15:15:29,275 INFO MemoryStore: Block broadcast_3 stored as values in memory (estimated size 3.9 KB, free 2.1 GB)
17/01/29 15:15:29,277 INFO MemoryStore: Block broadcast_3_piece0 stored as bytes in memory (estimated size 2.2 KB, free 2.1 GB)
17/01/29 15:15:29,278 INFO BlockManagerInfo: Added broadcast_3_piece0 in memory on 10.1.2.152:36982 (size: 2.2 KB, free: 2.1 GB)
17/01/29 15:15:29,279 INFO SparkContext: Created broadcast 3 from broadcast at DAGScheduler.scala:1012
17/01/29 15:15:29,279 INFO DAGScheduler: Submitting 32 missing tasks from ResultStage 2 (MapPartitionsRDD[8] at map at GeneralizedLinearAlgorithm.scala:297)
17/01/29 15:15:29,280 INFO TaskSchedulerImpl: Adding task set 2.0 with 32 tasks
17/01/29 15:15:29,284 INFO TaskSetManager: Starting task 2.0 in stage 2.0 (TID 33, 10.1.2.176, partition 2, PROCESS_LOCAL, 5373 bytes)
17/01/29 15:15:29,287 INFO TaskSetManager: Starting task 12.0 in stage 2.0 (TID 34, 10.1.2.191, partition 12, PROCESS_LOCAL, 5373 bytes)
17/01/29 15:15:29,288 INFO TaskSetManager: Starting task 5.0 in stage 2.0 (TID 35, 10.1.2.66, partition 5, PROCESS_LOCAL, 5373 bytes)
17/01/29 15:15:29,290 INFO TaskSetManager: Starting task 0.0 in stage 2.0 (TID 36, 10.1.2.224, partition 0, PROCESS_LOCAL, 5373 bytes)
17/01/29 15:15:29,292 INFO TaskSetManager: Starting task 7.0 in stage 2.0 (TID 37, 10.1.2.139, partition 7, PROCESS_LOCAL, 5373 bytes)
17/01/29 15:15:29,294 INFO TaskSetManager: Starting task 3.0 in stage 2.0 (TID 38, 10.1.2.65, partition 3, PROCESS_LOCAL, 5373 bytes)
17/01/29 15:15:29,295 INFO TaskSetManager: Starting task 6.0 in stage 2.0 (TID 39, 10.1.2.28, partition 6, PROCESS_LOCAL, 5373 bytes)
17/01/29 15:15:29,297 INFO TaskSetManager: Starting task 1.0 in stage 2.0 (TID 40, 10.1.2.38, partition 1, PROCESS_LOCAL, 5373 bytes)
17/01/29 15:15:29,299 INFO TaskSetManager: Starting task 15.0 in stage 2.0 (TID 41, 10.1.2.176, partition 15, PROCESS_LOCAL, 5373 bytes)
17/01/29 15:15:29,300 INFO TaskSetManager: Starting task 13.0 in stage 2.0 (TID 42, 10.1.2.191, partition 13, PROCESS_LOCAL, 5373 bytes)
17/01/29 15:15:29,302 INFO TaskSetManager: Starting task 9.0 in stage 2.0 (TID 43, 10.1.2.66, partition 9, PROCESS_LOCAL, 5373 bytes)
17/01/29 15:15:29,303 INFO TaskSetManager: Starting task 10.0 in stage 2.0 (TID 44, 10.1.2.224, partition 10, PROCESS_LOCAL, 5373 bytes)
17/01/29 15:15:29,304 INFO TaskSetManager: Starting task 8.0 in stage 2.0 (TID 45, 10.1.2.139, partition 8, PROCESS_LOCAL, 5373 bytes)
17/01/29 15:15:29,305 INFO TaskSetManager: Starting task 16.0 in stage 2.0 (TID 46, 10.1.2.65, partition 16, PROCESS_LOCAL, 5373 bytes)
17/01/29 15:15:29,307 INFO TaskSetManager: Starting task 18.0 in stage 2.0 (TID 47, 10.1.2.28, partition 18, PROCESS_LOCAL, 5373 bytes)
17/01/29 15:15:29,308 INFO TaskSetManager: Starting task 4.0 in stage 2.0 (TID 48, 10.1.2.38, partition 4, PROCESS_LOCAL, 5373 bytes)
17/01/29 15:15:29,309 INFO TaskSetManager: Starting task 21.0 in stage 2.0 (TID 49, 10.1.2.176, partition 21, PROCESS_LOCAL, 5373 bytes)
17/01/29 15:15:29,310 INFO TaskSetManager: Starting task 14.0 in stage 2.0 (TID 50, 10.1.2.191, partition 14, PROCESS_LOCAL, 5373 bytes)
17/01/29 15:15:29,311 INFO TaskSetManager: Starting task 22.0 in stage 2.0 (TID 51, 10.1.2.66, partition 22, PROCESS_LOCAL, 5373 bytes)
17/01/29 15:15:29,312 INFO TaskSetManager: Starting task 11.0 in stage 2.0 (TID 52, 10.1.2.224, partition 11, PROCESS_LOCAL, 5373 bytes)
17/01/29 15:15:29,314 INFO TaskSetManager: Starting task 23.0 in stage 2.0 (TID 53, 10.1.2.139, partition 23, PROCESS_LOCAL, 5373 bytes)
17/01/29 15:15:29,315 INFO TaskSetManager: Starting task 19.0 in stage 2.0 (TID 54, 10.1.2.65, partition 19, PROCESS_LOCAL, 5373 bytes)
17/01/29 15:15:29,316 INFO TaskSetManager: Starting task 26.0 in stage 2.0 (TID 55, 10.1.2.28, partition 26, PROCESS_LOCAL, 5373 bytes)
17/01/29 15:15:29,318 INFO TaskSetManager: Starting task 17.0 in stage 2.0 (TID 56, 10.1.2.38, partition 17, PROCESS_LOCAL, 5373 bytes)
17/01/29 15:15:29,319 INFO TaskSetManager: Starting task 24.0 in stage 2.0 (TID 57, 10.1.2.176, partition 24, PROCESS_LOCAL, 5373 bytes)
17/01/29 15:15:29,320 INFO TaskSetManager: Starting task 28.0 in stage 2.0 (TID 58, 10.1.2.191, partition 28, PROCESS_LOCAL, 5373 bytes)
17/01/29 15:15:29,322 INFO TaskSetManager: Starting task 29.0 in stage 2.0 (TID 59, 10.1.2.66, partition 29, PROCESS_LOCAL, 5373 bytes)
17/01/29 15:15:29,323 INFO TaskSetManager: Starting task 20.0 in stage 2.0 (TID 60, 10.1.2.224, partition 20, PROCESS_LOCAL, 5373 bytes)
17/01/29 15:15:29,324 INFO TaskSetManager: Starting task 31.0 in stage 2.0 (TID 61, 10.1.2.65, partition 31, PROCESS_LOCAL, 5373 bytes)
17/01/29 15:15:29,326 INFO TaskSetManager: Starting task 30.0 in stage 2.0 (TID 62, 10.1.2.28, partition 30, PROCESS_LOCAL, 5373 bytes)
17/01/29 15:15:29,327 INFO TaskSetManager: Starting task 27.0 in stage 2.0 (TID 63, 10.1.2.38, partition 27, PROCESS_LOCAL, 5373 bytes)
17/01/29 15:15:29,328 INFO CoarseGrainedSchedulerBackend$DriverEndpoint: Launching task 33 on executor id: 5 hostname: 10.1.2.176.
17/01/29 15:15:29,329 INFO CoarseGrainedSchedulerBackend$DriverEndpoint: Launching task 41 on executor id: 5 hostname: 10.1.2.176.
17/01/29 15:15:29,330 INFO CoarseGrainedSchedulerBackend$DriverEndpoint: Launching task 49 on executor id: 5 hostname: 10.1.2.176.
17/01/29 15:15:29,331 INFO CoarseGrainedSchedulerBackend$DriverEndpoint: Launching task 57 on executor id: 5 hostname: 10.1.2.176.
17/01/29 15:15:29,332 INFO CoarseGrainedSchedulerBackend$DriverEndpoint: Launching task 34 on executor id: 1 hostname: 10.1.2.191.
17/01/29 15:15:29,333 INFO CoarseGrainedSchedulerBackend$DriverEndpoint: Launching task 42 on executor id: 1 hostname: 10.1.2.191.
17/01/29 15:15:29,334 INFO CoarseGrainedSchedulerBackend$DriverEndpoint: Launching task 50 on executor id: 1 hostname: 10.1.2.191.
17/01/29 15:15:29,335 INFO CoarseGrainedSchedulerBackend$DriverEndpoint: Launching task 58 on executor id: 1 hostname: 10.1.2.191.
17/01/29 15:15:29,335 INFO CoarseGrainedSchedulerBackend$DriverEndpoint: Launching task 35 on executor id: 3 hostname: 10.1.2.66.
17/01/29 15:15:29,336 INFO CoarseGrainedSchedulerBackend$DriverEndpoint: Launching task 43 on executor id: 3 hostname: 10.1.2.66.
17/01/29 15:15:29,337 INFO CoarseGrainedSchedulerBackend$DriverEndpoint: Launching task 51 on executor id: 3 hostname: 10.1.2.66.
17/01/29 15:15:29,337 INFO CoarseGrainedSchedulerBackend$DriverEndpoint: Launching task 59 on executor id: 3 hostname: 10.1.2.66.
17/01/29 15:15:29,338 INFO CoarseGrainedSchedulerBackend$DriverEndpoint: Launching task 36 on executor id: 4 hostname: 10.1.2.224.
17/01/29 15:15:29,339 INFO CoarseGrainedSchedulerBackend$DriverEndpoint: Launching task 44 on executor id: 4 hostname: 10.1.2.224.
17/01/29 15:15:29,340 INFO CoarseGrainedSchedulerBackend$DriverEndpoint: Launching task 52 on executor id: 4 hostname: 10.1.2.224.
17/01/29 15:15:29,341 INFO CoarseGrainedSchedulerBackend$DriverEndpoint: Launching task 60 on executor id: 4 hostname: 10.1.2.224.
17/01/29 15:15:29,342 INFO CoarseGrainedSchedulerBackend$DriverEndpoint: Launching task 37 on executor id: 0 hostname: 10.1.2.139.
17/01/29 15:15:29,342 INFO CoarseGrainedSchedulerBackend$DriverEndpoint: Launching task 45 on executor id: 0 hostname: 10.1.2.139.
17/01/29 15:15:29,342 INFO CoarseGrainedSchedulerBackend$DriverEndpoint: Launching task 53 on executor id: 0 hostname: 10.1.2.139.
17/01/29 15:15:29,343 INFO CoarseGrainedSchedulerBackend$DriverEndpoint: Launching task 38 on executor id: 2 hostname: 10.1.2.65.
17/01/29 15:15:29,343 INFO CoarseGrainedSchedulerBackend$DriverEndpoint: Launching task 46 on executor id: 2 hostname: 10.1.2.65.
17/01/29 15:15:29,343 INFO CoarseGrainedSchedulerBackend$DriverEndpoint: Launching task 54 on executor id: 2 hostname: 10.1.2.65.
17/01/29 15:15:29,345 INFO CoarseGrainedSchedulerBackend$DriverEndpoint: Launching task 61 on executor id: 2 hostname: 10.1.2.65.
17/01/29 15:15:29,346 INFO CoarseGrainedSchedulerBackend$DriverEndpoint: Launching task 39 on executor id: 7 hostname: 10.1.2.28.
17/01/29 15:15:29,346 INFO CoarseGrainedSchedulerBackend$DriverEndpoint: Launching task 47 on executor id: 7 hostname: 10.1.2.28.
17/01/29 15:15:29,347 INFO CoarseGrainedSchedulerBackend$DriverEndpoint: Launching task 55 on executor id: 7 hostname: 10.1.2.28.
17/01/29 15:15:29,351 INFO CoarseGrainedSchedulerBackend$DriverEndpoint: Launching task 62 on executor id: 7 hostname: 10.1.2.28.
17/01/29 15:15:29,355 INFO CoarseGrainedSchedulerBackend$DriverEndpoint: Launching task 40 on executor id: 6 hostname: 10.1.2.38.
17/01/29 15:15:29,358 INFO CoarseGrainedSchedulerBackend$DriverEndpoint: Launching task 48 on executor id: 6 hostname: 10.1.2.38.
17/01/29 15:15:29,359 INFO CoarseGrainedSchedulerBackend$DriverEndpoint: Launching task 56 on executor id: 6 hostname: 10.1.2.38.
17/01/29 15:15:29,360 INFO CoarseGrainedSchedulerBackend$DriverEndpoint: Launching task 63 on executor id: 6 hostname: 10.1.2.38.
17/01/29 15:15:29,373 INFO BlockManagerInfo: Added broadcast_3_piece0 in memory on 10.1.2.66:39959 (size: 2.2 KB, free: 1943.0 MB)
17/01/29 15:15:29,374 INFO BlockManagerInfo: Added broadcast_3_piece0 in memory on 10.1.2.191:36335 (size: 2.2 KB, free: 1942.8 MB)
17/01/29 15:15:29,374 INFO BlockManagerInfo: Added broadcast_3_piece0 in memory on 10.1.2.224:33482 (size: 2.2 KB, free: 1898.6 MB)
17/01/29 15:15:29,375 INFO BlockManagerInfo: Added broadcast_3_piece0 in memory on 10.1.2.65:41459 (size: 2.2 KB, free: 1942.8 MB)
17/01/29 15:15:29,378 INFO BlockManagerInfo: Added broadcast_3_piece0 in memory on 10.1.2.176:33908 (size: 2.2 KB, free: 1942.8 MB)
17/01/29 15:15:29,383 INFO BlockManagerInfo: Added broadcast_3_piece0 in memory on 10.1.2.139:38077 (size: 2.2 KB, free: 1987.3 MB)
17/01/29 15:15:29,403 INFO BlockManagerInfo: Added broadcast_3_piece0 in memory on 10.1.2.28:35923 (size: 2.2 KB, free: 1942.9 MB)
17/01/29 15:15:29,407 INFO BlockManagerInfo: Added broadcast_3_piece0 in memory on 10.1.2.38:44632 (size: 2.2 KB, free: 1942.7 MB)
17/01/29 15:15:29,411 INFO TaskSetManager: Finished task 20.0 in stage 2.0 (TID 60) in 89 ms on 10.1.2.224 (1/32)
17/01/29 15:15:29,413 INFO TaskSetManager: Starting task 25.0 in stage 2.0 (TID 64, 10.1.2.224, partition 25, PROCESS_LOCAL, 5373 bytes)
17/01/29 15:15:29,414 INFO CoarseGrainedSchedulerBackend$DriverEndpoint: Launching task 64 on executor id: 4 hostname: 10.1.2.224.
17/01/29 15:15:29,415 INFO TaskSetManager: Finished task 10.0 in stage 2.0 (TID 44) in 113 ms on 10.1.2.224 (2/32)
17/01/29 15:15:29,419 INFO TaskSetManager: Finished task 0.0 in stage 2.0 (TID 36) in 130 ms on 10.1.2.224 (3/32)
17/01/29 15:15:29,419 INFO TaskSetManager: Finished task 15.0 in stage 2.0 (TID 41) in 122 ms on 10.1.2.176 (4/32)
17/01/29 15:15:29,420 INFO TaskSetManager: Finished task 5.0 in stage 2.0 (TID 35) in 132 ms on 10.1.2.66 (5/32)
17/01/29 15:15:29,421 INFO TaskSetManager: Finished task 11.0 in stage 2.0 (TID 52) in 109 ms on 10.1.2.224 (6/32)
17/01/29 15:15:29,422 INFO TaskSetManager: Finished task 12.0 in stage 2.0 (TID 34) in 137 ms on 10.1.2.191 (7/32)
17/01/29 15:15:29,422 INFO TaskSetManager: Finished task 24.0 in stage 2.0 (TID 57) in 104 ms on 10.1.2.176 (8/32)
17/01/29 15:15:29,423 INFO TaskSetManager: Finished task 3.0 in stage 2.0 (TID 38) in 131 ms on 10.1.2.65 (9/32)
17/01/29 15:15:29,424 INFO TaskSetManager: Finished task 16.0 in stage 2.0 (TID 46) in 119 ms on 10.1.2.65 (10/32)
17/01/29 15:15:29,426 INFO TaskSetManager: Finished task 13.0 in stage 2.0 (TID 42) in 127 ms on 10.1.2.191 (11/32)
17/01/29 15:15:29,427 INFO TaskSetManager: Finished task 14.0 in stage 2.0 (TID 50) in 117 ms on 10.1.2.191 (12/32)
17/01/29 15:15:29,428 INFO TaskSetManager: Finished task 8.0 in stage 2.0 (TID 45) in 124 ms on 10.1.2.139 (13/32)
17/01/29 15:15:29,430 INFO TaskSetManager: Finished task 31.0 in stage 2.0 (TID 61) in 106 ms on 10.1.2.65 (14/32)
17/01/29 15:15:29,431 INFO TaskSetManager: Finished task 19.0 in stage 2.0 (TID 54) in 117 ms on 10.1.2.65 (15/32)
17/01/29 15:15:29,434 INFO TaskSetManager: Finished task 28.0 in stage 2.0 (TID 58) in 114 ms on 10.1.2.191 (16/32)
17/01/29 15:15:29,434 INFO TaskSetManager: Finished task 22.0 in stage 2.0 (TID 51) in 123 ms on 10.1.2.66 (17/32)
17/01/29 15:15:29,441 INFO TaskSetManager: Finished task 25.0 in stage 2.0 (TID 64) in 29 ms on 10.1.2.224 (18/32)
17/01/29 15:15:29,443 INFO TaskSetManager: Finished task 27.0 in stage 2.0 (TID 63) in 116 ms on 10.1.2.38 (19/32)
17/01/29 15:15:29,447 INFO TaskSetManager: Finished task 7.0 in stage 2.0 (TID 37) in 157 ms on 10.1.2.139 (20/32)
17/01/29 15:15:29,454 INFO TaskSetManager: Finished task 30.0 in stage 2.0 (TID 62) in 129 ms on 10.1.2.28 (21/32)
17/01/29 15:15:29,456 INFO TaskSetManager: Finished task 18.0 in stage 2.0 (TID 47) in 150 ms on 10.1.2.28 (22/32)
17/01/29 15:15:29,457 INFO TaskSetManager: Finished task 26.0 in stage 2.0 (TID 55) in 141 ms on 10.1.2.28 (23/32)
17/01/29 15:15:29,468 INFO TaskSetManager: Finished task 29.0 in stage 2.0 (TID 59) in 147 ms on 10.1.2.66 (24/32)
17/01/29 15:15:29,476 INFO TaskSetManager: Finished task 21.0 in stage 2.0 (TID 49) in 168 ms on 10.1.2.176 (25/32)
17/01/29 15:15:29,503 INFO TaskSetManager: Finished task 6.0 in stage 2.0 (TID 39) in 209 ms on 10.1.2.28 (26/32)
17/01/29 15:15:29,514 INFO TaskSetManager: Finished task 2.0 in stage 2.0 (TID 33) in 233 ms on 10.1.2.176 (27/32)
17/01/29 15:15:29,556 INFO TaskSetManager: Finished task 23.0 in stage 2.0 (TID 53) in 242 ms on 10.1.2.139 (28/32)
17/01/29 15:15:29,563 INFO TaskSetManager: Finished task 1.0 in stage 2.0 (TID 40) in 268 ms on 10.1.2.38 (29/32)
17/01/29 15:15:29,607 INFO TaskSetManager: Finished task 9.0 in stage 2.0 (TID 43) in 307 ms on 10.1.2.66 (30/32)
17/01/29 15:15:29,609 INFO TaskSetManager: Finished task 4.0 in stage 2.0 (TID 48) in 302 ms on 10.1.2.38 (31/32)
17/01/29 15:15:29,684 INFO TaskSetManager: Finished task 17.0 in stage 2.0 (TID 56) in 366 ms on 10.1.2.38 (32/32)
17/01/29 15:15:29,684 INFO TaskSchedulerImpl: Removed TaskSet 2.0, whose tasks have all completed, from pool 
17/01/29 15:15:29,684 INFO DAGScheduler: ResultStage 2 (count at GradientDescent.scala:209) finished in 0.403 s
17/01/29 15:15:29,685 INFO DAGScheduler: Job 2 finished: count at GradientDescent.scala:209, took 0.418197 s
17/01/29 15:15:29,917 WARN BLAS: Failed to load implementation from: com.github.fommil.netlib.NativeSystemBLAS
17/01/29 15:15:29,917 WARN BLAS: Failed to load implementation from: com.github.fommil.netlib.NativeRefBLAS
17/01/29 15:15:29,941 INFO MemoryStore: Block broadcast_4 stored as values in memory (estimated size 200.0 B, free 2.1 GB)
17/01/29 15:15:29,945 INFO MemoryStore: Block broadcast_4_piece0 stored as bytes in memory (estimated size 153.0 B, free 2.1 GB)
17/01/29 15:15:29,946 INFO BlockManagerInfo: Added broadcast_4_piece0 in memory on 10.1.2.152:36982 (size: 153.0 B, free: 2.1 GB)
17/01/29 15:15:29,947 INFO SparkContext: Created broadcast 4 from broadcast at GradientDescent.scala:235
17/01/29 15:15:29,996 INFO SparkContext: Starting job: treeAggregate at GradientDescent.scala:239
17/01/29 15:15:30,002 INFO DAGScheduler: Registering RDD 11 (treeAggregate at GradientDescent.scala:239)
17/01/29 15:15:30,003 INFO DAGScheduler: Got job 3 (treeAggregate at GradientDescent.scala:239) with 5 output partitions
17/01/29 15:15:30,003 INFO DAGScheduler: Final stage: ResultStage 4 (treeAggregate at GradientDescent.scala:239)
17/01/29 15:15:30,003 INFO DAGScheduler: Parents of final stage: List(ShuffleMapStage 3)
17/01/29 15:15:30,003 INFO DAGScheduler: Missing parents: List(ShuffleMapStage 3)
17/01/29 15:15:30,006 INFO DAGScheduler: Submitting ShuffleMapStage 3 (MapPartitionsRDD[11] at treeAggregate at GradientDescent.scala:239), which has no missing parents
17/01/29 15:15:30,020 INFO MemoryStore: Block broadcast_5 stored as values in memory (estimated size 7.1 KB, free 2.1 GB)
17/01/29 15:15:30,022 INFO MemoryStore: Block broadcast_5_piece0 stored as bytes in memory (estimated size 3.7 KB, free 2.1 GB)
17/01/29 15:15:30,023 INFO BlockManagerInfo: Added broadcast_5_piece0 in memory on 10.1.2.152:36982 (size: 3.7 KB, free: 2.1 GB)
17/01/29 15:15:30,023 INFO SparkContext: Created broadcast 5 from broadcast at DAGScheduler.scala:1012
17/01/29 15:15:30,025 INFO DAGScheduler: Submitting 32 missing tasks from ShuffleMapStage 3 (MapPartitionsRDD[11] at treeAggregate at GradientDescent.scala:239)
17/01/29 15:15:30,026 INFO TaskSchedulerImpl: Adding task set 3.0 with 32 tasks
17/01/29 15:15:30,030 INFO TaskSetManager: Starting task 3.0 in stage 3.0 (TID 65, 10.1.2.65, partition 3, PROCESS_LOCAL, 5562 bytes)
17/01/29 15:15:30,030 INFO TaskSetManager: Starting task 5.0 in stage 3.0 (TID 66, 10.1.2.66, partition 5, PROCESS_LOCAL, 5562 bytes)
17/01/29 15:15:30,031 INFO TaskSetManager: Starting task 1.0 in stage 3.0 (TID 67, 10.1.2.38, partition 1, PROCESS_LOCAL, 5562 bytes)
17/01/29 15:15:30,032 INFO TaskSetManager: Starting task 0.0 in stage 3.0 (TID 68, 10.1.2.224, partition 0, PROCESS_LOCAL, 5562 bytes)
17/01/29 15:15:30,032 INFO TaskSetManager: Starting task 7.0 in stage 3.0 (TID 69, 10.1.2.139, partition 7, PROCESS_LOCAL, 5562 bytes)
17/01/29 15:15:30,033 INFO TaskSetManager: Starting task 6.0 in stage 3.0 (TID 70, 10.1.2.28, partition 6, PROCESS_LOCAL, 5562 bytes)
17/01/29 15:15:30,034 INFO TaskSetManager: Starting task 12.0 in stage 3.0 (TID 71, 10.1.2.191, partition 12, PROCESS_LOCAL, 5562 bytes)
17/01/29 15:15:30,034 INFO TaskSetManager: Starting task 2.0 in stage 3.0 (TID 72, 10.1.2.176, partition 2, PROCESS_LOCAL, 5562 bytes)
17/01/29 15:15:30,035 INFO TaskSetManager: Starting task 16.0 in stage 3.0 (TID 73, 10.1.2.65, partition 16, PROCESS_LOCAL, 5562 bytes)
17/01/29 15:15:30,035 INFO TaskSetManager: Starting task 9.0 in stage 3.0 (TID 74, 10.1.2.66, partition 9, PROCESS_LOCAL, 5562 bytes)
17/01/29 15:15:30,036 INFO TaskSetManager: Starting task 4.0 in stage 3.0 (TID 75, 10.1.2.38, partition 4, PROCESS_LOCAL, 5562 bytes)
17/01/29 15:15:30,037 INFO TaskSetManager: Starting task 10.0 in stage 3.0 (TID 76, 10.1.2.224, partition 10, PROCESS_LOCAL, 5562 bytes)
17/01/29 15:15:30,037 INFO TaskSetManager: Starting task 8.0 in stage 3.0 (TID 77, 10.1.2.139, partition 8, PROCESS_LOCAL, 5562 bytes)
17/01/29 15:15:30,038 INFO TaskSetManager: Starting task 18.0 in stage 3.0 (TID 78, 10.1.2.28, partition 18, PROCESS_LOCAL, 5562 bytes)
17/01/29 15:15:30,038 INFO TaskSetManager: Starting task 13.0 in stage 3.0 (TID 79, 10.1.2.191, partition 13, PROCESS_LOCAL, 5562 bytes)
17/01/29 15:15:30,039 INFO TaskSetManager: Starting task 15.0 in stage 3.0 (TID 80, 10.1.2.176, partition 15, PROCESS_LOCAL, 5562 bytes)
17/01/29 15:15:30,040 INFO TaskSetManager: Starting task 19.0 in stage 3.0 (TID 81, 10.1.2.65, partition 19, PROCESS_LOCAL, 5562 bytes)
17/01/29 15:15:30,040 INFO TaskSetManager: Starting task 22.0 in stage 3.0 (TID 82, 10.1.2.66, partition 22, PROCESS_LOCAL, 5562 bytes)
17/01/29 15:15:30,041 INFO TaskSetManager: Starting task 17.0 in stage 3.0 (TID 83, 10.1.2.38, partition 17, PROCESS_LOCAL, 5562 bytes)
17/01/29 15:15:30,041 INFO TaskSetManager: Starting task 11.0 in stage 3.0 (TID 84, 10.1.2.224, partition 11, PROCESS_LOCAL, 5562 bytes)
17/01/29 15:15:30,042 INFO TaskSetManager: Starting task 23.0 in stage 3.0 (TID 85, 10.1.2.139, partition 23, PROCESS_LOCAL, 5562 bytes)
17/01/29 15:15:30,043 INFO TaskSetManager: Starting task 26.0 in stage 3.0 (TID 86, 10.1.2.28, partition 26, PROCESS_LOCAL, 5562 bytes)
17/01/29 15:15:30,043 INFO TaskSetManager: Starting task 14.0 in stage 3.0 (TID 87, 10.1.2.191, partition 14, PROCESS_LOCAL, 5562 bytes)
17/01/29 15:15:30,044 INFO TaskSetManager: Starting task 21.0 in stage 3.0 (TID 88, 10.1.2.176, partition 21, PROCESS_LOCAL, 5562 bytes)
17/01/29 15:15:30,045 INFO TaskSetManager: Starting task 31.0 in stage 3.0 (TID 89, 10.1.2.65, partition 31, PROCESS_LOCAL, 5562 bytes)
17/01/29 15:15:30,045 INFO TaskSetManager: Starting task 29.0 in stage 3.0 (TID 90, 10.1.2.66, partition 29, PROCESS_LOCAL, 5562 bytes)
17/01/29 15:15:30,046 INFO TaskSetManager: Starting task 27.0 in stage 3.0 (TID 91, 10.1.2.38, partition 27, PROCESS_LOCAL, 5562 bytes)
17/01/29 15:15:30,046 INFO TaskSetManager: Starting task 20.0 in stage 3.0 (TID 92, 10.1.2.224, partition 20, PROCESS_LOCAL, 5562 bytes)
17/01/29 15:15:30,047 INFO TaskSetManager: Starting task 30.0 in stage 3.0 (TID 93, 10.1.2.28, partition 30, PROCESS_LOCAL, 5562 bytes)
17/01/29 15:15:30,048 INFO TaskSetManager: Starting task 28.0 in stage 3.0 (TID 94, 10.1.2.191, partition 28, PROCESS_LOCAL, 5562 bytes)
17/01/29 15:15:30,048 INFO TaskSetManager: Starting task 24.0 in stage 3.0 (TID 95, 10.1.2.176, partition 24, PROCESS_LOCAL, 5562 bytes)
17/01/29 15:15:30,049 INFO CoarseGrainedSchedulerBackend$DriverEndpoint: Launching task 65 on executor id: 2 hostname: 10.1.2.65.
17/01/29 15:15:30,049 INFO CoarseGrainedSchedulerBackend$DriverEndpoint: Launching task 73 on executor id: 2 hostname: 10.1.2.65.
17/01/29 15:15:30,049 INFO CoarseGrainedSchedulerBackend$DriverEndpoint: Launching task 81 on executor id: 2 hostname: 10.1.2.65.
17/01/29 15:15:30,050 INFO CoarseGrainedSchedulerBackend$DriverEndpoint: Launching task 89 on executor id: 2 hostname: 10.1.2.65.
17/01/29 15:15:30,050 INFO CoarseGrainedSchedulerBackend$DriverEndpoint: Launching task 66 on executor id: 3 hostname: 10.1.2.66.
17/01/29 15:15:30,050 INFO CoarseGrainedSchedulerBackend$DriverEndpoint: Launching task 74 on executor id: 3 hostname: 10.1.2.66.
17/01/29 15:15:30,050 INFO CoarseGrainedSchedulerBackend$DriverEndpoint: Launching task 82 on executor id: 3 hostname: 10.1.2.66.
17/01/29 15:15:30,050 INFO CoarseGrainedSchedulerBackend$DriverEndpoint: Launching task 90 on executor id: 3 hostname: 10.1.2.66.
17/01/29 15:15:30,051 INFO CoarseGrainedSchedulerBackend$DriverEndpoint: Launching task 67 on executor id: 6 hostname: 10.1.2.38.
17/01/29 15:15:30,051 INFO CoarseGrainedSchedulerBackend$DriverEndpoint: Launching task 75 on executor id: 6 hostname: 10.1.2.38.
17/01/29 15:15:30,051 INFO CoarseGrainedSchedulerBackend$DriverEndpoint: Launching task 83 on executor id: 6 hostname: 10.1.2.38.
17/01/29 15:15:30,051 INFO CoarseGrainedSchedulerBackend$DriverEndpoint: Launching task 91 on executor id: 6 hostname: 10.1.2.38.
17/01/29 15:15:30,052 INFO CoarseGrainedSchedulerBackend$DriverEndpoint: Launching task 68 on executor id: 4 hostname: 10.1.2.224.
17/01/29 15:15:30,052 INFO CoarseGrainedSchedulerBackend$DriverEndpoint: Launching task 76 on executor id: 4 hostname: 10.1.2.224.
17/01/29 15:15:30,052 INFO CoarseGrainedSchedulerBackend$DriverEndpoint: Launching task 84 on executor id: 4 hostname: 10.1.2.224.
17/01/29 15:15:30,052 INFO CoarseGrainedSchedulerBackend$DriverEndpoint: Launching task 92 on executor id: 4 hostname: 10.1.2.224.
17/01/29 15:15:30,053 INFO CoarseGrainedSchedulerBackend$DriverEndpoint: Launching task 69 on executor id: 0 hostname: 10.1.2.139.
17/01/29 15:15:30,053 INFO CoarseGrainedSchedulerBackend$DriverEndpoint: Launching task 77 on executor id: 0 hostname: 10.1.2.139.
17/01/29 15:15:30,053 INFO CoarseGrainedSchedulerBackend$DriverEndpoint: Launching task 85 on executor id: 0 hostname: 10.1.2.139.
17/01/29 15:15:30,053 INFO CoarseGrainedSchedulerBackend$DriverEndpoint: Launching task 70 on executor id: 7 hostname: 10.1.2.28.
17/01/29 15:15:30,054 INFO CoarseGrainedSchedulerBackend$DriverEndpoint: Launching task 78 on executor id: 7 hostname: 10.1.2.28.
17/01/29 15:15:30,054 INFO CoarseGrainedSchedulerBackend$DriverEndpoint: Launching task 86 on executor id: 7 hostname: 10.1.2.28.
17/01/29 15:15:30,054 INFO CoarseGrainedSchedulerBackend$DriverEndpoint: Launching task 93 on executor id: 7 hostname: 10.1.2.28.
17/01/29 15:15:30,054 INFO CoarseGrainedSchedulerBackend$DriverEndpoint: Launching task 71 on executor id: 1 hostname: 10.1.2.191.
17/01/29 15:15:30,055 INFO CoarseGrainedSchedulerBackend$DriverEndpoint: Launching task 79 on executor id: 1 hostname: 10.1.2.191.
17/01/29 15:15:30,055 INFO CoarseGrainedSchedulerBackend$DriverEndpoint: Launching task 87 on executor id: 1 hostname: 10.1.2.191.
17/01/29 15:15:30,055 INFO CoarseGrainedSchedulerBackend$DriverEndpoint: Launching task 94 on executor id: 1 hostname: 10.1.2.191.
17/01/29 15:15:30,055 INFO CoarseGrainedSchedulerBackend$DriverEndpoint: Launching task 72 on executor id: 5 hostname: 10.1.2.176.
17/01/29 15:15:30,055 INFO CoarseGrainedSchedulerBackend$DriverEndpoint: Launching task 80 on executor id: 5 hostname: 10.1.2.176.
17/01/29 15:15:30,056 INFO CoarseGrainedSchedulerBackend$DriverEndpoint: Launching task 88 on executor id: 5 hostname: 10.1.2.176.
17/01/29 15:15:30,056 INFO CoarseGrainedSchedulerBackend$DriverEndpoint: Launching task 95 on executor id: 5 hostname: 10.1.2.176.
17/01/29 15:15:30,078 INFO BlockManagerInfo: Added broadcast_5_piece0 in memory on 10.1.2.224:33482 (size: 3.7 KB, free: 1898.6 MB)
17/01/29 15:15:30,079 INFO BlockManagerInfo: Added broadcast_5_piece0 in memory on 10.1.2.28:35923 (size: 3.7 KB, free: 1942.9 MB)
17/01/29 15:15:30,081 INFO BlockManagerInfo: Added broadcast_5_piece0 in memory on 10.1.2.66:39959 (size: 3.7 KB, free: 1943.0 MB)
17/01/29 15:15:30,082 INFO BlockManagerInfo: Added broadcast_5_piece0 in memory on 10.1.2.65:41459 (size: 3.7 KB, free: 1942.8 MB)
17/01/29 15:15:30,082 INFO BlockManagerInfo: Added broadcast_5_piece0 in memory on 10.1.2.139:38077 (size: 3.7 KB, free: 1987.3 MB)
17/01/29 15:15:30,084 INFO BlockManagerInfo: Added broadcast_5_piece0 in memory on 10.1.2.191:36335 (size: 3.7 KB, free: 1942.8 MB)
17/01/29 15:15:30,085 INFO BlockManagerInfo: Added broadcast_5_piece0 in memory on 10.1.2.176:33908 (size: 3.7 KB, free: 1942.8 MB)
17/01/29 15:15:30,089 INFO BlockManagerInfo: Added broadcast_5_piece0 in memory on 10.1.2.38:44632 (size: 3.7 KB, free: 1942.7 MB)
17/01/29 15:15:30,368 INFO BlockManagerInfo: Added broadcast_4_piece0 in memory on 10.1.2.224:33482 (size: 153.0 B, free: 1898.6 MB)
17/01/29 15:15:30,382 INFO BlockManagerInfo: Added broadcast_4_piece0 in memory on 10.1.2.66:39959 (size: 153.0 B, free: 1943.0 MB)
17/01/29 15:15:30,384 INFO BlockManagerInfo: Added broadcast_4_piece0 in memory on 10.1.2.38:44632 (size: 153.0 B, free: 1942.7 MB)
17/01/29 15:15:30,385 INFO BlockManagerInfo: Added broadcast_4_piece0 in memory on 10.1.2.139:38077 (size: 153.0 B, free: 1987.3 MB)
17/01/29 15:15:30,396 INFO BlockManagerInfo: Added broadcast_4_piece0 in memory on 10.1.2.191:36335 (size: 153.0 B, free: 1942.8 MB)
17/01/29 15:15:30,404 INFO BlockManagerInfo: Added broadcast_4_piece0 in memory on 10.1.2.28:35923 (size: 153.0 B, free: 1942.9 MB)
17/01/29 15:15:30,433 INFO BlockManagerInfo: Added broadcast_4_piece0 in memory on 10.1.2.176:33908 (size: 153.0 B, free: 1942.8 MB)
17/01/29 15:15:30,434 INFO BlockManagerInfo: Added broadcast_4_piece0 in memory on 10.1.2.65:41459 (size: 153.0 B, free: 1942.8 MB)
17/01/29 15:15:30,542 INFO TaskSetManager: Starting task 25.0 in stage 3.0 (TID 96, 10.1.2.224, partition 25, PROCESS_LOCAL, 5562 bytes)
17/01/29 15:15:30,543 INFO CoarseGrainedSchedulerBackend$DriverEndpoint: Launching task 96 on executor id: 4 hostname: 10.1.2.224.
17/01/29 15:15:30,545 INFO TaskSetManager: Finished task 0.0 in stage 3.0 (TID 68) in 514 ms on 10.1.2.224 (1/32)
17/01/29 15:15:30,546 INFO TaskSetManager: Finished task 11.0 in stage 3.0 (TID 84) in 505 ms on 10.1.2.224 (2/32)
17/01/29 15:15:30,547 INFO TaskSetManager: Finished task 8.0 in stage 3.0 (TID 77) in 509 ms on 10.1.2.139 (3/32)
17/01/29 15:15:30,548 INFO TaskSetManager: Finished task 4.0 in stage 3.0 (TID 75) in 512 ms on 10.1.2.38 (4/32)
17/01/29 15:15:30,549 INFO TaskSetManager: Finished task 10.0 in stage 3.0 (TID 76) in 512 ms on 10.1.2.224 (5/32)
17/01/29 15:15:30,550 INFO TaskSetManager: Finished task 20.0 in stage 3.0 (TID 92) in 503 ms on 10.1.2.224 (6/32)
17/01/29 15:15:30,551 INFO TaskSetManager: Finished task 7.0 in stage 3.0 (TID 69) in 519 ms on 10.1.2.139 (7/32)
17/01/29 15:15:30,553 INFO TaskSetManager: Finished task 23.0 in stage 3.0 (TID 85) in 510 ms on 10.1.2.139 (8/32)
17/01/29 15:15:30,553 INFO TaskSetManager: Finished task 1.0 in stage 3.0 (TID 67) in 522 ms on 10.1.2.38 (9/32)
17/01/29 15:15:30,555 INFO TaskSetManager: Finished task 27.0 in stage 3.0 (TID 91) in 510 ms on 10.1.2.38 (10/32)
17/01/29 15:15:30,556 INFO TaskSetManager: Finished task 17.0 in stage 3.0 (TID 83) in 516 ms on 10.1.2.38 (11/32)
17/01/29 15:15:30,565 INFO TaskSetManager: Finished task 28.0 in stage 3.0 (TID 94) in 517 ms on 10.1.2.191 (12/32)
17/01/29 15:15:30,566 INFO TaskSetManager: Finished task 12.0 in stage 3.0 (TID 71) in 533 ms on 10.1.2.191 (13/32)
17/01/29 15:15:30,567 INFO TaskSetManager: Finished task 14.0 in stage 3.0 (TID 87) in 524 ms on 10.1.2.191 (14/32)
17/01/29 15:15:30,568 INFO TaskSetManager: Finished task 13.0 in stage 3.0 (TID 79) in 530 ms on 10.1.2.191 (15/32)
17/01/29 15:15:30,584 INFO TaskSetManager: Finished task 30.0 in stage 3.0 (TID 93) in 537 ms on 10.1.2.28 (16/32)
17/01/29 15:15:30,585 INFO TaskSetManager: Finished task 26.0 in stage 3.0 (TID 86) in 543 ms on 10.1.2.28 (17/32)
17/01/29 15:15:30,585 INFO TaskSetManager: Finished task 18.0 in stage 3.0 (TID 78) in 548 ms on 10.1.2.28 (18/32)
17/01/29 15:15:30,586 INFO TaskSetManager: Finished task 6.0 in stage 3.0 (TID 70) in 554 ms on 10.1.2.28 (19/32)
17/01/29 15:15:30,589 INFO TaskSetManager: Finished task 22.0 in stage 3.0 (TID 82) in 548 ms on 10.1.2.66 (20/32)
17/01/29 15:15:30,590 INFO TaskSetManager: Finished task 9.0 in stage 3.0 (TID 74) in 555 ms on 10.1.2.66 (21/32)
17/01/29 15:15:30,592 INFO TaskSetManager: Finished task 29.0 in stage 3.0 (TID 90) in 547 ms on 10.1.2.66 (22/32)
17/01/29 15:15:30,593 INFO TaskSetManager: Finished task 5.0 in stage 3.0 (TID 66) in 562 ms on 10.1.2.66 (23/32)
17/01/29 15:15:30,605 INFO TaskSetManager: Finished task 31.0 in stage 3.0 (TID 89) in 561 ms on 10.1.2.65 (24/32)
17/01/29 15:15:30,605 INFO TaskSetManager: Finished task 3.0 in stage 3.0 (TID 65) in 578 ms on 10.1.2.65 (25/32)
17/01/29 15:15:30,606 INFO TaskSetManager: Finished task 25.0 in stage 3.0 (TID 96) in 64 ms on 10.1.2.224 (26/32)
17/01/29 15:15:30,606 INFO TaskSetManager: Finished task 16.0 in stage 3.0 (TID 73) in 572 ms on 10.1.2.65 (27/32)
17/01/29 15:15:30,608 INFO TaskSetManager: Finished task 19.0 in stage 3.0 (TID 81) in 569 ms on 10.1.2.65 (28/32)
17/01/29 15:15:30,622 INFO TaskSetManager: Finished task 2.0 in stage 3.0 (TID 72) in 588 ms on 10.1.2.176 (29/32)
17/01/29 15:15:30,623 INFO TaskSetManager: Finished task 15.0 in stage 3.0 (TID 80) in 584 ms on 10.1.2.176 (30/32)
17/01/29 15:15:30,625 INFO TaskSetManager: Finished task 24.0 in stage 3.0 (TID 95) in 577 ms on 10.1.2.176 (31/32)
17/01/29 15:15:30,625 INFO TaskSetManager: Finished task 21.0 in stage 3.0 (TID 88) in 582 ms on 10.1.2.176 (32/32)
17/01/29 15:15:30,625 INFO TaskSchedulerImpl: Removed TaskSet 3.0, whose tasks have all completed, from pool 
17/01/29 15:15:30,626 INFO DAGScheduler: ShuffleMapStage 3 (treeAggregate at GradientDescent.scala:239) finished in 0.598 s
17/01/29 15:15:30,626 INFO DAGScheduler: looking for newly runnable stages
17/01/29 15:15:30,627 INFO DAGScheduler: running: Set()
17/01/29 15:15:30,627 INFO DAGScheduler: waiting: Set(ResultStage 4)
17/01/29 15:15:30,628 INFO DAGScheduler: failed: Set()
17/01/29 15:15:30,629 INFO DAGScheduler: Submitting ResultStage 4 (MapPartitionsRDD[13] at treeAggregate at GradientDescent.scala:239), which has no missing parents
17/01/29 15:15:30,634 INFO MemoryStore: Block broadcast_6 stored as values in memory (estimated size 3.1 KB, free 2.1 GB)
17/01/29 15:15:30,636 INFO MemoryStore: Block broadcast_6_piece0 stored as bytes in memory (estimated size 1890.0 B, free 2.1 GB)
17/01/29 15:15:30,637 INFO BlockManagerInfo: Added broadcast_6_piece0 in memory on 10.1.2.152:36982 (size: 1890.0 B, free: 2.1 GB)
17/01/29 15:15:30,638 INFO SparkContext: Created broadcast 6 from broadcast at DAGScheduler.scala:1012
17/01/29 15:15:30,638 INFO DAGScheduler: Submitting 5 missing tasks from ResultStage 4 (MapPartitionsRDD[13] at treeAggregate at GradientDescent.scala:239)
17/01/29 15:15:30,638 INFO TaskSchedulerImpl: Adding task set 4.0 with 5 tasks
17/01/29 15:15:30,640 INFO TaskSetManager: Starting task 1.0 in stage 4.0 (TID 97, 10.1.2.28, partition 1, NODE_LOCAL, 5228 bytes)
17/01/29 15:15:30,641 INFO TaskSetManager: Starting task 0.0 in stage 4.0 (TID 98, 10.1.2.224, partition 0, NODE_LOCAL, 5228 bytes)
17/01/29 15:15:30,641 INFO TaskSetManager: Starting task 3.0 in stage 4.0 (TID 99, 10.1.2.191, partition 3, NODE_LOCAL, 5228 bytes)
17/01/29 15:15:30,642 INFO TaskSetManager: Starting task 4.0 in stage 4.0 (TID 100, 10.1.2.66, partition 4, NODE_LOCAL, 5228 bytes)
17/01/29 15:15:30,642 INFO TaskSetManager: Starting task 2.0 in stage 4.0 (TID 101, 10.1.2.38, partition 2, NODE_LOCAL, 5228 bytes)
17/01/29 15:15:30,643 INFO CoarseGrainedSchedulerBackend$DriverEndpoint: Launching task 97 on executor id: 7 hostname: 10.1.2.28.
17/01/29 15:15:30,643 INFO CoarseGrainedSchedulerBackend$DriverEndpoint: Launching task 98 on executor id: 4 hostname: 10.1.2.224.
17/01/29 15:15:30,644 INFO CoarseGrainedSchedulerBackend$DriverEndpoint: Launching task 99 on executor id: 1 hostname: 10.1.2.191.
17/01/29 15:15:30,644 INFO CoarseGrainedSchedulerBackend$DriverEndpoint: Launching task 100 on executor id: 3 hostname: 10.1.2.66.
17/01/29 15:15:30,645 INFO CoarseGrainedSchedulerBackend$DriverEndpoint: Launching task 101 on executor id: 6 hostname: 10.1.2.38.
17/01/29 15:15:30,658 INFO BlockManagerInfo: Added broadcast_6_piece0 in memory on 10.1.2.224:33482 (size: 1890.0 B, free: 1898.6 MB)
17/01/29 15:15:30,659 INFO BlockManagerInfo: Added broadcast_6_piece0 in memory on 10.1.2.28:35923 (size: 1890.0 B, free: 1942.9 MB)
17/01/29 15:15:30,661 INFO BlockManagerInfo: Added broadcast_6_piece0 in memory on 10.1.2.38:44632 (size: 1890.0 B, free: 1942.7 MB)
17/01/29 15:15:30,662 INFO BlockManagerInfo: Added broadcast_6_piece0 in memory on 10.1.2.66:39959 (size: 1890.0 B, free: 1943.0 MB)
17/01/29 15:15:30,662 INFO BlockManagerInfo: Added broadcast_6_piece0 in memory on 10.1.2.191:36335 (size: 1890.0 B, free: 1942.8 MB)
17/01/29 15:15:30,674 INFO MapOutputTrackerMasterEndpoint: Asked to send map output locations for shuffle 0 to 10.1.2.224:41220
17/01/29 15:15:30,675 INFO MapOutputTrackerMasterEndpoint: Asked to send map output locations for shuffle 0 to 10.1.2.28:52520
17/01/29 15:15:30,676 INFO MapOutputTrackerMasterEndpoint: Asked to send map output locations for shuffle 0 to 10.1.2.38:51050
17/01/29 15:15:30,678 INFO MapOutputTrackerMasterEndpoint: Asked to send map output locations for shuffle 0 to 10.1.2.191:44068
17/01/29 15:15:30,679 INFO MapOutputTrackerMasterEndpoint: Asked to send map output locations for shuffle 0 to 10.1.2.66:59764
17/01/29 15:15:30,679 INFO MapOutputTrackerMaster: Size of output statuses for shuffle 0 is 338 bytes
17/01/29 15:15:30,741 INFO TaskSetManager: Finished task 3.0 in stage 4.0 (TID 99) in 100 ms on 10.1.2.191 (1/5)
17/01/29 15:15:30,750 INFO TaskSetManager: Finished task 0.0 in stage 4.0 (TID 98) in 109 ms on 10.1.2.224 (2/5)
17/01/29 15:15:30,750 INFO TaskSetManager: Finished task 2.0 in stage 4.0 (TID 101) in 108 ms on 10.1.2.38 (3/5)
17/01/29 15:15:30,757 INFO TaskSetManager: Finished task 4.0 in stage 4.0 (TID 100) in 116 ms on 10.1.2.66 (4/5)
17/01/29 15:15:30,757 INFO TaskSetManager: Finished task 1.0 in stage 4.0 (TID 97) in 118 ms on 10.1.2.28 (5/5)
17/01/29 15:15:30,758 INFO TaskSchedulerImpl: Removed TaskSet 4.0, whose tasks have all completed, from pool 
17/01/29 15:15:30,758 INFO DAGScheduler: ResultStage 4 (treeAggregate at GradientDescent.scala:239) finished in 0.119 s
17/01/29 15:15:30,758 INFO DAGScheduler: Job 3 finished: treeAggregate at GradientDescent.scala:239, took 0.761851 s
17/01/29 15:15:30,761 INFO MemoryStore: Block broadcast_7 stored as values in memory (estimated size 200.0 B, free 2.1 GB)
17/01/29 15:15:30,763 INFO MemoryStore: Block broadcast_7_piece0 stored as bytes in memory (estimated size 285.0 B, free 2.1 GB)
17/01/29 15:15:30,764 INFO BlockManagerInfo: Added broadcast_7_piece0 in memory on 10.1.2.152:36982 (size: 285.0 B, free: 2.1 GB)
17/01/29 15:15:30,765 INFO SparkContext: Created broadcast 7 from broadcast at GradientDescent.scala:235
17/01/29 15:15:30,789 INFO SparkContext: Starting job: treeAggregate at GradientDescent.scala:239
17/01/29 15:15:30,791 INFO DAGScheduler: Registering RDD 16 (treeAggregate at GradientDescent.scala:239)
17/01/29 15:15:30,791 INFO DAGScheduler: Got job 4 (treeAggregate at GradientDescent.scala:239) with 5 output partitions
17/01/29 15:15:30,792 INFO DAGScheduler: Final stage: ResultStage 6 (treeAggregate at GradientDescent.scala:239)
17/01/29 15:15:30,792 INFO DAGScheduler: Parents of final stage: List(ShuffleMapStage 5)
17/01/29 15:15:30,792 INFO DAGScheduler: Missing parents: List(ShuffleMapStage 5)
17/01/29 15:15:30,794 INFO DAGScheduler: Submitting ShuffleMapStage 5 (MapPartitionsRDD[16] at treeAggregate at GradientDescent.scala:239), which has no missing parents
17/01/29 15:15:30,800 INFO MemoryStore: Block broadcast_8 stored as values in memory (estimated size 7.1 KB, free 2.1 GB)
17/01/29 15:15:30,801 INFO MemoryStore: Block broadcast_8_piece0 stored as bytes in memory (estimated size 3.7 KB, free 2.1 GB)
17/01/29 15:15:30,802 INFO BlockManagerInfo: Added broadcast_8_piece0 in memory on 10.1.2.152:36982 (size: 3.7 KB, free: 2.1 GB)
17/01/29 15:15:30,802 INFO SparkContext: Created broadcast 8 from broadcast at DAGScheduler.scala:1012
17/01/29 15:15:30,803 INFO DAGScheduler: Submitting 32 missing tasks from ShuffleMapStage 5 (MapPartitionsRDD[16] at treeAggregate at GradientDescent.scala:239)
17/01/29 15:15:30,804 INFO TaskSchedulerImpl: Adding task set 5.0 with 32 tasks
17/01/29 15:15:30,806 INFO TaskSetManager: Starting task 2.0 in stage 5.0 (TID 102, 10.1.2.176, partition 2, PROCESS_LOCAL, 5562 bytes)
17/01/29 15:15:30,807 INFO TaskSetManager: Starting task 6.0 in stage 5.0 (TID 103, 10.1.2.28, partition 6, PROCESS_LOCAL, 5562 bytes)
17/01/29 15:15:30,807 INFO TaskSetManager: Starting task 12.0 in stage 5.0 (TID 104, 10.1.2.191, partition 12, PROCESS_LOCAL, 5562 bytes)
17/01/29 15:15:30,808 INFO TaskSetManager: Starting task 5.0 in stage 5.0 (TID 105, 10.1.2.66, partition 5, PROCESS_LOCAL, 5562 bytes)
17/01/29 15:15:30,808 INFO TaskSetManager: Starting task 0.0 in stage 5.0 (TID 106, 10.1.2.224, partition 0, PROCESS_LOCAL, 5562 bytes)
17/01/29 15:15:30,809 INFO TaskSetManager: Starting task 3.0 in stage 5.0 (TID 107, 10.1.2.65, partition 3, PROCESS_LOCAL, 5562 bytes)
17/01/29 15:15:30,809 INFO TaskSetManager: Starting task 1.0 in stage 5.0 (TID 108, 10.1.2.38, partition 1, PROCESS_LOCAL, 5562 bytes)
17/01/29 15:15:30,809 INFO TaskSetManager: Starting task 7.0 in stage 5.0 (TID 109, 10.1.2.139, partition 7, PROCESS_LOCAL, 5562 bytes)
17/01/29 15:15:30,810 INFO TaskSetManager: Starting task 15.0 in stage 5.0 (TID 110, 10.1.2.176, partition 15, PROCESS_LOCAL, 5562 bytes)
17/01/29 15:15:30,810 INFO TaskSetManager: Starting task 18.0 in stage 5.0 (TID 111, 10.1.2.28, partition 18, PROCESS_LOCAL, 5562 bytes)
17/01/29 15:15:30,811 INFO TaskSetManager: Starting task 13.0 in stage 5.0 (TID 112, 10.1.2.191, partition 13, PROCESS_LOCAL, 5562 bytes)
17/01/29 15:15:30,811 INFO TaskSetManager: Starting task 9.0 in stage 5.0 (TID 113, 10.1.2.66, partition 9, PROCESS_LOCAL, 5562 bytes)
17/01/29 15:15:30,812 INFO TaskSetManager: Starting task 10.0 in stage 5.0 (TID 114, 10.1.2.224, partition 10, PROCESS_LOCAL, 5562 bytes)
17/01/29 15:15:30,812 INFO TaskSetManager: Starting task 16.0 in stage 5.0 (TID 115, 10.1.2.65, partition 16, PROCESS_LOCAL, 5562 bytes)
17/01/29 15:15:30,813 INFO TaskSetManager: Starting task 4.0 in stage 5.0 (TID 116, 10.1.2.38, partition 4, PROCESS_LOCAL, 5562 bytes)
17/01/29 15:15:30,813 INFO TaskSetManager: Starting task 8.0 in stage 5.0 (TID 117, 10.1.2.139, partition 8, PROCESS_LOCAL, 5562 bytes)
17/01/29 15:15:30,814 INFO TaskSetManager: Starting task 21.0 in stage 5.0 (TID 118, 10.1.2.176, partition 21, PROCESS_LOCAL, 5562 bytes)
17/01/29 15:15:30,814 INFO TaskSetManager: Starting task 26.0 in stage 5.0 (TID 119, 10.1.2.28, partition 26, PROCESS_LOCAL, 5562 bytes)
17/01/29 15:15:30,815 INFO TaskSetManager: Starting task 14.0 in stage 5.0 (TID 120, 10.1.2.191, partition 14, PROCESS_LOCAL, 5562 bytes)
17/01/29 15:15:30,815 INFO TaskSetManager: Starting task 22.0 in stage 5.0 (TID 121, 10.1.2.66, partition 22, PROCESS_LOCAL, 5562 bytes)
17/01/29 15:15:30,816 INFO TaskSetManager: Starting task 11.0 in stage 5.0 (TID 122, 10.1.2.224, partition 11, PROCESS_LOCAL, 5562 bytes)
17/01/29 15:15:30,816 INFO TaskSetManager: Starting task 19.0 in stage 5.0 (TID 123, 10.1.2.65, partition 19, PROCESS_LOCAL, 5562 bytes)
17/01/29 15:15:30,817 INFO TaskSetManager: Starting task 17.0 in stage 5.0 (TID 124, 10.1.2.38, partition 17, PROCESS_LOCAL, 5562 bytes)
17/01/29 15:15:30,817 INFO TaskSetManager: Starting task 23.0 in stage 5.0 (TID 125, 10.1.2.139, partition 23, PROCESS_LOCAL, 5562 bytes)
17/01/29 15:15:30,818 INFO TaskSetManager: Starting task 24.0 in stage 5.0 (TID 126, 10.1.2.176, partition 24, PROCESS_LOCAL, 5562 bytes)
17/01/29 15:15:30,819 INFO TaskSetManager: Starting task 30.0 in stage 5.0 (TID 127, 10.1.2.28, partition 30, PROCESS_LOCAL, 5562 bytes)
17/01/29 15:15:30,820 INFO TaskSetManager: Starting task 28.0 in stage 5.0 (TID 128, 10.1.2.191, partition 28, PROCESS_LOCAL, 5562 bytes)
17/01/29 15:15:30,820 INFO TaskSetManager: Starting task 29.0 in stage 5.0 (TID 129, 10.1.2.66, partition 29, PROCESS_LOCAL, 5562 bytes)
17/01/29 15:15:30,821 INFO TaskSetManager: Starting task 20.0 in stage 5.0 (TID 130, 10.1.2.224, partition 20, PROCESS_LOCAL, 5562 bytes)
17/01/29 15:15:30,821 INFO TaskSetManager: Starting task 31.0 in stage 5.0 (TID 131, 10.1.2.65, partition 31, PROCESS_LOCAL, 5562 bytes)
17/01/29 15:15:30,822 INFO TaskSetManager: Starting task 27.0 in stage 5.0 (TID 132, 10.1.2.38, partition 27, PROCESS_LOCAL, 5562 bytes)
17/01/29 15:15:30,822 INFO CoarseGrainedSchedulerBackend$DriverEndpoint: Launching task 102 on executor id: 5 hostname: 10.1.2.176.
17/01/29 15:15:30,822 INFO CoarseGrainedSchedulerBackend$DriverEndpoint: Launching task 110 on executor id: 5 hostname: 10.1.2.176.
17/01/29 15:15:30,823 INFO CoarseGrainedSchedulerBackend$DriverEndpoint: Launching task 118 on executor id: 5 hostname: 10.1.2.176.
17/01/29 15:15:30,823 INFO CoarseGrainedSchedulerBackend$DriverEndpoint: Launching task 126 on executor id: 5 hostname: 10.1.2.176.
17/01/29 15:15:30,823 INFO CoarseGrainedSchedulerBackend$DriverEndpoint: Launching task 103 on executor id: 7 hostname: 10.1.2.28.
17/01/29 15:15:30,823 INFO CoarseGrainedSchedulerBackend$DriverEndpoint: Launching task 111 on executor id: 7 hostname: 10.1.2.28.
17/01/29 15:15:30,824 INFO CoarseGrainedSchedulerBackend$DriverEndpoint: Launching task 119 on executor id: 7 hostname: 10.1.2.28.
17/01/29 15:15:30,824 INFO CoarseGrainedSchedulerBackend$DriverEndpoint: Launching task 127 on executor id: 7 hostname: 10.1.2.28.
17/01/29 15:15:30,824 INFO CoarseGrainedSchedulerBackend$DriverEndpoint: Launching task 104 on executor id: 1 hostname: 10.1.2.191.
17/01/29 15:15:30,824 INFO CoarseGrainedSchedulerBackend$DriverEndpoint: Launching task 112 on executor id: 1 hostname: 10.1.2.191.
17/01/29 15:15:30,825 INFO CoarseGrainedSchedulerBackend$DriverEndpoint: Launching task 120 on executor id: 1 hostname: 10.1.2.191.
17/01/29 15:15:30,825 INFO CoarseGrainedSchedulerBackend$DriverEndpoint: Launching task 128 on executor id: 1 hostname: 10.1.2.191.
17/01/29 15:15:30,825 INFO CoarseGrainedSchedulerBackend$DriverEndpoint: Launching task 105 on executor id: 3 hostname: 10.1.2.66.
17/01/29 15:15:30,825 INFO CoarseGrainedSchedulerBackend$DriverEndpoint: Launching task 113 on executor id: 3 hostname: 10.1.2.66.
17/01/29 15:15:30,826 INFO CoarseGrainedSchedulerBackend$DriverEndpoint: Launching task 121 on executor id: 3 hostname: 10.1.2.66.
17/01/29 15:15:30,826 INFO CoarseGrainedSchedulerBackend$DriverEndpoint: Launching task 129 on executor id: 3 hostname: 10.1.2.66.
17/01/29 15:15:30,826 INFO CoarseGrainedSchedulerBackend$DriverEndpoint: Launching task 106 on executor id: 4 hostname: 10.1.2.224.
17/01/29 15:15:30,826 INFO CoarseGrainedSchedulerBackend$DriverEndpoint: Launching task 114 on executor id: 4 hostname: 10.1.2.224.
17/01/29 15:15:30,827 INFO CoarseGrainedSchedulerBackend$DriverEndpoint: Launching task 122 on executor id: 4 hostname: 10.1.2.224.
17/01/29 15:15:30,827 INFO CoarseGrainedSchedulerBackend$DriverEndpoint: Launching task 130 on executor id: 4 hostname: 10.1.2.224.
17/01/29 15:15:30,827 INFO CoarseGrainedSchedulerBackend$DriverEndpoint: Launching task 107 on executor id: 2 hostname: 10.1.2.65.
17/01/29 15:15:30,827 INFO CoarseGrainedSchedulerBackend$DriverEndpoint: Launching task 115 on executor id: 2 hostname: 10.1.2.65.
17/01/29 15:15:30,828 INFO CoarseGrainedSchedulerBackend$DriverEndpoint: Launching task 123 on executor id: 2 hostname: 10.1.2.65.
17/01/29 15:15:30,828 INFO CoarseGrainedSchedulerBackend$DriverEndpoint: Launching task 131 on executor id: 2 hostname: 10.1.2.65.
17/01/29 15:15:30,828 INFO CoarseGrainedSchedulerBackend$DriverEndpoint: Launching task 108 on executor id: 6 hostname: 10.1.2.38.
17/01/29 15:15:30,828 INFO CoarseGrainedSchedulerBackend$DriverEndpoint: Launching task 116 on executor id: 6 hostname: 10.1.2.38.
17/01/29 15:15:30,828 INFO CoarseGrainedSchedulerBackend$DriverEndpoint: Launching task 124 on executor id: 6 hostname: 10.1.2.38.
17/01/29 15:15:30,829 INFO CoarseGrainedSchedulerBackend$DriverEndpoint: Launching task 132 on executor id: 6 hostname: 10.1.2.38.
17/01/29 15:15:30,829 INFO CoarseGrainedSchedulerBackend$DriverEndpoint: Launching task 109 on executor id: 0 hostname: 10.1.2.139.
17/01/29 15:15:30,829 INFO CoarseGrainedSchedulerBackend$DriverEndpoint: Launching task 117 on executor id: 0 hostname: 10.1.2.139.
17/01/29 15:15:30,829 INFO CoarseGrainedSchedulerBackend$DriverEndpoint: Launching task 125 on executor id: 0 hostname: 10.1.2.139.
17/01/29 15:15:30,844 INFO BlockManagerInfo: Added broadcast_8_piece0 in memory on 10.1.2.191:36335 (size: 3.7 KB, free: 1942.8 MB)
17/01/29 15:15:30,844 INFO BlockManagerInfo: Added broadcast_8_piece0 in memory on 10.1.2.28:35923 (size: 3.7 KB, free: 1942.9 MB)
17/01/29 15:15:30,849 INFO BlockManagerInfo: Added broadcast_8_piece0 in memory on 10.1.2.176:33908 (size: 3.7 KB, free: 1942.8 MB)
17/01/29 15:15:30,850 INFO BlockManagerInfo: Added broadcast_8_piece0 in memory on 10.1.2.38:44632 (size: 3.7 KB, free: 1942.7 MB)
17/01/29 15:15:30,850 INFO BlockManagerInfo: Added broadcast_8_piece0 in memory on 10.1.2.66:39959 (size: 3.7 KB, free: 1943.0 MB)
17/01/29 15:15:30,851 INFO BlockManagerInfo: Added broadcast_8_piece0 in memory on 10.1.2.139:38077 (size: 3.7 KB, free: 1987.3 MB)
17/01/29 15:15:30,851 INFO BlockManagerInfo: Added broadcast_8_piece0 in memory on 10.1.2.224:33482 (size: 3.7 KB, free: 1898.6 MB)
17/01/29 15:15:30,852 INFO BlockManagerInfo: Added broadcast_8_piece0 in memory on 10.1.2.65:41459 (size: 3.7 KB, free: 1942.8 MB)
17/01/29 15:15:30,864 INFO BlockManagerInfo: Added broadcast_7_piece0 in memory on 10.1.2.28:35923 (size: 285.0 B, free: 1942.9 MB)
17/01/29 15:15:30,866 INFO BlockManagerInfo: Added broadcast_7_piece0 in memory on 10.1.2.191:36335 (size: 285.0 B, free: 1942.8 MB)
17/01/29 15:15:30,868 INFO BlockManagerInfo: Added broadcast_7_piece0 in memory on 10.1.2.176:33908 (size: 285.0 B, free: 1942.8 MB)
17/01/29 15:15:30,869 INFO BlockManagerInfo: Added broadcast_7_piece0 in memory on 10.1.2.66:39959 (size: 285.0 B, free: 1943.0 MB)
17/01/29 15:15:30,871 INFO BlockManagerInfo: Added broadcast_7_piece0 in memory on 10.1.2.65:41459 (size: 285.0 B, free: 1942.8 MB)
17/01/29 15:15:30,872 INFO BlockManagerInfo: Added broadcast_7_piece0 in memory on 10.1.2.139:38077 (size: 285.0 B, free: 1987.3 MB)
17/01/29 15:15:30,873 INFO BlockManagerInfo: Added broadcast_7_piece0 in memory on 10.1.2.38:44632 (size: 285.0 B, free: 1942.7 MB)
17/01/29 15:15:30,874 INFO BlockManagerInfo: Added broadcast_7_piece0 in memory on 10.1.2.224:33482 (size: 285.0 B, free: 1898.6 MB)
17/01/29 15:15:30,932 INFO TaskSetManager: Finished task 8.0 in stage 5.0 (TID 117) in 119 ms on 10.1.2.139 (1/32)
17/01/29 15:15:30,933 INFO TaskSetManager: Finished task 7.0 in stage 5.0 (TID 109) in 124 ms on 10.1.2.139 (2/32)
17/01/29 15:15:30,940 INFO TaskSetManager: Finished task 23.0 in stage 5.0 (TID 125) in 122 ms on 10.1.2.139 (3/32)
17/01/29 15:15:30,954 INFO TaskSetManager: Finished task 10.0 in stage 5.0 (TID 114) in 143 ms on 10.1.2.224 (4/32)
17/01/29 15:15:30,955 INFO TaskSetManager: Starting task 25.0 in stage 5.0 (TID 133, 10.1.2.224, partition 25, PROCESS_LOCAL, 5562 bytes)
17/01/29 15:15:30,955 INFO CoarseGrainedSchedulerBackend$DriverEndpoint: Launching task 133 on executor id: 4 hostname: 10.1.2.224.
17/01/29 15:15:30,962 INFO TaskSetManager: Finished task 18.0 in stage 5.0 (TID 111) in 152 ms on 10.1.2.28 (5/32)
17/01/29 15:15:30,962 INFO TaskSetManager: Finished task 1.0 in stage 5.0 (TID 108) in 153 ms on 10.1.2.38 (6/32)
17/01/29 15:15:30,963 INFO TaskSetManager: Finished task 11.0 in stage 5.0 (TID 122) in 148 ms on 10.1.2.224 (7/32)
17/01/29 15:15:30,964 INFO TaskSetManager: Finished task 20.0 in stage 5.0 (TID 130) in 144 ms on 10.1.2.224 (8/32)
17/01/29 15:15:30,966 INFO TaskSetManager: Finished task 0.0 in stage 5.0 (TID 106) in 158 ms on 10.1.2.224 (9/32)
17/01/29 15:15:30,967 INFO TaskSetManager: Finished task 26.0 in stage 5.0 (TID 119) in 153 ms on 10.1.2.28 (10/32)
17/01/29 15:15:30,970 INFO TaskSetManager: Finished task 6.0 in stage 5.0 (TID 103) in 164 ms on 10.1.2.28 (11/32)
17/01/29 15:15:30,970 INFO TaskSetManager: Finished task 19.0 in stage 5.0 (TID 123) in 154 ms on 10.1.2.65 (12/32)
17/01/29 15:15:30,971 INFO TaskSetManager: Finished task 30.0 in stage 5.0 (TID 127) in 153 ms on 10.1.2.28 (13/32)
17/01/29 15:15:30,972 INFO TaskSetManager: Finished task 3.0 in stage 5.0 (TID 107) in 164 ms on 10.1.2.65 (14/32)
17/01/29 15:15:30,973 INFO TaskSetManager: Finished task 17.0 in stage 5.0 (TID 124) in 156 ms on 10.1.2.38 (15/32)
17/01/29 15:15:30,974 INFO TaskSetManager: Finished task 27.0 in stage 5.0 (TID 132) in 153 ms on 10.1.2.38 (16/32)
17/01/29 15:15:30,980 INFO TaskSetManager: Finished task 22.0 in stage 5.0 (TID 121) in 165 ms on 10.1.2.66 (17/32)
17/01/29 15:15:30,986 INFO TaskSetManager: Finished task 16.0 in stage 5.0 (TID 115) in 174 ms on 10.1.2.65 (18/32)
17/01/29 15:15:30,989 INFO TaskSetManager: Finished task 31.0 in stage 5.0 (TID 131) in 168 ms on 10.1.2.65 (19/32)
17/01/29 15:15:30,990 INFO TaskSetManager: Finished task 9.0 in stage 5.0 (TID 113) in 179 ms on 10.1.2.66 (20/32)
17/01/29 15:15:30,991 INFO TaskSetManager: Finished task 21.0 in stage 5.0 (TID 118) in 178 ms on 10.1.2.176 (21/32)
17/01/29 15:15:30,993 INFO TaskSetManager: Finished task 5.0 in stage 5.0 (TID 105) in 186 ms on 10.1.2.66 (22/32)
17/01/29 15:15:30,994 INFO TaskSetManager: Finished task 2.0 in stage 5.0 (TID 102) in 189 ms on 10.1.2.176 (23/32)
17/01/29 15:15:30,995 INFO TaskSetManager: Finished task 4.0 in stage 5.0 (TID 116) in 183 ms on 10.1.2.38 (24/32)
17/01/29 15:15:31,005 INFO TaskSetManager: Finished task 29.0 in stage 5.0 (TID 129) in 185 ms on 10.1.2.66 (25/32)
17/01/29 15:15:31,017 INFO TaskSetManager: Finished task 24.0 in stage 5.0 (TID 126) in 200 ms on 10.1.2.176 (26/32)
17/01/29 15:15:31,018 INFO TaskSetManager: Finished task 25.0 in stage 5.0 (TID 133) in 64 ms on 10.1.2.224 (27/32)
17/01/29 15:15:31,027 INFO TaskSetManager: Finished task 15.0 in stage 5.0 (TID 110) in 216 ms on 10.1.2.176 (28/32)
17/01/29 15:15:31,063 INFO TaskSetManager: Finished task 13.0 in stage 5.0 (TID 112) in 253 ms on 10.1.2.191 (29/32)
17/01/29 15:15:31,081 INFO TaskSetManager: Finished task 28.0 in stage 5.0 (TID 128) in 262 ms on 10.1.2.191 (30/32)
17/01/29 15:15:31,083 INFO TaskSetManager: Finished task 14.0 in stage 5.0 (TID 120) in 269 ms on 10.1.2.191 (31/32)
17/01/29 15:15:31,092 INFO TaskSetManager: Finished task 12.0 in stage 5.0 (TID 104) in 285 ms on 10.1.2.191 (32/32)
17/01/29 15:15:31,093 INFO TaskSchedulerImpl: Removed TaskSet 5.0, whose tasks have all completed, from pool 
17/01/29 15:15:31,093 INFO DAGScheduler: ShuffleMapStage 5 (treeAggregate at GradientDescent.scala:239) finished in 0.288 s
17/01/29 15:15:31,093 INFO DAGScheduler: looking for newly runnable stages
17/01/29 15:15:31,093 INFO DAGScheduler: running: Set()
17/01/29 15:15:31,093 INFO DAGScheduler: waiting: Set(ResultStage 6)
17/01/29 15:15:31,093 INFO DAGScheduler: failed: Set()
17/01/29 15:15:31,094 INFO DAGScheduler: Submitting ResultStage 6 (MapPartitionsRDD[18] at treeAggregate at GradientDescent.scala:239), which has no missing parents
17/01/29 15:15:31,096 INFO MemoryStore: Block broadcast_9 stored as values in memory (estimated size 3.1 KB, free 2.1 GB)
17/01/29 15:15:31,098 INFO MemoryStore: Block broadcast_9_piece0 stored as bytes in memory (estimated size 1889.0 B, free 2.1 GB)
17/01/29 15:15:31,099 INFO BlockManagerInfo: Added broadcast_9_piece0 in memory on 10.1.2.152:36982 (size: 1889.0 B, free: 2.1 GB)
17/01/29 15:15:31,099 INFO SparkContext: Created broadcast 9 from broadcast at DAGScheduler.scala:1012
17/01/29 15:15:31,099 INFO DAGScheduler: Submitting 5 missing tasks from ResultStage 6 (MapPartitionsRDD[18] at treeAggregate at GradientDescent.scala:239)
17/01/29 15:15:31,100 INFO TaskSchedulerImpl: Adding task set 6.0 with 5 tasks
17/01/29 15:15:31,101 INFO TaskSetManager: Starting task 1.0 in stage 6.0 (TID 134, 10.1.2.65, partition 1, NODE_LOCAL, 5228 bytes)
17/01/29 15:15:31,102 INFO TaskSetManager: Starting task 2.0 in stage 6.0 (TID 135, 10.1.2.38, partition 2, NODE_LOCAL, 5228 bytes)
17/01/29 15:15:31,102 INFO TaskSetManager: Starting task 3.0 in stage 6.0 (TID 136, 10.1.2.139, partition 3, NODE_LOCAL, 5228 bytes)
17/01/29 15:15:31,103 INFO TaskSetManager: Starting task 0.0 in stage 6.0 (TID 137, 10.1.2.224, partition 0, NODE_LOCAL, 5228 bytes)
17/01/29 15:15:31,103 INFO TaskSetManager: Starting task 4.0 in stage 6.0 (TID 138, 10.1.2.66, partition 4, NODE_LOCAL, 5228 bytes)
17/01/29 15:15:31,104 INFO CoarseGrainedSchedulerBackend$DriverEndpoint: Launching task 134 on executor id: 2 hostname: 10.1.2.65.
17/01/29 15:15:31,104 INFO CoarseGrainedSchedulerBackend$DriverEndpoint: Launching task 135 on executor id: 6 hostname: 10.1.2.38.
17/01/29 15:15:31,105 INFO CoarseGrainedSchedulerBackend$DriverEndpoint: Launching task 136 on executor id: 0 hostname: 10.1.2.139.
17/01/29 15:15:31,105 INFO CoarseGrainedSchedulerBackend$DriverEndpoint: Launching task 137 on executor id: 4 hostname: 10.1.2.224.
17/01/29 15:15:31,105 INFO CoarseGrainedSchedulerBackend$DriverEndpoint: Launching task 138 on executor id: 3 hostname: 10.1.2.66.
17/01/29 15:15:31,119 INFO BlockManagerInfo: Added broadcast_9_piece0 in memory on 10.1.2.65:41459 (size: 1889.0 B, free: 1942.8 MB)
17/01/29 15:15:31,120 INFO BlockManagerInfo: Added broadcast_9_piece0 in memory on 10.1.2.38:44632 (size: 1889.0 B, free: 1942.7 MB)
17/01/29 15:15:31,121 INFO BlockManagerInfo: Added broadcast_9_piece0 in memory on 10.1.2.224:33482 (size: 1889.0 B, free: 1898.6 MB)
17/01/29 15:15:31,121 INFO BlockManagerInfo: Added broadcast_9_piece0 in memory on 10.1.2.139:38077 (size: 1889.0 B, free: 1987.3 MB)
17/01/29 15:15:31,122 INFO BlockManagerInfo: Added broadcast_9_piece0 in memory on 10.1.2.66:39959 (size: 1889.0 B, free: 1943.0 MB)
17/01/29 15:15:31,126 INFO MapOutputTrackerMasterEndpoint: Asked to send map output locations for shuffle 1 to 10.1.2.38:51050
17/01/29 15:15:31,126 INFO MapOutputTrackerMasterEndpoint: Asked to send map output locations for shuffle 1 to 10.1.2.224:41220
17/01/29 15:15:31,127 INFO MapOutputTrackerMaster: Size of output statuses for shuffle 1 is 338 bytes
17/01/29 15:15:31,128 INFO MapOutputTrackerMasterEndpoint: Asked to send map output locations for shuffle 1 to 10.1.2.66:59764
17/01/29 15:15:31,135 INFO MapOutputTrackerMasterEndpoint: Asked to send map output locations for shuffle 1 to 10.1.2.65:58668
17/01/29 15:15:31,139 INFO MapOutputTrackerMasterEndpoint: Asked to send map output locations for shuffle 1 to 10.1.2.139:47550
17/01/29 15:15:31,143 INFO TaskSetManager: Finished task 0.0 in stage 6.0 (TID 137) in 41 ms on 10.1.2.224 (1/5)
17/01/29 15:15:31,144 INFO TaskSetManager: Finished task 2.0 in stage 6.0 (TID 135) in 43 ms on 10.1.2.38 (2/5)
17/01/29 15:15:31,149 INFO TaskSetManager: Finished task 4.0 in stage 6.0 (TID 138) in 46 ms on 10.1.2.66 (3/5)
17/01/29 15:15:31,198 INFO TaskSetManager: Finished task 1.0 in stage 6.0 (TID 134) in 97 ms on 10.1.2.65 (4/5)
17/01/29 15:15:31,200 INFO TaskSetManager: Finished task 3.0 in stage 6.0 (TID 136) in 98 ms on 10.1.2.139 (5/5)
17/01/29 15:15:31,201 INFO TaskSchedulerImpl: Removed TaskSet 6.0, whose tasks have all completed, from pool 
17/01/29 15:15:31,201 INFO DAGScheduler: ResultStage 6 (treeAggregate at GradientDescent.scala:239) finished in 0.101 s
17/01/29 15:15:31,201 INFO DAGScheduler: Job 4 finished: treeAggregate at GradientDescent.scala:239, took 0.412372 s
17/01/29 15:15:31,210 INFO MemoryStore: Block broadcast_10 stored as values in memory (estimated size 200.0 B, free 2.1 GB)
17/01/29 15:15:31,211 INFO MemoryStore: Block broadcast_10_piece0 stored as bytes in memory (estimated size 285.0 B, free 2.1 GB)
17/01/29 15:15:31,212 INFO BlockManagerInfo: Added broadcast_10_piece0 in memory on 10.1.2.152:36982 (size: 285.0 B, free: 2.1 GB)
17/01/29 15:15:31,213 INFO SparkContext: Created broadcast 10 from broadcast at GradientDescent.scala:235
17/01/29 15:15:31,231 INFO SparkContext: Starting job: treeAggregate at GradientDescent.scala:239
17/01/29 15:15:31,233 INFO DAGScheduler: Registering RDD 21 (treeAggregate at GradientDescent.scala:239)
17/01/29 15:15:31,233 INFO DAGScheduler: Got job 5 (treeAggregate at GradientDescent.scala:239) with 5 output partitions
17/01/29 15:15:31,233 INFO DAGScheduler: Final stage: ResultStage 8 (treeAggregate at GradientDescent.scala:239)
17/01/29 15:15:31,234 INFO DAGScheduler: Parents of final stage: List(ShuffleMapStage 7)
17/01/29 15:15:31,234 INFO DAGScheduler: Missing parents: List(ShuffleMapStage 7)
17/01/29 15:15:31,241 INFO DAGScheduler: Submitting ShuffleMapStage 7 (MapPartitionsRDD[21] at treeAggregate at GradientDescent.scala:239), which has no missing parents
17/01/29 15:15:31,246 INFO MemoryStore: Block broadcast_11 stored as values in memory (estimated size 7.1 KB, free 2.1 GB)
17/01/29 15:15:31,248 INFO MemoryStore: Block broadcast_11_piece0 stored as bytes in memory (estimated size 3.7 KB, free 2.1 GB)
17/01/29 15:15:31,249 INFO BlockManagerInfo: Added broadcast_11_piece0 in memory on 10.1.2.152:36982 (size: 3.7 KB, free: 2.1 GB)
17/01/29 15:15:31,250 INFO SparkContext: Created broadcast 11 from broadcast at DAGScheduler.scala:1012
17/01/29 15:15:31,250 INFO DAGScheduler: Submitting 32 missing tasks from ShuffleMapStage 7 (MapPartitionsRDD[21] at treeAggregate at GradientDescent.scala:239)
17/01/29 15:15:31,251 INFO TaskSchedulerImpl: Adding task set 7.0 with 32 tasks
17/01/29 15:15:31,253 INFO TaskSetManager: Starting task 5.0 in stage 7.0 (TID 139, 10.1.2.66, partition 5, PROCESS_LOCAL, 5562 bytes)
17/01/29 15:15:31,254 INFO TaskSetManager: Starting task 12.0 in stage 7.0 (TID 140, 10.1.2.191, partition 12, PROCESS_LOCAL, 5562 bytes)
17/01/29 15:15:31,254 INFO TaskSetManager: Starting task 7.0 in stage 7.0 (TID 141, 10.1.2.139, partition 7, PROCESS_LOCAL, 5562 bytes)
17/01/29 15:15:31,255 INFO TaskSetManager: Starting task 3.0 in stage 7.0 (TID 142, 10.1.2.65, partition 3, PROCESS_LOCAL, 5562 bytes)
17/01/29 15:15:31,255 INFO TaskSetManager: Starting task 0.0 in stage 7.0 (TID 143, 10.1.2.224, partition 0, PROCESS_LOCAL, 5562 bytes)
17/01/29 15:15:31,256 INFO TaskSetManager: Starting task 6.0 in stage 7.0 (TID 144, 10.1.2.28, partition 6, PROCESS_LOCAL, 5562 bytes)
17/01/29 15:15:31,256 INFO TaskSetManager: Starting task 2.0 in stage 7.0 (TID 145, 10.1.2.176, partition 2, PROCESS_LOCAL, 5562 bytes)
17/01/29 15:15:31,257 INFO TaskSetManager: Starting task 1.0 in stage 7.0 (TID 146, 10.1.2.38, partition 1, PROCESS_LOCAL, 5562 bytes)
17/01/29 15:15:31,257 INFO TaskSetManager: Starting task 9.0 in stage 7.0 (TID 147, 10.1.2.66, partition 9, PROCESS_LOCAL, 5562 bytes)
17/01/29 15:15:31,258 INFO TaskSetManager: Starting task 13.0 in stage 7.0 (TID 148, 10.1.2.191, partition 13, PROCESS_LOCAL, 5562 bytes)
17/01/29 15:15:31,258 INFO TaskSetManager: Starting task 8.0 in stage 7.0 (TID 149, 10.1.2.139, partition 8, PROCESS_LOCAL, 5562 bytes)
17/01/29 15:15:31,259 INFO TaskSetManager: Starting task 16.0 in stage 7.0 (TID 150, 10.1.2.65, partition 16, PROCESS_LOCAL, 5562 bytes)
17/01/29 15:15:31,259 INFO TaskSetManager: Starting task 10.0 in stage 7.0 (TID 151, 10.1.2.224, partition 10, PROCESS_LOCAL, 5562 bytes)
17/01/29 15:15:31,259 INFO TaskSetManager: Starting task 18.0 in stage 7.0 (TID 152, 10.1.2.28, partition 18, PROCESS_LOCAL, 5562 bytes)
17/01/29 15:15:31,260 INFO TaskSetManager: Starting task 15.0 in stage 7.0 (TID 153, 10.1.2.176, partition 15, PROCESS_LOCAL, 5562 bytes)
17/01/29 15:15:31,260 INFO TaskSetManager: Starting task 4.0 in stage 7.0 (TID 154, 10.1.2.38, partition 4, PROCESS_LOCAL, 5562 bytes)
17/01/29 15:15:31,261 INFO TaskSetManager: Starting task 22.0 in stage 7.0 (TID 155, 10.1.2.66, partition 22, PROCESS_LOCAL, 5562 bytes)
17/01/29 15:15:31,261 INFO TaskSetManager: Starting task 14.0 in stage 7.0 (TID 156, 10.1.2.191, partition 14, PROCESS_LOCAL, 5562 bytes)
17/01/29 15:15:31,262 INFO TaskSetManager: Starting task 23.0 in stage 7.0 (TID 157, 10.1.2.139, partition 23, PROCESS_LOCAL, 5562 bytes)
17/01/29 15:15:31,262 INFO TaskSetManager: Starting task 19.0 in stage 7.0 (TID 158, 10.1.2.65, partition 19, PROCESS_LOCAL, 5562 bytes)
17/01/29 15:15:31,263 INFO TaskSetManager: Starting task 11.0 in stage 7.0 (TID 159, 10.1.2.224, partition 11, PROCESS_LOCAL, 5562 bytes)
17/01/29 15:15:31,263 INFO TaskSetManager: Starting task 26.0 in stage 7.0 (TID 160, 10.1.2.28, partition 26, PROCESS_LOCAL, 5562 bytes)
17/01/29 15:15:31,264 INFO TaskSetManager: Starting task 21.0 in stage 7.0 (TID 161, 10.1.2.176, partition 21, PROCESS_LOCAL, 5562 bytes)
17/01/29 15:15:31,264 INFO TaskSetManager: Starting task 17.0 in stage 7.0 (TID 162, 10.1.2.38, partition 17, PROCESS_LOCAL, 5562 bytes)
17/01/29 15:15:31,264 INFO TaskSetManager: Starting task 29.0 in stage 7.0 (TID 163, 10.1.2.66, partition 29, PROCESS_LOCAL, 5562 bytes)
17/01/29 15:15:31,265 INFO TaskSetManager: Starting task 28.0 in stage 7.0 (TID 164, 10.1.2.191, partition 28, PROCESS_LOCAL, 5562 bytes)
17/01/29 15:15:31,265 INFO TaskSetManager: Starting task 31.0 in stage 7.0 (TID 165, 10.1.2.65, partition 31, PROCESS_LOCAL, 5562 bytes)
17/01/29 15:15:31,266 INFO TaskSetManager: Starting task 20.0 in stage 7.0 (TID 166, 10.1.2.224, partition 20, PROCESS_LOCAL, 5562 bytes)
17/01/29 15:15:31,266 INFO TaskSetManager: Starting task 30.0 in stage 7.0 (TID 167, 10.1.2.28, partition 30, PROCESS_LOCAL, 5562 bytes)
17/01/29 15:15:31,267 INFO TaskSetManager: Starting task 24.0 in stage 7.0 (TID 168, 10.1.2.176, partition 24, PROCESS_LOCAL, 5562 bytes)
17/01/29 15:15:31,267 INFO TaskSetManager: Starting task 27.0 in stage 7.0 (TID 169, 10.1.2.38, partition 27, PROCESS_LOCAL, 5562 bytes)
