Using properties file: /home/ubuntu/spark-2.0.0/conf/spark-defaults.conf
Adding default property: spark.driver.extraJavaOptions=-XX:+PrintGCDetails -XX:+PrintGCTimeStamps -Xms4000m -Dlog4j.configuration=file:///home/ubuntu/spark-2.0.0/conf/log4j.properties
Adding default property: spark.executor.extraJavaOptions=-XX:+PrintGCDetails -XX:+PrintGCTimeStamps -Xms4000m -Dlog4j.configuration=file:///home/ubuntu/spark-2.0.0/conf/log4j.properties
Parsed arguments:
  master                  spark://euca-10-1-2-152:7077
  deployMode              client
  executorMemory          4000m
  executorCores           null
  totalExecutorCores      null
  propertiesFile          /home/ubuntu/spark-2.0.0/conf/spark-defaults.conf
  driverMemory            4000m
  driverCores             null
  driverExtraClassPath    null
  driverExtraLibraryPath  null
  driverExtraJavaOptions  -XX:+PrintGCDetails -XX:+PrintGCTimeStamps -Xms4000m -Dlog4j.configuration=file:///home/ubuntu/spark-2.0.0/conf/log4j.properties
  supervise               false
  queue                   null
  numExecutors            8
  files                   null
  pyFiles                 null
  archives                null
  mainClass               LogRegExplicitParallelism
  primaryResource         file:///home/ubuntu/jars/log-reg-explicit-parallelism_2.11-1.0.jar
  name                    LogRegExplicitParallelism
  childArgs               [cluster 18 euca-10-1-2-152 9000 susy_0_exp 5 32]
  jars                    null
  packages                null
  packagesExclusions      null
  repositories            null
  verbose                 true

Spark properties used, including those specified through
 --conf and those from the properties file /home/ubuntu/spark-2.0.0/conf/spark-defaults.conf:
  spark.default.parallelism -> 32
  spark.driver.memory -> 4000m
  spark.executor.extraJavaOptions -> -XX:+PrintGCDetails -XX:+PrintGCTimeStamps -Xms4000m -Dlog4j.configuration=file:///home/ubuntu/spark-2.0.0/conf/log4j.properties
  spark.driver.extraJavaOptions -> -XX:+PrintGCDetails -XX:+PrintGCTimeStamps -Xms4000m -Dlog4j.configuration=file:///home/ubuntu/spark-2.0.0/conf/log4j.properties
  spark.shuffle.spill -> false

    
Main class:
LogRegExplicitParallelism
Arguments:
cluster
18
euca-10-1-2-152
9000
susy_0_exp
5
32
System properties:
spark.default.parallelism -> 32
spark.executor.memory -> 4000m
spark.driver.memory -> 4000m
SPARK_SUBMIT -> true
spark.executor.extraJavaOptions -> -XX:+PrintGCDetails -XX:+PrintGCTimeStamps -Xms4000m -Dlog4j.configuration=file:///home/ubuntu/spark-2.0.0/conf/log4j.properties
spark.app.name -> LogRegExplicitParallelism
spark.shuffle.spill -> false
spark.driver.extraJavaOptions -> -XX:+PrintGCDetails -XX:+PrintGCTimeStamps -Xms4000m -Dlog4j.configuration=file:///home/ubuntu/spark-2.0.0/conf/log4j.properties
spark.jars -> file:///home/ubuntu/jars/log-reg-explicit-parallelism_2.11-1.0.jar
spark.submit.deployMode -> client
spark.master -> spark://euca-10-1-2-152:7077
Classpath elements:
file:///home/ubuntu/jars/log-reg-explicit-parallelism_2.11-1.0.jar


17/01/29 15:00:09,226 INFO SparkContext: Running Spark version 2.0.0
17/01/29 15:00:09,584 WARN NativeCodeLoader: Unable to load native-hadoop library for your platform... using builtin-java classes where applicable
17/01/29 15:00:09,766 INFO SecurityManager: Changing view acls to: ubuntu
17/01/29 15:00:09,767 INFO SecurityManager: Changing modify acls to: ubuntu
17/01/29 15:00:09,767 INFO SecurityManager: Changing view acls groups to: 
17/01/29 15:00:09,768 INFO SecurityManager: Changing modify acls groups to: 
17/01/29 15:00:09,768 INFO SecurityManager: SecurityManager: authentication disabled; ui acls disabled; users  with view permissions: Set(ubuntu); groups with view permissions: Set(); users  with modify permissions: Set(ubuntu); groups with modify permissions: Set()
17/01/29 15:00:10,112 INFO Utils: Successfully started service 'sparkDriver' on port 35258.
17/01/29 15:00:10,134 INFO SparkEnv: Registering MapOutputTracker
17/01/29 15:00:10,141 WARN SortShuffleManager: spark.shuffle.spill was set to false, but this configuration is ignored as of Spark 1.6+. Shuffle will continue to spill to disk when necessary.
17/01/29 15:00:10,153 INFO SparkEnv: Registering BlockManagerMaster
17/01/29 15:00:10,170 INFO DiskBlockManager: Created local directory at /tmp/blockmgr-a425f35e-eb72-4852-a4be-eace5edd7cf2
17/01/29 15:00:10,191 INFO MemoryStore: MemoryStore started with capacity 2.1 GB
17/01/29 15:00:10,252 INFO SparkEnv: Registering OutputCommitCoordinator
17/01/29 15:00:10,484 INFO Utils: Successfully started service 'SparkUI' on port 4040.
17/01/29 15:00:10,486 INFO SparkUI: Bound SparkUI to 10.1.2.152, and started at http://10.1.2.152:4040
17/01/29 15:00:10,521 INFO SparkContext: Added JAR file:///home/ubuntu/jars/log-reg-explicit-parallelism_2.11-1.0.jar at spark://10.1.2.152:35258/jars/log-reg-explicit-parallelism_2.11-1.0.jar with timestamp 1485702010521
17/01/29 15:00:10,625 INFO StandaloneAppClient$ClientEndpoint: Connecting to master spark://euca-10-1-2-152:7077...
17/01/29 15:00:10,683 INFO TransportClientFactory: Successfully created connection to euca-10-1-2-152/10.1.2.152:7077 after 23 ms (0 ms spent in bootstraps)
17/01/29 15:00:10,774 INFO StandaloneSchedulerBackend: Connected to Spark cluster with app ID app-20170129150010-0000
17/01/29 15:00:10,780 INFO Utils: Successfully started service 'org.apache.spark.network.netty.NettyBlockTransferService' on port 42412.
17/01/29 15:00:10,780 INFO NettyBlockTransferService: Server created on 10.1.2.152:42412
17/01/29 15:00:10,783 INFO BlockManagerMaster: Registering BlockManager BlockManagerId(driver, 10.1.2.152, 42412)
17/01/29 15:00:10,785 INFO BlockManagerMasterEndpoint: Registering block manager 10.1.2.152:42412 with 2.1 GB RAM, BlockManagerId(driver, 10.1.2.152, 42412)
17/01/29 15:00:10,788 INFO BlockManagerMaster: Registered BlockManager BlockManagerId(driver, 10.1.2.152, 42412)
17/01/29 15:00:10,810 INFO StandaloneAppClient$ClientEndpoint: Executor added: app-20170129150010-0000/0 on worker-20170129145946-10.1.2.224-37122 (10.1.2.224:37122) with 4 cores
17/01/29 15:00:10,811 INFO StandaloneSchedulerBackend: Granted executor ID app-20170129150010-0000/0 on hostPort 10.1.2.224:37122 with 4 cores, 3.9 GB RAM
17/01/29 15:00:10,813 INFO StandaloneAppClient$ClientEndpoint: Executor added: app-20170129150010-0000/1 on worker-20170129145946-10.1.2.38-32875 (10.1.2.38:32875) with 4 cores
17/01/29 15:00:10,813 INFO StandaloneSchedulerBackend: Granted executor ID app-20170129150010-0000/1 on hostPort 10.1.2.38:32875 with 4 cores, 3.9 GB RAM
17/01/29 15:00:10,815 INFO StandaloneAppClient$ClientEndpoint: Executor added: app-20170129150010-0000/2 on worker-20170129145946-10.1.2.28-43585 (10.1.2.28:43585) with 4 cores
17/01/29 15:00:10,815 INFO StandaloneSchedulerBackend: Granted executor ID app-20170129150010-0000/2 on hostPort 10.1.2.28:43585 with 4 cores, 3.9 GB RAM
17/01/29 15:00:10,816 INFO StandaloneAppClient$ClientEndpoint: Executor added: app-20170129150010-0000/3 on worker-20170129145946-10.1.2.65-44516 (10.1.2.65:44516) with 4 cores
17/01/29 15:00:10,817 INFO StandaloneSchedulerBackend: Granted executor ID app-20170129150010-0000/3 on hostPort 10.1.2.65:44516 with 4 cores, 3.9 GB RAM
17/01/29 15:00:10,818 INFO StandaloneAppClient$ClientEndpoint: Executor added: app-20170129150010-0000/4 on worker-20170129145946-10.1.2.176-40752 (10.1.2.176:40752) with 4 cores
17/01/29 15:00:10,819 INFO StandaloneSchedulerBackend: Granted executor ID app-20170129150010-0000/4 on hostPort 10.1.2.176:40752 with 4 cores, 3.9 GB RAM
17/01/29 15:00:10,820 INFO StandaloneAppClient$ClientEndpoint: Executor added: app-20170129150010-0000/5 on worker-20170129145946-10.1.2.191-45352 (10.1.2.191:45352) with 4 cores
17/01/29 15:00:10,821 INFO StandaloneSchedulerBackend: Granted executor ID app-20170129150010-0000/5 on hostPort 10.1.2.191:45352 with 4 cores, 3.9 GB RAM
17/01/29 15:00:10,823 INFO StandaloneAppClient$ClientEndpoint: Executor added: app-20170129150010-0000/6 on worker-20170129145946-10.1.2.66-44403 (10.1.2.66:44403) with 4 cores
17/01/29 15:00:10,823 INFO StandaloneSchedulerBackend: Granted executor ID app-20170129150010-0000/6 on hostPort 10.1.2.66:44403 with 4 cores, 3.9 GB RAM
17/01/29 15:00:10,824 INFO StandaloneAppClient$ClientEndpoint: Executor added: app-20170129150010-0000/7 on worker-20170129145946-10.1.2.139-35294 (10.1.2.139:35294) with 4 cores
17/01/29 15:00:10,824 INFO StandaloneSchedulerBackend: Granted executor ID app-20170129150010-0000/7 on hostPort 10.1.2.139:35294 with 4 cores, 3.9 GB RAM
17/01/29 15:00:10,875 INFO StandaloneAppClient$ClientEndpoint: Executor updated: app-20170129150010-0000/1 is now RUNNING
17/01/29 15:00:10,878 INFO StandaloneAppClient$ClientEndpoint: Executor updated: app-20170129150010-0000/3 is now RUNNING
17/01/29 15:00:10,882 INFO StandaloneAppClient$ClientEndpoint: Executor updated: app-20170129150010-0000/2 is now RUNNING
17/01/29 15:00:10,884 INFO StandaloneAppClient$ClientEndpoint: Executor updated: app-20170129150010-0000/0 is now RUNNING
17/01/29 15:00:10,887 INFO StandaloneAppClient$ClientEndpoint: Executor updated: app-20170129150010-0000/6 is now RUNNING
17/01/29 15:00:10,890 INFO StandaloneAppClient$ClientEndpoint: Executor updated: app-20170129150010-0000/7 is now RUNNING
17/01/29 15:00:10,893 INFO StandaloneAppClient$ClientEndpoint: Executor updated: app-20170129150010-0000/4 is now RUNNING
17/01/29 15:00:10,896 INFO StandaloneAppClient$ClientEndpoint: Executor updated: app-20170129150010-0000/5 is now RUNNING
17/01/29 15:00:10,978 INFO StandaloneSchedulerBackend: SchedulerBackend is ready for scheduling beginning after reached minRegisteredResourcesRatio: 0.0
17/01/29 15:00:11,419 INFO MemoryStore: Block broadcast_0 stored as values in memory (estimated size 130.8 KB, free 2.1 GB)
17/01/29 15:00:11,506 INFO MemoryStore: Block broadcast_0_piece0 stored as bytes in memory (estimated size 16.5 KB, free 2.1 GB)
17/01/29 15:00:11,508 INFO BlockManagerInfo: Added broadcast_0_piece0 in memory on 10.1.2.152:42412 (size: 16.5 KB, free: 2.1 GB)
17/01/29 15:00:11,517 INFO SparkContext: Created broadcast 0 from textFile at MLUtils.scala:99
17/01/29 15:00:12,257 INFO FileInputFormat: Total input paths to process : 1
17/01/29 15:00:12,316 INFO NetworkTopology: Adding a new node: /default-rack/10.1.2.224:50010
17/01/29 15:00:12,316 INFO NetworkTopology: Adding a new node: /default-rack/10.1.2.66:50010
17/01/29 15:00:12,317 INFO NetworkTopology: Adding a new node: /default-rack/10.1.2.38:50010
17/01/29 15:00:12,317 INFO NetworkTopology: Adding a new node: /default-rack/10.1.2.28:50010
17/01/29 15:00:12,317 INFO NetworkTopology: Adding a new node: /default-rack/10.1.2.176:50010
17/01/29 15:00:12,318 INFO NetworkTopology: Adding a new node: /default-rack/10.1.2.65:50010
17/01/29 15:00:12,318 INFO NetworkTopology: Adding a new node: /default-rack/10.1.2.139:50010
17/01/29 15:00:12,319 INFO NetworkTopology: Adding a new node: /default-rack/10.1.2.191:50010
17/01/29 15:00:12,365 INFO SparkContext: Starting job: first at GeneralizedLinearAlgorithm.scala:246
17/01/29 15:00:12,385 INFO DAGScheduler: Got job 0 (first at GeneralizedLinearAlgorithm.scala:246) with 1 output partitions
17/01/29 15:00:12,386 INFO DAGScheduler: Final stage: ResultStage 0 (first at GeneralizedLinearAlgorithm.scala:246)
17/01/29 15:00:12,387 INFO DAGScheduler: Parents of final stage: List()
17/01/29 15:00:12,395 INFO DAGScheduler: Missing parents: List()
17/01/29 15:00:12,416 INFO DAGScheduler: Submitting ResultStage 0 (MapPartitionsRDD[6] at map at GeneralizedLinearAlgorithm.scala:246), which has no missing parents
17/01/29 15:00:12,444 INFO MemoryStore: Block broadcast_1 stored as values in memory (estimated size 4.2 KB, free 2.1 GB)
17/01/29 15:00:12,448 INFO MemoryStore: Block broadcast_1_piece0 stored as bytes in memory (estimated size 2.4 KB, free 2.1 GB)
17/01/29 15:00:12,448 INFO BlockManagerInfo: Added broadcast_1_piece0 in memory on 10.1.2.152:42412 (size: 2.4 KB, free: 2.1 GB)
17/01/29 15:00:12,450 INFO SparkContext: Created broadcast 1 from broadcast at DAGScheduler.scala:1012
17/01/29 15:00:12,453 INFO DAGScheduler: Submitting 1 missing tasks from ResultStage 0 (MapPartitionsRDD[6] at map at GeneralizedLinearAlgorithm.scala:246)
17/01/29 15:00:12,454 INFO TaskSchedulerImpl: Adding task set 0.0 with 1 tasks
17/01/29 15:00:12,802 INFO CoarseGrainedSchedulerBackend$DriverEndpoint: Registered executor NettyRpcEndpointRef(null) (10.1.2.224:39078) with ID 0
17/01/29 15:00:12,840 INFO TaskSetManager: Starting task 0.0 in stage 0.0 (TID 0, 10.1.2.224, partition 0, ANY, 5455 bytes)
17/01/29 15:00:12,846 INFO CoarseGrainedSchedulerBackend$DriverEndpoint: Launching task 0 on executor id: 0 hostname: 10.1.2.224.
17/01/29 15:00:12,848 INFO CoarseGrainedSchedulerBackend$DriverEndpoint: Registered executor NettyRpcEndpointRef(null) (10.1.2.38:35190) with ID 1
17/01/29 15:00:12,857 INFO BlockManagerMasterEndpoint: Registering block manager 10.1.2.224:35157 with 2.1 GB RAM, BlockManagerId(0, 10.1.2.224, 35157)
17/01/29 15:00:12,880 INFO CoarseGrainedSchedulerBackend$DriverEndpoint: Registered executor NettyRpcEndpointRef(null) (10.1.2.191:40452) with ID 5
17/01/29 15:00:12,903 INFO BlockManagerMasterEndpoint: Registering block manager 10.1.2.38:38828 with 2.1 GB RAM, BlockManagerId(1, 10.1.2.38, 38828)
17/01/29 15:00:12,935 INFO BlockManagerMasterEndpoint: Registering block manager 10.1.2.191:44404 with 2.1 GB RAM, BlockManagerId(5, 10.1.2.191, 44404)
17/01/29 15:00:12,962 INFO CoarseGrainedSchedulerBackend$DriverEndpoint: Registered executor NettyRpcEndpointRef(null) (10.1.2.176:45614) with ID 4
17/01/29 15:00:13,005 INFO CoarseGrainedSchedulerBackend$DriverEndpoint: Registered executor NettyRpcEndpointRef(null) (10.1.2.66:42632) with ID 6
17/01/29 15:00:13,019 INFO BlockManagerMasterEndpoint: Registering block manager 10.1.2.176:44820 with 2.1 GB RAM, BlockManagerId(4, 10.1.2.176, 44820)
17/01/29 15:00:13,060 INFO BlockManagerMasterEndpoint: Registering block manager 10.1.2.66:40837 with 2.1 GB RAM, BlockManagerId(6, 10.1.2.66, 40837)
17/01/29 15:00:13,138 INFO CoarseGrainedSchedulerBackend$DriverEndpoint: Registered executor NettyRpcEndpointRef(null) (10.1.2.28:39128) with ID 2
17/01/29 15:00:13,140 INFO CoarseGrainedSchedulerBackend$DriverEndpoint: Registered executor NettyRpcEndpointRef(null) (10.1.2.65:49110) with ID 3
17/01/29 15:00:13,150 INFO BlockManagerInfo: Added broadcast_1_piece0 in memory on 10.1.2.224:35157 (size: 2.4 KB, free: 2.1 GB)
17/01/29 15:00:13,187 INFO BlockManagerMasterEndpoint: Registering block manager 10.1.2.28:43497 with 2.1 GB RAM, BlockManagerId(2, 10.1.2.28, 43497)
17/01/29 15:00:13,190 INFO BlockManagerMasterEndpoint: Registering block manager 10.1.2.65:37362 with 2.1 GB RAM, BlockManagerId(3, 10.1.2.65, 37362)
17/01/29 15:00:13,312 INFO BlockManagerInfo: Added broadcast_0_piece0 in memory on 10.1.2.224:35157 (size: 16.5 KB, free: 2.1 GB)
17/01/29 15:00:15,979 INFO CoarseGrainedSchedulerBackend$DriverEndpoint: Registered executor NettyRpcEndpointRef(null) (10.1.2.139:42690) with ID 7
17/01/29 15:00:16,042 INFO BlockManagerMasterEndpoint: Registering block manager 10.1.2.139:33064 with 2.1 GB RAM, BlockManagerId(7, 10.1.2.139, 33064)
17/01/29 15:00:18,301 INFO BlockManagerInfo: Added rdd_5_0 in memory on 10.1.2.224:35157 (size: 44.3 MB, free: 2.0 GB)
17/01/29 15:00:18,358 INFO TaskSetManager: Finished task 0.0 in stage 0.0 (TID 0) in 5546 ms on 10.1.2.224 (1/1)
17/01/29 15:00:18,359 INFO TaskSchedulerImpl: Removed TaskSet 0.0, whose tasks have all completed, from pool 
17/01/29 15:00:18,362 INFO DAGScheduler: ResultStage 0 (first at GeneralizedLinearAlgorithm.scala:246) finished in 5.896 s
17/01/29 15:00:18,366 INFO DAGScheduler: Job 0 finished: first at GeneralizedLinearAlgorithm.scala:246, took 6.000758 s
17/01/29 15:00:18,377 INFO SparkContext: Starting job: count at DataValidators.scala:40
17/01/29 15:00:18,379 INFO DAGScheduler: Got job 1 (count at DataValidators.scala:40) with 32 output partitions
17/01/29 15:00:18,379 INFO DAGScheduler: Final stage: ResultStage 1 (count at DataValidators.scala:40)
17/01/29 15:00:18,379 INFO DAGScheduler: Parents of final stage: List()
17/01/29 15:00:18,382 INFO DAGScheduler: Missing parents: List()
17/01/29 15:00:18,382 INFO DAGScheduler: Submitting ResultStage 1 (MapPartitionsRDD[7] at filter at DataValidators.scala:40), which has no missing parents
17/01/29 15:00:18,396 INFO MemoryStore: Block broadcast_2 stored as values in memory (estimated size 3.9 KB, free 2.1 GB)
17/01/29 15:00:18,398 INFO MemoryStore: Block broadcast_2_piece0 stored as bytes in memory (estimated size 2.2 KB, free 2.1 GB)
17/01/29 15:00:18,399 INFO BlockManagerInfo: Added broadcast_2_piece0 in memory on 10.1.2.152:42412 (size: 2.2 KB, free: 2.1 GB)
17/01/29 15:00:18,400 INFO SparkContext: Created broadcast 2 from broadcast at DAGScheduler.scala:1012
17/01/29 15:00:18,401 INFO DAGScheduler: Submitting 32 missing tasks from ResultStage 1 (MapPartitionsRDD[7] at filter at DataValidators.scala:40)
17/01/29 15:00:18,401 INFO TaskSchedulerImpl: Adding task set 1.0 with 32 tasks
17/01/29 15:00:18,407 INFO TaskSetManager: Starting task 0.0 in stage 1.0 (TID 1, 10.1.2.224, partition 0, PROCESS_LOCAL, 5373 bytes)
17/01/29 15:00:18,410 INFO TaskSetManager: Starting task 1.0 in stage 1.0 (TID 2, 10.1.2.224, partition 1, NODE_LOCAL, 5373 bytes)
17/01/29 15:00:18,413 INFO TaskSetManager: Starting task 5.0 in stage 1.0 (TID 3, 10.1.2.28, partition 5, NODE_LOCAL, 5373 bytes)
17/01/29 15:00:18,415 INFO TaskSetManager: Starting task 12.0 in stage 1.0 (TID 4, 10.1.2.191, partition 12, NODE_LOCAL, 5373 bytes)
17/01/29 15:00:18,418 INFO TaskSetManager: Starting task 3.0 in stage 1.0 (TID 5, 10.1.2.65, partition 3, NODE_LOCAL, 5373 bytes)
17/01/29 15:00:18,421 INFO TaskSetManager: Starting task 17.0 in stage 1.0 (TID 6, 10.1.2.38, partition 17, NODE_LOCAL, 5373 bytes)
17/01/29 15:00:18,423 INFO TaskSetManager: Starting task 8.0 in stage 1.0 (TID 7, 10.1.2.176, partition 8, NODE_LOCAL, 5373 bytes)
17/01/29 15:00:18,425 INFO TaskSetManager: Starting task 13.0 in stage 1.0 (TID 8, 10.1.2.139, partition 13, NODE_LOCAL, 5373 bytes)
17/01/29 15:00:18,427 INFO TaskSetManager: Starting task 6.0 in stage 1.0 (TID 9, 10.1.2.66, partition 6, NODE_LOCAL, 5373 bytes)
17/01/29 15:00:18,429 INFO TaskSetManager: Starting task 10.0 in stage 1.0 (TID 10, 10.1.2.224, partition 10, NODE_LOCAL, 5373 bytes)
17/01/29 15:00:18,431 INFO TaskSetManager: Starting task 15.0 in stage 1.0 (TID 11, 10.1.2.28, partition 15, NODE_LOCAL, 5373 bytes)
17/01/29 15:00:18,433 INFO TaskSetManager: Starting task 24.0 in stage 1.0 (TID 12, 10.1.2.191, partition 24, NODE_LOCAL, 5373 bytes)
17/01/29 15:00:18,435 INFO TaskSetManager: Starting task 19.0 in stage 1.0 (TID 13, 10.1.2.65, partition 19, NODE_LOCAL, 5373 bytes)
17/01/29 15:00:18,437 INFO TaskSetManager: Starting task 22.0 in stage 1.0 (TID 14, 10.1.2.38, partition 22, NODE_LOCAL, 5373 bytes)
17/01/29 15:00:18,439 INFO TaskSetManager: Starting task 29.0 in stage 1.0 (TID 15, 10.1.2.176, partition 29, NODE_LOCAL, 5373 bytes)
17/01/29 15:00:18,441 INFO TaskSetManager: Starting task 20.0 in stage 1.0 (TID 16, 10.1.2.224, partition 20, NODE_LOCAL, 5373 bytes)
17/01/29 15:00:18,443 INFO TaskSetManager: Starting task 26.0 in stage 1.0 (TID 17, 10.1.2.28, partition 26, NODE_LOCAL, 5373 bytes)
17/01/29 15:00:18,445 INFO TaskSetManager: Starting task 31.0 in stage 1.0 (TID 18, 10.1.2.65, partition 31, NODE_LOCAL, 5373 bytes)
17/01/29 15:00:18,447 INFO TaskSetManager: Starting task 27.0 in stage 1.0 (TID 19, 10.1.2.38, partition 27, NODE_LOCAL, 5373 bytes)
17/01/29 15:00:18,448 INFO CoarseGrainedSchedulerBackend$DriverEndpoint: Launching task 1 on executor id: 0 hostname: 10.1.2.224.
17/01/29 15:00:18,449 INFO CoarseGrainedSchedulerBackend$DriverEndpoint: Launching task 2 on executor id: 0 hostname: 10.1.2.224.
17/01/29 15:00:18,450 INFO CoarseGrainedSchedulerBackend$DriverEndpoint: Launching task 10 on executor id: 0 hostname: 10.1.2.224.
17/01/29 15:00:18,451 INFO CoarseGrainedSchedulerBackend$DriverEndpoint: Launching task 16 on executor id: 0 hostname: 10.1.2.224.
17/01/29 15:00:18,452 INFO CoarseGrainedSchedulerBackend$DriverEndpoint: Launching task 3 on executor id: 2 hostname: 10.1.2.28.
17/01/29 15:00:18,453 INFO CoarseGrainedSchedulerBackend$DriverEndpoint: Launching task 11 on executor id: 2 hostname: 10.1.2.28.
17/01/29 15:00:18,454 INFO CoarseGrainedSchedulerBackend$DriverEndpoint: Launching task 17 on executor id: 2 hostname: 10.1.2.28.
17/01/29 15:00:18,455 INFO CoarseGrainedSchedulerBackend$DriverEndpoint: Launching task 4 on executor id: 5 hostname: 10.1.2.191.
17/01/29 15:00:18,455 INFO CoarseGrainedSchedulerBackend$DriverEndpoint: Launching task 12 on executor id: 5 hostname: 10.1.2.191.
17/01/29 15:00:18,456 INFO CoarseGrainedSchedulerBackend$DriverEndpoint: Launching task 5 on executor id: 3 hostname: 10.1.2.65.
17/01/29 15:00:18,460 INFO CoarseGrainedSchedulerBackend$DriverEndpoint: Launching task 13 on executor id: 3 hostname: 10.1.2.65.
17/01/29 15:00:18,461 INFO CoarseGrainedSchedulerBackend$DriverEndpoint: Launching task 18 on executor id: 3 hostname: 10.1.2.65.
17/01/29 15:00:18,461 INFO CoarseGrainedSchedulerBackend$DriverEndpoint: Launching task 6 on executor id: 1 hostname: 10.1.2.38.
17/01/29 15:00:18,462 INFO CoarseGrainedSchedulerBackend$DriverEndpoint: Launching task 14 on executor id: 1 hostname: 10.1.2.38.
17/01/29 15:00:18,462 INFO CoarseGrainedSchedulerBackend$DriverEndpoint: Launching task 19 on executor id: 1 hostname: 10.1.2.38.
17/01/29 15:00:18,462 INFO CoarseGrainedSchedulerBackend$DriverEndpoint: Launching task 7 on executor id: 4 hostname: 10.1.2.176.
17/01/29 15:00:18,463 INFO CoarseGrainedSchedulerBackend$DriverEndpoint: Launching task 15 on executor id: 4 hostname: 10.1.2.176.
17/01/29 15:00:18,463 INFO CoarseGrainedSchedulerBackend$DriverEndpoint: Launching task 8 on executor id: 7 hostname: 10.1.2.139.
17/01/29 15:00:18,464 INFO CoarseGrainedSchedulerBackend$DriverEndpoint: Launching task 9 on executor id: 6 hostname: 10.1.2.66.
17/01/29 15:00:18,479 INFO BlockManagerInfo: Added broadcast_2_piece0 in memory on 10.1.2.224:35157 (size: 2.2 KB, free: 2.0 GB)
17/01/29 15:00:18,650 INFO TaskSetManager: Finished task 0.0 in stage 1.0 (TID 1) in 246 ms on 10.1.2.224 (1/32)
10.144: [GC [PSYoungGen: 1024512K->140460K(1195008K)] 1024512K->140468K(3926016K), 0.0681250 secs] [Times: user=0.10 sys=0.03, real=0.06 secs] 
17/01/29 15:00:18,811 INFO BlockManagerInfo: Added broadcast_2_piece0 in memory on 10.1.2.139:33064 (size: 2.2 KB, free: 2.1 GB)
17/01/29 15:00:18,851 INFO BlockManagerInfo: Added broadcast_2_piece0 in memory on 10.1.2.191:44404 (size: 2.2 KB, free: 2.1 GB)
17/01/29 15:00:18,852 INFO BlockManagerInfo: Added broadcast_2_piece0 in memory on 10.1.2.66:40837 (size: 2.2 KB, free: 2.1 GB)
17/01/29 15:00:18,853 INFO BlockManagerInfo: Added broadcast_2_piece0 in memory on 10.1.2.38:38828 (size: 2.2 KB, free: 2.1 GB)
17/01/29 15:00:18,857 INFO BlockManagerInfo: Added broadcast_2_piece0 in memory on 10.1.2.176:44820 (size: 2.2 KB, free: 2.1 GB)
17/01/29 15:00:18,858 INFO BlockManagerInfo: Removed broadcast_1_piece0 on 10.1.2.152:42412 in memory (size: 2.4 KB, free: 2.1 GB)
17/01/29 15:00:18,869 INFO BlockManagerInfo: Removed broadcast_1_piece0 on 10.1.2.224:35157 in memory (size: 2.4 KB, free: 2.0 GB)
17/01/29 15:00:18,871 INFO BlockManagerInfo: Added broadcast_2_piece0 in memory on 10.1.2.28:43497 (size: 2.2 KB, free: 2.1 GB)
17/01/29 15:00:18,876 INFO BlockManagerInfo: Added broadcast_2_piece0 in memory on 10.1.2.65:37362 (size: 2.2 KB, free: 2.1 GB)
17/01/29 15:00:19,006 INFO BlockManagerInfo: Added broadcast_0_piece0 in memory on 10.1.2.139:33064 (size: 16.5 KB, free: 2.1 GB)
17/01/29 15:00:19,037 INFO BlockManagerInfo: Added broadcast_0_piece0 in memory on 10.1.2.38:38828 (size: 16.5 KB, free: 2.1 GB)
17/01/29 15:00:19,041 INFO BlockManagerInfo: Added broadcast_0_piece0 in memory on 10.1.2.66:40837 (size: 16.5 KB, free: 2.1 GB)
17/01/29 15:00:19,048 INFO BlockManagerInfo: Added broadcast_0_piece0 in memory on 10.1.2.65:37362 (size: 16.5 KB, free: 2.1 GB)
17/01/29 15:00:19,059 INFO BlockManagerInfo: Added broadcast_0_piece0 in memory on 10.1.2.28:43497 (size: 16.5 KB, free: 2.1 GB)
17/01/29 15:00:19,061 INFO BlockManagerInfo: Added broadcast_0_piece0 in memory on 10.1.2.191:44404 (size: 16.5 KB, free: 2.1 GB)
17/01/29 15:00:19,070 INFO BlockManagerInfo: Added broadcast_0_piece0 in memory on 10.1.2.176:44820 (size: 16.5 KB, free: 2.1 GB)
17/01/29 15:00:21,612 INFO TaskSetManager: Starting task 2.0 in stage 1.0 (TID 20, 10.1.2.38, partition 2, ANY, 5373 bytes)
17/01/29 15:00:21,614 INFO TaskSetManager: Starting task 4.0 in stage 1.0 (TID 21, 10.1.2.139, partition 4, ANY, 5373 bytes)
17/01/29 15:00:21,615 INFO TaskSetManager: Starting task 7.0 in stage 1.0 (TID 22, 10.1.2.65, partition 7, ANY, 5373 bytes)
17/01/29 15:00:21,617 INFO TaskSetManager: Starting task 9.0 in stage 1.0 (TID 23, 10.1.2.28, partition 9, ANY, 5373 bytes)
17/01/29 15:00:21,619 INFO TaskSetManager: Starting task 11.0 in stage 1.0 (TID 24, 10.1.2.66, partition 11, ANY, 5373 bytes)
17/01/29 15:00:21,621 INFO TaskSetManager: Starting task 14.0 in stage 1.0 (TID 25, 10.1.2.191, partition 14, ANY, 5373 bytes)
17/01/29 15:00:21,622 INFO TaskSetManager: Starting task 16.0 in stage 1.0 (TID 26, 10.1.2.224, partition 16, ANY, 5373 bytes)
17/01/29 15:00:21,624 INFO TaskSetManager: Starting task 18.0 in stage 1.0 (TID 27, 10.1.2.176, partition 18, ANY, 5373 bytes)
17/01/29 15:00:21,626 INFO TaskSetManager: Starting task 21.0 in stage 1.0 (TID 28, 10.1.2.139, partition 21, ANY, 5373 bytes)
17/01/29 15:00:21,628 INFO TaskSetManager: Starting task 23.0 in stage 1.0 (TID 29, 10.1.2.66, partition 23, ANY, 5373 bytes)
17/01/29 15:00:21,629 INFO TaskSetManager: Starting task 25.0 in stage 1.0 (TID 30, 10.1.2.191, partition 25, ANY, 5373 bytes)
17/01/29 15:00:21,631 INFO TaskSetManager: Starting task 28.0 in stage 1.0 (TID 31, 10.1.2.176, partition 28, ANY, 5373 bytes)
17/01/29 15:00:21,633 INFO TaskSetManager: Starting task 30.0 in stage 1.0 (TID 32, 10.1.2.139, partition 30, ANY, 5373 bytes)
17/01/29 15:00:21,633 INFO CoarseGrainedSchedulerBackend$DriverEndpoint: Launching task 20 on executor id: 1 hostname: 10.1.2.38.
17/01/29 15:00:21,634 INFO CoarseGrainedSchedulerBackend$DriverEndpoint: Launching task 21 on executor id: 7 hostname: 10.1.2.139.
17/01/29 15:00:21,634 INFO CoarseGrainedSchedulerBackend$DriverEndpoint: Launching task 28 on executor id: 7 hostname: 10.1.2.139.
17/01/29 15:00:21,635 INFO CoarseGrainedSchedulerBackend$DriverEndpoint: Launching task 32 on executor id: 7 hostname: 10.1.2.139.
17/01/29 15:00:21,635 INFO CoarseGrainedSchedulerBackend$DriverEndpoint: Launching task 22 on executor id: 3 hostname: 10.1.2.65.
17/01/29 15:00:21,636 INFO CoarseGrainedSchedulerBackend$DriverEndpoint: Launching task 23 on executor id: 2 hostname: 10.1.2.28.
17/01/29 15:00:21,637 INFO CoarseGrainedSchedulerBackend$DriverEndpoint: Launching task 24 on executor id: 6 hostname: 10.1.2.66.
17/01/29 15:00:21,637 INFO CoarseGrainedSchedulerBackend$DriverEndpoint: Launching task 29 on executor id: 6 hostname: 10.1.2.66.
17/01/29 15:00:21,638 INFO CoarseGrainedSchedulerBackend$DriverEndpoint: Launching task 25 on executor id: 5 hostname: 10.1.2.191.
17/01/29 15:00:21,639 INFO CoarseGrainedSchedulerBackend$DriverEndpoint: Launching task 30 on executor id: 5 hostname: 10.1.2.191.
17/01/29 15:00:21,639 INFO CoarseGrainedSchedulerBackend$DriverEndpoint: Launching task 26 on executor id: 0 hostname: 10.1.2.224.
17/01/29 15:00:21,640 INFO CoarseGrainedSchedulerBackend$DriverEndpoint: Launching task 27 on executor id: 4 hostname: 10.1.2.176.
17/01/29 15:00:21,640 INFO CoarseGrainedSchedulerBackend$DriverEndpoint: Launching task 31 on executor id: 4 hostname: 10.1.2.176.
17/01/29 15:00:28,223 INFO BlockManagerInfo: Added rdd_5_20 in memory on 10.1.2.224:35157 (size: 44.4 MB, free: 2031.7 MB)
17/01/29 15:00:28,260 INFO TaskSetManager: Finished task 20.0 in stage 1.0 (TID 16) in 9820 ms on 10.1.2.224 (2/32)
17/01/29 15:00:28,755 INFO BlockManagerInfo: Added rdd_5_10 in memory on 10.1.2.224:35157 (size: 44.4 MB, free: 1987.3 MB)
17/01/29 15:00:28,780 INFO TaskSetManager: Finished task 10.0 in stage 1.0 (TID 10) in 10352 ms on 10.1.2.224 (3/32)
17/01/29 15:00:28,886 INFO BlockManagerInfo: Added rdd_5_1 in memory on 10.1.2.224:35157 (size: 44.4 MB, free: 1942.9 MB)
17/01/29 15:00:28,910 INFO TaskSetManager: Finished task 1.0 in stage 1.0 (TID 2) in 10500 ms on 10.1.2.224 (4/32)
17/01/29 15:00:29,007 INFO BlockManagerInfo: Added rdd_5_13 in memory on 10.1.2.139:33064 (size: 44.4 MB, free: 2.0 GB)
17/01/29 15:00:29,090 INFO TaskSetManager: Finished task 13.0 in stage 1.0 (TID 8) in 10666 ms on 10.1.2.139 (5/32)
17/01/29 15:00:29,946 INFO BlockManagerInfo: Added rdd_5_6 in memory on 10.1.2.66:40837 (size: 44.4 MB, free: 2.0 GB)
17/01/29 15:00:30,024 INFO TaskSetManager: Finished task 6.0 in stage 1.0 (TID 9) in 11597 ms on 10.1.2.66 (6/32)
17/01/29 15:00:30,057 INFO BlockManagerInfo: Added rdd_5_24 in memory on 10.1.2.191:44404 (size: 44.4 MB, free: 2.0 GB)
17/01/29 15:00:30,164 INFO TaskSetManager: Finished task 24.0 in stage 1.0 (TID 12) in 11732 ms on 10.1.2.191 (7/32)
17/01/29 15:00:30,351 INFO BlockManagerInfo: Added rdd_5_12 in memory on 10.1.2.191:44404 (size: 44.4 MB, free: 2031.6 MB)
17/01/29 15:00:30,370 INFO TaskSetManager: Finished task 12.0 in stage 1.0 (TID 4) in 11956 ms on 10.1.2.191 (8/32)
17/01/29 15:00:30,385 INFO BlockManagerInfo: Added rdd_5_29 in memory on 10.1.2.176:44820 (size: 44.4 MB, free: 2.0 GB)
17/01/29 15:00:30,453 INFO BlockManagerInfo: Added rdd_5_16 in memory on 10.1.2.224:35157 (size: 44.4 MB, free: 1898.6 MB)
17/01/29 15:00:30,457 INFO TaskSetManager: Finished task 29.0 in stage 1.0 (TID 15) in 12020 ms on 10.1.2.176 (9/32)
17/01/29 15:00:30,472 INFO TaskSetManager: Finished task 16.0 in stage 1.0 (TID 26) in 8851 ms on 10.1.2.224 (10/32)
17/01/29 15:00:30,550 INFO BlockManagerInfo: Added rdd_5_8 in memory on 10.1.2.176:44820 (size: 44.4 MB, free: 2031.6 MB)
17/01/29 15:00:30,571 INFO TaskSetManager: Finished task 8.0 in stage 1.0 (TID 7) in 12150 ms on 10.1.2.176 (11/32)
17/01/29 15:00:31,102 INFO BlockManagerInfo: Added rdd_5_23 in memory on 10.1.2.66:40837 (size: 44.3 MB, free: 2031.7 MB)
17/01/29 15:00:31,120 INFO TaskSetManager: Finished task 23.0 in stage 1.0 (TID 29) in 9494 ms on 10.1.2.66 (12/32)
17/01/29 15:00:31,235 INFO BlockManagerInfo: Added rdd_5_4 in memory on 10.1.2.139:33064 (size: 44.4 MB, free: 2031.6 MB)
17/01/29 15:00:31,250 INFO TaskSetManager: Finished task 4.0 in stage 1.0 (TID 21) in 9638 ms on 10.1.2.139 (13/32)
17/01/29 15:00:31,255 INFO BlockManagerInfo: Added rdd_5_30 in memory on 10.1.2.139:33064 (size: 44.4 MB, free: 1987.3 MB)
17/01/29 15:00:31,258 INFO BlockManagerInfo: Added rdd_5_25 in memory on 10.1.2.191:44404 (size: 44.3 MB, free: 1987.2 MB)
17/01/29 15:00:31,275 INFO BlockManagerInfo: Added rdd_5_21 in memory on 10.1.2.139:33064 (size: 44.4 MB, free: 1942.9 MB)
17/01/29 15:00:31,279 INFO TaskSetManager: Finished task 25.0 in stage 1.0 (TID 30) in 9650 ms on 10.1.2.191 (14/32)
17/01/29 15:00:31,282 INFO TaskSetManager: Finished task 30.0 in stage 1.0 (TID 32) in 9651 ms on 10.1.2.139 (15/32)
17/01/29 15:00:31,291 INFO TaskSetManager: Finished task 21.0 in stage 1.0 (TID 28) in 9667 ms on 10.1.2.139 (16/32)
17/01/29 15:00:31,364 INFO BlockManagerInfo: Added rdd_5_14 in memory on 10.1.2.191:44404 (size: 44.4 MB, free: 1942.8 MB)
17/01/29 15:00:31,381 INFO TaskSetManager: Finished task 14.0 in stage 1.0 (TID 25) in 9762 ms on 10.1.2.191 (17/32)
17/01/29 15:00:31,436 INFO BlockManagerInfo: Added rdd_5_11 in memory on 10.1.2.66:40837 (size: 44.4 MB, free: 1987.3 MB)
17/01/29 15:00:31,453 INFO TaskSetManager: Finished task 11.0 in stage 1.0 (TID 24) in 9836 ms on 10.1.2.66 (18/32)
17/01/29 15:00:31,466 INFO BlockManagerInfo: Added rdd_5_26 in memory on 10.1.2.28:43497 (size: 44.4 MB, free: 2.0 GB)
17/01/29 15:00:31,541 INFO TaskSetManager: Finished task 26.0 in stage 1.0 (TID 17) in 13100 ms on 10.1.2.28 (19/32)
17/01/29 15:00:31,690 INFO BlockManagerInfo: Added rdd_5_18 in memory on 10.1.2.176:44820 (size: 44.3 MB, free: 1987.3 MB)
17/01/29 15:00:31,695 INFO BlockManagerInfo: Added rdd_5_5 in memory on 10.1.2.28:43497 (size: 44.3 MB, free: 2031.7 MB)
17/01/29 15:00:31,713 INFO TaskSetManager: Finished task 5.0 in stage 1.0 (TID 3) in 13302 ms on 10.1.2.28 (20/32)
17/01/29 15:00:31,714 INFO BlockManagerInfo: Added rdd_5_28 in memory on 10.1.2.176:44820 (size: 44.4 MB, free: 1942.9 MB)
17/01/29 15:00:31,717 INFO TaskSetManager: Finished task 18.0 in stage 1.0 (TID 27) in 10094 ms on 10.1.2.176 (21/32)
17/01/29 15:00:31,725 INFO BlockManagerInfo: Added rdd_5_15 in memory on 10.1.2.28:43497 (size: 44.4 MB, free: 1987.3 MB)
17/01/29 15:00:31,733 INFO TaskSetManager: Finished task 28.0 in stage 1.0 (TID 31) in 10104 ms on 10.1.2.176 (22/32)
17/01/29 15:00:31,753 INFO TaskSetManager: Finished task 15.0 in stage 1.0 (TID 11) in 13323 ms on 10.1.2.28 (23/32)
17/01/29 15:00:32,281 INFO BlockManagerInfo: Added rdd_5_27 in memory on 10.1.2.38:38828 (size: 44.4 MB, free: 2.0 GB)
17/01/29 15:00:32,357 INFO TaskSetManager: Finished task 27.0 in stage 1.0 (TID 19) in 13912 ms on 10.1.2.38 (24/32)
17/01/29 15:00:32,395 INFO BlockManagerInfo: Added rdd_5_9 in memory on 10.1.2.28:43497 (size: 44.4 MB, free: 1942.9 MB)
17/01/29 15:00:32,409 INFO TaskSetManager: Finished task 9.0 in stage 1.0 (TID 23) in 10793 ms on 10.1.2.28 (25/32)
17/01/29 15:00:32,458 INFO BlockManagerInfo: Added rdd_5_22 in memory on 10.1.2.38:38828 (size: 44.3 MB, free: 2031.6 MB)
17/01/29 15:00:32,476 INFO TaskSetManager: Finished task 22.0 in stage 1.0 (TID 14) in 14041 ms on 10.1.2.38 (26/32)
17/01/29 15:00:32,846 INFO BlockManagerInfo: Added rdd_5_17 in memory on 10.1.2.38:38828 (size: 44.4 MB, free: 1987.2 MB)
17/01/29 15:00:32,863 INFO TaskSetManager: Finished task 17.0 in stage 1.0 (TID 6) in 14445 ms on 10.1.2.38 (27/32)
17/01/29 15:00:33,106 INFO BlockManagerInfo: Added rdd_5_2 in memory on 10.1.2.38:38828 (size: 44.4 MB, free: 1942.8 MB)
17/01/29 15:00:33,123 INFO TaskSetManager: Finished task 2.0 in stage 1.0 (TID 20) in 11512 ms on 10.1.2.38 (28/32)
17/01/29 15:00:33,139 INFO BlockManagerInfo: Added rdd_5_3 in memory on 10.1.2.65:37362 (size: 44.4 MB, free: 2.0 GB)
17/01/29 15:00:33,203 INFO TaskSetManager: Finished task 3.0 in stage 1.0 (TID 5) in 14788 ms on 10.1.2.65 (29/32)
17/01/29 15:00:33,249 INFO BlockManagerInfo: Added rdd_5_31 in memory on 10.1.2.65:37362 (size: 44.3 MB, free: 2031.7 MB)
17/01/29 15:00:33,265 INFO TaskSetManager: Finished task 31.0 in stage 1.0 (TID 18) in 14822 ms on 10.1.2.65 (30/32)
17/01/29 15:00:33,419 INFO BlockManagerInfo: Added rdd_5_19 in memory on 10.1.2.65:37362 (size: 44.4 MB, free: 1987.2 MB)
17/01/29 15:00:33,450 INFO TaskSetManager: Finished task 19.0 in stage 1.0 (TID 13) in 15017 ms on 10.1.2.65 (31/32)
17/01/29 15:00:33,866 INFO BlockManagerInfo: Added rdd_5_7 in memory on 10.1.2.65:37362 (size: 44.4 MB, free: 1942.9 MB)
17/01/29 15:00:33,880 INFO TaskSetManager: Finished task 7.0 in stage 1.0 (TID 22) in 12266 ms on 10.1.2.65 (32/32)
17/01/29 15:00:33,881 INFO TaskSchedulerImpl: Removed TaskSet 1.0, whose tasks have all completed, from pool 
17/01/29 15:00:33,881 INFO DAGScheduler: ResultStage 1 (count at DataValidators.scala:40) finished in 15.477 s
17/01/29 15:00:33,882 INFO DAGScheduler: Job 1 finished: count at DataValidators.scala:40, took 15.503897 s
17/01/29 15:00:33,893 INFO SparkContext: Starting job: count at GradientDescent.scala:209
17/01/29 15:00:33,894 INFO DAGScheduler: Got job 2 (count at GradientDescent.scala:209) with 32 output partitions
17/01/29 15:00:33,894 INFO DAGScheduler: Final stage: ResultStage 2 (count at GradientDescent.scala:209)
17/01/29 15:00:33,894 INFO DAGScheduler: Parents of final stage: List()
17/01/29 15:00:33,897 INFO DAGScheduler: Missing parents: List()
17/01/29 15:00:33,898 INFO DAGScheduler: Submitting ResultStage 2 (MapPartitionsRDD[8] at map at GeneralizedLinearAlgorithm.scala:297), which has no missing parents
17/01/29 15:00:33,902 INFO MemoryStore: Block broadcast_3 stored as values in memory (estimated size 3.9 KB, free 2.1 GB)
17/01/29 15:00:33,904 INFO MemoryStore: Block broadcast_3_piece0 stored as bytes in memory (estimated size 2.2 KB, free 2.1 GB)
17/01/29 15:00:33,904 INFO BlockManagerInfo: Added broadcast_3_piece0 in memory on 10.1.2.152:42412 (size: 2.2 KB, free: 2.1 GB)
17/01/29 15:00:33,905 INFO SparkContext: Created broadcast 3 from broadcast at DAGScheduler.scala:1012
17/01/29 15:00:33,906 INFO DAGScheduler: Submitting 32 missing tasks from ResultStage 2 (MapPartitionsRDD[8] at map at GeneralizedLinearAlgorithm.scala:297)
17/01/29 15:00:33,907 INFO TaskSchedulerImpl: Adding task set 2.0 with 32 tasks
17/01/29 15:00:33,910 INFO TaskSetManager: Starting task 2.0 in stage 2.0 (TID 33, 10.1.2.38, partition 2, PROCESS_LOCAL, 5373 bytes)
17/01/29 15:00:33,911 INFO TaskSetManager: Starting task 0.0 in stage 2.0 (TID 34, 10.1.2.224, partition 0, PROCESS_LOCAL, 5373 bytes)
17/01/29 15:00:33,912 INFO TaskSetManager: Starting task 5.0 in stage 2.0 (TID 35, 10.1.2.28, partition 5, PROCESS_LOCAL, 5373 bytes)
17/01/29 15:00:33,913 INFO TaskSetManager: Starting task 8.0 in stage 2.0 (TID 36, 10.1.2.176, partition 8, PROCESS_LOCAL, 5373 bytes)
17/01/29 15:00:33,914 INFO TaskSetManager: Starting task 12.0 in stage 2.0 (TID 37, 10.1.2.191, partition 12, PROCESS_LOCAL, 5373 bytes)
17/01/29 15:00:33,915 INFO TaskSetManager: Starting task 3.0 in stage 2.0 (TID 38, 10.1.2.65, partition 3, PROCESS_LOCAL, 5373 bytes)
17/01/29 15:00:33,916 INFO TaskSetManager: Starting task 6.0 in stage 2.0 (TID 39, 10.1.2.66, partition 6, PROCESS_LOCAL, 5373 bytes)
17/01/29 15:00:33,918 INFO TaskSetManager: Starting task 4.0 in stage 2.0 (TID 40, 10.1.2.139, partition 4, PROCESS_LOCAL, 5373 bytes)
17/01/29 15:00:33,919 INFO TaskSetManager: Starting task 17.0 in stage 2.0 (TID 41, 10.1.2.38, partition 17, PROCESS_LOCAL, 5373 bytes)
17/01/29 15:00:33,921 INFO TaskSetManager: Starting task 1.0 in stage 2.0 (TID 42, 10.1.2.224, partition 1, PROCESS_LOCAL, 5373 bytes)
17/01/29 15:00:33,922 INFO TaskSetManager: Starting task 9.0 in stage 2.0 (TID 43, 10.1.2.28, partition 9, PROCESS_LOCAL, 5373 bytes)
17/01/29 15:00:33,923 INFO TaskSetManager: Starting task 18.0 in stage 2.0 (TID 44, 10.1.2.176, partition 18, PROCESS_LOCAL, 5373 bytes)
17/01/29 15:00:33,924 INFO TaskSetManager: Starting task 14.0 in stage 2.0 (TID 45, 10.1.2.191, partition 14, PROCESS_LOCAL, 5373 bytes)
17/01/29 15:00:33,925 INFO TaskSetManager: Starting task 7.0 in stage 2.0 (TID 46, 10.1.2.65, partition 7, PROCESS_LOCAL, 5373 bytes)
17/01/29 15:00:33,926 INFO TaskSetManager: Starting task 11.0 in stage 2.0 (TID 47, 10.1.2.66, partition 11, PROCESS_LOCAL, 5373 bytes)
17/01/29 15:00:33,928 INFO TaskSetManager: Starting task 13.0 in stage 2.0 (TID 48, 10.1.2.139, partition 13, PROCESS_LOCAL, 5373 bytes)
17/01/29 15:00:33,929 INFO TaskSetManager: Starting task 22.0 in stage 2.0 (TID 49, 10.1.2.38, partition 22, PROCESS_LOCAL, 5373 bytes)
17/01/29 15:00:33,930 INFO TaskSetManager: Starting task 10.0 in stage 2.0 (TID 50, 10.1.2.224, partition 10, PROCESS_LOCAL, 5373 bytes)
17/01/29 15:00:33,931 INFO TaskSetManager: Starting task 15.0 in stage 2.0 (TID 51, 10.1.2.28, partition 15, PROCESS_LOCAL, 5373 bytes)
17/01/29 15:00:33,931 INFO TaskSetManager: Starting task 28.0 in stage 2.0 (TID 52, 10.1.2.176, partition 28, PROCESS_LOCAL, 5373 bytes)
17/01/29 15:00:33,932 INFO TaskSetManager: Starting task 24.0 in stage 2.0 (TID 53, 10.1.2.191, partition 24, PROCESS_LOCAL, 5373 bytes)
17/01/29 15:00:33,933 INFO TaskSetManager: Starting task 19.0 in stage 2.0 (TID 54, 10.1.2.65, partition 19, PROCESS_LOCAL, 5373 bytes)
17/01/29 15:00:33,934 INFO TaskSetManager: Starting task 23.0 in stage 2.0 (TID 55, 10.1.2.66, partition 23, PROCESS_LOCAL, 5373 bytes)
17/01/29 15:00:33,935 INFO TaskSetManager: Starting task 21.0 in stage 2.0 (TID 56, 10.1.2.139, partition 21, PROCESS_LOCAL, 5373 bytes)
17/01/29 15:00:33,937 INFO TaskSetManager: Starting task 27.0 in stage 2.0 (TID 57, 10.1.2.38, partition 27, PROCESS_LOCAL, 5373 bytes)
17/01/29 15:00:33,938 INFO TaskSetManager: Starting task 16.0 in stage 2.0 (TID 58, 10.1.2.224, partition 16, PROCESS_LOCAL, 5373 bytes)
17/01/29 15:00:33,938 INFO TaskSetManager: Starting task 26.0 in stage 2.0 (TID 59, 10.1.2.28, partition 26, PROCESS_LOCAL, 5373 bytes)
17/01/29 15:00:33,939 INFO TaskSetManager: Starting task 29.0 in stage 2.0 (TID 60, 10.1.2.176, partition 29, PROCESS_LOCAL, 5373 bytes)
17/01/29 15:00:33,941 INFO TaskSetManager: Starting task 25.0 in stage 2.0 (TID 61, 10.1.2.191, partition 25, PROCESS_LOCAL, 5373 bytes)
17/01/29 15:00:33,942 INFO TaskSetManager: Starting task 31.0 in stage 2.0 (TID 62, 10.1.2.65, partition 31, PROCESS_LOCAL, 5373 bytes)
17/01/29 15:00:33,943 INFO TaskSetManager: Starting task 30.0 in stage 2.0 (TID 63, 10.1.2.139, partition 30, PROCESS_LOCAL, 5373 bytes)
17/01/29 15:00:33,944 INFO CoarseGrainedSchedulerBackend$DriverEndpoint: Launching task 33 on executor id: 1 hostname: 10.1.2.38.
17/01/29 15:00:33,944 INFO CoarseGrainedSchedulerBackend$DriverEndpoint: Launching task 41 on executor id: 1 hostname: 10.1.2.38.
17/01/29 15:00:33,945 INFO CoarseGrainedSchedulerBackend$DriverEndpoint: Launching task 49 on executor id: 1 hostname: 10.1.2.38.
17/01/29 15:00:33,945 INFO CoarseGrainedSchedulerBackend$DriverEndpoint: Launching task 57 on executor id: 1 hostname: 10.1.2.38.
17/01/29 15:00:33,945 INFO CoarseGrainedSchedulerBackend$DriverEndpoint: Launching task 34 on executor id: 0 hostname: 10.1.2.224.
17/01/29 15:00:33,946 INFO CoarseGrainedSchedulerBackend$DriverEndpoint: Launching task 42 on executor id: 0 hostname: 10.1.2.224.
17/01/29 15:00:33,946 INFO CoarseGrainedSchedulerBackend$DriverEndpoint: Launching task 50 on executor id: 0 hostname: 10.1.2.224.
17/01/29 15:00:33,947 INFO CoarseGrainedSchedulerBackend$DriverEndpoint: Launching task 58 on executor id: 0 hostname: 10.1.2.224.
17/01/29 15:00:33,947 INFO CoarseGrainedSchedulerBackend$DriverEndpoint: Launching task 35 on executor id: 2 hostname: 10.1.2.28.
17/01/29 15:00:33,947 INFO CoarseGrainedSchedulerBackend$DriverEndpoint: Launching task 43 on executor id: 2 hostname: 10.1.2.28.
17/01/29 15:00:33,948 INFO CoarseGrainedSchedulerBackend$DriverEndpoint: Launching task 51 on executor id: 2 hostname: 10.1.2.28.
17/01/29 15:00:33,948 INFO CoarseGrainedSchedulerBackend$DriverEndpoint: Launching task 59 on executor id: 2 hostname: 10.1.2.28.
17/01/29 15:00:33,949 INFO CoarseGrainedSchedulerBackend$DriverEndpoint: Launching task 36 on executor id: 4 hostname: 10.1.2.176.
17/01/29 15:00:33,949 INFO CoarseGrainedSchedulerBackend$DriverEndpoint: Launching task 44 on executor id: 4 hostname: 10.1.2.176.
17/01/29 15:00:33,949 INFO CoarseGrainedSchedulerBackend$DriverEndpoint: Launching task 52 on executor id: 4 hostname: 10.1.2.176.
17/01/29 15:00:33,949 INFO CoarseGrainedSchedulerBackend$DriverEndpoint: Launching task 60 on executor id: 4 hostname: 10.1.2.176.
17/01/29 15:00:33,950 INFO CoarseGrainedSchedulerBackend$DriverEndpoint: Launching task 37 on executor id: 5 hostname: 10.1.2.191.
17/01/29 15:00:33,950 INFO CoarseGrainedSchedulerBackend$DriverEndpoint: Launching task 45 on executor id: 5 hostname: 10.1.2.191.
17/01/29 15:00:33,950 INFO CoarseGrainedSchedulerBackend$DriverEndpoint: Launching task 53 on executor id: 5 hostname: 10.1.2.191.
17/01/29 15:00:33,951 INFO CoarseGrainedSchedulerBackend$DriverEndpoint: Launching task 61 on executor id: 5 hostname: 10.1.2.191.
17/01/29 15:00:33,951 INFO CoarseGrainedSchedulerBackend$DriverEndpoint: Launching task 38 on executor id: 3 hostname: 10.1.2.65.
17/01/29 15:00:33,952 INFO CoarseGrainedSchedulerBackend$DriverEndpoint: Launching task 46 on executor id: 3 hostname: 10.1.2.65.
17/01/29 15:00:33,952 INFO CoarseGrainedSchedulerBackend$DriverEndpoint: Launching task 54 on executor id: 3 hostname: 10.1.2.65.
17/01/29 15:00:33,953 INFO CoarseGrainedSchedulerBackend$DriverEndpoint: Launching task 62 on executor id: 3 hostname: 10.1.2.65.
17/01/29 15:00:33,953 INFO CoarseGrainedSchedulerBackend$DriverEndpoint: Launching task 39 on executor id: 6 hostname: 10.1.2.66.
17/01/29 15:00:33,954 INFO CoarseGrainedSchedulerBackend$DriverEndpoint: Launching task 47 on executor id: 6 hostname: 10.1.2.66.
17/01/29 15:00:33,955 INFO CoarseGrainedSchedulerBackend$DriverEndpoint: Launching task 55 on executor id: 6 hostname: 10.1.2.66.
17/01/29 15:00:33,955 INFO CoarseGrainedSchedulerBackend$DriverEndpoint: Launching task 40 on executor id: 7 hostname: 10.1.2.139.
17/01/29 15:00:33,955 INFO CoarseGrainedSchedulerBackend$DriverEndpoint: Launching task 48 on executor id: 7 hostname: 10.1.2.139.
17/01/29 15:00:33,956 INFO CoarseGrainedSchedulerBackend$DriverEndpoint: Launching task 56 on executor id: 7 hostname: 10.1.2.139.
17/01/29 15:00:33,956 INFO CoarseGrainedSchedulerBackend$DriverEndpoint: Launching task 63 on executor id: 7 hostname: 10.1.2.139.
17/01/29 15:00:33,967 INFO BlockManagerInfo: Added broadcast_3_piece0 in memory on 10.1.2.38:38828 (size: 2.2 KB, free: 1942.8 MB)
17/01/29 15:00:33,983 INFO BlockManagerInfo: Added broadcast_3_piece0 in memory on 10.1.2.191:44404 (size: 2.2 KB, free: 1942.8 MB)
17/01/29 15:00:33,986 INFO BlockManagerInfo: Added broadcast_3_piece0 in memory on 10.1.2.176:44820 (size: 2.2 KB, free: 1942.9 MB)
17/01/29 15:00:33,988 INFO BlockManagerInfo: Added broadcast_3_piece0 in memory on 10.1.2.66:40837 (size: 2.2 KB, free: 1987.3 MB)
17/01/29 15:00:34,016 INFO TaskSetManager: Finished task 2.0 in stage 2.0 (TID 33) in 107 ms on 10.1.2.38 (1/32)
17/01/29 15:00:34,022 INFO TaskSetManager: Finished task 27.0 in stage 2.0 (TID 57) in 87 ms on 10.1.2.38 (2/32)
17/01/29 15:00:34,024 INFO TaskSetManager: Finished task 17.0 in stage 2.0 (TID 41) in 106 ms on 10.1.2.38 (3/32)
17/01/29 15:00:34,030 INFO TaskSetManager: Finished task 22.0 in stage 2.0 (TID 49) in 102 ms on 10.1.2.38 (4/32)
17/01/29 15:00:34,033 INFO TaskSetManager: Finished task 11.0 in stage 2.0 (TID 47) in 107 ms on 10.1.2.66 (5/32)
17/01/29 15:00:34,034 INFO TaskSetManager: Finished task 8.0 in stage 2.0 (TID 36) in 122 ms on 10.1.2.176 (6/32)
17/01/29 15:00:34,036 INFO BlockManagerInfo: Added broadcast_3_piece0 in memory on 10.1.2.28:43497 (size: 2.2 KB, free: 1942.9 MB)
17/01/29 15:00:34,036 INFO BlockManagerInfo: Added broadcast_3_piece0 in memory on 10.1.2.65:37362 (size: 2.2 KB, free: 1942.9 MB)
17/01/29 15:00:34,037 INFO BlockManagerInfo: Added broadcast_3_piece0 in memory on 10.1.2.224:35157 (size: 2.2 KB, free: 1898.6 MB)
17/01/29 15:00:34,047 INFO TaskSetManager: Finished task 28.0 in stage 2.0 (TID 52) in 116 ms on 10.1.2.176 (7/32)
17/01/29 15:00:34,053 INFO TaskSetManager: Finished task 25.0 in stage 2.0 (TID 61) in 113 ms on 10.1.2.191 (8/32)
17/01/29 15:00:34,058 INFO TaskSetManager: Finished task 12.0 in stage 2.0 (TID 37) in 145 ms on 10.1.2.191 (9/32)
17/01/29 15:00:34,073 INFO TaskSetManager: Finished task 6.0 in stage 2.0 (TID 39) in 157 ms on 10.1.2.66 (10/32)
17/01/29 15:00:34,077 INFO TaskSetManager: Finished task 23.0 in stage 2.0 (TID 55) in 144 ms on 10.1.2.66 (11/32)
17/01/29 15:00:34,079 INFO TaskSetManager: Finished task 31.0 in stage 2.0 (TID 62) in 138 ms on 10.1.2.65 (12/32)
17/01/29 15:00:34,081 INFO BlockManagerInfo: Added broadcast_3_piece0 in memory on 10.1.2.139:33064 (size: 2.2 KB, free: 1942.9 MB)
17/01/29 15:00:34,082 INFO TaskSetManager: Starting task 20.0 in stage 2.0 (TID 64, 10.1.2.224, partition 20, PROCESS_LOCAL, 5373 bytes)
17/01/29 15:00:34,082 INFO CoarseGrainedSchedulerBackend$DriverEndpoint: Launching task 64 on executor id: 0 hostname: 10.1.2.224.
17/01/29 15:00:34,082 INFO TaskSetManager: Finished task 10.0 in stage 2.0 (TID 50) in 153 ms on 10.1.2.224 (13/32)
17/01/29 15:00:34,084 INFO TaskSetManager: Finished task 0.0 in stage 2.0 (TID 34) in 174 ms on 10.1.2.224 (14/32)
17/01/29 15:00:34,086 INFO TaskSetManager: Finished task 16.0 in stage 2.0 (TID 58) in 149 ms on 10.1.2.224 (15/32)
17/01/29 15:00:34,092 INFO TaskSetManager: Finished task 5.0 in stage 2.0 (TID 35) in 181 ms on 10.1.2.28 (16/32)
17/01/29 15:00:34,094 INFO TaskSetManager: Finished task 1.0 in stage 2.0 (TID 42) in 174 ms on 10.1.2.224 (17/32)
17/01/29 15:00:34,105 INFO TaskSetManager: Finished task 26.0 in stage 2.0 (TID 59) in 167 ms on 10.1.2.28 (18/32)
17/01/29 15:00:34,108 INFO TaskSetManager: Finished task 20.0 in stage 2.0 (TID 64) in 27 ms on 10.1.2.224 (19/32)
17/01/29 15:00:34,113 INFO TaskSetManager: Finished task 19.0 in stage 2.0 (TID 54) in 181 ms on 10.1.2.65 (20/32)
17/01/29 15:00:34,114 INFO TaskSetManager: Finished task 9.0 in stage 2.0 (TID 43) in 193 ms on 10.1.2.28 (21/32)
17/01/29 15:00:34,117 INFO TaskSetManager: Finished task 7.0 in stage 2.0 (TID 46) in 193 ms on 10.1.2.65 (22/32)
17/01/29 15:00:34,122 INFO TaskSetManager: Finished task 14.0 in stage 2.0 (TID 45) in 198 ms on 10.1.2.191 (23/32)
17/01/29 15:00:34,136 INFO TaskSetManager: Finished task 13.0 in stage 2.0 (TID 48) in 210 ms on 10.1.2.139 (24/32)
17/01/29 15:00:34,142 INFO TaskSetManager: Finished task 18.0 in stage 2.0 (TID 44) in 220 ms on 10.1.2.176 (25/32)
17/01/29 15:00:34,145 INFO TaskSetManager: Finished task 21.0 in stage 2.0 (TID 56) in 211 ms on 10.1.2.139 (26/32)
17/01/29 15:00:34,163 INFO TaskSetManager: Finished task 24.0 in stage 2.0 (TID 53) in 232 ms on 10.1.2.191 (27/32)
17/01/29 15:00:34,172 INFO TaskSetManager: Finished task 29.0 in stage 2.0 (TID 60) in 233 ms on 10.1.2.176 (28/32)
17/01/29 15:00:34,230 INFO TaskSetManager: Finished task 15.0 in stage 2.0 (TID 51) in 300 ms on 10.1.2.28 (29/32)
17/01/29 15:00:34,251 INFO TaskSetManager: Finished task 3.0 in stage 2.0 (TID 38) in 336 ms on 10.1.2.65 (30/32)
17/01/29 15:00:34,252 INFO TaskSetManager: Finished task 30.0 in stage 2.0 (TID 63) in 309 ms on 10.1.2.139 (31/32)
17/01/29 15:00:34,318 INFO TaskSetManager: Finished task 4.0 in stage 2.0 (TID 40) in 402 ms on 10.1.2.139 (32/32)
17/01/29 15:00:34,319 INFO TaskSchedulerImpl: Removed TaskSet 2.0, whose tasks have all completed, from pool 
17/01/29 15:00:34,319 INFO DAGScheduler: ResultStage 2 (count at GradientDescent.scala:209) finished in 0.411 s
17/01/29 15:00:34,319 INFO DAGScheduler: Job 2 finished: count at GradientDescent.scala:209, took 0.426269 s
17/01/29 15:00:34,654 WARN BLAS: Failed to load implementation from: com.github.fommil.netlib.NativeSystemBLAS
17/01/29 15:00:34,654 WARN BLAS: Failed to load implementation from: com.github.fommil.netlib.NativeRefBLAS
17/01/29 15:00:34,683 INFO MemoryStore: Block broadcast_4 stored as values in memory (estimated size 200.0 B, free 2.1 GB)
17/01/29 15:00:34,687 INFO MemoryStore: Block broadcast_4_piece0 stored as bytes in memory (estimated size 153.0 B, free 2.1 GB)
17/01/29 15:00:34,688 INFO BlockManagerInfo: Added broadcast_4_piece0 in memory on 10.1.2.152:42412 (size: 153.0 B, free: 2.1 GB)
17/01/29 15:00:34,688 INFO SparkContext: Created broadcast 4 from broadcast at GradientDescent.scala:235
17/01/29 15:00:34,743 INFO SparkContext: Starting job: treeAggregate at GradientDescent.scala:239
17/01/29 15:00:34,749 INFO DAGScheduler: Registering RDD 11 (treeAggregate at GradientDescent.scala:239)
17/01/29 15:00:34,749 INFO DAGScheduler: Got job 3 (treeAggregate at GradientDescent.scala:239) with 5 output partitions
17/01/29 15:00:34,749 INFO DAGScheduler: Final stage: ResultStage 4 (treeAggregate at GradientDescent.scala:239)
17/01/29 15:00:34,750 INFO DAGScheduler: Parents of final stage: List(ShuffleMapStage 3)
17/01/29 15:00:34,750 INFO DAGScheduler: Missing parents: List(ShuffleMapStage 3)
17/01/29 15:00:34,752 INFO DAGScheduler: Submitting ShuffleMapStage 3 (MapPartitionsRDD[11] at treeAggregate at GradientDescent.scala:239), which has no missing parents
17/01/29 15:00:34,767 INFO MemoryStore: Block broadcast_5 stored as values in memory (estimated size 7.1 KB, free 2.1 GB)
17/01/29 15:00:34,770 INFO MemoryStore: Block broadcast_5_piece0 stored as bytes in memory (estimated size 3.7 KB, free 2.1 GB)
17/01/29 15:00:34,770 INFO BlockManagerInfo: Added broadcast_5_piece0 in memory on 10.1.2.152:42412 (size: 3.7 KB, free: 2.1 GB)
17/01/29 15:00:34,771 INFO SparkContext: Created broadcast 5 from broadcast at DAGScheduler.scala:1012
17/01/29 15:00:34,773 INFO DAGScheduler: Submitting 32 missing tasks from ShuffleMapStage 3 (MapPartitionsRDD[11] at treeAggregate at GradientDescent.scala:239)
17/01/29 15:00:34,773 INFO TaskSchedulerImpl: Adding task set 3.0 with 32 tasks
17/01/29 15:00:34,778 INFO TaskSetManager: Starting task 2.0 in stage 3.0 (TID 65, 10.1.2.38, partition 2, PROCESS_LOCAL, 5562 bytes)
17/01/29 15:00:34,779 INFO TaskSetManager: Starting task 3.0 in stage 3.0 (TID 66, 10.1.2.65, partition 3, PROCESS_LOCAL, 5562 bytes)
17/01/29 15:00:34,779 INFO TaskSetManager: Starting task 8.0 in stage 3.0 (TID 67, 10.1.2.176, partition 8, PROCESS_LOCAL, 5562 bytes)
17/01/29 15:00:34,780 INFO TaskSetManager: Starting task 5.0 in stage 3.0 (TID 68, 10.1.2.28, partition 5, PROCESS_LOCAL, 5562 bytes)
17/01/29 15:00:34,781 INFO TaskSetManager: Starting task 12.0 in stage 3.0 (TID 69, 10.1.2.191, partition 12, PROCESS_LOCAL, 5562 bytes)
17/01/29 15:00:34,782 INFO TaskSetManager: Starting task 4.0 in stage 3.0 (TID 70, 10.1.2.139, partition 4, PROCESS_LOCAL, 5562 bytes)
17/01/29 15:00:34,783 INFO TaskSetManager: Starting task 6.0 in stage 3.0 (TID 71, 10.1.2.66, partition 6, PROCESS_LOCAL, 5562 bytes)
17/01/29 15:00:34,784 INFO TaskSetManager: Starting task 0.0 in stage 3.0 (TID 72, 10.1.2.224, partition 0, PROCESS_LOCAL, 5562 bytes)
17/01/29 15:00:34,784 INFO TaskSetManager: Starting task 17.0 in stage 3.0 (TID 73, 10.1.2.38, partition 17, PROCESS_LOCAL, 5562 bytes)
17/01/29 15:00:34,785 INFO TaskSetManager: Starting task 7.0 in stage 3.0 (TID 74, 10.1.2.65, partition 7, PROCESS_LOCAL, 5562 bytes)
17/01/29 15:00:34,786 INFO TaskSetManager: Starting task 18.0 in stage 3.0 (TID 75, 10.1.2.176, partition 18, PROCESS_LOCAL, 5562 bytes)
17/01/29 15:00:34,787 INFO TaskSetManager: Starting task 9.0 in stage 3.0 (TID 76, 10.1.2.28, partition 9, PROCESS_LOCAL, 5562 bytes)
17/01/29 15:00:34,788 INFO TaskSetManager: Starting task 14.0 in stage 3.0 (TID 77, 10.1.2.191, partition 14, PROCESS_LOCAL, 5562 bytes)
17/01/29 15:00:34,788 INFO TaskSetManager: Starting task 13.0 in stage 3.0 (TID 78, 10.1.2.139, partition 13, PROCESS_LOCAL, 5562 bytes)
17/01/29 15:00:34,789 INFO TaskSetManager: Starting task 11.0 in stage 3.0 (TID 79, 10.1.2.66, partition 11, PROCESS_LOCAL, 5562 bytes)
17/01/29 15:00:34,790 INFO TaskSetManager: Starting task 1.0 in stage 3.0 (TID 80, 10.1.2.224, partition 1, PROCESS_LOCAL, 5562 bytes)
17/01/29 15:00:34,791 INFO TaskSetManager: Starting task 22.0 in stage 3.0 (TID 81, 10.1.2.38, partition 22, PROCESS_LOCAL, 5562 bytes)
17/01/29 15:00:34,792 INFO TaskSetManager: Starting task 19.0 in stage 3.0 (TID 82, 10.1.2.65, partition 19, PROCESS_LOCAL, 5562 bytes)
17/01/29 15:00:34,793 INFO TaskSetManager: Starting task 28.0 in stage 3.0 (TID 83, 10.1.2.176, partition 28, PROCESS_LOCAL, 5562 bytes)
17/01/29 15:00:34,793 INFO TaskSetManager: Starting task 15.0 in stage 3.0 (TID 84, 10.1.2.28, partition 15, PROCESS_LOCAL, 5562 bytes)
17/01/29 15:00:34,794 INFO TaskSetManager: Starting task 24.0 in stage 3.0 (TID 85, 10.1.2.191, partition 24, PROCESS_LOCAL, 5562 bytes)
17/01/29 15:00:34,795 INFO TaskSetManager: Starting task 21.0 in stage 3.0 (TID 86, 10.1.2.139, partition 21, PROCESS_LOCAL, 5562 bytes)
17/01/29 15:00:34,796 INFO TaskSetManager: Starting task 23.0 in stage 3.0 (TID 87, 10.1.2.66, partition 23, PROCESS_LOCAL, 5562 bytes)
17/01/29 15:00:34,797 INFO TaskSetManager: Starting task 10.0 in stage 3.0 (TID 88, 10.1.2.224, partition 10, PROCESS_LOCAL, 5562 bytes)
17/01/29 15:00:34,797 INFO TaskSetManager: Starting task 27.0 in stage 3.0 (TID 89, 10.1.2.38, partition 27, PROCESS_LOCAL, 5562 bytes)
17/01/29 15:00:34,798 INFO TaskSetManager: Starting task 31.0 in stage 3.0 (TID 90, 10.1.2.65, partition 31, PROCESS_LOCAL, 5562 bytes)
17/01/29 15:00:34,799 INFO TaskSetManager: Starting task 29.0 in stage 3.0 (TID 91, 10.1.2.176, partition 29, PROCESS_LOCAL, 5562 bytes)
17/01/29 15:00:34,799 INFO TaskSetManager: Starting task 26.0 in stage 3.0 (TID 92, 10.1.2.28, partition 26, PROCESS_LOCAL, 5562 bytes)
17/01/29 15:00:34,800 INFO TaskSetManager: Starting task 25.0 in stage 3.0 (TID 93, 10.1.2.191, partition 25, PROCESS_LOCAL, 5562 bytes)
17/01/29 15:00:34,801 INFO TaskSetManager: Starting task 30.0 in stage 3.0 (TID 94, 10.1.2.139, partition 30, PROCESS_LOCAL, 5562 bytes)
17/01/29 15:00:34,802 INFO TaskSetManager: Starting task 16.0 in stage 3.0 (TID 95, 10.1.2.224, partition 16, PROCESS_LOCAL, 5562 bytes)
17/01/29 15:00:34,802 INFO CoarseGrainedSchedulerBackend$DriverEndpoint: Launching task 65 on executor id: 1 hostname: 10.1.2.38.
17/01/29 15:00:34,803 INFO CoarseGrainedSchedulerBackend$DriverEndpoint: Launching task 73 on executor id: 1 hostname: 10.1.2.38.
17/01/29 15:00:34,804 INFO CoarseGrainedSchedulerBackend$DriverEndpoint: Launching task 81 on executor id: 1 hostname: 10.1.2.38.
17/01/29 15:00:34,804 INFO CoarseGrainedSchedulerBackend$DriverEndpoint: Launching task 89 on executor id: 1 hostname: 10.1.2.38.
17/01/29 15:00:34,805 INFO CoarseGrainedSchedulerBackend$DriverEndpoint: Launching task 66 on executor id: 3 hostname: 10.1.2.65.
17/01/29 15:00:34,806 INFO CoarseGrainedSchedulerBackend$DriverEndpoint: Launching task 74 on executor id: 3 hostname: 10.1.2.65.
17/01/29 15:00:34,806 INFO CoarseGrainedSchedulerBackend$DriverEndpoint: Launching task 82 on executor id: 3 hostname: 10.1.2.65.
17/01/29 15:00:34,807 INFO CoarseGrainedSchedulerBackend$DriverEndpoint: Launching task 90 on executor id: 3 hostname: 10.1.2.65.
17/01/29 15:00:34,807 INFO CoarseGrainedSchedulerBackend$DriverEndpoint: Launching task 67 on executor id: 4 hostname: 10.1.2.176.
17/01/29 15:00:34,808 INFO CoarseGrainedSchedulerBackend$DriverEndpoint: Launching task 75 on executor id: 4 hostname: 10.1.2.176.
17/01/29 15:00:34,809 INFO CoarseGrainedSchedulerBackend$DriverEndpoint: Launching task 83 on executor id: 4 hostname: 10.1.2.176.
17/01/29 15:00:34,809 INFO CoarseGrainedSchedulerBackend$DriverEndpoint: Launching task 91 on executor id: 4 hostname: 10.1.2.176.
17/01/29 15:00:34,810 INFO CoarseGrainedSchedulerBackend$DriverEndpoint: Launching task 68 on executor id: 2 hostname: 10.1.2.28.
17/01/29 15:00:34,810 INFO CoarseGrainedSchedulerBackend$DriverEndpoint: Launching task 76 on executor id: 2 hostname: 10.1.2.28.
17/01/29 15:00:34,811 INFO CoarseGrainedSchedulerBackend$DriverEndpoint: Launching task 84 on executor id: 2 hostname: 10.1.2.28.
17/01/29 15:00:34,815 INFO CoarseGrainedSchedulerBackend$DriverEndpoint: Launching task 92 on executor id: 2 hostname: 10.1.2.28.
17/01/29 15:00:34,816 INFO CoarseGrainedSchedulerBackend$DriverEndpoint: Launching task 69 on executor id: 5 hostname: 10.1.2.191.
17/01/29 15:00:34,816 INFO CoarseGrainedSchedulerBackend$DriverEndpoint: Launching task 77 on executor id: 5 hostname: 10.1.2.191.
17/01/29 15:00:34,817 INFO CoarseGrainedSchedulerBackend$DriverEndpoint: Launching task 85 on executor id: 5 hostname: 10.1.2.191.
17/01/29 15:00:34,817 INFO CoarseGrainedSchedulerBackend$DriverEndpoint: Launching task 93 on executor id: 5 hostname: 10.1.2.191.
17/01/29 15:00:34,819 INFO CoarseGrainedSchedulerBackend$DriverEndpoint: Launching task 70 on executor id: 7 hostname: 10.1.2.139.
17/01/29 15:00:34,821 INFO CoarseGrainedSchedulerBackend$DriverEndpoint: Launching task 78 on executor id: 7 hostname: 10.1.2.139.
17/01/29 15:00:34,821 INFO CoarseGrainedSchedulerBackend$DriverEndpoint: Launching task 86 on executor id: 7 hostname: 10.1.2.139.
17/01/29 15:00:34,822 INFO CoarseGrainedSchedulerBackend$DriverEndpoint: Launching task 94 on executor id: 7 hostname: 10.1.2.139.
17/01/29 15:00:34,822 INFO CoarseGrainedSchedulerBackend$DriverEndpoint: Launching task 71 on executor id: 6 hostname: 10.1.2.66.
17/01/29 15:00:34,822 INFO CoarseGrainedSchedulerBackend$DriverEndpoint: Launching task 79 on executor id: 6 hostname: 10.1.2.66.
17/01/29 15:00:34,822 INFO CoarseGrainedSchedulerBackend$DriverEndpoint: Launching task 87 on executor id: 6 hostname: 10.1.2.66.
17/01/29 15:00:34,823 INFO CoarseGrainedSchedulerBackend$DriverEndpoint: Launching task 72 on executor id: 0 hostname: 10.1.2.224.
17/01/29 15:00:34,823 INFO CoarseGrainedSchedulerBackend$DriverEndpoint: Launching task 80 on executor id: 0 hostname: 10.1.2.224.
17/01/29 15:00:34,823 INFO CoarseGrainedSchedulerBackend$DriverEndpoint: Launching task 88 on executor id: 0 hostname: 10.1.2.224.
17/01/29 15:00:34,823 INFO CoarseGrainedSchedulerBackend$DriverEndpoint: Launching task 95 on executor id: 0 hostname: 10.1.2.224.
17/01/29 15:00:34,834 INFO BlockManagerInfo: Added broadcast_5_piece0 in memory on 10.1.2.38:38828 (size: 3.7 KB, free: 1942.8 MB)
17/01/29 15:00:34,840 INFO BlockManagerInfo: Added broadcast_5_piece0 in memory on 10.1.2.191:44404 (size: 3.7 KB, free: 1942.8 MB)
17/01/29 15:00:34,841 INFO BlockManagerInfo: Added broadcast_5_piece0 in memory on 10.1.2.65:37362 (size: 3.7 KB, free: 1942.9 MB)
17/01/29 15:00:34,848 INFO BlockManagerInfo: Added broadcast_5_piece0 in memory on 10.1.2.176:44820 (size: 3.7 KB, free: 1942.9 MB)
17/01/29 15:00:34,854 INFO BlockManagerInfo: Added broadcast_5_piece0 in memory on 10.1.2.28:43497 (size: 3.7 KB, free: 1942.9 MB)
17/01/29 15:00:34,857 INFO BlockManagerInfo: Added broadcast_5_piece0 in memory on 10.1.2.224:35157 (size: 3.7 KB, free: 1898.5 MB)
17/01/29 15:00:34,885 INFO BlockManagerInfo: Added broadcast_5_piece0 in memory on 10.1.2.66:40837 (size: 3.7 KB, free: 1987.3 MB)
17/01/29 15:00:34,895 INFO BlockManagerInfo: Added broadcast_5_piece0 in memory on 10.1.2.139:33064 (size: 3.7 KB, free: 1942.9 MB)
17/01/29 15:00:35,230 INFO BlockManagerInfo: Added broadcast_4_piece0 in memory on 10.1.2.38:38828 (size: 153.0 B, free: 1942.8 MB)
17/01/29 15:00:35,253 INFO BlockManagerInfo: Added broadcast_4_piece0 in memory on 10.1.2.191:44404 (size: 153.0 B, free: 1942.8 MB)
17/01/29 15:00:35,255 INFO BlockManagerInfo: Added broadcast_4_piece0 in memory on 10.1.2.224:35157 (size: 153.0 B, free: 1898.5 MB)
17/01/29 15:00:35,274 INFO BlockManagerInfo: Added broadcast_4_piece0 in memory on 10.1.2.65:37362 (size: 153.0 B, free: 1942.9 MB)
17/01/29 15:00:35,282 INFO BlockManagerInfo: Added broadcast_4_piece0 in memory on 10.1.2.28:43497 (size: 153.0 B, free: 1942.9 MB)
17/01/29 15:00:35,300 INFO BlockManagerInfo: Added broadcast_4_piece0 in memory on 10.1.2.176:44820 (size: 153.0 B, free: 1942.9 MB)
17/01/29 15:00:35,325 INFO BlockManagerInfo: Added broadcast_4_piece0 in memory on 10.1.2.139:33064 (size: 153.0 B, free: 1942.9 MB)
17/01/29 15:00:35,377 INFO BlockManagerInfo: Added broadcast_4_piece0 in memory on 10.1.2.66:40837 (size: 153.0 B, free: 1987.3 MB)
17/01/29 15:00:35,396 INFO TaskSetManager: Finished task 2.0 in stage 3.0 (TID 65) in 620 ms on 10.1.2.38 (1/32)
17/01/29 15:00:35,398 INFO TaskSetManager: Finished task 17.0 in stage 3.0 (TID 73) in 614 ms on 10.1.2.38 (2/32)
17/01/29 15:00:35,401 INFO TaskSetManager: Finished task 22.0 in stage 3.0 (TID 81) in 610 ms on 10.1.2.38 (3/32)
17/01/29 15:00:35,401 INFO TaskSetManager: Finished task 27.0 in stage 3.0 (TID 89) in 604 ms on 10.1.2.38 (4/32)
17/01/29 15:00:35,430 INFO TaskSetManager: Starting task 20.0 in stage 3.0 (TID 96, 10.1.2.224, partition 20, PROCESS_LOCAL, 5562 bytes)
17/01/29 15:00:35,431 INFO CoarseGrainedSchedulerBackend$DriverEndpoint: Launching task 96 on executor id: 0 hostname: 10.1.2.224.
17/01/29 15:00:35,431 INFO TaskSetManager: Finished task 10.0 in stage 3.0 (TID 88) in 635 ms on 10.1.2.224 (5/32)
17/01/29 15:00:35,433 INFO TaskSetManager: Finished task 1.0 in stage 3.0 (TID 80) in 643 ms on 10.1.2.224 (6/32)
17/01/29 15:00:35,435 INFO TaskSetManager: Finished task 16.0 in stage 3.0 (TID 95) in 633 ms on 10.1.2.224 (7/32)
17/01/29 15:00:35,435 INFO TaskSetManager: Finished task 0.0 in stage 3.0 (TID 72) in 652 ms on 10.1.2.224 (8/32)
17/01/29 15:00:35,440 INFO TaskSetManager: Finished task 14.0 in stage 3.0 (TID 77) in 653 ms on 10.1.2.191 (9/32)
17/01/29 15:00:35,442 INFO TaskSetManager: Finished task 12.0 in stage 3.0 (TID 69) in 662 ms on 10.1.2.191 (10/32)
17/01/29 15:00:35,443 INFO TaskSetManager: Finished task 24.0 in stage 3.0 (TID 85) in 650 ms on 10.1.2.191 (11/32)
17/01/29 15:00:35,444 INFO TaskSetManager: Finished task 25.0 in stage 3.0 (TID 93) in 644 ms on 10.1.2.191 (12/32)
17/01/29 15:00:35,454 INFO TaskSetManager: Finished task 5.0 in stage 3.0 (TID 68) in 674 ms on 10.1.2.28 (13/32)
17/01/29 15:00:35,455 INFO TaskSetManager: Finished task 9.0 in stage 3.0 (TID 76) in 669 ms on 10.1.2.28 (14/32)
17/01/29 15:00:35,456 INFO TaskSetManager: Finished task 15.0 in stage 3.0 (TID 84) in 663 ms on 10.1.2.28 (15/32)
17/01/29 15:00:35,459 INFO TaskSetManager: Finished task 26.0 in stage 3.0 (TID 92) in 659 ms on 10.1.2.28 (16/32)
17/01/29 15:00:35,466 INFO TaskSetManager: Finished task 19.0 in stage 3.0 (TID 82) in 675 ms on 10.1.2.65 (17/32)
17/01/29 15:00:35,466 INFO TaskSetManager: Finished task 7.0 in stage 3.0 (TID 74) in 681 ms on 10.1.2.65 (18/32)
17/01/29 15:00:35,467 INFO TaskSetManager: Finished task 3.0 in stage 3.0 (TID 66) in 688 ms on 10.1.2.65 (19/32)
17/01/29 15:00:35,467 INFO TaskSetManager: Finished task 31.0 in stage 3.0 (TID 90) in 670 ms on 10.1.2.65 (20/32)
17/01/29 15:00:35,477 INFO TaskSetManager: Finished task 18.0 in stage 3.0 (TID 75) in 691 ms on 10.1.2.176 (21/32)
17/01/29 15:00:35,478 INFO TaskSetManager: Finished task 29.0 in stage 3.0 (TID 91) in 680 ms on 10.1.2.176 (22/32)
17/01/29 15:00:35,479 INFO TaskSetManager: Finished task 28.0 in stage 3.0 (TID 83) in 687 ms on 10.1.2.176 (23/32)
17/01/29 15:00:35,481 INFO TaskSetManager: Finished task 8.0 in stage 3.0 (TID 67) in 702 ms on 10.1.2.176 (24/32)
17/01/29 15:00:35,491 INFO TaskSetManager: Finished task 20.0 in stage 3.0 (TID 96) in 60 ms on 10.1.2.224 (25/32)
17/01/29 15:00:35,508 INFO TaskSetManager: Finished task 13.0 in stage 3.0 (TID 78) in 719 ms on 10.1.2.139 (26/32)
17/01/29 15:00:35,508 INFO TaskSetManager: Finished task 21.0 in stage 3.0 (TID 86) in 714 ms on 10.1.2.139 (27/32)
17/01/29 15:00:35,509 INFO TaskSetManager: Finished task 4.0 in stage 3.0 (TID 70) in 728 ms on 10.1.2.139 (28/32)
17/01/29 15:00:35,510 INFO TaskSetManager: Finished task 30.0 in stage 3.0 (TID 94) in 709 ms on 10.1.2.139 (29/32)
17/01/29 15:00:35,557 INFO TaskSetManager: Finished task 23.0 in stage 3.0 (TID 87) in 761 ms on 10.1.2.66 (30/32)
17/01/29 15:00:35,557 INFO TaskSetManager: Finished task 6.0 in stage 3.0 (TID 71) in 775 ms on 10.1.2.66 (31/32)
17/01/29 15:00:35,557 INFO TaskSetManager: Finished task 11.0 in stage 3.0 (TID 79) in 768 ms on 10.1.2.66 (32/32)
17/01/29 15:00:35,557 INFO TaskSchedulerImpl: Removed TaskSet 3.0, whose tasks have all completed, from pool 
17/01/29 15:00:35,559 INFO DAGScheduler: ShuffleMapStage 3 (treeAggregate at GradientDescent.scala:239) finished in 0.785 s
17/01/29 15:00:35,560 INFO DAGScheduler: looking for newly runnable stages
17/01/29 15:00:35,561 INFO DAGScheduler: running: Set()
17/01/29 15:00:35,561 INFO DAGScheduler: waiting: Set(ResultStage 4)
17/01/29 15:00:35,561 INFO DAGScheduler: failed: Set()
17/01/29 15:00:35,563 INFO DAGScheduler: Submitting ResultStage 4 (MapPartitionsRDD[13] at treeAggregate at GradientDescent.scala:239), which has no missing parents
17/01/29 15:00:35,571 INFO MemoryStore: Block broadcast_6 stored as values in memory (estimated size 3.1 KB, free 2.1 GB)
17/01/29 15:00:35,573 INFO MemoryStore: Block broadcast_6_piece0 stored as bytes in memory (estimated size 1890.0 B, free 2.1 GB)
17/01/29 15:00:35,574 INFO BlockManagerInfo: Added broadcast_6_piece0 in memory on 10.1.2.152:42412 (size: 1890.0 B, free: 2.1 GB)
17/01/29 15:00:35,575 INFO SparkContext: Created broadcast 6 from broadcast at DAGScheduler.scala:1012
17/01/29 15:00:35,575 INFO DAGScheduler: Submitting 5 missing tasks from ResultStage 4 (MapPartitionsRDD[13] at treeAggregate at GradientDescent.scala:239)
17/01/29 15:00:35,575 INFO TaskSchedulerImpl: Adding task set 4.0 with 5 tasks
17/01/29 15:00:35,577 INFO TaskSetManager: Starting task 3.0 in stage 4.0 (TID 97, 10.1.2.176, partition 3, NODE_LOCAL, 5228 bytes)
17/01/29 15:00:35,578 INFO TaskSetManager: Starting task 4.0 in stage 4.0 (TID 98, 10.1.2.191, partition 4, NODE_LOCAL, 5228 bytes)
17/01/29 15:00:35,578 INFO TaskSetManager: Starting task 2.0 in stage 4.0 (TID 99, 10.1.2.38, partition 2, NODE_LOCAL, 5228 bytes)
17/01/29 15:00:35,579 INFO TaskSetManager: Starting task 0.0 in stage 4.0 (TID 100, 10.1.2.224, partition 0, NODE_LOCAL, 5228 bytes)
17/01/29 15:00:35,580 INFO TaskSetManager: Starting task 1.0 in stage 4.0 (TID 101, 10.1.2.66, partition 1, NODE_LOCAL, 5228 bytes)
17/01/29 15:00:35,581 INFO CoarseGrainedSchedulerBackend$DriverEndpoint: Launching task 97 on executor id: 4 hostname: 10.1.2.176.
17/01/29 15:00:35,581 INFO CoarseGrainedSchedulerBackend$DriverEndpoint: Launching task 98 on executor id: 5 hostname: 10.1.2.191.
17/01/29 15:00:35,581 INFO CoarseGrainedSchedulerBackend$DriverEndpoint: Launching task 99 on executor id: 1 hostname: 10.1.2.38.
17/01/29 15:00:35,582 INFO CoarseGrainedSchedulerBackend$DriverEndpoint: Launching task 100 on executor id: 0 hostname: 10.1.2.224.
17/01/29 15:00:35,582 INFO CoarseGrainedSchedulerBackend$DriverEndpoint: Launching task 101 on executor id: 6 hostname: 10.1.2.66.
17/01/29 15:00:35,597 INFO BlockManagerInfo: Added broadcast_6_piece0 in memory on 10.1.2.224:35157 (size: 1890.0 B, free: 1898.5 MB)
17/01/29 15:00:35,598 INFO BlockManagerInfo: Added broadcast_6_piece0 in memory on 10.1.2.38:38828 (size: 1890.0 B, free: 1942.8 MB)
17/01/29 15:00:35,599 INFO BlockManagerInfo: Added broadcast_6_piece0 in memory on 10.1.2.66:40837 (size: 1890.0 B, free: 1987.3 MB)
17/01/29 15:00:35,599 INFO BlockManagerInfo: Added broadcast_6_piece0 in memory on 10.1.2.191:44404 (size: 1890.0 B, free: 1942.8 MB)
17/01/29 15:00:35,600 INFO BlockManagerInfo: Added broadcast_6_piece0 in memory on 10.1.2.176:44820 (size: 1890.0 B, free: 1942.9 MB)
17/01/29 15:00:35,617 INFO MapOutputTrackerMasterEndpoint: Asked to send map output locations for shuffle 0 to 10.1.2.224:39078
17/01/29 15:00:35,617 INFO MapOutputTrackerMasterEndpoint: Asked to send map output locations for shuffle 0 to 10.1.2.66:42632
17/01/29 15:00:35,621 INFO MapOutputTrackerMasterEndpoint: Asked to send map output locations for shuffle 0 to 10.1.2.38:35190
17/01/29 15:00:35,621 INFO MapOutputTrackerMasterEndpoint: Asked to send map output locations for shuffle 0 to 10.1.2.176:45614
17/01/29 15:00:35,621 INFO MapOutputTrackerMasterEndpoint: Asked to send map output locations for shuffle 0 to 10.1.2.191:40452
17/01/29 15:00:35,621 INFO MapOutputTrackerMaster: Size of output statuses for shuffle 0 is 328 bytes
17/01/29 15:00:35,688 INFO TaskSetManager: Finished task 2.0 in stage 4.0 (TID 99) in 109 ms on 10.1.2.38 (1/5)
17/01/29 15:00:35,696 INFO TaskSetManager: Finished task 0.0 in stage 4.0 (TID 100) in 116 ms on 10.1.2.224 (2/5)
17/01/29 15:00:35,697 INFO TaskSetManager: Finished task 1.0 in stage 4.0 (TID 101) in 117 ms on 10.1.2.66 (3/5)
17/01/29 15:00:35,704 INFO TaskSetManager: Finished task 3.0 in stage 4.0 (TID 97) in 128 ms on 10.1.2.176 (4/5)
17/01/29 15:00:35,711 INFO TaskSetManager: Finished task 4.0 in stage 4.0 (TID 98) in 133 ms on 10.1.2.191 (5/5)
17/01/29 15:00:35,711 INFO TaskSchedulerImpl: Removed TaskSet 4.0, whose tasks have all completed, from pool 
17/01/29 15:00:35,711 INFO DAGScheduler: ResultStage 4 (treeAggregate at GradientDescent.scala:239) finished in 0.135 s
17/01/29 15:00:35,712 INFO DAGScheduler: Job 3 finished: treeAggregate at GradientDescent.scala:239, took 0.969003 s
17/01/29 15:00:35,715 INFO MemoryStore: Block broadcast_7 stored as values in memory (estimated size 200.0 B, free 2.1 GB)
17/01/29 15:00:35,717 INFO MemoryStore: Block broadcast_7_piece0 stored as bytes in memory (estimated size 285.0 B, free 2.1 GB)
17/01/29 15:00:35,718 INFO BlockManagerInfo: Added broadcast_7_piece0 in memory on 10.1.2.152:42412 (size: 285.0 B, free: 2.1 GB)
17/01/29 15:00:35,719 INFO SparkContext: Created broadcast 7 from broadcast at GradientDescent.scala:235
17/01/29 15:00:35,736 INFO SparkContext: Starting job: treeAggregate at GradientDescent.scala:239
17/01/29 15:00:35,738 INFO DAGScheduler: Registering RDD 16 (treeAggregate at GradientDescent.scala:239)
17/01/29 15:00:35,738 INFO DAGScheduler: Got job 4 (treeAggregate at GradientDescent.scala:239) with 5 output partitions
17/01/29 15:00:35,738 INFO DAGScheduler: Final stage: ResultStage 6 (treeAggregate at GradientDescent.scala:239)
17/01/29 15:00:35,738 INFO DAGScheduler: Parents of final stage: List(ShuffleMapStage 5)
17/01/29 15:00:35,738 INFO DAGScheduler: Missing parents: List(ShuffleMapStage 5)
17/01/29 15:00:35,740 INFO DAGScheduler: Submitting ShuffleMapStage 5 (MapPartitionsRDD[16] at treeAggregate at GradientDescent.scala:239), which has no missing parents
17/01/29 15:00:35,746 INFO MemoryStore: Block broadcast_8 stored as values in memory (estimated size 7.1 KB, free 2.1 GB)
17/01/29 15:00:35,748 INFO MemoryStore: Block broadcast_8_piece0 stored as bytes in memory (estimated size 3.7 KB, free 2.1 GB)
17/01/29 15:00:35,749 INFO BlockManagerInfo: Added broadcast_8_piece0 in memory on 10.1.2.152:42412 (size: 3.7 KB, free: 2.1 GB)
17/01/29 15:00:35,750 INFO SparkContext: Created broadcast 8 from broadcast at DAGScheduler.scala:1012
17/01/29 15:00:35,750 INFO DAGScheduler: Submitting 32 missing tasks from ShuffleMapStage 5 (MapPartitionsRDD[16] at treeAggregate at GradientDescent.scala:239)
17/01/29 15:00:35,751 INFO TaskSchedulerImpl: Adding task set 5.0 with 32 tasks
17/01/29 15:00:35,753 INFO TaskSetManager: Starting task 5.0 in stage 5.0 (TID 102, 10.1.2.28, partition 5, PROCESS_LOCAL, 5562 bytes)
17/01/29 15:00:35,753 INFO TaskSetManager: Starting task 6.0 in stage 5.0 (TID 103, 10.1.2.66, partition 6, PROCESS_LOCAL, 5562 bytes)
17/01/29 15:00:35,754 INFO TaskSetManager: Starting task 2.0 in stage 5.0 (TID 104, 10.1.2.38, partition 2, PROCESS_LOCAL, 5562 bytes)
17/01/29 15:00:35,754 INFO TaskSetManager: Starting task 4.0 in stage 5.0 (TID 105, 10.1.2.139, partition 4, PROCESS_LOCAL, 5562 bytes)
17/01/29 15:00:35,755 INFO TaskSetManager: Starting task 0.0 in stage 5.0 (TID 106, 10.1.2.224, partition 0, PROCESS_LOCAL, 5562 bytes)
17/01/29 15:00:35,755 INFO TaskSetManager: Starting task 8.0 in stage 5.0 (TID 107, 10.1.2.176, partition 8, PROCESS_LOCAL, 5562 bytes)
17/01/29 15:00:35,756 INFO TaskSetManager: Starting task 3.0 in stage 5.0 (TID 108, 10.1.2.65, partition 3, PROCESS_LOCAL, 5562 bytes)
17/01/29 15:00:35,756 INFO TaskSetManager: Starting task 12.0 in stage 5.0 (TID 109, 10.1.2.191, partition 12, PROCESS_LOCAL, 5562 bytes)
17/01/29 15:00:35,757 INFO TaskSetManager: Starting task 9.0 in stage 5.0 (TID 110, 10.1.2.28, partition 9, PROCESS_LOCAL, 5562 bytes)
17/01/29 15:00:35,757 INFO TaskSetManager: Starting task 11.0 in stage 5.0 (TID 111, 10.1.2.66, partition 11, PROCESS_LOCAL, 5562 bytes)
17/01/29 15:00:35,758 INFO TaskSetManager: Starting task 17.0 in stage 5.0 (TID 112, 10.1.2.38, partition 17, PROCESS_LOCAL, 5562 bytes)
17/01/29 15:00:35,758 INFO TaskSetManager: Starting task 13.0 in stage 5.0 (TID 113, 10.1.2.139, partition 13, PROCESS_LOCAL, 5562 bytes)
17/01/29 15:00:35,759 INFO TaskSetManager: Starting task 1.0 in stage 5.0 (TID 114, 10.1.2.224, partition 1, PROCESS_LOCAL, 5562 bytes)
17/01/29 15:00:35,759 INFO TaskSetManager: Starting task 18.0 in stage 5.0 (TID 115, 10.1.2.176, partition 18, PROCESS_LOCAL, 5562 bytes)
17/01/29 15:00:35,760 INFO TaskSetManager: Starting task 7.0 in stage 5.0 (TID 116, 10.1.2.65, partition 7, PROCESS_LOCAL, 5562 bytes)
17/01/29 15:00:35,760 INFO TaskSetManager: Starting task 14.0 in stage 5.0 (TID 117, 10.1.2.191, partition 14, PROCESS_LOCAL, 5562 bytes)
17/01/29 15:00:35,761 INFO TaskSetManager: Starting task 15.0 in stage 5.0 (TID 118, 10.1.2.28, partition 15, PROCESS_LOCAL, 5562 bytes)
17/01/29 15:00:35,761 INFO TaskSetManager: Starting task 23.0 in stage 5.0 (TID 119, 10.1.2.66, partition 23, PROCESS_LOCAL, 5562 bytes)
17/01/29 15:00:35,762 INFO TaskSetManager: Starting task 22.0 in stage 5.0 (TID 120, 10.1.2.38, partition 22, PROCESS_LOCAL, 5562 bytes)
17/01/29 15:00:35,762 INFO TaskSetManager: Starting task 21.0 in stage 5.0 (TID 121, 10.1.2.139, partition 21, PROCESS_LOCAL, 5562 bytes)
17/01/29 15:00:35,762 INFO TaskSetManager: Starting task 10.0 in stage 5.0 (TID 122, 10.1.2.224, partition 10, PROCESS_LOCAL, 5562 bytes)
17/01/29 15:00:35,763 INFO TaskSetManager: Starting task 28.0 in stage 5.0 (TID 123, 10.1.2.176, partition 28, PROCESS_LOCAL, 5562 bytes)
17/01/29 15:00:35,763 INFO TaskSetManager: Starting task 19.0 in stage 5.0 (TID 124, 10.1.2.65, partition 19, PROCESS_LOCAL, 5562 bytes)
17/01/29 15:00:35,764 INFO TaskSetManager: Starting task 24.0 in stage 5.0 (TID 125, 10.1.2.191, partition 24, PROCESS_LOCAL, 5562 bytes)
17/01/29 15:00:35,764 INFO TaskSetManager: Starting task 26.0 in stage 5.0 (TID 126, 10.1.2.28, partition 26, PROCESS_LOCAL, 5562 bytes)
17/01/29 15:00:35,765 INFO TaskSetManager: Starting task 27.0 in stage 5.0 (TID 127, 10.1.2.38, partition 27, PROCESS_LOCAL, 5562 bytes)
17/01/29 15:00:35,765 INFO TaskSetManager: Starting task 30.0 in stage 5.0 (TID 128, 10.1.2.139, partition 30, PROCESS_LOCAL, 5562 bytes)
17/01/29 15:00:35,766 INFO TaskSetManager: Starting task 16.0 in stage 5.0 (TID 129, 10.1.2.224, partition 16, PROCESS_LOCAL, 5562 bytes)
17/01/29 15:00:35,767 INFO TaskSetManager: Starting task 29.0 in stage 5.0 (TID 130, 10.1.2.176, partition 29, PROCESS_LOCAL, 5562 bytes)
17/01/29 15:00:35,767 INFO TaskSetManager: Starting task 31.0 in stage 5.0 (TID 131, 10.1.2.65, partition 31, PROCESS_LOCAL, 5562 bytes)
17/01/29 15:00:35,767 INFO TaskSetManager: Starting task 25.0 in stage 5.0 (TID 132, 10.1.2.191, partition 25, PROCESS_LOCAL, 5562 bytes)
17/01/29 15:00:35,768 INFO CoarseGrainedSchedulerBackend$DriverEndpoint: Launching task 102 on executor id: 2 hostname: 10.1.2.28.
17/01/29 15:00:35,768 INFO CoarseGrainedSchedulerBackend$DriverEndpoint: Launching task 110 on executor id: 2 hostname: 10.1.2.28.
17/01/29 15:00:35,768 INFO CoarseGrainedSchedulerBackend$DriverEndpoint: Launching task 118 on executor id: 2 hostname: 10.1.2.28.
17/01/29 15:00:35,769 INFO CoarseGrainedSchedulerBackend$DriverEndpoint: Launching task 126 on executor id: 2 hostname: 10.1.2.28.
17/01/29 15:00:35,769 INFO CoarseGrainedSchedulerBackend$DriverEndpoint: Launching task 103 on executor id: 6 hostname: 10.1.2.66.
17/01/29 15:00:35,769 INFO CoarseGrainedSchedulerBackend$DriverEndpoint: Launching task 111 on executor id: 6 hostname: 10.1.2.66.
17/01/29 15:00:35,770 INFO CoarseGrainedSchedulerBackend$DriverEndpoint: Launching task 119 on executor id: 6 hostname: 10.1.2.66.
17/01/29 15:00:35,771 INFO CoarseGrainedSchedulerBackend$DriverEndpoint: Launching task 104 on executor id: 1 hostname: 10.1.2.38.
17/01/29 15:00:35,771 INFO CoarseGrainedSchedulerBackend$DriverEndpoint: Launching task 112 on executor id: 1 hostname: 10.1.2.38.
17/01/29 15:00:35,771 INFO CoarseGrainedSchedulerBackend$DriverEndpoint: Launching task 120 on executor id: 1 hostname: 10.1.2.38.
17/01/29 15:00:35,771 INFO CoarseGrainedSchedulerBackend$DriverEndpoint: Launching task 127 on executor id: 1 hostname: 10.1.2.38.
17/01/29 15:00:35,771 INFO CoarseGrainedSchedulerBackend$DriverEndpoint: Launching task 105 on executor id: 7 hostname: 10.1.2.139.
17/01/29 15:00:35,772 INFO CoarseGrainedSchedulerBackend$DriverEndpoint: Launching task 113 on executor id: 7 hostname: 10.1.2.139.
17/01/29 15:00:35,772 INFO CoarseGrainedSchedulerBackend$DriverEndpoint: Launching task 121 on executor id: 7 hostname: 10.1.2.139.
17/01/29 15:00:35,772 INFO CoarseGrainedSchedulerBackend$DriverEndpoint: Launching task 128 on executor id: 7 hostname: 10.1.2.139.
17/01/29 15:00:35,772 INFO CoarseGrainedSchedulerBackend$DriverEndpoint: Launching task 106 on executor id: 0 hostname: 10.1.2.224.
17/01/29 15:00:35,773 INFO CoarseGrainedSchedulerBackend$DriverEndpoint: Launching task 114 on executor id: 0 hostname: 10.1.2.224.
17/01/29 15:00:35,773 INFO CoarseGrainedSchedulerBackend$DriverEndpoint: Launching task 122 on executor id: 0 hostname: 10.1.2.224.
17/01/29 15:00:35,773 INFO CoarseGrainedSchedulerBackend$DriverEndpoint: Launching task 129 on executor id: 0 hostname: 10.1.2.224.
17/01/29 15:00:35,773 INFO CoarseGrainedSchedulerBackend$DriverEndpoint: Launching task 107 on executor id: 4 hostname: 10.1.2.176.
17/01/29 15:00:35,773 INFO CoarseGrainedSchedulerBackend$DriverEndpoint: Launching task 115 on executor id: 4 hostname: 10.1.2.176.
17/01/29 15:00:35,774 INFO CoarseGrainedSchedulerBackend$DriverEndpoint: Launching task 123 on executor id: 4 hostname: 10.1.2.176.
17/01/29 15:00:35,774 INFO CoarseGrainedSchedulerBackend$DriverEndpoint: Launching task 130 on executor id: 4 hostname: 10.1.2.176.
17/01/29 15:00:35,774 INFO CoarseGrainedSchedulerBackend$DriverEndpoint: Launching task 108 on executor id: 3 hostname: 10.1.2.65.
17/01/29 15:00:35,774 INFO CoarseGrainedSchedulerBackend$DriverEndpoint: Launching task 116 on executor id: 3 hostname: 10.1.2.65.
17/01/29 15:00:35,775 INFO CoarseGrainedSchedulerBackend$DriverEndpoint: Launching task 124 on executor id: 3 hostname: 10.1.2.65.
17/01/29 15:00:35,775 INFO CoarseGrainedSchedulerBackend$DriverEndpoint: Launching task 131 on executor id: 3 hostname: 10.1.2.65.
17/01/29 15:00:35,776 INFO CoarseGrainedSchedulerBackend$DriverEndpoint: Launching task 109 on executor id: 5 hostname: 10.1.2.191.
17/01/29 15:00:35,776 INFO CoarseGrainedSchedulerBackend$DriverEndpoint: Launching task 117 on executor id: 5 hostname: 10.1.2.191.
17/01/29 15:00:35,776 INFO CoarseGrainedSchedulerBackend$DriverEndpoint: Launching task 125 on executor id: 5 hostname: 10.1.2.191.
17/01/29 15:00:35,776 INFO CoarseGrainedSchedulerBackend$DriverEndpoint: Launching task 132 on executor id: 5 hostname: 10.1.2.191.
17/01/29 15:00:35,790 INFO BlockManagerInfo: Added broadcast_8_piece0 in memory on 10.1.2.66:40837 (size: 3.7 KB, free: 1987.3 MB)
17/01/29 15:00:35,792 INFO BlockManagerInfo: Added broadcast_8_piece0 in memory on 10.1.2.38:38828 (size: 3.7 KB, free: 1942.8 MB)
17/01/29 15:00:35,797 INFO BlockManagerInfo: Added broadcast_8_piece0 in memory on 10.1.2.65:37362 (size: 3.7 KB, free: 1942.9 MB)
17/01/29 15:00:35,800 INFO BlockManagerInfo: Added broadcast_8_piece0 in memory on 10.1.2.191:44404 (size: 3.7 KB, free: 1942.8 MB)
17/01/29 15:00:35,804 INFO BlockManagerInfo: Added broadcast_8_piece0 in memory on 10.1.2.224:35157 (size: 3.7 KB, free: 1898.5 MB)
17/01/29 15:00:35,810 INFO BlockManagerInfo: Added broadcast_7_piece0 in memory on 10.1.2.66:40837 (size: 285.0 B, free: 1987.3 MB)
17/01/29 15:00:35,813 INFO BlockManagerInfo: Added broadcast_8_piece0 in memory on 10.1.2.176:44820 (size: 3.7 KB, free: 1942.9 MB)
17/01/29 15:00:35,815 INFO BlockManagerInfo: Added broadcast_7_piece0 in memory on 10.1.2.65:37362 (size: 285.0 B, free: 1942.8 MB)
17/01/29 15:00:35,816 INFO BlockManagerInfo: Added broadcast_8_piece0 in memory on 10.1.2.139:33064 (size: 3.7 KB, free: 1942.9 MB)
17/01/29 15:00:35,818 INFO BlockManagerInfo: Added broadcast_7_piece0 in memory on 10.1.2.38:38828 (size: 285.0 B, free: 1942.8 MB)
17/01/29 15:00:35,828 INFO BlockManagerInfo: Added broadcast_8_piece0 in memory on 10.1.2.28:43497 (size: 3.7 KB, free: 1942.9 MB)
17/01/29 15:00:35,830 INFO BlockManagerInfo: Added broadcast_7_piece0 in memory on 10.1.2.224:35157 (size: 285.0 B, free: 1898.5 MB)
17/01/29 15:00:35,831 INFO BlockManagerInfo: Added broadcast_7_piece0 in memory on 10.1.2.176:44820 (size: 285.0 B, free: 1942.9 MB)
17/01/29 15:00:35,848 INFO BlockManagerInfo: Added broadcast_7_piece0 in memory on 10.1.2.28:43497 (size: 285.0 B, free: 1942.9 MB)
17/01/29 15:00:35,849 INFO BlockManagerInfo: Added broadcast_7_piece0 in memory on 10.1.2.191:44404 (size: 285.0 B, free: 1942.8 MB)
17/01/29 15:00:35,859 INFO BlockManagerInfo: Added broadcast_7_piece0 in memory on 10.1.2.139:33064 (size: 285.0 B, free: 1942.9 MB)
17/01/29 15:00:35,889 INFO TaskSetManager: Finished task 6.0 in stage 5.0 (TID 103) in 136 ms on 10.1.2.66 (1/32)
17/01/29 15:00:35,894 INFO TaskSetManager: Finished task 23.0 in stage 5.0 (TID 119) in 133 ms on 10.1.2.66 (2/32)
17/01/29 15:00:35,896 INFO TaskSetManager: Finished task 11.0 in stage 5.0 (TID 111) in 138 ms on 10.1.2.66 (3/32)
17/01/29 15:00:35,929 INFO TaskSetManager: Finished task 19.0 in stage 5.0 (TID 124) in 166 ms on 10.1.2.65 (4/32)
17/01/29 15:00:35,930 INFO TaskSetManager: Finished task 15.0 in stage 5.0 (TID 118) in 170 ms on 10.1.2.28 (5/32)
17/01/29 15:00:35,933 INFO TaskSetManager: Finished task 31.0 in stage 5.0 (TID 131) in 166 ms on 10.1.2.65 (6/32)
17/01/29 15:00:35,933 INFO TaskSetManager: Finished task 5.0 in stage 5.0 (TID 102) in 181 ms on 10.1.2.28 (7/32)
17/01/29 15:00:35,935 INFO TaskSetManager: Finished task 8.0 in stage 5.0 (TID 107) in 180 ms on 10.1.2.176 (8/32)
17/01/29 15:00:35,937 INFO TaskSetManager: Starting task 20.0 in stage 5.0 (TID 133, 10.1.2.224, partition 20, PROCESS_LOCAL, 5562 bytes)
17/01/29 15:00:35,938 INFO CoarseGrainedSchedulerBackend$DriverEndpoint: Launching task 133 on executor id: 0 hostname: 10.1.2.224.
17/01/29 15:00:35,938 INFO TaskSetManager: Finished task 1.0 in stage 5.0 (TID 114) in 180 ms on 10.1.2.224 (9/32)
17/01/29 15:00:35,939 INFO TaskSetManager: Finished task 16.0 in stage 5.0 (TID 129) in 173 ms on 10.1.2.224 (10/32)
17/01/29 15:00:35,940 INFO TaskSetManager: Finished task 24.0 in stage 5.0 (TID 125) in 176 ms on 10.1.2.191 (11/32)
17/01/29 15:00:35,941 INFO TaskSetManager: Finished task 25.0 in stage 5.0 (TID 132) in 174 ms on 10.1.2.191 (12/32)
17/01/29 15:00:35,942 INFO TaskSetManager: Finished task 7.0 in stage 5.0 (TID 116) in 183 ms on 10.1.2.65 (13/32)
17/01/29 15:00:35,943 INFO TaskSetManager: Finished task 9.0 in stage 5.0 (TID 110) in 187 ms on 10.1.2.28 (14/32)
17/01/29 15:00:35,944 INFO TaskSetManager: Finished task 14.0 in stage 5.0 (TID 117) in 183 ms on 10.1.2.191 (15/32)
17/01/29 15:00:35,944 INFO TaskSetManager: Finished task 12.0 in stage 5.0 (TID 109) in 188 ms on 10.1.2.191 (16/32)
17/01/29 15:00:35,945 INFO TaskSetManager: Finished task 0.0 in stage 5.0 (TID 106) in 191 ms on 10.1.2.224 (17/32)
17/01/29 15:00:35,947 INFO TaskSetManager: Finished task 29.0 in stage 5.0 (TID 130) in 181 ms on 10.1.2.176 (18/32)
17/01/29 15:00:35,949 INFO TaskSetManager: Finished task 30.0 in stage 5.0 (TID 128) in 184 ms on 10.1.2.139 (19/32)
17/01/29 15:00:35,950 INFO TaskSetManager: Finished task 10.0 in stage 5.0 (TID 122) in 188 ms on 10.1.2.224 (20/32)
17/01/29 15:00:35,952 INFO TaskSetManager: Finished task 4.0 in stage 5.0 (TID 105) in 198 ms on 10.1.2.139 (21/32)
17/01/29 15:00:35,954 INFO TaskSetManager: Finished task 21.0 in stage 5.0 (TID 121) in 192 ms on 10.1.2.139 (22/32)
17/01/29 15:00:35,955 INFO TaskSetManager: Finished task 26.0 in stage 5.0 (TID 126) in 191 ms on 10.1.2.28 (23/32)
17/01/29 15:00:35,957 INFO TaskSetManager: Finished task 3.0 in stage 5.0 (TID 108) in 202 ms on 10.1.2.65 (24/32)
17/01/29 15:00:35,957 INFO TaskSetManager: Finished task 13.0 in stage 5.0 (TID 113) in 199 ms on 10.1.2.139 (25/32)
17/01/29 15:00:35,960 INFO TaskSetManager: Finished task 18.0 in stage 5.0 (TID 115) in 201 ms on 10.1.2.176 (26/32)
17/01/29 15:00:35,962 INFO TaskSetManager: Finished task 22.0 in stage 5.0 (TID 120) in 201 ms on 10.1.2.38 (27/32)
17/01/29 15:00:35,962 INFO TaskSetManager: Finished task 17.0 in stage 5.0 (TID 112) in 205 ms on 10.1.2.38 (28/32)
17/01/29 15:00:35,966 INFO TaskSetManager: Finished task 27.0 in stage 5.0 (TID 127) in 201 ms on 10.1.2.38 (29/32)
17/01/29 15:00:35,968 INFO TaskSetManager: Finished task 28.0 in stage 5.0 (TID 123) in 204 ms on 10.1.2.176 (30/32)
17/01/29 15:00:35,972 INFO TaskSetManager: Finished task 2.0 in stage 5.0 (TID 104) in 218 ms on 10.1.2.38 (31/32)
17/01/29 15:00:35,999 INFO TaskSetManager: Finished task 20.0 in stage 5.0 (TID 133) in 62 ms on 10.1.2.224 (32/32)
17/01/29 15:00:35,999 INFO TaskSchedulerImpl: Removed TaskSet 5.0, whose tasks have all completed, from pool 
17/01/29 15:00:36,000 INFO DAGScheduler: ShuffleMapStage 5 (treeAggregate at GradientDescent.scala:239) finished in 0.247 s
17/01/29 15:00:36,000 INFO DAGScheduler: looking for newly runnable stages
17/01/29 15:00:36,000 INFO DAGScheduler: running: Set()
17/01/29 15:00:36,000 INFO DAGScheduler: waiting: Set(ResultStage 6)
17/01/29 15:00:36,000 INFO DAGScheduler: failed: Set()
17/01/29 15:00:36,001 INFO DAGScheduler: Submitting ResultStage 6 (MapPartitionsRDD[18] at treeAggregate at GradientDescent.scala:239), which has no missing parents
17/01/29 15:00:36,003 INFO MemoryStore: Block broadcast_9 stored as values in memory (estimated size 3.1 KB, free 2.1 GB)
17/01/29 15:00:36,006 INFO MemoryStore: Block broadcast_9_piece0 stored as bytes in memory (estimated size 1889.0 B, free 2.1 GB)
17/01/29 15:00:36,007 INFO BlockManagerInfo: Added broadcast_9_piece0 in memory on 10.1.2.152:42412 (size: 1889.0 B, free: 2.1 GB)
17/01/29 15:00:36,008 INFO SparkContext: Created broadcast 9 from broadcast at DAGScheduler.scala:1012
17/01/29 15:00:36,008 INFO DAGScheduler: Submitting 5 missing tasks from ResultStage 6 (MapPartitionsRDD[18] at treeAggregate at GradientDescent.scala:239)
17/01/29 15:00:36,008 INFO TaskSchedulerImpl: Adding task set 6.0 with 5 tasks
17/01/29 15:00:36,009 INFO TaskSetManager: Starting task 4.0 in stage 6.0 (TID 134, 10.1.2.191, partition 4, NODE_LOCAL, 5228 bytes)
17/01/29 15:00:36,010 INFO TaskSetManager: Starting task 0.0 in stage 6.0 (TID 135, 10.1.2.224, partition 0, NODE_LOCAL, 5228 bytes)
17/01/29 15:00:36,010 INFO TaskSetManager: Starting task 3.0 in stage 6.0 (TID 136, 10.1.2.176, partition 3, NODE_LOCAL, 5228 bytes)
17/01/29 15:00:36,011 INFO TaskSetManager: Starting task 2.0 in stage 6.0 (TID 137, 10.1.2.38, partition 2, NODE_LOCAL, 5228 bytes)
17/01/29 15:00:36,011 INFO TaskSetManager: Starting task 1.0 in stage 6.0 (TID 138, 10.1.2.66, partition 1, NODE_LOCAL, 5228 bytes)
17/01/29 15:00:36,012 INFO CoarseGrainedSchedulerBackend$DriverEndpoint: Launching task 134 on executor id: 5 hostname: 10.1.2.191.
17/01/29 15:00:36,012 INFO CoarseGrainedSchedulerBackend$DriverEndpoint: Launching task 135 on executor id: 0 hostname: 10.1.2.224.
17/01/29 15:00:36,012 INFO CoarseGrainedSchedulerBackend$DriverEndpoint: Launching task 136 on executor id: 4 hostname: 10.1.2.176.
17/01/29 15:00:36,012 INFO CoarseGrainedSchedulerBackend$DriverEndpoint: Launching task 137 on executor id: 1 hostname: 10.1.2.38.
17/01/29 15:00:36,013 INFO CoarseGrainedSchedulerBackend$DriverEndpoint: Launching task 138 on executor id: 6 hostname: 10.1.2.66.
17/01/29 15:00:36,027 INFO BlockManagerInfo: Added broadcast_9_piece0 in memory on 10.1.2.191:44404 (size: 1889.0 B, free: 1942.8 MB)
17/01/29 15:00:36,028 INFO BlockManagerInfo: Added broadcast_9_piece0 in memory on 10.1.2.224:35157 (size: 1889.0 B, free: 1898.5 MB)
17/01/29 15:00:36,028 INFO BlockManagerInfo: Added broadcast_9_piece0 in memory on 10.1.2.176:44820 (size: 1889.0 B, free: 1942.9 MB)
17/01/29 15:00:36,029 INFO BlockManagerInfo: Added broadcast_9_piece0 in memory on 10.1.2.38:38828 (size: 1889.0 B, free: 1942.8 MB)
17/01/29 15:00:36,030 INFO BlockManagerInfo: Added broadcast_9_piece0 in memory on 10.1.2.66:40837 (size: 1889.0 B, free: 1987.3 MB)
17/01/29 15:00:36,033 INFO MapOutputTrackerMasterEndpoint: Asked to send map output locations for shuffle 1 to 10.1.2.191:40452
17/01/29 15:00:36,033 INFO MapOutputTrackerMaster: Size of output statuses for shuffle 1 is 328 bytes
17/01/29 15:00:36,034 INFO MapOutputTrackerMasterEndpoint: Asked to send map output locations for shuffle 1 to 10.1.2.224:39078
17/01/29 15:00:36,035 INFO MapOutputTrackerMasterEndpoint: Asked to send map output locations for shuffle 1 to 10.1.2.176:45614
17/01/29 15:00:36,035 INFO MapOutputTrackerMasterEndpoint: Asked to send map output locations for shuffle 1 to 10.1.2.38:35190
17/01/29 15:00:36,036 INFO MapOutputTrackerMasterEndpoint: Asked to send map output locations for shuffle 1 to 10.1.2.66:42632
17/01/29 15:00:36,048 INFO TaskSetManager: Finished task 2.0 in stage 6.0 (TID 137) in 38 ms on 10.1.2.38 (1/5)
17/01/29 15:00:36,052 INFO TaskSetManager: Finished task 4.0 in stage 6.0 (TID 134) in 43 ms on 10.1.2.191 (2/5)
17/01/29 15:00:36,054 INFO TaskSetManager: Finished task 0.0 in stage 6.0 (TID 135) in 44 ms on 10.1.2.224 (3/5)
17/01/29 15:00:36,054 INFO TaskSetManager: Finished task 3.0 in stage 6.0 (TID 136) in 44 ms on 10.1.2.176 (4/5)
17/01/29 15:00:36,055 INFO TaskSetManager: Finished task 1.0 in stage 6.0 (TID 138) in 44 ms on 10.1.2.66 (5/5)
17/01/29 15:00:36,055 INFO TaskSchedulerImpl: Removed TaskSet 6.0, whose tasks have all completed, from pool 
17/01/29 15:00:36,055 INFO DAGScheduler: ResultStage 6 (treeAggregate at GradientDescent.scala:239) finished in 0.046 s
17/01/29 15:00:36,056 INFO DAGScheduler: Job 4 finished: treeAggregate at GradientDescent.scala:239, took 0.319390 s
17/01/29 15:00:36,066 INFO MemoryStore: Block broadcast_10 stored as values in memory (estimated size 200.0 B, free 2.1 GB)
17/01/29 15:00:36,067 INFO MemoryStore: Block broadcast_10_piece0 stored as bytes in memory (estimated size 285.0 B, free 2.1 GB)
17/01/29 15:00:36,068 INFO BlockManagerInfo: Added broadcast_10_piece0 in memory on 10.1.2.152:42412 (size: 285.0 B, free: 2.1 GB)
17/01/29 15:00:36,069 INFO SparkContext: Created broadcast 10 from broadcast at GradientDescent.scala:235
17/01/29 15:00:36,085 INFO SparkContext: Starting job: treeAggregate at GradientDescent.scala:239
17/01/29 15:00:36,087 INFO DAGScheduler: Registering RDD 21 (treeAggregate at GradientDescent.scala:239)
17/01/29 15:00:36,087 INFO DAGScheduler: Got job 5 (treeAggregate at GradientDescent.scala:239) with 5 output partitions
17/01/29 15:00:36,087 INFO DAGScheduler: Final stage: ResultStage 8 (treeAggregate at GradientDescent.scala:239)
17/01/29 15:00:36,087 INFO DAGScheduler: Parents of final stage: List(ShuffleMapStage 7)
17/01/29 15:00:36,087 INFO DAGScheduler: Missing parents: List(ShuffleMapStage 7)
17/01/29 15:00:36,090 INFO DAGScheduler: Submitting ShuffleMapStage 7 (MapPartitionsRDD[21] at treeAggregate at GradientDescent.scala:239), which has no missing parents
17/01/29 15:00:36,095 INFO MemoryStore: Block broadcast_11 stored as values in memory (estimated size 7.1 KB, free 2.1 GB)
17/01/29 15:00:36,098 INFO MemoryStore: Block broadcast_11_piece0 stored as bytes in memory (estimated size 3.7 KB, free 2.1 GB)
17/01/29 15:00:36,098 INFO BlockManagerInfo: Added broadcast_11_piece0 in memory on 10.1.2.152:42412 (size: 3.7 KB, free: 2.1 GB)
17/01/29 15:00:36,099 INFO SparkContext: Created broadcast 11 from broadcast at DAGScheduler.scala:1012
17/01/29 15:00:36,100 INFO DAGScheduler: Submitting 32 missing tasks from ShuffleMapStage 7 (MapPartitionsRDD[21] at treeAggregate at GradientDescent.scala:239)
17/01/29 15:00:36,100 INFO TaskSchedulerImpl: Adding task set 7.0 with 32 tasks
17/01/29 15:00:36,102 INFO TaskSetManager: Starting task 5.0 in stage 7.0 (TID 139, 10.1.2.28, partition 5, PROCESS_LOCAL, 5562 bytes)
17/01/29 15:00:36,102 INFO TaskSetManager: Starting task 2.0 in stage 7.0 (TID 140, 10.1.2.38, partition 2, PROCESS_LOCAL, 5562 bytes)
17/01/29 15:00:36,103 INFO TaskSetManager: Starting task 3.0 in stage 7.0 (TID 141, 10.1.2.65, partition 3, PROCESS_LOCAL, 5562 bytes)
17/01/29 15:00:36,103 INFO TaskSetManager: Starting task 0.0 in stage 7.0 (TID 142, 10.1.2.224, partition 0, PROCESS_LOCAL, 5562 bytes)
17/01/29 15:00:36,104 INFO TaskSetManager: Starting task 4.0 in stage 7.0 (TID 143, 10.1.2.139, partition 4, PROCESS_LOCAL, 5562 bytes)
17/01/29 15:00:36,104 INFO TaskSetManager: Starting task 8.0 in stage 7.0 (TID 144, 10.1.2.176, partition 8, PROCESS_LOCAL, 5562 bytes)
17/01/29 15:00:36,105 INFO TaskSetManager: Starting task 12.0 in stage 7.0 (TID 145, 10.1.2.191, partition 12, PROCESS_LOCAL, 5562 bytes)
17/01/29 15:00:36,105 INFO TaskSetManager: Starting task 6.0 in stage 7.0 (TID 146, 10.1.2.66, partition 6, PROCESS_LOCAL, 5562 bytes)
17/01/29 15:00:36,106 INFO TaskSetManager: Starting task 9.0 in stage 7.0 (TID 147, 10.1.2.28, partition 9, PROCESS_LOCAL, 5562 bytes)
17/01/29 15:00:36,106 INFO TaskSetManager: Starting task 17.0 in stage 7.0 (TID 148, 10.1.2.38, partition 17, PROCESS_LOCAL, 5562 bytes)
17/01/29 15:00:36,107 INFO TaskSetManager: Starting task 7.0 in stage 7.0 (TID 149, 10.1.2.65, partition 7, PROCESS_LOCAL, 5562 bytes)
17/01/29 15:00:36,107 INFO TaskSetManager: Starting task 1.0 in stage 7.0 (TID 150, 10.1.2.224, partition 1, PROCESS_LOCAL, 5562 bytes)
17/01/29 15:00:36,108 INFO TaskSetManager: Starting task 13.0 in stage 7.0 (TID 151, 10.1.2.139, partition 13, PROCESS_LOCAL, 5562 bytes)
17/01/29 15:00:36,108 INFO TaskSetManager: Starting task 18.0 in stage 7.0 (TID 152, 10.1.2.176, partition 18, PROCESS_LOCAL, 5562 bytes)
17/01/29 15:00:36,109 INFO TaskSetManager: Starting task 14.0 in stage 7.0 (TID 153, 10.1.2.191, partition 14, PROCESS_LOCAL, 5562 bytes)
17/01/29 15:00:36,109 INFO TaskSetManager: Starting task 11.0 in stage 7.0 (TID 154, 10.1.2.66, partition 11, PROCESS_LOCAL, 5562 bytes)
17/01/29 15:00:36,110 INFO TaskSetManager: Starting task 15.0 in stage 7.0 (TID 155, 10.1.2.28, partition 15, PROCESS_LOCAL, 5562 bytes)
17/01/29 15:00:36,110 INFO TaskSetManager: Starting task 22.0 in stage 7.0 (TID 156, 10.1.2.38, partition 22, PROCESS_LOCAL, 5562 bytes)
17/01/29 15:00:36,120 INFO TaskSetManager: Starting task 19.0 in stage 7.0 (TID 157, 10.1.2.65, partition 19, PROCESS_LOCAL, 5562 bytes)
17/01/29 15:00:36,121 INFO TaskSetManager: Starting task 10.0 in stage 7.0 (TID 158, 10.1.2.224, partition 10, PROCESS_LOCAL, 5562 bytes)
17/01/29 15:00:36,121 INFO TaskSetManager: Starting task 21.0 in stage 7.0 (TID 159, 10.1.2.139, partition 21, PROCESS_LOCAL, 5562 bytes)
17/01/29 15:00:36,121 INFO TaskSetManager: Starting task 28.0 in stage 7.0 (TID 160, 10.1.2.176, partition 28, PROCESS_LOCAL, 5562 bytes)
17/01/29 15:00:36,122 INFO TaskSetManager: Starting task 24.0 in stage 7.0 (TID 161, 10.1.2.191, partition 24, PROCESS_LOCAL, 5562 bytes)
17/01/29 15:00:36,122 INFO TaskSetManager: Starting task 23.0 in stage 7.0 (TID 162, 10.1.2.66, partition 23, PROCESS_LOCAL, 5562 bytes)
17/01/29 15:00:36,123 INFO TaskSetManager: Starting task 26.0 in stage 7.0 (TID 163, 10.1.2.28, partition 26, PROCESS_LOCAL, 5562 bytes)
17/01/29 15:00:36,123 INFO TaskSetManager: Starting task 27.0 in stage 7.0 (TID 164, 10.1.2.38, partition 27, PROCESS_LOCAL, 5562 bytes)
17/01/29 15:00:36,124 INFO TaskSetManager: Starting task 31.0 in stage 7.0 (TID 165, 10.1.2.65, partition 31, PROCESS_LOCAL, 5562 bytes)
17/01/29 15:00:36,124 INFO TaskSetManager: Starting task 16.0 in stage 7.0 (TID 166, 10.1.2.224, partition 16, PROCESS_LOCAL, 5562 bytes)
17/01/29 15:00:36,125 INFO TaskSetManager: Starting task 30.0 in stage 7.0 (TID 167, 10.1.2.139, partition 30, PROCESS_LOCAL, 5562 bytes)
17/01/29 15:00:36,125 INFO TaskSetManager: Starting task 29.0 in stage 7.0 (TID 168, 10.1.2.176, partition 29, PROCESS_LOCAL, 5562 bytes)
17/01/29 15:00:36,126 INFO TaskSetManager: Starting task 25.0 in stage 7.0 (TID 169, 10.1.2.191, partition 25, PROCESS_LOCAL, 5562 bytes)
17/01/29 15:00:36,126 INFO CoarseGrainedSchedulerBackend$DriverEndpoint: Launching task 139 on executor id: 2 hostname: 10.1.2.28.
