Using properties file: /home/ubuntu/spark-2.0.0/conf/spark-defaults.conf
Adding default property: spark.driver.extraJavaOptions=-XX:+PrintGCDetails -XX:+PrintGCTimeStamps -Xms4000m -Dlog4j.configuration=file:///home/ubuntu/spark-2.0.0/conf/log4j.properties
Adding default property: spark.executor.extraJavaOptions=-XX:+PrintGCDetails -XX:+PrintGCTimeStamps -Xms4000m -Dlog4j.configuration=file:///home/ubuntu/spark-2.0.0/conf/log4j.properties
Parsed arguments:
  master                  spark://euca-10-1-2-152:7077
  deployMode              client
  executorMemory          4000m
  executorCores           null
  totalExecutorCores      null
  propertiesFile          /home/ubuntu/spark-2.0.0/conf/spark-defaults.conf
  driverMemory            4000m
  driverCores             null
  driverExtraClassPath    null
  driverExtraLibraryPath  null
  driverExtraJavaOptions  -XX:+PrintGCDetails -XX:+PrintGCTimeStamps -Xms4000m -Dlog4j.configuration=file:///home/ubuntu/spark-2.0.0/conf/log4j.properties
  supervise               false
  queue                   null
  numExecutors            8
  files                   null
  pyFiles                 null
  archives                null
  mainClass               LogRegExplicitParallelism
  primaryResource         file:///home/ubuntu/jars/log-reg-explicit-parallelism_2.11-1.0.jar
  name                    LogRegExplicitParallelism
  childArgs               [cluster 18 euca-10-1-2-152 9000 susy_0_exp 5 32]
  jars                    null
  packages                null
  packagesExclusions      null
  repositories            null
  verbose                 true

Spark properties used, including those specified through
 --conf and those from the properties file /home/ubuntu/spark-2.0.0/conf/spark-defaults.conf:
  spark.default.parallelism -> 32
  spark.driver.memory -> 4000m
  spark.executor.extraJavaOptions -> -XX:+PrintGCDetails -XX:+PrintGCTimeStamps -Xms4000m -Dlog4j.configuration=file:///home/ubuntu/spark-2.0.0/conf/log4j.properties
  spark.driver.extraJavaOptions -> -XX:+PrintGCDetails -XX:+PrintGCTimeStamps -Xms4000m -Dlog4j.configuration=file:///home/ubuntu/spark-2.0.0/conf/log4j.properties
  spark.shuffle.spill -> false

    
Main class:
LogRegExplicitParallelism
Arguments:
cluster
18
euca-10-1-2-152
9000
susy_0_exp
5
32
System properties:
spark.default.parallelism -> 32
spark.executor.memory -> 4000m
spark.driver.memory -> 4000m
SPARK_SUBMIT -> true
spark.executor.extraJavaOptions -> -XX:+PrintGCDetails -XX:+PrintGCTimeStamps -Xms4000m -Dlog4j.configuration=file:///home/ubuntu/spark-2.0.0/conf/log4j.properties
spark.app.name -> LogRegExplicitParallelism
spark.shuffle.spill -> false
spark.driver.extraJavaOptions -> -XX:+PrintGCDetails -XX:+PrintGCTimeStamps -Xms4000m -Dlog4j.configuration=file:///home/ubuntu/spark-2.0.0/conf/log4j.properties
spark.jars -> file:///home/ubuntu/jars/log-reg-explicit-parallelism_2.11-1.0.jar
spark.submit.deployMode -> client
spark.master -> spark://euca-10-1-2-152:7077
Classpath elements:
file:///home/ubuntu/jars/log-reg-explicit-parallelism_2.11-1.0.jar


17/01/29 15:27:06,032 INFO SparkContext: Running Spark version 2.0.0
17/01/29 15:27:06,366 WARN NativeCodeLoader: Unable to load native-hadoop library for your platform... using builtin-java classes where applicable
17/01/29 15:27:06,522 INFO SecurityManager: Changing view acls to: ubuntu
17/01/29 15:27:06,522 INFO SecurityManager: Changing modify acls to: ubuntu
17/01/29 15:27:06,523 INFO SecurityManager: Changing view acls groups to: 
17/01/29 15:27:06,523 INFO SecurityManager: Changing modify acls groups to: 
17/01/29 15:27:06,524 INFO SecurityManager: SecurityManager: authentication disabled; ui acls disabled; users  with view permissions: Set(ubuntu); groups with view permissions: Set(); users  with modify permissions: Set(ubuntu); groups with modify permissions: Set()
17/01/29 15:27:09,783 WARN ThreadLocalRandom: Failed to generate a seed from SecureRandom within 3 seconds. Not enough entrophy?
17/01/29 15:27:09,835 INFO Utils: Successfully started service 'sparkDriver' on port 33272.
17/01/29 15:27:09,853 INFO SparkEnv: Registering MapOutputTracker
17/01/29 15:27:09,859 WARN SortShuffleManager: spark.shuffle.spill was set to false, but this configuration is ignored as of Spark 1.6+. Shuffle will continue to spill to disk when necessary.
17/01/29 15:27:09,871 INFO SparkEnv: Registering BlockManagerMaster
17/01/29 15:27:09,884 INFO DiskBlockManager: Created local directory at /tmp/blockmgr-5ffbfe90-20f2-4487-8492-9504f0327f63
17/01/29 15:27:09,904 INFO MemoryStore: MemoryStore started with capacity 2.1 GB
17/01/29 15:27:09,975 INFO SparkEnv: Registering OutputCommitCoordinator
17/01/29 15:27:10,188 INFO Utils: Successfully started service 'SparkUI' on port 4040.
17/01/29 15:27:10,189 INFO SparkUI: Bound SparkUI to 10.1.2.152, and started at http://10.1.2.152:4040
17/01/29 15:27:10,223 INFO SparkContext: Added JAR file:///home/ubuntu/jars/log-reg-explicit-parallelism_2.11-1.0.jar at spark://10.1.2.152:33272/jars/log-reg-explicit-parallelism_2.11-1.0.jar with timestamp 1485703630222
17/01/29 15:27:10,305 INFO StandaloneAppClient$ClientEndpoint: Connecting to master spark://euca-10-1-2-152:7077...
17/01/29 15:27:10,356 INFO TransportClientFactory: Successfully created connection to euca-10-1-2-152/10.1.2.152:7077 after 25 ms (0 ms spent in bootstraps)
17/01/29 15:27:10,454 INFO StandaloneSchedulerBackend: Connected to Spark cluster with app ID app-20170129152710-0000
17/01/29 15:27:10,460 INFO Utils: Successfully started service 'org.apache.spark.network.netty.NettyBlockTransferService' on port 45830.
17/01/29 15:27:10,460 INFO NettyBlockTransferService: Server created on 10.1.2.152:45830
17/01/29 15:27:10,462 INFO BlockManagerMaster: Registering BlockManager BlockManagerId(driver, 10.1.2.152, 45830)
17/01/29 15:27:10,465 INFO BlockManagerMasterEndpoint: Registering block manager 10.1.2.152:45830 with 2.1 GB RAM, BlockManagerId(driver, 10.1.2.152, 45830)
17/01/29 15:27:10,467 INFO BlockManagerMaster: Registered BlockManager BlockManagerId(driver, 10.1.2.152, 45830)
17/01/29 15:27:10,496 INFO StandaloneAppClient$ClientEndpoint: Executor added: app-20170129152710-0000/0 on worker-20170129152646-10.1.2.28-46054 (10.1.2.28:46054) with 4 cores
17/01/29 15:27:10,500 INFO StandaloneSchedulerBackend: Granted executor ID app-20170129152710-0000/0 on hostPort 10.1.2.28:46054 with 4 cores, 3.9 GB RAM
17/01/29 15:27:10,501 INFO StandaloneAppClient$ClientEndpoint: Executor added: app-20170129152710-0000/1 on worker-20170129152646-10.1.2.191-46558 (10.1.2.191:46558) with 4 cores
17/01/29 15:27:10,501 INFO StandaloneSchedulerBackend: Granted executor ID app-20170129152710-0000/1 on hostPort 10.1.2.191:46558 with 4 cores, 3.9 GB RAM
17/01/29 15:27:10,501 INFO StandaloneAppClient$ClientEndpoint: Executor added: app-20170129152710-0000/2 on worker-20170129152646-10.1.2.66-33787 (10.1.2.66:33787) with 4 cores
17/01/29 15:27:10,502 INFO StandaloneSchedulerBackend: Granted executor ID app-20170129152710-0000/2 on hostPort 10.1.2.66:33787 with 4 cores, 3.9 GB RAM
17/01/29 15:27:10,502 INFO StandaloneAppClient$ClientEndpoint: Executor added: app-20170129152710-0000/3 on worker-20170129152646-10.1.2.65-46311 (10.1.2.65:46311) with 4 cores
17/01/29 15:27:10,502 INFO StandaloneSchedulerBackend: Granted executor ID app-20170129152710-0000/3 on hostPort 10.1.2.65:46311 with 4 cores, 3.9 GB RAM
17/01/29 15:27:10,503 INFO StandaloneAppClient$ClientEndpoint: Executor added: app-20170129152710-0000/4 on worker-20170129152646-10.1.2.38-37300 (10.1.2.38:37300) with 4 cores
17/01/29 15:27:10,504 INFO StandaloneSchedulerBackend: Granted executor ID app-20170129152710-0000/4 on hostPort 10.1.2.38:37300 with 4 cores, 3.9 GB RAM
17/01/29 15:27:10,505 INFO StandaloneAppClient$ClientEndpoint: Executor added: app-20170129152710-0000/5 on worker-20170129152646-10.1.2.176-34123 (10.1.2.176:34123) with 4 cores
17/01/29 15:27:10,505 INFO StandaloneSchedulerBackend: Granted executor ID app-20170129152710-0000/5 on hostPort 10.1.2.176:34123 with 4 cores, 3.9 GB RAM
17/01/29 15:27:10,506 INFO StandaloneAppClient$ClientEndpoint: Executor added: app-20170129152710-0000/6 on worker-20170129152646-10.1.2.224-42855 (10.1.2.224:42855) with 4 cores
17/01/29 15:27:10,507 INFO StandaloneSchedulerBackend: Granted executor ID app-20170129152710-0000/6 on hostPort 10.1.2.224:42855 with 4 cores, 3.9 GB RAM
17/01/29 15:27:10,507 INFO StandaloneAppClient$ClientEndpoint: Executor added: app-20170129152710-0000/7 on worker-20170129152646-10.1.2.139-44140 (10.1.2.139:44140) with 4 cores
17/01/29 15:27:10,508 INFO StandaloneSchedulerBackend: Granted executor ID app-20170129152710-0000/7 on hostPort 10.1.2.139:44140 with 4 cores, 3.9 GB RAM
17/01/29 15:27:10,548 INFO StandaloneAppClient$ClientEndpoint: Executor updated: app-20170129152710-0000/4 is now RUNNING
17/01/29 15:27:10,548 INFO StandaloneAppClient$ClientEndpoint: Executor updated: app-20170129152710-0000/2 is now RUNNING
17/01/29 15:27:10,551 INFO StandaloneAppClient$ClientEndpoint: Executor updated: app-20170129152710-0000/1 is now RUNNING
17/01/29 15:27:10,554 INFO StandaloneAppClient$ClientEndpoint: Executor updated: app-20170129152710-0000/5 is now RUNNING
17/01/29 15:27:10,556 INFO StandaloneAppClient$ClientEndpoint: Executor updated: app-20170129152710-0000/0 is now RUNNING
17/01/29 15:27:10,559 INFO StandaloneAppClient$ClientEndpoint: Executor updated: app-20170129152710-0000/3 is now RUNNING
17/01/29 15:27:10,561 INFO StandaloneAppClient$ClientEndpoint: Executor updated: app-20170129152710-0000/7 is now RUNNING
17/01/29 15:27:10,563 INFO StandaloneAppClient$ClientEndpoint: Executor updated: app-20170129152710-0000/6 is now RUNNING
17/01/29 15:27:10,678 INFO StandaloneSchedulerBackend: SchedulerBackend is ready for scheduling beginning after reached minRegisteredResourcesRatio: 0.0
17/01/29 15:27:11,075 INFO MemoryStore: Block broadcast_0 stored as values in memory (estimated size 130.8 KB, free 2.1 GB)
17/01/29 15:27:11,142 INFO MemoryStore: Block broadcast_0_piece0 stored as bytes in memory (estimated size 16.5 KB, free 2.1 GB)
17/01/29 15:27:11,144 INFO BlockManagerInfo: Added broadcast_0_piece0 in memory on 10.1.2.152:45830 (size: 16.5 KB, free: 2.1 GB)
17/01/29 15:27:11,153 INFO SparkContext: Created broadcast 0 from textFile at MLUtils.scala:99
17/01/29 15:27:11,791 INFO FileInputFormat: Total input paths to process : 1
17/01/29 15:27:11,826 INFO NetworkTopology: Adding a new node: /default-rack/10.1.2.66:50010
17/01/29 15:27:11,827 INFO NetworkTopology: Adding a new node: /default-rack/10.1.2.38:50010
17/01/29 15:27:11,827 INFO NetworkTopology: Adding a new node: /default-rack/10.1.2.224:50010
17/01/29 15:27:11,827 INFO NetworkTopology: Adding a new node: /default-rack/10.1.2.28:50010
17/01/29 15:27:11,827 INFO NetworkTopology: Adding a new node: /default-rack/10.1.2.176:50010
17/01/29 15:27:11,828 INFO NetworkTopology: Adding a new node: /default-rack/10.1.2.65:50010
17/01/29 15:27:11,828 INFO NetworkTopology: Adding a new node: /default-rack/10.1.2.139:50010
17/01/29 15:27:11,829 INFO NetworkTopology: Adding a new node: /default-rack/10.1.2.191:50010
17/01/29 15:27:11,870 INFO SparkContext: Starting job: first at GeneralizedLinearAlgorithm.scala:246
17/01/29 15:27:11,883 INFO DAGScheduler: Got job 0 (first at GeneralizedLinearAlgorithm.scala:246) with 1 output partitions
17/01/29 15:27:11,883 INFO DAGScheduler: Final stage: ResultStage 0 (first at GeneralizedLinearAlgorithm.scala:246)
17/01/29 15:27:11,884 INFO DAGScheduler: Parents of final stage: List()
17/01/29 15:27:11,889 INFO DAGScheduler: Missing parents: List()
17/01/29 15:27:11,904 INFO DAGScheduler: Submitting ResultStage 0 (MapPartitionsRDD[6] at map at GeneralizedLinearAlgorithm.scala:246), which has no missing parents
17/01/29 15:27:11,928 INFO MemoryStore: Block broadcast_1 stored as values in memory (estimated size 4.2 KB, free 2.1 GB)
17/01/29 15:27:11,931 INFO MemoryStore: Block broadcast_1_piece0 stored as bytes in memory (estimated size 2.4 KB, free 2.1 GB)
17/01/29 15:27:11,932 INFO BlockManagerInfo: Added broadcast_1_piece0 in memory on 10.1.2.152:45830 (size: 2.4 KB, free: 2.1 GB)
17/01/29 15:27:11,934 INFO SparkContext: Created broadcast 1 from broadcast at DAGScheduler.scala:1012
17/01/29 15:27:11,936 INFO DAGScheduler: Submitting 1 missing tasks from ResultStage 0 (MapPartitionsRDD[6] at map at GeneralizedLinearAlgorithm.scala:246)
17/01/29 15:27:11,938 INFO TaskSchedulerImpl: Adding task set 0.0 with 1 tasks
17/01/29 15:27:15,354 INFO CoarseGrainedSchedulerBackend$DriverEndpoint: Registered executor NettyRpcEndpointRef(null) (10.1.2.65:36874) with ID 3
17/01/29 15:27:15,394 INFO TaskSetManager: Starting task 0.0 in stage 0.0 (TID 0, 10.1.2.65, partition 0, ANY, 5455 bytes)
17/01/29 15:27:15,403 INFO CoarseGrainedSchedulerBackend$DriverEndpoint: Launching task 0 on executor id: 3 hostname: 10.1.2.65.
17/01/29 15:27:15,405 INFO CoarseGrainedSchedulerBackend$DriverEndpoint: Registered executor NettyRpcEndpointRef(null) (10.1.2.176:54556) with ID 5
17/01/29 15:27:15,409 INFO BlockManagerMasterEndpoint: Registering block manager 10.1.2.65:33751 with 2.1 GB RAM, BlockManagerId(3, 10.1.2.65, 33751)
17/01/29 15:27:15,421 INFO CoarseGrainedSchedulerBackend$DriverEndpoint: Registered executor NettyRpcEndpointRef(null) (10.1.2.191:46308) with ID 1
17/01/29 15:27:15,425 INFO CoarseGrainedSchedulerBackend$DriverEndpoint: Registered executor NettyRpcEndpointRef(null) (10.1.2.224:50594) with ID 6
17/01/29 15:27:15,427 INFO CoarseGrainedSchedulerBackend$DriverEndpoint: Registered executor NettyRpcEndpointRef(null) (10.1.2.28:57576) with ID 0
17/01/29 15:27:15,440 INFO CoarseGrainedSchedulerBackend$DriverEndpoint: Registered executor NettyRpcEndpointRef(null) (10.1.2.38:46002) with ID 4
17/01/29 15:27:15,452 INFO BlockManagerMasterEndpoint: Registering block manager 10.1.2.176:37793 with 2.1 GB RAM, BlockManagerId(5, 10.1.2.176, 37793)
17/01/29 15:27:15,478 INFO BlockManagerMasterEndpoint: Registering block manager 10.1.2.224:33593 with 2.1 GB RAM, BlockManagerId(6, 10.1.2.224, 33593)
17/01/29 15:27:15,481 INFO BlockManagerMasterEndpoint: Registering block manager 10.1.2.28:44512 with 2.1 GB RAM, BlockManagerId(0, 10.1.2.28, 44512)
17/01/29 15:27:15,482 INFO BlockManagerMasterEndpoint: Registering block manager 10.1.2.191:37586 with 2.1 GB RAM, BlockManagerId(1, 10.1.2.191, 37586)
17/01/29 15:27:15,488 INFO BlockManagerMasterEndpoint: Registering block manager 10.1.2.38:33985 with 2.1 GB RAM, BlockManagerId(4, 10.1.2.38, 33985)
17/01/29 15:27:15,534 INFO CoarseGrainedSchedulerBackend$DriverEndpoint: Registered executor NettyRpcEndpointRef(null) (10.1.2.139:46046) with ID 7
17/01/29 15:27:15,554 INFO CoarseGrainedSchedulerBackend$DriverEndpoint: Registered executor NettyRpcEndpointRef(null) (10.1.2.66:39392) with ID 2
17/01/29 15:27:15,599 INFO BlockManagerMasterEndpoint: Registering block manager 10.1.2.139:45024 with 2.1 GB RAM, BlockManagerId(7, 10.1.2.139, 45024)
17/01/29 15:27:15,609 INFO BlockManagerMasterEndpoint: Registering block manager 10.1.2.66:34001 with 2.1 GB RAM, BlockManagerId(2, 10.1.2.66, 34001)
17/01/29 15:27:15,685 INFO BlockManagerInfo: Added broadcast_1_piece0 in memory on 10.1.2.65:33751 (size: 2.4 KB, free: 2.1 GB)
17/01/29 15:27:15,831 INFO BlockManagerInfo: Added broadcast_0_piece0 in memory on 10.1.2.65:33751 (size: 16.5 KB, free: 2.1 GB)
17/01/29 15:27:20,596 INFO BlockManagerInfo: Added rdd_5_0 in memory on 10.1.2.65:33751 (size: 44.3 MB, free: 2.0 GB)
17/01/29 15:27:20,640 INFO TaskSetManager: Finished task 0.0 in stage 0.0 (TID 0) in 5275 ms on 10.1.2.65 (1/1)
17/01/29 15:27:20,645 INFO DAGScheduler: ResultStage 0 (first at GeneralizedLinearAlgorithm.scala:246) finished in 8.696 s
17/01/29 15:27:20,641 INFO TaskSchedulerImpl: Removed TaskSet 0.0, whose tasks have all completed, from pool 
17/01/29 15:27:20,650 INFO DAGScheduler: Job 0 finished: first at GeneralizedLinearAlgorithm.scala:246, took 8.779410 s
17/01/29 15:27:20,661 INFO SparkContext: Starting job: count at DataValidators.scala:40
17/01/29 15:27:20,663 INFO DAGScheduler: Got job 1 (count at DataValidators.scala:40) with 32 output partitions
17/01/29 15:27:20,663 INFO DAGScheduler: Final stage: ResultStage 1 (count at DataValidators.scala:40)
17/01/29 15:27:20,664 INFO DAGScheduler: Parents of final stage: List()
17/01/29 15:27:20,666 INFO DAGScheduler: Missing parents: List()
17/01/29 15:27:20,666 INFO DAGScheduler: Submitting ResultStage 1 (MapPartitionsRDD[7] at filter at DataValidators.scala:40), which has no missing parents
17/01/29 15:27:20,683 INFO MemoryStore: Block broadcast_2 stored as values in memory (estimated size 3.9 KB, free 2.1 GB)
17/01/29 15:27:20,685 INFO MemoryStore: Block broadcast_2_piece0 stored as bytes in memory (estimated size 2.2 KB, free 2.1 GB)
17/01/29 15:27:20,686 INFO BlockManagerInfo: Added broadcast_2_piece0 in memory on 10.1.2.152:45830 (size: 2.2 KB, free: 2.1 GB)
17/01/29 15:27:20,687 INFO SparkContext: Created broadcast 2 from broadcast at DAGScheduler.scala:1012
17/01/29 15:27:20,688 INFO DAGScheduler: Submitting 32 missing tasks from ResultStage 1 (MapPartitionsRDD[7] at filter at DataValidators.scala:40)
17/01/29 15:27:20,689 INFO TaskSchedulerImpl: Adding task set 1.0 with 32 tasks
17/01/29 15:27:20,696 INFO TaskSetManager: Starting task 0.0 in stage 1.0 (TID 1, 10.1.2.65, partition 0, PROCESS_LOCAL, 5373 bytes)
17/01/29 15:27:20,699 INFO TaskSetManager: Starting task 1.0 in stage 1.0 (TID 2, 10.1.2.224, partition 1, NODE_LOCAL, 5373 bytes)
17/01/29 15:27:20,701 INFO TaskSetManager: Starting task 8.0 in stage 1.0 (TID 3, 10.1.2.176, partition 8, NODE_LOCAL, 5373 bytes)
17/01/29 15:27:20,704 INFO TaskSetManager: Starting task 5.0 in stage 1.0 (TID 4, 10.1.2.28, partition 5, NODE_LOCAL, 5373 bytes)
17/01/29 15:27:20,706 INFO TaskSetManager: Starting task 3.0 in stage 1.0 (TID 5, 10.1.2.66, partition 3, NODE_LOCAL, 5373 bytes)
17/01/29 15:27:20,711 INFO TaskSetManager: Starting task 17.0 in stage 1.0 (TID 6, 10.1.2.38, partition 17, NODE_LOCAL, 5373 bytes)
17/01/29 15:27:20,714 INFO TaskSetManager: Starting task 12.0 in stage 1.0 (TID 7, 10.1.2.191, partition 12, NODE_LOCAL, 5373 bytes)
17/01/29 15:27:20,716 INFO TaskSetManager: Starting task 6.0 in stage 1.0 (TID 8, 10.1.2.65, partition 6, NODE_LOCAL, 5373 bytes)
17/01/29 15:27:20,719 INFO TaskSetManager: Starting task 13.0 in stage 1.0 (TID 9, 10.1.2.139, partition 13, NODE_LOCAL, 5373 bytes)
17/01/29 15:27:20,721 INFO TaskSetManager: Starting task 10.0 in stage 1.0 (TID 10, 10.1.2.224, partition 10, NODE_LOCAL, 5373 bytes)
17/01/29 15:27:20,725 INFO TaskSetManager: Starting task 15.0 in stage 1.0 (TID 11, 10.1.2.176, partition 15, NODE_LOCAL, 5373 bytes)
17/01/29 15:27:20,727 INFO TaskSetManager: Starting task 19.0 in stage 1.0 (TID 12, 10.1.2.28, partition 19, NODE_LOCAL, 5373 bytes)
17/01/29 15:27:20,729 INFO TaskSetManager: Starting task 22.0 in stage 1.0 (TID 13, 10.1.2.66, partition 22, NODE_LOCAL, 5373 bytes)
17/01/29 15:27:20,732 INFO TaskSetManager: Starting task 26.0 in stage 1.0 (TID 14, 10.1.2.38, partition 26, NODE_LOCAL, 5373 bytes)
17/01/29 15:27:20,734 INFO TaskSetManager: Starting task 24.0 in stage 1.0 (TID 15, 10.1.2.191, partition 24, NODE_LOCAL, 5373 bytes)
17/01/29 15:27:20,737 INFO TaskSetManager: Starting task 20.0 in stage 1.0 (TID 16, 10.1.2.65, partition 20, NODE_LOCAL, 5373 bytes)
17/01/29 15:27:20,739 INFO TaskSetManager: Starting task 27.0 in stage 1.0 (TID 17, 10.1.2.224, partition 27, NODE_LOCAL, 5373 bytes)
17/01/29 15:27:20,741 INFO TaskSetManager: Starting task 29.0 in stage 1.0 (TID 18, 10.1.2.176, partition 29, NODE_LOCAL, 5373 bytes)
17/01/29 15:27:20,744 INFO TaskSetManager: Starting task 31.0 in stage 1.0 (TID 19, 10.1.2.65, partition 31, NODE_LOCAL, 5373 bytes)
17/01/29 15:27:20,745 INFO CoarseGrainedSchedulerBackend$DriverEndpoint: Launching task 2 on executor id: 6 hostname: 10.1.2.224.
17/01/29 15:27:20,745 INFO CoarseGrainedSchedulerBackend$DriverEndpoint: Launching task 10 on executor id: 6 hostname: 10.1.2.224.
17/01/29 15:27:20,746 INFO CoarseGrainedSchedulerBackend$DriverEndpoint: Launching task 17 on executor id: 6 hostname: 10.1.2.224.
17/01/29 15:27:20,747 INFO CoarseGrainedSchedulerBackend$DriverEndpoint: Launching task 3 on executor id: 5 hostname: 10.1.2.176.
17/01/29 15:27:20,748 INFO CoarseGrainedSchedulerBackend$DriverEndpoint: Launching task 11 on executor id: 5 hostname: 10.1.2.176.
17/01/29 15:27:20,749 INFO CoarseGrainedSchedulerBackend$DriverEndpoint: Launching task 18 on executor id: 5 hostname: 10.1.2.176.
17/01/29 15:27:20,750 INFO CoarseGrainedSchedulerBackend$DriverEndpoint: Launching task 4 on executor id: 0 hostname: 10.1.2.28.
17/01/29 15:27:20,751 INFO CoarseGrainedSchedulerBackend$DriverEndpoint: Launching task 12 on executor id: 0 hostname: 10.1.2.28.
17/01/29 15:27:20,751 INFO CoarseGrainedSchedulerBackend$DriverEndpoint: Launching task 5 on executor id: 2 hostname: 10.1.2.66.
17/01/29 15:27:20,752 INFO CoarseGrainedSchedulerBackend$DriverEndpoint: Launching task 13 on executor id: 2 hostname: 10.1.2.66.
17/01/29 15:27:20,752 INFO CoarseGrainedSchedulerBackend$DriverEndpoint: Launching task 6 on executor id: 4 hostname: 10.1.2.38.
17/01/29 15:27:20,753 INFO CoarseGrainedSchedulerBackend$DriverEndpoint: Launching task 14 on executor id: 4 hostname: 10.1.2.38.
17/01/29 15:27:20,754 INFO CoarseGrainedSchedulerBackend$DriverEndpoint: Launching task 7 on executor id: 1 hostname: 10.1.2.191.
17/01/29 15:27:20,755 INFO CoarseGrainedSchedulerBackend$DriverEndpoint: Launching task 15 on executor id: 1 hostname: 10.1.2.191.
17/01/29 15:27:20,755 INFO CoarseGrainedSchedulerBackend$DriverEndpoint: Launching task 1 on executor id: 3 hostname: 10.1.2.65.
17/01/29 15:27:20,756 INFO CoarseGrainedSchedulerBackend$DriverEndpoint: Launching task 8 on executor id: 3 hostname: 10.1.2.65.
17/01/29 15:27:20,756 INFO CoarseGrainedSchedulerBackend$DriverEndpoint: Launching task 16 on executor id: 3 hostname: 10.1.2.65.
17/01/29 15:27:20,757 INFO CoarseGrainedSchedulerBackend$DriverEndpoint: Launching task 19 on executor id: 3 hostname: 10.1.2.65.
17/01/29 15:27:20,757 INFO CoarseGrainedSchedulerBackend$DriverEndpoint: Launching task 9 on executor id: 7 hostname: 10.1.2.139.
17/01/29 15:27:20,821 INFO BlockManagerInfo: Added broadcast_2_piece0 in memory on 10.1.2.65:33751 (size: 2.2 KB, free: 2.0 GB)
17/01/29 15:27:20,913 INFO TaskSetManager: Finished task 0.0 in stage 1.0 (TID 1) in 218 ms on 10.1.2.65 (1/32)
15.602: [GC [PSYoungGen: 1024512K->140460K(1195008K)] 1024512K->140468K(3926016K), 0.0496170 secs] [Times: user=0.06 sys=0.06, real=0.05 secs] 
17/01/29 15:27:21,105 INFO BlockManagerInfo: Added broadcast_2_piece0 in memory on 10.1.2.191:37586 (size: 2.2 KB, free: 2.1 GB)
17/01/29 15:27:21,113 INFO BlockManagerInfo: Added broadcast_2_piece0 in memory on 10.1.2.224:33593 (size: 2.2 KB, free: 2.1 GB)
17/01/29 15:27:21,114 INFO BlockManagerInfo: Added broadcast_2_piece0 in memory on 10.1.2.139:45024 (size: 2.2 KB, free: 2.1 GB)
17/01/29 15:27:21,126 INFO BlockManagerInfo: Removed broadcast_1_piece0 on 10.1.2.152:45830 in memory (size: 2.4 KB, free: 2.1 GB)
17/01/29 15:27:21,127 INFO BlockManagerInfo: Added broadcast_2_piece0 in memory on 10.1.2.176:37793 (size: 2.2 KB, free: 2.1 GB)
17/01/29 15:27:21,128 INFO BlockManagerInfo: Added broadcast_2_piece0 in memory on 10.1.2.38:33985 (size: 2.2 KB, free: 2.1 GB)
17/01/29 15:27:21,132 INFO BlockManagerInfo: Removed broadcast_1_piece0 on 10.1.2.65:33751 in memory (size: 2.4 KB, free: 2.0 GB)
17/01/29 15:27:21,136 INFO BlockManagerInfo: Added broadcast_2_piece0 in memory on 10.1.2.66:34001 (size: 2.2 KB, free: 2.1 GB)
17/01/29 15:27:21,144 INFO BlockManagerInfo: Added broadcast_2_piece0 in memory on 10.1.2.28:44512 (size: 2.2 KB, free: 2.1 GB)
17/01/29 15:27:21,259 INFO BlockManagerInfo: Added broadcast_0_piece0 in memory on 10.1.2.191:37586 (size: 16.5 KB, free: 2.1 GB)
17/01/29 15:27:21,279 INFO BlockManagerInfo: Added broadcast_0_piece0 in memory on 10.1.2.139:45024 (size: 16.5 KB, free: 2.1 GB)
17/01/29 15:27:21,284 INFO BlockManagerInfo: Added broadcast_0_piece0 in memory on 10.1.2.38:33985 (size: 16.5 KB, free: 2.1 GB)
17/01/29 15:27:21,315 INFO BlockManagerInfo: Added broadcast_0_piece0 in memory on 10.1.2.224:33593 (size: 16.5 KB, free: 2.1 GB)
17/01/29 15:27:21,337 INFO BlockManagerInfo: Added broadcast_0_piece0 in memory on 10.1.2.28:44512 (size: 16.5 KB, free: 2.1 GB)
17/01/29 15:27:21,343 INFO BlockManagerInfo: Added broadcast_0_piece0 in memory on 10.1.2.66:34001 (size: 16.5 KB, free: 2.1 GB)
17/01/29 15:27:21,346 INFO BlockManagerInfo: Added broadcast_0_piece0 in memory on 10.1.2.176:37793 (size: 16.5 KB, free: 2.1 GB)
17/01/29 15:27:24,295 INFO TaskSetManager: Starting task 2.0 in stage 1.0 (TID 20, 10.1.2.139, partition 2, ANY, 5373 bytes)
17/01/29 15:27:24,297 INFO TaskSetManager: Starting task 4.0 in stage 1.0 (TID 21, 10.1.2.224, partition 4, ANY, 5373 bytes)
17/01/29 15:27:24,299 INFO TaskSetManager: Starting task 7.0 in stage 1.0 (TID 22, 10.1.2.66, partition 7, ANY, 5373 bytes)
17/01/29 15:27:24,301 INFO TaskSetManager: Starting task 9.0 in stage 1.0 (TID 23, 10.1.2.176, partition 9, ANY, 5373 bytes)
17/01/29 15:27:24,303 INFO TaskSetManager: Starting task 11.0 in stage 1.0 (TID 24, 10.1.2.65, partition 11, ANY, 5373 bytes)
17/01/29 15:27:24,305 INFO TaskSetManager: Starting task 14.0 in stage 1.0 (TID 25, 10.1.2.28, partition 14, ANY, 5373 bytes)
17/01/29 15:27:24,306 INFO TaskSetManager: Starting task 16.0 in stage 1.0 (TID 26, 10.1.2.38, partition 16, ANY, 5373 bytes)
17/01/29 15:27:24,308 INFO TaskSetManager: Starting task 18.0 in stage 1.0 (TID 27, 10.1.2.191, partition 18, ANY, 5373 bytes)
17/01/29 15:27:24,309 INFO TaskSetManager: Starting task 21.0 in stage 1.0 (TID 28, 10.1.2.139, partition 21, ANY, 5373 bytes)
17/01/29 15:27:24,311 INFO TaskSetManager: Starting task 23.0 in stage 1.0 (TID 29, 10.1.2.66, partition 23, ANY, 5373 bytes)
17/01/29 15:27:24,313 INFO TaskSetManager: Starting task 25.0 in stage 1.0 (TID 30, 10.1.2.28, partition 25, ANY, 5373 bytes)
17/01/29 15:27:24,314 INFO TaskSetManager: Starting task 28.0 in stage 1.0 (TID 31, 10.1.2.38, partition 28, ANY, 5373 bytes)
17/01/29 15:27:24,316 INFO TaskSetManager: Starting task 30.0 in stage 1.0 (TID 32, 10.1.2.191, partition 30, ANY, 5373 bytes)
17/01/29 15:27:24,316 INFO CoarseGrainedSchedulerBackend$DriverEndpoint: Launching task 20 on executor id: 7 hostname: 10.1.2.139.
17/01/29 15:27:24,317 INFO CoarseGrainedSchedulerBackend$DriverEndpoint: Launching task 28 on executor id: 7 hostname: 10.1.2.139.
17/01/29 15:27:24,317 INFO CoarseGrainedSchedulerBackend$DriverEndpoint: Launching task 21 on executor id: 6 hostname: 10.1.2.224.
17/01/29 15:27:24,318 INFO CoarseGrainedSchedulerBackend$DriverEndpoint: Launching task 22 on executor id: 2 hostname: 10.1.2.66.
17/01/29 15:27:24,318 INFO CoarseGrainedSchedulerBackend$DriverEndpoint: Launching task 29 on executor id: 2 hostname: 10.1.2.66.
17/01/29 15:27:24,319 INFO CoarseGrainedSchedulerBackend$DriverEndpoint: Launching task 23 on executor id: 5 hostname: 10.1.2.176.
17/01/29 15:27:24,320 INFO CoarseGrainedSchedulerBackend$DriverEndpoint: Launching task 24 on executor id: 3 hostname: 10.1.2.65.
17/01/29 15:27:24,320 INFO CoarseGrainedSchedulerBackend$DriverEndpoint: Launching task 25 on executor id: 0 hostname: 10.1.2.28.
17/01/29 15:27:24,321 INFO CoarseGrainedSchedulerBackend$DriverEndpoint: Launching task 30 on executor id: 0 hostname: 10.1.2.28.
17/01/29 15:27:24,322 INFO CoarseGrainedSchedulerBackend$DriverEndpoint: Launching task 26 on executor id: 4 hostname: 10.1.2.38.
17/01/29 15:27:24,323 INFO CoarseGrainedSchedulerBackend$DriverEndpoint: Launching task 31 on executor id: 4 hostname: 10.1.2.38.
17/01/29 15:27:24,331 INFO CoarseGrainedSchedulerBackend$DriverEndpoint: Launching task 27 on executor id: 1 hostname: 10.1.2.191.
17/01/29 15:27:24,331 INFO CoarseGrainedSchedulerBackend$DriverEndpoint: Launching task 32 on executor id: 1 hostname: 10.1.2.191.
17/01/29 15:27:28,561 INFO BlockManagerInfo: Added rdd_5_13 in memory on 10.1.2.139:45024 (size: 44.4 MB, free: 2.0 GB)
17/01/29 15:27:28,640 INFO TaskSetManager: Finished task 13.0 in stage 1.0 (TID 9) in 7923 ms on 10.1.2.139 (2/32)
17/01/29 15:27:30,234 INFO BlockManagerInfo: Added rdd_5_31 in memory on 10.1.2.65:33751 (size: 44.3 MB, free: 2031.7 MB)
17/01/29 15:27:30,282 INFO TaskSetManager: Finished task 31.0 in stage 1.0 (TID 19) in 9539 ms on 10.1.2.65 (3/32)
17/01/29 15:27:30,547 INFO BlockManagerInfo: Added rdd_5_6 in memory on 10.1.2.65:33751 (size: 44.4 MB, free: 1987.4 MB)
17/01/29 15:27:30,575 INFO TaskSetManager: Finished task 6.0 in stage 1.0 (TID 8) in 9861 ms on 10.1.2.65 (4/32)
17/01/29 15:27:30,676 INFO BlockManagerInfo: Added rdd_5_2 in memory on 10.1.2.139:45024 (size: 44.4 MB, free: 2031.6 MB)
17/01/29 15:27:30,700 INFO TaskSetManager: Finished task 2.0 in stage 1.0 (TID 20) in 6407 ms on 10.1.2.139 (5/32)
17/01/29 15:27:30,739 INFO BlockManagerInfo: Added rdd_5_21 in memory on 10.1.2.139:45024 (size: 44.4 MB, free: 1987.3 MB)
17/01/29 15:27:30,770 INFO TaskSetManager: Finished task 21.0 in stage 1.0 (TID 28) in 6461 ms on 10.1.2.139 (6/32)
17/01/29 15:27:30,774 INFO BlockManagerInfo: Added rdd_5_20 in memory on 10.1.2.65:33751 (size: 44.4 MB, free: 1943.0 MB)
17/01/29 15:27:30,797 INFO TaskSetManager: Finished task 20.0 in stage 1.0 (TID 16) in 10060 ms on 10.1.2.65 (7/32)
17/01/29 15:27:31,289 INFO BlockManagerInfo: Added rdd_5_5 in memory on 10.1.2.28:44512 (size: 44.3 MB, free: 2.0 GB)
17/01/29 15:27:31,370 INFO TaskSetManager: Finished task 5.0 in stage 1.0 (TID 4) in 10669 ms on 10.1.2.28 (8/32)
17/01/29 15:27:31,599 INFO BlockManagerInfo: Added rdd_5_19 in memory on 10.1.2.28:44512 (size: 44.4 MB, free: 2031.6 MB)
17/01/29 15:27:31,628 INFO TaskSetManager: Finished task 19.0 in stage 1.0 (TID 12) in 10903 ms on 10.1.2.28 (9/32)
17/01/29 15:27:31,984 INFO BlockManagerInfo: Added rdd_5_12 in memory on 10.1.2.191:37586 (size: 44.4 MB, free: 2.0 GB)
17/01/29 15:27:32,064 INFO TaskSetManager: Finished task 12.0 in stage 1.0 (TID 7) in 11352 ms on 10.1.2.191 (10/32)
17/01/29 15:27:32,107 INFO BlockManagerInfo: Added rdd_5_11 in memory on 10.1.2.65:33751 (size: 44.4 MB, free: 1898.6 MB)
17/01/29 15:27:32,129 INFO TaskSetManager: Finished task 11.0 in stage 1.0 (TID 24) in 7827 ms on 10.1.2.65 (11/32)
17/01/29 15:27:32,169 INFO BlockManagerInfo: Added rdd_5_24 in memory on 10.1.2.191:37586 (size: 44.4 MB, free: 2031.6 MB)
17/01/29 15:27:32,189 INFO TaskSetManager: Finished task 24.0 in stage 1.0 (TID 15) in 11457 ms on 10.1.2.191 (12/32)
17/01/29 15:27:32,997 INFO BlockManagerInfo: Added rdd_5_26 in memory on 10.1.2.38:33985 (size: 44.4 MB, free: 2.0 GB)
17/01/29 15:27:33,069 INFO BlockManagerInfo: Added rdd_5_14 in memory on 10.1.2.28:44512 (size: 44.4 MB, free: 1987.2 MB)
17/01/29 15:27:33,077 INFO BlockManagerInfo: Added rdd_5_25 in memory on 10.1.2.28:44512 (size: 44.3 MB, free: 1942.9 MB)
17/01/29 15:27:33,097 INFO TaskSetManager: Finished task 14.0 in stage 1.0 (TID 25) in 8793 ms on 10.1.2.28 (13/32)
17/01/29 15:27:33,098 INFO TaskSetManager: Finished task 26.0 in stage 1.0 (TID 14) in 12368 ms on 10.1.2.38 (14/32)
17/01/29 15:27:33,100 INFO TaskSetManager: Finished task 25.0 in stage 1.0 (TID 30) in 8788 ms on 10.1.2.28 (15/32)
17/01/29 15:27:33,408 INFO BlockManagerInfo: Added rdd_5_30 in memory on 10.1.2.191:37586 (size: 44.4 MB, free: 1987.2 MB)
17/01/29 15:27:33,431 INFO TaskSetManager: Finished task 30.0 in stage 1.0 (TID 32) in 9117 ms on 10.1.2.191 (16/32)
17/01/29 15:27:33,699 INFO BlockManagerInfo: Added rdd_5_18 in memory on 10.1.2.191:37586 (size: 44.3 MB, free: 1942.9 MB)
17/01/29 15:27:33,721 INFO TaskSetManager: Finished task 18.0 in stage 1.0 (TID 27) in 9414 ms on 10.1.2.191 (17/32)
17/01/29 15:27:34,558 INFO BlockManagerInfo: Added rdd_5_28 in memory on 10.1.2.38:33985 (size: 44.4 MB, free: 2031.6 MB)
17/01/29 15:27:34,581 INFO TaskSetManager: Finished task 28.0 in stage 1.0 (TID 31) in 10267 ms on 10.1.2.38 (18/32)
17/01/29 15:27:34,617 INFO BlockManagerInfo: Added rdd_5_10 in memory on 10.1.2.224:33593 (size: 44.4 MB, free: 2.0 GB)
17/01/29 15:27:34,671 INFO BlockManagerInfo: Added rdd_5_29 in memory on 10.1.2.176:37793 (size: 44.4 MB, free: 2.0 GB)
17/01/29 15:27:34,684 INFO TaskSetManager: Finished task 10.0 in stage 1.0 (TID 10) in 13964 ms on 10.1.2.224 (19/32)
17/01/29 15:27:34,696 INFO BlockManagerInfo: Added rdd_5_17 in memory on 10.1.2.38:33985 (size: 44.4 MB, free: 1987.1 MB)
17/01/29 15:27:34,700 INFO BlockManagerInfo: Added rdd_5_1 in memory on 10.1.2.224:33593 (size: 44.4 MB, free: 2031.6 MB)
17/01/29 15:27:34,710 INFO BlockManagerInfo: Added rdd_5_3 in memory on 10.1.2.66:34001 (size: 44.4 MB, free: 2.0 GB)
17/01/29 15:27:34,715 INFO TaskSetManager: Finished task 17.0 in stage 1.0 (TID 6) in 14008 ms on 10.1.2.38 (20/32)
17/01/29 15:27:34,719 INFO TaskSetManager: Finished task 1.0 in stage 1.0 (TID 2) in 14021 ms on 10.1.2.224 (21/32)
17/01/29 15:27:34,775 INFO BlockManagerInfo: Added rdd_5_8 in memory on 10.1.2.176:37793 (size: 44.4 MB, free: 2031.6 MB)
17/01/29 15:27:34,780 INFO TaskSetManager: Finished task 3.0 in stage 1.0 (TID 5) in 14076 ms on 10.1.2.66 (22/32)
17/01/29 15:27:34,790 INFO TaskSetManager: Finished task 29.0 in stage 1.0 (TID 18) in 14051 ms on 10.1.2.176 (23/32)
17/01/29 15:27:34,801 INFO TaskSetManager: Finished task 8.0 in stage 1.0 (TID 3) in 14101 ms on 10.1.2.176 (24/32)
17/01/29 15:27:34,867 INFO BlockManagerInfo: Added rdd_5_15 in memory on 10.1.2.176:37793 (size: 44.4 MB, free: 1987.2 MB)
17/01/29 15:27:34,898 INFO TaskSetManager: Finished task 15.0 in stage 1.0 (TID 11) in 14177 ms on 10.1.2.176 (25/32)
17/01/29 15:27:34,939 INFO BlockManagerInfo: Added rdd_5_27 in memory on 10.1.2.224:33593 (size: 44.4 MB, free: 1987.2 MB)
17/01/29 15:27:34,957 INFO TaskSetManager: Finished task 27.0 in stage 1.0 (TID 17) in 14220 ms on 10.1.2.224 (26/32)
17/01/29 15:27:35,283 INFO BlockManagerInfo: Added rdd_5_16 in memory on 10.1.2.38:33985 (size: 44.4 MB, free: 1942.8 MB)
17/01/29 15:27:35,300 INFO TaskSetManager: Finished task 16.0 in stage 1.0 (TID 26) in 10995 ms on 10.1.2.38 (27/32)
17/01/29 15:27:35,588 INFO BlockManagerInfo: Added rdd_5_9 in memory on 10.1.2.176:37793 (size: 44.4 MB, free: 1942.8 MB)
17/01/29 15:27:35,607 INFO TaskSetManager: Finished task 9.0 in stage 1.0 (TID 23) in 11308 ms on 10.1.2.176 (28/32)
17/01/29 15:27:35,769 INFO BlockManagerInfo: Added rdd_5_4 in memory on 10.1.2.224:33593 (size: 44.4 MB, free: 1942.8 MB)
17/01/29 15:27:35,786 INFO TaskSetManager: Finished task 4.0 in stage 1.0 (TID 21) in 11491 ms on 10.1.2.224 (29/32)
17/01/29 15:27:36,296 INFO BlockManagerInfo: Added rdd_5_22 in memory on 10.1.2.66:34001 (size: 44.3 MB, free: 2031.7 MB)
17/01/29 15:27:36,319 INFO TaskSetManager: Finished task 22.0 in stage 1.0 (TID 13) in 15592 ms on 10.1.2.66 (30/32)
17/01/29 15:27:37,204 INFO BlockManagerInfo: Added rdd_5_7 in memory on 10.1.2.66:34001 (size: 44.4 MB, free: 1987.3 MB)
17/01/29 15:27:37,231 INFO TaskSetManager: Finished task 7.0 in stage 1.0 (TID 22) in 12934 ms on 10.1.2.66 (31/32)
17/01/29 15:27:37,567 INFO BlockManagerInfo: Added rdd_5_23 in memory on 10.1.2.66:34001 (size: 44.3 MB, free: 1943.0 MB)
17/01/29 15:27:37,586 INFO TaskSetManager: Finished task 23.0 in stage 1.0 (TID 29) in 13276 ms on 10.1.2.66 (32/32)
17/01/29 15:27:37,587 INFO TaskSchedulerImpl: Removed TaskSet 1.0, whose tasks have all completed, from pool 
17/01/29 15:27:37,588 INFO DAGScheduler: ResultStage 1 (count at DataValidators.scala:40) finished in 16.896 s
17/01/29 15:27:37,588 INFO DAGScheduler: Job 1 finished: count at DataValidators.scala:40, took 16.926312 s
17/01/29 15:27:37,598 INFO SparkContext: Starting job: count at GradientDescent.scala:209
17/01/29 15:27:37,600 INFO DAGScheduler: Got job 2 (count at GradientDescent.scala:209) with 32 output partitions
17/01/29 15:27:37,600 INFO DAGScheduler: Final stage: ResultStage 2 (count at GradientDescent.scala:209)
17/01/29 15:27:37,600 INFO DAGScheduler: Parents of final stage: List()
17/01/29 15:27:37,602 INFO DAGScheduler: Missing parents: List()
17/01/29 15:27:37,602 INFO DAGScheduler: Submitting ResultStage 2 (MapPartitionsRDD[8] at map at GeneralizedLinearAlgorithm.scala:297), which has no missing parents
17/01/29 15:27:37,607 INFO MemoryStore: Block broadcast_3 stored as values in memory (estimated size 3.9 KB, free 2.1 GB)
17/01/29 15:27:37,609 INFO MemoryStore: Block broadcast_3_piece0 stored as bytes in memory (estimated size 2.2 KB, free 2.1 GB)
17/01/29 15:27:37,609 INFO BlockManagerInfo: Added broadcast_3_piece0 in memory on 10.1.2.152:45830 (size: 2.2 KB, free: 2.1 GB)
17/01/29 15:27:37,610 INFO SparkContext: Created broadcast 3 from broadcast at DAGScheduler.scala:1012
17/01/29 15:27:37,611 INFO DAGScheduler: Submitting 32 missing tasks from ResultStage 2 (MapPartitionsRDD[8] at map at GeneralizedLinearAlgorithm.scala:297)
17/01/29 15:27:37,612 INFO TaskSchedulerImpl: Adding task set 2.0 with 32 tasks
17/01/29 15:27:37,615 INFO TaskSetManager: Starting task 2.0 in stage 2.0 (TID 33, 10.1.2.139, partition 2, PROCESS_LOCAL, 5373 bytes)
17/01/29 15:27:37,616 INFO TaskSetManager: Starting task 3.0 in stage 2.0 (TID 34, 10.1.2.66, partition 3, PROCESS_LOCAL, 5373 bytes)
17/01/29 15:27:37,617 INFO TaskSetManager: Starting task 5.0 in stage 2.0 (TID 35, 10.1.2.28, partition 5, PROCESS_LOCAL, 5373 bytes)
17/01/29 15:27:37,621 INFO TaskSetManager: Starting task 8.0 in stage 2.0 (TID 36, 10.1.2.176, partition 8, PROCESS_LOCAL, 5373 bytes)
17/01/29 15:27:37,623 INFO TaskSetManager: Starting task 12.0 in stage 2.0 (TID 37, 10.1.2.191, partition 12, PROCESS_LOCAL, 5373 bytes)
17/01/29 15:27:37,624 INFO TaskSetManager: Starting task 1.0 in stage 2.0 (TID 38, 10.1.2.224, partition 1, PROCESS_LOCAL, 5373 bytes)
17/01/29 15:27:37,625 INFO TaskSetManager: Starting task 0.0 in stage 2.0 (TID 39, 10.1.2.65, partition 0, PROCESS_LOCAL, 5373 bytes)
17/01/29 15:27:37,626 INFO TaskSetManager: Starting task 16.0 in stage 2.0 (TID 40, 10.1.2.38, partition 16, PROCESS_LOCAL, 5373 bytes)
17/01/29 15:27:37,627 INFO TaskSetManager: Starting task 13.0 in stage 2.0 (TID 41, 10.1.2.139, partition 13, PROCESS_LOCAL, 5373 bytes)
17/01/29 15:27:37,629 INFO TaskSetManager: Starting task 7.0 in stage 2.0 (TID 42, 10.1.2.66, partition 7, PROCESS_LOCAL, 5373 bytes)
17/01/29 15:27:37,630 INFO TaskSetManager: Starting task 14.0 in stage 2.0 (TID 43, 10.1.2.28, partition 14, PROCESS_LOCAL, 5373 bytes)
17/01/29 15:27:37,631 INFO TaskSetManager: Starting task 9.0 in stage 2.0 (TID 44, 10.1.2.176, partition 9, PROCESS_LOCAL, 5373 bytes)
17/01/29 15:27:37,633 INFO TaskSetManager: Starting task 18.0 in stage 2.0 (TID 45, 10.1.2.191, partition 18, PROCESS_LOCAL, 5373 bytes)
17/01/29 15:27:37,634 INFO TaskSetManager: Starting task 4.0 in stage 2.0 (TID 46, 10.1.2.224, partition 4, PROCESS_LOCAL, 5373 bytes)
17/01/29 15:27:37,636 INFO TaskSetManager: Starting task 6.0 in stage 2.0 (TID 47, 10.1.2.65, partition 6, PROCESS_LOCAL, 5373 bytes)
17/01/29 15:27:37,637 INFO TaskSetManager: Starting task 17.0 in stage 2.0 (TID 48, 10.1.2.38, partition 17, PROCESS_LOCAL, 5373 bytes)
17/01/29 15:27:37,639 INFO TaskSetManager: Starting task 21.0 in stage 2.0 (TID 49, 10.1.2.139, partition 21, PROCESS_LOCAL, 5373 bytes)
17/01/29 15:27:37,640 INFO TaskSetManager: Starting task 22.0 in stage 2.0 (TID 50, 10.1.2.66, partition 22, PROCESS_LOCAL, 5373 bytes)
17/01/29 15:27:37,642 INFO TaskSetManager: Starting task 19.0 in stage 2.0 (TID 51, 10.1.2.28, partition 19, PROCESS_LOCAL, 5373 bytes)
17/01/29 15:27:37,643 INFO TaskSetManager: Starting task 15.0 in stage 2.0 (TID 52, 10.1.2.176, partition 15, PROCESS_LOCAL, 5373 bytes)
17/01/29 15:27:37,644 INFO TaskSetManager: Starting task 24.0 in stage 2.0 (TID 53, 10.1.2.191, partition 24, PROCESS_LOCAL, 5373 bytes)
17/01/29 15:27:37,646 INFO TaskSetManager: Starting task 10.0 in stage 2.0 (TID 54, 10.1.2.224, partition 10, PROCESS_LOCAL, 5373 bytes)
17/01/29 15:27:37,647 INFO TaskSetManager: Starting task 11.0 in stage 2.0 (TID 55, 10.1.2.65, partition 11, PROCESS_LOCAL, 5373 bytes)
17/01/29 15:27:37,649 INFO TaskSetManager: Starting task 26.0 in stage 2.0 (TID 56, 10.1.2.38, partition 26, PROCESS_LOCAL, 5373 bytes)
17/01/29 15:27:37,650 INFO TaskSetManager: Starting task 23.0 in stage 2.0 (TID 57, 10.1.2.66, partition 23, PROCESS_LOCAL, 5373 bytes)
17/01/29 15:27:37,651 INFO TaskSetManager: Starting task 25.0 in stage 2.0 (TID 58, 10.1.2.28, partition 25, PROCESS_LOCAL, 5373 bytes)
17/01/29 15:27:37,653 INFO TaskSetManager: Starting task 29.0 in stage 2.0 (TID 59, 10.1.2.176, partition 29, PROCESS_LOCAL, 5373 bytes)
17/01/29 15:27:37,654 INFO TaskSetManager: Starting task 30.0 in stage 2.0 (TID 60, 10.1.2.191, partition 30, PROCESS_LOCAL, 5373 bytes)
17/01/29 15:27:37,656 INFO TaskSetManager: Starting task 27.0 in stage 2.0 (TID 61, 10.1.2.224, partition 27, PROCESS_LOCAL, 5373 bytes)
17/01/29 15:27:37,657 INFO TaskSetManager: Starting task 20.0 in stage 2.0 (TID 62, 10.1.2.65, partition 20, PROCESS_LOCAL, 5373 bytes)
17/01/29 15:27:37,658 INFO TaskSetManager: Starting task 28.0 in stage 2.0 (TID 63, 10.1.2.38, partition 28, PROCESS_LOCAL, 5373 bytes)
17/01/29 15:27:37,659 INFO CoarseGrainedSchedulerBackend$DriverEndpoint: Launching task 33 on executor id: 7 hostname: 10.1.2.139.
17/01/29 15:27:37,659 INFO CoarseGrainedSchedulerBackend$DriverEndpoint: Launching task 41 on executor id: 7 hostname: 10.1.2.139.
17/01/29 15:27:37,659 INFO CoarseGrainedSchedulerBackend$DriverEndpoint: Launching task 49 on executor id: 7 hostname: 10.1.2.139.
17/01/29 15:27:37,660 INFO CoarseGrainedSchedulerBackend$DriverEndpoint: Launching task 34 on executor id: 2 hostname: 10.1.2.66.
17/01/29 15:27:37,660 INFO CoarseGrainedSchedulerBackend$DriverEndpoint: Launching task 42 on executor id: 2 hostname: 10.1.2.66.
17/01/29 15:27:37,661 INFO CoarseGrainedSchedulerBackend$DriverEndpoint: Launching task 50 on executor id: 2 hostname: 10.1.2.66.
17/01/29 15:27:37,661 INFO CoarseGrainedSchedulerBackend$DriverEndpoint: Launching task 57 on executor id: 2 hostname: 10.1.2.66.
17/01/29 15:27:37,662 INFO CoarseGrainedSchedulerBackend$DriverEndpoint: Launching task 35 on executor id: 0 hostname: 10.1.2.28.
17/01/29 15:27:37,662 INFO CoarseGrainedSchedulerBackend$DriverEndpoint: Launching task 43 on executor id: 0 hostname: 10.1.2.28.
17/01/29 15:27:37,662 INFO CoarseGrainedSchedulerBackend$DriverEndpoint: Launching task 51 on executor id: 0 hostname: 10.1.2.28.
17/01/29 15:27:37,663 INFO CoarseGrainedSchedulerBackend$DriverEndpoint: Launching task 58 on executor id: 0 hostname: 10.1.2.28.
17/01/29 15:27:37,663 INFO CoarseGrainedSchedulerBackend$DriverEndpoint: Launching task 36 on executor id: 5 hostname: 10.1.2.176.
17/01/29 15:27:37,664 INFO CoarseGrainedSchedulerBackend$DriverEndpoint: Launching task 44 on executor id: 5 hostname: 10.1.2.176.
17/01/29 15:27:37,664 INFO CoarseGrainedSchedulerBackend$DriverEndpoint: Launching task 52 on executor id: 5 hostname: 10.1.2.176.
17/01/29 15:27:37,665 INFO CoarseGrainedSchedulerBackend$DriverEndpoint: Launching task 59 on executor id: 5 hostname: 10.1.2.176.
17/01/29 15:27:37,665 INFO CoarseGrainedSchedulerBackend$DriverEndpoint: Launching task 37 on executor id: 1 hostname: 10.1.2.191.
17/01/29 15:27:37,665 INFO CoarseGrainedSchedulerBackend$DriverEndpoint: Launching task 45 on executor id: 1 hostname: 10.1.2.191.
17/01/29 15:27:37,666 INFO CoarseGrainedSchedulerBackend$DriverEndpoint: Launching task 53 on executor id: 1 hostname: 10.1.2.191.
17/01/29 15:27:37,666 INFO CoarseGrainedSchedulerBackend$DriverEndpoint: Launching task 60 on executor id: 1 hostname: 10.1.2.191.
17/01/29 15:27:37,666 INFO CoarseGrainedSchedulerBackend$DriverEndpoint: Launching task 38 on executor id: 6 hostname: 10.1.2.224.
17/01/29 15:27:37,667 INFO CoarseGrainedSchedulerBackend$DriverEndpoint: Launching task 46 on executor id: 6 hostname: 10.1.2.224.
17/01/29 15:27:37,667 INFO CoarseGrainedSchedulerBackend$DriverEndpoint: Launching task 54 on executor id: 6 hostname: 10.1.2.224.
17/01/29 15:27:37,668 INFO CoarseGrainedSchedulerBackend$DriverEndpoint: Launching task 61 on executor id: 6 hostname: 10.1.2.224.
17/01/29 15:27:37,668 INFO CoarseGrainedSchedulerBackend$DriverEndpoint: Launching task 39 on executor id: 3 hostname: 10.1.2.65.
17/01/29 15:27:37,669 INFO CoarseGrainedSchedulerBackend$DriverEndpoint: Launching task 47 on executor id: 3 hostname: 10.1.2.65.
17/01/29 15:27:37,669 INFO CoarseGrainedSchedulerBackend$DriverEndpoint: Launching task 55 on executor id: 3 hostname: 10.1.2.65.
17/01/29 15:27:37,669 INFO CoarseGrainedSchedulerBackend$DriverEndpoint: Launching task 62 on executor id: 3 hostname: 10.1.2.65.
17/01/29 15:27:37,670 INFO CoarseGrainedSchedulerBackend$DriverEndpoint: Launching task 40 on executor id: 4 hostname: 10.1.2.38.
17/01/29 15:27:37,670 INFO CoarseGrainedSchedulerBackend$DriverEndpoint: Launching task 48 on executor id: 4 hostname: 10.1.2.38.
17/01/29 15:27:37,670 INFO CoarseGrainedSchedulerBackend$DriverEndpoint: Launching task 56 on executor id: 4 hostname: 10.1.2.38.
17/01/29 15:27:37,671 INFO CoarseGrainedSchedulerBackend$DriverEndpoint: Launching task 63 on executor id: 4 hostname: 10.1.2.38.
17/01/29 15:27:37,693 INFO BlockManagerInfo: Added broadcast_3_piece0 in memory on 10.1.2.176:37793 (size: 2.2 KB, free: 1942.8 MB)
17/01/29 15:27:37,695 INFO BlockManagerInfo: Added broadcast_3_piece0 in memory on 10.1.2.28:44512 (size: 2.2 KB, free: 1942.9 MB)
17/01/29 15:27:37,696 INFO BlockManagerInfo: Added broadcast_3_piece0 in memory on 10.1.2.224:33593 (size: 2.2 KB, free: 1942.8 MB)
17/01/29 15:27:37,697 INFO BlockManagerInfo: Added broadcast_3_piece0 in memory on 10.1.2.139:45024 (size: 2.2 KB, free: 1987.3 MB)
17/01/29 15:27:37,700 INFO BlockManagerInfo: Added broadcast_3_piece0 in memory on 10.1.2.65:33751 (size: 2.2 KB, free: 1898.6 MB)
17/01/29 15:27:37,701 INFO BlockManagerInfo: Added broadcast_3_piece0 in memory on 10.1.2.66:34001 (size: 2.2 KB, free: 1943.0 MB)
17/01/29 15:27:37,710 INFO BlockManagerInfo: Added broadcast_3_piece0 in memory on 10.1.2.191:37586 (size: 2.2 KB, free: 1942.9 MB)
17/01/29 15:27:37,739 INFO TaskSetManager: Finished task 9.0 in stage 2.0 (TID 44) in 109 ms on 10.1.2.176 (1/32)
17/01/29 15:27:37,740 INFO TaskSetManager: Finished task 15.0 in stage 2.0 (TID 52) in 98 ms on 10.1.2.176 (2/32)
17/01/29 15:27:37,745 INFO TaskSetManager: Finished task 3.0 in stage 2.0 (TID 34) in 130 ms on 10.1.2.66 (3/32)
17/01/29 15:27:37,747 INFO TaskSetManager: Finished task 25.0 in stage 2.0 (TID 58) in 96 ms on 10.1.2.28 (4/32)
17/01/29 15:27:37,747 INFO TaskSetManager: Finished task 13.0 in stage 2.0 (TID 41) in 121 ms on 10.1.2.139 (5/32)
17/01/29 15:27:37,748 INFO TaskSetManager: Finished task 5.0 in stage 2.0 (TID 35) in 132 ms on 10.1.2.28 (6/32)
17/01/29 15:27:37,749 INFO TaskSetManager: Finished task 21.0 in stage 2.0 (TID 49) in 111 ms on 10.1.2.139 (7/32)
17/01/29 15:27:37,750 INFO TaskSetManager: Finished task 19.0 in stage 2.0 (TID 51) in 110 ms on 10.1.2.28 (8/32)
17/01/29 15:27:37,751 INFO TaskSetManager: Starting task 31.0 in stage 2.0 (TID 64, 10.1.2.65, partition 31, PROCESS_LOCAL, 5373 bytes)
17/01/29 15:27:37,752 INFO CoarseGrainedSchedulerBackend$DriverEndpoint: Launching task 64 on executor id: 3 hostname: 10.1.2.65.
17/01/29 15:27:37,752 INFO TaskSetManager: Finished task 11.0 in stage 2.0 (TID 55) in 106 ms on 10.1.2.65 (9/32)
17/01/29 15:27:37,753 INFO TaskSetManager: Finished task 6.0 in stage 2.0 (TID 47) in 118 ms on 10.1.2.65 (10/32)
17/01/29 15:27:37,754 INFO TaskSetManager: Finished task 20.0 in stage 2.0 (TID 62) in 97 ms on 10.1.2.65 (11/32)
17/01/29 15:27:37,757 INFO TaskSetManager: Finished task 27.0 in stage 2.0 (TID 61) in 103 ms on 10.1.2.224 (12/32)
17/01/29 15:27:37,757 INFO TaskSetManager: Finished task 1.0 in stage 2.0 (TID 38) in 134 ms on 10.1.2.224 (13/32)
17/01/29 15:27:37,759 INFO TaskSetManager: Finished task 18.0 in stage 2.0 (TID 45) in 127 ms on 10.1.2.191 (14/32)
17/01/29 15:27:37,760 INFO TaskSetManager: Finished task 30.0 in stage 2.0 (TID 60) in 107 ms on 10.1.2.191 (15/32)
17/01/29 15:27:37,761 INFO TaskSetManager: Finished task 23.0 in stage 2.0 (TID 57) in 112 ms on 10.1.2.66 (16/32)
17/01/29 15:27:37,762 INFO TaskSetManager: Finished task 29.0 in stage 2.0 (TID 59) in 110 ms on 10.1.2.176 (17/32)
17/01/29 15:27:37,762 INFO TaskSetManager: Finished task 0.0 in stage 2.0 (TID 39) in 138 ms on 10.1.2.65 (18/32)
17/01/29 15:27:37,766 INFO TaskSetManager: Finished task 7.0 in stage 2.0 (TID 42) in 137 ms on 10.1.2.66 (19/32)
17/01/29 15:27:37,772 INFO BlockManagerInfo: Added broadcast_3_piece0 in memory on 10.1.2.38:33985 (size: 2.2 KB, free: 1942.8 MB)
17/01/29 15:27:37,783 INFO TaskSetManager: Finished task 31.0 in stage 2.0 (TID 64) in 33 ms on 10.1.2.65 (20/32)
17/01/29 15:27:37,786 INFO TaskSetManager: Finished task 24.0 in stage 2.0 (TID 53) in 143 ms on 10.1.2.191 (21/32)
17/01/29 15:27:37,801 INFO TaskSetManager: Finished task 14.0 in stage 2.0 (TID 43) in 172 ms on 10.1.2.28 (22/32)
17/01/29 15:27:37,806 INFO TaskSetManager: Finished task 4.0 in stage 2.0 (TID 46) in 173 ms on 10.1.2.224 (23/32)
17/01/29 15:27:37,807 INFO TaskSetManager: Finished task 8.0 in stage 2.0 (TID 36) in 190 ms on 10.1.2.176 (24/32)
17/01/29 15:27:37,817 INFO TaskSetManager: Finished task 22.0 in stage 2.0 (TID 50) in 178 ms on 10.1.2.66 (25/32)
17/01/29 15:27:37,820 INFO TaskSetManager: Finished task 26.0 in stage 2.0 (TID 56) in 173 ms on 10.1.2.38 (26/32)
17/01/29 15:27:37,821 INFO TaskSetManager: Finished task 28.0 in stage 2.0 (TID 63) in 164 ms on 10.1.2.38 (27/32)
17/01/29 15:27:37,823 INFO TaskSetManager: Finished task 10.0 in stage 2.0 (TID 54) in 178 ms on 10.1.2.224 (28/32)
17/01/29 15:27:37,828 INFO TaskSetManager: Finished task 17.0 in stage 2.0 (TID 48) in 192 ms on 10.1.2.38 (29/32)
17/01/29 15:27:37,831 INFO TaskSetManager: Finished task 16.0 in stage 2.0 (TID 40) in 206 ms on 10.1.2.38 (30/32)
17/01/29 15:27:37,848 INFO TaskSetManager: Finished task 12.0 in stage 2.0 (TID 37) in 225 ms on 10.1.2.191 (31/32)
17/01/29 15:27:37,861 INFO TaskSetManager: Finished task 2.0 in stage 2.0 (TID 33) in 248 ms on 10.1.2.139 (32/32)
17/01/29 15:27:37,861 INFO TaskSchedulerImpl: Removed TaskSet 2.0, whose tasks have all completed, from pool 
17/01/29 15:27:37,862 INFO DAGScheduler: ResultStage 2 (count at GradientDescent.scala:209) finished in 0.249 s
17/01/29 15:27:37,862 INFO DAGScheduler: Job 2 finished: count at GradientDescent.scala:209, took 0.263928 s
17/01/29 15:27:38,097 WARN BLAS: Failed to load implementation from: com.github.fommil.netlib.NativeSystemBLAS
17/01/29 15:27:38,097 WARN BLAS: Failed to load implementation from: com.github.fommil.netlib.NativeRefBLAS
17/01/29 15:27:38,121 INFO MemoryStore: Block broadcast_4 stored as values in memory (estimated size 200.0 B, free 2.1 GB)
17/01/29 15:27:38,124 INFO MemoryStore: Block broadcast_4_piece0 stored as bytes in memory (estimated size 153.0 B, free 2.1 GB)
17/01/29 15:27:38,126 INFO BlockManagerInfo: Added broadcast_4_piece0 in memory on 10.1.2.152:45830 (size: 153.0 B, free: 2.1 GB)
17/01/29 15:27:38,127 INFO SparkContext: Created broadcast 4 from broadcast at GradientDescent.scala:235
17/01/29 15:27:38,176 INFO SparkContext: Starting job: treeAggregate at GradientDescent.scala:239
17/01/29 15:27:38,182 INFO DAGScheduler: Registering RDD 11 (treeAggregate at GradientDescent.scala:239)
17/01/29 15:27:38,183 INFO DAGScheduler: Got job 3 (treeAggregate at GradientDescent.scala:239) with 5 output partitions
17/01/29 15:27:38,183 INFO DAGScheduler: Final stage: ResultStage 4 (treeAggregate at GradientDescent.scala:239)
17/01/29 15:27:38,183 INFO DAGScheduler: Parents of final stage: List(ShuffleMapStage 3)
17/01/29 15:27:38,183 INFO DAGScheduler: Missing parents: List(ShuffleMapStage 3)
17/01/29 15:27:38,186 INFO DAGScheduler: Submitting ShuffleMapStage 3 (MapPartitionsRDD[11] at treeAggregate at GradientDescent.scala:239), which has no missing parents
17/01/29 15:27:38,200 INFO MemoryStore: Block broadcast_5 stored as values in memory (estimated size 7.1 KB, free 2.1 GB)
17/01/29 15:27:38,201 INFO MemoryStore: Block broadcast_5_piece0 stored as bytes in memory (estimated size 3.7 KB, free 2.1 GB)
17/01/29 15:27:38,202 INFO BlockManagerInfo: Added broadcast_5_piece0 in memory on 10.1.2.152:45830 (size: 3.7 KB, free: 2.1 GB)
17/01/29 15:27:38,203 INFO SparkContext: Created broadcast 5 from broadcast at DAGScheduler.scala:1012
17/01/29 15:27:38,204 INFO DAGScheduler: Submitting 32 missing tasks from ShuffleMapStage 3 (MapPartitionsRDD[11] at treeAggregate at GradientDescent.scala:239)
17/01/29 15:27:38,205 INFO TaskSchedulerImpl: Adding task set 3.0 with 32 tasks
17/01/29 15:27:38,208 INFO TaskSetManager: Starting task 2.0 in stage 3.0 (TID 65, 10.1.2.139, partition 2, PROCESS_LOCAL, 5562 bytes)
17/01/29 15:27:38,209 INFO TaskSetManager: Starting task 5.0 in stage 3.0 (TID 66, 10.1.2.28, partition 5, PROCESS_LOCAL, 5562 bytes)
17/01/29 15:27:38,210 INFO TaskSetManager: Starting task 1.0 in stage 3.0 (TID 67, 10.1.2.224, partition 1, PROCESS_LOCAL, 5562 bytes)
17/01/29 15:27:38,211 INFO TaskSetManager: Starting task 3.0 in stage 3.0 (TID 68, 10.1.2.66, partition 3, PROCESS_LOCAL, 5562 bytes)
17/01/29 15:27:38,211 INFO TaskSetManager: Starting task 16.0 in stage 3.0 (TID 69, 10.1.2.38, partition 16, PROCESS_LOCAL, 5562 bytes)
17/01/29 15:27:38,212 INFO TaskSetManager: Starting task 8.0 in stage 3.0 (TID 70, 10.1.2.176, partition 8, PROCESS_LOCAL, 5562 bytes)
17/01/29 15:27:38,213 INFO TaskSetManager: Starting task 12.0 in stage 3.0 (TID 71, 10.1.2.191, partition 12, PROCESS_LOCAL, 5562 bytes)
17/01/29 15:27:38,213 INFO TaskSetManager: Starting task 0.0 in stage 3.0 (TID 72, 10.1.2.65, partition 0, PROCESS_LOCAL, 5562 bytes)
17/01/29 15:27:38,214 INFO TaskSetManager: Starting task 13.0 in stage 3.0 (TID 73, 10.1.2.139, partition 13, PROCESS_LOCAL, 5562 bytes)
17/01/29 15:27:38,215 INFO TaskSetManager: Starting task 14.0 in stage 3.0 (TID 74, 10.1.2.28, partition 14, PROCESS_LOCAL, 5562 bytes)
17/01/29 15:27:38,216 INFO TaskSetManager: Starting task 4.0 in stage 3.0 (TID 75, 10.1.2.224, partition 4, PROCESS_LOCAL, 5562 bytes)
17/01/29 15:27:38,216 INFO TaskSetManager: Starting task 7.0 in stage 3.0 (TID 76, 10.1.2.66, partition 7, PROCESS_LOCAL, 5562 bytes)
17/01/29 15:27:38,217 INFO TaskSetManager: Starting task 17.0 in stage 3.0 (TID 77, 10.1.2.38, partition 17, PROCESS_LOCAL, 5562 bytes)
17/01/29 15:27:38,218 INFO TaskSetManager: Starting task 9.0 in stage 3.0 (TID 78, 10.1.2.176, partition 9, PROCESS_LOCAL, 5562 bytes)
17/01/29 15:27:38,218 INFO TaskSetManager: Starting task 18.0 in stage 3.0 (TID 79, 10.1.2.191, partition 18, PROCESS_LOCAL, 5562 bytes)
17/01/29 15:27:38,219 INFO TaskSetManager: Starting task 6.0 in stage 3.0 (TID 80, 10.1.2.65, partition 6, PROCESS_LOCAL, 5562 bytes)
17/01/29 15:27:38,220 INFO TaskSetManager: Starting task 21.0 in stage 3.0 (TID 81, 10.1.2.139, partition 21, PROCESS_LOCAL, 5562 bytes)
17/01/29 15:27:38,221 INFO TaskSetManager: Starting task 19.0 in stage 3.0 (TID 82, 10.1.2.28, partition 19, PROCESS_LOCAL, 5562 bytes)
17/01/29 15:27:38,221 INFO TaskSetManager: Starting task 10.0 in stage 3.0 (TID 83, 10.1.2.224, partition 10, PROCESS_LOCAL, 5562 bytes)
17/01/29 15:27:38,222 INFO TaskSetManager: Starting task 22.0 in stage 3.0 (TID 84, 10.1.2.66, partition 22, PROCESS_LOCAL, 5562 bytes)
17/01/29 15:27:38,223 INFO TaskSetManager: Starting task 26.0 in stage 3.0 (TID 85, 10.1.2.38, partition 26, PROCESS_LOCAL, 5562 bytes)
17/01/29 15:27:38,223 INFO TaskSetManager: Starting task 15.0 in stage 3.0 (TID 86, 10.1.2.176, partition 15, PROCESS_LOCAL, 5562 bytes)
17/01/29 15:27:38,224 INFO TaskSetManager: Starting task 24.0 in stage 3.0 (TID 87, 10.1.2.191, partition 24, PROCESS_LOCAL, 5562 bytes)
17/01/29 15:27:38,225 INFO TaskSetManager: Starting task 11.0 in stage 3.0 (TID 88, 10.1.2.65, partition 11, PROCESS_LOCAL, 5562 bytes)
17/01/29 15:27:38,225 INFO TaskSetManager: Starting task 25.0 in stage 3.0 (TID 89, 10.1.2.28, partition 25, PROCESS_LOCAL, 5562 bytes)
17/01/29 15:27:38,226 INFO TaskSetManager: Starting task 27.0 in stage 3.0 (TID 90, 10.1.2.224, partition 27, PROCESS_LOCAL, 5562 bytes)
17/01/29 15:27:38,227 INFO TaskSetManager: Starting task 23.0 in stage 3.0 (TID 91, 10.1.2.66, partition 23, PROCESS_LOCAL, 5562 bytes)
17/01/29 15:27:38,227 INFO TaskSetManager: Starting task 28.0 in stage 3.0 (TID 92, 10.1.2.38, partition 28, PROCESS_LOCAL, 5562 bytes)
17/01/29 15:27:38,228 INFO TaskSetManager: Starting task 29.0 in stage 3.0 (TID 93, 10.1.2.176, partition 29, PROCESS_LOCAL, 5562 bytes)
17/01/29 15:27:38,229 INFO TaskSetManager: Starting task 30.0 in stage 3.0 (TID 94, 10.1.2.191, partition 30, PROCESS_LOCAL, 5562 bytes)
17/01/29 15:27:38,229 INFO TaskSetManager: Starting task 20.0 in stage 3.0 (TID 95, 10.1.2.65, partition 20, PROCESS_LOCAL, 5562 bytes)
17/01/29 15:27:38,230 INFO CoarseGrainedSchedulerBackend$DriverEndpoint: Launching task 65 on executor id: 7 hostname: 10.1.2.139.
17/01/29 15:27:38,231 INFO CoarseGrainedSchedulerBackend$DriverEndpoint: Launching task 73 on executor id: 7 hostname: 10.1.2.139.
17/01/29 15:27:38,231 INFO CoarseGrainedSchedulerBackend$DriverEndpoint: Launching task 81 on executor id: 7 hostname: 10.1.2.139.
17/01/29 15:27:38,232 INFO CoarseGrainedSchedulerBackend$DriverEndpoint: Launching task 66 on executor id: 0 hostname: 10.1.2.28.
17/01/29 15:27:38,232 INFO CoarseGrainedSchedulerBackend$DriverEndpoint: Launching task 74 on executor id: 0 hostname: 10.1.2.28.
17/01/29 15:27:38,232 INFO CoarseGrainedSchedulerBackend$DriverEndpoint: Launching task 82 on executor id: 0 hostname: 10.1.2.28.
17/01/29 15:27:38,233 INFO CoarseGrainedSchedulerBackend$DriverEndpoint: Launching task 89 on executor id: 0 hostname: 10.1.2.28.
17/01/29 15:27:38,233 INFO CoarseGrainedSchedulerBackend$DriverEndpoint: Launching task 67 on executor id: 6 hostname: 10.1.2.224.
17/01/29 15:27:38,234 INFO CoarseGrainedSchedulerBackend$DriverEndpoint: Launching task 75 on executor id: 6 hostname: 10.1.2.224.
17/01/29 15:27:38,234 INFO CoarseGrainedSchedulerBackend$DriverEndpoint: Launching task 83 on executor id: 6 hostname: 10.1.2.224.
17/01/29 15:27:38,235 INFO CoarseGrainedSchedulerBackend$DriverEndpoint: Launching task 90 on executor id: 6 hostname: 10.1.2.224.
17/01/29 15:27:38,235 INFO CoarseGrainedSchedulerBackend$DriverEndpoint: Launching task 68 on executor id: 2 hostname: 10.1.2.66.
17/01/29 15:27:38,235 INFO CoarseGrainedSchedulerBackend$DriverEndpoint: Launching task 76 on executor id: 2 hostname: 10.1.2.66.
17/01/29 15:27:38,236 INFO CoarseGrainedSchedulerBackend$DriverEndpoint: Launching task 84 on executor id: 2 hostname: 10.1.2.66.
17/01/29 15:27:38,236 INFO CoarseGrainedSchedulerBackend$DriverEndpoint: Launching task 91 on executor id: 2 hostname: 10.1.2.66.
17/01/29 15:27:38,236 INFO CoarseGrainedSchedulerBackend$DriverEndpoint: Launching task 69 on executor id: 4 hostname: 10.1.2.38.
17/01/29 15:27:38,237 INFO CoarseGrainedSchedulerBackend$DriverEndpoint: Launching task 77 on executor id: 4 hostname: 10.1.2.38.
17/01/29 15:27:38,237 INFO CoarseGrainedSchedulerBackend$DriverEndpoint: Launching task 85 on executor id: 4 hostname: 10.1.2.38.
17/01/29 15:27:38,237 INFO CoarseGrainedSchedulerBackend$DriverEndpoint: Launching task 92 on executor id: 4 hostname: 10.1.2.38.
17/01/29 15:27:38,237 INFO CoarseGrainedSchedulerBackend$DriverEndpoint: Launching task 70 on executor id: 5 hostname: 10.1.2.176.
17/01/29 15:27:38,238 INFO CoarseGrainedSchedulerBackend$DriverEndpoint: Launching task 78 on executor id: 5 hostname: 10.1.2.176.
17/01/29 15:27:38,238 INFO CoarseGrainedSchedulerBackend$DriverEndpoint: Launching task 86 on executor id: 5 hostname: 10.1.2.176.
17/01/29 15:27:38,238 INFO CoarseGrainedSchedulerBackend$DriverEndpoint: Launching task 93 on executor id: 5 hostname: 10.1.2.176.
17/01/29 15:27:38,238 INFO CoarseGrainedSchedulerBackend$DriverEndpoint: Launching task 71 on executor id: 1 hostname: 10.1.2.191.
17/01/29 15:27:38,239 INFO CoarseGrainedSchedulerBackend$DriverEndpoint: Launching task 79 on executor id: 1 hostname: 10.1.2.191.
17/01/29 15:27:38,239 INFO CoarseGrainedSchedulerBackend$DriverEndpoint: Launching task 87 on executor id: 1 hostname: 10.1.2.191.
17/01/29 15:27:38,240 INFO CoarseGrainedSchedulerBackend$DriverEndpoint: Launching task 94 on executor id: 1 hostname: 10.1.2.191.
17/01/29 15:27:38,240 INFO CoarseGrainedSchedulerBackend$DriverEndpoint: Launching task 72 on executor id: 3 hostname: 10.1.2.65.
17/01/29 15:27:38,242 INFO CoarseGrainedSchedulerBackend$DriverEndpoint: Launching task 80 on executor id: 3 hostname: 10.1.2.65.
17/01/29 15:27:38,243 INFO CoarseGrainedSchedulerBackend$DriverEndpoint: Launching task 88 on executor id: 3 hostname: 10.1.2.65.
17/01/29 15:27:38,243 INFO CoarseGrainedSchedulerBackend$DriverEndpoint: Launching task 95 on executor id: 3 hostname: 10.1.2.65.
17/01/29 15:27:38,260 INFO BlockManagerInfo: Added broadcast_5_piece0 in memory on 10.1.2.139:45024 (size: 3.7 KB, free: 1987.3 MB)
17/01/29 15:27:38,262 INFO BlockManagerInfo: Added broadcast_5_piece0 in memory on 10.1.2.38:33985 (size: 3.7 KB, free: 1942.7 MB)
17/01/29 15:27:38,263 INFO BlockManagerInfo: Added broadcast_5_piece0 in memory on 10.1.2.224:33593 (size: 3.7 KB, free: 1942.8 MB)
17/01/29 15:27:38,264 INFO BlockManagerInfo: Added broadcast_5_piece0 in memory on 10.1.2.66:34001 (size: 3.7 KB, free: 1943.0 MB)
17/01/29 15:27:38,264 INFO BlockManagerInfo: Added broadcast_5_piece0 in memory on 10.1.2.28:44512 (size: 3.7 KB, free: 1942.9 MB)
17/01/29 15:27:38,266 INFO BlockManagerInfo: Added broadcast_5_piece0 in memory on 10.1.2.176:37793 (size: 3.7 KB, free: 1942.8 MB)
17/01/29 15:27:38,267 INFO BlockManagerInfo: Added broadcast_5_piece0 in memory on 10.1.2.65:33751 (size: 3.7 KB, free: 1898.6 MB)
17/01/29 15:27:38,270 INFO BlockManagerInfo: Added broadcast_5_piece0 in memory on 10.1.2.191:37586 (size: 3.7 KB, free: 1942.8 MB)
17/01/29 15:27:38,544 INFO BlockManagerInfo: Added broadcast_4_piece0 in memory on 10.1.2.224:33593 (size: 153.0 B, free: 1942.8 MB)
17/01/29 15:27:38,547 INFO BlockManagerInfo: Added broadcast_4_piece0 in memory on 10.1.2.38:33985 (size: 153.0 B, free: 1942.7 MB)
17/01/29 15:27:38,554 INFO BlockManagerInfo: Added broadcast_4_piece0 in memory on 10.1.2.65:33751 (size: 153.0 B, free: 1898.6 MB)
17/01/29 15:27:38,577 INFO BlockManagerInfo: Added broadcast_4_piece0 in memory on 10.1.2.66:34001 (size: 153.0 B, free: 1943.0 MB)
17/01/29 15:27:38,578 INFO BlockManagerInfo: Added broadcast_4_piece0 in memory on 10.1.2.139:45024 (size: 153.0 B, free: 1987.3 MB)
17/01/29 15:27:38,590 INFO BlockManagerInfo: Added broadcast_4_piece0 in memory on 10.1.2.176:37793 (size: 153.0 B, free: 1942.8 MB)
17/01/29 15:27:38,615 INFO BlockManagerInfo: Added broadcast_4_piece0 in memory on 10.1.2.191:37586 (size: 153.0 B, free: 1942.8 MB)
17/01/29 15:27:38,628 INFO BlockManagerInfo: Added broadcast_4_piece0 in memory on 10.1.2.28:44512 (size: 153.0 B, free: 1942.9 MB)
17/01/29 15:27:38,708 INFO TaskSetManager: Finished task 10.0 in stage 3.0 (TID 83) in 487 ms on 10.1.2.224 (1/32)
17/01/29 15:27:38,710 INFO TaskSetManager: Finished task 26.0 in stage 3.0 (TID 85) in 488 ms on 10.1.2.38 (2/32)
17/01/29 15:27:38,710 INFO TaskSetManager: Finished task 27.0 in stage 3.0 (TID 90) in 484 ms on 10.1.2.224 (3/32)
17/01/29 15:27:38,711 INFO TaskSetManager: Finished task 1.0 in stage 3.0 (TID 67) in 502 ms on 10.1.2.224 (4/32)
17/01/29 15:27:38,712 INFO TaskSetManager: Finished task 17.0 in stage 3.0 (TID 77) in 496 ms on 10.1.2.38 (5/32)
17/01/29 15:27:38,713 INFO TaskSetManager: Finished task 4.0 in stage 3.0 (TID 75) in 498 ms on 10.1.2.224 (6/32)
17/01/29 15:27:38,714 INFO TaskSetManager: Finished task 28.0 in stage 3.0 (TID 92) in 487 ms on 10.1.2.38 (7/32)
17/01/29 15:27:38,715 INFO TaskSetManager: Finished task 16.0 in stage 3.0 (TID 69) in 504 ms on 10.1.2.38 (8/32)
17/01/29 15:27:38,719 INFO TaskSetManager: Starting task 31.0 in stage 3.0 (TID 96, 10.1.2.65, partition 31, PROCESS_LOCAL, 5562 bytes)
17/01/29 15:27:38,719 INFO CoarseGrainedSchedulerBackend$DriverEndpoint: Launching task 96 on executor id: 3 hostname: 10.1.2.65.
17/01/29 15:27:38,721 INFO TaskSetManager: Finished task 0.0 in stage 3.0 (TID 72) in 507 ms on 10.1.2.65 (9/32)
17/01/29 15:27:38,721 INFO TaskSetManager: Finished task 11.0 in stage 3.0 (TID 88) in 497 ms on 10.1.2.65 (10/32)
17/01/29 15:27:38,722 INFO TaskSetManager: Finished task 20.0 in stage 3.0 (TID 95) in 492 ms on 10.1.2.65 (11/32)
17/01/29 15:27:38,726 INFO TaskSetManager: Finished task 6.0 in stage 3.0 (TID 80) in 507 ms on 10.1.2.65 (12/32)
17/01/29 15:27:38,742 INFO TaskSetManager: Finished task 2.0 in stage 3.0 (TID 65) in 536 ms on 10.1.2.139 (13/32)
17/01/29 15:27:38,743 INFO TaskSetManager: Finished task 21.0 in stage 3.0 (TID 81) in 524 ms on 10.1.2.139 (14/32)
17/01/29 15:27:38,744 INFO TaskSetManager: Finished task 13.0 in stage 3.0 (TID 73) in 530 ms on 10.1.2.139 (15/32)
17/01/29 15:27:38,761 INFO TaskSetManager: Finished task 8.0 in stage 3.0 (TID 70) in 550 ms on 10.1.2.176 (16/32)
17/01/29 15:27:38,762 INFO TaskSetManager: Finished task 9.0 in stage 3.0 (TID 78) in 545 ms on 10.1.2.176 (17/32)
17/01/29 15:27:38,764 INFO TaskSetManager: Finished task 15.0 in stage 3.0 (TID 86) in 541 ms on 10.1.2.176 (18/32)
17/01/29 15:27:38,766 INFO TaskSetManager: Finished task 29.0 in stage 3.0 (TID 93) in 538 ms on 10.1.2.176 (19/32)
17/01/29 15:27:38,782 INFO TaskSetManager: Finished task 3.0 in stage 3.0 (TID 68) in 571 ms on 10.1.2.66 (20/32)
17/01/29 15:27:38,783 INFO TaskSetManager: Finished task 23.0 in stage 3.0 (TID 91) in 557 ms on 10.1.2.66 (21/32)
17/01/29 15:27:38,785 INFO TaskSetManager: Finished task 7.0 in stage 3.0 (TID 76) in 569 ms on 10.1.2.66 (22/32)
17/01/29 15:27:38,785 INFO TaskSetManager: Finished task 31.0 in stage 3.0 (TID 96) in 66 ms on 10.1.2.65 (23/32)
17/01/29 15:27:38,786 INFO TaskSetManager: Finished task 22.0 in stage 3.0 (TID 84) in 565 ms on 10.1.2.66 (24/32)
17/01/29 15:27:38,797 INFO TaskSetManager: Finished task 24.0 in stage 3.0 (TID 87) in 574 ms on 10.1.2.191 (25/32)
17/01/29 15:27:38,797 INFO TaskSetManager: Finished task 12.0 in stage 3.0 (TID 71) in 585 ms on 10.1.2.191 (26/32)
17/01/29 15:27:38,799 INFO TaskSetManager: Finished task 30.0 in stage 3.0 (TID 94) in 571 ms on 10.1.2.191 (27/32)
17/01/29 15:27:38,801 INFO TaskSetManager: Finished task 18.0 in stage 3.0 (TID 79) in 582 ms on 10.1.2.191 (28/32)
17/01/29 15:27:38,803 INFO TaskSetManager: Finished task 25.0 in stage 3.0 (TID 89) in 577 ms on 10.1.2.28 (29/32)
17/01/29 15:27:38,803 INFO TaskSetManager: Finished task 5.0 in stage 3.0 (TID 66) in 595 ms on 10.1.2.28 (30/32)
17/01/29 15:27:38,805 INFO TaskSetManager: Finished task 14.0 in stage 3.0 (TID 74) in 591 ms on 10.1.2.28 (31/32)
17/01/29 15:27:38,806 INFO TaskSetManager: Finished task 19.0 in stage 3.0 (TID 82) in 586 ms on 10.1.2.28 (32/32)
17/01/29 15:27:38,806 INFO TaskSchedulerImpl: Removed TaskSet 3.0, whose tasks have all completed, from pool 
17/01/29 15:27:38,807 INFO DAGScheduler: ShuffleMapStage 3 (treeAggregate at GradientDescent.scala:239) finished in 0.601 s
17/01/29 15:27:38,808 INFO DAGScheduler: looking for newly runnable stages
17/01/29 15:27:38,808 INFO DAGScheduler: running: Set()
17/01/29 15:27:38,809 INFO DAGScheduler: waiting: Set(ResultStage 4)
17/01/29 15:27:38,809 INFO DAGScheduler: failed: Set()
17/01/29 15:27:38,811 INFO DAGScheduler: Submitting ResultStage 4 (MapPartitionsRDD[13] at treeAggregate at GradientDescent.scala:239), which has no missing parents
17/01/29 15:27:38,816 INFO MemoryStore: Block broadcast_6 stored as values in memory (estimated size 3.1 KB, free 2.1 GB)
17/01/29 15:27:38,818 INFO MemoryStore: Block broadcast_6_piece0 stored as bytes in memory (estimated size 1890.0 B, free 2.1 GB)
17/01/29 15:27:38,818 INFO BlockManagerInfo: Added broadcast_6_piece0 in memory on 10.1.2.152:45830 (size: 1890.0 B, free: 2.1 GB)
17/01/29 15:27:38,819 INFO SparkContext: Created broadcast 6 from broadcast at DAGScheduler.scala:1012
17/01/29 15:27:38,820 INFO DAGScheduler: Submitting 5 missing tasks from ResultStage 4 (MapPartitionsRDD[13] at treeAggregate at GradientDescent.scala:239)
17/01/29 15:27:38,820 INFO TaskSchedulerImpl: Adding task set 4.0 with 5 tasks
17/01/29 15:27:38,822 INFO TaskSetManager: Starting task 4.0 in stage 4.0 (TID 97, 10.1.2.176, partition 4, NODE_LOCAL, 5228 bytes)
17/01/29 15:27:38,822 INFO TaskSetManager: Starting task 1.0 in stage 4.0 (TID 98, 10.1.2.38, partition 1, NODE_LOCAL, 5228 bytes)
17/01/29 15:27:38,823 INFO TaskSetManager: Starting task 0.0 in stage 4.0 (TID 99, 10.1.2.65, partition 0, NODE_LOCAL, 5228 bytes)
17/01/29 15:27:38,823 INFO TaskSetManager: Starting task 2.0 in stage 4.0 (TID 100, 10.1.2.66, partition 2, NODE_LOCAL, 5228 bytes)
17/01/29 15:27:38,824 INFO TaskSetManager: Starting task 3.0 in stage 4.0 (TID 101, 10.1.2.66, partition 3, NODE_LOCAL, 5228 bytes)
17/01/29 15:27:38,825 INFO CoarseGrainedSchedulerBackend$DriverEndpoint: Launching task 97 on executor id: 5 hostname: 10.1.2.176.
17/01/29 15:27:38,825 INFO CoarseGrainedSchedulerBackend$DriverEndpoint: Launching task 98 on executor id: 4 hostname: 10.1.2.38.
17/01/29 15:27:38,826 INFO CoarseGrainedSchedulerBackend$DriverEndpoint: Launching task 99 on executor id: 3 hostname: 10.1.2.65.
17/01/29 15:27:38,826 INFO CoarseGrainedSchedulerBackend$DriverEndpoint: Launching task 100 on executor id: 2 hostname: 10.1.2.66.
17/01/29 15:27:38,826 INFO CoarseGrainedSchedulerBackend$DriverEndpoint: Launching task 101 on executor id: 2 hostname: 10.1.2.66.
17/01/29 15:27:38,841 INFO BlockManagerInfo: Added broadcast_6_piece0 in memory on 10.1.2.176:37793 (size: 1890.0 B, free: 1942.8 MB)
17/01/29 15:27:38,842 INFO BlockManagerInfo: Added broadcast_6_piece0 in memory on 10.1.2.38:33985 (size: 1890.0 B, free: 1942.7 MB)
17/01/29 15:27:38,843 INFO BlockManagerInfo: Added broadcast_6_piece0 in memory on 10.1.2.66:34001 (size: 1890.0 B, free: 1943.0 MB)
17/01/29 15:27:38,844 INFO BlockManagerInfo: Added broadcast_6_piece0 in memory on 10.1.2.65:33751 (size: 1890.0 B, free: 1898.6 MB)
17/01/29 15:27:38,858 INFO MapOutputTrackerMasterEndpoint: Asked to send map output locations for shuffle 0 to 10.1.2.176:54556
17/01/29 15:27:38,858 INFO MapOutputTrackerMasterEndpoint: Asked to send map output locations for shuffle 0 to 10.1.2.65:36874
17/01/29 15:27:38,862 INFO MapOutputTrackerMasterEndpoint: Asked to send map output locations for shuffle 0 to 10.1.2.66:39392
17/01/29 15:27:38,863 INFO MapOutputTrackerMasterEndpoint: Asked to send map output locations for shuffle 0 to 10.1.2.38:46002
17/01/29 15:27:38,863 INFO MapOutputTrackerMaster: Size of output statuses for shuffle 0 is 332 bytes
17/01/29 15:27:38,936 INFO TaskSetManager: Finished task 2.0 in stage 4.0 (TID 100) in 112 ms on 10.1.2.66 (1/5)
17/01/29 15:27:38,936 INFO TaskSetManager: Finished task 4.0 in stage 4.0 (TID 97) in 115 ms on 10.1.2.176 (2/5)
17/01/29 15:27:38,938 INFO TaskSetManager: Finished task 1.0 in stage 4.0 (TID 98) in 116 ms on 10.1.2.38 (3/5)
17/01/29 15:27:38,940 INFO TaskSetManager: Finished task 3.0 in stage 4.0 (TID 101) in 115 ms on 10.1.2.66 (4/5)
17/01/29 15:27:38,943 INFO TaskSetManager: Finished task 0.0 in stage 4.0 (TID 99) in 121 ms on 10.1.2.65 (5/5)
17/01/29 15:27:38,944 INFO TaskSchedulerImpl: Removed TaskSet 4.0, whose tasks have all completed, from pool 
17/01/29 15:27:38,944 INFO DAGScheduler: ResultStage 4 (treeAggregate at GradientDescent.scala:239) finished in 0.123 s
17/01/29 15:27:38,944 INFO DAGScheduler: Job 3 finished: treeAggregate at GradientDescent.scala:239, took 0.767729 s
17/01/29 15:27:38,947 INFO MemoryStore: Block broadcast_7 stored as values in memory (estimated size 200.0 B, free 2.1 GB)
17/01/29 15:27:38,949 INFO MemoryStore: Block broadcast_7_piece0 stored as bytes in memory (estimated size 285.0 B, free 2.1 GB)
17/01/29 15:27:38,950 INFO BlockManagerInfo: Added broadcast_7_piece0 in memory on 10.1.2.152:45830 (size: 285.0 B, free: 2.1 GB)
17/01/29 15:27:38,951 INFO SparkContext: Created broadcast 7 from broadcast at GradientDescent.scala:235
17/01/29 15:27:38,968 INFO SparkContext: Starting job: treeAggregate at GradientDescent.scala:239
17/01/29 15:27:38,969 INFO DAGScheduler: Registering RDD 16 (treeAggregate at GradientDescent.scala:239)
17/01/29 15:27:38,970 INFO DAGScheduler: Got job 4 (treeAggregate at GradientDescent.scala:239) with 5 output partitions
17/01/29 15:27:38,970 INFO DAGScheduler: Final stage: ResultStage 6 (treeAggregate at GradientDescent.scala:239)
17/01/29 15:27:38,970 INFO DAGScheduler: Parents of final stage: List(ShuffleMapStage 5)
17/01/29 15:27:38,971 INFO DAGScheduler: Missing parents: List(ShuffleMapStage 5)
17/01/29 15:27:38,974 INFO DAGScheduler: Submitting ShuffleMapStage 5 (MapPartitionsRDD[16] at treeAggregate at GradientDescent.scala:239), which has no missing parents
17/01/29 15:27:38,981 INFO MemoryStore: Block broadcast_8 stored as values in memory (estimated size 7.1 KB, free 2.1 GB)
17/01/29 15:27:38,983 INFO MemoryStore: Block broadcast_8_piece0 stored as bytes in memory (estimated size 3.7 KB, free 2.1 GB)
17/01/29 15:27:38,984 INFO BlockManagerInfo: Added broadcast_8_piece0 in memory on 10.1.2.152:45830 (size: 3.7 KB, free: 2.1 GB)
17/01/29 15:27:38,985 INFO SparkContext: Created broadcast 8 from broadcast at DAGScheduler.scala:1012
17/01/29 15:27:38,985 INFO DAGScheduler: Submitting 32 missing tasks from ShuffleMapStage 5 (MapPartitionsRDD[16] at treeAggregate at GradientDescent.scala:239)
17/01/29 15:27:38,986 INFO TaskSchedulerImpl: Adding task set 5.0 with 32 tasks
17/01/29 15:27:38,988 INFO TaskSetManager: Starting task 8.0 in stage 5.0 (TID 102, 10.1.2.176, partition 8, PROCESS_LOCAL, 5562 bytes)
17/01/29 15:27:38,989 INFO TaskSetManager: Starting task 1.0 in stage 5.0 (TID 103, 10.1.2.224, partition 1, PROCESS_LOCAL, 5562 bytes)
17/01/29 15:27:38,989 INFO TaskSetManager: Starting task 12.0 in stage 5.0 (TID 104, 10.1.2.191, partition 12, PROCESS_LOCAL, 5562 bytes)
17/01/29 15:27:38,990 INFO TaskSetManager: Starting task 2.0 in stage 5.0 (TID 105, 10.1.2.139, partition 2, PROCESS_LOCAL, 5562 bytes)
17/01/29 15:27:38,990 INFO TaskSetManager: Starting task 0.0 in stage 5.0 (TID 106, 10.1.2.65, partition 0, PROCESS_LOCAL, 5562 bytes)
17/01/29 15:27:38,990 INFO TaskSetManager: Starting task 3.0 in stage 5.0 (TID 107, 10.1.2.66, partition 3, PROCESS_LOCAL, 5562 bytes)
17/01/29 15:27:38,991 INFO TaskSetManager: Starting task 5.0 in stage 5.0 (TID 108, 10.1.2.28, partition 5, PROCESS_LOCAL, 5562 bytes)
17/01/29 15:27:38,991 INFO TaskSetManager: Starting task 16.0 in stage 5.0 (TID 109, 10.1.2.38, partition 16, PROCESS_LOCAL, 5562 bytes)
17/01/29 15:27:38,991 INFO TaskSetManager: Starting task 9.0 in stage 5.0 (TID 110, 10.1.2.176, partition 9, PROCESS_LOCAL, 5562 bytes)
17/01/29 15:27:38,992 INFO TaskSetManager: Starting task 4.0 in stage 5.0 (TID 111, 10.1.2.224, partition 4, PROCESS_LOCAL, 5562 bytes)
17/01/29 15:27:38,992 INFO TaskSetManager: Starting task 18.0 in stage 5.0 (TID 112, 10.1.2.191, partition 18, PROCESS_LOCAL, 5562 bytes)
17/01/29 15:27:38,993 INFO TaskSetManager: Starting task 13.0 in stage 5.0 (TID 113, 10.1.2.139, partition 13, PROCESS_LOCAL, 5562 bytes)
17/01/29 15:27:38,993 INFO TaskSetManager: Starting task 6.0 in stage 5.0 (TID 114, 10.1.2.65, partition 6, PROCESS_LOCAL, 5562 bytes)
17/01/29 15:27:38,993 INFO TaskSetManager: Starting task 7.0 in stage 5.0 (TID 115, 10.1.2.66, partition 7, PROCESS_LOCAL, 5562 bytes)
17/01/29 15:27:38,995 INFO TaskSetManager: Starting task 14.0 in stage 5.0 (TID 116, 10.1.2.28, partition 14, PROCESS_LOCAL, 5562 bytes)
17/01/29 15:27:38,997 INFO TaskSetManager: Starting task 17.0 in stage 5.0 (TID 117, 10.1.2.38, partition 17, PROCESS_LOCAL, 5562 bytes)
17/01/29 15:27:39,000 INFO TaskSetManager: Starting task 15.0 in stage 5.0 (TID 118, 10.1.2.176, partition 15, PROCESS_LOCAL, 5562 bytes)
17/01/29 15:27:39,000 INFO TaskSetManager: Starting task 10.0 in stage 5.0 (TID 119, 10.1.2.224, partition 10, PROCESS_LOCAL, 5562 bytes)
17/01/29 15:27:39,001 INFO TaskSetManager: Starting task 24.0 in stage 5.0 (TID 120, 10.1.2.191, partition 24, PROCESS_LOCAL, 5562 bytes)
17/01/29 15:27:39,002 INFO TaskSetManager: Starting task 21.0 in stage 5.0 (TID 121, 10.1.2.139, partition 21, PROCESS_LOCAL, 5562 bytes)
17/01/29 15:27:39,003 INFO TaskSetManager: Starting task 11.0 in stage 5.0 (TID 122, 10.1.2.65, partition 11, PROCESS_LOCAL, 5562 bytes)
17/01/29 15:27:39,004 INFO TaskSetManager: Starting task 22.0 in stage 5.0 (TID 123, 10.1.2.66, partition 22, PROCESS_LOCAL, 5562 bytes)
17/01/29 15:27:39,005 INFO TaskSetManager: Starting task 19.0 in stage 5.0 (TID 124, 10.1.2.28, partition 19, PROCESS_LOCAL, 5562 bytes)
17/01/29 15:27:39,005 INFO TaskSetManager: Starting task 26.0 in stage 5.0 (TID 125, 10.1.2.38, partition 26, PROCESS_LOCAL, 5562 bytes)
17/01/29 15:27:39,006 INFO TaskSetManager: Starting task 29.0 in stage 5.0 (TID 126, 10.1.2.176, partition 29, PROCESS_LOCAL, 5562 bytes)
17/01/29 15:27:39,007 INFO TaskSetManager: Starting task 27.0 in stage 5.0 (TID 127, 10.1.2.224, partition 27, PROCESS_LOCAL, 5562 bytes)
17/01/29 15:27:39,008 INFO TaskSetManager: Starting task 30.0 in stage 5.0 (TID 128, 10.1.2.191, partition 30, PROCESS_LOCAL, 5562 bytes)
17/01/29 15:27:39,009 INFO TaskSetManager: Starting task 20.0 in stage 5.0 (TID 129, 10.1.2.65, partition 20, PROCESS_LOCAL, 5562 bytes)
17/01/29 15:27:39,010 INFO TaskSetManager: Starting task 23.0 in stage 5.0 (TID 130, 10.1.2.66, partition 23, PROCESS_LOCAL, 5562 bytes)
17/01/29 15:27:39,011 INFO TaskSetManager: Starting task 25.0 in stage 5.0 (TID 131, 10.1.2.28, partition 25, PROCESS_LOCAL, 5562 bytes)
17/01/29 15:27:39,012 INFO TaskSetManager: Starting task 28.0 in stage 5.0 (TID 132, 10.1.2.38, partition 28, PROCESS_LOCAL, 5562 bytes)
17/01/29 15:27:39,012 INFO CoarseGrainedSchedulerBackend$DriverEndpoint: Launching task 102 on executor id: 5 hostname: 10.1.2.176.
17/01/29 15:27:39,013 INFO CoarseGrainedSchedulerBackend$DriverEndpoint: Launching task 110 on executor id: 5 hostname: 10.1.2.176.
17/01/29 15:27:39,013 INFO CoarseGrainedSchedulerBackend$DriverEndpoint: Launching task 118 on executor id: 5 hostname: 10.1.2.176.
17/01/29 15:27:39,014 INFO CoarseGrainedSchedulerBackend$DriverEndpoint: Launching task 126 on executor id: 5 hostname: 10.1.2.176.
17/01/29 15:27:39,014 INFO CoarseGrainedSchedulerBackend$DriverEndpoint: Launching task 103 on executor id: 6 hostname: 10.1.2.224.
17/01/29 15:27:39,014 INFO CoarseGrainedSchedulerBackend$DriverEndpoint: Launching task 111 on executor id: 6 hostname: 10.1.2.224.
17/01/29 15:27:39,014 INFO CoarseGrainedSchedulerBackend$DriverEndpoint: Launching task 119 on executor id: 6 hostname: 10.1.2.224.
17/01/29 15:27:39,015 INFO CoarseGrainedSchedulerBackend$DriverEndpoint: Launching task 127 on executor id: 6 hostname: 10.1.2.224.
17/01/29 15:27:39,015 INFO CoarseGrainedSchedulerBackend$DriverEndpoint: Launching task 104 on executor id: 1 hostname: 10.1.2.191.
17/01/29 15:27:39,015 INFO CoarseGrainedSchedulerBackend$DriverEndpoint: Launching task 112 on executor id: 1 hostname: 10.1.2.191.
17/01/29 15:27:39,016 INFO CoarseGrainedSchedulerBackend$DriverEndpoint: Launching task 120 on executor id: 1 hostname: 10.1.2.191.
17/01/29 15:27:39,016 INFO CoarseGrainedSchedulerBackend$DriverEndpoint: Launching task 128 on executor id: 1 hostname: 10.1.2.191.
17/01/29 15:27:39,016 INFO CoarseGrainedSchedulerBackend$DriverEndpoint: Launching task 105 on executor id: 7 hostname: 10.1.2.139.
17/01/29 15:27:39,016 INFO CoarseGrainedSchedulerBackend$DriverEndpoint: Launching task 113 on executor id: 7 hostname: 10.1.2.139.
17/01/29 15:27:39,017 INFO CoarseGrainedSchedulerBackend$DriverEndpoint: Launching task 121 on executor id: 7 hostname: 10.1.2.139.
17/01/29 15:27:39,017 INFO CoarseGrainedSchedulerBackend$DriverEndpoint: Launching task 106 on executor id: 3 hostname: 10.1.2.65.
17/01/29 15:27:39,017 INFO CoarseGrainedSchedulerBackend$DriverEndpoint: Launching task 114 on executor id: 3 hostname: 10.1.2.65.
17/01/29 15:27:39,017 INFO CoarseGrainedSchedulerBackend$DriverEndpoint: Launching task 122 on executor id: 3 hostname: 10.1.2.65.
17/01/29 15:27:39,018 INFO CoarseGrainedSchedulerBackend$DriverEndpoint: Launching task 129 on executor id: 3 hostname: 10.1.2.65.
17/01/29 15:27:39,018 INFO CoarseGrainedSchedulerBackend$DriverEndpoint: Launching task 107 on executor id: 2 hostname: 10.1.2.66.
17/01/29 15:27:39,018 INFO CoarseGrainedSchedulerBackend$DriverEndpoint: Launching task 115 on executor id: 2 hostname: 10.1.2.66.
17/01/29 15:27:39,018 INFO CoarseGrainedSchedulerBackend$DriverEndpoint: Launching task 123 on executor id: 2 hostname: 10.1.2.66.
17/01/29 15:27:39,019 INFO CoarseGrainedSchedulerBackend$DriverEndpoint: Launching task 130 on executor id: 2 hostname: 10.1.2.66.
17/01/29 15:27:39,019 INFO CoarseGrainedSchedulerBackend$DriverEndpoint: Launching task 108 on executor id: 0 hostname: 10.1.2.28.
17/01/29 15:27:39,019 INFO CoarseGrainedSchedulerBackend$DriverEndpoint: Launching task 116 on executor id: 0 hostname: 10.1.2.28.
17/01/29 15:27:39,019 INFO CoarseGrainedSchedulerBackend$DriverEndpoint: Launching task 124 on executor id: 0 hostname: 10.1.2.28.
17/01/29 15:27:39,019 INFO CoarseGrainedSchedulerBackend$DriverEndpoint: Launching task 131 on executor id: 0 hostname: 10.1.2.28.
17/01/29 15:27:39,020 INFO CoarseGrainedSchedulerBackend$DriverEndpoint: Launching task 109 on executor id: 4 hostname: 10.1.2.38.
17/01/29 15:27:39,020 INFO CoarseGrainedSchedulerBackend$DriverEndpoint: Launching task 117 on executor id: 4 hostname: 10.1.2.38.
17/01/29 15:27:39,020 INFO CoarseGrainedSchedulerBackend$DriverEndpoint: Launching task 125 on executor id: 4 hostname: 10.1.2.38.
17/01/29 15:27:39,021 INFO CoarseGrainedSchedulerBackend$DriverEndpoint: Launching task 132 on executor id: 4 hostname: 10.1.2.38.
17/01/29 15:27:39,036 INFO BlockManagerInfo: Added broadcast_8_piece0 in memory on 10.1.2.224:33593 (size: 3.7 KB, free: 1942.8 MB)
17/01/29 15:27:39,037 INFO BlockManagerInfo: Added broadcast_8_piece0 in memory on 10.1.2.65:33751 (size: 3.7 KB, free: 1898.6 MB)
17/01/29 15:27:39,039 INFO BlockManagerInfo: Added broadcast_8_piece0 in memory on 10.1.2.176:37793 (size: 3.7 KB, free: 1942.8 MB)
17/01/29 15:27:39,039 INFO BlockManagerInfo: Added broadcast_8_piece0 in memory on 10.1.2.66:34001 (size: 3.7 KB, free: 1943.0 MB)
17/01/29 15:27:39,040 INFO BlockManagerInfo: Added broadcast_8_piece0 in memory on 10.1.2.191:37586 (size: 3.7 KB, free: 1942.8 MB)
17/01/29 15:27:39,040 INFO BlockManagerInfo: Added broadcast_8_piece0 in memory on 10.1.2.139:45024 (size: 3.7 KB, free: 1987.2 MB)
17/01/29 15:27:39,042 INFO BlockManagerInfo: Added broadcast_8_piece0 in memory on 10.1.2.38:33985 (size: 3.7 KB, free: 1942.7 MB)
17/01/29 15:27:39,044 INFO BlockManagerInfo: Added broadcast_8_piece0 in memory on 10.1.2.28:44512 (size: 3.7 KB, free: 1942.9 MB)
17/01/29 15:27:39,052 INFO BlockManagerInfo: Added broadcast_7_piece0 in memory on 10.1.2.224:33593 (size: 285.0 B, free: 1942.8 MB)
17/01/29 15:27:39,056 INFO BlockManagerInfo: Added broadcast_7_piece0 in memory on 10.1.2.191:37586 (size: 285.0 B, free: 1942.8 MB)
17/01/29 15:27:39,059 INFO BlockManagerInfo: Added broadcast_7_piece0 in memory on 10.1.2.65:33751 (size: 285.0 B, free: 1898.6 MB)
17/01/29 15:27:39,060 INFO BlockManagerInfo: Added broadcast_7_piece0 in memory on 10.1.2.66:34001 (size: 285.0 B, free: 1943.0 MB)
17/01/29 15:27:39,061 INFO BlockManagerInfo: Added broadcast_7_piece0 in memory on 10.1.2.139:45024 (size: 285.0 B, free: 1987.2 MB)
17/01/29 15:27:39,063 INFO BlockManagerInfo: Added broadcast_7_piece0 in memory on 10.1.2.28:44512 (size: 285.0 B, free: 1942.9 MB)
17/01/29 15:27:39,065 INFO BlockManagerInfo: Added broadcast_7_piece0 in memory on 10.1.2.38:33985 (size: 285.0 B, free: 1942.7 MB)
17/01/29 15:27:39,071 INFO BlockManagerInfo: Added broadcast_7_piece0 in memory on 10.1.2.176:37793 (size: 285.0 B, free: 1942.8 MB)
17/01/29 15:27:39,121 INFO TaskSetManager: Finished task 27.0 in stage 5.0 (TID 127) in 113 ms on 10.1.2.224 (1/32)
17/01/29 15:27:39,121 INFO TaskSetManager: Finished task 30.0 in stage 5.0 (TID 128) in 113 ms on 10.1.2.191 (2/32)
17/01/29 15:27:39,123 INFO TaskSetManager: Finished task 4.0 in stage 5.0 (TID 111) in 131 ms on 10.1.2.224 (3/32)
17/01/29 15:27:39,123 INFO TaskSetManager: Finished task 18.0 in stage 5.0 (TID 112) in 131 ms on 10.1.2.191 (4/32)
17/01/29 15:27:39,125 INFO TaskSetManager: Finished task 12.0 in stage 5.0 (TID 104) in 136 ms on 10.1.2.191 (5/32)
17/01/29 15:27:39,126 INFO TaskSetManager: Finished task 24.0 in stage 5.0 (TID 120) in 124 ms on 10.1.2.191 (6/32)
17/01/29 15:27:39,136 INFO TaskSetManager: Finished task 21.0 in stage 5.0 (TID 121) in 134 ms on 10.1.2.139 (7/32)
17/01/29 15:27:39,137 INFO TaskSetManager: Finished task 13.0 in stage 5.0 (TID 113) in 145 ms on 10.1.2.139 (8/32)
17/01/29 15:27:39,141 INFO TaskSetManager: Finished task 1.0 in stage 5.0 (TID 103) in 153 ms on 10.1.2.224 (9/32)
17/01/29 15:27:39,143 INFO TaskSetManager: Finished task 10.0 in stage 5.0 (TID 119) in 143 ms on 10.1.2.224 (10/32)
17/01/29 15:27:39,144 INFO TaskSetManager: Starting task 31.0 in stage 5.0 (TID 133, 10.1.2.65, partition 31, PROCESS_LOCAL, 5562 bytes)
17/01/29 15:27:39,145 INFO CoarseGrainedSchedulerBackend$DriverEndpoint: Launching task 133 on executor id: 3 hostname: 10.1.2.65.
17/01/29 15:27:39,145 INFO TaskSetManager: Finished task 11.0 in stage 5.0 (TID 122) in 143 ms on 10.1.2.65 (11/32)
17/01/29 15:27:39,146 INFO TaskSetManager: Finished task 20.0 in stage 5.0 (TID 129) in 137 ms on 10.1.2.65 (12/32)
17/01/29 15:27:39,146 INFO TaskSetManager: Finished task 0.0 in stage 5.0 (TID 106) in 156 ms on 10.1.2.65 (13/32)
17/01/29 15:27:39,147 INFO TaskSetManager: Finished task 2.0 in stage 5.0 (TID 105) in 158 ms on 10.1.2.139 (14/32)
17/01/29 15:27:39,149 INFO TaskSetManager: Finished task 29.0 in stage 5.0 (TID 126) in 142 ms on 10.1.2.176 (15/32)
17/01/29 15:27:39,149 INFO TaskSetManager: Finished task 3.0 in stage 5.0 (TID 107) in 159 ms on 10.1.2.66 (16/32)
17/01/29 15:27:39,150 INFO TaskSetManager: Finished task 23.0 in stage 5.0 (TID 130) in 141 ms on 10.1.2.66 (17/32)
17/01/29 15:27:39,152 INFO TaskSetManager: Finished task 8.0 in stage 5.0 (TID 102) in 164 ms on 10.1.2.176 (18/32)
17/01/29 15:27:39,152 INFO TaskSetManager: Finished task 6.0 in stage 5.0 (TID 114) in 159 ms on 10.1.2.65 (19/32)
17/01/29 15:27:39,160 INFO TaskSetManager: Finished task 22.0 in stage 5.0 (TID 123) in 157 ms on 10.1.2.66 (20/32)
17/01/29 15:27:39,164 INFO TaskSetManager: Finished task 7.0 in stage 5.0 (TID 115) in 171 ms on 10.1.2.66 (21/32)
17/01/29 15:27:39,170 INFO TaskSetManager: Finished task 9.0 in stage 5.0 (TID 110) in 179 ms on 10.1.2.176 (22/32)
17/01/29 15:27:39,171 INFO TaskSetManager: Finished task 15.0 in stage 5.0 (TID 118) in 173 ms on 10.1.2.176 (23/32)
17/01/29 15:27:39,181 INFO TaskSetManager: Finished task 16.0 in stage 5.0 (TID 109) in 190 ms on 10.1.2.38 (24/32)
17/01/29 15:27:39,185 INFO TaskSetManager: Finished task 28.0 in stage 5.0 (TID 132) in 174 ms on 10.1.2.38 (25/32)
17/01/29 15:27:39,192 INFO TaskSetManager: Finished task 17.0 in stage 5.0 (TID 117) in 197 ms on 10.1.2.38 (26/32)
17/01/29 15:27:39,196 INFO TaskSetManager: Finished task 26.0 in stage 5.0 (TID 125) in 191 ms on 10.1.2.38 (27/32)
17/01/29 15:27:39,205 INFO TaskSetManager: Finished task 5.0 in stage 5.0 (TID 108) in 215 ms on 10.1.2.28 (28/32)
17/01/29 15:27:39,209 INFO TaskSetManager: Finished task 31.0 in stage 5.0 (TID 133) in 66 ms on 10.1.2.65 (29/32)
17/01/29 15:27:39,212 INFO TaskSetManager: Finished task 19.0 in stage 5.0 (TID 124) in 208 ms on 10.1.2.28 (30/32)
17/01/29 15:27:39,220 INFO TaskSetManager: Finished task 25.0 in stage 5.0 (TID 131) in 210 ms on 10.1.2.28 (31/32)
17/01/29 15:27:39,222 INFO TaskSetManager: Finished task 14.0 in stage 5.0 (TID 116) in 228 ms on 10.1.2.28 (32/32)
17/01/29 15:27:39,222 INFO TaskSchedulerImpl: Removed TaskSet 5.0, whose tasks have all completed, from pool 
17/01/29 15:27:39,223 INFO DAGScheduler: ShuffleMapStage 5 (treeAggregate at GradientDescent.scala:239) finished in 0.229 s
17/01/29 15:27:39,223 INFO DAGScheduler: looking for newly runnable stages
17/01/29 15:27:39,223 INFO DAGScheduler: running: Set()
17/01/29 15:27:39,223 INFO DAGScheduler: waiting: Set(ResultStage 6)
17/01/29 15:27:39,223 INFO DAGScheduler: failed: Set()
17/01/29 15:27:39,224 INFO DAGScheduler: Submitting ResultStage 6 (MapPartitionsRDD[18] at treeAggregate at GradientDescent.scala:239), which has no missing parents
17/01/29 15:27:39,226 INFO MemoryStore: Block broadcast_9 stored as values in memory (estimated size 3.1 KB, free 2.1 GB)
17/01/29 15:27:39,228 INFO MemoryStore: Block broadcast_9_piece0 stored as bytes in memory (estimated size 1889.0 B, free 2.1 GB)
17/01/29 15:27:39,229 INFO BlockManagerInfo: Added broadcast_9_piece0 in memory on 10.1.2.152:45830 (size: 1889.0 B, free: 2.1 GB)
17/01/29 15:27:39,229 INFO SparkContext: Created broadcast 9 from broadcast at DAGScheduler.scala:1012
17/01/29 15:27:39,230 INFO DAGScheduler: Submitting 5 missing tasks from ResultStage 6 (MapPartitionsRDD[18] at treeAggregate at GradientDescent.scala:239)
17/01/29 15:27:39,230 INFO TaskSchedulerImpl: Adding task set 6.0 with 5 tasks
17/01/29 15:27:39,231 INFO TaskSetManager: Starting task 0.0 in stage 6.0 (TID 134, 10.1.2.28, partition 0, NODE_LOCAL, 5228 bytes)
17/01/29 15:27:39,232 INFO TaskSetManager: Starting task 4.0 in stage 6.0 (TID 135, 10.1.2.176, partition 4, NODE_LOCAL, 5228 bytes)
17/01/29 15:27:39,232 INFO TaskSetManager: Starting task 1.0 in stage 6.0 (TID 136, 10.1.2.38, partition 1, NODE_LOCAL, 5228 bytes)
17/01/29 15:27:39,233 INFO TaskSetManager: Starting task 2.0 in stage 6.0 (TID 137, 10.1.2.66, partition 2, NODE_LOCAL, 5228 bytes)
17/01/29 15:27:39,233 INFO TaskSetManager: Starting task 3.0 in stage 6.0 (TID 138, 10.1.2.66, partition 3, NODE_LOCAL, 5228 bytes)
17/01/29 15:27:39,234 INFO CoarseGrainedSchedulerBackend$DriverEndpoint: Launching task 134 on executor id: 0 hostname: 10.1.2.28.
17/01/29 15:27:39,234 INFO CoarseGrainedSchedulerBackend$DriverEndpoint: Launching task 135 on executor id: 5 hostname: 10.1.2.176.
17/01/29 15:27:39,234 INFO CoarseGrainedSchedulerBackend$DriverEndpoint: Launching task 136 on executor id: 4 hostname: 10.1.2.38.
17/01/29 15:27:39,235 INFO CoarseGrainedSchedulerBackend$DriverEndpoint: Launching task 137 on executor id: 2 hostname: 10.1.2.66.
17/01/29 15:27:39,235 INFO CoarseGrainedSchedulerBackend$DriverEndpoint: Launching task 138 on executor id: 2 hostname: 10.1.2.66.
17/01/29 15:27:39,247 INFO BlockManagerInfo: Added broadcast_9_piece0 in memory on 10.1.2.38:33985 (size: 1889.0 B, free: 1942.7 MB)
17/01/29 15:27:39,252 INFO BlockManagerInfo: Added broadcast_9_piece0 in memory on 10.1.2.176:37793 (size: 1889.0 B, free: 1942.8 MB)
17/01/29 15:27:39,253 INFO BlockManagerInfo: Added broadcast_9_piece0 in memory on 10.1.2.66:34001 (size: 1889.0 B, free: 1943.0 MB)
17/01/29 15:27:39,254 INFO MapOutputTrackerMasterEndpoint: Asked to send map output locations for shuffle 1 to 10.1.2.38:46002
17/01/29 15:27:39,255 INFO MapOutputTrackerMaster: Size of output statuses for shuffle 1 is 332 bytes
17/01/29 15:27:39,259 INFO MapOutputTrackerMasterEndpoint: Asked to send map output locations for shuffle 1 to 10.1.2.176:54556
17/01/29 15:27:39,259 INFO MapOutputTrackerMasterEndpoint: Asked to send map output locations for shuffle 1 to 10.1.2.66:39392
17/01/29 15:27:39,278 INFO TaskSetManager: Finished task 1.0 in stage 6.0 (TID 136) in 45 ms on 10.1.2.38 (1/5)
17/01/29 15:27:39,280 INFO BlockManagerInfo: Added broadcast_9_piece0 in memory on 10.1.2.28:44512 (size: 1889.0 B, free: 1942.9 MB)
17/01/29 15:27:39,282 INFO TaskSetManager: Finished task 4.0 in stage 6.0 (TID 135) in 51 ms on 10.1.2.176 (2/5)
17/01/29 15:27:39,287 INFO TaskSetManager: Finished task 2.0 in stage 6.0 (TID 137) in 55 ms on 10.1.2.66 (3/5)
17/01/29 15:27:39,289 INFO TaskSetManager: Finished task 3.0 in stage 6.0 (TID 138) in 56 ms on 10.1.2.66 (4/5)
17/01/29 15:27:39,295 INFO MapOutputTrackerMasterEndpoint: Asked to send map output locations for shuffle 1 to 10.1.2.28:57576
17/01/29 15:27:39,339 INFO TaskSetManager: Finished task 0.0 in stage 6.0 (TID 134) in 108 ms on 10.1.2.28 (5/5)
17/01/29 15:27:39,339 INFO TaskSchedulerImpl: Removed TaskSet 6.0, whose tasks have all completed, from pool 
17/01/29 15:27:39,340 INFO DAGScheduler: ResultStage 6 (treeAggregate at GradientDescent.scala:239) finished in 0.108 s
17/01/29 15:27:39,340 INFO DAGScheduler: Job 4 finished: treeAggregate at GradientDescent.scala:239, took 0.371923 s
17/01/29 15:27:39,347 INFO MemoryStore: Block broadcast_10 stored as values in memory (estimated size 200.0 B, free 2.1 GB)
17/01/29 15:27:39,349 INFO MemoryStore: Block broadcast_10_piece0 stored as bytes in memory (estimated size 285.0 B, free 2.1 GB)
17/01/29 15:27:39,350 INFO BlockManagerInfo: Added broadcast_10_piece0 in memory on 10.1.2.152:45830 (size: 285.0 B, free: 2.1 GB)
17/01/29 15:27:39,351 INFO SparkContext: Created broadcast 10 from broadcast at GradientDescent.scala:235
17/01/29 15:27:39,369 INFO SparkContext: Starting job: treeAggregate at GradientDescent.scala:239
17/01/29 15:27:39,371 INFO DAGScheduler: Registering RDD 21 (treeAggregate at GradientDescent.scala:239)
17/01/29 15:27:39,371 INFO DAGScheduler: Got job 5 (treeAggregate at GradientDescent.scala:239) with 5 output partitions
17/01/29 15:27:39,371 INFO DAGScheduler: Final stage: ResultStage 8 (treeAggregate at GradientDescent.scala:239)
17/01/29 15:27:39,371 INFO DAGScheduler: Parents of final stage: List(ShuffleMapStage 7)
17/01/29 15:27:39,372 INFO DAGScheduler: Missing parents: List(ShuffleMapStage 7)
17/01/29 15:27:39,374 INFO DAGScheduler: Submitting ShuffleMapStage 7 (MapPartitionsRDD[21] at treeAggregate at GradientDescent.scala:239), which has no missing parents
17/01/29 15:27:39,380 INFO MemoryStore: Block broadcast_11 stored as values in memory (estimated size 7.1 KB, free 2.1 GB)
17/01/29 15:27:39,382 INFO MemoryStore: Block broadcast_11_piece0 stored as bytes in memory (estimated size 3.7 KB, free 2.1 GB)
17/01/29 15:27:39,382 INFO BlockManagerInfo: Added broadcast_11_piece0 in memory on 10.1.2.152:45830 (size: 3.7 KB, free: 2.1 GB)
17/01/29 15:27:39,383 INFO SparkContext: Created broadcast 11 from broadcast at DAGScheduler.scala:1012
17/01/29 15:27:39,384 INFO DAGScheduler: Submitting 32 missing tasks from ShuffleMapStage 7 (MapPartitionsRDD[21] at treeAggregate at GradientDescent.scala:239)
17/01/29 15:27:39,384 INFO TaskSchedulerImpl: Adding task set 7.0 with 32 tasks
17/01/29 15:27:39,386 INFO TaskSetManager: Starting task 16.0 in stage 7.0 (TID 139, 10.1.2.38, partition 16, PROCESS_LOCAL, 5562 bytes)
17/01/29 15:27:39,387 INFO TaskSetManager: Starting task 2.0 in stage 7.0 (TID 140, 10.1.2.139, partition 2, PROCESS_LOCAL, 5562 bytes)
17/01/29 15:27:39,387 INFO TaskSetManager: Starting task 5.0 in stage 7.0 (TID 141, 10.1.2.28, partition 5, PROCESS_LOCAL, 5562 bytes)
17/01/29 15:27:39,387 INFO TaskSetManager: Starting task 0.0 in stage 7.0 (TID 142, 10.1.2.65, partition 0, PROCESS_LOCAL, 5562 bytes)
17/01/29 15:27:39,388 INFO TaskSetManager: Starting task 1.0 in stage 7.0 (TID 143, 10.1.2.224, partition 1, PROCESS_LOCAL, 5562 bytes)
17/01/29 15:27:39,388 INFO TaskSetManager: Starting task 12.0 in stage 7.0 (TID 144, 10.1.2.191, partition 12, PROCESS_LOCAL, 5562 bytes)
17/01/29 15:27:39,389 INFO TaskSetManager: Starting task 3.0 in stage 7.0 (TID 145, 10.1.2.66, partition 3, PROCESS_LOCAL, 5562 bytes)
17/01/29 15:27:39,389 INFO TaskSetManager: Starting task 8.0 in stage 7.0 (TID 146, 10.1.2.176, partition 8, PROCESS_LOCAL, 5562 bytes)
17/01/29 15:27:39,390 INFO TaskSetManager: Starting task 17.0 in stage 7.0 (TID 147, 10.1.2.38, partition 17, PROCESS_LOCAL, 5562 bytes)
17/01/29 15:27:39,390 INFO TaskSetManager: Starting task 13.0 in stage 7.0 (TID 148, 10.1.2.139, partition 13, PROCESS_LOCAL, 5562 bytes)
17/01/29 15:27:39,391 INFO TaskSetManager: Starting task 14.0 in stage 7.0 (TID 149, 10.1.2.28, partition 14, PROCESS_LOCAL, 5562 bytes)
17/01/29 15:27:39,391 INFO TaskSetManager: Starting task 6.0 in stage 7.0 (TID 150, 10.1.2.65, partition 6, PROCESS_LOCAL, 5562 bytes)
17/01/29 15:27:39,392 INFO TaskSetManager: Starting task 4.0 in stage 7.0 (TID 151, 10.1.2.224, partition 4, PROCESS_LOCAL, 5562 bytes)
17/01/29 15:27:39,392 INFO TaskSetManager: Starting task 18.0 in stage 7.0 (TID 152, 10.1.2.191, partition 18, PROCESS_LOCAL, 5562 bytes)
17/01/29 15:27:39,393 INFO TaskSetManager: Starting task 7.0 in stage 7.0 (TID 153, 10.1.2.66, partition 7, PROCESS_LOCAL, 5562 bytes)
17/01/29 15:27:39,393 INFO TaskSetManager: Starting task 9.0 in stage 7.0 (TID 154, 10.1.2.176, partition 9, PROCESS_LOCAL, 5562 bytes)
17/01/29 15:27:39,394 INFO TaskSetManager: Starting task 26.0 in stage 7.0 (TID 155, 10.1.2.38, partition 26, PROCESS_LOCAL, 5562 bytes)
17/01/29 15:27:39,394 INFO TaskSetManager: Starting task 21.0 in stage 7.0 (TID 156, 10.1.2.139, partition 21, PROCESS_LOCAL, 5562 bytes)
17/01/29 15:27:39,395 INFO TaskSetManager: Starting task 19.0 in stage 7.0 (TID 157, 10.1.2.28, partition 19, PROCESS_LOCAL, 5562 bytes)
17/01/29 15:27:39,395 INFO TaskSetManager: Starting task 11.0 in stage 7.0 (TID 158, 10.1.2.65, partition 11, PROCESS_LOCAL, 5562 bytes)
17/01/29 15:27:39,398 INFO TaskSetManager: Starting task 10.0 in stage 7.0 (TID 159, 10.1.2.224, partition 10, PROCESS_LOCAL, 5562 bytes)
17/01/29 15:27:39,399 INFO TaskSetManager: Starting task 24.0 in stage 7.0 (TID 160, 10.1.2.191, partition 24, PROCESS_LOCAL, 5562 bytes)
17/01/29 15:27:39,400 INFO TaskSetManager: Starting task 22.0 in stage 7.0 (TID 161, 10.1.2.66, partition 22, PROCESS_LOCAL, 5562 bytes)
17/01/29 15:27:39,400 INFO TaskSetManager: Starting task 15.0 in stage 7.0 (TID 162, 10.1.2.176, partition 15, PROCESS_LOCAL, 5562 bytes)
17/01/29 15:27:39,401 INFO TaskSetManager: Starting task 28.0 in stage 7.0 (TID 163, 10.1.2.38, partition 28, PROCESS_LOCAL, 5562 bytes)
17/01/29 15:27:39,402 INFO TaskSetManager: Starting task 25.0 in stage 7.0 (TID 164, 10.1.2.28, partition 25, PROCESS_LOCAL, 5562 bytes)
17/01/29 15:27:39,402 INFO TaskSetManager: Starting task 20.0 in stage 7.0 (TID 165, 10.1.2.65, partition 20, PROCESS_LOCAL, 5562 bytes)
17/01/29 15:27:39,403 INFO TaskSetManager: Starting task 27.0 in stage 7.0 (TID 166, 10.1.2.224, partition 27, PROCESS_LOCAL, 5562 bytes)
17/01/29 15:27:39,404 INFO TaskSetManager: Starting task 30.0 in stage 7.0 (TID 167, 10.1.2.191, partition 30, PROCESS_LOCAL, 5562 bytes)
17/01/29 15:27:39,404 INFO TaskSetManager: Starting task 23.0 in stage 7.0 (TID 168, 10.1.2.66, partition 23, PROCESS_LOCAL, 5562 bytes)
17/01/29 15:27:39,405 INFO TaskSetManager: Starting task 29.0 in stage 7.0 (TID 169, 10.1.2.176, partition 29, PROCESS_LOCAL, 5562 bytes)
17/01/29 15:27:39,406 INFO CoarseGrainedSchedulerBackend$DriverEndpoint: Launching task 139 on executor id: 4 hostname: 10.1.2.38.
17/01/29 15:27:39,406 INFO CoarseGrainedSchedulerBackend$DriverEndpoint: Launching task 147 on executor id: 4 hostname: 10.1.2.38.
17/01/29 15:27:39,407 INFO CoarseGrainedSchedulerBackend$DriverEndpoint: Launching task 155 on executor id: 4 hostname: 10.1.2.38.
17/01/29 15:27:39,407 INFO CoarseGrainedSchedulerBackend$DriverEndpoint: Launching task 163 on executor id: 4 hostname: 10.1.2.38.
17/01/29 15:27:39,408 INFO CoarseGrainedSchedulerBackend$DriverEndpoint: Launching task 140 on executor id: 7 hostname: 10.1.2.139.
