Using properties file: /home/ubuntu/spark-2.0.0/conf/spark-defaults.conf
Adding default property: spark.executor.extraJavaOptions=-XX:+PrintGCDetails -XX:+PrintGCTimeStamps -Xms11500m -Dlog4j.configuration=file:///home/ubuntu/spark-2.0.0/conf/log4j.properties
Adding default property: spark.driver.extraJavaOptions=-XX:+PrintGCDetails -XX:+PrintGCTimeStamps -Xms11500m -Dlog4j.configuration=file:///home/ubuntu/spark-2.0.0/conf/log4j.properties
Parsed arguments:
  master                  spark://euca-10-1-2-142:7077
  deployMode              client
  executorMemory          11500m
  executorCores           null
  totalExecutorCores      null
  propertiesFile          /home/ubuntu/spark-2.0.0/conf/spark-defaults.conf
  driverMemory            11500m
  driverCores             null
  driverExtraClassPath    null
  driverExtraLibraryPath  null
  driverExtraJavaOptions  -XX:+PrintGCDetails -XX:+PrintGCTimeStamps -Xms11500m -Dlog4j.configuration=file:///home/ubuntu/spark-2.0.0/conf/log4j.properties
  supervise               false
  queue                   null
  numExecutors            16
  files                   null
  pyFiles                 null
  archives                null
  mainClass               LogRegExplicitParallelism
  primaryResource         file:///home/ubuntu/jars/log-reg-explicit-parallelism_2.11-1.0.jar
  name                    LogRegExplicitParallelism
  childArgs               [cluster 28 euca-10-1-2-142 9000 higgs_0_exp 5 64]
  jars                    null
  packages                null
  packagesExclusions      null
  repositories            null
  verbose                 true

Spark properties used, including those specified through
 --conf and those from the properties file /home/ubuntu/spark-2.0.0/conf/spark-defaults.conf:
  spark.default.parallelism -> 64
  spark.driver.memory -> 11500m
  spark.executor.extraJavaOptions -> -XX:+PrintGCDetails -XX:+PrintGCTimeStamps -Xms11500m -Dlog4j.configuration=file:///home/ubuntu/spark-2.0.0/conf/log4j.properties
  spark.driver.extraJavaOptions -> -XX:+PrintGCDetails -XX:+PrintGCTimeStamps -Xms11500m -Dlog4j.configuration=file:///home/ubuntu/spark-2.0.0/conf/log4j.properties
  spark.shuffle.spill -> false
  spark.driver.maxResultSize -> 5g

    
Main class:
LogRegExplicitParallelism
Arguments:
cluster
28
euca-10-1-2-142
9000
higgs_0_exp
5
64
System properties:
spark.default.parallelism -> 64
spark.executor.memory -> 11500m
spark.driver.memory -> 11500m
SPARK_SUBMIT -> true
spark.executor.extraJavaOptions -> -XX:+PrintGCDetails -XX:+PrintGCTimeStamps -Xms11500m -Dlog4j.configuration=file:///home/ubuntu/spark-2.0.0/conf/log4j.properties
spark.app.name -> LogRegExplicitParallelism
spark.shuffle.spill -> false
spark.driver.extraJavaOptions -> -XX:+PrintGCDetails -XX:+PrintGCTimeStamps -Xms11500m -Dlog4j.configuration=file:///home/ubuntu/spark-2.0.0/conf/log4j.properties
spark.jars -> file:///home/ubuntu/jars/log-reg-explicit-parallelism_2.11-1.0.jar
spark.submit.deployMode -> client
spark.driver.maxResultSize -> 5g
spark.master -> spark://euca-10-1-2-142:7077
Classpath elements:
file:///home/ubuntu/jars/log-reg-explicit-parallelism_2.11-1.0.jar


17/02/07 11:54:28,210 INFO SparkContext: Running Spark version 2.0.0
17/02/07 11:54:28,589 WARN NativeCodeLoader: Unable to load native-hadoop library for your platform... using builtin-java classes where applicable
17/02/07 11:54:28,774 INFO SecurityManager: Changing view acls to: ubuntu
17/02/07 11:54:28,774 INFO SecurityManager: Changing modify acls to: ubuntu
17/02/07 11:54:28,775 INFO SecurityManager: Changing view acls groups to: 
17/02/07 11:54:28,777 INFO SecurityManager: Changing modify acls groups to: 
17/02/07 11:54:28,777 INFO SecurityManager: SecurityManager: authentication disabled; ui acls disabled; users  with view permissions: Set(ubuntu); groups with view permissions: Set(); users  with modify permissions: Set(ubuntu); groups with modify permissions: Set()
17/02/07 11:54:29,145 INFO Utils: Successfully started service 'sparkDriver' on port 46185.
17/02/07 11:54:29,173 INFO SparkEnv: Registering MapOutputTracker
17/02/07 11:54:29,181 WARN SortShuffleManager: spark.shuffle.spill was set to false, but this configuration is ignored as of Spark 1.6+. Shuffle will continue to spill to disk when necessary.
17/02/07 11:54:29,195 INFO SparkEnv: Registering BlockManagerMaster
17/02/07 11:54:29,213 INFO DiskBlockManager: Created local directory at /tmp/blockmgr-f45f522e-6af8-46e2-bbfc-e6ae793c1599
17/02/07 11:54:29,237 INFO MemoryStore: MemoryStore started with capacity 6.3 GB
17/02/07 11:54:29,302 INFO SparkEnv: Registering OutputCommitCoordinator
17/02/07 11:54:29,543 INFO Utils: Successfully started service 'SparkUI' on port 4040.
17/02/07 11:54:29,545 INFO SparkUI: Bound SparkUI to 10.1.2.142, and started at http://10.1.2.142:4040
17/02/07 11:54:29,583 INFO SparkContext: Added JAR file:///home/ubuntu/jars/log-reg-explicit-parallelism_2.11-1.0.jar at spark://10.1.2.142:46185/jars/log-reg-explicit-parallelism_2.11-1.0.jar with timestamp 1486468469583
17/02/07 11:54:29,692 INFO StandaloneAppClient$ClientEndpoint: Connecting to master spark://euca-10-1-2-142:7077...
17/02/07 11:54:29,750 INFO TransportClientFactory: Successfully created connection to euca-10-1-2-142/10.1.2.142:7077 after 27 ms (0 ms spent in bootstraps)
17/02/07 11:54:29,879 INFO StandaloneSchedulerBackend: Connected to Spark cluster with app ID app-20170207115429-0000
17/02/07 11:54:29,890 INFO Utils: Successfully started service 'org.apache.spark.network.netty.NettyBlockTransferService' on port 39400.
17/02/07 11:54:29,891 INFO NettyBlockTransferService: Server created on 10.1.2.142:39400
17/02/07 11:54:29,893 INFO BlockManagerMaster: Registering BlockManager BlockManagerId(driver, 10.1.2.142, 39400)
17/02/07 11:54:29,896 INFO BlockManagerMasterEndpoint: Registering block manager 10.1.2.142:39400 with 6.3 GB RAM, BlockManagerId(driver, 10.1.2.142, 39400)
17/02/07 11:54:29,900 INFO BlockManagerMaster: Registered BlockManager BlockManagerId(driver, 10.1.2.142, 39400)
17/02/07 11:54:29,925 INFO StandaloneAppClient$ClientEndpoint: Executor added: app-20170207115429-0000/0 on worker-20170207115342-10.1.2.250-37359 (10.1.2.250:37359) with 4 cores
17/02/07 11:54:29,926 INFO StandaloneSchedulerBackend: Granted executor ID app-20170207115429-0000/0 on hostPort 10.1.2.250:37359 with 4 cores, 11.2 GB RAM
17/02/07 11:54:29,927 INFO StandaloneAppClient$ClientEndpoint: Executor added: app-20170207115429-0000/1 on worker-20170207115341-10.1.2.207-44149 (10.1.2.207:44149) with 4 cores
17/02/07 11:54:29,927 INFO StandaloneSchedulerBackend: Granted executor ID app-20170207115429-0000/1 on hostPort 10.1.2.207:44149 with 4 cores, 11.2 GB RAM
17/02/07 11:54:29,928 INFO StandaloneAppClient$ClientEndpoint: Executor added: app-20170207115429-0000/2 on worker-20170207115341-10.1.2.189-39049 (10.1.2.189:39049) with 4 cores
17/02/07 11:54:29,928 INFO StandaloneSchedulerBackend: Granted executor ID app-20170207115429-0000/2 on hostPort 10.1.2.189:39049 with 4 cores, 11.2 GB RAM
17/02/07 11:54:29,930 INFO StandaloneAppClient$ClientEndpoint: Executor added: app-20170207115429-0000/3 on worker-20170207115341-10.1.2.115-44245 (10.1.2.115:44245) with 4 cores
17/02/07 11:54:29,930 INFO StandaloneSchedulerBackend: Granted executor ID app-20170207115429-0000/3 on hostPort 10.1.2.115:44245 with 4 cores, 11.2 GB RAM
17/02/07 11:54:29,931 INFO StandaloneAppClient$ClientEndpoint: Executor added: app-20170207115429-0000/4 on worker-20170207115341-10.1.2.108-40527 (10.1.2.108:40527) with 4 cores
17/02/07 11:54:29,932 INFO StandaloneSchedulerBackend: Granted executor ID app-20170207115429-0000/4 on hostPort 10.1.2.108:40527 with 4 cores, 11.2 GB RAM
17/02/07 11:54:29,933 INFO StandaloneAppClient$ClientEndpoint: Executor added: app-20170207115429-0000/5 on worker-20170207115342-10.1.2.188-36399 (10.1.2.188:36399) with 4 cores
17/02/07 11:54:29,934 INFO StandaloneSchedulerBackend: Granted executor ID app-20170207115429-0000/5 on hostPort 10.1.2.188:36399 with 4 cores, 11.2 GB RAM
17/02/07 11:54:29,935 INFO StandaloneAppClient$ClientEndpoint: Executor added: app-20170207115429-0000/6 on worker-20170207115341-10.1.2.90-35458 (10.1.2.90:35458) with 4 cores
17/02/07 11:54:29,935 INFO StandaloneSchedulerBackend: Granted executor ID app-20170207115429-0000/6 on hostPort 10.1.2.90:35458 with 4 cores, 11.2 GB RAM
17/02/07 11:54:29,937 INFO StandaloneAppClient$ClientEndpoint: Executor added: app-20170207115429-0000/7 on worker-20170207115341-10.1.2.62-33585 (10.1.2.62:33585) with 4 cores
17/02/07 11:54:29,937 INFO StandaloneSchedulerBackend: Granted executor ID app-20170207115429-0000/7 on hostPort 10.1.2.62:33585 with 4 cores, 11.2 GB RAM
17/02/07 11:54:29,944 INFO StandaloneAppClient$ClientEndpoint: Executor added: app-20170207115429-0000/8 on worker-20170207115341-10.1.2.211-45345 (10.1.2.211:45345) with 4 cores
17/02/07 11:54:29,944 INFO StandaloneSchedulerBackend: Granted executor ID app-20170207115429-0000/8 on hostPort 10.1.2.211:45345 with 4 cores, 11.2 GB RAM
17/02/07 11:54:29,944 INFO StandaloneAppClient$ClientEndpoint: Executor added: app-20170207115429-0000/9 on worker-20170207115344-10.1.2.149-35095 (10.1.2.149:35095) with 4 cores
17/02/07 11:54:29,945 INFO StandaloneSchedulerBackend: Granted executor ID app-20170207115429-0000/9 on hostPort 10.1.2.149:35095 with 4 cores, 11.2 GB RAM
17/02/07 11:54:29,945 INFO StandaloneAppClient$ClientEndpoint: Executor added: app-20170207115429-0000/10 on worker-20170207115341-10.1.2.157-34785 (10.1.2.157:34785) with 4 cores
17/02/07 11:54:29,946 INFO StandaloneSchedulerBackend: Granted executor ID app-20170207115429-0000/10 on hostPort 10.1.2.157:34785 with 4 cores, 11.2 GB RAM
17/02/07 11:54:29,946 INFO StandaloneAppClient$ClientEndpoint: Executor added: app-20170207115429-0000/11 on worker-20170207115343-10.1.2.214-42148 (10.1.2.214:42148) with 4 cores
17/02/07 11:54:29,947 INFO StandaloneSchedulerBackend: Granted executor ID app-20170207115429-0000/11 on hostPort 10.1.2.214:42148 with 4 cores, 11.2 GB RAM
17/02/07 11:54:29,947 INFO StandaloneAppClient$ClientEndpoint: Executor added: app-20170207115429-0000/12 on worker-20170207115340-10.1.2.35-38216 (10.1.2.35:38216) with 4 cores
17/02/07 11:54:29,948 INFO StandaloneSchedulerBackend: Granted executor ID app-20170207115429-0000/12 on hostPort 10.1.2.35:38216 with 4 cores, 11.2 GB RAM
17/02/07 11:54:29,948 INFO StandaloneAppClient$ClientEndpoint: Executor added: app-20170207115429-0000/13 on worker-20170207115347-10.1.2.37-34568 (10.1.2.37:34568) with 4 cores
17/02/07 11:54:29,949 INFO StandaloneSchedulerBackend: Granted executor ID app-20170207115429-0000/13 on hostPort 10.1.2.37:34568 with 4 cores, 11.2 GB RAM
17/02/07 11:54:29,949 INFO StandaloneAppClient$ClientEndpoint: Executor added: app-20170207115429-0000/14 on worker-20170207115341-10.1.2.253-44941 (10.1.2.253:44941) with 4 cores
17/02/07 11:54:29,950 INFO StandaloneSchedulerBackend: Granted executor ID app-20170207115429-0000/14 on hostPort 10.1.2.253:44941 with 4 cores, 11.2 GB RAM
17/02/07 11:54:29,950 INFO StandaloneAppClient$ClientEndpoint: Executor added: app-20170207115429-0000/15 on worker-20170207115343-10.1.2.96-42601 (10.1.2.96:42601) with 4 cores
17/02/07 11:54:29,951 INFO StandaloneSchedulerBackend: Granted executor ID app-20170207115429-0000/15 on hostPort 10.1.2.96:42601 with 4 cores, 11.2 GB RAM
17/02/07 11:54:29,999 INFO StandaloneAppClient$ClientEndpoint: Executor updated: app-20170207115429-0000/3 is now RUNNING
17/02/07 11:54:30,000 INFO StandaloneAppClient$ClientEndpoint: Executor updated: app-20170207115429-0000/1 is now RUNNING
17/02/07 11:54:30,000 INFO StandaloneAppClient$ClientEndpoint: Executor updated: app-20170207115429-0000/4 is now RUNNING
17/02/07 11:54:30,000 INFO StandaloneAppClient$ClientEndpoint: Executor updated: app-20170207115429-0000/8 is now RUNNING
17/02/07 11:54:30,002 INFO StandaloneAppClient$ClientEndpoint: Executor updated: app-20170207115429-0000/10 is now RUNNING
17/02/07 11:54:30,004 INFO StandaloneAppClient$ClientEndpoint: Executor updated: app-20170207115429-0000/6 is now RUNNING
17/02/07 11:54:30,007 INFO StandaloneAppClient$ClientEndpoint: Executor updated: app-20170207115429-0000/11 is now RUNNING
17/02/07 11:54:30,010 INFO StandaloneAppClient$ClientEndpoint: Executor updated: app-20170207115429-0000/9 is now RUNNING
17/02/07 11:54:30,014 INFO StandaloneAppClient$ClientEndpoint: Executor updated: app-20170207115429-0000/5 is now RUNNING
17/02/07 11:54:30,017 INFO StandaloneAppClient$ClientEndpoint: Executor updated: app-20170207115429-0000/0 is now RUNNING
17/02/07 11:54:30,019 INFO StandaloneAppClient$ClientEndpoint: Executor updated: app-20170207115429-0000/15 is now RUNNING
17/02/07 11:54:30,022 INFO StandaloneAppClient$ClientEndpoint: Executor updated: app-20170207115429-0000/14 is now RUNNING
17/02/07 11:54:30,024 INFO StandaloneAppClient$ClientEndpoint: Executor updated: app-20170207115429-0000/2 is now RUNNING
17/02/07 11:54:30,026 INFO StandaloneAppClient$ClientEndpoint: Executor updated: app-20170207115429-0000/7 is now RUNNING
17/02/07 11:54:30,028 INFO StandaloneAppClient$ClientEndpoint: Executor updated: app-20170207115429-0000/12 is now RUNNING
17/02/07 11:54:30,031 INFO StandaloneAppClient$ClientEndpoint: Executor updated: app-20170207115429-0000/13 is now RUNNING
17/02/07 11:54:30,151 INFO StandaloneSchedulerBackend: SchedulerBackend is ready for scheduling beginning after reached minRegisteredResourcesRatio: 0.0
17/02/07 11:54:30,675 INFO MemoryStore: Block broadcast_0 stored as values in memory (estimated size 130.8 KB, free 6.3 GB)
17/02/07 11:54:30,760 INFO MemoryStore: Block broadcast_0_piece0 stored as bytes in memory (estimated size 16.5 KB, free 6.3 GB)
17/02/07 11:54:30,764 INFO BlockManagerInfo: Added broadcast_0_piece0 in memory on 10.1.2.142:39400 (size: 16.5 KB, free: 6.3 GB)
17/02/07 11:54:30,773 INFO SparkContext: Created broadcast 0 from textFile at MLUtils.scala:99
17/02/07 11:54:31,836 INFO FileInputFormat: Total input paths to process : 1
17/02/07 11:54:31,938 INFO NetworkTopology: Adding a new node: /default-rack/10.1.2.90:50010
17/02/07 11:54:31,939 INFO NetworkTopology: Adding a new node: /default-rack/10.1.2.62:50010
17/02/07 11:54:31,939 INFO NetworkTopology: Adding a new node: /default-rack/10.1.2.35:50010
17/02/07 11:54:31,939 INFO NetworkTopology: Adding a new node: /default-rack/10.1.2.189:50010
17/02/07 11:54:31,939 INFO NetworkTopology: Adding a new node: /default-rack/10.1.2.207:50010
17/02/07 11:54:31,940 INFO NetworkTopology: Adding a new node: /default-rack/10.1.2.37:50010
17/02/07 11:54:31,940 INFO NetworkTopology: Adding a new node: /default-rack/10.1.2.115:50010
17/02/07 11:54:31,941 INFO NetworkTopology: Adding a new node: /default-rack/10.1.2.214:50010
17/02/07 11:54:31,941 INFO NetworkTopology: Adding a new node: /default-rack/10.1.2.250:50010
17/02/07 11:54:31,941 INFO NetworkTopology: Adding a new node: /default-rack/10.1.2.188:50010
17/02/07 11:54:31,941 INFO NetworkTopology: Adding a new node: /default-rack/10.1.2.157:50010
17/02/07 11:54:31,942 INFO NetworkTopology: Adding a new node: /default-rack/10.1.2.149:50010
17/02/07 11:54:31,942 INFO NetworkTopology: Adding a new node: /default-rack/10.1.2.211:50010
17/02/07 11:54:31,942 INFO NetworkTopology: Adding a new node: /default-rack/10.1.2.253:50010
17/02/07 11:54:31,942 INFO NetworkTopology: Adding a new node: /default-rack/10.1.2.96:50010
17/02/07 11:54:31,943 INFO NetworkTopology: Adding a new node: /default-rack/10.1.2.108:50010
17/02/07 11:54:32,003 INFO SparkContext: Starting job: first at GeneralizedLinearAlgorithm.scala:246
17/02/07 11:54:32,021 INFO DAGScheduler: Got job 0 (first at GeneralizedLinearAlgorithm.scala:246) with 1 output partitions
17/02/07 11:54:32,021 INFO DAGScheduler: Final stage: ResultStage 0 (first at GeneralizedLinearAlgorithm.scala:246)
17/02/07 11:54:32,022 INFO DAGScheduler: Parents of final stage: List()
17/02/07 11:54:32,029 INFO DAGScheduler: Missing parents: List()
17/02/07 11:54:32,040 INFO DAGScheduler: Submitting ResultStage 0 (MapPartitionsRDD[6] at map at GeneralizedLinearAlgorithm.scala:246), which has no missing parents
17/02/07 11:54:32,071 INFO MemoryStore: Block broadcast_1 stored as values in memory (estimated size 4.2 KB, free 6.3 GB)
17/02/07 11:54:32,077 INFO MemoryStore: Block broadcast_1_piece0 stored as bytes in memory (estimated size 2.4 KB, free 6.3 GB)
17/02/07 11:54:32,078 INFO BlockManagerInfo: Added broadcast_1_piece0 in memory on 10.1.2.142:39400 (size: 2.4 KB, free: 6.3 GB)
17/02/07 11:54:32,082 INFO SparkContext: Created broadcast 1 from broadcast at DAGScheduler.scala:1012
17/02/07 11:54:32,085 INFO DAGScheduler: Submitting 1 missing tasks from ResultStage 0 (MapPartitionsRDD[6] at map at GeneralizedLinearAlgorithm.scala:246)
17/02/07 11:54:32,086 INFO TaskSchedulerImpl: Adding task set 0.0 with 1 tasks
17/02/07 11:54:32,097 INFO CoarseGrainedSchedulerBackend$DriverEndpoint: Registered executor NettyRpcEndpointRef(null) (10.1.2.189:37802) with ID 2
17/02/07 11:54:32,149 INFO TaskSetManager: Starting task 0.0 in stage 0.0 (TID 0, 10.1.2.189, partition 0, ANY, 5456 bytes)
17/02/07 11:54:32,163 INFO BlockManagerMasterEndpoint: Registering block manager 10.1.2.189:44110 with 6.3 GB RAM, BlockManagerId(2, 10.1.2.189, 44110)
17/02/07 11:54:32,164 INFO CoarseGrainedSchedulerBackend$DriverEndpoint: Launching task 0 on executor id: 2 hostname: 10.1.2.189.
17/02/07 11:54:32,169 INFO CoarseGrainedSchedulerBackend$DriverEndpoint: Registered executor NettyRpcEndpointRef(null) (10.1.2.207:53398) with ID 1
17/02/07 11:54:32,171 INFO CoarseGrainedSchedulerBackend$DriverEndpoint: Registered executor NettyRpcEndpointRef(null) (10.1.2.250:38276) with ID 0
17/02/07 11:54:32,173 INFO CoarseGrainedSchedulerBackend$DriverEndpoint: Registered executor NettyRpcEndpointRef(null) (10.1.2.115:44904) with ID 3
17/02/07 11:54:32,174 INFO CoarseGrainedSchedulerBackend$DriverEndpoint: Registered executor NettyRpcEndpointRef(null) (10.1.2.90:46124) with ID 6
17/02/07 11:54:32,176 INFO CoarseGrainedSchedulerBackend$DriverEndpoint: Registered executor NettyRpcEndpointRef(null) (10.1.2.214:54904) with ID 11
17/02/07 11:54:32,177 INFO CoarseGrainedSchedulerBackend$DriverEndpoint: Registered executor NettyRpcEndpointRef(null) (10.1.2.157:34692) with ID 10
17/02/07 11:54:32,179 INFO CoarseGrainedSchedulerBackend$DriverEndpoint: Registered executor NettyRpcEndpointRef(null) (10.1.2.253:49428) with ID 14
17/02/07 11:54:32,181 INFO CoarseGrainedSchedulerBackend$DriverEndpoint: Registered executor NettyRpcEndpointRef(null) (10.1.2.35:56272) with ID 12
17/02/07 11:54:32,183 INFO CoarseGrainedSchedulerBackend$DriverEndpoint: Registered executor NettyRpcEndpointRef(null) (10.1.2.96:52040) with ID 15
17/02/07 11:54:32,191 INFO CoarseGrainedSchedulerBackend$DriverEndpoint: Registered executor NettyRpcEndpointRef(null) (10.1.2.108:34110) with ID 4
17/02/07 11:54:32,193 INFO CoarseGrainedSchedulerBackend$DriverEndpoint: Registered executor NettyRpcEndpointRef(null) (10.1.2.149:54912) with ID 9
17/02/07 11:54:32,196 INFO CoarseGrainedSchedulerBackend$DriverEndpoint: Registered executor NettyRpcEndpointRef(null) (10.1.2.188:56760) with ID 5
17/02/07 11:54:32,199 INFO CoarseGrainedSchedulerBackend$DriverEndpoint: Registered executor NettyRpcEndpointRef(null) (10.1.2.211:37216) with ID 8
17/02/07 11:54:32,202 INFO CoarseGrainedSchedulerBackend$DriverEndpoint: Registered executor NettyRpcEndpointRef(null) (10.1.2.62:56652) with ID 7
17/02/07 11:54:32,217 INFO BlockManagerMasterEndpoint: Registering block manager 10.1.2.207:35507 with 6.3 GB RAM, BlockManagerId(1, 10.1.2.207, 35507)
17/02/07 11:54:32,225 INFO BlockManagerMasterEndpoint: Registering block manager 10.1.2.157:33891 with 6.3 GB RAM, BlockManagerId(10, 10.1.2.157, 33891)
17/02/07 11:54:32,231 INFO BlockManagerMasterEndpoint: Registering block manager 10.1.2.214:42923 with 6.3 GB RAM, BlockManagerId(11, 10.1.2.214, 42923)
17/02/07 11:54:32,233 INFO BlockManagerMasterEndpoint: Registering block manager 10.1.2.90:41907 with 6.3 GB RAM, BlockManagerId(6, 10.1.2.90, 41907)
17/02/07 11:54:32,235 INFO BlockManagerMasterEndpoint: Registering block manager 10.1.2.115:36118 with 6.3 GB RAM, BlockManagerId(3, 10.1.2.115, 36118)
17/02/07 11:54:32,237 INFO CoarseGrainedSchedulerBackend$DriverEndpoint: Registered executor NettyRpcEndpointRef(null) (10.1.2.37:50390) with ID 13
17/02/07 11:54:32,238 INFO BlockManagerMasterEndpoint: Registering block manager 10.1.2.250:41300 with 6.3 GB RAM, BlockManagerId(0, 10.1.2.250, 41300)
17/02/07 11:54:32,241 INFO BlockManagerMasterEndpoint: Registering block manager 10.1.2.253:33411 with 6.3 GB RAM, BlockManagerId(14, 10.1.2.253, 33411)
17/02/07 11:54:32,243 INFO BlockManagerMasterEndpoint: Registering block manager 10.1.2.35:37955 with 6.3 GB RAM, BlockManagerId(12, 10.1.2.35, 37955)
17/02/07 11:54:32,244 INFO BlockManagerMasterEndpoint: Registering block manager 10.1.2.108:44508 with 6.3 GB RAM, BlockManagerId(4, 10.1.2.108, 44508)
17/02/07 11:54:32,245 INFO BlockManagerMasterEndpoint: Registering block manager 10.1.2.96:35345 with 6.3 GB RAM, BlockManagerId(15, 10.1.2.96, 35345)
17/02/07 11:54:32,249 INFO BlockManagerMasterEndpoint: Registering block manager 10.1.2.149:40201 with 6.3 GB RAM, BlockManagerId(9, 10.1.2.149, 40201)
17/02/07 11:54:32,260 INFO BlockManagerMasterEndpoint: Registering block manager 10.1.2.211:46771 with 6.3 GB RAM, BlockManagerId(8, 10.1.2.211, 46771)
17/02/07 11:54:32,261 INFO BlockManagerMasterEndpoint: Registering block manager 10.1.2.188:36014 with 6.3 GB RAM, BlockManagerId(5, 10.1.2.188, 36014)
17/02/07 11:54:32,263 INFO BlockManagerMasterEndpoint: Registering block manager 10.1.2.62:37738 with 6.3 GB RAM, BlockManagerId(7, 10.1.2.62, 37738)
17/02/07 11:54:32,293 INFO BlockManagerMasterEndpoint: Registering block manager 10.1.2.37:37810 with 6.3 GB RAM, BlockManagerId(13, 10.1.2.37, 37810)
17/02/07 11:54:32,500 INFO BlockManagerInfo: Added broadcast_1_piece0 in memory on 10.1.2.189:44110 (size: 2.4 KB, free: 6.3 GB)
17/02/07 11:54:32,663 INFO BlockManagerInfo: Added broadcast_0_piece0 in memory on 10.1.2.189:44110 (size: 16.5 KB, free: 6.3 GB)
17/02/07 11:54:39,837 INFO BlockManagerInfo: Added rdd_5_0 in memory on 10.1.2.189:44110 (size: 64.6 MB, free: 6.2 GB)
17/02/07 11:54:39,897 INFO DAGScheduler: ResultStage 0 (first at GeneralizedLinearAlgorithm.scala:246) finished in 7.796 s
17/02/07 11:54:39,897 INFO TaskSetManager: Finished task 0.0 in stage 0.0 (TID 0) in 7781 ms on 10.1.2.189 (1/1)
17/02/07 11:54:39,899 INFO TaskSchedulerImpl: Removed TaskSet 0.0, whose tasks have all completed, from pool 
17/02/07 11:54:39,907 INFO DAGScheduler: Job 0 finished: first at GeneralizedLinearAlgorithm.scala:246, took 7.903743 s
17/02/07 11:54:39,922 INFO SparkContext: Starting job: count at DataValidators.scala:40
17/02/07 11:54:39,924 INFO DAGScheduler: Got job 1 (count at DataValidators.scala:40) with 64 output partitions
17/02/07 11:54:39,924 INFO DAGScheduler: Final stage: ResultStage 1 (count at DataValidators.scala:40)
17/02/07 11:54:39,924 INFO DAGScheduler: Parents of final stage: List()
17/02/07 11:54:39,927 INFO DAGScheduler: Missing parents: List()
17/02/07 11:54:39,927 INFO DAGScheduler: Submitting ResultStage 1 (MapPartitionsRDD[7] at filter at DataValidators.scala:40), which has no missing parents
17/02/07 11:54:39,951 INFO MemoryStore: Block broadcast_2 stored as values in memory (estimated size 3.9 KB, free 6.3 GB)
17/02/07 11:54:39,957 INFO MemoryStore: Block broadcast_2_piece0 stored as bytes in memory (estimated size 2.2 KB, free 6.3 GB)
17/02/07 11:54:39,958 INFO BlockManagerInfo: Added broadcast_2_piece0 in memory on 10.1.2.142:39400 (size: 2.2 KB, free: 6.3 GB)
17/02/07 11:54:39,959 INFO SparkContext: Created broadcast 2 from broadcast at DAGScheduler.scala:1012
17/02/07 11:54:39,961 INFO DAGScheduler: Submitting 64 missing tasks from ResultStage 1 (MapPartitionsRDD[7] at filter at DataValidators.scala:40)
17/02/07 11:54:39,962 INFO TaskSchedulerImpl: Adding task set 1.0 with 64 tasks
17/02/07 11:54:39,968 INFO TaskSetManager: Starting task 0.0 in stage 1.0 (TID 1, 10.1.2.189, partition 0, PROCESS_LOCAL, 5374 bytes)
17/02/07 11:54:39,972 INFO TaskSetManager: Starting task 5.0 in stage 1.0 (TID 2, 10.1.2.149, partition 5, NODE_LOCAL, 5374 bytes)
17/02/07 11:54:39,977 INFO TaskSetManager: Starting task 4.0 in stage 1.0 (TID 3, 10.1.2.62, partition 4, NODE_LOCAL, 5374 bytes)
17/02/07 11:54:39,978 INFO TaskSetManager: Starting task 1.0 in stage 1.0 (TID 4, 10.1.2.189, partition 1, NODE_LOCAL, 5374 bytes)
17/02/07 11:54:39,980 INFO TaskSetManager: Starting task 2.0 in stage 1.0 (TID 5, 10.1.2.37, partition 2, NODE_LOCAL, 5374 bytes)
17/02/07 11:54:39,982 INFO TaskSetManager: Starting task 28.0 in stage 1.0 (TID 6, 10.1.2.188, partition 28, NODE_LOCAL, 5374 bytes)
17/02/07 11:54:39,983 INFO TaskSetManager: Starting task 11.0 in stage 1.0 (TID 7, 10.1.2.90, partition 11, NODE_LOCAL, 5374 bytes)
17/02/07 11:54:39,985 INFO TaskSetManager: Starting task 3.0 in stage 1.0 (TID 8, 10.1.2.115, partition 3, NODE_LOCAL, 5374 bytes)
17/02/07 11:54:39,987 INFO TaskSetManager: Starting task 8.0 in stage 1.0 (TID 9, 10.1.2.214, partition 8, NODE_LOCAL, 5374 bytes)
17/02/07 11:54:39,988 INFO TaskSetManager: Starting task 21.0 in stage 1.0 (TID 10, 10.1.2.35, partition 21, NODE_LOCAL, 5374 bytes)
17/02/07 11:54:39,991 INFO TaskSetManager: Starting task 6.0 in stage 1.0 (TID 11, 10.1.2.157, partition 6, NODE_LOCAL, 5374 bytes)
17/02/07 11:54:39,992 INFO TaskSetManager: Starting task 9.0 in stage 1.0 (TID 12, 10.1.2.96, partition 9, NODE_LOCAL, 5374 bytes)
17/02/07 11:54:39,997 INFO TaskSetManager: Starting task 18.0 in stage 1.0 (TID 13, 10.1.2.207, partition 18, NODE_LOCAL, 5374 bytes)
17/02/07 11:54:39,999 INFO TaskSetManager: Starting task 13.0 in stage 1.0 (TID 14, 10.1.2.108, partition 13, NODE_LOCAL, 5374 bytes)
17/02/07 11:54:40,000 INFO TaskSetManager: Starting task 16.0 in stage 1.0 (TID 15, 10.1.2.253, partition 16, NODE_LOCAL, 5374 bytes)
17/02/07 11:54:40,004 INFO TaskSetManager: Starting task 29.0 in stage 1.0 (TID 16, 10.1.2.211, partition 29, NODE_LOCAL, 5374 bytes)
17/02/07 11:54:40,005 INFO TaskSetManager: Starting task 15.0 in stage 1.0 (TID 17, 10.1.2.250, partition 15, NODE_LOCAL, 5374 bytes)
17/02/07 11:54:40,007 INFO TaskSetManager: Starting task 7.0 in stage 1.0 (TID 18, 10.1.2.149, partition 7, NODE_LOCAL, 5374 bytes)
17/02/07 11:54:40,009 INFO TaskSetManager: Starting task 20.0 in stage 1.0 (TID 19, 10.1.2.62, partition 20, NODE_LOCAL, 5374 bytes)
17/02/07 11:54:40,010 INFO TaskSetManager: Starting task 10.0 in stage 1.0 (TID 20, 10.1.2.189, partition 10, NODE_LOCAL, 5374 bytes)
17/02/07 11:54:40,012 INFO TaskSetManager: Starting task 17.0 in stage 1.0 (TID 21, 10.1.2.37, partition 17, NODE_LOCAL, 5374 bytes)
17/02/07 11:54:40,014 INFO TaskSetManager: Starting task 40.0 in stage 1.0 (TID 22, 10.1.2.188, partition 40, NODE_LOCAL, 5374 bytes)
17/02/07 11:54:40,015 INFO TaskSetManager: Starting task 27.0 in stage 1.0 (TID 23, 10.1.2.90, partition 27, NODE_LOCAL, 5374 bytes)
17/02/07 11:54:40,018 INFO TaskSetManager: Starting task 14.0 in stage 1.0 (TID 24, 10.1.2.115, partition 14, NODE_LOCAL, 5374 bytes)
17/02/07 11:54:40,019 INFO TaskSetManager: Starting task 19.0 in stage 1.0 (TID 25, 10.1.2.214, partition 19, NODE_LOCAL, 5374 bytes)
17/02/07 11:54:40,021 INFO TaskSetManager: Starting task 23.0 in stage 1.0 (TID 26, 10.1.2.35, partition 23, NODE_LOCAL, 5374 bytes)
17/02/07 11:54:40,023 INFO TaskSetManager: Starting task 22.0 in stage 1.0 (TID 27, 10.1.2.157, partition 22, NODE_LOCAL, 5374 bytes)
17/02/07 11:54:40,024 INFO TaskSetManager: Starting task 36.0 in stage 1.0 (TID 28, 10.1.2.96, partition 36, NODE_LOCAL, 5374 bytes)
17/02/07 11:54:40,026 INFO TaskSetManager: Starting task 24.0 in stage 1.0 (TID 29, 10.1.2.207, partition 24, NODE_LOCAL, 5374 bytes)
17/02/07 11:54:40,028 INFO TaskSetManager: Starting task 30.0 in stage 1.0 (TID 30, 10.1.2.108, partition 30, NODE_LOCAL, 5374 bytes)
17/02/07 11:54:40,029 INFO TaskSetManager: Starting task 26.0 in stage 1.0 (TID 31, 10.1.2.253, partition 26, NODE_LOCAL, 5374 bytes)
17/02/07 11:54:40,031 INFO TaskSetManager: Starting task 37.0 in stage 1.0 (TID 32, 10.1.2.211, partition 37, NODE_LOCAL, 5374 bytes)
17/02/07 11:54:40,033 INFO TaskSetManager: Starting task 33.0 in stage 1.0 (TID 33, 10.1.2.250, partition 33, NODE_LOCAL, 5374 bytes)
17/02/07 11:54:40,041 INFO TaskSetManager: Starting task 31.0 in stage 1.0 (TID 34, 10.1.2.149, partition 31, NODE_LOCAL, 5374 bytes)
17/02/07 11:54:40,043 INFO TaskSetManager: Starting task 41.0 in stage 1.0 (TID 35, 10.1.2.62, partition 41, NODE_LOCAL, 5374 bytes)
17/02/07 11:54:40,044 INFO TaskSetManager: Starting task 35.0 in stage 1.0 (TID 36, 10.1.2.189, partition 35, NODE_LOCAL, 5374 bytes)
17/02/07 11:54:40,046 INFO TaskSetManager: Starting task 39.0 in stage 1.0 (TID 37, 10.1.2.37, partition 39, NODE_LOCAL, 5374 bytes)
17/02/07 11:54:40,048 INFO TaskSetManager: Starting task 47.0 in stage 1.0 (TID 38, 10.1.2.188, partition 47, NODE_LOCAL, 5374 bytes)
17/02/07 11:54:40,050 INFO TaskSetManager: Starting task 48.0 in stage 1.0 (TID 39, 10.1.2.90, partition 48, NODE_LOCAL, 5374 bytes)
17/02/07 11:54:40,052 INFO TaskSetManager: Starting task 46.0 in stage 1.0 (TID 40, 10.1.2.115, partition 46, NODE_LOCAL, 5374 bytes)
17/02/07 11:54:40,054 INFO TaskSetManager: Starting task 32.0 in stage 1.0 (TID 41, 10.1.2.214, partition 32, NODE_LOCAL, 5374 bytes)
17/02/07 11:54:40,056 INFO TaskSetManager: Starting task 42.0 in stage 1.0 (TID 42, 10.1.2.35, partition 42, NODE_LOCAL, 5374 bytes)
17/02/07 11:54:40,058 INFO TaskSetManager: Starting task 44.0 in stage 1.0 (TID 43, 10.1.2.157, partition 44, NODE_LOCAL, 5374 bytes)
17/02/07 11:54:40,060 INFO TaskSetManager: Starting task 43.0 in stage 1.0 (TID 44, 10.1.2.96, partition 43, NODE_LOCAL, 5374 bytes)
17/02/07 11:54:40,061 INFO TaskSetManager: Starting task 34.0 in stage 1.0 (TID 45, 10.1.2.207, partition 34, NODE_LOCAL, 5374 bytes)
17/02/07 11:54:40,063 INFO TaskSetManager: Starting task 49.0 in stage 1.0 (TID 46, 10.1.2.108, partition 49, NODE_LOCAL, 5374 bytes)
17/02/07 11:54:40,065 INFO TaskSetManager: Starting task 45.0 in stage 1.0 (TID 47, 10.1.2.253, partition 45, NODE_LOCAL, 5374 bytes)
17/02/07 11:54:40,066 INFO TaskSetManager: Starting task 50.0 in stage 1.0 (TID 48, 10.1.2.211, partition 50, NODE_LOCAL, 5374 bytes)
17/02/07 11:54:40,068 INFO TaskSetManager: Starting task 56.0 in stage 1.0 (TID 49, 10.1.2.250, partition 56, NODE_LOCAL, 5374 bytes)
17/02/07 11:54:40,070 INFO TaskSetManager: Starting task 52.0 in stage 1.0 (TID 50, 10.1.2.62, partition 52, NODE_LOCAL, 5374 bytes)
17/02/07 11:54:40,072 INFO TaskSetManager: Starting task 59.0 in stage 1.0 (TID 51, 10.1.2.37, partition 59, NODE_LOCAL, 5374 bytes)
17/02/07 11:54:40,073 INFO TaskSetManager: Starting task 57.0 in stage 1.0 (TID 52, 10.1.2.188, partition 57, NODE_LOCAL, 5374 bytes)
17/02/07 11:54:40,075 INFO TaskSetManager: Starting task 54.0 in stage 1.0 (TID 53, 10.1.2.90, partition 54, NODE_LOCAL, 5374 bytes)
17/02/07 11:54:40,078 INFO TaskSetManager: Starting task 53.0 in stage 1.0 (TID 54, 10.1.2.115, partition 53, NODE_LOCAL, 5374 bytes)
17/02/07 11:54:40,080 INFO TaskSetManager: Starting task 58.0 in stage 1.0 (TID 55, 10.1.2.214, partition 58, NODE_LOCAL, 5374 bytes)
17/02/07 11:54:40,081 INFO TaskSetManager: Starting task 61.0 in stage 1.0 (TID 56, 10.1.2.35, partition 61, NODE_LOCAL, 5374 bytes)
17/02/07 11:54:40,082 INFO TaskSetManager: Starting task 55.0 in stage 1.0 (TID 57, 10.1.2.157, partition 55, NODE_LOCAL, 5374 bytes)
17/02/07 11:54:40,084 INFO TaskSetManager: Starting task 62.0 in stage 1.0 (TID 58, 10.1.2.207, partition 62, NODE_LOCAL, 5374 bytes)
17/02/07 11:54:40,085 INFO TaskSetManager: Starting task 60.0 in stage 1.0 (TID 59, 10.1.2.211, partition 60, NODE_LOCAL, 5374 bytes)
17/02/07 11:54:40,086 INFO CoarseGrainedSchedulerBackend$DriverEndpoint: Launching task 2 on executor id: 9 hostname: 10.1.2.149.
17/02/07 11:54:40,087 INFO CoarseGrainedSchedulerBackend$DriverEndpoint: Launching task 18 on executor id: 9 hostname: 10.1.2.149.
17/02/07 11:54:40,087 INFO CoarseGrainedSchedulerBackend$DriverEndpoint: Launching task 34 on executor id: 9 hostname: 10.1.2.149.
17/02/07 11:54:40,088 INFO CoarseGrainedSchedulerBackend$DriverEndpoint: Launching task 3 on executor id: 7 hostname: 10.1.2.62.
17/02/07 11:54:40,088 INFO CoarseGrainedSchedulerBackend$DriverEndpoint: Launching task 19 on executor id: 7 hostname: 10.1.2.62.
17/02/07 11:54:40,089 INFO CoarseGrainedSchedulerBackend$DriverEndpoint: Launching task 35 on executor id: 7 hostname: 10.1.2.62.
17/02/07 11:54:40,089 INFO CoarseGrainedSchedulerBackend$DriverEndpoint: Launching task 50 on executor id: 7 hostname: 10.1.2.62.
17/02/07 11:54:40,090 INFO CoarseGrainedSchedulerBackend$DriverEndpoint: Launching task 1 on executor id: 2 hostname: 10.1.2.189.
17/02/07 11:54:40,091 INFO CoarseGrainedSchedulerBackend$DriverEndpoint: Launching task 4 on executor id: 2 hostname: 10.1.2.189.
17/02/07 11:54:40,091 INFO CoarseGrainedSchedulerBackend$DriverEndpoint: Launching task 20 on executor id: 2 hostname: 10.1.2.189.
17/02/07 11:54:40,092 INFO CoarseGrainedSchedulerBackend$DriverEndpoint: Launching task 36 on executor id: 2 hostname: 10.1.2.189.
17/02/07 11:54:40,092 INFO CoarseGrainedSchedulerBackend$DriverEndpoint: Launching task 5 on executor id: 13 hostname: 10.1.2.37.
17/02/07 11:54:40,093 INFO CoarseGrainedSchedulerBackend$DriverEndpoint: Launching task 21 on executor id: 13 hostname: 10.1.2.37.
17/02/07 11:54:40,093 INFO CoarseGrainedSchedulerBackend$DriverEndpoint: Launching task 37 on executor id: 13 hostname: 10.1.2.37.
17/02/07 11:54:40,094 INFO CoarseGrainedSchedulerBackend$DriverEndpoint: Launching task 51 on executor id: 13 hostname: 10.1.2.37.
17/02/07 11:54:40,094 INFO CoarseGrainedSchedulerBackend$DriverEndpoint: Launching task 6 on executor id: 5 hostname: 10.1.2.188.
17/02/07 11:54:40,095 INFO CoarseGrainedSchedulerBackend$DriverEndpoint: Launching task 22 on executor id: 5 hostname: 10.1.2.188.
17/02/07 11:54:40,095 INFO CoarseGrainedSchedulerBackend$DriverEndpoint: Launching task 38 on executor id: 5 hostname: 10.1.2.188.
17/02/07 11:54:40,096 INFO CoarseGrainedSchedulerBackend$DriverEndpoint: Launching task 52 on executor id: 5 hostname: 10.1.2.188.
17/02/07 11:54:40,096 INFO CoarseGrainedSchedulerBackend$DriverEndpoint: Launching task 7 on executor id: 6 hostname: 10.1.2.90.
17/02/07 11:54:40,097 INFO CoarseGrainedSchedulerBackend$DriverEndpoint: Launching task 23 on executor id: 6 hostname: 10.1.2.90.
17/02/07 11:54:40,098 INFO CoarseGrainedSchedulerBackend$DriverEndpoint: Launching task 39 on executor id: 6 hostname: 10.1.2.90.
17/02/07 11:54:40,098 INFO CoarseGrainedSchedulerBackend$DriverEndpoint: Launching task 53 on executor id: 6 hostname: 10.1.2.90.
17/02/07 11:54:40,098 INFO CoarseGrainedSchedulerBackend$DriverEndpoint: Launching task 8 on executor id: 3 hostname: 10.1.2.115.
17/02/07 11:54:40,099 INFO CoarseGrainedSchedulerBackend$DriverEndpoint: Launching task 24 on executor id: 3 hostname: 10.1.2.115.
17/02/07 11:54:40,099 INFO CoarseGrainedSchedulerBackend$DriverEndpoint: Launching task 40 on executor id: 3 hostname: 10.1.2.115.
17/02/07 11:54:40,100 INFO CoarseGrainedSchedulerBackend$DriverEndpoint: Launching task 54 on executor id: 3 hostname: 10.1.2.115.
17/02/07 11:54:40,103 INFO CoarseGrainedSchedulerBackend$DriverEndpoint: Launching task 9 on executor id: 11 hostname: 10.1.2.214.
17/02/07 11:54:40,103 INFO CoarseGrainedSchedulerBackend$DriverEndpoint: Launching task 25 on executor id: 11 hostname: 10.1.2.214.
17/02/07 11:54:40,104 INFO CoarseGrainedSchedulerBackend$DriverEndpoint: Launching task 41 on executor id: 11 hostname: 10.1.2.214.
17/02/07 11:54:40,104 INFO CoarseGrainedSchedulerBackend$DriverEndpoint: Launching task 55 on executor id: 11 hostname: 10.1.2.214.
17/02/07 11:54:40,105 INFO CoarseGrainedSchedulerBackend$DriverEndpoint: Launching task 10 on executor id: 12 hostname: 10.1.2.35.
17/02/07 11:54:40,105 INFO CoarseGrainedSchedulerBackend$DriverEndpoint: Launching task 26 on executor id: 12 hostname: 10.1.2.35.
17/02/07 11:54:40,106 INFO CoarseGrainedSchedulerBackend$DriverEndpoint: Launching task 42 on executor id: 12 hostname: 10.1.2.35.
17/02/07 11:54:40,106 INFO CoarseGrainedSchedulerBackend$DriverEndpoint: Launching task 56 on executor id: 12 hostname: 10.1.2.35.
17/02/07 11:54:40,107 INFO CoarseGrainedSchedulerBackend$DriverEndpoint: Launching task 11 on executor id: 10 hostname: 10.1.2.157.
17/02/07 11:54:40,107 INFO CoarseGrainedSchedulerBackend$DriverEndpoint: Launching task 27 on executor id: 10 hostname: 10.1.2.157.
17/02/07 11:54:40,108 INFO CoarseGrainedSchedulerBackend$DriverEndpoint: Launching task 43 on executor id: 10 hostname: 10.1.2.157.
17/02/07 11:54:40,108 INFO CoarseGrainedSchedulerBackend$DriverEndpoint: Launching task 57 on executor id: 10 hostname: 10.1.2.157.
17/02/07 11:54:40,108 INFO CoarseGrainedSchedulerBackend$DriverEndpoint: Launching task 12 on executor id: 15 hostname: 10.1.2.96.
17/02/07 11:54:40,109 INFO CoarseGrainedSchedulerBackend$DriverEndpoint: Launching task 28 on executor id: 15 hostname: 10.1.2.96.
17/02/07 11:54:40,109 INFO CoarseGrainedSchedulerBackend$DriverEndpoint: Launching task 44 on executor id: 15 hostname: 10.1.2.96.
17/02/07 11:54:40,110 INFO CoarseGrainedSchedulerBackend$DriverEndpoint: Launching task 13 on executor id: 1 hostname: 10.1.2.207.
17/02/07 11:54:40,110 INFO CoarseGrainedSchedulerBackend$DriverEndpoint: Launching task 29 on executor id: 1 hostname: 10.1.2.207.
17/02/07 11:54:40,111 INFO CoarseGrainedSchedulerBackend$DriverEndpoint: Launching task 45 on executor id: 1 hostname: 10.1.2.207.
17/02/07 11:54:40,111 INFO CoarseGrainedSchedulerBackend$DriverEndpoint: Launching task 58 on executor id: 1 hostname: 10.1.2.207.
17/02/07 11:54:40,111 INFO CoarseGrainedSchedulerBackend$DriverEndpoint: Launching task 14 on executor id: 4 hostname: 10.1.2.108.
17/02/07 11:54:40,112 INFO CoarseGrainedSchedulerBackend$DriverEndpoint: Launching task 30 on executor id: 4 hostname: 10.1.2.108.
17/02/07 11:54:40,112 INFO CoarseGrainedSchedulerBackend$DriverEndpoint: Launching task 46 on executor id: 4 hostname: 10.1.2.108.
17/02/07 11:54:40,113 INFO CoarseGrainedSchedulerBackend$DriverEndpoint: Launching task 15 on executor id: 14 hostname: 10.1.2.253.
17/02/07 11:54:40,113 INFO CoarseGrainedSchedulerBackend$DriverEndpoint: Launching task 31 on executor id: 14 hostname: 10.1.2.253.
17/02/07 11:54:40,114 INFO CoarseGrainedSchedulerBackend$DriverEndpoint: Launching task 47 on executor id: 14 hostname: 10.1.2.253.
17/02/07 11:54:40,114 INFO CoarseGrainedSchedulerBackend$DriverEndpoint: Launching task 16 on executor id: 8 hostname: 10.1.2.211.
17/02/07 11:54:40,115 INFO CoarseGrainedSchedulerBackend$DriverEndpoint: Launching task 32 on executor id: 8 hostname: 10.1.2.211.
17/02/07 11:54:40,116 INFO CoarseGrainedSchedulerBackend$DriverEndpoint: Launching task 48 on executor id: 8 hostname: 10.1.2.211.
17/02/07 11:54:40,117 INFO CoarseGrainedSchedulerBackend$DriverEndpoint: Launching task 59 on executor id: 8 hostname: 10.1.2.211.
17/02/07 11:54:40,118 INFO CoarseGrainedSchedulerBackend$DriverEndpoint: Launching task 17 on executor id: 0 hostname: 10.1.2.250.
17/02/07 11:54:40,118 INFO CoarseGrainedSchedulerBackend$DriverEndpoint: Launching task 33 on executor id: 0 hostname: 10.1.2.250.
17/02/07 11:54:40,119 INFO CoarseGrainedSchedulerBackend$DriverEndpoint: Launching task 49 on executor id: 0 hostname: 10.1.2.250.
17/02/07 11:54:40,122 INFO BlockManagerInfo: Added broadcast_2_piece0 in memory on 10.1.2.189:44110 (size: 2.2 KB, free: 6.2 GB)
17/02/07 11:54:40,220 INFO TaskSetManager: Starting task 63.0 in stage 1.0 (TID 60, 10.1.2.189, partition 63, NODE_LOCAL, 5374 bytes)
17/02/07 11:54:40,221 INFO CoarseGrainedSchedulerBackend$DriverEndpoint: Launching task 60 on executor id: 2 hostname: 10.1.2.189.
17/02/07 11:54:40,222 INFO TaskSetManager: Finished task 0.0 in stage 1.0 (TID 1) in 256 ms on 10.1.2.189 (1/64)
17/02/07 11:54:40,481 INFO BlockManagerInfo: Added broadcast_2_piece0 in memory on 10.1.2.37:37810 (size: 2.2 KB, free: 6.3 GB)
17/02/07 11:54:40,491 INFO BlockManagerInfo: Added broadcast_2_piece0 in memory on 10.1.2.157:33891 (size: 2.2 KB, free: 6.3 GB)
17/02/07 11:54:40,507 INFO BlockManagerInfo: Added broadcast_2_piece0 in memory on 10.1.2.62:37738 (size: 2.2 KB, free: 6.3 GB)
17/02/07 11:54:40,508 INFO BlockManagerInfo: Added broadcast_2_piece0 in memory on 10.1.2.253:33411 (size: 2.2 KB, free: 6.3 GB)
17/02/07 11:54:40,510 INFO BlockManagerInfo: Added broadcast_2_piece0 in memory on 10.1.2.188:36014 (size: 2.2 KB, free: 6.3 GB)
17/02/07 11:54:40,514 INFO BlockManagerInfo: Added broadcast_2_piece0 in memory on 10.1.2.149:40201 (size: 2.2 KB, free: 6.3 GB)
17/02/07 11:54:40,517 INFO BlockManagerInfo: Added broadcast_2_piece0 in memory on 10.1.2.96:35345 (size: 2.2 KB, free: 6.3 GB)
17/02/07 11:54:40,518 INFO BlockManagerInfo: Added broadcast_2_piece0 in memory on 10.1.2.207:35507 (size: 2.2 KB, free: 6.3 GB)
17/02/07 11:54:40,523 INFO BlockManagerInfo: Added broadcast_2_piece0 in memory on 10.1.2.90:41907 (size: 2.2 KB, free: 6.3 GB)
17/02/07 11:54:40,525 INFO BlockManagerInfo: Added broadcast_2_piece0 in memory on 10.1.2.108:44508 (size: 2.2 KB, free: 6.3 GB)
17/02/07 11:54:40,533 INFO BlockManagerInfo: Added broadcast_2_piece0 in memory on 10.1.2.211:46771 (size: 2.2 KB, free: 6.3 GB)
17/02/07 11:54:40,539 INFO BlockManagerInfo: Added broadcast_2_piece0 in memory on 10.1.2.35:37955 (size: 2.2 KB, free: 6.3 GB)
17/02/07 11:54:40,548 INFO BlockManagerInfo: Added broadcast_2_piece0 in memory on 10.1.2.214:42923 (size: 2.2 KB, free: 6.3 GB)
17/02/07 11:54:40,557 INFO BlockManagerInfo: Added broadcast_2_piece0 in memory on 10.1.2.250:41300 (size: 2.2 KB, free: 6.3 GB)
17/02/07 11:54:40,559 INFO BlockManagerInfo: Added broadcast_2_piece0 in memory on 10.1.2.115:36118 (size: 2.2 KB, free: 6.3 GB)
17/02/07 11:54:40,682 INFO BlockManagerInfo: Added broadcast_0_piece0 in memory on 10.1.2.37:37810 (size: 16.5 KB, free: 6.3 GB)
17/02/07 11:54:40,683 INFO BlockManagerInfo: Added broadcast_0_piece0 in memory on 10.1.2.157:33891 (size: 16.5 KB, free: 6.3 GB)
17/02/07 11:54:40,700 INFO BlockManagerInfo: Added broadcast_0_piece0 in memory on 10.1.2.62:37738 (size: 16.5 KB, free: 6.3 GB)
17/02/07 11:54:40,710 INFO BlockManagerInfo: Added broadcast_0_piece0 in memory on 10.1.2.149:40201 (size: 16.5 KB, free: 6.3 GB)
17/02/07 11:54:40,722 INFO BlockManagerInfo: Added broadcast_0_piece0 in memory on 10.1.2.96:35345 (size: 16.5 KB, free: 6.3 GB)
17/02/07 11:54:40,744 INFO BlockManagerInfo: Added broadcast_0_piece0 in memory on 10.1.2.214:42923 (size: 16.5 KB, free: 6.3 GB)
17/02/07 11:54:40,756 INFO BlockManagerInfo: Added broadcast_0_piece0 in memory on 10.1.2.108:44508 (size: 16.5 KB, free: 6.3 GB)
17/02/07 11:54:40,763 INFO BlockManagerInfo: Added broadcast_0_piece0 in memory on 10.1.2.253:33411 (size: 16.5 KB, free: 6.3 GB)
17/02/07 11:54:40,764 INFO BlockManagerInfo: Added broadcast_0_piece0 in memory on 10.1.2.35:37955 (size: 16.5 KB, free: 6.3 GB)
17/02/07 11:54:40,766 INFO BlockManagerInfo: Added broadcast_0_piece0 in memory on 10.1.2.90:41907 (size: 16.5 KB, free: 6.3 GB)
17/02/07 11:54:40,768 INFO BlockManagerInfo: Added broadcast_0_piece0 in memory on 10.1.2.115:36118 (size: 16.5 KB, free: 6.3 GB)
17/02/07 11:54:40,781 INFO BlockManagerInfo: Added broadcast_0_piece0 in memory on 10.1.2.207:35507 (size: 16.5 KB, free: 6.3 GB)
17/02/07 11:54:40,783 INFO BlockManagerInfo: Added broadcast_0_piece0 in memory on 10.1.2.250:41300 (size: 16.5 KB, free: 6.3 GB)
17/02/07 11:54:40,821 INFO BlockManagerInfo: Added broadcast_0_piece0 in memory on 10.1.2.188:36014 (size: 16.5 KB, free: 6.3 GB)
17/02/07 11:54:40,835 INFO BlockManagerInfo: Added broadcast_0_piece0 in memory on 10.1.2.211:46771 (size: 16.5 KB, free: 6.3 GB)
17/02/07 11:54:43,678 INFO TaskSetManager: Starting task 12.0 in stage 1.0 (TID 61, 10.1.2.250, partition 12, ANY, 5374 bytes)
17/02/07 11:54:43,679 INFO TaskSetManager: Starting task 25.0 in stage 1.0 (TID 62, 10.1.2.253, partition 25, ANY, 5374 bytes)
17/02/07 11:54:43,681 INFO TaskSetManager: Starting task 38.0 in stage 1.0 (TID 63, 10.1.2.108, partition 38, ANY, 5374 bytes)
17/02/07 11:54:43,683 INFO TaskSetManager: Starting task 51.0 in stage 1.0 (TID 64, 10.1.2.149, partition 51, ANY, 5374 bytes)
17/02/07 11:54:43,684 INFO CoarseGrainedSchedulerBackend$DriverEndpoint: Launching task 61 on executor id: 0 hostname: 10.1.2.250.
17/02/07 11:54:43,684 INFO CoarseGrainedSchedulerBackend$DriverEndpoint: Launching task 62 on executor id: 14 hostname: 10.1.2.253.
17/02/07 11:54:43,686 INFO CoarseGrainedSchedulerBackend$DriverEndpoint: Launching task 63 on executor id: 4 hostname: 10.1.2.108.
17/02/07 11:54:43,687 INFO CoarseGrainedSchedulerBackend$DriverEndpoint: Launching task 64 on executor id: 9 hostname: 10.1.2.149.
17/02/07 11:54:55,593 INFO BlockManagerInfo: Added rdd_5_36 in memory on 10.1.2.96:35345 (size: 64.6 MB, free: 6.2 GB)
17/02/07 11:54:55,629 INFO BlockManagerInfo: Added rdd_5_43 in memory on 10.1.2.96:35345 (size: 64.6 MB, free: 6.2 GB)
17/02/07 11:54:55,705 INFO TaskSetManager: Finished task 36.0 in stage 1.0 (TID 28) in 15681 ms on 10.1.2.96 (2/64)
17/02/07 11:54:55,714 INFO TaskSetManager: Finished task 43.0 in stage 1.0 (TID 44) in 15653 ms on 10.1.2.96 (3/64)
17/02/07 11:54:56,064 INFO BlockManagerInfo: Added rdd_5_9 in memory on 10.1.2.96:35345 (size: 64.5 MB, free: 6.1 GB)
17/02/07 11:54:56,089 INFO TaskSetManager: Finished task 9.0 in stage 1.0 (TID 12) in 16097 ms on 10.1.2.96 (4/64)
17/02/07 11:54:57,002 INFO BlockManagerInfo: Added rdd_5_35 in memory on 10.1.2.189:44110 (size: 64.5 MB, free: 6.2 GB)
17/02/07 11:54:57,037 INFO TaskSetManager: Finished task 35.0 in stage 1.0 (TID 36) in 16994 ms on 10.1.2.189 (5/64)
17/02/07 11:54:57,321 INFO BlockManagerInfo: Added rdd_5_10 in memory on 10.1.2.189:44110 (size: 64.5 MB, free: 6.1 GB)
17/02/07 11:54:57,341 INFO TaskSetManager: Finished task 10.0 in stage 1.0 (TID 20) in 17332 ms on 10.1.2.189 (6/64)
17/02/07 11:54:57,593 INFO BlockManagerInfo: Added rdd_5_63 in memory on 10.1.2.189:44110 (size: 64.5 MB, free: 6.0 GB)
17/02/07 11:54:57,613 INFO TaskSetManager: Finished task 63.0 in stage 1.0 (TID 60) in 17394 ms on 10.1.2.189 (7/64)
17/02/07 11:54:57,684 INFO BlockManagerInfo: Added rdd_5_1 in memory on 10.1.2.189:44110 (size: 64.5 MB, free: 6.0 GB)
17/02/07 11:54:57,701 INFO TaskSetManager: Finished task 1.0 in stage 1.0 (TID 4) in 17723 ms on 10.1.2.189 (8/64)
17/02/07 11:54:58,040 INFO BlockManagerInfo: Added rdd_5_42 in memory on 10.1.2.35:37955 (size: 64.5 MB, free: 6.2 GB)
17/02/07 11:54:58,079 INFO BlockManagerInfo: Added rdd_5_27 in memory on 10.1.2.90:41907 (size: 64.5 MB, free: 6.2 GB)
17/02/07 11:54:58,109 INFO TaskSetManager: Finished task 42.0 in stage 1.0 (TID 42) in 18055 ms on 10.1.2.35 (9/64)
17/02/07 11:54:58,171 INFO TaskSetManager: Finished task 27.0 in stage 1.0 (TID 23) in 18156 ms on 10.1.2.90 (10/64)
17/02/07 11:54:58,178 INFO BlockManagerInfo: Added rdd_5_48 in memory on 10.1.2.90:41907 (size: 64.5 MB, free: 6.2 GB)
17/02/07 11:54:58,199 INFO TaskSetManager: Finished task 48.0 in stage 1.0 (TID 39) in 18150 ms on 10.1.2.90 (11/64)
17/02/07 11:54:58,213 INFO BlockManagerInfo: Added rdd_5_54 in memory on 10.1.2.90:41907 (size: 64.5 MB, free: 6.1 GB)
17/02/07 11:54:58,254 INFO BlockManagerInfo: Added rdd_5_19 in memory on 10.1.2.214:42923 (size: 64.5 MB, free: 6.2 GB)
17/02/07 11:54:58,258 INFO TaskSetManager: Finished task 54.0 in stage 1.0 (TID 53) in 18184 ms on 10.1.2.90 (12/64)
17/02/07 11:54:58,269 INFO BlockManagerInfo: Added rdd_5_61 in memory on 10.1.2.35:37955 (size: 64.6 MB, free: 6.2 GB)
17/02/07 11:54:58,286 INFO TaskSetManager: Finished task 61.0 in stage 1.0 (TID 56) in 18205 ms on 10.1.2.35 (13/64)
17/02/07 11:54:58,307 INFO BlockManagerInfo: Added rdd_5_11 in memory on 10.1.2.90:41907 (size: 64.6 MB, free: 6.0 GB)
17/02/07 11:54:58,325 INFO TaskSetManager: Finished task 11.0 in stage 1.0 (TID 7) in 18343 ms on 10.1.2.90 (14/64)
17/02/07 11:54:58,332 INFO TaskSetManager: Finished task 19.0 in stage 1.0 (TID 25) in 18314 ms on 10.1.2.214 (15/64)
17/02/07 11:54:58,508 INFO BlockManagerInfo: Added rdd_5_59 in memory on 10.1.2.37:37810 (size: 64.5 MB, free: 6.2 GB)
17/02/07 11:54:58,574 INFO TaskSetManager: Finished task 59.0 in stage 1.0 (TID 51) in 18503 ms on 10.1.2.37 (16/64)
17/02/07 11:54:58,655 INFO BlockManagerInfo: Added rdd_5_39 in memory on 10.1.2.37:37810 (size: 64.5 MB, free: 6.2 GB)
17/02/07 11:54:58,658 INFO BlockManagerInfo: Added rdd_5_23 in memory on 10.1.2.35:37955 (size: 64.5 MB, free: 6.1 GB)
17/02/07 11:54:58,677 INFO TaskSetManager: Finished task 23.0 in stage 1.0 (TID 26) in 18657 ms on 10.1.2.35 (17/64)
17/02/07 11:54:58,679 INFO TaskSetManager: Finished task 39.0 in stage 1.0 (TID 37) in 18635 ms on 10.1.2.37 (18/64)
17/02/07 11:54:58,809 INFO BlockManagerInfo: Added rdd_5_56 in memory on 10.1.2.250:41300 (size: 64.7 MB, free: 6.2 GB)
17/02/07 11:54:58,862 INFO BlockManagerInfo: Added rdd_5_21 in memory on 10.1.2.35:37955 (size: 64.5 MB, free: 6.0 GB)
17/02/07 11:54:58,875 INFO TaskSetManager: Finished task 56.0 in stage 1.0 (TID 49) in 18807 ms on 10.1.2.250 (19/64)
17/02/07 11:54:58,879 INFO TaskSetManager: Finished task 21.0 in stage 1.0 (TID 10) in 18892 ms on 10.1.2.35 (20/64)
17/02/07 11:54:58,900 INFO BlockManagerInfo: Added rdd_5_15 in memory on 10.1.2.250:41300 (size: 64.5 MB, free: 6.2 GB)
17/02/07 11:54:58,917 INFO TaskSetManager: Finished task 15.0 in stage 1.0 (TID 17) in 18913 ms on 10.1.2.250 (21/64)
17/02/07 11:54:58,958 INFO BlockManagerInfo: Added rdd_5_2 in memory on 10.1.2.37:37810 (size: 64.6 MB, free: 6.1 GB)
17/02/07 11:54:58,971 INFO BlockManagerInfo: Added rdd_5_17 in memory on 10.1.2.37:37810 (size: 64.5 MB, free: 6.0 GB)
17/02/07 11:54:58,978 INFO TaskSetManager: Finished task 2.0 in stage 1.0 (TID 5) in 19000 ms on 10.1.2.37 (22/64)
17/02/07 11:54:58,990 INFO TaskSetManager: Finished task 17.0 in stage 1.0 (TID 21) in 18979 ms on 10.1.2.37 (23/64)
17/02/07 11:54:59,039 INFO BlockManagerInfo: Added rdd_5_24 in memory on 10.1.2.207:35507 (size: 64.4 MB, free: 6.2 GB)
17/02/07 11:54:59,053 INFO BlockManagerInfo: Added rdd_5_3 in memory on 10.1.2.115:36118 (size: 64.5 MB, free: 6.2 GB)
17/02/07 11:54:59,105 INFO BlockManagerInfo: Added rdd_5_8 in memory on 10.1.2.214:42923 (size: 64.6 MB, free: 6.2 GB)
17/02/07 11:54:59,109 INFO TaskSetManager: Finished task 24.0 in stage 1.0 (TID 29) in 19083 ms on 10.1.2.207 (24/64)
17/02/07 11:54:59,126 INFO TaskSetManager: Finished task 8.0 in stage 1.0 (TID 9) in 19141 ms on 10.1.2.214 (25/64)
17/02/07 11:54:59,144 INFO TaskSetManager: Finished task 3.0 in stage 1.0 (TID 8) in 19160 ms on 10.1.2.115 (26/64)
17/02/07 11:54:59,159 INFO BlockManagerInfo: Added rdd_5_16 in memory on 10.1.2.253:33411 (size: 64.6 MB, free: 6.2 GB)
17/02/07 11:54:59,224 INFO TaskSetManager: Finished task 16.0 in stage 1.0 (TID 15) in 19225 ms on 10.1.2.253 (27/64)
17/02/07 11:54:59,226 INFO BlockManagerInfo: Added rdd_5_32 in memory on 10.1.2.214:42923 (size: 64.6 MB, free: 6.1 GB)
17/02/07 11:54:59,247 INFO BlockManagerInfo: Added rdd_5_37 in memory on 10.1.2.211:46771 (size: 64.5 MB, free: 6.2 GB)
17/02/07 11:54:59,265 INFO TaskSetManager: Finished task 32.0 in stage 1.0 (TID 41) in 19213 ms on 10.1.2.214 (28/64)
17/02/07 11:54:59,289 INFO BlockManagerInfo: Added rdd_5_29 in memory on 10.1.2.211:46771 (size: 64.5 MB, free: 6.2 GB)
17/02/07 11:54:59,289 INFO BlockManagerInfo: Added rdd_5_58 in memory on 10.1.2.214:42923 (size: 64.6 MB, free: 6.0 GB)
17/02/07 11:54:59,306 INFO TaskSetManager: Finished task 58.0 in stage 1.0 (TID 55) in 19227 ms on 10.1.2.214 (29/64)
17/02/07 11:54:59,328 INFO TaskSetManager: Finished task 29.0 in stage 1.0 (TID 16) in 19327 ms on 10.1.2.211 (30/64)
17/02/07 11:54:59,330 INFO BlockManagerInfo: Added rdd_5_33 in memory on 10.1.2.250:41300 (size: 64.4 MB, free: 6.1 GB)
17/02/07 11:54:59,330 INFO TaskSetManager: Finished task 37.0 in stage 1.0 (TID 32) in 19299 ms on 10.1.2.211 (31/64)
17/02/07 11:54:59,350 INFO TaskSetManager: Finished task 33.0 in stage 1.0 (TID 33) in 19318 ms on 10.1.2.250 (32/64)
17/02/07 11:54:59,367 INFO BlockManagerInfo: Added rdd_5_26 in memory on 10.1.2.253:33411 (size: 64.4 MB, free: 6.2 GB)
17/02/07 11:54:59,386 INFO TaskSetManager: Finished task 26.0 in stage 1.0 (TID 31) in 19358 ms on 10.1.2.253 (33/64)
17/02/07 11:54:59,545 INFO BlockManagerInfo: Added rdd_5_18 in memory on 10.1.2.207:35507 (size: 64.6 MB, free: 6.2 GB)
17/02/07 11:54:59,550 INFO BlockManagerInfo: Added rdd_5_45 in memory on 10.1.2.253:33411 (size: 64.4 MB, free: 6.1 GB)
17/02/07 11:54:59,559 INFO TaskSetManager: Finished task 18.0 in stage 1.0 (TID 13) in 19565 ms on 10.1.2.207 (34/64)
17/02/07 11:54:59,584 INFO TaskSetManager: Finished task 45.0 in stage 1.0 (TID 47) in 19520 ms on 10.1.2.253 (35/64)
17/02/07 11:54:59,657 INFO BlockManagerInfo: Added rdd_5_60 in memory on 10.1.2.211:46771 (size: 64.5 MB, free: 6.1 GB)
17/02/07 11:54:59,658 INFO BlockManagerInfo: Added rdd_5_5 in memory on 10.1.2.149:40201 (size: 64.5 MB, free: 6.2 GB)
17/02/07 11:54:59,673 INFO TaskSetManager: Finished task 60.0 in stage 1.0 (TID 59) in 19589 ms on 10.1.2.211 (36/64)
17/02/07 11:54:59,675 INFO BlockManagerInfo: Added rdd_5_12 in memory on 10.1.2.250:41300 (size: 64.6 MB, free: 6.0 GB)
17/02/07 11:54:59,681 INFO BlockManagerInfo: Added rdd_5_50 in memory on 10.1.2.211:46771 (size: 64.3 MB, free: 6.0 GB)
17/02/07 11:54:59,682 INFO BlockManagerInfo: Added rdd_5_62 in memory on 10.1.2.207:35507 (size: 64.5 MB, free: 6.1 GB)
17/02/07 11:54:59,691 INFO TaskSetManager: Finished task 12.0 in stage 1.0 (TID 61) in 16013 ms on 10.1.2.250 (37/64)
17/02/07 11:54:59,697 INFO TaskSetManager: Finished task 50.0 in stage 1.0 (TID 48) in 19632 ms on 10.1.2.211 (38/64)
17/02/07 11:54:59,706 INFO TaskSetManager: Finished task 62.0 in stage 1.0 (TID 58) in 19622 ms on 10.1.2.207 (39/64)
17/02/07 11:54:59,723 INFO TaskSetManager: Finished task 5.0 in stage 1.0 (TID 2) in 19753 ms on 10.1.2.149 (40/64)
17/02/07 11:54:59,772 INFO BlockManagerInfo: Added rdd_5_7 in memory on 10.1.2.149:40201 (size: 64.5 MB, free: 6.2 GB)
17/02/07 11:54:59,784 INFO BlockManagerInfo: Added rdd_5_31 in memory on 10.1.2.149:40201 (size: 64.6 MB, free: 6.1 GB)
17/02/07 11:54:59,785 INFO BlockManagerInfo: Added rdd_5_34 in memory on 10.1.2.207:35507 (size: 64.6 MB, free: 6.0 GB)
17/02/07 11:54:59,794 INFO TaskSetManager: Finished task 7.0 in stage 1.0 (TID 18) in 19788 ms on 10.1.2.149 (41/64)
17/02/07 11:54:59,800 INFO TaskSetManager: Finished task 31.0 in stage 1.0 (TID 34) in 19767 ms on 10.1.2.149 (42/64)
17/02/07 11:54:59,802 INFO TaskSetManager: Finished task 34.0 in stage 1.0 (TID 45) in 19742 ms on 10.1.2.207 (43/64)
17/02/07 11:54:59,950 INFO BlockManagerInfo: Added rdd_5_49 in memory on 10.1.2.108:44508 (size: 64.5 MB, free: 6.2 GB)
17/02/07 11:54:59,980 INFO BlockManagerInfo: Added rdd_5_30 in memory on 10.1.2.108:44508 (size: 64.5 MB, free: 6.2 GB)
17/02/07 11:55:00,030 INFO BlockManagerInfo: Added rdd_5_46 in memory on 10.1.2.115:36118 (size: 64.5 MB, free: 6.2 GB)
17/02/07 11:55:00,045 INFO TaskSetManager: Finished task 30.0 in stage 1.0 (TID 30) in 20019 ms on 10.1.2.108 (44/64)
17/02/07 11:55:00,048 INFO TaskSetManager: Finished task 49.0 in stage 1.0 (TID 46) in 19986 ms on 10.1.2.108 (45/64)
17/02/07 11:55:00,060 INFO TaskSetManager: Finished task 46.0 in stage 1.0 (TID 40) in 20010 ms on 10.1.2.115 (46/64)
17/02/07 11:55:00,168 INFO BlockManagerInfo: Added rdd_5_14 in memory on 10.1.2.115:36118 (size: 64.6 MB, free: 6.1 GB)
17/02/07 11:55:00,211 INFO TaskSetManager: Finished task 14.0 in stage 1.0 (TID 24) in 20196 ms on 10.1.2.115 (47/64)
17/02/07 11:55:00,272 INFO BlockManagerInfo: Added rdd_5_51 in memory on 10.1.2.149:40201 (size: 64.6 MB, free: 6.0 GB)
17/02/07 11:55:00,293 INFO TaskSetManager: Finished task 51.0 in stage 1.0 (TID 64) in 16611 ms on 10.1.2.149 (48/64)
17/02/07 11:55:00,310 INFO BlockManagerInfo: Added rdd_5_57 in memory on 10.1.2.188:36014 (size: 64.6 MB, free: 6.2 GB)
17/02/07 11:55:00,333 INFO BlockManagerInfo: Added rdd_5_53 in memory on 10.1.2.115:36118 (size: 64.6 MB, free: 6.0 GB)
17/02/07 11:55:00,349 INFO TaskSetManager: Finished task 53.0 in stage 1.0 (TID 54) in 20272 ms on 10.1.2.115 (49/64)
17/02/07 11:55:00,380 INFO TaskSetManager: Finished task 57.0 in stage 1.0 (TID 52) in 20308 ms on 10.1.2.188 (50/64)
17/02/07 11:55:00,540 INFO BlockManagerInfo: Added rdd_5_25 in memory on 10.1.2.253:33411 (size: 64.5 MB, free: 6.0 GB)
17/02/07 11:55:00,555 INFO TaskSetManager: Finished task 25.0 in stage 1.0 (TID 62) in 16877 ms on 10.1.2.253 (51/64)
17/02/07 11:55:00,657 INFO BlockManagerInfo: Added rdd_5_47 in memory on 10.1.2.188:36014 (size: 64.5 MB, free: 6.2 GB)
17/02/07 11:55:00,686 INFO TaskSetManager: Finished task 47.0 in stage 1.0 (TID 38) in 20640 ms on 10.1.2.188 (52/64)
17/02/07 11:55:00,697 INFO BlockManagerInfo: Added rdd_5_38 in memory on 10.1.2.108:44508 (size: 64.4 MB, free: 6.1 GB)
17/02/07 11:55:00,715 INFO TaskSetManager: Finished task 38.0 in stage 1.0 (TID 63) in 17036 ms on 10.1.2.108 (53/64)
17/02/07 11:55:00,777 INFO BlockManagerInfo: Added rdd_5_13 in memory on 10.1.2.108:44508 (size: 64.6 MB, free: 6.0 GB)
17/02/07 11:55:00,795 INFO TaskSetManager: Finished task 13.0 in stage 1.0 (TID 14) in 20798 ms on 10.1.2.108 (54/64)
17/02/07 11:55:00,831 INFO BlockManagerInfo: Added rdd_5_4 in memory on 10.1.2.62:37738 (size: 64.6 MB, free: 6.2 GB)
17/02/07 11:55:00,902 INFO TaskSetManager: Finished task 4.0 in stage 1.0 (TID 3) in 20930 ms on 10.1.2.62 (55/64)
17/02/07 11:55:00,923 INFO BlockManagerInfo: Added rdd_5_52 in memory on 10.1.2.62:37738 (size: 64.5 MB, free: 6.2 GB)
17/02/07 11:55:00,939 INFO TaskSetManager: Finished task 52.0 in stage 1.0 (TID 50) in 20870 ms on 10.1.2.62 (56/64)
17/02/07 11:55:01,130 INFO BlockManagerInfo: Added rdd_5_40 in memory on 10.1.2.188:36014 (size: 64.5 MB, free: 6.1 GB)
17/02/07 11:55:01,132 INFO BlockManagerInfo: Added rdd_5_20 in memory on 10.1.2.62:37738 (size: 64.5 MB, free: 6.1 GB)
17/02/07 11:55:01,155 INFO TaskSetManager: Finished task 40.0 in stage 1.0 (TID 22) in 21143 ms on 10.1.2.188 (57/64)
17/02/07 11:55:01,168 INFO TaskSetManager: Finished task 20.0 in stage 1.0 (TID 19) in 21160 ms on 10.1.2.62 (58/64)
17/02/07 11:55:01,172 INFO BlockManagerInfo: Added rdd_5_28 in memory on 10.1.2.188:36014 (size: 64.4 MB, free: 6.0 GB)
17/02/07 11:55:01,187 INFO TaskSetManager: Finished task 28.0 in stage 1.0 (TID 6) in 21207 ms on 10.1.2.188 (59/64)
17/02/07 11:55:01,247 INFO BlockManagerInfo: Added rdd_5_41 in memory on 10.1.2.62:37738 (size: 64.5 MB, free: 6.0 GB)
17/02/07 11:55:01,263 INFO TaskSetManager: Finished task 41.0 in stage 1.0 (TID 35) in 21221 ms on 10.1.2.62 (60/64)
17/02/07 11:55:03,725 INFO BlockManagerInfo: Added rdd_5_22 in memory on 10.1.2.157:33891 (size: 64.5 MB, free: 6.2 GB)
17/02/07 11:55:03,788 INFO TaskSetManager: Finished task 22.0 in stage 1.0 (TID 27) in 23767 ms on 10.1.2.157 (61/64)
17/02/07 11:55:03,859 INFO BlockManagerInfo: Added rdd_5_44 in memory on 10.1.2.157:33891 (size: 64.4 MB, free: 6.2 GB)
17/02/07 11:55:03,880 INFO TaskSetManager: Finished task 44.0 in stage 1.0 (TID 43) in 23823 ms on 10.1.2.157 (62/64)
17/02/07 11:55:04,337 INFO BlockManagerInfo: Added rdd_5_55 in memory on 10.1.2.157:33891 (size: 64.5 MB, free: 6.1 GB)
17/02/07 11:55:04,380 INFO TaskSetManager: Finished task 55.0 in stage 1.0 (TID 57) in 24299 ms on 10.1.2.157 (63/64)
17/02/07 11:55:04,411 INFO BlockManagerInfo: Added rdd_5_6 in memory on 10.1.2.157:33891 (size: 64.5 MB, free: 6.0 GB)
17/02/07 11:55:04,425 INFO TaskSetManager: Finished task 6.0 in stage 1.0 (TID 11) in 24436 ms on 10.1.2.157 (64/64)
17/02/07 11:55:04,425 INFO TaskSchedulerImpl: Removed TaskSet 1.0, whose tasks have all completed, from pool 
17/02/07 11:55:04,426 INFO DAGScheduler: ResultStage 1 (count at DataValidators.scala:40) finished in 24.459 s
17/02/07 11:55:04,426 INFO DAGScheduler: Job 1 finished: count at DataValidators.scala:40, took 24.503291 s
17/02/07 11:55:04,446 INFO SparkContext: Starting job: count at GradientDescent.scala:209
17/02/07 11:55:04,448 INFO DAGScheduler: Got job 2 (count at GradientDescent.scala:209) with 64 output partitions
17/02/07 11:55:04,448 INFO DAGScheduler: Final stage: ResultStage 2 (count at GradientDescent.scala:209)
17/02/07 11:55:04,448 INFO DAGScheduler: Parents of final stage: List()
17/02/07 11:55:04,451 INFO DAGScheduler: Missing parents: List()
17/02/07 11:55:04,451 INFO DAGScheduler: Submitting ResultStage 2 (MapPartitionsRDD[8] at map at GeneralizedLinearAlgorithm.scala:297), which has no missing parents
17/02/07 11:55:04,457 INFO MemoryStore: Block broadcast_3 stored as values in memory (estimated size 3.9 KB, free 6.3 GB)
17/02/07 11:55:04,461 INFO MemoryStore: Block broadcast_3_piece0 stored as bytes in memory (estimated size 2.2 KB, free 6.3 GB)
17/02/07 11:55:04,462 INFO BlockManagerInfo: Added broadcast_3_piece0 in memory on 10.1.2.142:39400 (size: 2.2 KB, free: 6.3 GB)
17/02/07 11:55:04,462 INFO SparkContext: Created broadcast 3 from broadcast at DAGScheduler.scala:1012
17/02/07 11:55:04,464 INFO DAGScheduler: Submitting 64 missing tasks from ResultStage 2 (MapPartitionsRDD[8] at map at GeneralizedLinearAlgorithm.scala:297)
17/02/07 11:55:04,464 INFO TaskSchedulerImpl: Adding task set 2.0 with 64 tasks
17/02/07 11:55:04,468 INFO TaskSetManager: Starting task 3.0 in stage 2.0 (TID 65, 10.1.2.115, partition 3, PROCESS_LOCAL, 5374 bytes)
17/02/07 11:55:04,469 INFO TaskSetManager: Starting task 28.0 in stage 2.0 (TID 66, 10.1.2.188, partition 28, PROCESS_LOCAL, 5374 bytes)
17/02/07 11:55:04,470 INFO TaskSetManager: Starting task 5.0 in stage 2.0 (TID 67, 10.1.2.149, partition 5, PROCESS_LOCAL, 5374 bytes)
17/02/07 11:55:04,471 INFO TaskSetManager: Starting task 29.0 in stage 2.0 (TID 68, 10.1.2.211, partition 29, PROCESS_LOCAL, 5374 bytes)
17/02/07 11:55:04,472 INFO TaskSetManager: Starting task 16.0 in stage 2.0 (TID 69, 10.1.2.253, partition 16, PROCESS_LOCAL, 5374 bytes)
17/02/07 11:55:04,473 INFO TaskSetManager: Starting task 6.0 in stage 2.0 (TID 70, 10.1.2.157, partition 6, PROCESS_LOCAL, 5374 bytes)
17/02/07 11:55:04,474 INFO TaskSetManager: Starting task 2.0 in stage 2.0 (TID 71, 10.1.2.37, partition 2, PROCESS_LOCAL, 5374 bytes)
17/02/07 11:55:04,474 INFO TaskSetManager: Starting task 13.0 in stage 2.0 (TID 72, 10.1.2.108, partition 13, PROCESS_LOCAL, 5374 bytes)
17/02/07 11:55:04,475 INFO TaskSetManager: Starting task 4.0 in stage 2.0 (TID 73, 10.1.2.62, partition 4, PROCESS_LOCAL, 5374 bytes)
17/02/07 11:55:04,476 INFO TaskSetManager: Starting task 9.0 in stage 2.0 (TID 74, 10.1.2.96, partition 9, PROCESS_LOCAL, 5374 bytes)
17/02/07 11:55:04,477 INFO TaskSetManager: Starting task 8.0 in stage 2.0 (TID 75, 10.1.2.214, partition 8, PROCESS_LOCAL, 5374 bytes)
17/02/07 11:55:04,478 INFO TaskSetManager: Starting task 12.0 in stage 2.0 (TID 76, 10.1.2.250, partition 12, PROCESS_LOCAL, 5374 bytes)
17/02/07 11:55:04,479 INFO TaskSetManager: Starting task 11.0 in stage 2.0 (TID 77, 10.1.2.90, partition 11, PROCESS_LOCAL, 5374 bytes)
17/02/07 11:55:04,480 INFO TaskSetManager: Starting task 18.0 in stage 2.0 (TID 78, 10.1.2.207, partition 18, PROCESS_LOCAL, 5374 bytes)
17/02/07 11:55:04,481 INFO TaskSetManager: Starting task 0.0 in stage 2.0 (TID 79, 10.1.2.189, partition 0, PROCESS_LOCAL, 5374 bytes)
17/02/07 11:55:04,481 INFO TaskSetManager: Starting task 21.0 in stage 2.0 (TID 80, 10.1.2.35, partition 21, PROCESS_LOCAL, 5374 bytes)
17/02/07 11:55:04,482 INFO TaskSetManager: Starting task 14.0 in stage 2.0 (TID 81, 10.1.2.115, partition 14, PROCESS_LOCAL, 5374 bytes)
17/02/07 11:55:04,484 INFO TaskSetManager: Starting task 40.0 in stage 2.0 (TID 82, 10.1.2.188, partition 40, PROCESS_LOCAL, 5374 bytes)
17/02/07 11:55:04,484 INFO TaskSetManager: Starting task 7.0 in stage 2.0 (TID 83, 10.1.2.149, partition 7, PROCESS_LOCAL, 5374 bytes)
17/02/07 11:55:04,485 INFO TaskSetManager: Starting task 37.0 in stage 2.0 (TID 84, 10.1.2.211, partition 37, PROCESS_LOCAL, 5374 bytes)
17/02/07 11:55:04,486 INFO TaskSetManager: Starting task 25.0 in stage 2.0 (TID 85, 10.1.2.253, partition 25, PROCESS_LOCAL, 5374 bytes)
17/02/07 11:55:04,487 INFO TaskSetManager: Starting task 22.0 in stage 2.0 (TID 86, 10.1.2.157, partition 22, PROCESS_LOCAL, 5374 bytes)
17/02/07 11:55:04,488 INFO TaskSetManager: Starting task 17.0 in stage 2.0 (TID 87, 10.1.2.37, partition 17, PROCESS_LOCAL, 5374 bytes)
17/02/07 11:55:04,489 INFO TaskSetManager: Starting task 30.0 in stage 2.0 (TID 88, 10.1.2.108, partition 30, PROCESS_LOCAL, 5374 bytes)
17/02/07 11:55:04,489 INFO TaskSetManager: Starting task 20.0 in stage 2.0 (TID 89, 10.1.2.62, partition 20, PROCESS_LOCAL, 5374 bytes)
17/02/07 11:55:04,490 INFO TaskSetManager: Starting task 36.0 in stage 2.0 (TID 90, 10.1.2.96, partition 36, PROCESS_LOCAL, 5374 bytes)
17/02/07 11:55:04,491 INFO TaskSetManager: Starting task 19.0 in stage 2.0 (TID 91, 10.1.2.214, partition 19, PROCESS_LOCAL, 5374 bytes)
17/02/07 11:55:04,492 INFO TaskSetManager: Starting task 15.0 in stage 2.0 (TID 92, 10.1.2.250, partition 15, PROCESS_LOCAL, 5374 bytes)
17/02/07 11:55:04,493 INFO TaskSetManager: Starting task 27.0 in stage 2.0 (TID 93, 10.1.2.90, partition 27, PROCESS_LOCAL, 5374 bytes)
17/02/07 11:55:04,494 INFO TaskSetManager: Starting task 24.0 in stage 2.0 (TID 94, 10.1.2.207, partition 24, PROCESS_LOCAL, 5374 bytes)
17/02/07 11:55:04,498 INFO TaskSetManager: Starting task 1.0 in stage 2.0 (TID 95, 10.1.2.189, partition 1, PROCESS_LOCAL, 5374 bytes)
17/02/07 11:55:04,499 INFO TaskSetManager: Starting task 23.0 in stage 2.0 (TID 96, 10.1.2.35, partition 23, PROCESS_LOCAL, 5374 bytes)
17/02/07 11:55:04,500 INFO TaskSetManager: Starting task 46.0 in stage 2.0 (TID 97, 10.1.2.115, partition 46, PROCESS_LOCAL, 5374 bytes)
17/02/07 11:55:04,501 INFO TaskSetManager: Starting task 47.0 in stage 2.0 (TID 98, 10.1.2.188, partition 47, PROCESS_LOCAL, 5374 bytes)
17/02/07 11:55:04,503 INFO TaskSetManager: Starting task 31.0 in stage 2.0 (TID 99, 10.1.2.149, partition 31, PROCESS_LOCAL, 5374 bytes)
17/02/07 11:55:04,504 INFO TaskSetManager: Starting task 50.0 in stage 2.0 (TID 100, 10.1.2.211, partition 50, PROCESS_LOCAL, 5374 bytes)
17/02/07 11:55:04,505 INFO TaskSetManager: Starting task 26.0 in stage 2.0 (TID 101, 10.1.2.253, partition 26, PROCESS_LOCAL, 5374 bytes)
17/02/07 11:55:04,506 INFO TaskSetManager: Starting task 44.0 in stage 2.0 (TID 102, 10.1.2.157, partition 44, PROCESS_LOCAL, 5374 bytes)
17/02/07 11:55:04,507 INFO TaskSetManager: Starting task 39.0 in stage 2.0 (TID 103, 10.1.2.37, partition 39, PROCESS_LOCAL, 5374 bytes)
17/02/07 11:55:04,508 INFO TaskSetManager: Starting task 38.0 in stage 2.0 (TID 104, 10.1.2.108, partition 38, PROCESS_LOCAL, 5374 bytes)
17/02/07 11:55:04,509 INFO TaskSetManager: Starting task 41.0 in stage 2.0 (TID 105, 10.1.2.62, partition 41, PROCESS_LOCAL, 5374 bytes)
17/02/07 11:55:04,510 INFO TaskSetManager: Starting task 43.0 in stage 2.0 (TID 106, 10.1.2.96, partition 43, PROCESS_LOCAL, 5374 bytes)
17/02/07 11:55:04,511 INFO TaskSetManager: Starting task 32.0 in stage 2.0 (TID 107, 10.1.2.214, partition 32, PROCESS_LOCAL, 5374 bytes)
17/02/07 11:55:04,512 INFO TaskSetManager: Starting task 33.0 in stage 2.0 (TID 108, 10.1.2.250, partition 33, PROCESS_LOCAL, 5374 bytes)
17/02/07 11:55:04,513 INFO TaskSetManager: Starting task 48.0 in stage 2.0 (TID 109, 10.1.2.90, partition 48, PROCESS_LOCAL, 5374 bytes)
17/02/07 11:55:04,514 INFO TaskSetManager: Starting task 34.0 in stage 2.0 (TID 110, 10.1.2.207, partition 34, PROCESS_LOCAL, 5374 bytes)
17/02/07 11:55:04,515 INFO TaskSetManager: Starting task 10.0 in stage 2.0 (TID 111, 10.1.2.189, partition 10, PROCESS_LOCAL, 5374 bytes)
17/02/07 11:55:04,516 INFO TaskSetManager: Starting task 42.0 in stage 2.0 (TID 112, 10.1.2.35, partition 42, PROCESS_LOCAL, 5374 bytes)
17/02/07 11:55:04,517 INFO TaskSetManager: Starting task 53.0 in stage 2.0 (TID 113, 10.1.2.115, partition 53, PROCESS_LOCAL, 5374 bytes)
17/02/07 11:55:04,518 INFO TaskSetManager: Starting task 57.0 in stage 2.0 (TID 114, 10.1.2.188, partition 57, PROCESS_LOCAL, 5374 bytes)
17/02/07 11:55:04,519 INFO TaskSetManager: Starting task 51.0 in stage 2.0 (TID 115, 10.1.2.149, partition 51, PROCESS_LOCAL, 5374 bytes)
17/02/07 11:55:04,520 INFO TaskSetManager: Starting task 60.0 in stage 2.0 (TID 116, 10.1.2.211, partition 60, PROCESS_LOCAL, 5374 bytes)
17/02/07 11:55:04,521 INFO TaskSetManager: Starting task 45.0 in stage 2.0 (TID 117, 10.1.2.253, partition 45, PROCESS_LOCAL, 5374 bytes)
17/02/07 11:55:04,522 INFO TaskSetManager: Starting task 55.0 in stage 2.0 (TID 118, 10.1.2.157, partition 55, PROCESS_LOCAL, 5374 bytes)
17/02/07 11:55:04,523 INFO TaskSetManager: Starting task 59.0 in stage 2.0 (TID 119, 10.1.2.37, partition 59, PROCESS_LOCAL, 5374 bytes)
17/02/07 11:55:04,524 INFO TaskSetManager: Starting task 49.0 in stage 2.0 (TID 120, 10.1.2.108, partition 49, PROCESS_LOCAL, 5374 bytes)
17/02/07 11:55:04,524 INFO TaskSetManager: Starting task 52.0 in stage 2.0 (TID 121, 10.1.2.62, partition 52, PROCESS_LOCAL, 5374 bytes)
17/02/07 11:55:04,525 INFO TaskSetManager: Starting task 58.0 in stage 2.0 (TID 122, 10.1.2.214, partition 58, PROCESS_LOCAL, 5374 bytes)
17/02/07 11:55:04,526 INFO TaskSetManager: Starting task 56.0 in stage 2.0 (TID 123, 10.1.2.250, partition 56, PROCESS_LOCAL, 5374 bytes)
17/02/07 11:55:04,527 INFO TaskSetManager: Starting task 54.0 in stage 2.0 (TID 124, 10.1.2.90, partition 54, PROCESS_LOCAL, 5374 bytes)
17/02/07 11:55:04,527 INFO TaskSetManager: Starting task 62.0 in stage 2.0 (TID 125, 10.1.2.207, partition 62, PROCESS_LOCAL, 5374 bytes)
17/02/07 11:55:04,528 INFO TaskSetManager: Starting task 35.0 in stage 2.0 (TID 126, 10.1.2.189, partition 35, PROCESS_LOCAL, 5374 bytes)
17/02/07 11:55:04,529 INFO TaskSetManager: Starting task 61.0 in stage 2.0 (TID 127, 10.1.2.35, partition 61, PROCESS_LOCAL, 5374 bytes)
17/02/07 11:55:04,529 INFO CoarseGrainedSchedulerBackend$DriverEndpoint: Launching task 65 on executor id: 3 hostname: 10.1.2.115.
17/02/07 11:55:04,530 INFO CoarseGrainedSchedulerBackend$DriverEndpoint: Launching task 81 on executor id: 3 hostname: 10.1.2.115.
17/02/07 11:55:04,530 INFO CoarseGrainedSchedulerBackend$DriverEndpoint: Launching task 97 on executor id: 3 hostname: 10.1.2.115.
17/02/07 11:55:04,530 INFO CoarseGrainedSchedulerBackend$DriverEndpoint: Launching task 113 on executor id: 3 hostname: 10.1.2.115.
17/02/07 11:55:04,531 INFO CoarseGrainedSchedulerBackend$DriverEndpoint: Launching task 66 on executor id: 5 hostname: 10.1.2.188.
17/02/07 11:55:04,531 INFO CoarseGrainedSchedulerBackend$DriverEndpoint: Launching task 82 on executor id: 5 hostname: 10.1.2.188.
17/02/07 11:55:04,531 INFO CoarseGrainedSchedulerBackend$DriverEndpoint: Launching task 98 on executor id: 5 hostname: 10.1.2.188.
17/02/07 11:55:04,535 INFO CoarseGrainedSchedulerBackend$DriverEndpoint: Launching task 114 on executor id: 5 hostname: 10.1.2.188.
17/02/07 11:55:04,535 INFO CoarseGrainedSchedulerBackend$DriverEndpoint: Launching task 67 on executor id: 9 hostname: 10.1.2.149.
17/02/07 11:55:04,535 INFO CoarseGrainedSchedulerBackend$DriverEndpoint: Launching task 83 on executor id: 9 hostname: 10.1.2.149.
17/02/07 11:55:04,536 INFO CoarseGrainedSchedulerBackend$DriverEndpoint: Launching task 99 on executor id: 9 hostname: 10.1.2.149.
17/02/07 11:55:04,536 INFO CoarseGrainedSchedulerBackend$DriverEndpoint: Launching task 115 on executor id: 9 hostname: 10.1.2.149.
17/02/07 11:55:04,536 INFO CoarseGrainedSchedulerBackend$DriverEndpoint: Launching task 68 on executor id: 8 hostname: 10.1.2.211.
17/02/07 11:55:04,537 INFO CoarseGrainedSchedulerBackend$DriverEndpoint: Launching task 84 on executor id: 8 hostname: 10.1.2.211.
17/02/07 11:55:04,537 INFO CoarseGrainedSchedulerBackend$DriverEndpoint: Launching task 100 on executor id: 8 hostname: 10.1.2.211.
17/02/07 11:55:04,537 INFO CoarseGrainedSchedulerBackend$DriverEndpoint: Launching task 116 on executor id: 8 hostname: 10.1.2.211.
17/02/07 11:55:04,538 INFO CoarseGrainedSchedulerBackend$DriverEndpoint: Launching task 69 on executor id: 14 hostname: 10.1.2.253.
17/02/07 11:55:04,538 INFO CoarseGrainedSchedulerBackend$DriverEndpoint: Launching task 85 on executor id: 14 hostname: 10.1.2.253.
17/02/07 11:55:04,538 INFO CoarseGrainedSchedulerBackend$DriverEndpoint: Launching task 101 on executor id: 14 hostname: 10.1.2.253.
17/02/07 11:55:04,538 INFO CoarseGrainedSchedulerBackend$DriverEndpoint: Launching task 117 on executor id: 14 hostname: 10.1.2.253.
17/02/07 11:55:04,539 INFO CoarseGrainedSchedulerBackend$DriverEndpoint: Launching task 70 on executor id: 10 hostname: 10.1.2.157.
17/02/07 11:55:04,539 INFO CoarseGrainedSchedulerBackend$DriverEndpoint: Launching task 86 on executor id: 10 hostname: 10.1.2.157.
17/02/07 11:55:04,540 INFO CoarseGrainedSchedulerBackend$DriverEndpoint: Launching task 102 on executor id: 10 hostname: 10.1.2.157.
17/02/07 11:55:04,540 INFO CoarseGrainedSchedulerBackend$DriverEndpoint: Launching task 118 on executor id: 10 hostname: 10.1.2.157.
17/02/07 11:55:04,541 INFO CoarseGrainedSchedulerBackend$DriverEndpoint: Launching task 71 on executor id: 13 hostname: 10.1.2.37.
17/02/07 11:55:04,541 INFO CoarseGrainedSchedulerBackend$DriverEndpoint: Launching task 87 on executor id: 13 hostname: 10.1.2.37.
17/02/07 11:55:04,541 INFO CoarseGrainedSchedulerBackend$DriverEndpoint: Launching task 103 on executor id: 13 hostname: 10.1.2.37.
17/02/07 11:55:04,542 INFO CoarseGrainedSchedulerBackend$DriverEndpoint: Launching task 119 on executor id: 13 hostname: 10.1.2.37.
17/02/07 11:55:04,542 INFO CoarseGrainedSchedulerBackend$DriverEndpoint: Launching task 72 on executor id: 4 hostname: 10.1.2.108.
17/02/07 11:55:04,542 INFO CoarseGrainedSchedulerBackend$DriverEndpoint: Launching task 88 on executor id: 4 hostname: 10.1.2.108.
17/02/07 11:55:04,543 INFO CoarseGrainedSchedulerBackend$DriverEndpoint: Launching task 104 on executor id: 4 hostname: 10.1.2.108.
17/02/07 11:55:04,543 INFO CoarseGrainedSchedulerBackend$DriverEndpoint: Launching task 120 on executor id: 4 hostname: 10.1.2.108.
17/02/07 11:55:04,544 INFO CoarseGrainedSchedulerBackend$DriverEndpoint: Launching task 73 on executor id: 7 hostname: 10.1.2.62.
17/02/07 11:55:04,544 INFO CoarseGrainedSchedulerBackend$DriverEndpoint: Launching task 89 on executor id: 7 hostname: 10.1.2.62.
17/02/07 11:55:04,545 INFO CoarseGrainedSchedulerBackend$DriverEndpoint: Launching task 105 on executor id: 7 hostname: 10.1.2.62.
17/02/07 11:55:04,545 INFO CoarseGrainedSchedulerBackend$DriverEndpoint: Launching task 121 on executor id: 7 hostname: 10.1.2.62.
17/02/07 11:55:04,546 INFO CoarseGrainedSchedulerBackend$DriverEndpoint: Launching task 74 on executor id: 15 hostname: 10.1.2.96.
17/02/07 11:55:04,546 INFO CoarseGrainedSchedulerBackend$DriverEndpoint: Launching task 90 on executor id: 15 hostname: 10.1.2.96.
17/02/07 11:55:04,550 INFO CoarseGrainedSchedulerBackend$DriverEndpoint: Launching task 106 on executor id: 15 hostname: 10.1.2.96.
17/02/07 11:55:04,550 INFO CoarseGrainedSchedulerBackend$DriverEndpoint: Launching task 75 on executor id: 11 hostname: 10.1.2.214.
17/02/07 11:55:04,550 INFO CoarseGrainedSchedulerBackend$DriverEndpoint: Launching task 91 on executor id: 11 hostname: 10.1.2.214.
17/02/07 11:55:04,551 INFO CoarseGrainedSchedulerBackend$DriverEndpoint: Launching task 107 on executor id: 11 hostname: 10.1.2.214.
17/02/07 11:55:04,551 INFO CoarseGrainedSchedulerBackend$DriverEndpoint: Launching task 122 on executor id: 11 hostname: 10.1.2.214.
17/02/07 11:55:04,551 INFO CoarseGrainedSchedulerBackend$DriverEndpoint: Launching task 76 on executor id: 0 hostname: 10.1.2.250.
17/02/07 11:55:04,551 INFO CoarseGrainedSchedulerBackend$DriverEndpoint: Launching task 92 on executor id: 0 hostname: 10.1.2.250.
17/02/07 11:55:04,552 INFO CoarseGrainedSchedulerBackend$DriverEndpoint: Launching task 108 on executor id: 0 hostname: 10.1.2.250.
17/02/07 11:55:04,552 INFO CoarseGrainedSchedulerBackend$DriverEndpoint: Launching task 123 on executor id: 0 hostname: 10.1.2.250.
17/02/07 11:55:04,552 INFO CoarseGrainedSchedulerBackend$DriverEndpoint: Launching task 77 on executor id: 6 hostname: 10.1.2.90.
17/02/07 11:55:04,552 INFO CoarseGrainedSchedulerBackend$DriverEndpoint: Launching task 93 on executor id: 6 hostname: 10.1.2.90.
17/02/07 11:55:04,553 INFO CoarseGrainedSchedulerBackend$DriverEndpoint: Launching task 109 on executor id: 6 hostname: 10.1.2.90.
17/02/07 11:55:04,553 INFO CoarseGrainedSchedulerBackend$DriverEndpoint: Launching task 124 on executor id: 6 hostname: 10.1.2.90.
17/02/07 11:55:04,553 INFO CoarseGrainedSchedulerBackend$DriverEndpoint: Launching task 78 on executor id: 1 hostname: 10.1.2.207.
17/02/07 11:55:04,553 INFO CoarseGrainedSchedulerBackend$DriverEndpoint: Launching task 94 on executor id: 1 hostname: 10.1.2.207.
17/02/07 11:55:04,554 INFO CoarseGrainedSchedulerBackend$DriverEndpoint: Launching task 110 on executor id: 1 hostname: 10.1.2.207.
17/02/07 11:55:04,554 INFO CoarseGrainedSchedulerBackend$DriverEndpoint: Launching task 125 on executor id: 1 hostname: 10.1.2.207.
17/02/07 11:55:04,554 INFO CoarseGrainedSchedulerBackend$DriverEndpoint: Launching task 79 on executor id: 2 hostname: 10.1.2.189.
17/02/07 11:55:04,554 INFO CoarseGrainedSchedulerBackend$DriverEndpoint: Launching task 95 on executor id: 2 hostname: 10.1.2.189.
17/02/07 11:55:04,555 INFO CoarseGrainedSchedulerBackend$DriverEndpoint: Launching task 111 on executor id: 2 hostname: 10.1.2.189.
17/02/07 11:55:04,555 INFO CoarseGrainedSchedulerBackend$DriverEndpoint: Launching task 126 on executor id: 2 hostname: 10.1.2.189.
17/02/07 11:55:04,555 INFO CoarseGrainedSchedulerBackend$DriverEndpoint: Launching task 80 on executor id: 12 hostname: 10.1.2.35.
17/02/07 11:55:04,555 INFO CoarseGrainedSchedulerBackend$DriverEndpoint: Launching task 96 on executor id: 12 hostname: 10.1.2.35.
17/02/07 11:55:04,555 INFO CoarseGrainedSchedulerBackend$DriverEndpoint: Launching task 112 on executor id: 12 hostname: 10.1.2.35.
17/02/07 11:55:04,556 INFO CoarseGrainedSchedulerBackend$DriverEndpoint: Launching task 127 on executor id: 12 hostname: 10.1.2.35.
17/02/07 11:55:04,563 INFO BlockManagerInfo: Added broadcast_3_piece0 in memory on 10.1.2.188:36014 (size: 2.2 KB, free: 6.0 GB)
17/02/07 11:55:04,565 INFO BlockManagerInfo: Added broadcast_3_piece0 in memory on 10.1.2.115:36118 (size: 2.2 KB, free: 6.0 GB)
17/02/07 11:55:04,570 INFO BlockManagerInfo: Added broadcast_3_piece0 in memory on 10.1.2.157:33891 (size: 2.2 KB, free: 6.0 GB)
17/02/07 11:55:04,581 INFO BlockManagerInfo: Added broadcast_3_piece0 in memory on 10.1.2.253:33411 (size: 2.2 KB, free: 6.0 GB)
17/02/07 11:55:04,582 INFO BlockManagerInfo: Added broadcast_3_piece0 in memory on 10.1.2.211:46771 (size: 2.2 KB, free: 6.0 GB)
17/02/07 11:55:04,593 INFO BlockManagerInfo: Added broadcast_3_piece0 in memory on 10.1.2.149:40201 (size: 2.2 KB, free: 6.0 GB)
17/02/07 11:55:04,604 INFO BlockManagerInfo: Added broadcast_3_piece0 in memory on 10.1.2.250:41300 (size: 2.2 KB, free: 6.0 GB)
17/02/07 11:55:04,621 INFO TaskSetManager: Finished task 44.0 in stage 2.0 (TID 102) in 116 ms on 10.1.2.157 (1/64)
17/02/07 11:55:04,622 INFO BlockManagerInfo: Added broadcast_3_piece0 in memory on 10.1.2.62:37738 (size: 2.2 KB, free: 6.0 GB)
17/02/07 11:55:04,629 INFO TaskSetManager: Finished task 16.0 in stage 2.0 (TID 69) in 157 ms on 10.1.2.253 (2/64)
17/02/07 11:55:04,630 INFO TaskSetManager: Finished task 3.0 in stage 2.0 (TID 65) in 164 ms on 10.1.2.115 (3/64)
17/02/07 11:55:04,631 INFO BlockManagerInfo: Added broadcast_3_piece0 in memory on 10.1.2.207:35507 (size: 2.2 KB, free: 6.0 GB)
17/02/07 11:55:04,635 INFO BlockManagerInfo: Added broadcast_3_piece0 in memory on 10.1.2.214:42923 (size: 2.2 KB, free: 6.0 GB)
17/02/07 11:55:04,639 INFO TaskSetManager: Finished task 47.0 in stage 2.0 (TID 98) in 139 ms on 10.1.2.188 (4/64)
17/02/07 11:55:04,641 INFO TaskSetManager: Finished task 37.0 in stage 2.0 (TID 84) in 156 ms on 10.1.2.211 (5/64)
17/02/07 11:55:04,642 INFO TaskSetManager: Finished task 53.0 in stage 2.0 (TID 113) in 126 ms on 10.1.2.115 (6/64)
17/02/07 11:55:04,643 INFO BlockManagerInfo: Added broadcast_3_piece0 in memory on 10.1.2.37:37810 (size: 2.2 KB, free: 6.0 GB)
17/02/07 11:55:04,644 INFO BlockManagerInfo: Added broadcast_3_piece0 in memory on 10.1.2.108:44508 (size: 2.2 KB, free: 6.0 GB)
17/02/07 11:55:04,645 INFO BlockManagerInfo: Added broadcast_3_piece0 in memory on 10.1.2.96:35345 (size: 2.2 KB, free: 6.1 GB)
17/02/07 11:55:04,649 INFO TaskSetManager: Finished task 45.0 in stage 2.0 (TID 117) in 129 ms on 10.1.2.253 (7/64)
17/02/07 11:55:04,651 INFO TaskSetManager: Finished task 6.0 in stage 2.0 (TID 70) in 179 ms on 10.1.2.157 (8/64)
17/02/07 11:55:04,661 INFO BlockManagerInfo: Added broadcast_3_piece0 in memory on 10.1.2.189:44110 (size: 2.2 KB, free: 6.0 GB)
17/02/07 11:55:04,663 INFO BlockManagerInfo: Added broadcast_3_piece0 in memory on 10.1.2.35:37955 (size: 2.2 KB, free: 6.0 GB)
17/02/07 11:55:04,664 INFO BlockManagerInfo: Added broadcast_3_piece0 in memory on 10.1.2.90:41907 (size: 2.2 KB, free: 6.0 GB)
17/02/07 11:55:04,673 INFO TaskSetManager: Finished task 22.0 in stage 2.0 (TID 86) in 187 ms on 10.1.2.157 (9/64)
17/02/07 11:55:04,675 INFO TaskSetManager: Finished task 31.0 in stage 2.0 (TID 99) in 172 ms on 10.1.2.149 (10/64)
17/02/07 11:55:04,679 INFO TaskSetManager: Finished task 20.0 in stage 2.0 (TID 89) in 190 ms on 10.1.2.62 (11/64)
17/02/07 11:55:04,681 INFO TaskSetManager: Finished task 46.0 in stage 2.0 (TID 97) in 181 ms on 10.1.2.115 (12/64)
17/02/07 11:55:04,682 INFO TaskSetManager: Finished task 7.0 in stage 2.0 (TID 83) in 198 ms on 10.1.2.149 (13/64)
17/02/07 11:55:04,684 INFO TaskSetManager: Finished task 12.0 in stage 2.0 (TID 76) in 207 ms on 10.1.2.250 (14/64)
17/02/07 11:55:04,685 INFO TaskSetManager: Finished task 18.0 in stage 2.0 (TID 78) in 206 ms on 10.1.2.207 (15/64)
17/02/07 11:55:04,687 INFO TaskSetManager: Finished task 32.0 in stage 2.0 (TID 107) in 177 ms on 10.1.2.214 (16/64)
17/02/07 11:55:04,688 INFO TaskSetManager: Finished task 30.0 in stage 2.0 (TID 88) in 200 ms on 10.1.2.108 (17/64)
17/02/07 11:55:04,689 INFO TaskSetManager: Finished task 13.0 in stage 2.0 (TID 72) in 215 ms on 10.1.2.108 (18/64)
17/02/07 11:55:04,693 INFO TaskSetManager: Finished task 38.0 in stage 2.0 (TID 104) in 186 ms on 10.1.2.108 (19/64)
17/02/07 11:55:04,696 INFO TaskSetManager: Finished task 62.0 in stage 2.0 (TID 125) in 169 ms on 10.1.2.207 (20/64)
17/02/07 11:55:04,697 INFO TaskSetManager: Finished task 8.0 in stage 2.0 (TID 75) in 221 ms on 10.1.2.214 (21/64)
17/02/07 11:55:04,698 INFO TaskSetManager: Finished task 49.0 in stage 2.0 (TID 120) in 175 ms on 10.1.2.108 (22/64)
17/02/07 11:55:04,699 INFO TaskSetManager: Finished task 17.0 in stage 2.0 (TID 87) in 212 ms on 10.1.2.37 (23/64)
17/02/07 11:55:04,703 INFO TaskSetManager: Finished task 34.0 in stage 2.0 (TID 110) in 190 ms on 10.1.2.207 (24/64)
17/02/07 11:55:04,706 INFO TaskSetManager: Starting task 63.0 in stage 2.0 (TID 128, 10.1.2.189, partition 63, PROCESS_LOCAL, 5374 bytes)
17/02/07 11:55:04,706 INFO CoarseGrainedSchedulerBackend$DriverEndpoint: Launching task 128 on executor id: 2 hostname: 10.1.2.189.
17/02/07 11:55:04,707 INFO TaskSetManager: Finished task 35.0 in stage 2.0 (TID 126) in 179 ms on 10.1.2.189 (25/64)
17/02/07 11:55:04,708 INFO TaskSetManager: Finished task 9.0 in stage 2.0 (TID 74) in 233 ms on 10.1.2.96 (26/64)
17/02/07 11:55:04,708 INFO TaskSetManager: Finished task 43.0 in stage 2.0 (TID 106) in 199 ms on 10.1.2.96 (27/64)
17/02/07 11:55:04,709 INFO TaskSetManager: Finished task 36.0 in stage 2.0 (TID 90) in 219 ms on 10.1.2.96 (28/64)
17/02/07 11:55:04,713 INFO TaskSetManager: Finished task 14.0 in stage 2.0 (TID 81) in 231 ms on 10.1.2.115 (29/64)
17/02/07 11:55:04,714 INFO TaskSetManager: Finished task 42.0 in stage 2.0 (TID 112) in 199 ms on 10.1.2.35 (30/64)
17/02/07 11:55:04,719 INFO TaskSetManager: Finished task 27.0 in stage 2.0 (TID 93) in 227 ms on 10.1.2.90 (31/64)
17/02/07 11:55:04,721 INFO TaskSetManager: Finished task 48.0 in stage 2.0 (TID 109) in 208 ms on 10.1.2.90 (32/64)
17/02/07 11:55:04,722 INFO TaskSetManager: Finished task 10.0 in stage 2.0 (TID 111) in 208 ms on 10.1.2.189 (33/64)
17/02/07 11:55:04,723 INFO TaskSetManager: Finished task 1.0 in stage 2.0 (TID 95) in 229 ms on 10.1.2.189 (34/64)
17/02/07 11:55:04,724 INFO TaskSetManager: Finished task 57.0 in stage 2.0 (TID 114) in 207 ms on 10.1.2.188 (35/64)
17/02/07 11:55:04,727 INFO TaskSetManager: Finished task 61.0 in stage 2.0 (TID 127) in 199 ms on 10.1.2.35 (36/64)
17/02/07 11:55:04,728 INFO TaskSetManager: Finished task 54.0 in stage 2.0 (TID 124) in 202 ms on 10.1.2.90 (37/64)
17/02/07 11:55:04,729 INFO TaskSetManager: Finished task 0.0 in stage 2.0 (TID 79) in 249 ms on 10.1.2.189 (38/64)
17/02/07 11:55:04,731 INFO TaskSetManager: Finished task 11.0 in stage 2.0 (TID 77) in 252 ms on 10.1.2.90 (39/64)
17/02/07 11:55:04,732 INFO TaskSetManager: Finished task 29.0 in stage 2.0 (TID 68) in 261 ms on 10.1.2.211 (40/64)
17/02/07 11:55:04,733 INFO TaskSetManager: Finished task 40.0 in stage 2.0 (TID 82) in 251 ms on 10.1.2.188 (41/64)
17/02/07 11:55:04,739 INFO TaskSetManager: Finished task 63.0 in stage 2.0 (TID 128) in 33 ms on 10.1.2.189 (42/64)
17/02/07 11:55:04,739 INFO TaskSetManager: Finished task 24.0 in stage 2.0 (TID 94) in 246 ms on 10.1.2.207 (43/64)
17/02/07 11:55:04,749 INFO TaskSetManager: Finished task 15.0 in stage 2.0 (TID 92) in 257 ms on 10.1.2.250 (44/64)
17/02/07 11:55:04,753 INFO TaskSetManager: Finished task 19.0 in stage 2.0 (TID 91) in 262 ms on 10.1.2.214 (45/64)
17/02/07 11:55:04,753 INFO TaskSetManager: Finished task 5.0 in stage 2.0 (TID 67) in 284 ms on 10.1.2.149 (46/64)
17/02/07 11:55:04,761 INFO TaskSetManager: Finished task 21.0 in stage 2.0 (TID 80) in 277 ms on 10.1.2.35 (47/64)
17/02/07 11:55:04,773 INFO TaskSetManager: Finished task 25.0 in stage 2.0 (TID 85) in 288 ms on 10.1.2.253 (48/64)
17/02/07 11:55:04,780 INFO TaskSetManager: Finished task 23.0 in stage 2.0 (TID 96) in 281 ms on 10.1.2.35 (49/64)
17/02/07 11:55:04,781 INFO TaskSetManager: Finished task 33.0 in stage 2.0 (TID 108) in 270 ms on 10.1.2.250 (50/64)
17/02/07 11:55:04,784 INFO TaskSetManager: Finished task 60.0 in stage 2.0 (TID 116) in 265 ms on 10.1.2.211 (51/64)
17/02/07 11:55:04,793 INFO TaskSetManager: Finished task 51.0 in stage 2.0 (TID 115) in 274 ms on 10.1.2.149 (52/64)
17/02/07 11:55:04,796 INFO TaskSetManager: Finished task 50.0 in stage 2.0 (TID 100) in 293 ms on 10.1.2.211 (53/64)
17/02/07 11:55:04,798 INFO TaskSetManager: Finished task 26.0 in stage 2.0 (TID 101) in 294 ms on 10.1.2.253 (54/64)
17/02/07 11:55:04,813 INFO TaskSetManager: Finished task 4.0 in stage 2.0 (TID 73) in 338 ms on 10.1.2.62 (55/64)
17/02/07 11:55:04,816 INFO TaskSetManager: Finished task 55.0 in stage 2.0 (TID 118) in 295 ms on 10.1.2.157 (56/64)
17/02/07 11:55:04,821 INFO TaskSetManager: Finished task 52.0 in stage 2.0 (TID 121) in 297 ms on 10.1.2.62 (57/64)
17/02/07 11:55:04,821 INFO TaskSetManager: Finished task 2.0 in stage 2.0 (TID 71) in 348 ms on 10.1.2.37 (58/64)
17/02/07 11:55:04,838 INFO TaskSetManager: Finished task 56.0 in stage 2.0 (TID 123) in 313 ms on 10.1.2.250 (59/64)
17/02/07 11:55:04,879 INFO TaskSetManager: Finished task 28.0 in stage 2.0 (TID 66) in 411 ms on 10.1.2.188 (60/64)
17/02/07 11:55:04,881 INFO TaskSetManager: Finished task 58.0 in stage 2.0 (TID 122) in 356 ms on 10.1.2.214 (61/64)
17/02/07 11:55:04,891 INFO TaskSetManager: Finished task 41.0 in stage 2.0 (TID 105) in 383 ms on 10.1.2.62 (62/64)
17/02/07 11:55:04,893 INFO TaskSetManager: Finished task 59.0 in stage 2.0 (TID 119) in 371 ms on 10.1.2.37 (63/64)
17/02/07 11:55:04,932 INFO TaskSetManager: Finished task 39.0 in stage 2.0 (TID 103) in 426 ms on 10.1.2.37 (64/64)
17/02/07 11:55:04,932 INFO TaskSchedulerImpl: Removed TaskSet 2.0, whose tasks have all completed, from pool 
17/02/07 11:55:04,932 INFO DAGScheduler: ResultStage 2 (count at GradientDescent.scala:209) finished in 0.466 s
17/02/07 11:55:04,933 INFO DAGScheduler: Job 2 finished: count at GradientDescent.scala:209, took 0.486358 s
17/02/07 11:55:05,344 WARN BLAS: Failed to load implementation from: com.github.fommil.netlib.NativeSystemBLAS
17/02/07 11:55:05,344 WARN BLAS: Failed to load implementation from: com.github.fommil.netlib.NativeRefBLAS
17/02/07 11:55:05,375 INFO MemoryStore: Block broadcast_4 stored as values in memory (estimated size 280.0 B, free 6.3 GB)
17/02/07 11:55:05,384 INFO MemoryStore: Block broadcast_4_piece0 stored as bytes in memory (estimated size 153.0 B, free 6.3 GB)
17/02/07 11:55:05,385 INFO BlockManagerInfo: Added broadcast_4_piece0 in memory on 10.1.2.142:39400 (size: 153.0 B, free: 6.3 GB)
17/02/07 11:55:05,386 INFO SparkContext: Created broadcast 4 from broadcast at GradientDescent.scala:235
17/02/07 11:55:05,452 INFO SparkContext: Starting job: treeAggregate at GradientDescent.scala:239
17/02/07 11:55:05,459 INFO DAGScheduler: Registering RDD 11 (treeAggregate at GradientDescent.scala:239)
17/02/07 11:55:05,459 INFO DAGScheduler: Got job 3 (treeAggregate at GradientDescent.scala:239) with 8 output partitions
17/02/07 11:55:05,460 INFO DAGScheduler: Final stage: ResultStage 4 (treeAggregate at GradientDescent.scala:239)
17/02/07 11:55:05,460 INFO DAGScheduler: Parents of final stage: List(ShuffleMapStage 3)
17/02/07 11:55:05,460 INFO DAGScheduler: Missing parents: List(ShuffleMapStage 3)
17/02/07 11:55:05,464 INFO DAGScheduler: Submitting ShuffleMapStage 3 (MapPartitionsRDD[11] at treeAggregate at GradientDescent.scala:239), which has no missing parents
17/02/07 11:55:05,484 INFO MemoryStore: Block broadcast_5 stored as values in memory (estimated size 7.2 KB, free 6.3 GB)
17/02/07 11:55:05,492 INFO MemoryStore: Block broadcast_5_piece0 stored as bytes in memory (estimated size 3.7 KB, free 6.3 GB)
17/02/07 11:55:05,493 INFO BlockManagerInfo: Added broadcast_5_piece0 in memory on 10.1.2.142:39400 (size: 3.7 KB, free: 6.3 GB)
17/02/07 11:55:05,494 INFO SparkContext: Created broadcast 5 from broadcast at DAGScheduler.scala:1012
17/02/07 11:55:05,496 INFO DAGScheduler: Submitting 64 missing tasks from ShuffleMapStage 3 (MapPartitionsRDD[11] at treeAggregate at GradientDescent.scala:239)
17/02/07 11:55:05,497 INFO TaskSchedulerImpl: Adding task set 3.0 with 64 tasks
17/02/07 11:55:05,500 INFO TaskSetManager: Starting task 21.0 in stage 3.0 (TID 129, 10.1.2.35, partition 21, PROCESS_LOCAL, 5563 bytes)
17/02/07 11:55:05,501 INFO TaskSetManager: Starting task 11.0 in stage 3.0 (TID 130, 10.1.2.90, partition 11, PROCESS_LOCAL, 5563 bytes)
17/02/07 11:55:05,503 INFO TaskSetManager: Starting task 18.0 in stage 3.0 (TID 131, 10.1.2.207, partition 18, PROCESS_LOCAL, 5563 bytes)
17/02/07 11:55:05,504 INFO TaskSetManager: Starting task 9.0 in stage 3.0 (TID 132, 10.1.2.96, partition 9, PROCESS_LOCAL, 5563 bytes)
17/02/07 11:55:05,504 INFO TaskSetManager: Starting task 3.0 in stage 3.0 (TID 133, 10.1.2.115, partition 3, PROCESS_LOCAL, 5563 bytes)
17/02/07 11:55:05,505 INFO TaskSetManager: Starting task 0.0 in stage 3.0 (TID 134, 10.1.2.189, partition 0, PROCESS_LOCAL, 5563 bytes)
17/02/07 11:55:05,505 INFO TaskSetManager: Starting task 8.0 in stage 3.0 (TID 135, 10.1.2.214, partition 8, PROCESS_LOCAL, 5563 bytes)
17/02/07 11:55:05,505 INFO TaskSetManager: Starting task 6.0 in stage 3.0 (TID 136, 10.1.2.157, partition 6, PROCESS_LOCAL, 5563 bytes)
17/02/07 11:55:05,506 INFO TaskSetManager: Starting task 5.0 in stage 3.0 (TID 137, 10.1.2.149, partition 5, PROCESS_LOCAL, 5563 bytes)
17/02/07 11:55:05,506 INFO TaskSetManager: Starting task 12.0 in stage 3.0 (TID 138, 10.1.2.250, partition 12, PROCESS_LOCAL, 5563 bytes)
17/02/07 11:55:05,507 INFO TaskSetManager: Starting task 2.0 in stage 3.0 (TID 139, 10.1.2.37, partition 2, PROCESS_LOCAL, 5563 bytes)
17/02/07 11:55:05,507 INFO TaskSetManager: Starting task 29.0 in stage 3.0 (TID 140, 10.1.2.211, partition 29, PROCESS_LOCAL, 5563 bytes)
17/02/07 11:55:05,508 INFO TaskSetManager: Starting task 4.0 in stage 3.0 (TID 141, 10.1.2.62, partition 4, PROCESS_LOCAL, 5563 bytes)
17/02/07 11:55:05,508 INFO TaskSetManager: Starting task 13.0 in stage 3.0 (TID 142, 10.1.2.108, partition 13, PROCESS_LOCAL, 5563 bytes)
17/02/07 11:55:05,509 INFO TaskSetManager: Starting task 28.0 in stage 3.0 (TID 143, 10.1.2.188, partition 28, PROCESS_LOCAL, 5563 bytes)
17/02/07 11:55:05,509 INFO TaskSetManager: Starting task 16.0 in stage 3.0 (TID 144, 10.1.2.253, partition 16, PROCESS_LOCAL, 5563 bytes)
17/02/07 11:55:05,510 INFO TaskSetManager: Starting task 23.0 in stage 3.0 (TID 145, 10.1.2.35, partition 23, PROCESS_LOCAL, 5563 bytes)
17/02/07 11:55:05,510 INFO TaskSetManager: Starting task 27.0 in stage 3.0 (TID 146, 10.1.2.90, partition 27, PROCESS_LOCAL, 5563 bytes)
17/02/07 11:55:05,511 INFO TaskSetManager: Starting task 24.0 in stage 3.0 (TID 147, 10.1.2.207, partition 24, PROCESS_LOCAL, 5563 bytes)
17/02/07 11:55:05,511 INFO TaskSetManager: Starting task 36.0 in stage 3.0 (TID 148, 10.1.2.96, partition 36, PROCESS_LOCAL, 5563 bytes)
17/02/07 11:55:05,512 INFO TaskSetManager: Starting task 14.0 in stage 3.0 (TID 149, 10.1.2.115, partition 14, PROCESS_LOCAL, 5563 bytes)
17/02/07 11:55:05,512 INFO TaskSetManager: Starting task 1.0 in stage 3.0 (TID 150, 10.1.2.189, partition 1, PROCESS_LOCAL, 5563 bytes)
17/02/07 11:55:05,513 INFO TaskSetManager: Starting task 19.0 in stage 3.0 (TID 151, 10.1.2.214, partition 19, PROCESS_LOCAL, 5563 bytes)
17/02/07 11:55:05,513 INFO TaskSetManager: Starting task 22.0 in stage 3.0 (TID 152, 10.1.2.157, partition 22, PROCESS_LOCAL, 5563 bytes)
17/02/07 11:55:05,514 INFO TaskSetManager: Starting task 7.0 in stage 3.0 (TID 153, 10.1.2.149, partition 7, PROCESS_LOCAL, 5563 bytes)
17/02/07 11:55:05,514 INFO TaskSetManager: Starting task 15.0 in stage 3.0 (TID 154, 10.1.2.250, partition 15, PROCESS_LOCAL, 5563 bytes)
17/02/07 11:55:05,515 INFO TaskSetManager: Starting task 17.0 in stage 3.0 (TID 155, 10.1.2.37, partition 17, PROCESS_LOCAL, 5563 bytes)
17/02/07 11:55:05,515 INFO TaskSetManager: Starting task 37.0 in stage 3.0 (TID 156, 10.1.2.211, partition 37, PROCESS_LOCAL, 5563 bytes)
17/02/07 11:55:05,516 INFO TaskSetManager: Starting task 20.0 in stage 3.0 (TID 157, 10.1.2.62, partition 20, PROCESS_LOCAL, 5563 bytes)
17/02/07 11:55:05,516 INFO TaskSetManager: Starting task 30.0 in stage 3.0 (TID 158, 10.1.2.108, partition 30, PROCESS_LOCAL, 5563 bytes)
17/02/07 11:55:05,517 INFO TaskSetManager: Starting task 40.0 in stage 3.0 (TID 159, 10.1.2.188, partition 40, PROCESS_LOCAL, 5563 bytes)
17/02/07 11:55:05,517 INFO TaskSetManager: Starting task 25.0 in stage 3.0 (TID 160, 10.1.2.253, partition 25, PROCESS_LOCAL, 5563 bytes)
17/02/07 11:55:05,518 INFO TaskSetManager: Starting task 42.0 in stage 3.0 (TID 161, 10.1.2.35, partition 42, PROCESS_LOCAL, 5563 bytes)
17/02/07 11:55:05,518 INFO TaskSetManager: Starting task 48.0 in stage 3.0 (TID 162, 10.1.2.90, partition 48, PROCESS_LOCAL, 5563 bytes)
17/02/07 11:55:05,519 INFO TaskSetManager: Starting task 34.0 in stage 3.0 (TID 163, 10.1.2.207, partition 34, PROCESS_LOCAL, 5563 bytes)
17/02/07 11:55:05,519 INFO TaskSetManager: Starting task 43.0 in stage 3.0 (TID 164, 10.1.2.96, partition 43, PROCESS_LOCAL, 5563 bytes)
17/02/07 11:55:05,520 INFO TaskSetManager: Starting task 46.0 in stage 3.0 (TID 165, 10.1.2.115, partition 46, PROCESS_LOCAL, 5563 bytes)
17/02/07 11:55:05,520 INFO TaskSetManager: Starting task 10.0 in stage 3.0 (TID 166, 10.1.2.189, partition 10, PROCESS_LOCAL, 5563 bytes)
17/02/07 11:55:05,521 INFO TaskSetManager: Starting task 32.0 in stage 3.0 (TID 167, 10.1.2.214, partition 32, PROCESS_LOCAL, 5563 bytes)
17/02/07 11:55:05,521 INFO TaskSetManager: Starting task 44.0 in stage 3.0 (TID 168, 10.1.2.157, partition 44, PROCESS_LOCAL, 5563 bytes)
17/02/07 11:55:05,522 INFO TaskSetManager: Starting task 31.0 in stage 3.0 (TID 169, 10.1.2.149, partition 31, PROCESS_LOCAL, 5563 bytes)
17/02/07 11:55:05,522 INFO TaskSetManager: Starting task 33.0 in stage 3.0 (TID 170, 10.1.2.250, partition 33, PROCESS_LOCAL, 5563 bytes)
17/02/07 11:55:05,523 INFO TaskSetManager: Starting task 39.0 in stage 3.0 (TID 171, 10.1.2.37, partition 39, PROCESS_LOCAL, 5563 bytes)
17/02/07 11:55:05,523 INFO TaskSetManager: Starting task 50.0 in stage 3.0 (TID 172, 10.1.2.211, partition 50, PROCESS_LOCAL, 5563 bytes)
17/02/07 11:55:05,524 INFO TaskSetManager: Starting task 41.0 in stage 3.0 (TID 173, 10.1.2.62, partition 41, PROCESS_LOCAL, 5563 bytes)
17/02/07 11:55:05,524 INFO TaskSetManager: Starting task 38.0 in stage 3.0 (TID 174, 10.1.2.108, partition 38, PROCESS_LOCAL, 5563 bytes)
17/02/07 11:55:05,525 INFO TaskSetManager: Starting task 47.0 in stage 3.0 (TID 175, 10.1.2.188, partition 47, PROCESS_LOCAL, 5563 bytes)
17/02/07 11:55:05,525 INFO TaskSetManager: Starting task 26.0 in stage 3.0 (TID 176, 10.1.2.253, partition 26, PROCESS_LOCAL, 5563 bytes)
17/02/07 11:55:05,526 INFO TaskSetManager: Starting task 61.0 in stage 3.0 (TID 177, 10.1.2.35, partition 61, PROCESS_LOCAL, 5563 bytes)
17/02/07 11:55:05,526 INFO TaskSetManager: Starting task 54.0 in stage 3.0 (TID 178, 10.1.2.90, partition 54, PROCESS_LOCAL, 5563 bytes)
17/02/07 11:55:05,526 INFO TaskSetManager: Starting task 62.0 in stage 3.0 (TID 179, 10.1.2.207, partition 62, PROCESS_LOCAL, 5563 bytes)
17/02/07 11:55:05,527 INFO TaskSetManager: Starting task 53.0 in stage 3.0 (TID 180, 10.1.2.115, partition 53, PROCESS_LOCAL, 5563 bytes)
17/02/07 11:55:05,527 INFO TaskSetManager: Starting task 35.0 in stage 3.0 (TID 181, 10.1.2.189, partition 35, PROCESS_LOCAL, 5563 bytes)
17/02/07 11:55:05,528 INFO TaskSetManager: Starting task 58.0 in stage 3.0 (TID 182, 10.1.2.214, partition 58, PROCESS_LOCAL, 5563 bytes)
17/02/07 11:55:05,528 INFO TaskSetManager: Starting task 55.0 in stage 3.0 (TID 183, 10.1.2.157, partition 55, PROCESS_LOCAL, 5563 bytes)
17/02/07 11:55:05,528 INFO TaskSetManager: Starting task 51.0 in stage 3.0 (TID 184, 10.1.2.149, partition 51, PROCESS_LOCAL, 5563 bytes)
17/02/07 11:55:05,529 INFO TaskSetManager: Starting task 56.0 in stage 3.0 (TID 185, 10.1.2.250, partition 56, PROCESS_LOCAL, 5563 bytes)
17/02/07 11:55:05,529 INFO TaskSetManager: Starting task 59.0 in stage 3.0 (TID 186, 10.1.2.37, partition 59, PROCESS_LOCAL, 5563 bytes)
17/02/07 11:55:05,530 INFO TaskSetManager: Starting task 60.0 in stage 3.0 (TID 187, 10.1.2.211, partition 60, PROCESS_LOCAL, 5563 bytes)
17/02/07 11:55:05,530 INFO TaskSetManager: Starting task 52.0 in stage 3.0 (TID 188, 10.1.2.62, partition 52, PROCESS_LOCAL, 5563 bytes)
17/02/07 11:55:05,531 INFO TaskSetManager: Starting task 49.0 in stage 3.0 (TID 189, 10.1.2.108, partition 49, PROCESS_LOCAL, 5563 bytes)
17/02/07 11:55:05,531 INFO TaskSetManager: Starting task 57.0 in stage 3.0 (TID 190, 10.1.2.188, partition 57, PROCESS_LOCAL, 5563 bytes)
17/02/07 11:55:05,531 INFO TaskSetManager: Starting task 45.0 in stage 3.0 (TID 191, 10.1.2.253, partition 45, PROCESS_LOCAL, 5563 bytes)
17/02/07 11:55:05,532 INFO CoarseGrainedSchedulerBackend$DriverEndpoint: Launching task 129 on executor id: 12 hostname: 10.1.2.35.
17/02/07 11:55:05,532 INFO CoarseGrainedSchedulerBackend$DriverEndpoint: Launching task 145 on executor id: 12 hostname: 10.1.2.35.
17/02/07 11:55:05,532 INFO CoarseGrainedSchedulerBackend$DriverEndpoint: Launching task 161 on executor id: 12 hostname: 10.1.2.35.
