Using properties file: /home/ubuntu/spark-2.0.0/conf/spark-defaults.conf
Adding default property: spark.driver.extraJavaOptions=-XX:+PrintGCDetails -XX:+PrintGCTimeStamps -Xms4000m -Dlog4j.configuration=file:///home/ubuntu/spark-2.0.0/conf/log4j.properties
Adding default property: spark.executor.extraJavaOptions=-XX:+PrintGCDetails -XX:+PrintGCTimeStamps -Xms4000m -Dlog4j.configuration=file:///home/ubuntu/spark-2.0.0/conf/log4j.properties
Parsed arguments:
  master                  spark://euca-10-1-2-142:7077
  deployMode              client
  executorMemory          4000m
  executorCores           null
  totalExecutorCores      null
  propertiesFile          /home/ubuntu/spark-2.0.0/conf/spark-defaults.conf
  driverMemory            4000m
  driverCores             null
  driverExtraClassPath    null
  driverExtraLibraryPath  null
  driverExtraJavaOptions  -XX:+PrintGCDetails -XX:+PrintGCTimeStamps -Xms4000m -Dlog4j.configuration=file:///home/ubuntu/spark-2.0.0/conf/log4j.properties
  supervise               false
  queue                   null
  numExecutors            4
  files                   null
  pyFiles                 null
  archives                null
  mainClass               LogRegExplicitParallelism
  primaryResource         file:///home/ubuntu/jars/log-reg-explicit-parallelism_2.11-1.0.jar
  name                    LogRegExplicitParallelism
  childArgs               [cluster 28 euca-10-1-2-142 9000 higgs_0_exp 5 16]
  jars                    null
  packages                null
  packagesExclusions      null
  repositories            null
  verbose                 true

Spark properties used, including those specified through
 --conf and those from the properties file /home/ubuntu/spark-2.0.0/conf/spark-defaults.conf:
  spark.default.parallelism -> 16
  spark.driver.memory -> 4000m
  spark.executor.extraJavaOptions -> -XX:+PrintGCDetails -XX:+PrintGCTimeStamps -Xms4000m -Dlog4j.configuration=file:///home/ubuntu/spark-2.0.0/conf/log4j.properties
  spark.driver.extraJavaOptions -> -XX:+PrintGCDetails -XX:+PrintGCTimeStamps -Xms4000m -Dlog4j.configuration=file:///home/ubuntu/spark-2.0.0/conf/log4j.properties
  spark.shuffle.spill -> false

    
Main class:
LogRegExplicitParallelism
Arguments:
cluster
28
euca-10-1-2-142
9000
higgs_0_exp
5
16
System properties:
spark.default.parallelism -> 16
spark.executor.memory -> 4000m
spark.driver.memory -> 4000m
SPARK_SUBMIT -> true
spark.executor.extraJavaOptions -> -XX:+PrintGCDetails -XX:+PrintGCTimeStamps -Xms4000m -Dlog4j.configuration=file:///home/ubuntu/spark-2.0.0/conf/log4j.properties
spark.app.name -> LogRegExplicitParallelism
spark.shuffle.spill -> false
spark.driver.extraJavaOptions -> -XX:+PrintGCDetails -XX:+PrintGCTimeStamps -Xms4000m -Dlog4j.configuration=file:///home/ubuntu/spark-2.0.0/conf/log4j.properties
spark.jars -> file:///home/ubuntu/jars/log-reg-explicit-parallelism_2.11-1.0.jar
spark.submit.deployMode -> client
spark.master -> spark://euca-10-1-2-142:7077
Classpath elements:
file:///home/ubuntu/jars/log-reg-explicit-parallelism_2.11-1.0.jar


17/01/29 07:03:56,612 INFO SparkContext: Running Spark version 2.0.0
17/01/29 07:03:56,944 WARN NativeCodeLoader: Unable to load native-hadoop library for your platform... using builtin-java classes where applicable
17/01/29 07:03:57,098 INFO SecurityManager: Changing view acls to: ubuntu
17/01/29 07:03:57,098 INFO SecurityManager: Changing modify acls to: ubuntu
17/01/29 07:03:57,099 INFO SecurityManager: Changing view acls groups to: 
17/01/29 07:03:57,099 INFO SecurityManager: Changing modify acls groups to: 
17/01/29 07:03:57,100 INFO SecurityManager: SecurityManager: authentication disabled; ui acls disabled; users  with view permissions: Set(ubuntu); groups with view permissions: Set(); users  with modify permissions: Set(ubuntu); groups with modify permissions: Set()
17/01/29 07:03:57,404 INFO Utils: Successfully started service 'sparkDriver' on port 39593.
17/01/29 07:03:57,422 INFO SparkEnv: Registering MapOutputTracker
17/01/29 07:03:57,427 WARN SortShuffleManager: spark.shuffle.spill was set to false, but this configuration is ignored as of Spark 1.6+. Shuffle will continue to spill to disk when necessary.
17/01/29 07:03:57,438 INFO SparkEnv: Registering BlockManagerMaster
17/01/29 07:03:57,451 INFO DiskBlockManager: Created local directory at /tmp/blockmgr-e6890d87-6ba5-4b06-9ecc-95828112ebc5
17/01/29 07:03:57,468 INFO MemoryStore: MemoryStore started with capacity 2.1 GB
17/01/29 07:03:57,520 INFO SparkEnv: Registering OutputCommitCoordinator
17/01/29 07:03:57,718 INFO Utils: Successfully started service 'SparkUI' on port 4040.
17/01/29 07:03:57,720 INFO SparkUI: Bound SparkUI to 10.1.2.142, and started at http://10.1.2.142:4040
17/01/29 07:03:57,758 INFO SparkContext: Added JAR file:///home/ubuntu/jars/log-reg-explicit-parallelism_2.11-1.0.jar at spark://10.1.2.142:39593/jars/log-reg-explicit-parallelism_2.11-1.0.jar with timestamp 1485673437758
17/01/29 07:03:57,845 INFO StandaloneAppClient$ClientEndpoint: Connecting to master spark://euca-10-1-2-142:7077...
17/01/29 07:03:57,906 INFO TransportClientFactory: Successfully created connection to euca-10-1-2-142/10.1.2.142:7077 after 27 ms (0 ms spent in bootstraps)
17/01/29 07:03:58,019 INFO StandaloneSchedulerBackend: Connected to Spark cluster with app ID app-20170129070358-0000
17/01/29 07:03:58,025 INFO Utils: Successfully started service 'org.apache.spark.network.netty.NettyBlockTransferService' on port 43652.
17/01/29 07:03:58,026 INFO NettyBlockTransferService: Server created on 10.1.2.142:43652
17/01/29 07:03:58,028 INFO BlockManagerMaster: Registering BlockManager BlockManagerId(driver, 10.1.2.142, 43652)
17/01/29 07:03:58,031 INFO BlockManagerMasterEndpoint: Registering block manager 10.1.2.142:43652 with 2.1 GB RAM, BlockManagerId(driver, 10.1.2.142, 43652)
17/01/29 07:03:58,033 INFO BlockManagerMaster: Registered BlockManager BlockManagerId(driver, 10.1.2.142, 43652)
17/01/29 07:03:58,046 INFO StandaloneAppClient$ClientEndpoint: Executor added: app-20170129070358-0000/0 on worker-20170129070342-10.1.2.71-38900 (10.1.2.71:38900) with 4 cores
17/01/29 07:03:58,047 INFO StandaloneSchedulerBackend: Granted executor ID app-20170129070358-0000/0 on hostPort 10.1.2.71:38900 with 4 cores, 3.9 GB RAM
17/01/29 07:03:58,047 INFO StandaloneAppClient$ClientEndpoint: Executor added: app-20170129070358-0000/1 on worker-20170129070342-10.1.2.181-35648 (10.1.2.181:35648) with 4 cores
17/01/29 07:03:58,047 INFO StandaloneSchedulerBackend: Granted executor ID app-20170129070358-0000/1 on hostPort 10.1.2.181:35648 with 4 cores, 3.9 GB RAM
17/01/29 07:03:58,048 INFO StandaloneAppClient$ClientEndpoint: Executor added: app-20170129070358-0000/2 on worker-20170129070342-10.1.2.63-45759 (10.1.2.63:45759) with 4 cores
17/01/29 07:03:58,049 INFO StandaloneSchedulerBackend: Granted executor ID app-20170129070358-0000/2 on hostPort 10.1.2.63:45759 with 4 cores, 3.9 GB RAM
17/01/29 07:03:58,050 INFO StandaloneAppClient$ClientEndpoint: Executor added: app-20170129070358-0000/3 on worker-20170129070342-10.1.2.236-40297 (10.1.2.236:40297) with 4 cores
17/01/29 07:03:58,050 INFO StandaloneSchedulerBackend: Granted executor ID app-20170129070358-0000/3 on hostPort 10.1.2.236:40297 with 4 cores, 3.9 GB RAM
17/01/29 07:03:58,107 INFO StandaloneAppClient$ClientEndpoint: Executor updated: app-20170129070358-0000/1 is now RUNNING
17/01/29 07:03:58,107 INFO StandaloneAppClient$ClientEndpoint: Executor updated: app-20170129070358-0000/3 is now RUNNING
17/01/29 07:03:58,110 INFO StandaloneAppClient$ClientEndpoint: Executor updated: app-20170129070358-0000/0 is now RUNNING
17/01/29 07:03:58,113 INFO StandaloneAppClient$ClientEndpoint: Executor updated: app-20170129070358-0000/2 is now RUNNING
17/01/29 07:03:58,254 INFO StandaloneSchedulerBackend: SchedulerBackend is ready for scheduling beginning after reached minRegisteredResourcesRatio: 0.0
17/01/29 07:03:58,634 INFO MemoryStore: Block broadcast_0 stored as values in memory (estimated size 130.8 KB, free 2.1 GB)
17/01/29 07:03:58,713 INFO MemoryStore: Block broadcast_0_piece0 stored as bytes in memory (estimated size 16.5 KB, free 2.1 GB)
17/01/29 07:03:58,715 INFO BlockManagerInfo: Added broadcast_0_piece0 in memory on 10.1.2.142:43652 (size: 16.5 KB, free: 2.1 GB)
17/01/29 07:03:58,723 INFO SparkContext: Created broadcast 0 from textFile at MLUtils.scala:99
17/01/29 07:03:59,400 INFO FileInputFormat: Total input paths to process : 1
17/01/29 07:03:59,448 INFO NetworkTopology: Adding a new node: /default-rack/10.1.2.71:50010
17/01/29 07:03:59,449 INFO NetworkTopology: Adding a new node: /default-rack/10.1.2.236:50010
17/01/29 07:03:59,449 INFO NetworkTopology: Adding a new node: /default-rack/10.1.2.63:50010
17/01/29 07:03:59,495 INFO SparkContext: Starting job: first at GeneralizedLinearAlgorithm.scala:246
17/01/29 07:03:59,510 INFO DAGScheduler: Got job 0 (first at GeneralizedLinearAlgorithm.scala:246) with 1 output partitions
17/01/29 07:03:59,510 INFO DAGScheduler: Final stage: ResultStage 0 (first at GeneralizedLinearAlgorithm.scala:246)
17/01/29 07:03:59,512 INFO DAGScheduler: Parents of final stage: List()
17/01/29 07:03:59,519 INFO DAGScheduler: Missing parents: List()
17/01/29 07:03:59,528 INFO DAGScheduler: Submitting ResultStage 0 (MapPartitionsRDD[6] at map at GeneralizedLinearAlgorithm.scala:246), which has no missing parents
17/01/29 07:03:59,551 INFO MemoryStore: Block broadcast_1 stored as values in memory (estimated size 4.2 KB, free 2.1 GB)
17/01/29 07:03:59,556 INFO MemoryStore: Block broadcast_1_piece0 stored as bytes in memory (estimated size 2.4 KB, free 2.1 GB)
17/01/29 07:03:59,557 INFO BlockManagerInfo: Added broadcast_1_piece0 in memory on 10.1.2.142:43652 (size: 2.4 KB, free: 2.1 GB)
17/01/29 07:03:59,558 INFO SparkContext: Created broadcast 1 from broadcast at DAGScheduler.scala:1012
17/01/29 07:03:59,561 INFO DAGScheduler: Submitting 1 missing tasks from ResultStage 0 (MapPartitionsRDD[6] at map at GeneralizedLinearAlgorithm.scala:246)
17/01/29 07:03:59,563 INFO TaskSchedulerImpl: Adding task set 0.0 with 1 tasks
17/01/29 07:03:59,885 INFO CoarseGrainedSchedulerBackend$DriverEndpoint: Registered executor NettyRpcEndpointRef(null) (10.1.2.236:37354) with ID 3
17/01/29 07:03:59,913 INFO TaskSetManager: Starting task 0.0 in stage 0.0 (TID 0, 10.1.2.236, partition 0, ANY, 5456 bytes)
17/01/29 07:03:59,919 INFO CoarseGrainedSchedulerBackend$DriverEndpoint: Launching task 0 on executor id: 3 hostname: 10.1.2.236.
17/01/29 07:03:59,933 INFO BlockManagerMasterEndpoint: Registering block manager 10.1.2.236:39970 with 2.1 GB RAM, BlockManagerId(3, 10.1.2.236, 39970)
17/01/29 07:03:59,940 INFO CoarseGrainedSchedulerBackend$DriverEndpoint: Registered executor NettyRpcEndpointRef(null) (10.1.2.181:44102) with ID 1
17/01/29 07:03:59,960 INFO CoarseGrainedSchedulerBackend$DriverEndpoint: Registered executor NettyRpcEndpointRef(null) (10.1.2.71:52084) with ID 0
17/01/29 07:03:59,987 INFO BlockManagerMasterEndpoint: Registering block manager 10.1.2.181:36196 with 2.1 GB RAM, BlockManagerId(1, 10.1.2.181, 36196)
17/01/29 07:04:00,008 INFO BlockManagerMasterEndpoint: Registering block manager 10.1.2.71:38780 with 2.1 GB RAM, BlockManagerId(0, 10.1.2.71, 38780)
17/01/29 07:04:00,201 INFO BlockManagerInfo: Added broadcast_1_piece0 in memory on 10.1.2.236:39970 (size: 2.4 KB, free: 2.1 GB)
17/01/29 07:04:00,348 INFO BlockManagerInfo: Added broadcast_0_piece0 in memory on 10.1.2.236:39970 (size: 16.5 KB, free: 2.1 GB)
17/01/29 07:04:02,916 INFO CoarseGrainedSchedulerBackend$DriverEndpoint: Registered executor NettyRpcEndpointRef(null) (10.1.2.63:41838) with ID 2
17/01/29 07:04:02,970 INFO BlockManagerMasterEndpoint: Registering block manager 10.1.2.63:46374 with 2.1 GB RAM, BlockManagerId(2, 10.1.2.63, 46374)
17/01/29 07:04:07,617 INFO BlockManagerInfo: Added rdd_5_0 in memory on 10.1.2.236:39970 (size: 70.0 MB, free: 2.0 GB)
17/01/29 07:04:07,666 INFO TaskSetManager: Finished task 0.0 in stage 0.0 (TID 0) in 7775 ms on 10.1.2.236 (1/1)
17/01/29 07:04:07,667 INFO TaskSchedulerImpl: Removed TaskSet 0.0, whose tasks have all completed, from pool 
17/01/29 07:04:07,671 INFO DAGScheduler: ResultStage 0 (first at GeneralizedLinearAlgorithm.scala:246) finished in 8.096 s
17/01/29 07:04:07,675 INFO DAGScheduler: Job 0 finished: first at GeneralizedLinearAlgorithm.scala:246, took 8.180145 s
17/01/29 07:04:07,686 INFO SparkContext: Starting job: count at DataValidators.scala:40
17/01/29 07:04:07,688 INFO DAGScheduler: Got job 1 (count at DataValidators.scala:40) with 59 output partitions
17/01/29 07:04:07,688 INFO DAGScheduler: Final stage: ResultStage 1 (count at DataValidators.scala:40)
17/01/29 07:04:07,688 INFO DAGScheduler: Parents of final stage: List()
17/01/29 07:04:07,691 INFO DAGScheduler: Missing parents: List()
17/01/29 07:04:07,692 INFO DAGScheduler: Submitting ResultStage 1 (MapPartitionsRDD[7] at filter at DataValidators.scala:40), which has no missing parents
17/01/29 07:04:07,715 INFO MemoryStore: Block broadcast_2 stored as values in memory (estimated size 3.9 KB, free 2.1 GB)
17/01/29 07:04:07,717 INFO MemoryStore: Block broadcast_2_piece0 stored as bytes in memory (estimated size 2.2 KB, free 2.1 GB)
17/01/29 07:04:07,718 INFO BlockManagerInfo: Added broadcast_2_piece0 in memory on 10.1.2.142:43652 (size: 2.2 KB, free: 2.1 GB)
17/01/29 07:04:07,719 INFO SparkContext: Created broadcast 2 from broadcast at DAGScheduler.scala:1012
17/01/29 07:04:07,721 INFO DAGScheduler: Submitting 59 missing tasks from ResultStage 1 (MapPartitionsRDD[7] at filter at DataValidators.scala:40)
17/01/29 07:04:07,722 INFO TaskSchedulerImpl: Adding task set 1.0 with 59 tasks
17/01/29 07:04:07,728 INFO TaskSetManager: Starting task 0.0 in stage 1.0 (TID 1, 10.1.2.236, partition 0, PROCESS_LOCAL, 5374 bytes)
17/01/29 07:04:07,731 INFO TaskSetManager: Starting task 58.0 in stage 1.0 (TID 2, 10.1.2.71, partition 58, NODE_LOCAL, 5374 bytes)
17/01/29 07:04:07,732 INFO CoarseGrainedSchedulerBackend$DriverEndpoint: Launching task 2 on executor id: 0 hostname: 10.1.2.71.
17/01/29 07:04:07,733 INFO CoarseGrainedSchedulerBackend$DriverEndpoint: Launching task 1 on executor id: 3 hostname: 10.1.2.236.
17/01/29 07:04:07,751 INFO BlockManagerInfo: Added broadcast_2_piece0 in memory on 10.1.2.236:39970 (size: 2.2 KB, free: 2.0 GB)
17/01/29 07:04:07,798 INFO TaskSetManager: Finished task 0.0 in stage 1.0 (TID 1) in 71 ms on 10.1.2.236 (1/59)
17/01/29 07:04:07,997 INFO BlockManagerInfo: Added broadcast_2_piece0 in memory on 10.1.2.71:38780 (size: 2.2 KB, free: 2.1 GB)
17/01/29 07:04:08,174 INFO BlockManagerInfo: Added broadcast_0_piece0 in memory on 10.1.2.71:38780 (size: 16.5 KB, free: 2.1 GB)
17/01/29 07:04:10,836 INFO TaskSetManager: Starting task 1.0 in stage 1.0 (TID 3, 10.1.2.181, partition 1, ANY, 5374 bytes)
17/01/29 07:04:10,841 INFO TaskSetManager: Starting task 2.0 in stage 1.0 (TID 4, 10.1.2.71, partition 2, ANY, 5374 bytes)
17/01/29 07:04:10,843 INFO TaskSetManager: Starting task 3.0 in stage 1.0 (TID 5, 10.1.2.236, partition 3, ANY, 5374 bytes)
17/01/29 07:04:10,849 INFO TaskSetManager: Starting task 4.0 in stage 1.0 (TID 6, 10.1.2.63, partition 4, ANY, 5374 bytes)
17/01/29 07:04:10,852 INFO TaskSetManager: Starting task 5.0 in stage 1.0 (TID 7, 10.1.2.181, partition 5, ANY, 5374 bytes)
17/01/29 07:04:10,854 INFO TaskSetManager: Starting task 6.0 in stage 1.0 (TID 8, 10.1.2.71, partition 6, ANY, 5374 bytes)
17/01/29 07:04:10,856 INFO TaskSetManager: Starting task 7.0 in stage 1.0 (TID 9, 10.1.2.236, partition 7, ANY, 5374 bytes)
17/01/29 07:04:10,858 INFO TaskSetManager: Starting task 8.0 in stage 1.0 (TID 10, 10.1.2.63, partition 8, ANY, 5374 bytes)
17/01/29 07:04:10,860 INFO TaskSetManager: Starting task 9.0 in stage 1.0 (TID 11, 10.1.2.181, partition 9, ANY, 5374 bytes)
17/01/29 07:04:10,863 INFO TaskSetManager: Starting task 10.0 in stage 1.0 (TID 12, 10.1.2.71, partition 10, ANY, 5374 bytes)
17/01/29 07:04:10,865 INFO TaskSetManager: Starting task 11.0 in stage 1.0 (TID 13, 10.1.2.236, partition 11, ANY, 5374 bytes)
17/01/29 07:04:10,867 INFO TaskSetManager: Starting task 12.0 in stage 1.0 (TID 14, 10.1.2.63, partition 12, ANY, 5374 bytes)
17/01/29 07:04:10,871 INFO TaskSetManager: Starting task 13.0 in stage 1.0 (TID 15, 10.1.2.181, partition 13, ANY, 5374 bytes)
17/01/29 07:04:10,873 INFO TaskSetManager: Starting task 14.0 in stage 1.0 (TID 16, 10.1.2.236, partition 14, ANY, 5374 bytes)
17/01/29 07:04:10,875 INFO TaskSetManager: Starting task 15.0 in stage 1.0 (TID 17, 10.1.2.63, partition 15, ANY, 5374 bytes)
17/01/29 07:04:10,875 INFO CoarseGrainedSchedulerBackend$DriverEndpoint: Launching task 3 on executor id: 1 hostname: 10.1.2.181.
17/01/29 07:04:10,876 INFO CoarseGrainedSchedulerBackend$DriverEndpoint: Launching task 7 on executor id: 1 hostname: 10.1.2.181.
17/01/29 07:04:10,877 INFO CoarseGrainedSchedulerBackend$DriverEndpoint: Launching task 11 on executor id: 1 hostname: 10.1.2.181.
17/01/29 07:04:10,878 INFO CoarseGrainedSchedulerBackend$DriverEndpoint: Launching task 15 on executor id: 1 hostname: 10.1.2.181.
17/01/29 07:04:10,879 INFO CoarseGrainedSchedulerBackend$DriverEndpoint: Launching task 4 on executor id: 0 hostname: 10.1.2.71.
17/01/29 07:04:10,880 INFO CoarseGrainedSchedulerBackend$DriverEndpoint: Launching task 8 on executor id: 0 hostname: 10.1.2.71.
17/01/29 07:04:10,880 INFO CoarseGrainedSchedulerBackend$DriverEndpoint: Launching task 12 on executor id: 0 hostname: 10.1.2.71.
17/01/29 07:04:10,881 INFO CoarseGrainedSchedulerBackend$DriverEndpoint: Launching task 5 on executor id: 3 hostname: 10.1.2.236.
17/01/29 07:04:10,882 INFO CoarseGrainedSchedulerBackend$DriverEndpoint: Launching task 9 on executor id: 3 hostname: 10.1.2.236.
17/01/29 07:04:10,883 INFO CoarseGrainedSchedulerBackend$DriverEndpoint: Launching task 13 on executor id: 3 hostname: 10.1.2.236.
17/01/29 07:04:10,884 INFO CoarseGrainedSchedulerBackend$DriverEndpoint: Launching task 16 on executor id: 3 hostname: 10.1.2.236.
17/01/29 07:04:10,884 INFO CoarseGrainedSchedulerBackend$DriverEndpoint: Launching task 6 on executor id: 2 hostname: 10.1.2.63.
17/01/29 07:04:10,885 INFO CoarseGrainedSchedulerBackend$DriverEndpoint: Launching task 10 on executor id: 2 hostname: 10.1.2.63.
17/01/29 07:04:10,886 INFO CoarseGrainedSchedulerBackend$DriverEndpoint: Launching task 14 on executor id: 2 hostname: 10.1.2.63.
17/01/29 07:04:10,887 INFO CoarseGrainedSchedulerBackend$DriverEndpoint: Launching task 17 on executor id: 2 hostname: 10.1.2.63.
17/01/29 07:04:11,208 INFO BlockManagerInfo: Added broadcast_2_piece0 in memory on 10.1.2.63:46374 (size: 2.2 KB, free: 2.1 GB)
17/01/29 07:04:11,254 INFO BlockManagerInfo: Added broadcast_2_piece0 in memory on 10.1.2.181:36196 (size: 2.2 KB, free: 2.1 GB)
17/01/29 07:04:11,363 INFO BlockManagerInfo: Added broadcast_0_piece0 in memory on 10.1.2.63:46374 (size: 16.5 KB, free: 2.1 GB)
17/01/29 07:04:11,413 INFO BlockManagerInfo: Added broadcast_0_piece0 in memory on 10.1.2.181:36196 (size: 16.5 KB, free: 2.1 GB)
17.194: [GC [PSYoungGen: 1024512K->157227K(1195008K)] 1024512K->157235K(3926016K), 0.1203540 secs] [Times: user=0.14 sys=0.14, real=0.12 secs] 
17/01/29 07:04:13,354 INFO BlockManagerInfo: Removed broadcast_1_piece0 on 10.1.2.142:43652 in memory (size: 2.4 KB, free: 2.1 GB)
17/01/29 07:04:13,412 INFO BlockManagerInfo: Removed broadcast_1_piece0 on 10.1.2.236:39970 in memory (size: 2.4 KB, free: 2.0 GB)
17/01/29 07:04:24,503 INFO BlockManagerInfo: Added rdd_5_58 in memory on 10.1.2.71:38780 (size: 72.8 MB, free: 2047.6 MB)
17/01/29 07:04:24,586 INFO TaskSetManager: Starting task 16.0 in stage 1.0 (TID 18, 10.1.2.71, partition 16, ANY, 5374 bytes)
17/01/29 07:04:24,587 INFO CoarseGrainedSchedulerBackend$DriverEndpoint: Launching task 18 on executor id: 0 hostname: 10.1.2.71.
17/01/29 07:04:24,592 INFO TaskSetManager: Finished task 58.0 in stage 1.0 (TID 2) in 16862 ms on 10.1.2.71 (2/59)
17/01/29 07:04:28,057 INFO BlockManagerInfo: Added rdd_5_6 in memory on 10.1.2.71:38780 (size: 69.9 MB, free: 1977.7 MB)
17/01/29 07:04:28,093 INFO TaskSetManager: Starting task 17.0 in stage 1.0 (TID 19, 10.1.2.71, partition 17, ANY, 5374 bytes)
17/01/29 07:04:28,093 INFO CoarseGrainedSchedulerBackend$DriverEndpoint: Launching task 19 on executor id: 0 hostname: 10.1.2.71.
17/01/29 07:04:28,096 INFO TaskSetManager: Finished task 6.0 in stage 1.0 (TID 8) in 17243 ms on 10.1.2.71 (3/59)
17/01/29 07:04:28,459 INFO BlockManagerInfo: Added rdd_5_10 in memory on 10.1.2.71:38780 (size: 70.0 MB, free: 1907.7 MB)
17/01/29 07:04:28,492 INFO TaskSetManager: Starting task 18.0 in stage 1.0 (TID 20, 10.1.2.71, partition 18, ANY, 5374 bytes)
17/01/29 07:04:28,492 INFO CoarseGrainedSchedulerBackend$DriverEndpoint: Launching task 20 on executor id: 0 hostname: 10.1.2.71.
17/01/29 07:04:28,493 INFO TaskSetManager: Finished task 10.0 in stage 1.0 (TID 12) in 17632 ms on 10.1.2.71 (4/59)
17/01/29 07:04:28,495 INFO BlockManagerInfo: Added rdd_5_2 in memory on 10.1.2.71:38780 (size: 69.9 MB, free: 1837.8 MB)
17/01/29 07:04:28,520 INFO TaskSetManager: Starting task 19.0 in stage 1.0 (TID 21, 10.1.2.71, partition 19, ANY, 5374 bytes)
17/01/29 07:04:28,521 INFO CoarseGrainedSchedulerBackend$DriverEndpoint: Launching task 21 on executor id: 0 hostname: 10.1.2.71.
17/01/29 07:04:28,521 INFO TaskSetManager: Finished task 2.0 in stage 1.0 (TID 4) in 17685 ms on 10.1.2.71 (5/59)
17/01/29 07:04:31,632 INFO BlockManagerInfo: Added rdd_5_3 in memory on 10.1.2.236:39970 (size: 69.9 MB, free: 1980.5 MB)
17/01/29 07:04:31,670 INFO TaskSetManager: Starting task 20.0 in stage 1.0 (TID 22, 10.1.2.236, partition 20, ANY, 5374 bytes)
17/01/29 07:04:31,671 INFO CoarseGrainedSchedulerBackend$DriverEndpoint: Launching task 22 on executor id: 3 hostname: 10.1.2.236.
17/01/29 07:04:31,672 INFO TaskSetManager: Finished task 3.0 in stage 1.0 (TID 5) in 20831 ms on 10.1.2.236 (6/59)
17/01/29 07:04:31,856 INFO BlockManagerInfo: Added rdd_5_9 in memory on 10.1.2.181:36196 (size: 69.9 MB, free: 2.0 GB)
17/01/29 07:04:31,930 INFO TaskSetManager: Starting task 21.0 in stage 1.0 (TID 23, 10.1.2.181, partition 21, ANY, 5374 bytes)
17/01/29 07:04:31,931 INFO CoarseGrainedSchedulerBackend$DriverEndpoint: Launching task 23 on executor id: 1 hostname: 10.1.2.181.
17/01/29 07:04:31,933 INFO TaskSetManager: Finished task 9.0 in stage 1.0 (TID 11) in 21074 ms on 10.1.2.181 (7/59)
17/01/29 07:04:32,235 INFO BlockManagerInfo: Added rdd_5_1 in memory on 10.1.2.181:36196 (size: 70.0 MB, free: 1980.5 MB)
17/01/29 07:04:32,239 INFO BlockManagerInfo: Added rdd_5_13 in memory on 10.1.2.181:36196 (size: 69.9 MB, free: 1910.6 MB)
17/01/29 07:04:32,261 INFO TaskSetManager: Starting task 22.0 in stage 1.0 (TID 24, 10.1.2.181, partition 22, ANY, 5374 bytes)
17/01/29 07:04:32,261 INFO CoarseGrainedSchedulerBackend$DriverEndpoint: Launching task 24 on executor id: 1 hostname: 10.1.2.181.
17/01/29 07:04:32,262 INFO TaskSetManager: Finished task 1.0 in stage 1.0 (TID 3) in 21429 ms on 10.1.2.181 (8/59)
17/01/29 07:04:32,265 INFO TaskSetManager: Starting task 23.0 in stage 1.0 (TID 25, 10.1.2.181, partition 23, ANY, 5374 bytes)
17/01/29 07:04:32,265 INFO CoarseGrainedSchedulerBackend$DriverEndpoint: Launching task 25 on executor id: 1 hostname: 10.1.2.181.
17/01/29 07:04:32,266 INFO TaskSetManager: Finished task 13.0 in stage 1.0 (TID 15) in 21399 ms on 10.1.2.181 (9/59)
17/01/29 07:04:32,442 INFO BlockManagerInfo: Added rdd_5_11 in memory on 10.1.2.236:39970 (size: 69.9 MB, free: 1910.6 MB)
17/01/29 07:04:32,474 INFO TaskSetManager: Starting task 24.0 in stage 1.0 (TID 26, 10.1.2.236, partition 24, ANY, 5374 bytes)
17/01/29 07:04:32,474 INFO CoarseGrainedSchedulerBackend$DriverEndpoint: Launching task 26 on executor id: 3 hostname: 10.1.2.236.
17/01/29 07:04:32,474 INFO TaskSetManager: Finished task 11.0 in stage 1.0 (TID 13) in 21611 ms on 10.1.2.236 (10/59)
17/01/29 07:04:32,740 INFO BlockManagerInfo: Added rdd_5_5 in memory on 10.1.2.181:36196 (size: 70.0 MB, free: 1840.6 MB)
17/01/29 07:04:32,767 INFO TaskSetManager: Starting task 25.0 in stage 1.0 (TID 27, 10.1.2.181, partition 25, ANY, 5374 bytes)
17/01/29 07:04:32,768 INFO CoarseGrainedSchedulerBackend$DriverEndpoint: Launching task 27 on executor id: 1 hostname: 10.1.2.181.
17/01/29 07:04:32,769 INFO TaskSetManager: Finished task 5.0 in stage 1.0 (TID 7) in 21920 ms on 10.1.2.181 (11/59)
17/01/29 07:04:33,993 INFO BlockManagerInfo: Added rdd_5_7 in memory on 10.1.2.236:39970 (size: 70.0 MB, free: 1840.6 MB)
17/01/29 07:04:34,012 INFO TaskSetManager: Starting task 26.0 in stage 1.0 (TID 28, 10.1.2.236, partition 26, ANY, 5374 bytes)
17/01/29 07:04:34,012 INFO CoarseGrainedSchedulerBackend$DriverEndpoint: Launching task 28 on executor id: 3 hostname: 10.1.2.236.
17/01/29 07:04:34,012 INFO TaskSetManager: Finished task 7.0 in stage 1.0 (TID 9) in 23158 ms on 10.1.2.236 (12/59)
17/01/29 07:04:34,723 INFO BlockManagerInfo: Added rdd_5_14 in memory on 10.1.2.236:39970 (size: 69.9 MB, free: 1770.7 MB)
17/01/29 07:04:34,749 INFO TaskSetManager: Starting task 27.0 in stage 1.0 (TID 29, 10.1.2.236, partition 27, ANY, 5374 bytes)
17/01/29 07:04:34,750 INFO TaskSetManager: Finished task 14.0 in stage 1.0 (TID 16) in 23878 ms on 10.1.2.236 (13/59)
17/01/29 07:04:34,750 INFO CoarseGrainedSchedulerBackend$DriverEndpoint: Launching task 29 on executor id: 3 hostname: 10.1.2.236.
17/01/29 07:04:35,968 INFO BlockManagerInfo: Added rdd_5_4 in memory on 10.1.2.63:46374 (size: 70.0 MB, free: 2.0 GB)
17/01/29 07:04:36,071 INFO TaskSetManager: Starting task 28.0 in stage 1.0 (TID 30, 10.1.2.63, partition 28, ANY, 5374 bytes)
17/01/29 07:04:36,071 INFO CoarseGrainedSchedulerBackend$DriverEndpoint: Launching task 30 on executor id: 2 hostname: 10.1.2.63.
17/01/29 07:04:36,073 INFO TaskSetManager: Finished task 4.0 in stage 1.0 (TID 6) in 25229 ms on 10.1.2.63 (14/59)
17/01/29 07:04:36,439 INFO BlockManagerInfo: Added rdd_5_12 in memory on 10.1.2.63:46374 (size: 70.0 MB, free: 1980.4 MB)
17/01/29 07:04:36,472 INFO TaskSetManager: Finished task 12.0 in stage 1.0 (TID 14) in 25607 ms on 10.1.2.63 (15/59)
17/01/29 07:04:36,476 INFO BlockManagerInfo: Added rdd_5_8 in memory on 10.1.2.63:46374 (size: 70.0 MB, free: 1910.5 MB)
17/01/29 07:04:36,476 INFO TaskSetManager: Starting task 29.0 in stage 1.0 (TID 31, 10.1.2.63, partition 29, ANY, 5374 bytes)
17/01/29 07:04:36,477 INFO CoarseGrainedSchedulerBackend$DriverEndpoint: Launching task 31 on executor id: 2 hostname: 10.1.2.63.
17/01/29 07:04:36,519 INFO TaskSetManager: Starting task 30.0 in stage 1.0 (TID 32, 10.1.2.63, partition 30, ANY, 5374 bytes)
17/01/29 07:04:36,520 INFO CoarseGrainedSchedulerBackend$DriverEndpoint: Launching task 32 on executor id: 2 hostname: 10.1.2.63.
17/01/29 07:04:36,520 INFO TaskSetManager: Finished task 8.0 in stage 1.0 (TID 10) in 25664 ms on 10.1.2.63 (16/59)
17/01/29 07:04:37,006 INFO BlockManagerInfo: Added rdd_5_15 in memory on 10.1.2.63:46374 (size: 69.9 MB, free: 1840.5 MB)
17/01/29 07:04:37,028 INFO TaskSetManager: Starting task 31.0 in stage 1.0 (TID 33, 10.1.2.63, partition 31, ANY, 5374 bytes)
17/01/29 07:04:37,028 INFO CoarseGrainedSchedulerBackend$DriverEndpoint: Launching task 33 on executor id: 2 hostname: 10.1.2.63.
17/01/29 07:04:37,029 INFO TaskSetManager: Finished task 15.0 in stage 1.0 (TID 17) in 26156 ms on 10.1.2.63 (17/59)
17/01/29 07:04:43,260 INFO BlockManagerInfo: Added rdd_5_16 in memory on 10.1.2.71:38780 (size: 70.0 MB, free: 1767.8 MB)
17/01/29 07:04:43,288 INFO TaskSetManager: Starting task 32.0 in stage 1.0 (TID 34, 10.1.2.71, partition 32, ANY, 5374 bytes)
17/01/29 07:04:43,289 INFO CoarseGrainedSchedulerBackend$DriverEndpoint: Launching task 34 on executor id: 0 hostname: 10.1.2.71.
17/01/29 07:04:43,291 INFO TaskSetManager: Finished task 16.0 in stage 1.0 (TID 18) in 18706 ms on 10.1.2.71 (18/59)
17/01/29 07:04:48,304 INFO BlockManagerInfo: Added rdd_5_17 in memory on 10.1.2.71:38780 (size: 69.9 MB, free: 1697.9 MB)
17/01/29 07:04:48,324 INFO TaskSetManager: Starting task 33.0 in stage 1.0 (TID 35, 10.1.2.71, partition 33, ANY, 5374 bytes)
17/01/29 07:04:48,324 INFO CoarseGrainedSchedulerBackend$DriverEndpoint: Launching task 35 on executor id: 0 hostname: 10.1.2.71.
17/01/29 07:04:48,325 INFO TaskSetManager: Finished task 17.0 in stage 1.0 (TID 19) in 20234 ms on 10.1.2.71 (19/59)
17/01/29 07:04:48,413 INFO BlockManagerInfo: Added rdd_5_19 in memory on 10.1.2.71:38780 (size: 70.0 MB, free: 1628.0 MB)
17/01/29 07:04:48,434 INFO TaskSetManager: Starting task 34.0 in stage 1.0 (TID 36, 10.1.2.71, partition 34, ANY, 5374 bytes)
17/01/29 07:04:48,435 INFO CoarseGrainedSchedulerBackend$DriverEndpoint: Launching task 36 on executor id: 0 hostname: 10.1.2.71.
17/01/29 07:04:48,436 INFO TaskSetManager: Finished task 19.0 in stage 1.0 (TID 21) in 19916 ms on 10.1.2.71 (20/59)
17/01/29 07:04:48,768 INFO BlockManagerInfo: Added rdd_5_18 in memory on 10.1.2.71:38780 (size: 70.0 MB, free: 1558.0 MB)
17/01/29 07:04:48,788 INFO TaskSetManager: Starting task 35.0 in stage 1.0 (TID 37, 10.1.2.71, partition 35, ANY, 5374 bytes)
17/01/29 07:04:48,789 INFO CoarseGrainedSchedulerBackend$DriverEndpoint: Launching task 37 on executor id: 0 hostname: 10.1.2.71.
17/01/29 07:04:48,789 INFO TaskSetManager: Finished task 18.0 in stage 1.0 (TID 20) in 20300 ms on 10.1.2.71 (21/59)
17/01/29 07:04:50,404 INFO BlockManagerInfo: Added rdd_5_21 in memory on 10.1.2.181:36196 (size: 69.9 MB, free: 1770.7 MB)
17/01/29 07:04:50,421 INFO TaskSetManager: Finished task 21.0 in stage 1.0 (TID 23) in 18492 ms on 10.1.2.181 (22/59)
17/01/29 07:04:50,423 INFO TaskSetManager: Starting task 36.0 in stage 1.0 (TID 38, 10.1.2.181, partition 36, ANY, 5374 bytes)
17/01/29 07:04:50,423 INFO CoarseGrainedSchedulerBackend$DriverEndpoint: Launching task 38 on executor id: 1 hostname: 10.1.2.181.
17/01/29 07:04:50,496 INFO BlockManagerInfo: Added rdd_5_23 in memory on 10.1.2.181:36196 (size: 69.9 MB, free: 1700.8 MB)
17/01/29 07:04:50,512 INFO TaskSetManager: Finished task 23.0 in stage 1.0 (TID 25) in 18249 ms on 10.1.2.181 (23/59)
17/01/29 07:04:50,514 INFO TaskSetManager: Starting task 37.0 in stage 1.0 (TID 39, 10.1.2.181, partition 37, ANY, 5374 bytes)
17/01/29 07:04:50,514 INFO CoarseGrainedSchedulerBackend$DriverEndpoint: Launching task 39 on executor id: 1 hostname: 10.1.2.181.
17/01/29 07:04:51,124 INFO BlockManagerInfo: Added rdd_5_22 in memory on 10.1.2.181:36196 (size: 69.8 MB, free: 1630.9 MB)
17/01/29 07:04:51,142 INFO TaskSetManager: Starting task 38.0 in stage 1.0 (TID 40, 10.1.2.181, partition 38, ANY, 5374 bytes)
17/01/29 07:04:51,142 INFO CoarseGrainedSchedulerBackend$DriverEndpoint: Launching task 40 on executor id: 1 hostname: 10.1.2.181.
17/01/29 07:04:51,143 INFO TaskSetManager: Finished task 22.0 in stage 1.0 (TID 24) in 18883 ms on 10.1.2.181 (24/59)
17/01/29 07:04:51,596 INFO BlockManagerInfo: Added rdd_5_25 in memory on 10.1.2.181:36196 (size: 70.0 MB, free: 1561.0 MB)
17/01/29 07:04:51,614 INFO TaskSetManager: Starting task 39.0 in stage 1.0 (TID 41, 10.1.2.181, partition 39, ANY, 5374 bytes)
17/01/29 07:04:51,615 INFO CoarseGrainedSchedulerBackend$DriverEndpoint: Launching task 41 on executor id: 1 hostname: 10.1.2.181.
17/01/29 07:04:51,615 INFO TaskSetManager: Finished task 25.0 in stage 1.0 (TID 27) in 18849 ms on 10.1.2.181 (25/59)
17/01/29 07:04:52,139 INFO BlockManagerInfo: Added rdd_5_24 in memory on 10.1.2.236:39970 (size: 69.8 MB, free: 1700.9 MB)
17/01/29 07:04:52,155 INFO TaskSetManager: Starting task 40.0 in stage 1.0 (TID 42, 10.1.2.236, partition 40, ANY, 5374 bytes)
17/01/29 07:04:52,155 INFO CoarseGrainedSchedulerBackend$DriverEndpoint: Launching task 42 on executor id: 3 hostname: 10.1.2.236.
17/01/29 07:04:52,156 INFO TaskSetManager: Finished task 24.0 in stage 1.0 (TID 26) in 19684 ms on 10.1.2.236 (26/59)
17/01/29 07:04:55,262 INFO BlockManagerInfo: Added rdd_5_20 in memory on 10.1.2.236:39970 (size: 69.8 MB, free: 1631.1 MB)
17/01/29 07:04:55,279 INFO TaskSetManager: Starting task 41.0 in stage 1.0 (TID 43, 10.1.2.236, partition 41, ANY, 5374 bytes)
17/01/29 07:04:55,279 INFO CoarseGrainedSchedulerBackend$DriverEndpoint: Launching task 43 on executor id: 3 hostname: 10.1.2.236.
17/01/29 07:04:55,279 INFO TaskSetManager: Finished task 20.0 in stage 1.0 (TID 22) in 23610 ms on 10.1.2.236 (27/59)
17/01/29 07:04:55,568 INFO BlockManagerInfo: Added rdd_5_26 in memory on 10.1.2.236:39970 (size: 69.9 MB, free: 1561.2 MB)
17/01/29 07:04:55,588 INFO TaskSetManager: Starting task 42.0 in stage 1.0 (TID 44, 10.1.2.236, partition 42, ANY, 5374 bytes)
17/01/29 07:04:55,588 INFO CoarseGrainedSchedulerBackend$DriverEndpoint: Launching task 44 on executor id: 3 hostname: 10.1.2.236.
17/01/29 07:04:55,588 INFO TaskSetManager: Finished task 26.0 in stage 1.0 (TID 28) in 21578 ms on 10.1.2.236 (28/59)
17/01/29 07:04:55,692 INFO BlockManagerInfo: Added rdd_5_27 in memory on 10.1.2.236:39970 (size: 69.9 MB, free: 1491.3 MB)
17/01/29 07:04:55,710 INFO TaskSetManager: Starting task 43.0 in stage 1.0 (TID 45, 10.1.2.236, partition 43, ANY, 5374 bytes)
17/01/29 07:04:55,710 INFO CoarseGrainedSchedulerBackend$DriverEndpoint: Launching task 45 on executor id: 3 hostname: 10.1.2.236.
17/01/29 07:04:55,711 INFO TaskSetManager: Finished task 27.0 in stage 1.0 (TID 29) in 20963 ms on 10.1.2.236 (29/59)
17/01/29 07:04:56,553 INFO BlockManagerInfo: Added rdd_5_30 in memory on 10.1.2.63:46374 (size: 70.0 MB, free: 1770.6 MB)
17/01/29 07:04:56,572 INFO TaskSetManager: Starting task 44.0 in stage 1.0 (TID 46, 10.1.2.63, partition 44, ANY, 5374 bytes)
17/01/29 07:04:56,572 INFO CoarseGrainedSchedulerBackend$DriverEndpoint: Launching task 46 on executor id: 2 hostname: 10.1.2.63.
17/01/29 07:04:56,573 INFO TaskSetManager: Finished task 30.0 in stage 1.0 (TID 32) in 20055 ms on 10.1.2.63 (30/59)
17/01/29 07:04:56,788 INFO BlockManagerInfo: Added rdd_5_28 in memory on 10.1.2.63:46374 (size: 70.0 MB, free: 1700.6 MB)
17/01/29 07:04:56,806 INFO TaskSetManager: Starting task 45.0 in stage 1.0 (TID 47, 10.1.2.63, partition 45, ANY, 5374 bytes)
17/01/29 07:04:56,806 INFO CoarseGrainedSchedulerBackend$DriverEndpoint: Launching task 47 on executor id: 2 hostname: 10.1.2.63.
17/01/29 07:04:56,806 INFO TaskSetManager: Finished task 28.0 in stage 1.0 (TID 30) in 20737 ms on 10.1.2.63 (31/59)
17/01/29 07:04:57,142 INFO BlockManagerInfo: Added rdd_5_29 in memory on 10.1.2.63:46374 (size: 69.9 MB, free: 1630.7 MB)
17/01/29 07:04:57,167 INFO TaskSetManager: Starting task 46.0 in stage 1.0 (TID 48, 10.1.2.63, partition 46, ANY, 5374 bytes)
17/01/29 07:04:57,168 INFO CoarseGrainedSchedulerBackend$DriverEndpoint: Launching task 48 on executor id: 2 hostname: 10.1.2.63.
17/01/29 07:04:57,169 INFO TaskSetManager: Finished task 29.0 in stage 1.0 (TID 31) in 20696 ms on 10.1.2.63 (32/59)
17/01/29 07:04:57,282 INFO BlockManagerInfo: Added rdd_5_31 in memory on 10.1.2.63:46374 (size: 69.7 MB, free: 1560.9 MB)
17/01/29 07:04:57,306 INFO TaskSetManager: Starting task 47.0 in stage 1.0 (TID 49, 10.1.2.63, partition 47, ANY, 5374 bytes)
17/01/29 07:04:57,306 INFO CoarseGrainedSchedulerBackend$DriverEndpoint: Launching task 49 on executor id: 2 hostname: 10.1.2.63.
17/01/29 07:04:57,307 INFO TaskSetManager: Finished task 31.0 in stage 1.0 (TID 33) in 20281 ms on 10.1.2.63 (33/59)
17/01/29 07:05:00,991 INFO BlockManagerInfo: Added rdd_5_32 in memory on 10.1.2.71:38780 (size: 69.9 MB, free: 1488.1 MB)
17/01/29 07:05:01,009 INFO TaskSetManager: Starting task 48.0 in stage 1.0 (TID 50, 10.1.2.71, partition 48, ANY, 5374 bytes)
17/01/29 07:05:01,009 INFO CoarseGrainedSchedulerBackend$DriverEndpoint: Launching task 50 on executor id: 0 hostname: 10.1.2.71.
17/01/29 07:05:01,011 INFO TaskSetManager: Finished task 32.0 in stage 1.0 (TID 34) in 17723 ms on 10.1.2.71 (34/59)
17/01/29 07:05:07,142 INFO BlockManagerInfo: Added rdd_5_33 in memory on 10.1.2.71:38780 (size: 69.9 MB, free: 1418.2 MB)
17/01/29 07:05:07,162 INFO TaskSetManager: Starting task 49.0 in stage 1.0 (TID 51, 10.1.2.71, partition 49, ANY, 5374 bytes)
17/01/29 07:05:07,162 INFO CoarseGrainedSchedulerBackend$DriverEndpoint: Launching task 51 on executor id: 0 hostname: 10.1.2.71.
17/01/29 07:05:07,163 INFO TaskSetManager: Finished task 33.0 in stage 1.0 (TID 35) in 18840 ms on 10.1.2.71 (35/59)
17/01/29 07:05:07,383 INFO BlockManagerInfo: Added rdd_5_34 in memory on 10.1.2.71:38780 (size: 70.0 MB, free: 1348.2 MB)
17/01/29 07:05:07,403 INFO TaskSetManager: Starting task 50.0 in stage 1.0 (TID 52, 10.1.2.71, partition 50, ANY, 5374 bytes)
17/01/29 07:05:07,403 INFO CoarseGrainedSchedulerBackend$DriverEndpoint: Launching task 52 on executor id: 0 hostname: 10.1.2.71.
17/01/29 07:05:07,403 INFO TaskSetManager: Finished task 34.0 in stage 1.0 (TID 36) in 18970 ms on 10.1.2.71 (36/59)
17/01/29 07:05:07,896 INFO BlockManagerInfo: Added rdd_5_35 in memory on 10.1.2.71:38780 (size: 70.0 MB, free: 1278.2 MB)
17/01/29 07:05:07,915 INFO TaskSetManager: Starting task 51.0 in stage 1.0 (TID 53, 10.1.2.71, partition 51, ANY, 5374 bytes)
17/01/29 07:05:07,915 INFO CoarseGrainedSchedulerBackend$DriverEndpoint: Launching task 53 on executor id: 0 hostname: 10.1.2.71.
17/01/29 07:05:07,915 INFO TaskSetManager: Finished task 35.0 in stage 1.0 (TID 37) in 19128 ms on 10.1.2.71 (37/59)
17/01/29 07:05:08,910 INFO BlockManagerInfo: Added rdd_5_37 in memory on 10.1.2.181:36196 (size: 69.9 MB, free: 1491.0 MB)
17/01/29 07:05:08,930 INFO TaskSetManager: Starting task 52.0 in stage 1.0 (TID 54, 10.1.2.181, partition 52, ANY, 5374 bytes)
17/01/29 07:05:08,930 INFO CoarseGrainedSchedulerBackend$DriverEndpoint: Launching task 54 on executor id: 1 hostname: 10.1.2.181.
17/01/29 07:05:08,931 INFO TaskSetManager: Finished task 37.0 in stage 1.0 (TID 39) in 18418 ms on 10.1.2.181 (38/59)
17/01/29 07:05:08,956 INFO BlockManagerInfo: Added rdd_5_36 in memory on 10.1.2.181:36196 (size: 70.0 MB, free: 1421.0 MB)
17/01/29 07:05:08,973 INFO TaskSetManager: Starting task 53.0 in stage 1.0 (TID 55, 10.1.2.181, partition 53, ANY, 5374 bytes)
17/01/29 07:05:08,974 INFO CoarseGrainedSchedulerBackend$DriverEndpoint: Launching task 55 on executor id: 1 hostname: 10.1.2.181.
17/01/29 07:05:08,974 INFO TaskSetManager: Finished task 36.0 in stage 1.0 (TID 38) in 18552 ms on 10.1.2.181 (39/59)
17/01/29 07:05:09,536 INFO BlockManagerInfo: Added rdd_5_38 in memory on 10.1.2.181:36196 (size: 70.0 MB, free: 1351.0 MB)
17/01/29 07:05:09,552 INFO TaskSetManager: Starting task 54.0 in stage 1.0 (TID 56, 10.1.2.181, partition 54, ANY, 5374 bytes)
17/01/29 07:05:09,553 INFO CoarseGrainedSchedulerBackend$DriverEndpoint: Launching task 56 on executor id: 1 hostname: 10.1.2.181.
17/01/29 07:05:09,553 INFO TaskSetManager: Finished task 38.0 in stage 1.0 (TID 40) in 18412 ms on 10.1.2.181 (40/59)
17/01/29 07:05:10,590 INFO BlockManagerInfo: Added rdd_5_39 in memory on 10.1.2.181:36196 (size: 70.0 MB, free: 1281.1 MB)
17/01/29 07:05:10,607 INFO TaskSetManager: Starting task 55.0 in stage 1.0 (TID 57, 10.1.2.181, partition 55, ANY, 5374 bytes)
17/01/29 07:05:10,607 INFO CoarseGrainedSchedulerBackend$DriverEndpoint: Launching task 57 on executor id: 1 hostname: 10.1.2.181.
17/01/29 07:05:10,607 INFO TaskSetManager: Finished task 39.0 in stage 1.0 (TID 41) in 18994 ms on 10.1.2.181 (41/59)
17/01/29 07:05:14,278 INFO BlockManagerInfo: Added rdd_5_40 in memory on 10.1.2.236:39970 (size: 70.0 MB, free: 1421.3 MB)
17/01/29 07:05:14,300 INFO TaskSetManager: Starting task 56.0 in stage 1.0 (TID 58, 10.1.2.236, partition 56, ANY, 5374 bytes)
17/01/29 07:05:14,300 INFO CoarseGrainedSchedulerBackend$DriverEndpoint: Launching task 58 on executor id: 3 hostname: 10.1.2.236.
17/01/29 07:05:14,301 INFO TaskSetManager: Finished task 40.0 in stage 1.0 (TID 42) in 22147 ms on 10.1.2.236 (42/59)
17/01/29 07:05:17,198 INFO BlockManagerInfo: Added rdd_5_44 in memory on 10.1.2.63:46374 (size: 70.0 MB, free: 1491.0 MB)
17/01/29 07:05:17,215 INFO TaskSetManager: Starting task 57.0 in stage 1.0 (TID 59, 10.1.2.63, partition 57, ANY, 5374 bytes)
17/01/29 07:05:17,215 INFO CoarseGrainedSchedulerBackend$DriverEndpoint: Launching task 59 on executor id: 2 hostname: 10.1.2.63.
17/01/29 07:05:17,216 INFO TaskSetManager: Finished task 44.0 in stage 1.0 (TID 46) in 20645 ms on 10.1.2.63 (43/59)
17/01/29 07:05:17,315 INFO BlockManagerInfo: Added rdd_5_41 in memory on 10.1.2.236:39970 (size: 70.0 MB, free: 1351.3 MB)
17/01/29 07:05:17,330 INFO TaskSetManager: Finished task 41.0 in stage 1.0 (TID 43) in 22052 ms on 10.1.2.236 (44/59)
17/01/29 07:05:17,820 INFO BlockManagerInfo: Added rdd_5_42 in memory on 10.1.2.236:39970 (size: 69.8 MB, free: 1281.5 MB)
17/01/29 07:05:17,839 INFO TaskSetManager: Finished task 42.0 in stage 1.0 (TID 44) in 22252 ms on 10.1.2.236 (45/59)
17/01/29 07:05:17,894 INFO BlockManagerInfo: Added rdd_5_43 in memory on 10.1.2.236:39970 (size: 69.8 MB, free: 1211.7 MB)
17/01/29 07:05:17,912 INFO TaskSetManager: Finished task 43.0 in stage 1.0 (TID 45) in 22203 ms on 10.1.2.236 (46/59)
17/01/29 07:05:18,239 INFO BlockManagerInfo: Added rdd_5_46 in memory on 10.1.2.63:46374 (size: 69.9 MB, free: 1421.0 MB)
17/01/29 07:05:18,256 INFO TaskSetManager: Finished task 46.0 in stage 1.0 (TID 48) in 21088 ms on 10.1.2.63 (47/59)
17/01/29 07:05:18,615 INFO BlockManagerInfo: Added rdd_5_47 in memory on 10.1.2.63:46374 (size: 70.0 MB, free: 1351.1 MB)
17/01/29 07:05:18,632 INFO TaskSetManager: Finished task 47.0 in stage 1.0 (TID 49) in 21327 ms on 10.1.2.63 (48/59)
17/01/29 07:05:18,744 INFO BlockManagerInfo: Added rdd_5_45 in memory on 10.1.2.63:46374 (size: 69.9 MB, free: 1281.2 MB)
17/01/29 07:05:18,762 INFO TaskSetManager: Finished task 45.0 in stage 1.0 (TID 47) in 21957 ms on 10.1.2.63 (49/59)
17/01/29 07:05:22,192 INFO BlockManagerInfo: Added rdd_5_48 in memory on 10.1.2.71:38780 (size: 69.9 MB, free: 1208.3 MB)
17/01/29 07:05:22,212 INFO TaskSetManager: Finished task 48.0 in stage 1.0 (TID 50) in 21204 ms on 10.1.2.71 (50/59)
17/01/29 07:05:22,465 INFO BlockManagerInfo: Added rdd_5_56 in memory on 10.1.2.236:39970 (size: 69.9 MB, free: 1141.8 MB)
17/01/29 07:05:22,484 INFO TaskSetManager: Finished task 56.0 in stage 1.0 (TID 58) in 8186 ms on 10.1.2.236 (51/59)
17/01/29 07:05:23,809 INFO BlockManagerInfo: Added rdd_5_57 in memory on 10.1.2.63:46374 (size: 70.1 MB, free: 1211.1 MB)
17/01/29 07:05:23,826 INFO TaskSetManager: Finished task 57.0 in stage 1.0 (TID 59) in 6612 ms on 10.1.2.63 (52/59)
17/01/29 07:05:25,745 INFO BlockManagerInfo: Added rdd_5_49 in memory on 10.1.2.71:38780 (size: 69.8 MB, free: 1138.5 MB)
17/01/29 07:05:25,763 INFO TaskSetManager: Finished task 49.0 in stage 1.0 (TID 51) in 18602 ms on 10.1.2.71 (53/59)
17/01/29 07:05:26,109 INFO BlockManagerInfo: Added rdd_5_50 in memory on 10.1.2.71:38780 (size: 69.9 MB, free: 1068.6 MB)
17/01/29 07:05:26,129 INFO TaskSetManager: Finished task 50.0 in stage 1.0 (TID 52) in 18726 ms on 10.1.2.71 (54/59)
17/01/29 07:05:26,332 INFO BlockManagerInfo: Added rdd_5_51 in memory on 10.1.2.71:38780 (size: 69.9 MB, free: 998.7 MB)
17/01/29 07:05:26,351 INFO TaskSetManager: Finished task 51.0 in stage 1.0 (TID 53) in 18437 ms on 10.1.2.71 (55/59)
17/01/29 07:05:27,363 INFO BlockManagerInfo: Added rdd_5_53 in memory on 10.1.2.181:36196 (size: 70.0 MB, free: 1211.0 MB)
17/01/29 07:05:27,379 INFO TaskSetManager: Finished task 53.0 in stage 1.0 (TID 55) in 18407 ms on 10.1.2.181 (56/59)
17/01/29 07:05:27,458 INFO BlockManagerInfo: Added rdd_5_52 in memory on 10.1.2.181:36196 (size: 69.9 MB, free: 1141.2 MB)
17/01/29 07:05:27,473 INFO TaskSetManager: Finished task 52.0 in stage 1.0 (TID 54) in 18544 ms on 10.1.2.181 (57/59)
17/01/29 07:05:27,672 INFO BlockManagerInfo: Added rdd_5_54 in memory on 10.1.2.181:36196 (size: 69.9 MB, free: 1071.2 MB)
17/01/29 07:05:27,687 INFO TaskSetManager: Finished task 54.0 in stage 1.0 (TID 56) in 18135 ms on 10.1.2.181 (58/59)
17/01/29 07:05:28,377 INFO BlockManagerInfo: Added rdd_5_55 in memory on 10.1.2.181:36196 (size: 69.9 MB, free: 1001.4 MB)
17/01/29 07:05:28,392 INFO TaskSetManager: Finished task 55.0 in stage 1.0 (TID 57) in 17785 ms on 10.1.2.181 (59/59)
17/01/29 07:05:28,392 INFO TaskSchedulerImpl: Removed TaskSet 1.0, whose tasks have all completed, from pool 
17/01/29 07:05:28,392 INFO DAGScheduler: ResultStage 1 (count at DataValidators.scala:40) finished in 80.664 s
17/01/29 07:05:28,393 INFO DAGScheduler: Job 1 finished: count at DataValidators.scala:40, took 80.705941 s
17/01/29 07:05:28,403 INFO SparkContext: Starting job: count at GradientDescent.scala:209
17/01/29 07:05:28,404 INFO DAGScheduler: Got job 2 (count at GradientDescent.scala:209) with 59 output partitions
17/01/29 07:05:28,404 INFO DAGScheduler: Final stage: ResultStage 2 (count at GradientDescent.scala:209)
17/01/29 07:05:28,404 INFO DAGScheduler: Parents of final stage: List()
17/01/29 07:05:28,407 INFO DAGScheduler: Missing parents: List()
17/01/29 07:05:28,408 INFO DAGScheduler: Submitting ResultStage 2 (MapPartitionsRDD[8] at map at GeneralizedLinearAlgorithm.scala:297), which has no missing parents
17/01/29 07:05:28,413 INFO MemoryStore: Block broadcast_3 stored as values in memory (estimated size 3.9 KB, free 2.1 GB)
17/01/29 07:05:28,416 INFO MemoryStore: Block broadcast_3_piece0 stored as bytes in memory (estimated size 2.2 KB, free 2.1 GB)
17/01/29 07:05:28,416 INFO BlockManagerInfo: Added broadcast_3_piece0 in memory on 10.1.2.142:43652 (size: 2.2 KB, free: 2.1 GB)
17/01/29 07:05:28,421 INFO SparkContext: Created broadcast 3 from broadcast at DAGScheduler.scala:1012
17/01/29 07:05:28,423 INFO DAGScheduler: Submitting 59 missing tasks from ResultStage 2 (MapPartitionsRDD[8] at map at GeneralizedLinearAlgorithm.scala:297)
17/01/29 07:05:28,423 INFO TaskSchedulerImpl: Adding task set 2.0 with 59 tasks
17/01/29 07:05:28,427 INFO TaskSetManager: Starting task 4.0 in stage 2.0 (TID 60, 10.1.2.63, partition 4, PROCESS_LOCAL, 5374 bytes)
17/01/29 07:05:28,428 INFO TaskSetManager: Starting task 1.0 in stage 2.0 (TID 61, 10.1.2.181, partition 1, PROCESS_LOCAL, 5374 bytes)
17/01/29 07:05:28,428 INFO TaskSetManager: Starting task 0.0 in stage 2.0 (TID 62, 10.1.2.236, partition 0, PROCESS_LOCAL, 5374 bytes)
17/01/29 07:05:28,429 INFO TaskSetManager: Starting task 2.0 in stage 2.0 (TID 63, 10.1.2.71, partition 2, PROCESS_LOCAL, 5374 bytes)
17/01/29 07:05:28,431 INFO TaskSetManager: Starting task 8.0 in stage 2.0 (TID 64, 10.1.2.63, partition 8, PROCESS_LOCAL, 5374 bytes)
17/01/29 07:05:28,432 INFO TaskSetManager: Starting task 5.0 in stage 2.0 (TID 65, 10.1.2.181, partition 5, PROCESS_LOCAL, 5374 bytes)
17/01/29 07:05:28,433 INFO TaskSetManager: Starting task 3.0 in stage 2.0 (TID 66, 10.1.2.236, partition 3, PROCESS_LOCAL, 5374 bytes)
17/01/29 07:05:28,433 INFO TaskSetManager: Starting task 6.0 in stage 2.0 (TID 67, 10.1.2.71, partition 6, PROCESS_LOCAL, 5374 bytes)
17/01/29 07:05:28,434 INFO TaskSetManager: Starting task 12.0 in stage 2.0 (TID 68, 10.1.2.63, partition 12, PROCESS_LOCAL, 5374 bytes)
17/01/29 07:05:28,435 INFO TaskSetManager: Starting task 9.0 in stage 2.0 (TID 69, 10.1.2.181, partition 9, PROCESS_LOCAL, 5374 bytes)
17/01/29 07:05:28,435 INFO TaskSetManager: Starting task 7.0 in stage 2.0 (TID 70, 10.1.2.236, partition 7, PROCESS_LOCAL, 5374 bytes)
17/01/29 07:05:28,436 INFO TaskSetManager: Starting task 10.0 in stage 2.0 (TID 71, 10.1.2.71, partition 10, PROCESS_LOCAL, 5374 bytes)
17/01/29 07:05:28,437 INFO TaskSetManager: Starting task 15.0 in stage 2.0 (TID 72, 10.1.2.63, partition 15, PROCESS_LOCAL, 5374 bytes)
17/01/29 07:05:28,438 INFO TaskSetManager: Starting task 13.0 in stage 2.0 (TID 73, 10.1.2.181, partition 13, PROCESS_LOCAL, 5374 bytes)
17/01/29 07:05:28,439 INFO TaskSetManager: Starting task 11.0 in stage 2.0 (TID 74, 10.1.2.236, partition 11, PROCESS_LOCAL, 5374 bytes)
17/01/29 07:05:28,440 INFO TaskSetManager: Starting task 16.0 in stage 2.0 (TID 75, 10.1.2.71, partition 16, PROCESS_LOCAL, 5374 bytes)
17/01/29 07:05:28,441 INFO CoarseGrainedSchedulerBackend$DriverEndpoint: Launching task 60 on executor id: 2 hostname: 10.1.2.63.
17/01/29 07:05:28,441 INFO CoarseGrainedSchedulerBackend$DriverEndpoint: Launching task 64 on executor id: 2 hostname: 10.1.2.63.
17/01/29 07:05:28,441 INFO CoarseGrainedSchedulerBackend$DriverEndpoint: Launching task 68 on executor id: 2 hostname: 10.1.2.63.
17/01/29 07:05:28,442 INFO CoarseGrainedSchedulerBackend$DriverEndpoint: Launching task 72 on executor id: 2 hostname: 10.1.2.63.
17/01/29 07:05:28,442 INFO CoarseGrainedSchedulerBackend$DriverEndpoint: Launching task 61 on executor id: 1 hostname: 10.1.2.181.
17/01/29 07:05:28,443 INFO CoarseGrainedSchedulerBackend$DriverEndpoint: Launching task 65 on executor id: 1 hostname: 10.1.2.181.
17/01/29 07:05:28,443 INFO CoarseGrainedSchedulerBackend$DriverEndpoint: Launching task 69 on executor id: 1 hostname: 10.1.2.181.
17/01/29 07:05:28,444 INFO CoarseGrainedSchedulerBackend$DriverEndpoint: Launching task 73 on executor id: 1 hostname: 10.1.2.181.
17/01/29 07:05:28,444 INFO CoarseGrainedSchedulerBackend$DriverEndpoint: Launching task 62 on executor id: 3 hostname: 10.1.2.236.
17/01/29 07:05:28,445 INFO CoarseGrainedSchedulerBackend$DriverEndpoint: Launching task 66 on executor id: 3 hostname: 10.1.2.236.
17/01/29 07:05:28,446 INFO CoarseGrainedSchedulerBackend$DriverEndpoint: Launching task 70 on executor id: 3 hostname: 10.1.2.236.
17/01/29 07:05:28,447 INFO CoarseGrainedSchedulerBackend$DriverEndpoint: Launching task 74 on executor id: 3 hostname: 10.1.2.236.
17/01/29 07:05:28,447 INFO CoarseGrainedSchedulerBackend$DriverEndpoint: Launching task 63 on executor id: 0 hostname: 10.1.2.71.
17/01/29 07:05:28,448 INFO CoarseGrainedSchedulerBackend$DriverEndpoint: Launching task 67 on executor id: 0 hostname: 10.1.2.71.
17/01/29 07:05:28,449 INFO CoarseGrainedSchedulerBackend$DriverEndpoint: Launching task 71 on executor id: 0 hostname: 10.1.2.71.
17/01/29 07:05:28,449 INFO CoarseGrainedSchedulerBackend$DriverEndpoint: Launching task 75 on executor id: 0 hostname: 10.1.2.71.
17/01/29 07:05:28,476 INFO BlockManagerInfo: Added broadcast_3_piece0 in memory on 10.1.2.236:39970 (size: 2.2 KB, free: 1141.8 MB)
17/01/29 07:05:28,478 INFO BlockManagerInfo: Added broadcast_3_piece0 in memory on 10.1.2.71:38780 (size: 2.2 KB, free: 998.7 MB)
17/01/29 07:05:28,511 INFO BlockManagerInfo: Added broadcast_3_piece0 in memory on 10.1.2.181:36196 (size: 2.2 KB, free: 1001.4 MB)
17/01/29 07:05:28,517 INFO TaskSetManager: Starting task 14.0 in stage 2.0 (TID 76, 10.1.2.236, partition 14, PROCESS_LOCAL, 5374 bytes)
17/01/29 07:05:28,518 INFO CoarseGrainedSchedulerBackend$DriverEndpoint: Launching task 76 on executor id: 3 hostname: 10.1.2.236.
17/01/29 07:05:28,518 INFO TaskSetManager: Finished task 3.0 in stage 2.0 (TID 66) in 86 ms on 10.1.2.236 (1/59)
17/01/29 07:05:28,520 INFO TaskSetManager: Starting task 17.0 in stage 2.0 (TID 77, 10.1.2.71, partition 17, PROCESS_LOCAL, 5374 bytes)
17/01/29 07:05:28,520 INFO CoarseGrainedSchedulerBackend$DriverEndpoint: Launching task 77 on executor id: 0 hostname: 10.1.2.71.
17/01/29 07:05:28,520 INFO BlockManagerInfo: Added broadcast_3_piece0 in memory on 10.1.2.63:46374 (size: 2.2 KB, free: 1211.1 MB)
17/01/29 07:05:28,520 INFO TaskSetManager: Finished task 2.0 in stage 2.0 (TID 63) in 91 ms on 10.1.2.71 (2/59)
17/01/29 07:05:28,522 INFO TaskSetManager: Starting task 20.0 in stage 2.0 (TID 78, 10.1.2.236, partition 20, PROCESS_LOCAL, 5374 bytes)
17/01/29 07:05:28,523 INFO CoarseGrainedSchedulerBackend$DriverEndpoint: Launching task 78 on executor id: 3 hostname: 10.1.2.236.
17/01/29 07:05:28,523 INFO TaskSetManager: Finished task 0.0 in stage 2.0 (TID 62) in 95 ms on 10.1.2.236 (3/59)
17/01/29 07:05:28,524 INFO TaskSetManager: Starting task 24.0 in stage 2.0 (TID 79, 10.1.2.236, partition 24, PROCESS_LOCAL, 5374 bytes)
17/01/29 07:05:28,524 INFO CoarseGrainedSchedulerBackend$DriverEndpoint: Launching task 79 on executor id: 3 hostname: 10.1.2.236.
17/01/29 07:05:28,524 INFO TaskSetManager: Finished task 11.0 in stage 2.0 (TID 74) in 86 ms on 10.1.2.236 (4/59)
17/01/29 07:05:28,530 INFO TaskSetManager: Starting task 26.0 in stage 2.0 (TID 80, 10.1.2.236, partition 26, PROCESS_LOCAL, 5374 bytes)
17/01/29 07:05:28,530 INFO CoarseGrainedSchedulerBackend$DriverEndpoint: Launching task 80 on executor id: 3 hostname: 10.1.2.236.
17/01/29 07:05:28,531 INFO TaskSetManager: Finished task 7.0 in stage 2.0 (TID 70) in 96 ms on 10.1.2.236 (5/59)
17/01/29 07:05:28,546 INFO TaskSetManager: Starting task 21.0 in stage 2.0 (TID 81, 10.1.2.181, partition 21, PROCESS_LOCAL, 5374 bytes)
17/01/29 07:05:28,546 INFO CoarseGrainedSchedulerBackend$DriverEndpoint: Launching task 81 on executor id: 1 hostname: 10.1.2.181.
17/01/29 07:05:28,546 INFO TaskSetManager: Finished task 1.0 in stage 2.0 (TID 61) in 119 ms on 10.1.2.181 (6/59)
17/01/29 07:05:28,547 INFO TaskSetManager: Starting task 22.0 in stage 2.0 (TID 82, 10.1.2.181, partition 22, PROCESS_LOCAL, 5374 bytes)
17/01/29 07:05:28,547 INFO CoarseGrainedSchedulerBackend$DriverEndpoint: Launching task 82 on executor id: 1 hostname: 10.1.2.181.
17/01/29 07:05:28,548 INFO TaskSetManager: Finished task 5.0 in stage 2.0 (TID 65) in 116 ms on 10.1.2.181 (7/59)
17/01/29 07:05:28,549 INFO TaskSetManager: Starting task 27.0 in stage 2.0 (TID 83, 10.1.2.236, partition 27, PROCESS_LOCAL, 5374 bytes)
17/01/29 07:05:28,549 INFO CoarseGrainedSchedulerBackend$DriverEndpoint: Launching task 83 on executor id: 3 hostname: 10.1.2.236.
17/01/29 07:05:28,549 INFO TaskSetManager: Finished task 24.0 in stage 2.0 (TID 79) in 26 ms on 10.1.2.236 (8/59)
17/01/29 07:05:28,552 INFO TaskSetManager: Starting task 40.0 in stage 2.0 (TID 84, 10.1.2.236, partition 40, PROCESS_LOCAL, 5374 bytes)
17/01/29 07:05:28,553 INFO CoarseGrainedSchedulerBackend$DriverEndpoint: Launching task 84 on executor id: 3 hostname: 10.1.2.236.
17/01/29 07:05:28,553 INFO TaskSetManager: Finished task 20.0 in stage 2.0 (TID 78) in 31 ms on 10.1.2.236 (9/59)
17/01/29 07:05:28,554 INFO TaskSetManager: Starting task 41.0 in stage 2.0 (TID 85, 10.1.2.236, partition 41, PROCESS_LOCAL, 5374 bytes)
17/01/29 07:05:28,555 INFO CoarseGrainedSchedulerBackend$DriverEndpoint: Launching task 85 on executor id: 3 hostname: 10.1.2.236.
17/01/29 07:05:28,555 INFO TaskSetManager: Finished task 14.0 in stage 2.0 (TID 76) in 38 ms on 10.1.2.236 (10/59)
17/01/29 07:05:28,557 INFO TaskSetManager: Starting task 18.0 in stage 2.0 (TID 86, 10.1.2.71, partition 18, PROCESS_LOCAL, 5374 bytes)
17/01/29 07:05:28,558 INFO CoarseGrainedSchedulerBackend$DriverEndpoint: Launching task 86 on executor id: 0 hostname: 10.1.2.71.
17/01/29 07:05:28,558 INFO TaskSetManager: Finished task 17.0 in stage 2.0 (TID 77) in 39 ms on 10.1.2.71 (11/59)
17/01/29 07:05:28,570 INFO TaskSetManager: Starting task 42.0 in stage 2.0 (TID 87, 10.1.2.236, partition 42, PROCESS_LOCAL, 5374 bytes)
17/01/29 07:05:28,571 INFO CoarseGrainedSchedulerBackend$DriverEndpoint: Launching task 87 on executor id: 3 hostname: 10.1.2.236.
17/01/29 07:05:28,571 INFO TaskSetManager: Finished task 26.0 in stage 2.0 (TID 80) in 41 ms on 10.1.2.236 (12/59)
17/01/29 07:05:28,572 INFO TaskSetManager: Starting task 19.0 in stage 2.0 (TID 88, 10.1.2.71, partition 19, PROCESS_LOCAL, 5374 bytes)
17/01/29 07:05:28,572 INFO CoarseGrainedSchedulerBackend$DriverEndpoint: Launching task 88 on executor id: 0 hostname: 10.1.2.71.
17/01/29 07:05:28,572 INFO TaskSetManager: Finished task 16.0 in stage 2.0 (TID 75) in 133 ms on 10.1.2.71 (13/59)
17/01/29 07:05:28,575 INFO TaskSetManager: Starting task 23.0 in stage 2.0 (TID 89, 10.1.2.181, partition 23, PROCESS_LOCAL, 5374 bytes)
17/01/29 07:05:28,575 INFO CoarseGrainedSchedulerBackend$DriverEndpoint: Launching task 89 on executor id: 1 hostname: 10.1.2.181.
17/01/29 07:05:28,575 INFO TaskSetManager: Finished task 21.0 in stage 2.0 (TID 81) in 30 ms on 10.1.2.181 (14/59)
17/01/29 07:05:28,576 INFO TaskSetManager: Starting task 25.0 in stage 2.0 (TID 90, 10.1.2.181, partition 25, PROCESS_LOCAL, 5374 bytes)
17/01/29 07:05:28,577 INFO CoarseGrainedSchedulerBackend$DriverEndpoint: Launching task 90 on executor id: 1 hostname: 10.1.2.181.
17/01/29 07:05:28,577 INFO TaskSetManager: Finished task 22.0 in stage 2.0 (TID 82) in 30 ms on 10.1.2.181 (15/59)
17/01/29 07:05:28,578 INFO TaskSetManager: Finished task 8.0 in stage 2.0 (TID 64) in 148 ms on 10.1.2.63 (16/59)
17/01/29 07:05:28,579 INFO TaskSetManager: Starting task 28.0 in stage 2.0 (TID 91, 10.1.2.63, partition 28, PROCESS_LOCAL, 5374 bytes)
17/01/29 07:05:28,580 INFO CoarseGrainedSchedulerBackend$DriverEndpoint: Launching task 91 on executor id: 2 hostname: 10.1.2.63.
17/01/29 07:05:28,581 INFO TaskSetManager: Starting task 29.0 in stage 2.0 (TID 92, 10.1.2.63, partition 29, PROCESS_LOCAL, 5374 bytes)
17/01/29 07:05:28,581 INFO CoarseGrainedSchedulerBackend$DriverEndpoint: Launching task 92 on executor id: 2 hostname: 10.1.2.63.
17/01/29 07:05:28,581 INFO TaskSetManager: Finished task 15.0 in stage 2.0 (TID 72) in 145 ms on 10.1.2.63 (17/59)
17/01/29 07:05:28,583 INFO TaskSetManager: Starting task 43.0 in stage 2.0 (TID 93, 10.1.2.236, partition 43, PROCESS_LOCAL, 5374 bytes)
17/01/29 07:05:28,583 INFO CoarseGrainedSchedulerBackend$DriverEndpoint: Launching task 93 on executor id: 3 hostname: 10.1.2.236.
17/01/29 07:05:28,583 INFO TaskSetManager: Finished task 41.0 in stage 2.0 (TID 85) in 29 ms on 10.1.2.236 (18/59)
17/01/29 07:05:28,585 INFO TaskSetManager: Starting task 56.0 in stage 2.0 (TID 94, 10.1.2.236, partition 56, PROCESS_LOCAL, 5374 bytes)
17/01/29 07:05:28,585 INFO CoarseGrainedSchedulerBackend$DriverEndpoint: Launching task 94 on executor id: 3 hostname: 10.1.2.236.
17/01/29 07:05:28,585 INFO TaskSetManager: Finished task 40.0 in stage 2.0 (TID 84) in 33 ms on 10.1.2.236 (19/59)
17/01/29 07:05:28,587 INFO TaskSetManager: Finished task 9.0 in stage 2.0 (TID 69) in 152 ms on 10.1.2.181 (20/59)
17/01/29 07:05:28,588 INFO TaskSetManager: Starting task 36.0 in stage 2.0 (TID 95, 10.1.2.181, partition 36, PROCESS_LOCAL, 5374 bytes)
17/01/29 07:05:28,588 INFO CoarseGrainedSchedulerBackend$DriverEndpoint: Launching task 95 on executor id: 1 hostname: 10.1.2.181.
17/01/29 07:05:28,589 INFO TaskSetManager: Starting task 30.0 in stage 2.0 (TID 96, 10.1.2.63, partition 30, PROCESS_LOCAL, 5374 bytes)
17/01/29 07:05:28,590 INFO TaskSetManager: Finished task 12.0 in stage 2.0 (TID 68) in 156 ms on 10.1.2.63 (21/59)
17/01/29 07:05:28,590 INFO CoarseGrainedSchedulerBackend$DriverEndpoint: Launching task 96 on executor id: 2 hostname: 10.1.2.63.
17/01/29 07:05:28,592 INFO TaskSetManager: Starting task 32.0 in stage 2.0 (TID 97, 10.1.2.71, partition 32, PROCESS_LOCAL, 5374 bytes)
17/01/29 07:05:28,592 INFO CoarseGrainedSchedulerBackend$DriverEndpoint: Launching task 97 on executor id: 0 hostname: 10.1.2.71.
17/01/29 07:05:28,593 INFO TaskSetManager: Finished task 18.0 in stage 2.0 (TID 86) in 35 ms on 10.1.2.71 (22/59)
17/01/29 07:05:28,593 INFO TaskSetManager: Finished task 27.0 in stage 2.0 (TID 83) in 45 ms on 10.1.2.236 (23/59)
17/01/29 07:05:28,594 INFO TaskSetManager: Finished task 4.0 in stage 2.0 (TID 60) in 168 ms on 10.1.2.63 (24/59)
17/01/29 07:05:28,596 INFO TaskSetManager: Starting task 31.0 in stage 2.0 (TID 98, 10.1.2.63, partition 31, PROCESS_LOCAL, 5374 bytes)
17/01/29 07:05:28,596 INFO CoarseGrainedSchedulerBackend$DriverEndpoint: Launching task 98 on executor id: 2 hostname: 10.1.2.63.
17/01/29 07:05:28,598 INFO TaskSetManager: Finished task 42.0 in stage 2.0 (TID 87) in 29 ms on 10.1.2.236 (25/59)
17/01/29 07:05:28,604 INFO TaskSetManager: Starting task 37.0 in stage 2.0 (TID 99, 10.1.2.181, partition 37, PROCESS_LOCAL, 5374 bytes)
17/01/29 07:05:28,605 INFO TaskSetManager: Finished task 25.0 in stage 2.0 (TID 90) in 29 ms on 10.1.2.181 (26/59)
17/01/29 07:05:28,606 INFO CoarseGrainedSchedulerBackend$DriverEndpoint: Launching task 99 on executor id: 1 hostname: 10.1.2.181.
17/01/29 07:05:28,607 INFO TaskSetManager: Starting task 38.0 in stage 2.0 (TID 100, 10.1.2.181, partition 38, PROCESS_LOCAL, 5374 bytes)
17/01/29 07:05:28,607 INFO CoarseGrainedSchedulerBackend$DriverEndpoint: Launching task 100 on executor id: 1 hostname: 10.1.2.181.
17/01/29 07:05:28,607 INFO TaskSetManager: Finished task 23.0 in stage 2.0 (TID 89) in 33 ms on 10.1.2.181 (27/59)
17/01/29 07:05:28,608 INFO TaskSetManager: Finished task 28.0 in stage 2.0 (TID 91) in 29 ms on 10.1.2.63 (28/59)
17/01/29 07:05:28,610 INFO TaskSetManager: Starting task 44.0 in stage 2.0 (TID 101, 10.1.2.63, partition 44, PROCESS_LOCAL, 5374 bytes)
17/01/29 07:05:28,610 INFO CoarseGrainedSchedulerBackend$DriverEndpoint: Launching task 101 on executor id: 2 hostname: 10.1.2.63.
17/01/29 07:05:28,611 INFO TaskSetManager: Starting task 33.0 in stage 2.0 (TID 102, 10.1.2.71, partition 33, PROCESS_LOCAL, 5374 bytes)
17/01/29 07:05:28,611 INFO CoarseGrainedSchedulerBackend$DriverEndpoint: Launching task 102 on executor id: 0 hostname: 10.1.2.71.
17/01/29 07:05:28,612 INFO TaskSetManager: Finished task 19.0 in stage 2.0 (TID 88) in 40 ms on 10.1.2.71 (29/59)
17/01/29 07:05:28,615 INFO TaskSetManager: Starting task 39.0 in stage 2.0 (TID 103, 10.1.2.181, partition 39, PROCESS_LOCAL, 5374 bytes)
17/01/29 07:05:28,616 INFO CoarseGrainedSchedulerBackend$DriverEndpoint: Launching task 103 on executor id: 1 hostname: 10.1.2.181.
17/01/29 07:05:28,616 INFO TaskSetManager: Finished task 43.0 in stage 2.0 (TID 93) in 34 ms on 10.1.2.236 (30/59)
17/01/29 07:05:28,616 INFO TaskSetManager: Finished task 36.0 in stage 2.0 (TID 95) in 29 ms on 10.1.2.181 (31/59)
17/01/29 07:05:28,617 INFO TaskSetManager: Starting task 52.0 in stage 2.0 (TID 104, 10.1.2.181, partition 52, PROCESS_LOCAL, 5374 bytes)
17/01/29 07:05:28,618 INFO CoarseGrainedSchedulerBackend$DriverEndpoint: Launching task 104 on executor id: 1 hostname: 10.1.2.181.
17/01/29 07:05:28,618 INFO TaskSetManager: Finished task 13.0 in stage 2.0 (TID 73) in 181 ms on 10.1.2.181 (32/59)
17/01/29 07:05:28,619 INFO TaskSetManager: Finished task 56.0 in stage 2.0 (TID 94) in 35 ms on 10.1.2.236 (33/59)
17/01/29 07:05:28,621 INFO TaskSetManager: Starting task 45.0 in stage 2.0 (TID 105, 10.1.2.63, partition 45, PROCESS_LOCAL, 5374 bytes)
17/01/29 07:05:28,621 INFO CoarseGrainedSchedulerBackend$DriverEndpoint: Launching task 105 on executor id: 2 hostname: 10.1.2.63.
17/01/29 07:05:28,621 INFO TaskSetManager: Finished task 29.0 in stage 2.0 (TID 92) in 41 ms on 10.1.2.63 (34/59)
17/01/29 07:05:28,623 INFO TaskSetManager: Starting task 34.0 in stage 2.0 (TID 106, 10.1.2.71, partition 34, PROCESS_LOCAL, 5374 bytes)
17/01/29 07:05:28,623 INFO CoarseGrainedSchedulerBackend$DriverEndpoint: Launching task 106 on executor id: 0 hostname: 10.1.2.71.
17/01/29 07:05:28,624 INFO TaskSetManager: Finished task 32.0 in stage 2.0 (TID 97) in 32 ms on 10.1.2.71 (35/59)
17/01/29 07:05:28,625 INFO TaskSetManager: Finished task 31.0 in stage 2.0 (TID 98) in 30 ms on 10.1.2.63 (36/59)
17/01/29 07:05:28,626 INFO TaskSetManager: Starting task 46.0 in stage 2.0 (TID 107, 10.1.2.63, partition 46, PROCESS_LOCAL, 5374 bytes)
17/01/29 07:05:28,627 INFO CoarseGrainedSchedulerBackend$DriverEndpoint: Launching task 107 on executor id: 2 hostname: 10.1.2.63.
17/01/29 07:05:28,628 INFO TaskSetManager: Starting task 47.0 in stage 2.0 (TID 108, 10.1.2.63, partition 47, PROCESS_LOCAL, 5374 bytes)
17/01/29 07:05:28,629 INFO CoarseGrainedSchedulerBackend$DriverEndpoint: Launching task 108 on executor id: 2 hostname: 10.1.2.63.
17/01/29 07:05:28,629 INFO TaskSetManager: Finished task 30.0 in stage 2.0 (TID 96) in 40 ms on 10.1.2.63 (37/59)
17/01/29 07:05:28,630 INFO TaskSetManager: Starting task 53.0 in stage 2.0 (TID 109, 10.1.2.181, partition 53, PROCESS_LOCAL, 5374 bytes)
17/01/29 07:05:28,631 INFO CoarseGrainedSchedulerBackend$DriverEndpoint: Launching task 109 on executor id: 1 hostname: 10.1.2.181.
17/01/29 07:05:28,631 INFO TaskSetManager: Finished task 37.0 in stage 2.0 (TID 99) in 27 ms on 10.1.2.181 (38/59)
17/01/29 07:05:28,638 INFO TaskSetManager: Starting task 57.0 in stage 2.0 (TID 110, 10.1.2.63, partition 57, PROCESS_LOCAL, 5374 bytes)
17/01/29 07:05:28,639 INFO CoarseGrainedSchedulerBackend$DriverEndpoint: Launching task 110 on executor id: 2 hostname: 10.1.2.63.
17/01/29 07:05:28,639 INFO TaskSetManager: Finished task 44.0 in stage 2.0 (TID 101) in 30 ms on 10.1.2.63 (39/59)
17/01/29 07:05:28,648 INFO TaskSetManager: Starting task 54.0 in stage 2.0 (TID 111, 10.1.2.181, partition 54, PROCESS_LOCAL, 5374 bytes)
17/01/29 07:05:28,648 INFO CoarseGrainedSchedulerBackend$DriverEndpoint: Launching task 111 on executor id: 1 hostname: 10.1.2.181.
17/01/29 07:05:28,648 INFO TaskSetManager: Finished task 38.0 in stage 2.0 (TID 100) in 42 ms on 10.1.2.181 (40/59)
17/01/29 07:05:28,649 INFO TaskSetManager: Starting task 55.0 in stage 2.0 (TID 112, 10.1.2.181, partition 55, PROCESS_LOCAL, 5374 bytes)
17/01/29 07:05:28,649 INFO CoarseGrainedSchedulerBackend$DriverEndpoint: Launching task 112 on executor id: 1 hostname: 10.1.2.181.
17/01/29 07:05:28,650 INFO TaskSetManager: Finished task 52.0 in stage 2.0 (TID 104) in 32 ms on 10.1.2.181 (41/59)
17/01/29 07:05:28,651 INFO TaskSetManager: Finished task 45.0 in stage 2.0 (TID 105) in 31 ms on 10.1.2.63 (42/59)
17/01/29 07:05:28,653 INFO TaskSetManager: Finished task 39.0 in stage 2.0 (TID 103) in 38 ms on 10.1.2.181 (43/59)
17/01/29 07:05:28,654 INFO TaskSetManager: Starting task 35.0 in stage 2.0 (TID 113, 10.1.2.71, partition 35, PROCESS_LOCAL, 5374 bytes)
17/01/29 07:05:28,654 INFO CoarseGrainedSchedulerBackend$DriverEndpoint: Launching task 113 on executor id: 0 hostname: 10.1.2.71.
17/01/29 07:05:28,654 INFO TaskSetManager: Finished task 6.0 in stage 2.0 (TID 67) in 221 ms on 10.1.2.71 (44/59)
17/01/29 07:05:28,655 INFO TaskSetManager: Starting task 48.0 in stage 2.0 (TID 114, 10.1.2.71, partition 48, PROCESS_LOCAL, 5374 bytes)
17/01/29 07:05:28,655 INFO CoarseGrainedSchedulerBackend$DriverEndpoint: Launching task 114 on executor id: 0 hostname: 10.1.2.71.
17/01/29 07:05:28,656 INFO TaskSetManager: Finished task 34.0 in stage 2.0 (TID 106) in 33 ms on 10.1.2.71 (45/59)
17/01/29 07:05:28,658 INFO TaskSetManager: Starting task 49.0 in stage 2.0 (TID 115, 10.1.2.71, partition 49, PROCESS_LOCAL, 5374 bytes)
17/01/29 07:05:28,659 INFO CoarseGrainedSchedulerBackend$DriverEndpoint: Launching task 115 on executor id: 0 hostname: 10.1.2.71.
17/01/29 07:05:28,659 INFO TaskSetManager: Finished task 33.0 in stage 2.0 (TID 102) in 49 ms on 10.1.2.71 (46/59)
17/01/29 07:05:28,661 INFO TaskSetManager: Finished task 47.0 in stage 2.0 (TID 108) in 33 ms on 10.1.2.63 (47/59)
17/01/29 07:05:28,662 INFO TaskSetManager: Finished task 46.0 in stage 2.0 (TID 107) in 36 ms on 10.1.2.63 (48/59)
17/01/29 07:05:28,664 INFO TaskSetManager: Finished task 57.0 in stage 2.0 (TID 110) in 26 ms on 10.1.2.63 (49/59)
17/01/29 07:05:28,670 INFO TaskSetManager: Finished task 53.0 in stage 2.0 (TID 109) in 39 ms on 10.1.2.181 (50/59)
17/01/29 07:05:28,673 INFO TaskSetManager: Finished task 54.0 in stage 2.0 (TID 111) in 26 ms on 10.1.2.181 (51/59)
17/01/29 07:05:28,682 INFO TaskSetManager: Starting task 50.0 in stage 2.0 (TID 116, 10.1.2.71, partition 50, PROCESS_LOCAL, 5374 bytes)
17/01/29 07:05:28,682 INFO CoarseGrainedSchedulerBackend$DriverEndpoint: Launching task 116 on executor id: 0 hostname: 10.1.2.71.
17/01/29 07:05:28,682 INFO TaskSetManager: Finished task 55.0 in stage 2.0 (TID 112) in 33 ms on 10.1.2.181 (52/59)
17/01/29 07:05:28,683 INFO TaskSetManager: Finished task 35.0 in stage 2.0 (TID 113) in 30 ms on 10.1.2.71 (53/59)
17/01/29 07:05:28,699 INFO TaskSetManager: Starting task 51.0 in stage 2.0 (TID 117, 10.1.2.71, partition 51, PROCESS_LOCAL, 5374 bytes)
17/01/29 07:05:28,699 INFO CoarseGrainedSchedulerBackend$DriverEndpoint: Launching task 117 on executor id: 0 hostname: 10.1.2.71.
17/01/29 07:05:28,699 INFO TaskSetManager: Finished task 49.0 in stage 2.0 (TID 115) in 42 ms on 10.1.2.71 (54/59)
17/01/29 07:05:28,708 INFO TaskSetManager: Starting task 58.0 in stage 2.0 (TID 118, 10.1.2.71, partition 58, PROCESS_LOCAL, 5374 bytes)
17/01/29 07:05:28,708 INFO CoarseGrainedSchedulerBackend$DriverEndpoint: Launching task 118 on executor id: 0 hostname: 10.1.2.71.
17/01/29 07:05:28,708 INFO TaskSetManager: Finished task 50.0 in stage 2.0 (TID 116) in 26 ms on 10.1.2.71 (55/59)
17/01/29 07:05:28,710 INFO TaskSetManager: Finished task 48.0 in stage 2.0 (TID 114) in 55 ms on 10.1.2.71 (56/59)
17/01/29 07:05:28,730 INFO TaskSetManager: Finished task 51.0 in stage 2.0 (TID 117) in 32 ms on 10.1.2.71 (57/59)
17/01/29 07:05:28,757 INFO TaskSetManager: Finished task 58.0 in stage 2.0 (TID 118) in 50 ms on 10.1.2.71 (58/59)
17/01/29 07:05:28,760 INFO TaskSetManager: Finished task 10.0 in stage 2.0 (TID 71) in 324 ms on 10.1.2.71 (59/59)
17/01/29 07:05:28,760 INFO TaskSchedulerImpl: Removed TaskSet 2.0, whose tasks have all completed, from pool 
17/01/29 07:05:28,760 INFO DAGScheduler: ResultStage 2 (count at GradientDescent.scala:209) finished in 0.334 s
17/01/29 07:05:28,761 INFO DAGScheduler: Job 2 finished: count at GradientDescent.scala:209, took 0.357996 s
17/01/29 07:05:29,000 WARN BLAS: Failed to load implementation from: com.github.fommil.netlib.NativeSystemBLAS
17/01/29 07:05:29,001 WARN BLAS: Failed to load implementation from: com.github.fommil.netlib.NativeRefBLAS
17/01/29 07:05:29,024 INFO MemoryStore: Block broadcast_4 stored as values in memory (estimated size 280.0 B, free 2.1 GB)
17/01/29 07:05:29,027 INFO MemoryStore: Block broadcast_4_piece0 stored as bytes in memory (estimated size 153.0 B, free 2.1 GB)
17/01/29 07:05:29,028 INFO BlockManagerInfo: Added broadcast_4_piece0 in memory on 10.1.2.142:43652 (size: 153.0 B, free: 2.1 GB)
17/01/29 07:05:29,029 INFO SparkContext: Created broadcast 4 from broadcast at GradientDescent.scala:235
17/01/29 07:05:29,079 INFO SparkContext: Starting job: treeAggregate at GradientDescent.scala:239
17/01/29 07:05:29,084 INFO DAGScheduler: Registering RDD 11 (treeAggregate at GradientDescent.scala:239)
17/01/29 07:05:29,085 INFO DAGScheduler: Got job 3 (treeAggregate at GradientDescent.scala:239) with 7 output partitions
17/01/29 07:05:29,085 INFO DAGScheduler: Final stage: ResultStage 4 (treeAggregate at GradientDescent.scala:239)
17/01/29 07:05:29,085 INFO DAGScheduler: Parents of final stage: List(ShuffleMapStage 3)
17/01/29 07:05:29,085 INFO DAGScheduler: Missing parents: List(ShuffleMapStage 3)
17/01/29 07:05:29,090 INFO DAGScheduler: Submitting ShuffleMapStage 3 (MapPartitionsRDD[11] at treeAggregate at GradientDescent.scala:239), which has no missing parents
17/01/29 07:05:29,108 INFO MemoryStore: Block broadcast_5 stored as values in memory (estimated size 7.2 KB, free 2.1 GB)
17/01/29 07:05:29,110 INFO MemoryStore: Block broadcast_5_piece0 stored as bytes in memory (estimated size 3.7 KB, free 2.1 GB)
17/01/29 07:05:29,111 INFO BlockManagerInfo: Added broadcast_5_piece0 in memory on 10.1.2.142:43652 (size: 3.7 KB, free: 2.1 GB)
17/01/29 07:05:29,111 INFO SparkContext: Created broadcast 5 from broadcast at DAGScheduler.scala:1012
17/01/29 07:05:29,113 INFO DAGScheduler: Submitting 59 missing tasks from ShuffleMapStage 3 (MapPartitionsRDD[11] at treeAggregate at GradientDescent.scala:239)
17/01/29 07:05:29,114 INFO TaskSchedulerImpl: Adding task set 3.0 with 59 tasks
17/01/29 07:05:29,117 INFO TaskSetManager: Starting task 1.0 in stage 3.0 (TID 119, 10.1.2.181, partition 1, PROCESS_LOCAL, 5563 bytes)
17/01/29 07:05:29,118 INFO TaskSetManager: Starting task 0.0 in stage 3.0 (TID 120, 10.1.2.236, partition 0, PROCESS_LOCAL, 5563 bytes)
17/01/29 07:05:29,118 INFO TaskSetManager: Starting task 4.0 in stage 3.0 (TID 121, 10.1.2.63, partition 4, PROCESS_LOCAL, 5563 bytes)
17/01/29 07:05:29,119 INFO TaskSetManager: Starting task 2.0 in stage 3.0 (TID 122, 10.1.2.71, partition 2, PROCESS_LOCAL, 5563 bytes)
17/01/29 07:05:29,120 INFO TaskSetManager: Starting task 5.0 in stage 3.0 (TID 123, 10.1.2.181, partition 5, PROCESS_LOCAL, 5563 bytes)
17/01/29 07:05:29,120 INFO TaskSetManager: Starting task 3.0 in stage 3.0 (TID 124, 10.1.2.236, partition 3, PROCESS_LOCAL, 5563 bytes)
17/01/29 07:05:29,120 INFO TaskSetManager: Starting task 8.0 in stage 3.0 (TID 125, 10.1.2.63, partition 8, PROCESS_LOCAL, 5563 bytes)
17/01/29 07:05:29,121 INFO TaskSetManager: Starting task 6.0 in stage 3.0 (TID 126, 10.1.2.71, partition 6, PROCESS_LOCAL, 5563 bytes)
17/01/29 07:05:29,121 INFO TaskSetManager: Starting task 9.0 in stage 3.0 (TID 127, 10.1.2.181, partition 9, PROCESS_LOCAL, 5563 bytes)
17/01/29 07:05:29,122 INFO TaskSetManager: Starting task 7.0 in stage 3.0 (TID 128, 10.1.2.236, partition 7, PROCESS_LOCAL, 5563 bytes)
17/01/29 07:05:29,122 INFO TaskSetManager: Starting task 12.0 in stage 3.0 (TID 129, 10.1.2.63, partition 12, PROCESS_LOCAL, 5563 bytes)
17/01/29 07:05:29,123 INFO TaskSetManager: Starting task 10.0 in stage 3.0 (TID 130, 10.1.2.71, partition 10, PROCESS_LOCAL, 5563 bytes)
17/01/29 07:05:29,123 INFO TaskSetManager: Starting task 13.0 in stage 3.0 (TID 131, 10.1.2.181, partition 13, PROCESS_LOCAL, 5563 bytes)
17/01/29 07:05:29,124 INFO TaskSetManager: Starting task 11.0 in stage 3.0 (TID 132, 10.1.2.236, partition 11, PROCESS_LOCAL, 5563 bytes)
17/01/29 07:05:29,124 INFO TaskSetManager: Starting task 15.0 in stage 3.0 (TID 133, 10.1.2.63, partition 15, PROCESS_LOCAL, 5563 bytes)
17/01/29 07:05:29,125 INFO TaskSetManager: Starting task 16.0 in stage 3.0 (TID 134, 10.1.2.71, partition 16, PROCESS_LOCAL, 5563 bytes)
17/01/29 07:05:29,125 INFO CoarseGrainedSchedulerBackend$DriverEndpoint: Launching task 119 on executor id: 1 hostname: 10.1.2.181.
17/01/29 07:05:29,125 INFO CoarseGrainedSchedulerBackend$DriverEndpoint: Launching task 123 on executor id: 1 hostname: 10.1.2.181.
17/01/29 07:05:29,125 INFO CoarseGrainedSchedulerBackend$DriverEndpoint: Launching task 127 on executor id: 1 hostname: 10.1.2.181.
17/01/29 07:05:29,125 INFO CoarseGrainedSchedulerBackend$DriverEndpoint: Launching task 131 on executor id: 1 hostname: 10.1.2.181.
17/01/29 07:05:29,126 INFO CoarseGrainedSchedulerBackend$DriverEndpoint: Launching task 120 on executor id: 3 hostname: 10.1.2.236.
17/01/29 07:05:29,126 INFO CoarseGrainedSchedulerBackend$DriverEndpoint: Launching task 124 on executor id: 3 hostname: 10.1.2.236.
17/01/29 07:05:29,126 INFO CoarseGrainedSchedulerBackend$DriverEndpoint: Launching task 128 on executor id: 3 hostname: 10.1.2.236.
17/01/29 07:05:29,126 INFO CoarseGrainedSchedulerBackend$DriverEndpoint: Launching task 132 on executor id: 3 hostname: 10.1.2.236.
17/01/29 07:05:29,127 INFO CoarseGrainedSchedulerBackend$DriverEndpoint: Launching task 121 on executor id: 2 hostname: 10.1.2.63.
17/01/29 07:05:29,127 INFO CoarseGrainedSchedulerBackend$DriverEndpoint: Launching task 125 on executor id: 2 hostname: 10.1.2.63.
17/01/29 07:05:29,127 INFO CoarseGrainedSchedulerBackend$DriverEndpoint: Launching task 129 on executor id: 2 hostname: 10.1.2.63.
17/01/29 07:05:29,127 INFO CoarseGrainedSchedulerBackend$DriverEndpoint: Launching task 133 on executor id: 2 hostname: 10.1.2.63.
17/01/29 07:05:29,127 INFO CoarseGrainedSchedulerBackend$DriverEndpoint: Launching task 122 on executor id: 0 hostname: 10.1.2.71.
17/01/29 07:05:29,128 INFO CoarseGrainedSchedulerBackend$DriverEndpoint: Launching task 126 on executor id: 0 hostname: 10.1.2.71.
17/01/29 07:05:29,128 INFO CoarseGrainedSchedulerBackend$DriverEndpoint: Launching task 130 on executor id: 0 hostname: 10.1.2.71.
17/01/29 07:05:29,128 INFO CoarseGrainedSchedulerBackend$DriverEndpoint: Launching task 134 on executor id: 0 hostname: 10.1.2.71.
17/01/29 07:05:29,145 INFO BlockManagerInfo: Added broadcast_5_piece0 in memory on 10.1.2.181:36196 (size: 3.7 KB, free: 1001.4 MB)
17/01/29 07:05:29,147 INFO BlockManagerInfo: Added broadcast_5_piece0 in memory on 10.1.2.236:39970 (size: 3.7 KB, free: 1141.8 MB)
17/01/29 07:05:29,148 INFO BlockManagerInfo: Added broadcast_5_piece0 in memory on 10.1.2.71:38780 (size: 3.7 KB, free: 998.7 MB)
17/01/29 07:05:29,153 INFO BlockManagerInfo: Added broadcast_5_piece0 in memory on 10.1.2.63:46374 (size: 3.7 KB, free: 1211.1 MB)
17/01/29 07:05:29,413 INFO BlockManagerInfo: Added broadcast_4_piece0 in memory on 10.1.2.181:36196 (size: 153.0 B, free: 1001.4 MB)
17/01/29 07:05:29,422 INFO BlockManagerInfo: Added broadcast_4_piece0 in memory on 10.1.2.71:38780 (size: 153.0 B, free: 998.7 MB)
17/01/29 07:05:29,438 INFO BlockManagerInfo: Added broadcast_4_piece0 in memory on 10.1.2.63:46374 (size: 153.0 B, free: 1211.1 MB)
17/01/29 07:05:29,505 INFO BlockManagerInfo: Added broadcast_4_piece0 in memory on 10.1.2.236:39970 (size: 153.0 B, free: 1141.8 MB)
17/01/29 07:05:29,594 INFO TaskSetManager: Starting task 17.0 in stage 3.0 (TID 135, 10.1.2.71, partition 17, PROCESS_LOCAL, 5563 bytes)
17/01/29 07:05:29,594 INFO CoarseGrainedSchedulerBackend$DriverEndpoint: Launching task 135 on executor id: 0 hostname: 10.1.2.71.
17/01/29 07:05:29,597 INFO TaskSetManager: Starting task 18.0 in stage 3.0 (TID 136, 10.1.2.71, partition 18, PROCESS_LOCAL, 5563 bytes)
17/01/29 07:05:29,597 INFO CoarseGrainedSchedulerBackend$DriverEndpoint: Launching task 136 on executor id: 0 hostname: 10.1.2.71.
17/01/29 07:05:29,597 INFO TaskSetManager: Finished task 10.0 in stage 3.0 (TID 130) in 475 ms on 10.1.2.71 (1/59)
17/01/29 07:05:29,599 INFO TaskSetManager: Starting task 19.0 in stage 3.0 (TID 137, 10.1.2.71, partition 19, PROCESS_LOCAL, 5563 bytes)
17/01/29 07:05:29,600 INFO CoarseGrainedSchedulerBackend$DriverEndpoint: Launching task 137 on executor id: 0 hostname: 10.1.2.71.
17/01/29 07:05:29,601 INFO TaskSetManager: Starting task 32.0 in stage 3.0 (TID 138, 10.1.2.71, partition 32, PROCESS_LOCAL, 5563 bytes)
17/01/29 07:05:29,601 INFO CoarseGrainedSchedulerBackend$DriverEndpoint: Launching task 138 on executor id: 0 hostname: 10.1.2.71.
17/01/29 07:05:29,601 INFO TaskSetManager: Finished task 6.0 in stage 3.0 (TID 126) in 480 ms on 10.1.2.71 (2/59)
17/01/29 07:05:29,602 INFO TaskSetManager: Finished task 2.0 in stage 3.0 (TID 122) in 484 ms on 10.1.2.71 (3/59)
17/01/29 07:05:29,602 INFO TaskSetManager: Finished task 16.0 in stage 3.0 (TID 134) in 478 ms on 10.1.2.71 (4/59)
17/01/29 07:05:29,605 INFO TaskSetManager: Starting task 21.0 in stage 3.0 (TID 139, 10.1.2.181, partition 21, PROCESS_LOCAL, 5563 bytes)
17/01/29 07:05:29,605 INFO CoarseGrainedSchedulerBackend$DriverEndpoint: Launching task 139 on executor id: 1 hostname: 10.1.2.181.
17/01/29 07:05:29,606 INFO TaskSetManager: Finished task 9.0 in stage 3.0 (TID 127) in 485 ms on 10.1.2.181 (5/59)
17/01/29 07:05:29,607 INFO TaskSetManager: Starting task 22.0 in stage 3.0 (TID 140, 10.1.2.181, partition 22, PROCESS_LOCAL, 5563 bytes)
17/01/29 07:05:29,607 INFO CoarseGrainedSchedulerBackend$DriverEndpoint: Launching task 140 on executor id: 1 hostname: 10.1.2.181.
17/01/29 07:05:29,608 INFO TaskSetManager: Finished task 1.0 in stage 3.0 (TID 119) in 492 ms on 10.1.2.181 (6/59)
17/01/29 07:05:29,609 INFO TaskSetManager: Starting task 23.0 in stage 3.0 (TID 141, 10.1.2.181, partition 23, PROCESS_LOCAL, 5563 bytes)
17/01/29 07:05:29,609 INFO CoarseGrainedSchedulerBackend$DriverEndpoint: Launching task 141 on executor id: 1 hostname: 10.1.2.181.
17/01/29 07:05:29,609 INFO TaskSetManager: Finished task 5.0 in stage 3.0 (TID 123) in 490 ms on 10.1.2.181 (7/59)
17/01/29 07:05:29,610 INFO TaskSetManager: Starting task 25.0 in stage 3.0 (TID 142, 10.1.2.181, partition 25, PROCESS_LOCAL, 5563 bytes)
17/01/29 07:05:29,610 INFO CoarseGrainedSchedulerBackend$DriverEndpoint: Launching task 142 on executor id: 1 hostname: 10.1.2.181.
17/01/29 07:05:29,610 INFO TaskSetManager: Finished task 13.0 in stage 3.0 (TID 131) in 487 ms on 10.1.2.181 (8/59)
17/01/29 07:05:29,615 INFO TaskSetManager: Starting task 28.0 in stage 3.0 (TID 143, 10.1.2.63, partition 28, PROCESS_LOCAL, 5563 bytes)
17/01/29 07:05:29,615 INFO CoarseGrainedSchedulerBackend$DriverEndpoint: Launching task 143 on executor id: 2 hostname: 10.1.2.63.
17/01/29 07:05:29,615 INFO TaskSetManager: Finished task 4.0 in stage 3.0 (TID 121) in 497 ms on 10.1.2.63 (9/59)
17/01/29 07:05:29,616 INFO TaskSetManager: Starting task 29.0 in stage 3.0 (TID 144, 10.1.2.63, partition 29, PROCESS_LOCAL, 5563 bytes)
17/01/29 07:05:29,616 INFO CoarseGrainedSchedulerBackend$DriverEndpoint: Launching task 144 on executor id: 2 hostname: 10.1.2.63.
17/01/29 07:05:29,616 INFO TaskSetManager: Finished task 12.0 in stage 3.0 (TID 129) in 494 ms on 10.1.2.63 (10/59)
17/01/29 07:05:29,618 INFO TaskSetManager: Starting task 30.0 in stage 3.0 (TID 145, 10.1.2.63, partition 30, PROCESS_LOCAL, 5563 bytes)
17/01/29 07:05:29,618 INFO CoarseGrainedSchedulerBackend$DriverEndpoint: Launching task 145 on executor id: 2 hostname: 10.1.2.63.
17/01/29 07:05:29,618 INFO TaskSetManager: Finished task 15.0 in stage 3.0 (TID 133) in 494 ms on 10.1.2.63 (11/59)
17/01/29 07:05:29,621 INFO TaskSetManager: Starting task 31.0 in stage 3.0 (TID 146, 10.1.2.63, partition 31, PROCESS_LOCAL, 5563 bytes)
17/01/29 07:05:29,621 INFO CoarseGrainedSchedulerBackend$DriverEndpoint: Launching task 146 on executor id: 2 hostname: 10.1.2.63.
17/01/29 07:05:29,621 INFO TaskSetManager: Finished task 8.0 in stage 3.0 (TID 125) in 501 ms on 10.1.2.63 (12/59)
17/01/29 07:05:29,667 INFO TaskSetManager: Starting task 14.0 in stage 3.0 (TID 147, 10.1.2.236, partition 14, PROCESS_LOCAL, 5563 bytes)
17/01/29 07:05:29,668 INFO CoarseGrainedSchedulerBackend$DriverEndpoint: Launching task 147 on executor id: 3 hostname: 10.1.2.236.
17/01/29 07:05:29,668 INFO TaskSetManager: Finished task 11.0 in stage 3.0 (TID 132) in 545 ms on 10.1.2.236 (13/59)
17/01/29 07:05:29,669 INFO TaskSetManager: Starting task 20.0 in stage 3.0 (TID 148, 10.1.2.236, partition 20, PROCESS_LOCAL, 5563 bytes)
17/01/29 07:05:29,669 INFO CoarseGrainedSchedulerBackend$DriverEndpoint: Launching task 148 on executor id: 3 hostname: 10.1.2.236.
17/01/29 07:05:29,669 INFO TaskSetManager: Finished task 3.0 in stage 3.0 (TID 124) in 549 ms on 10.1.2.236 (14/59)
17/01/29 07:05:29,670 INFO TaskSetManager: Starting task 24.0 in stage 3.0 (TID 149, 10.1.2.236, partition 24, PROCESS_LOCAL, 5563 bytes)
17/01/29 07:05:29,670 INFO CoarseGrainedSchedulerBackend$DriverEndpoint: Launching task 149 on executor id: 3 hostname: 10.1.2.236.
17/01/29 07:05:29,670 INFO TaskSetManager: Finished task 0.0 in stage 3.0 (TID 120) in 552 ms on 10.1.2.236 (15/59)
17/01/29 07:05:29,681 INFO TaskSetManager: Starting task 26.0 in stage 3.0 (TID 150, 10.1.2.236, partition 26, PROCESS_LOCAL, 5563 bytes)
17/01/29 07:05:29,681 INFO CoarseGrainedSchedulerBackend$DriverEndpoint: Launching task 150 on executor id: 3 hostname: 10.1.2.236.
17/01/29 07:05:29,682 INFO TaskSetManager: Finished task 7.0 in stage 3.0 (TID 128) in 561 ms on 10.1.2.236 (16/59)
17/01/29 07:05:29,684 INFO TaskSetManager: Starting task 36.0 in stage 3.0 (TID 151, 10.1.2.181, partition 36, PROCESS_LOCAL, 5563 bytes)
17/01/29 07:05:29,684 INFO CoarseGrainedSchedulerBackend$DriverEndpoint: Launching task 151 on executor id: 1 hostname: 10.1.2.181.
17/01/29 07:05:29,685 INFO TaskSetManager: Finished task 21.0 in stage 3.0 (TID 139) in 80 ms on 10.1.2.181 (17/59)
17/01/29 07:05:29,687 INFO TaskSetManager: Starting task 33.0 in stage 3.0 (TID 152, 10.1.2.71, partition 33, PROCESS_LOCAL, 5563 bytes)
17/01/29 07:05:29,687 INFO CoarseGrainedSchedulerBackend$DriverEndpoint: Launching task 152 on executor id: 0 hostname: 10.1.2.71.
17/01/29 07:05:29,687 INFO TaskSetManager: Finished task 17.0 in stage 3.0 (TID 135) in 93 ms on 10.1.2.71 (18/59)
17/01/29 07:05:29,694 INFO TaskSetManager: Starting task 34.0 in stage 3.0 (TID 153, 10.1.2.71, partition 34, PROCESS_LOCAL, 5563 bytes)
17/01/29 07:05:29,694 INFO CoarseGrainedSchedulerBackend$DriverEndpoint: Launching task 153 on executor id: 0 hostname: 10.1.2.71.
17/01/29 07:05:29,694 INFO TaskSetManager: Finished task 19.0 in stage 3.0 (TID 137) in 95 ms on 10.1.2.71 (19/59)
17/01/29 07:05:29,702 INFO TaskSetManager: Starting task 37.0 in stage 3.0 (TID 154, 10.1.2.181, partition 37, PROCESS_LOCAL, 5563 bytes)
17/01/29 07:05:29,702 INFO CoarseGrainedSchedulerBackend$DriverEndpoint: Launching task 154 on executor id: 1 hostname: 10.1.2.181.
17/01/29 07:05:29,702 INFO TaskSetManager: Finished task 22.0 in stage 3.0 (TID 140) in 95 ms on 10.1.2.181 (20/59)
17/01/29 07:05:29,704 INFO TaskSetManager: Starting task 35.0 in stage 3.0 (TID 155, 10.1.2.71, partition 35, PROCESS_LOCAL, 5563 bytes)
17/01/29 07:05:29,704 INFO CoarseGrainedSchedulerBackend$DriverEndpoint: Launching task 155 on executor id: 0 hostname: 10.1.2.71.
17/01/29 07:05:29,704 INFO TaskSetManager: Finished task 32.0 in stage 3.0 (TID 138) in 104 ms on 10.1.2.71 (21/59)
17/01/29 07:05:29,709 INFO TaskSetManager: Starting task 48.0 in stage 3.0 (TID 156, 10.1.2.71, partition 48, PROCESS_LOCAL, 5563 bytes)
17/01/29 07:05:29,709 INFO CoarseGrainedSchedulerBackend$DriverEndpoint: Launching task 156 on executor id: 0 hostname: 10.1.2.71.
17/01/29 07:05:29,709 INFO TaskSetManager: Finished task 18.0 in stage 3.0 (TID 136) in 113 ms on 10.1.2.71 (22/59)
17/01/29 07:05:29,711 INFO TaskSetManager: Starting task 38.0 in stage 3.0 (TID 157, 10.1.2.181, partition 38, PROCESS_LOCAL, 5563 bytes)
17/01/29 07:05:29,712 INFO CoarseGrainedSchedulerBackend$DriverEndpoint: Launching task 157 on executor id: 1 hostname: 10.1.2.181.
17/01/29 07:05:29,712 INFO TaskSetManager: Finished task 25.0 in stage 3.0 (TID 142) in 103 ms on 10.1.2.181 (23/59)
17/01/29 07:05:29,715 INFO TaskSetManager: Starting task 39.0 in stage 3.0 (TID 158, 10.1.2.181, partition 39, PROCESS_LOCAL, 5563 bytes)
17/01/29 07:05:29,716 INFO CoarseGrainedSchedulerBackend$DriverEndpoint: Launching task 158 on executor id: 1 hostname: 10.1.2.181.
17/01/29 07:05:29,716 INFO TaskSetManager: Finished task 23.0 in stage 3.0 (TID 141) in 108 ms on 10.1.2.181 (24/59)
17/01/29 07:05:29,717 INFO TaskSetManager: Starting task 44.0 in stage 3.0 (TID 159, 10.1.2.63, partition 44, PROCESS_LOCAL, 5563 bytes)
17/01/29 07:05:29,717 INFO CoarseGrainedSchedulerBackend$DriverEndpoint: Launching task 159 on executor id: 2 hostname: 10.1.2.63.
17/01/29 07:05:29,717 INFO TaskSetManager: Finished task 31.0 in stage 3.0 (TID 146) in 96 ms on 10.1.2.63 (25/59)
17/01/29 07:05:29,721 INFO TaskSetManager: Starting task 45.0 in stage 3.0 (TID 160, 10.1.2.63, partition 45, PROCESS_LOCAL, 5563 bytes)
17/01/29 07:05:29,722 INFO CoarseGrainedSchedulerBackend$DriverEndpoint: Launching task 160 on executor id: 2 hostname: 10.1.2.63.
17/01/29 07:05:29,722 INFO TaskSetManager: Finished task 30.0 in stage 3.0 (TID 145) in 105 ms on 10.1.2.63 (26/59)
17/01/29 07:05:29,723 INFO TaskSetManager: Starting task 46.0 in stage 3.0 (TID 161, 10.1.2.63, partition 46, PROCESS_LOCAL, 5563 bytes)
17/01/29 07:05:29,723 INFO CoarseGrainedSchedulerBackend$DriverEndpoint: Launching task 161 on executor id: 2 hostname: 10.1.2.63.
17/01/29 07:05:29,723 INFO TaskSetManager: Finished task 29.0 in stage 3.0 (TID 144) in 108 ms on 10.1.2.63 (27/59)
17/01/29 07:05:29,753 INFO TaskSetManager: Starting task 47.0 in stage 3.0 (TID 162, 10.1.2.63, partition 47, PROCESS_LOCAL, 5563 bytes)
17/01/29 07:05:29,753 INFO CoarseGrainedSchedulerBackend$DriverEndpoint: Launching task 162 on executor id: 2 hostname: 10.1.2.63.
17/01/29 07:05:29,754 INFO TaskSetManager: Finished task 28.0 in stage 3.0 (TID 143) in 139 ms on 10.1.2.63 (28/59)
17/01/29 07:05:29,755 INFO TaskSetManager: Starting task 52.0 in stage 3.0 (TID 163, 10.1.2.181, partition 52, PROCESS_LOCAL, 5563 bytes)
17/01/29 07:05:29,755 INFO CoarseGrainedSchedulerBackend$DriverEndpoint: Launching task 163 on executor id: 1 hostname: 10.1.2.181.
17/01/29 07:05:29,755 INFO TaskSetManager: Finished task 36.0 in stage 3.0 (TID 151) in 71 ms on 10.1.2.181 (29/59)
17/01/29 07:05:29,772 INFO TaskSetManager: Starting task 49.0 in stage 3.0 (TID 164, 10.1.2.71, partition 49, PROCESS_LOCAL, 5563 bytes)
17/01/29 07:05:29,773 INFO CoarseGrainedSchedulerBackend$DriverEndpoint: Launching task 164 on executor id: 0 hostname: 10.1.2.71.
17/01/29 07:05:29,773 INFO TaskSetManager: Finished task 35.0 in stage 3.0 (TID 155) in 70 ms on 10.1.2.71 (30/59)
17/01/29 07:05:29,774 INFO TaskSetManager: Starting task 50.0 in stage 3.0 (TID 165, 10.1.2.71, partition 50, PROCESS_LOCAL, 5563 bytes)
17/01/29 07:05:29,774 INFO CoarseGrainedSchedulerBackend$DriverEndpoint: Launching task 165 on executor id: 0 hostname: 10.1.2.71.
17/01/29 07:05:29,774 INFO TaskSetManager: Finished task 34.0 in stage 3.0 (TID 153) in 81 ms on 10.1.2.71 (31/59)
17/01/29 07:05:29,775 INFO TaskSetManager: Starting task 51.0 in stage 3.0 (TID 166, 10.1.2.71, partition 51, PROCESS_LOCAL, 5563 bytes)
17/01/29 07:05:29,775 INFO CoarseGrainedSchedulerBackend$DriverEndpoint: Launching task 166 on executor id: 0 hostname: 10.1.2.71.
17/01/29 07:05:29,775 INFO TaskSetManager: Finished task 33.0 in stage 3.0 (TID 152) in 89 ms on 10.1.2.71 (32/59)
17/01/29 07:05:29,776 INFO TaskSetManager: Starting task 53.0 in stage 3.0 (TID 167, 10.1.2.181, partition 53, PROCESS_LOCAL, 5563 bytes)
17/01/29 07:05:29,776 INFO CoarseGrainedSchedulerBackend$DriverEndpoint: Launching task 167 on executor id: 1 hostname: 10.1.2.181.
17/01/29 07:05:29,776 INFO TaskSetManager: Finished task 37.0 in stage 3.0 (TID 154) in 75 ms on 10.1.2.181 (33/59)
17/01/29 07:05:29,778 INFO TaskSetManager: Starting task 58.0 in stage 3.0 (TID 168, 10.1.2.71, partition 58, PROCESS_LOCAL, 5563 bytes)
17/01/29 07:05:29,778 INFO CoarseGrainedSchedulerBackend$DriverEndpoint: Launching task 168 on executor id: 0 hostname: 10.1.2.71.
17/01/29 07:05:29,778 INFO TaskSetManager: Finished task 48.0 in stage 3.0 (TID 156) in 70 ms on 10.1.2.71 (34/59)
17/01/29 07:05:29,782 INFO TaskSetManager: Starting task 54.0 in stage 3.0 (TID 169, 10.1.2.181, partition 54, PROCESS_LOCAL, 5563 bytes)
17/01/29 07:05:29,783 INFO CoarseGrainedSchedulerBackend$DriverEndpoint: Launching task 169 on executor id: 1 hostname: 10.1.2.181.
17/01/29 07:05:29,783 INFO TaskSetManager: Finished task 39.0 in stage 3.0 (TID 158) in 68 ms on 10.1.2.181 (35/59)
17/01/29 07:05:29,784 INFO TaskSetManager: Starting task 57.0 in stage 3.0 (TID 170, 10.1.2.63, partition 57, PROCESS_LOCAL, 5563 bytes)
17/01/29 07:05:29,784 INFO CoarseGrainedSchedulerBackend$DriverEndpoint: Launching task 170 on executor id: 2 hostname: 10.1.2.63.
17/01/29 07:05:29,785 INFO TaskSetManager: Finished task 44.0 in stage 3.0 (TID 159) in 68 ms on 10.1.2.63 (36/59)
17/01/29 07:05:29,803 INFO TaskSetManager: Finished task 45.0 in stage 3.0 (TID 160) in 82 ms on 10.1.2.63 (37/59)
17/01/29 07:05:29,804 INFO TaskSetManager: Finished task 46.0 in stage 3.0 (TID 161) in 80 ms on 10.1.2.63 (38/59)
17/01/29 07:05:29,820 INFO TaskSetManager: Starting task 55.0 in stage 3.0 (TID 171, 10.1.2.181, partition 55, PROCESS_LOCAL, 5563 bytes)
17/01/29 07:05:29,820 INFO CoarseGrainedSchedulerBackend$DriverEndpoint: Launching task 171 on executor id: 1 hostname: 10.1.2.181.
17/01/29 07:05:29,820 INFO TaskSetManager: Finished task 38.0 in stage 3.0 (TID 157) in 109 ms on 10.1.2.181 (39/59)
17/01/29 07:05:29,824 INFO TaskSetManager: Starting task 27.0 in stage 3.0 (TID 172, 10.1.2.236, partition 27, PROCESS_LOCAL, 5563 bytes)
17/01/29 07:05:29,824 INFO CoarseGrainedSchedulerBackend$DriverEndpoint: Launching task 172 on executor id: 3 hostname: 10.1.2.236.
17/01/29 07:05:29,825 INFO TaskSetManager: Finished task 14.0 in stage 3.0 (TID 147) in 157 ms on 10.1.2.236 (40/59)
17/01/29 07:05:29,831 INFO TaskSetManager: Finished task 47.0 in stage 3.0 (TID 162) in 79 ms on 10.1.2.63 (41/59)
17/01/29 07:05:29,835 INFO TaskSetManager: Starting task 40.0 in stage 3.0 (TID 173, 10.1.2.236, partition 40, PROCESS_LOCAL, 5563 bytes)
17/01/29 07:05:29,835 INFO CoarseGrainedSchedulerBackend$DriverEndpoint: Launching task 173 on executor id: 3 hostname: 10.1.2.236.
17/01/29 07:05:29,835 INFO TaskSetManager: Finished task 20.0 in stage 3.0 (TID 148) in 167 ms on 10.1.2.236 (42/59)
17/01/29 07:05:29,837 INFO TaskSetManager: Finished task 52.0 in stage 3.0 (TID 163) in 82 ms on 10.1.2.181 (43/59)
17/01/29 07:05:29,839 INFO TaskSetManager: Starting task 41.0 in stage 3.0 (TID 174, 10.1.2.236, partition 41, PROCESS_LOCAL, 5563 bytes)
17/01/29 07:05:29,839 INFO CoarseGrainedSchedulerBackend$DriverEndpoint: Launching task 174 on executor id: 3 hostname: 10.1.2.236.
17/01/29 07:05:29,839 INFO TaskSetManager: Finished task 24.0 in stage 3.0 (TID 149) in 170 ms on 10.1.2.236 (44/59)
17/01/29 07:05:29,840 INFO TaskSetManager: Starting task 42.0 in stage 3.0 (TID 175, 10.1.2.236, partition 42, PROCESS_LOCAL, 5563 bytes)
17/01/29 07:05:29,841 INFO CoarseGrainedSchedulerBackend$DriverEndpoint: Launching task 175 on executor id: 3 hostname: 10.1.2.236.
17/01/29 07:05:29,841 INFO TaskSetManager: Finished task 26.0 in stage 3.0 (TID 150) in 160 ms on 10.1.2.236 (45/59)
17/01/29 07:05:29,844 INFO TaskSetManager: Finished task 50.0 in stage 3.0 (TID 165) in 71 ms on 10.1.2.71 (46/59)
17/01/29 07:05:29,848 INFO TaskSetManager: Finished task 57.0 in stage 3.0 (TID 170) in 64 ms on 10.1.2.63 (47/59)
17/01/29 07:05:29,867 INFO TaskSetManager: Finished task 53.0 in stage 3.0 (TID 167) in 91 ms on 10.1.2.181 (48/59)
17/01/29 07:05:29,876 INFO TaskSetManager: Finished task 51.0 in stage 3.0 (TID 166) in 101 ms on 10.1.2.71 (49/59)
17/01/29 07:05:29,882 INFO TaskSetManager: Finished task 58.0 in stage 3.0 (TID 168) in 104 ms on 10.1.2.71 (50/59)
17/01/29 07:05:29,882 INFO TaskSetManager: Finished task 54.0 in stage 3.0 (TID 169) in 100 ms on 10.1.2.181 (51/59)
17/01/29 07:05:29,885 INFO TaskSetManager: Starting task 43.0 in stage 3.0 (TID 176, 10.1.2.236, partition 43, PROCESS_LOCAL, 5563 bytes)
17/01/29 07:05:29,886 INFO CoarseGrainedSchedulerBackend$DriverEndpoint: Launching task 176 on executor id: 3 hostname: 10.1.2.236.
17/01/29 07:05:29,886 INFO TaskSetManager: Finished task 27.0 in stage 3.0 (TID 172) in 63 ms on 10.1.2.236 (52/59)
17/01/29 07:05:29,895 INFO TaskSetManager: Finished task 55.0 in stage 3.0 (TID 171) in 76 ms on 10.1.2.181 (53/59)
17/01/29 07:05:29,903 INFO TaskSetManager: Starting task 56.0 in stage 3.0 (TID 177, 10.1.2.236, partition 56, PROCESS_LOCAL, 5563 bytes)
17/01/29 07:05:29,903 INFO CoarseGrainedSchedulerBackend$DriverEndpoint: Launching task 177 on executor id: 3 hostname: 10.1.2.236.
17/01/29 07:05:29,905 INFO TaskSetManager: Finished task 49.0 in stage 3.0 (TID 164) in 132 ms on 10.1.2.71 (54/59)
17/01/29 07:05:29,905 INFO TaskSetManager: Finished task 42.0 in stage 3.0 (TID 175) in 65 ms on 10.1.2.236 (55/59)
17/01/29 07:05:29,906 INFO TaskSetManager: Finished task 40.0 in stage 3.0 (TID 173) in 70 ms on 10.1.2.236 (56/59)
17/01/29 07:05:29,906 INFO TaskSetManager: Finished task 41.0 in stage 3.0 (TID 174) in 67 ms on 10.1.2.236 (57/59)
17/01/29 07:05:29,948 INFO TaskSetManager: Finished task 43.0 in stage 3.0 (TID 176) in 62 ms on 10.1.2.236 (58/59)
17/01/29 07:05:29,968 INFO TaskSetManager: Finished task 56.0 in stage 3.0 (TID 177) in 65 ms on 10.1.2.236 (59/59)
17/01/29 07:05:29,968 INFO TaskSchedulerImpl: Removed TaskSet 3.0, whose tasks have all completed, from pool 
17/01/29 07:05:29,969 INFO DAGScheduler: ShuffleMapStage 3 (treeAggregate at GradientDescent.scala:239) finished in 0.852 s
17/01/29 07:05:29,969 INFO DAGScheduler: looking for newly runnable stages
17/01/29 07:05:29,970 INFO DAGScheduler: running: Set()
17/01/29 07:05:29,970 INFO DAGScheduler: waiting: Set(ResultStage 4)
17/01/29 07:05:29,971 INFO DAGScheduler: failed: Set()
17/01/29 07:05:29,972 INFO DAGScheduler: Submitting ResultStage 4 (MapPartitionsRDD[13] at treeAggregate at GradientDescent.scala:239), which has no missing parents
17/01/29 07:05:29,980 INFO MemoryStore: Block broadcast_6 stored as values in memory (estimated size 3.1 KB, free 2.1 GB)
17/01/29 07:05:29,983 INFO MemoryStore: Block broadcast_6_piece0 stored as bytes in memory (estimated size 1893.0 B, free 2.1 GB)
17/01/29 07:05:29,984 INFO BlockManagerInfo: Added broadcast_6_piece0 in memory on 10.1.2.142:43652 (size: 1893.0 B, free: 2.1 GB)
17/01/29 07:05:29,985 INFO SparkContext: Created broadcast 6 from broadcast at DAGScheduler.scala:1012
17/01/29 07:05:29,985 INFO DAGScheduler: Submitting 7 missing tasks from ResultStage 4 (MapPartitionsRDD[13] at treeAggregate at GradientDescent.scala:239)
17/01/29 07:05:29,985 INFO TaskSchedulerImpl: Adding task set 4.0 with 7 tasks
17/01/29 07:05:29,988 INFO TaskSetManager: Starting task 1.0 in stage 4.0 (TID 178, 10.1.2.63, partition 1, NODE_LOCAL, 5228 bytes)
17/01/29 07:05:29,988 INFO TaskSetManager: Starting task 0.0 in stage 4.0 (TID 179, 10.1.2.71, partition 0, NODE_LOCAL, 5228 bytes)
17/01/29 07:05:29,989 INFO TaskSetManager: Starting task 2.0 in stage 4.0 (TID 180, 10.1.2.181, partition 2, NODE_LOCAL, 5228 bytes)
17/01/29 07:05:29,989 INFO TaskSetManager: Starting task 3.0 in stage 4.0 (TID 181, 10.1.2.236, partition 3, NODE_LOCAL, 5228 bytes)
17/01/29 07:05:29,989 INFO TaskSetManager: Starting task 4.0 in stage 4.0 (TID 182, 10.1.2.63, partition 4, NODE_LOCAL, 5228 bytes)
17/01/29 07:05:29,990 INFO TaskSetManager: Starting task 5.0 in stage 4.0 (TID 183, 10.1.2.71, partition 5, NODE_LOCAL, 5228 bytes)
17/01/29 07:05:29,991 INFO TaskSetManager: Starting task 6.0 in stage 4.0 (TID 184, 10.1.2.181, partition 6, NODE_LOCAL, 5228 bytes)
17/01/29 07:05:29,991 INFO CoarseGrainedSchedulerBackend$DriverEndpoint: Launching task 178 on executor id: 2 hostname: 10.1.2.63.
17/01/29 07:05:29,991 INFO CoarseGrainedSchedulerBackend$DriverEndpoint: Launching task 182 on executor id: 2 hostname: 10.1.2.63.
17/01/29 07:05:29,992 INFO CoarseGrainedSchedulerBackend$DriverEndpoint: Launching task 179 on executor id: 0 hostname: 10.1.2.71.
17/01/29 07:05:29,992 INFO CoarseGrainedSchedulerBackend$DriverEndpoint: Launching task 183 on executor id: 0 hostname: 10.1.2.71.
17/01/29 07:05:29,992 INFO CoarseGrainedSchedulerBackend$DriverEndpoint: Launching task 180 on executor id: 1 hostname: 10.1.2.181.
17/01/29 07:05:29,993 INFO CoarseGrainedSchedulerBackend$DriverEndpoint: Launching task 184 on executor id: 1 hostname: 10.1.2.181.
17/01/29 07:05:29,993 INFO CoarseGrainedSchedulerBackend$DriverEndpoint: Launching task 181 on executor id: 3 hostname: 10.1.2.236.
17/01/29 07:05:30,006 INFO BlockManagerInfo: Added broadcast_6_piece0 in memory on 10.1.2.71:38780 (size: 1893.0 B, free: 998.7 MB)
17/01/29 07:05:30,008 INFO BlockManagerInfo: Added broadcast_6_piece0 in memory on 10.1.2.236:39970 (size: 1893.0 B, free: 1141.8 MB)
17/01/29 07:05:30,009 INFO BlockManagerInfo: Added broadcast_6_piece0 in memory on 10.1.2.181:36196 (size: 1893.0 B, free: 1001.4 MB)
17/01/29 07:05:30,009 INFO BlockManagerInfo: Added broadcast_6_piece0 in memory on 10.1.2.63:46374 (size: 1893.0 B, free: 1211.1 MB)
17/01/29 07:05:30,027 INFO MapOutputTrackerMasterEndpoint: Asked to send map output locations for shuffle 0 to 10.1.2.236:37354
17/01/29 07:05:30,027 INFO MapOutputTrackerMasterEndpoint: Asked to send map output locations for shuffle 0 to 10.1.2.181:44102
17/01/29 07:05:30,029 INFO MapOutputTrackerMasterEndpoint: Asked to send map output locations for shuffle 0 to 10.1.2.71:52084
17/01/29 07:05:30,035 INFO MapOutputTrackerMaster: Size of output statuses for shuffle 0 is 352 bytes
17/01/29 07:05:30,035 INFO MapOutputTrackerMasterEndpoint: Asked to send map output locations for shuffle 0 to 10.1.2.63:41838
17/01/29 07:05:30,145 INFO TaskSetManager: Finished task 6.0 in stage 4.0 (TID 184) in 155 ms on 10.1.2.181 (1/7)
17/01/29 07:05:30,191 INFO TaskSetManager: Finished task 4.0 in stage 4.0 (TID 182) in 202 ms on 10.1.2.63 (2/7)
17/01/29 07:05:30,192 INFO TaskSetManager: Finished task 1.0 in stage 4.0 (TID 178) in 206 ms on 10.1.2.63 (3/7)
17/01/29 07:05:30,194 INFO TaskSetManager: Finished task 2.0 in stage 4.0 (TID 180) in 206 ms on 10.1.2.181 (4/7)
