Using properties file: /home/ubuntu/spark-2.0.0/conf/spark-defaults.conf
Adding default property: spark.driver.extraJavaOptions=-XX:+PrintGCDetails -XX:+PrintGCTimeStamps -Xms4000m -Dlog4j.configuration=file:///home/ubuntu/spark-2.0.0/conf/log4j.properties
Adding default property: spark.executor.extraJavaOptions=-XX:+PrintGCDetails -XX:+PrintGCTimeStamps -Xms4000m -Dlog4j.configuration=file:///home/ubuntu/spark-2.0.0/conf/log4j.properties
Parsed arguments:
  master                  spark://euca-10-1-2-142:7077
  deployMode              client
  executorMemory          4000m
  executorCores           null
  totalExecutorCores      null
  propertiesFile          /home/ubuntu/spark-2.0.0/conf/spark-defaults.conf
  driverMemory            4000m
  driverCores             null
  driverExtraClassPath    null
  driverExtraLibraryPath  null
  driverExtraJavaOptions  -XX:+PrintGCDetails -XX:+PrintGCTimeStamps -Xms4000m -Dlog4j.configuration=file:///home/ubuntu/spark-2.0.0/conf/log4j.properties
  supervise               false
  queue                   null
  numExecutors            4
  files                   null
  pyFiles                 null
  archives                null
  mainClass               LogRegExplicitParallelism
  primaryResource         file:///home/ubuntu/jars/log-reg-explicit-parallelism_2.11-1.0.jar
  name                    LogRegExplicitParallelism
  childArgs               [cluster 28 euca-10-1-2-142 9000 higgs_0_exp 5 16]
  jars                    null
  packages                null
  packagesExclusions      null
  repositories            null
  verbose                 true

Spark properties used, including those specified through
 --conf and those from the properties file /home/ubuntu/spark-2.0.0/conf/spark-defaults.conf:
  spark.default.parallelism -> 16
  spark.driver.memory -> 4000m
  spark.executor.extraJavaOptions -> -XX:+PrintGCDetails -XX:+PrintGCTimeStamps -Xms4000m -Dlog4j.configuration=file:///home/ubuntu/spark-2.0.0/conf/log4j.properties
  spark.driver.extraJavaOptions -> -XX:+PrintGCDetails -XX:+PrintGCTimeStamps -Xms4000m -Dlog4j.configuration=file:///home/ubuntu/spark-2.0.0/conf/log4j.properties
  spark.shuffle.spill -> false

    
Main class:
LogRegExplicitParallelism
Arguments:
cluster
28
euca-10-1-2-142
9000
higgs_0_exp
5
16
System properties:
spark.default.parallelism -> 16
spark.executor.memory -> 4000m
spark.driver.memory -> 4000m
SPARK_SUBMIT -> true
spark.executor.extraJavaOptions -> -XX:+PrintGCDetails -XX:+PrintGCTimeStamps -Xms4000m -Dlog4j.configuration=file:///home/ubuntu/spark-2.0.0/conf/log4j.properties
spark.app.name -> LogRegExplicitParallelism
spark.shuffle.spill -> false
spark.driver.extraJavaOptions -> -XX:+PrintGCDetails -XX:+PrintGCTimeStamps -Xms4000m -Dlog4j.configuration=file:///home/ubuntu/spark-2.0.0/conf/log4j.properties
spark.jars -> file:///home/ubuntu/jars/log-reg-explicit-parallelism_2.11-1.0.jar
spark.submit.deployMode -> client
spark.master -> spark://euca-10-1-2-142:7077
Classpath elements:
file:///home/ubuntu/jars/log-reg-explicit-parallelism_2.11-1.0.jar


17/01/29 07:01:36,021 INFO SparkContext: Running Spark version 2.0.0
17/01/29 07:01:36,363 WARN NativeCodeLoader: Unable to load native-hadoop library for your platform... using builtin-java classes where applicable
17/01/29 07:01:36,528 INFO SecurityManager: Changing view acls to: ubuntu
17/01/29 07:01:36,529 INFO SecurityManager: Changing modify acls to: ubuntu
17/01/29 07:01:36,529 INFO SecurityManager: Changing view acls groups to: 
17/01/29 07:01:36,530 INFO SecurityManager: Changing modify acls groups to: 
17/01/29 07:01:36,530 INFO SecurityManager: SecurityManager: authentication disabled; ui acls disabled; users  with view permissions: Set(ubuntu); groups with view permissions: Set(); users  with modify permissions: Set(ubuntu); groups with modify permissions: Set()
17/01/29 07:01:36,857 INFO Utils: Successfully started service 'sparkDriver' on port 44754.
17/01/29 07:01:36,875 INFO SparkEnv: Registering MapOutputTracker
17/01/29 07:01:36,881 WARN SortShuffleManager: spark.shuffle.spill was set to false, but this configuration is ignored as of Spark 1.6+. Shuffle will continue to spill to disk when necessary.
17/01/29 07:01:36,892 INFO SparkEnv: Registering BlockManagerMaster
17/01/29 07:01:36,905 INFO DiskBlockManager: Created local directory at /tmp/blockmgr-ac09cd18-0d34-4a6d-807c-f7b482693f8a
17/01/29 07:01:36,923 INFO MemoryStore: MemoryStore started with capacity 2.1 GB
17/01/29 07:01:36,979 INFO SparkEnv: Registering OutputCommitCoordinator
17/01/29 07:01:37,196 INFO Utils: Successfully started service 'SparkUI' on port 4040.
17/01/29 07:01:37,197 INFO SparkUI: Bound SparkUI to 10.1.2.142, and started at http://10.1.2.142:4040
17/01/29 07:01:37,229 INFO SparkContext: Added JAR file:///home/ubuntu/jars/log-reg-explicit-parallelism_2.11-1.0.jar at spark://10.1.2.142:44754/jars/log-reg-explicit-parallelism_2.11-1.0.jar with timestamp 1485673297229
17/01/29 07:01:37,305 INFO StandaloneAppClient$ClientEndpoint: Connecting to master spark://euca-10-1-2-142:7077...
17/01/29 07:01:37,357 INFO TransportClientFactory: Successfully created connection to euca-10-1-2-142/10.1.2.142:7077 after 24 ms (0 ms spent in bootstraps)
17/01/29 07:01:37,473 INFO StandaloneSchedulerBackend: Connected to Spark cluster with app ID app-20170129070137-0000
17/01/29 07:01:37,480 INFO Utils: Successfully started service 'org.apache.spark.network.netty.NettyBlockTransferService' on port 38331.
17/01/29 07:01:37,480 INFO NettyBlockTransferService: Server created on 10.1.2.142:38331
17/01/29 07:01:37,482 INFO BlockManagerMaster: Registering BlockManager BlockManagerId(driver, 10.1.2.142, 38331)
17/01/29 07:01:37,484 INFO BlockManagerMasterEndpoint: Registering block manager 10.1.2.142:38331 with 2.1 GB RAM, BlockManagerId(driver, 10.1.2.142, 38331)
17/01/29 07:01:37,492 INFO BlockManagerMaster: Registered BlockManager BlockManagerId(driver, 10.1.2.142, 38331)
17/01/29 07:01:37,500 INFO StandaloneAppClient$ClientEndpoint: Executor added: app-20170129070137-0000/0 on worker-20170129070121-10.1.2.236-45353 (10.1.2.236:45353) with 4 cores
17/01/29 07:01:37,500 INFO StandaloneSchedulerBackend: Granted executor ID app-20170129070137-0000/0 on hostPort 10.1.2.236:45353 with 4 cores, 3.9 GB RAM
17/01/29 07:01:37,501 INFO StandaloneAppClient$ClientEndpoint: Executor added: app-20170129070137-0000/1 on worker-20170129070121-10.1.2.63-40539 (10.1.2.63:40539) with 4 cores
17/01/29 07:01:37,501 INFO StandaloneSchedulerBackend: Granted executor ID app-20170129070137-0000/1 on hostPort 10.1.2.63:40539 with 4 cores, 3.9 GB RAM
17/01/29 07:01:37,501 INFO StandaloneAppClient$ClientEndpoint: Executor added: app-20170129070137-0000/2 on worker-20170129070121-10.1.2.71-38309 (10.1.2.71:38309) with 4 cores
17/01/29 07:01:37,502 INFO StandaloneSchedulerBackend: Granted executor ID app-20170129070137-0000/2 on hostPort 10.1.2.71:38309 with 4 cores, 3.9 GB RAM
17/01/29 07:01:37,503 INFO StandaloneAppClient$ClientEndpoint: Executor added: app-20170129070137-0000/3 on worker-20170129070121-10.1.2.181-45209 (10.1.2.181:45209) with 4 cores
17/01/29 07:01:37,503 INFO StandaloneSchedulerBackend: Granted executor ID app-20170129070137-0000/3 on hostPort 10.1.2.181:45209 with 4 cores, 3.9 GB RAM
17/01/29 07:01:37,562 INFO StandaloneAppClient$ClientEndpoint: Executor updated: app-20170129070137-0000/2 is now RUNNING
17/01/29 07:01:37,563 INFO StandaloneAppClient$ClientEndpoint: Executor updated: app-20170129070137-0000/3 is now RUNNING
17/01/29 07:01:37,571 INFO StandaloneAppClient$ClientEndpoint: Executor updated: app-20170129070137-0000/0 is now RUNNING
17/01/29 07:01:37,571 INFO StandaloneAppClient$ClientEndpoint: Executor updated: app-20170129070137-0000/1 is now RUNNING
17/01/29 07:01:37,700 INFO StandaloneSchedulerBackend: SchedulerBackend is ready for scheduling beginning after reached minRegisteredResourcesRatio: 0.0
17/01/29 07:01:38,118 INFO MemoryStore: Block broadcast_0 stored as values in memory (estimated size 130.8 KB, free 2.1 GB)
17/01/29 07:01:38,197 INFO MemoryStore: Block broadcast_0_piece0 stored as bytes in memory (estimated size 16.5 KB, free 2.1 GB)
17/01/29 07:01:38,199 INFO BlockManagerInfo: Added broadcast_0_piece0 in memory on 10.1.2.142:38331 (size: 16.5 KB, free: 2.1 GB)
17/01/29 07:01:38,207 INFO SparkContext: Created broadcast 0 from textFile at MLUtils.scala:99
17/01/29 07:01:38,888 INFO FileInputFormat: Total input paths to process : 1
17/01/29 07:01:38,935 INFO NetworkTopology: Adding a new node: /default-rack/10.1.2.236:50010
17/01/29 07:01:38,936 INFO NetworkTopology: Adding a new node: /default-rack/10.1.2.63:50010
17/01/29 07:01:38,936 INFO NetworkTopology: Adding a new node: /default-rack/10.1.2.71:50010
17/01/29 07:01:38,981 INFO SparkContext: Starting job: first at GeneralizedLinearAlgorithm.scala:246
17/01/29 07:01:38,996 INFO DAGScheduler: Got job 0 (first at GeneralizedLinearAlgorithm.scala:246) with 1 output partitions
17/01/29 07:01:38,997 INFO DAGScheduler: Final stage: ResultStage 0 (first at GeneralizedLinearAlgorithm.scala:246)
17/01/29 07:01:38,998 INFO DAGScheduler: Parents of final stage: List()
17/01/29 07:01:39,005 INFO DAGScheduler: Missing parents: List()
17/01/29 07:01:39,021 INFO DAGScheduler: Submitting ResultStage 0 (MapPartitionsRDD[6] at map at GeneralizedLinearAlgorithm.scala:246), which has no missing parents
17/01/29 07:01:39,052 INFO MemoryStore: Block broadcast_1 stored as values in memory (estimated size 4.2 KB, free 2.1 GB)
17/01/29 07:01:39,056 INFO MemoryStore: Block broadcast_1_piece0 stored as bytes in memory (estimated size 2.4 KB, free 2.1 GB)
17/01/29 07:01:39,057 INFO BlockManagerInfo: Added broadcast_1_piece0 in memory on 10.1.2.142:38331 (size: 2.4 KB, free: 2.1 GB)
17/01/29 07:01:39,058 INFO SparkContext: Created broadcast 1 from broadcast at DAGScheduler.scala:1012
17/01/29 07:01:39,063 INFO DAGScheduler: Submitting 1 missing tasks from ResultStage 0 (MapPartitionsRDD[6] at map at GeneralizedLinearAlgorithm.scala:246)
17/01/29 07:01:39,065 INFO TaskSchedulerImpl: Adding task set 0.0 with 1 tasks
17/01/29 07:01:39,332 INFO CoarseGrainedSchedulerBackend$DriverEndpoint: Registered executor NettyRpcEndpointRef(null) (10.1.2.236:35212) with ID 0
17/01/29 07:01:39,366 INFO TaskSetManager: Starting task 0.0 in stage 0.0 (TID 0, 10.1.2.236, partition 0, ANY, 5456 bytes)
17/01/29 07:01:39,371 INFO CoarseGrainedSchedulerBackend$DriverEndpoint: Launching task 0 on executor id: 0 hostname: 10.1.2.236.
17/01/29 07:01:39,374 INFO CoarseGrainedSchedulerBackend$DriverEndpoint: Registered executor NettyRpcEndpointRef(null) (10.1.2.71:56302) with ID 2
17/01/29 07:01:39,376 INFO CoarseGrainedSchedulerBackend$DriverEndpoint: Registered executor NettyRpcEndpointRef(null) (10.1.2.181:58576) with ID 3
17/01/29 07:01:39,381 INFO BlockManagerMasterEndpoint: Registering block manager 10.1.2.236:34996 with 2.1 GB RAM, BlockManagerId(0, 10.1.2.236, 34996)
17/01/29 07:01:39,425 INFO BlockManagerMasterEndpoint: Registering block manager 10.1.2.71:39018 with 2.1 GB RAM, BlockManagerId(2, 10.1.2.71, 39018)
17/01/29 07:01:39,427 INFO BlockManagerMasterEndpoint: Registering block manager 10.1.2.181:44727 with 2.1 GB RAM, BlockManagerId(3, 10.1.2.181, 44727)
17/01/29 07:01:39,433 INFO CoarseGrainedSchedulerBackend$DriverEndpoint: Registered executor NettyRpcEndpointRef(null) (10.1.2.63:35914) with ID 1
17/01/29 07:01:39,479 INFO BlockManagerMasterEndpoint: Registering block manager 10.1.2.63:45151 with 2.1 GB RAM, BlockManagerId(1, 10.1.2.63, 45151)
17/01/29 07:01:39,650 INFO BlockManagerInfo: Added broadcast_1_piece0 in memory on 10.1.2.236:34996 (size: 2.4 KB, free: 2.1 GB)
17/01/29 07:01:39,808 INFO BlockManagerInfo: Added broadcast_0_piece0 in memory on 10.1.2.236:34996 (size: 16.5 KB, free: 2.1 GB)
17/01/29 07:01:46,922 INFO BlockManagerInfo: Added rdd_5_0 in memory on 10.1.2.236:34996 (size: 70.0 MB, free: 2.0 GB)
17/01/29 07:01:46,971 INFO TaskSetManager: Finished task 0.0 in stage 0.0 (TID 0) in 7633 ms on 10.1.2.236 (1/1)
17/01/29 07:01:46,972 INFO TaskSchedulerImpl: Removed TaskSet 0.0, whose tasks have all completed, from pool 
17/01/29 07:01:46,976 INFO DAGScheduler: ResultStage 0 (first at GeneralizedLinearAlgorithm.scala:246) finished in 7.898 s
17/01/29 07:01:46,981 INFO DAGScheduler: Job 0 finished: first at GeneralizedLinearAlgorithm.scala:246, took 7.998833 s
17/01/29 07:01:46,992 INFO SparkContext: Starting job: count at DataValidators.scala:40
17/01/29 07:01:46,994 INFO DAGScheduler: Got job 1 (count at DataValidators.scala:40) with 59 output partitions
17/01/29 07:01:46,994 INFO DAGScheduler: Final stage: ResultStage 1 (count at DataValidators.scala:40)
17/01/29 07:01:46,994 INFO DAGScheduler: Parents of final stage: List()
17/01/29 07:01:46,997 INFO DAGScheduler: Missing parents: List()
17/01/29 07:01:46,998 INFO DAGScheduler: Submitting ResultStage 1 (MapPartitionsRDD[7] at filter at DataValidators.scala:40), which has no missing parents
17/01/29 07:01:47,022 INFO MemoryStore: Block broadcast_2 stored as values in memory (estimated size 3.9 KB, free 2.1 GB)
17/01/29 07:01:47,026 INFO MemoryStore: Block broadcast_2_piece0 stored as bytes in memory (estimated size 2.2 KB, free 2.1 GB)
17/01/29 07:01:47,027 INFO BlockManagerInfo: Added broadcast_2_piece0 in memory on 10.1.2.142:38331 (size: 2.2 KB, free: 2.1 GB)
17/01/29 07:01:47,028 INFO SparkContext: Created broadcast 2 from broadcast at DAGScheduler.scala:1012
17/01/29 07:01:47,030 INFO DAGScheduler: Submitting 59 missing tasks from ResultStage 1 (MapPartitionsRDD[7] at filter at DataValidators.scala:40)
17/01/29 07:01:47,031 INFO TaskSchedulerImpl: Adding task set 1.0 with 59 tasks
17/01/29 07:01:47,037 INFO TaskSetManager: Starting task 0.0 in stage 1.0 (TID 1, 10.1.2.236, partition 0, PROCESS_LOCAL, 5374 bytes)
17/01/29 07:01:47,040 INFO TaskSetManager: Starting task 58.0 in stage 1.0 (TID 2, 10.1.2.71, partition 58, NODE_LOCAL, 5374 bytes)
17/01/29 07:01:47,041 INFO CoarseGrainedSchedulerBackend$DriverEndpoint: Launching task 2 on executor id: 2 hostname: 10.1.2.71.
17/01/29 07:01:47,042 INFO CoarseGrainedSchedulerBackend$DriverEndpoint: Launching task 1 on executor id: 0 hostname: 10.1.2.236.
17/01/29 07:01:47,060 INFO BlockManagerInfo: Added broadcast_2_piece0 in memory on 10.1.2.236:34996 (size: 2.2 KB, free: 2.0 GB)
17/01/29 07:01:47,119 INFO TaskSetManager: Finished task 0.0 in stage 1.0 (TID 1) in 85 ms on 10.1.2.236 (1/59)
17/01/29 07:01:47,301 INFO BlockManagerInfo: Added broadcast_2_piece0 in memory on 10.1.2.71:39018 (size: 2.2 KB, free: 2.1 GB)
17/01/29 07:01:47,483 INFO BlockManagerInfo: Added broadcast_0_piece0 in memory on 10.1.2.71:39018 (size: 16.5 KB, free: 2.1 GB)
17/01/29 07:01:50,297 INFO TaskSetManager: Starting task 1.0 in stage 1.0 (TID 3, 10.1.2.71, partition 1, ANY, 5374 bytes)
17/01/29 07:01:50,301 INFO TaskSetManager: Starting task 2.0 in stage 1.0 (TID 4, 10.1.2.63, partition 2, ANY, 5374 bytes)
17/01/29 07:01:50,303 INFO TaskSetManager: Starting task 3.0 in stage 1.0 (TID 5, 10.1.2.236, partition 3, ANY, 5374 bytes)
17/01/29 07:01:50,308 INFO TaskSetManager: Starting task 4.0 in stage 1.0 (TID 6, 10.1.2.181, partition 4, ANY, 5374 bytes)
17/01/29 07:01:50,309 INFO TaskSetManager: Starting task 5.0 in stage 1.0 (TID 7, 10.1.2.71, partition 5, ANY, 5374 bytes)
17/01/29 07:01:50,311 INFO TaskSetManager: Starting task 6.0 in stage 1.0 (TID 8, 10.1.2.63, partition 6, ANY, 5374 bytes)
17/01/29 07:01:50,313 INFO TaskSetManager: Starting task 7.0 in stage 1.0 (TID 9, 10.1.2.236, partition 7, ANY, 5374 bytes)
17/01/29 07:01:50,315 INFO TaskSetManager: Starting task 8.0 in stage 1.0 (TID 10, 10.1.2.181, partition 8, ANY, 5374 bytes)
17/01/29 07:01:50,317 INFO TaskSetManager: Starting task 9.0 in stage 1.0 (TID 11, 10.1.2.71, partition 9, ANY, 5374 bytes)
17/01/29 07:01:50,320 INFO TaskSetManager: Starting task 10.0 in stage 1.0 (TID 12, 10.1.2.63, partition 10, ANY, 5374 bytes)
17/01/29 07:01:50,322 INFO TaskSetManager: Starting task 11.0 in stage 1.0 (TID 13, 10.1.2.236, partition 11, ANY, 5374 bytes)
17/01/29 07:01:50,323 INFO TaskSetManager: Starting task 12.0 in stage 1.0 (TID 14, 10.1.2.181, partition 12, ANY, 5374 bytes)
17/01/29 07:01:50,328 INFO TaskSetManager: Starting task 13.0 in stage 1.0 (TID 15, 10.1.2.63, partition 13, ANY, 5374 bytes)
17/01/29 07:01:50,329 INFO TaskSetManager: Starting task 14.0 in stage 1.0 (TID 16, 10.1.2.236, partition 14, ANY, 5374 bytes)
17/01/29 07:01:50,331 INFO TaskSetManager: Starting task 15.0 in stage 1.0 (TID 17, 10.1.2.181, partition 15, ANY, 5374 bytes)
17/01/29 07:01:50,331 INFO CoarseGrainedSchedulerBackend$DriverEndpoint: Launching task 3 on executor id: 2 hostname: 10.1.2.71.
17/01/29 07:01:50,332 INFO CoarseGrainedSchedulerBackend$DriverEndpoint: Launching task 7 on executor id: 2 hostname: 10.1.2.71.
17/01/29 07:01:50,333 INFO CoarseGrainedSchedulerBackend$DriverEndpoint: Launching task 11 on executor id: 2 hostname: 10.1.2.71.
17/01/29 07:01:50,334 INFO CoarseGrainedSchedulerBackend$DriverEndpoint: Launching task 4 on executor id: 1 hostname: 10.1.2.63.
17/01/29 07:01:50,335 INFO CoarseGrainedSchedulerBackend$DriverEndpoint: Launching task 8 on executor id: 1 hostname: 10.1.2.63.
17/01/29 07:01:50,336 INFO CoarseGrainedSchedulerBackend$DriverEndpoint: Launching task 12 on executor id: 1 hostname: 10.1.2.63.
17/01/29 07:01:50,337 INFO CoarseGrainedSchedulerBackend$DriverEndpoint: Launching task 15 on executor id: 1 hostname: 10.1.2.63.
17/01/29 07:01:50,339 INFO CoarseGrainedSchedulerBackend$DriverEndpoint: Launching task 5 on executor id: 0 hostname: 10.1.2.236.
17/01/29 07:01:50,339 INFO CoarseGrainedSchedulerBackend$DriverEndpoint: Launching task 9 on executor id: 0 hostname: 10.1.2.236.
17/01/29 07:01:50,340 INFO CoarseGrainedSchedulerBackend$DriverEndpoint: Launching task 13 on executor id: 0 hostname: 10.1.2.236.
17/01/29 07:01:50,341 INFO CoarseGrainedSchedulerBackend$DriverEndpoint: Launching task 16 on executor id: 0 hostname: 10.1.2.236.
14.997: [GC17/01/29 07:01:50,342 INFO CoarseGrainedSchedulerBackend$DriverEndpoint: Launching task 6 on executor id: 3 hostname: 10.1.2.181.
17/01/29 07:01:50,344 INFO CoarseGrainedSchedulerBackend$DriverEndpoint: Launching task 10 on executor id: 3 hostname: 10.1.2.181.
17/01/29 07:01:50,352 INFO CoarseGrainedSchedulerBackend$DriverEndpoint: Launching task 14 on executor id: 3 hostname: 10.1.2.181.
17/01/29 07:01:50,354 INFO CoarseGrainedSchedulerBackend$DriverEndpoint: Launching task 17 on executor id: 3 hostname: 10.1.2.181.
 [PSYoungGen: 1024512K->157042K(1195008K)] 1024512K->157114K(3926016K), 0.1023350 secs] [Times: user=0.09 sys=0.11, real=0.10 secs] 
17/01/29 07:01:50,525 INFO BlockManagerInfo: Removed broadcast_1_piece0 on 10.1.2.142:38331 in memory (size: 2.4 KB, free: 2.1 GB)
17/01/29 07:01:50,552 INFO BlockManagerInfo: Removed broadcast_1_piece0 on 10.1.2.236:34996 in memory (size: 2.4 KB, free: 2.0 GB)
17/01/29 07:01:50,669 INFO BlockManagerInfo: Added broadcast_2_piece0 in memory on 10.1.2.181:44727 (size: 2.2 KB, free: 2.1 GB)
17/01/29 07:01:50,746 INFO BlockManagerInfo: Added broadcast_2_piece0 in memory on 10.1.2.63:45151 (size: 2.2 KB, free: 2.1 GB)
17/01/29 07:01:50,850 INFO BlockManagerInfo: Added broadcast_0_piece0 in memory on 10.1.2.181:44727 (size: 16.5 KB, free: 2.1 GB)
17/01/29 07:01:50,948 INFO BlockManagerInfo: Added broadcast_0_piece0 in memory on 10.1.2.63:45151 (size: 16.5 KB, free: 2.1 GB)
17/01/29 07:02:03,755 INFO BlockManagerInfo: Added rdd_5_58 in memory on 10.1.2.71:39018 (size: 72.8 MB, free: 2047.6 MB)
17/01/29 07:02:03,817 INFO TaskSetManager: Starting task 16.0 in stage 1.0 (TID 18, 10.1.2.71, partition 16, ANY, 5374 bytes)
17/01/29 07:02:03,818 INFO CoarseGrainedSchedulerBackend$DriverEndpoint: Launching task 18 on executor id: 2 hostname: 10.1.2.71.
17/01/29 07:02:03,821 INFO TaskSetManager: Finished task 58.0 in stage 1.0 (TID 2) in 16782 ms on 10.1.2.71 (2/59)
17/01/29 07:02:07,714 INFO BlockManagerInfo: Added rdd_5_5 in memory on 10.1.2.71:39018 (size: 70.0 MB, free: 1977.6 MB)
17/01/29 07:02:07,754 INFO TaskSetManager: Starting task 17.0 in stage 1.0 (TID 19, 10.1.2.71, partition 17, ANY, 5374 bytes)
17/01/29 07:02:07,755 INFO CoarseGrainedSchedulerBackend$DriverEndpoint: Launching task 19 on executor id: 2 hostname: 10.1.2.71.
17/01/29 07:02:07,755 INFO TaskSetManager: Finished task 5.0 in stage 1.0 (TID 7) in 17447 ms on 10.1.2.71 (3/59)
17/01/29 07:02:07,767 INFO BlockManagerInfo: Added rdd_5_9 in memory on 10.1.2.71:39018 (size: 69.9 MB, free: 1907.7 MB)
17/01/29 07:02:07,804 INFO TaskSetManager: Starting task 18.0 in stage 1.0 (TID 20, 10.1.2.71, partition 18, ANY, 5374 bytes)
17/01/29 07:02:07,805 INFO CoarseGrainedSchedulerBackend$DriverEndpoint: Launching task 20 on executor id: 2 hostname: 10.1.2.71.
17/01/29 07:02:07,805 INFO TaskSetManager: Finished task 9.0 in stage 1.0 (TID 11) in 17490 ms on 10.1.2.71 (4/59)
17/01/29 07:02:08,049 INFO BlockManagerInfo: Added rdd_5_1 in memory on 10.1.2.71:39018 (size: 70.0 MB, free: 1837.7 MB)
17/01/29 07:02:08,068 INFO TaskSetManager: Starting task 19.0 in stage 1.0 (TID 21, 10.1.2.71, partition 19, ANY, 5374 bytes)
17/01/29 07:02:08,069 INFO CoarseGrainedSchedulerBackend$DriverEndpoint: Launching task 21 on executor id: 2 hostname: 10.1.2.71.
17/01/29 07:02:08,069 INFO TaskSetManager: Finished task 1.0 in stage 1.0 (TID 3) in 17774 ms on 10.1.2.71 (5/59)
17/01/29 07:02:08,833 INFO BlockManagerInfo: Added rdd_5_14 in memory on 10.1.2.236:34996 (size: 69.9 MB, free: 1980.5 MB)
17/01/29 07:02:08,865 INFO TaskSetManager: Starting task 20.0 in stage 1.0 (TID 22, 10.1.2.236, partition 20, ANY, 5374 bytes)
17/01/29 07:02:08,865 INFO CoarseGrainedSchedulerBackend$DriverEndpoint: Launching task 22 on executor id: 0 hostname: 10.1.2.236.
17/01/29 07:02:08,865 INFO TaskSetManager: Finished task 14.0 in stage 1.0 (TID 16) in 18537 ms on 10.1.2.236 (6/59)
17/01/29 07:02:09,387 INFO BlockManagerInfo: Added rdd_5_11 in memory on 10.1.2.236:34996 (size: 69.9 MB, free: 1910.6 MB)
17/01/29 07:02:09,406 INFO TaskSetManager: Starting task 21.0 in stage 1.0 (TID 23, 10.1.2.236, partition 21, ANY, 5374 bytes)
17/01/29 07:02:09,407 INFO CoarseGrainedSchedulerBackend$DriverEndpoint: Launching task 23 on executor id: 0 hostname: 10.1.2.236.
17/01/29 07:02:09,407 INFO TaskSetManager: Finished task 11.0 in stage 1.0 (TID 13) in 19087 ms on 10.1.2.236 (7/59)
17/01/29 07:02:09,435 INFO BlockManagerInfo: Added rdd_5_7 in memory on 10.1.2.236:34996 (size: 70.0 MB, free: 1840.6 MB)
17/01/29 07:02:09,458 INFO TaskSetManager: Starting task 22.0 in stage 1.0 (TID 24, 10.1.2.236, partition 22, ANY, 5374 bytes)
17/01/29 07:02:09,459 INFO CoarseGrainedSchedulerBackend$DriverEndpoint: Launching task 24 on executor id: 0 hostname: 10.1.2.236.
17/01/29 07:02:09,459 INFO TaskSetManager: Finished task 7.0 in stage 1.0 (TID 9) in 19148 ms on 10.1.2.236 (8/59)
17/01/29 07:02:09,746 INFO BlockManagerInfo: Added rdd_5_3 in memory on 10.1.2.236:34996 (size: 69.9 MB, free: 1770.7 MB)
17/01/29 07:02:09,763 INFO TaskSetManager: Starting task 23.0 in stage 1.0 (TID 25, 10.1.2.236, partition 23, ANY, 5374 bytes)
17/01/29 07:02:09,764 INFO CoarseGrainedSchedulerBackend$DriverEndpoint: Launching task 25 on executor id: 0 hostname: 10.1.2.236.
17/01/29 07:02:09,764 INFO TaskSetManager: Finished task 3.0 in stage 1.0 (TID 5) in 19463 ms on 10.1.2.236 (9/59)
17/01/29 07:02:10,265 INFO BlockManagerInfo: Added rdd_5_15 in memory on 10.1.2.181:44727 (size: 69.9 MB, free: 2.0 GB)
17/01/29 07:02:10,340 INFO TaskSetManager: Starting task 24.0 in stage 1.0 (TID 26, 10.1.2.181, partition 24, ANY, 5374 bytes)
17/01/29 07:02:10,340 INFO CoarseGrainedSchedulerBackend$DriverEndpoint: Launching task 26 on executor id: 3 hostname: 10.1.2.181.
17/01/29 07:02:10,341 INFO TaskSetManager: Finished task 15.0 in stage 1.0 (TID 17) in 20011 ms on 10.1.2.181 (10/59)
17/01/29 07:02:10,420 INFO BlockManagerInfo: Added rdd_5_12 in memory on 10.1.2.181:44727 (size: 70.0 MB, free: 1980.5 MB)
17/01/29 07:02:10,423 INFO BlockManagerInfo: Added rdd_5_8 in memory on 10.1.2.181:44727 (size: 70.0 MB, free: 1910.5 MB)
17/01/29 07:02:10,442 INFO TaskSetManager: Starting task 25.0 in stage 1.0 (TID 27, 10.1.2.181, partition 25, ANY, 5374 bytes)
17/01/29 07:02:10,442 INFO CoarseGrainedSchedulerBackend$DriverEndpoint: Launching task 27 on executor id: 3 hostname: 10.1.2.181.
17/01/29 07:02:10,443 INFO TaskSetManager: Finished task 12.0 in stage 1.0 (TID 14) in 20120 ms on 10.1.2.181 (11/59)
17/01/29 07:02:10,458 INFO TaskSetManager: Finished task 8.0 in stage 1.0 (TID 10) in 20145 ms on 10.1.2.181 (12/59)
17/01/29 07:02:10,460 INFO TaskSetManager: Starting task 26.0 in stage 1.0 (TID 28, 10.1.2.181, partition 26, ANY, 5374 bytes)
17/01/29 07:02:10,460 INFO CoarseGrainedSchedulerBackend$DriverEndpoint: Launching task 28 on executor id: 3 hostname: 10.1.2.181.
17/01/29 07:02:11,349 INFO BlockManagerInfo: Added rdd_5_10 in memory on 10.1.2.63:45151 (size: 70.0 MB, free: 2.0 GB)
17/01/29 07:02:11,361 INFO BlockManagerInfo: Added rdd_5_4 in memory on 10.1.2.181:44727 (size: 70.0 MB, free: 1840.5 MB)
17/01/29 07:02:11,381 INFO TaskSetManager: Starting task 27.0 in stage 1.0 (TID 29, 10.1.2.181, partition 27, ANY, 5374 bytes)
17/01/29 07:02:11,381 INFO CoarseGrainedSchedulerBackend$DriverEndpoint: Launching task 29 on executor id: 3 hostname: 10.1.2.181.
17/01/29 07:02:11,382 INFO TaskSetManager: Finished task 4.0 in stage 1.0 (TID 6) in 21078 ms on 10.1.2.181 (13/59)
17/01/29 07:02:11,408 INFO TaskSetManager: Starting task 28.0 in stage 1.0 (TID 30, 10.1.2.63, partition 28, ANY, 5374 bytes)
17/01/29 07:02:11,408 INFO CoarseGrainedSchedulerBackend$DriverEndpoint: Launching task 30 on executor id: 1 hostname: 10.1.2.63.
17/01/29 07:02:11,411 INFO TaskSetManager: Finished task 10.0 in stage 1.0 (TID 12) in 21093 ms on 10.1.2.63 (14/59)
17/01/29 07:02:12,218 INFO BlockManagerInfo: Added rdd_5_13 in memory on 10.1.2.63:45151 (size: 69.9 MB, free: 1980.5 MB)
17/01/29 07:02:12,242 INFO TaskSetManager: Starting task 29.0 in stage 1.0 (TID 31, 10.1.2.63, partition 29, ANY, 5374 bytes)
17/01/29 07:02:12,243 INFO CoarseGrainedSchedulerBackend$DriverEndpoint: Launching task 31 on executor id: 1 hostname: 10.1.2.63.
17/01/29 07:02:12,243 INFO TaskSetManager: Finished task 13.0 in stage 1.0 (TID 15) in 21919 ms on 10.1.2.63 (15/59)
17/01/29 07:02:12,318 INFO BlockManagerInfo: Added rdd_5_2 in memory on 10.1.2.63:45151 (size: 69.9 MB, free: 1910.6 MB)
17/01/29 07:02:12,358 INFO TaskSetManager: Starting task 30.0 in stage 1.0 (TID 32, 10.1.2.63, partition 30, ANY, 5374 bytes)
17/01/29 07:02:12,358 INFO CoarseGrainedSchedulerBackend$DriverEndpoint: Launching task 32 on executor id: 1 hostname: 10.1.2.63.
17/01/29 07:02:12,359 INFO TaskSetManager: Finished task 2.0 in stage 1.0 (TID 4) in 22062 ms on 10.1.2.63 (16/59)
17/01/29 07:02:12,446 INFO BlockManagerInfo: Added rdd_5_6 in memory on 10.1.2.63:45151 (size: 69.9 MB, free: 1840.7 MB)
17/01/29 07:02:12,465 INFO TaskSetManager: Starting task 31.0 in stage 1.0 (TID 33, 10.1.2.63, partition 31, ANY, 5374 bytes)
17/01/29 07:02:12,465 INFO CoarseGrainedSchedulerBackend$DriverEndpoint: Launching task 33 on executor id: 1 hostname: 10.1.2.63.
17/01/29 07:02:12,466 INFO TaskSetManager: Finished task 6.0 in stage 1.0 (TID 8) in 22155 ms on 10.1.2.63 (17/59)
17/01/29 07:02:21,299 INFO BlockManagerInfo: Added rdd_5_16 in memory on 10.1.2.71:39018 (size: 70.0 MB, free: 1767.8 MB)
17/01/29 07:02:21,317 INFO TaskSetManager: Starting task 32.0 in stage 1.0 (TID 34, 10.1.2.71, partition 32, ANY, 5374 bytes)
17/01/29 07:02:21,318 INFO CoarseGrainedSchedulerBackend$DriverEndpoint: Launching task 34 on executor id: 2 hostname: 10.1.2.71.
17/01/29 07:02:21,319 INFO TaskSetManager: Finished task 16.0 in stage 1.0 (TID 18) in 17503 ms on 10.1.2.71 (18/59)
17/01/29 07:02:24,560 INFO BlockManagerInfo: Added rdd_5_18 in memory on 10.1.2.71:39018 (size: 70.0 MB, free: 1697.8 MB)
17/01/29 07:02:24,578 INFO TaskSetManager: Starting task 33.0 in stage 1.0 (TID 35, 10.1.2.71, partition 33, ANY, 5374 bytes)
17/01/29 07:02:24,578 INFO CoarseGrainedSchedulerBackend$DriverEndpoint: Launching task 35 on executor id: 2 hostname: 10.1.2.71.
17/01/29 07:02:24,579 INFO TaskSetManager: Finished task 18.0 in stage 1.0 (TID 20) in 16776 ms on 10.1.2.71 (19/59)
17/01/29 07:02:24,775 INFO BlockManagerInfo: Added rdd_5_17 in memory on 10.1.2.71:39018 (size: 69.9 MB, free: 1627.9 MB)
17/01/29 07:02:24,795 INFO TaskSetManager: Starting task 34.0 in stage 1.0 (TID 36, 10.1.2.71, partition 34, ANY, 5374 bytes)
17/01/29 07:02:24,796 INFO CoarseGrainedSchedulerBackend$DriverEndpoint: Launching task 36 on executor id: 2 hostname: 10.1.2.71.
17/01/29 07:02:24,797 INFO TaskSetManager: Finished task 17.0 in stage 1.0 (TID 19) in 17044 ms on 10.1.2.71 (20/59)
17/01/29 07:02:25,558 INFO BlockManagerInfo: Added rdd_5_19 in memory on 10.1.2.71:39018 (size: 70.0 MB, free: 1557.9 MB)
17/01/29 07:02:25,577 INFO TaskSetManager: Starting task 35.0 in stage 1.0 (TID 37, 10.1.2.71, partition 35, ANY, 5374 bytes)
17/01/29 07:02:25,578 INFO CoarseGrainedSchedulerBackend$DriverEndpoint: Launching task 37 on executor id: 2 hostname: 10.1.2.71.
17/01/29 07:02:25,578 INFO TaskSetManager: Finished task 19.0 in stage 1.0 (TID 21) in 17511 ms on 10.1.2.71 (21/59)
17/01/29 07:02:26,982 INFO BlockManagerInfo: Added rdd_5_22 in memory on 10.1.2.236:34996 (size: 69.8 MB, free: 1700.8 MB)
17/01/29 07:02:27,000 INFO TaskSetManager: Starting task 36.0 in stage 1.0 (TID 38, 10.1.2.236, partition 36, ANY, 5374 bytes)
17/01/29 07:02:27,000 INFO CoarseGrainedSchedulerBackend$DriverEndpoint: Launching task 38 on executor id: 0 hostname: 10.1.2.236.
17/01/29 07:02:27,000 INFO TaskSetManager: Finished task 22.0 in stage 1.0 (TID 24) in 17543 ms on 10.1.2.236 (22/59)
17/01/29 07:02:28,048 INFO BlockManagerInfo: Added rdd_5_23 in memory on 10.1.2.236:34996 (size: 69.9 MB, free: 1631.0 MB)
17/01/29 07:02:28,065 INFO TaskSetManager: Starting task 37.0 in stage 1.0 (TID 39, 10.1.2.236, partition 37, ANY, 5374 bytes)
17/01/29 07:02:28,065 INFO CoarseGrainedSchedulerBackend$DriverEndpoint: Launching task 39 on executor id: 0 hostname: 10.1.2.236.
17/01/29 07:02:28,066 INFO TaskSetManager: Finished task 23.0 in stage 1.0 (TID 25) in 18304 ms on 10.1.2.236 (23/59)
17/01/29 07:02:28,876 INFO BlockManagerInfo: Added rdd_5_25 in memory on 10.1.2.181:44727 (size: 70.0 MB, free: 1770.6 MB)
17/01/29 07:02:28,894 INFO TaskSetManager: Starting task 38.0 in stage 1.0 (TID 40, 10.1.2.181, partition 38, ANY, 5374 bytes)
17/01/29 07:02:28,894 INFO CoarseGrainedSchedulerBackend$DriverEndpoint: Launching task 40 on executor id: 3 hostname: 10.1.2.181.
17/01/29 07:02:28,894 INFO TaskSetManager: Finished task 25.0 in stage 1.0 (TID 27) in 18453 ms on 10.1.2.181 (24/59)
17/01/29 07:02:28,991 INFO BlockManagerInfo: Added rdd_5_24 in memory on 10.1.2.181:44727 (size: 69.8 MB, free: 1700.8 MB)
17/01/29 07:02:29,007 INFO TaskSetManager: Starting task 39.0 in stage 1.0 (TID 41, 10.1.2.181, partition 39, ANY, 5374 bytes)
17/01/29 07:02:29,008 INFO CoarseGrainedSchedulerBackend$DriverEndpoint: Launching task 41 on executor id: 3 hostname: 10.1.2.181.
17/01/29 07:02:29,008 INFO TaskSetManager: Finished task 24.0 in stage 1.0 (TID 26) in 18670 ms on 10.1.2.181 (25/59)
17/01/29 07:02:29,086 INFO BlockManagerInfo: Added rdd_5_27 in memory on 10.1.2.181:44727 (size: 69.9 MB, free: 1630.9 MB)
17/01/29 07:02:29,102 INFO TaskSetManager: Starting task 40.0 in stage 1.0 (TID 42, 10.1.2.181, partition 40, ANY, 5374 bytes)
17/01/29 07:02:29,103 INFO CoarseGrainedSchedulerBackend$DriverEndpoint: Launching task 42 on executor id: 3 hostname: 10.1.2.181.
17/01/29 07:02:29,103 INFO TaskSetManager: Finished task 27.0 in stage 1.0 (TID 29) in 17724 ms on 10.1.2.181 (26/59)
17/01/29 07:02:29,187 INFO BlockManagerInfo: Added rdd_5_26 in memory on 10.1.2.181:44727 (size: 69.9 MB, free: 1561.0 MB)
17/01/29 07:02:29,204 INFO TaskSetManager: Starting task 41.0 in stage 1.0 (TID 43, 10.1.2.181, partition 41, ANY, 5374 bytes)
17/01/29 07:02:29,204 INFO CoarseGrainedSchedulerBackend$DriverEndpoint: Launching task 43 on executor id: 3 hostname: 10.1.2.181.
17/01/29 07:02:29,204 INFO TaskSetManager: Finished task 26.0 in stage 1.0 (TID 28) in 18745 ms on 10.1.2.181 (27/59)
17/01/29 07:02:29,542 INFO BlockManagerInfo: Added rdd_5_29 in memory on 10.1.2.63:45151 (size: 69.9 MB, free: 1770.7 MB)
17/01/29 07:02:29,561 INFO TaskSetManager: Starting task 42.0 in stage 1.0 (TID 44, 10.1.2.63, partition 42, ANY, 5374 bytes)
17/01/29 07:02:29,561 INFO CoarseGrainedSchedulerBackend$DriverEndpoint: Launching task 44 on executor id: 1 hostname: 10.1.2.63.
17/01/29 07:02:29,561 INFO TaskSetManager: Finished task 29.0 in stage 1.0 (TID 31) in 17320 ms on 10.1.2.63 (28/59)
17/01/29 07:02:29,569 INFO BlockManagerInfo: Added rdd_5_30 in memory on 10.1.2.63:45151 (size: 70.0 MB, free: 1700.8 MB)
17/01/29 07:02:29,602 INFO TaskSetManager: Starting task 43.0 in stage 1.0 (TID 45, 10.1.2.63, partition 43, ANY, 5374 bytes)
17/01/29 07:02:29,602 INFO CoarseGrainedSchedulerBackend$DriverEndpoint: Launching task 45 on executor id: 1 hostname: 10.1.2.63.
17/01/29 07:02:29,603 INFO TaskSetManager: Finished task 30.0 in stage 1.0 (TID 32) in 17245 ms on 10.1.2.63 (29/59)
17/01/29 07:02:29,606 INFO BlockManagerInfo: Added rdd_5_21 in memory on 10.1.2.236:34996 (size: 69.9 MB, free: 1561.0 MB)
17/01/29 07:02:29,625 INFO TaskSetManager: Starting task 44.0 in stage 1.0 (TID 46, 10.1.2.236, partition 44, ANY, 5374 bytes)
17/01/29 07:02:29,625 INFO CoarseGrainedSchedulerBackend$DriverEndpoint: Launching task 46 on executor id: 0 hostname: 10.1.2.236.
17/01/29 07:02:29,626 INFO TaskSetManager: Finished task 21.0 in stage 1.0 (TID 23) in 20221 ms on 10.1.2.236 (30/59)
17/01/29 07:02:29,766 INFO BlockManagerInfo: Added rdd_5_28 in memory on 10.1.2.63:45151 (size: 70.0 MB, free: 1630.8 MB)
17/01/29 07:02:29,784 INFO TaskSetManager: Starting task 45.0 in stage 1.0 (TID 47, 10.1.2.63, partition 45, ANY, 5374 bytes)
17/01/29 07:02:29,784 INFO CoarseGrainedSchedulerBackend$DriverEndpoint: Launching task 47 on executor id: 1 hostname: 10.1.2.63.
17/01/29 07:02:29,784 INFO TaskSetManager: Finished task 28.0 in stage 1.0 (TID 30) in 18377 ms on 10.1.2.63 (31/59)
17/01/29 07:02:30,938 INFO BlockManagerInfo: Added rdd_5_20 in memory on 10.1.2.236:34996 (size: 69.8 MB, free: 1491.2 MB)
17/01/29 07:02:30,980 INFO TaskSetManager: Starting task 46.0 in stage 1.0 (TID 48, 10.1.2.236, partition 46, ANY, 5374 bytes)
17/01/29 07:02:30,980 INFO CoarseGrainedSchedulerBackend$DriverEndpoint: Launching task 48 on executor id: 0 hostname: 10.1.2.236.
17/01/29 07:02:30,981 INFO TaskSetManager: Finished task 20.0 in stage 1.0 (TID 22) in 22118 ms on 10.1.2.236 (32/59)
17/01/29 07:02:31,486 INFO BlockManagerInfo: Added rdd_5_31 in memory on 10.1.2.63:45151 (size: 69.7 MB, free: 1561.1 MB)
17/01/29 07:02:31,505 INFO TaskSetManager: Starting task 47.0 in stage 1.0 (TID 49, 10.1.2.63, partition 47, ANY, 5374 bytes)
17/01/29 07:02:31,505 INFO CoarseGrainedSchedulerBackend$DriverEndpoint: Launching task 49 on executor id: 1 hostname: 10.1.2.63.
17/01/29 07:02:31,505 INFO TaskSetManager: Finished task 31.0 in stage 1.0 (TID 33) in 19041 ms on 10.1.2.63 (33/59)
17/01/29 07:02:39,005 INFO BlockManagerInfo: Added rdd_5_32 in memory on 10.1.2.71:39018 (size: 69.9 MB, free: 1488.0 MB)
17/01/29 07:02:39,025 INFO TaskSetManager: Starting task 48.0 in stage 1.0 (TID 50, 10.1.2.71, partition 48, ANY, 5374 bytes)
17/01/29 07:02:39,025 INFO CoarseGrainedSchedulerBackend$DriverEndpoint: Launching task 50 on executor id: 2 hostname: 10.1.2.71.
17/01/29 07:02:39,025 INFO TaskSetManager: Finished task 32.0 in stage 1.0 (TID 34) in 17709 ms on 10.1.2.71 (34/59)
17/01/29 07:02:41,913 INFO BlockManagerInfo: Added rdd_5_33 in memory on 10.1.2.71:39018 (size: 69.9 MB, free: 1418.1 MB)
17/01/29 07:02:41,933 INFO TaskSetManager: Starting task 49.0 in stage 1.0 (TID 51, 10.1.2.71, partition 49, ANY, 5374 bytes)
17/01/29 07:02:41,934 INFO CoarseGrainedSchedulerBackend$DriverEndpoint: Launching task 51 on executor id: 2 hostname: 10.1.2.71.
17/01/29 07:02:41,935 INFO TaskSetManager: Finished task 33.0 in stage 1.0 (TID 35) in 17357 ms on 10.1.2.71 (35/59)
17/01/29 07:02:42,452 INFO BlockManagerInfo: Added rdd_5_34 in memory on 10.1.2.71:39018 (size: 70.0 MB, free: 1348.1 MB)
17/01/29 07:02:42,470 INFO TaskSetManager: Starting task 50.0 in stage 1.0 (TID 52, 10.1.2.71, partition 50, ANY, 5374 bytes)
17/01/29 07:02:42,470 INFO CoarseGrainedSchedulerBackend$DriverEndpoint: Launching task 52 on executor id: 2 hostname: 10.1.2.71.
17/01/29 07:02:42,471 INFO TaskSetManager: Finished task 34.0 in stage 1.0 (TID 36) in 17676 ms on 10.1.2.71 (36/59)
17/01/29 07:02:43,024 INFO BlockManagerInfo: Added rdd_5_35 in memory on 10.1.2.71:39018 (size: 70.0 MB, free: 1278.1 MB)
17/01/29 07:02:43,042 INFO TaskSetManager: Starting task 51.0 in stage 1.0 (TID 53, 10.1.2.71, partition 51, ANY, 5374 bytes)
17/01/29 07:02:43,042 INFO CoarseGrainedSchedulerBackend$DriverEndpoint: Launching task 53 on executor id: 2 hostname: 10.1.2.71.
17/01/29 07:02:43,043 INFO TaskSetManager: Finished task 35.0 in stage 1.0 (TID 37) in 17466 ms on 10.1.2.71 (37/59)
17/01/29 07:02:45,362 INFO BlockManagerInfo: Added rdd_5_41 in memory on 10.1.2.181:44727 (size: 70.0 MB, free: 1491.0 MB)
17/01/29 07:02:45,402 INFO TaskSetManager: Starting task 52.0 in stage 1.0 (TID 54, 10.1.2.181, partition 52, ANY, 5374 bytes)
17/01/29 07:02:45,402 INFO CoarseGrainedSchedulerBackend$DriverEndpoint: Launching task 54 on executor id: 3 hostname: 10.1.2.181.
17/01/29 07:02:45,403 INFO TaskSetManager: Finished task 41.0 in stage 1.0 (TID 43) in 16200 ms on 10.1.2.181 (38/59)
17/01/29 07:02:45,744 INFO BlockManagerInfo: Added rdd_5_38 in memory on 10.1.2.181:44727 (size: 70.0 MB, free: 1421.1 MB)
17/01/29 07:02:45,762 INFO TaskSetManager: Starting task 53.0 in stage 1.0 (TID 55, 10.1.2.181, partition 53, ANY, 5374 bytes)
17/01/29 07:02:45,764 INFO TaskSetManager: Finished task 38.0 in stage 1.0 (TID 40) in 16870 ms on 10.1.2.181 (39/59)
17/01/29 07:02:45,765 INFO CoarseGrainedSchedulerBackend$DriverEndpoint: Launching task 55 on executor id: 3 hostname: 10.1.2.181.
17/01/29 07:02:46,557 INFO BlockManagerInfo: Added rdd_5_36 in memory on 10.1.2.236:34996 (size: 70.0 MB, free: 1421.2 MB)
17/01/29 07:02:46,574 INFO TaskSetManager: Starting task 54.0 in stage 1.0 (TID 56, 10.1.2.236, partition 54, ANY, 5374 bytes)
17/01/29 07:02:46,574 INFO CoarseGrainedSchedulerBackend$DriverEndpoint: Launching task 56 on executor id: 0 hostname: 10.1.2.236.
17/01/29 07:02:46,575 INFO TaskSetManager: Finished task 36.0 in stage 1.0 (TID 38) in 19576 ms on 10.1.2.236 (40/59)
17/01/29 07:02:47,907 INFO BlockManagerInfo: Added rdd_5_40 in memory on 10.1.2.181:44727 (size: 70.0 MB, free: 1351.1 MB)
17/01/29 07:02:47,953 INFO TaskSetManager: Starting task 55.0 in stage 1.0 (TID 57, 10.1.2.181, partition 55, ANY, 5374 bytes)
17/01/29 07:02:47,953 INFO CoarseGrainedSchedulerBackend$DriverEndpoint: Launching task 57 on executor id: 3 hostname: 10.1.2.181.
17/01/29 07:02:47,953 INFO TaskSetManager: Finished task 40.0 in stage 1.0 (TID 42) in 18851 ms on 10.1.2.181 (41/59)
17/01/29 07:02:48,104 INFO BlockManagerInfo: Added rdd_5_39 in memory on 10.1.2.181:44727 (size: 70.0 MB, free: 1281.1 MB)
17/01/29 07:02:48,122 INFO TaskSetManager: Starting task 56.0 in stage 1.0 (TID 58, 10.1.2.181, partition 56, ANY, 5374 bytes)
17/01/29 07:02:48,123 INFO CoarseGrainedSchedulerBackend$DriverEndpoint: Launching task 58 on executor id: 3 hostname: 10.1.2.181.
17/01/29 07:02:48,124 INFO TaskSetManager: Finished task 39.0 in stage 1.0 (TID 41) in 19117 ms on 10.1.2.181 (42/59)
17/01/29 07:02:48,198 INFO BlockManagerInfo: Added rdd_5_37 in memory on 10.1.2.236:34996 (size: 69.9 MB, free: 1351.2 MB)
17/01/29 07:02:48,214 INFO TaskSetManager: Finished task 37.0 in stage 1.0 (TID 39) in 20149 ms on 10.1.2.236 (43/59)
17/01/29 07:02:48,215 INFO TaskSetManager: Starting task 57.0 in stage 1.0 (TID 59, 10.1.2.236, partition 57, ANY, 5374 bytes)
17/01/29 07:02:48,215 INFO CoarseGrainedSchedulerBackend$DriverEndpoint: Launching task 59 on executor id: 0 hostname: 10.1.2.236.
17/01/29 07:02:48,314 INFO BlockManagerInfo: Added rdd_5_44 in memory on 10.1.2.236:34996 (size: 70.0 MB, free: 1281.3 MB)
17/01/29 07:02:48,332 INFO TaskSetManager: Finished task 44.0 in stage 1.0 (TID 46) in 18708 ms on 10.1.2.236 (44/59)
17/01/29 07:02:48,540 INFO BlockManagerInfo: Added rdd_5_46 in memory on 10.1.2.236:34996 (size: 69.9 MB, free: 1211.3 MB)
17/01/29 07:02:48,560 INFO TaskSetManager: Finished task 46.0 in stage 1.0 (TID 48) in 17581 ms on 10.1.2.236 (45/59)
17/01/29 07:02:50,818 INFO BlockManagerInfo: Added rdd_5_42 in memory on 10.1.2.63:45151 (size: 69.8 MB, free: 1491.3 MB)
17/01/29 07:02:50,835 INFO TaskSetManager: Finished task 42.0 in stage 1.0 (TID 44) in 21275 ms on 10.1.2.63 (46/59)
17/01/29 07:02:52,614 INFO BlockManagerInfo: Added rdd_5_43 in memory on 10.1.2.63:45151 (size: 69.8 MB, free: 1421.4 MB)
17/01/29 07:02:52,632 INFO TaskSetManager: Finished task 43.0 in stage 1.0 (TID 45) in 23031 ms on 10.1.2.63 (47/59)
17/01/29 07:02:52,748 INFO BlockManagerInfo: Added rdd_5_45 in memory on 10.1.2.63:45151 (size: 69.9 MB, free: 1351.5 MB)
17/01/29 07:02:52,766 INFO TaskSetManager: Finished task 45.0 in stage 1.0 (TID 47) in 22983 ms on 10.1.2.63 (48/59)
17/01/29 07:02:53,182 INFO BlockManagerInfo: Added rdd_5_47 in memory on 10.1.2.63:45151 (size: 70.0 MB, free: 1281.6 MB)
17/01/29 07:02:53,200 INFO TaskSetManager: Finished task 47.0 in stage 1.0 (TID 49) in 21697 ms on 10.1.2.63 (49/59)
17/01/29 07:02:55,890 INFO BlockManagerInfo: Added rdd_5_54 in memory on 10.1.2.236:34996 (size: 69.9 MB, free: 1141.4 MB)
17/01/29 07:02:55,912 INFO TaskSetManager: Finished task 54.0 in stage 1.0 (TID 56) in 9338 ms on 10.1.2.236 (50/59)
17/01/29 07:02:56,499 INFO BlockManagerInfo: Added rdd_5_57 in memory on 10.1.2.236:34996 (size: 70.1 MB, free: 1071.3 MB)
17/01/29 07:02:56,517 INFO TaskSetManager: Finished task 57.0 in stage 1.0 (TID 59) in 8303 ms on 10.1.2.236 (51/59)
17/01/29 07:02:57,763 INFO BlockManagerInfo: Added rdd_5_48 in memory on 10.1.2.71:39018 (size: 69.9 MB, free: 1208.2 MB)
17/01/29 07:02:57,782 INFO TaskSetManager: Finished task 48.0 in stage 1.0 (TID 50) in 18758 ms on 10.1.2.71 (52/59)
17/01/29 07:02:58,960 INFO BlockManagerInfo: Added rdd_5_49 in memory on 10.1.2.71:39018 (size: 69.8 MB, free: 1138.4 MB)
17/01/29 07:02:58,977 INFO TaskSetManager: Finished task 49.0 in stage 1.0 (TID 51) in 17043 ms on 10.1.2.71 (53/59)
17/01/29 07:02:59,201 INFO BlockManagerInfo: Added rdd_5_50 in memory on 10.1.2.71:39018 (size: 69.9 MB, free: 1068.5 MB)
17/01/29 07:02:59,218 INFO TaskSetManager: Finished task 50.0 in stage 1.0 (TID 52) in 16748 ms on 10.1.2.71 (54/59)
17/01/29 07:02:59,610 INFO BlockManagerInfo: Added rdd_5_51 in memory on 10.1.2.71:39018 (size: 69.9 MB, free: 998.7 MB)
17/01/29 07:02:59,626 INFO TaskSetManager: Finished task 51.0 in stage 1.0 (TID 53) in 16585 ms on 10.1.2.71 (55/59)
17/01/29 07:03:06,536 INFO BlockManagerInfo: Added rdd_5_52 in memory on 10.1.2.181:44727 (size: 69.9 MB, free: 1211.2 MB)
17/01/29 07:03:06,554 INFO TaskSetManager: Finished task 52.0 in stage 1.0 (TID 54) in 21152 ms on 10.1.2.181 (56/59)
17/01/29 07:03:06,568 INFO BlockManagerInfo: Added rdd_5_53 in memory on 10.1.2.181:44727 (size: 70.0 MB, free: 1141.2 MB)
17/01/29 07:03:06,585 INFO TaskSetManager: Finished task 53.0 in stage 1.0 (TID 55) in 20824 ms on 10.1.2.181 (57/59)
17/01/29 07:03:06,811 INFO BlockManagerInfo: Added rdd_5_55 in memory on 10.1.2.181:44727 (size: 69.9 MB, free: 1071.3 MB)
17/01/29 07:03:06,827 INFO TaskSetManager: Finished task 55.0 in stage 1.0 (TID 57) in 18875 ms on 10.1.2.181 (58/59)
17/01/29 07:03:07,164 INFO BlockManagerInfo: Added rdd_5_56 in memory on 10.1.2.181:44727 (size: 69.9 MB, free: 1001.4 MB)
17/01/29 07:03:07,179 INFO TaskSetManager: Finished task 56.0 in stage 1.0 (TID 58) in 19057 ms on 10.1.2.181 (59/59)
17/01/29 07:03:07,179 INFO TaskSchedulerImpl: Removed TaskSet 1.0, whose tasks have all completed, from pool 
17/01/29 07:03:07,180 INFO DAGScheduler: ResultStage 1 (count at DataValidators.scala:40) finished in 80.147 s
17/01/29 07:03:07,180 INFO DAGScheduler: Job 1 finished: count at DataValidators.scala:40, took 80.187954 s
17/01/29 07:03:07,192 INFO SparkContext: Starting job: count at GradientDescent.scala:209
17/01/29 07:03:07,193 INFO DAGScheduler: Got job 2 (count at GradientDescent.scala:209) with 59 output partitions
17/01/29 07:03:07,193 INFO DAGScheduler: Final stage: ResultStage 2 (count at GradientDescent.scala:209)
17/01/29 07:03:07,193 INFO DAGScheduler: Parents of final stage: List()
17/01/29 07:03:07,196 INFO DAGScheduler: Missing parents: List()
17/01/29 07:03:07,197 INFO DAGScheduler: Submitting ResultStage 2 (MapPartitionsRDD[8] at map at GeneralizedLinearAlgorithm.scala:297), which has no missing parents
17/01/29 07:03:07,203 INFO MemoryStore: Block broadcast_3 stored as values in memory (estimated size 3.9 KB, free 2.1 GB)
17/01/29 07:03:07,204 INFO MemoryStore: Block broadcast_3_piece0 stored as bytes in memory (estimated size 2.2 KB, free 2.1 GB)
17/01/29 07:03:07,205 INFO BlockManagerInfo: Added broadcast_3_piece0 in memory on 10.1.2.142:38331 (size: 2.2 KB, free: 2.1 GB)
17/01/29 07:03:07,206 INFO SparkContext: Created broadcast 3 from broadcast at DAGScheduler.scala:1012
17/01/29 07:03:07,207 INFO DAGScheduler: Submitting 59 missing tasks from ResultStage 2 (MapPartitionsRDD[8] at map at GeneralizedLinearAlgorithm.scala:297)
17/01/29 07:03:07,208 INFO TaskSchedulerImpl: Adding task set 2.0 with 59 tasks
17/01/29 07:03:07,210 INFO TaskSetManager: Starting task 4.0 in stage 2.0 (TID 60, 10.1.2.181, partition 4, PROCESS_LOCAL, 5374 bytes)
17/01/29 07:03:07,211 INFO TaskSetManager: Starting task 0.0 in stage 2.0 (TID 61, 10.1.2.236, partition 0, PROCESS_LOCAL, 5374 bytes)
17/01/29 07:03:07,212 INFO TaskSetManager: Starting task 2.0 in stage 2.0 (TID 62, 10.1.2.63, partition 2, PROCESS_LOCAL, 5374 bytes)
17/01/29 07:03:07,213 INFO TaskSetManager: Starting task 1.0 in stage 2.0 (TID 63, 10.1.2.71, partition 1, PROCESS_LOCAL, 5374 bytes)
17/01/29 07:03:07,213 INFO TaskSetManager: Starting task 8.0 in stage 2.0 (TID 64, 10.1.2.181, partition 8, PROCESS_LOCAL, 5374 bytes)
17/01/29 07:03:07,214 INFO TaskSetManager: Starting task 3.0 in stage 2.0 (TID 65, 10.1.2.236, partition 3, PROCESS_LOCAL, 5374 bytes)
17/01/29 07:03:07,215 INFO TaskSetManager: Starting task 6.0 in stage 2.0 (TID 66, 10.1.2.63, partition 6, PROCESS_LOCAL, 5374 bytes)
17/01/29 07:03:07,216 INFO TaskSetManager: Starting task 5.0 in stage 2.0 (TID 67, 10.1.2.71, partition 5, PROCESS_LOCAL, 5374 bytes)
17/01/29 07:03:07,216 INFO TaskSetManager: Starting task 12.0 in stage 2.0 (TID 68, 10.1.2.181, partition 12, PROCESS_LOCAL, 5374 bytes)
17/01/29 07:03:07,217 INFO TaskSetManager: Starting task 7.0 in stage 2.0 (TID 69, 10.1.2.236, partition 7, PROCESS_LOCAL, 5374 bytes)
17/01/29 07:03:07,218 INFO TaskSetManager: Starting task 10.0 in stage 2.0 (TID 70, 10.1.2.63, partition 10, PROCESS_LOCAL, 5374 bytes)
17/01/29 07:03:07,219 INFO TaskSetManager: Starting task 9.0 in stage 2.0 (TID 71, 10.1.2.71, partition 9, PROCESS_LOCAL, 5374 bytes)
17/01/29 07:03:07,220 INFO TaskSetManager: Starting task 15.0 in stage 2.0 (TID 72, 10.1.2.181, partition 15, PROCESS_LOCAL, 5374 bytes)
17/01/29 07:03:07,221 INFO TaskSetManager: Starting task 11.0 in stage 2.0 (TID 73, 10.1.2.236, partition 11, PROCESS_LOCAL, 5374 bytes)
17/01/29 07:03:07,221 INFO TaskSetManager: Starting task 13.0 in stage 2.0 (TID 74, 10.1.2.63, partition 13, PROCESS_LOCAL, 5374 bytes)
17/01/29 07:03:07,222 INFO TaskSetManager: Starting task 16.0 in stage 2.0 (TID 75, 10.1.2.71, partition 16, PROCESS_LOCAL, 5374 bytes)
17/01/29 07:03:07,223 INFO CoarseGrainedSchedulerBackend$DriverEndpoint: Launching task 60 on executor id: 3 hostname: 10.1.2.181.
17/01/29 07:03:07,224 INFO CoarseGrainedSchedulerBackend$DriverEndpoint: Launching task 64 on executor id: 3 hostname: 10.1.2.181.
17/01/29 07:03:07,225 INFO CoarseGrainedSchedulerBackend$DriverEndpoint: Launching task 68 on executor id: 3 hostname: 10.1.2.181.
17/01/29 07:03:07,226 INFO CoarseGrainedSchedulerBackend$DriverEndpoint: Launching task 72 on executor id: 3 hostname: 10.1.2.181.
17/01/29 07:03:07,227 INFO CoarseGrainedSchedulerBackend$DriverEndpoint: Launching task 61 on executor id: 0 hostname: 10.1.2.236.
17/01/29 07:03:07,227 INFO CoarseGrainedSchedulerBackend$DriverEndpoint: Launching task 65 on executor id: 0 hostname: 10.1.2.236.
17/01/29 07:03:07,227 INFO CoarseGrainedSchedulerBackend$DriverEndpoint: Launching task 69 on executor id: 0 hostname: 10.1.2.236.
17/01/29 07:03:07,230 INFO CoarseGrainedSchedulerBackend$DriverEndpoint: Launching task 73 on executor id: 0 hostname: 10.1.2.236.
17/01/29 07:03:07,231 INFO CoarseGrainedSchedulerBackend$DriverEndpoint: Launching task 62 on executor id: 1 hostname: 10.1.2.63.
17/01/29 07:03:07,231 INFO CoarseGrainedSchedulerBackend$DriverEndpoint: Launching task 66 on executor id: 1 hostname: 10.1.2.63.
17/01/29 07:03:07,232 INFO CoarseGrainedSchedulerBackend$DriverEndpoint: Launching task 70 on executor id: 1 hostname: 10.1.2.63.
17/01/29 07:03:07,234 INFO CoarseGrainedSchedulerBackend$DriverEndpoint: Launching task 74 on executor id: 1 hostname: 10.1.2.63.
17/01/29 07:03:07,235 INFO CoarseGrainedSchedulerBackend$DriverEndpoint: Launching task 63 on executor id: 2 hostname: 10.1.2.71.
17/01/29 07:03:07,237 INFO CoarseGrainedSchedulerBackend$DriverEndpoint: Launching task 67 on executor id: 2 hostname: 10.1.2.71.
17/01/29 07:03:07,238 INFO CoarseGrainedSchedulerBackend$DriverEndpoint: Launching task 71 on executor id: 2 hostname: 10.1.2.71.
17/01/29 07:03:07,239 INFO CoarseGrainedSchedulerBackend$DriverEndpoint: Launching task 75 on executor id: 2 hostname: 10.1.2.71.
17/01/29 07:03:07,241 INFO BlockManagerInfo: Added broadcast_3_piece0 in memory on 10.1.2.181:44727 (size: 2.2 KB, free: 1001.4 MB)
17/01/29 07:03:07,266 INFO BlockManagerInfo: Added broadcast_3_piece0 in memory on 10.1.2.63:45151 (size: 2.2 KB, free: 1281.6 MB)
17/01/29 07:03:07,280 INFO TaskSetManager: Starting task 24.0 in stage 2.0 (TID 76, 10.1.2.181, partition 24, PROCESS_LOCAL, 5374 bytes)
17/01/29 07:03:07,281 INFO CoarseGrainedSchedulerBackend$DriverEndpoint: Launching task 76 on executor id: 3 hostname: 10.1.2.181.
17/01/29 07:03:07,281 INFO TaskSetManager: Finished task 4.0 in stage 2.0 (TID 60) in 72 ms on 10.1.2.181 (1/59)
17/01/29 07:03:07,308 INFO TaskSetManager: Starting task 25.0 in stage 2.0 (TID 77, 10.1.2.181, partition 25, PROCESS_LOCAL, 5374 bytes)
17/01/29 07:03:07,309 INFO CoarseGrainedSchedulerBackend$DriverEndpoint: Launching task 77 on executor id: 3 hostname: 10.1.2.181.
17/01/29 07:03:07,309 INFO TaskSetManager: Finished task 15.0 in stage 2.0 (TID 72) in 90 ms on 10.1.2.181 (2/59)
17/01/29 07:03:07,313 INFO TaskSetManager: Starting task 28.0 in stage 2.0 (TID 78, 10.1.2.63, partition 28, PROCESS_LOCAL, 5374 bytes)
17/01/29 07:03:07,313 INFO CoarseGrainedSchedulerBackend$DriverEndpoint: Launching task 78 on executor id: 1 hostname: 10.1.2.63.
17/01/29 07:03:07,314 INFO TaskSetManager: Finished task 6.0 in stage 2.0 (TID 66) in 99 ms on 10.1.2.63 (3/59)
17/01/29 07:03:07,334 INFO BlockManagerInfo: Added broadcast_3_piece0 in memory on 10.1.2.236:34996 (size: 2.2 KB, free: 1071.3 MB)
17/01/29 07:03:07,335 INFO TaskSetManager: Starting task 26.0 in stage 2.0 (TID 79, 10.1.2.181, partition 26, PROCESS_LOCAL, 5374 bytes)
17/01/29 07:03:07,335 INFO CoarseGrainedSchedulerBackend$DriverEndpoint: Launching task 79 on executor id: 3 hostname: 10.1.2.181.
17/01/29 07:03:07,336 INFO TaskSetManager: Finished task 24.0 in stage 2.0 (TID 76) in 56 ms on 10.1.2.181 (4/59)
17/01/29 07:03:07,339 INFO TaskSetManager: Starting task 27.0 in stage 2.0 (TID 80, 10.1.2.181, partition 27, PROCESS_LOCAL, 5374 bytes)
17/01/29 07:03:07,339 INFO CoarseGrainedSchedulerBackend$DriverEndpoint: Launching task 80 on executor id: 3 hostname: 10.1.2.181.
17/01/29 07:03:07,339 INFO TaskSetManager: Finished task 12.0 in stage 2.0 (TID 68) in 123 ms on 10.1.2.181 (5/59)
17/01/29 07:03:07,341 INFO BlockManagerInfo: Added broadcast_3_piece0 in memory on 10.1.2.71:39018 (size: 2.2 KB, free: 998.7 MB)
17/01/29 07:03:07,343 INFO TaskSetManager: Starting task 29.0 in stage 2.0 (TID 81, 10.1.2.63, partition 29, PROCESS_LOCAL, 5374 bytes)
17/01/29 07:03:07,343 INFO CoarseGrainedSchedulerBackend$DriverEndpoint: Launching task 81 on executor id: 1 hostname: 10.1.2.63.
17/01/29 07:03:07,343 INFO TaskSetManager: Finished task 28.0 in stage 2.0 (TID 78) in 30 ms on 10.1.2.63 (6/59)
17/01/29 07:03:07,345 INFO TaskSetManager: Starting task 38.0 in stage 2.0 (TID 82, 10.1.2.181, partition 38, PROCESS_LOCAL, 5374 bytes)
17/01/29 07:03:07,345 INFO CoarseGrainedSchedulerBackend$DriverEndpoint: Launching task 82 on executor id: 3 hostname: 10.1.2.181.
17/01/29 07:03:07,345 INFO TaskSetManager: Finished task 25.0 in stage 2.0 (TID 77) in 37 ms on 10.1.2.181 (7/59)
17/01/29 07:03:07,363 INFO TaskSetManager: Starting task 39.0 in stage 2.0 (TID 83, 10.1.2.181, partition 39, PROCESS_LOCAL, 5374 bytes)
17/01/29 07:03:07,363 INFO CoarseGrainedSchedulerBackend$DriverEndpoint: Launching task 83 on executor id: 3 hostname: 10.1.2.181.
17/01/29 07:03:07,364 INFO TaskSetManager: Finished task 27.0 in stage 2.0 (TID 80) in 26 ms on 10.1.2.181 (8/59)
17/01/29 07:03:07,365 INFO TaskSetManager: Starting task 40.0 in stage 2.0 (TID 84, 10.1.2.181, partition 40, PROCESS_LOCAL, 5374 bytes)
17/01/29 07:03:07,366 INFO CoarseGrainedSchedulerBackend$DriverEndpoint: Launching task 84 on executor id: 3 hostname: 10.1.2.181.
17/01/29 07:03:07,366 INFO TaskSetManager: Finished task 26.0 in stage 2.0 (TID 79) in 31 ms on 10.1.2.181 (9/59)
17/01/29 07:03:07,370 INFO TaskSetManager: Starting task 14.0 in stage 2.0 (TID 85, 10.1.2.236, partition 14, PROCESS_LOCAL, 5374 bytes)
17/01/29 07:03:07,370 INFO CoarseGrainedSchedulerBackend$DriverEndpoint: Launching task 85 on executor id: 0 hostname: 10.1.2.236.
17/01/29 07:03:07,370 INFO TaskSetManager: Finished task 11.0 in stage 2.0 (TID 73) in 150 ms on 10.1.2.236 (10/59)
17/01/29 07:03:07,371 INFO TaskSetManager: Starting task 20.0 in stage 2.0 (TID 86, 10.1.2.236, partition 20, PROCESS_LOCAL, 5374 bytes)
17/01/29 07:03:07,372 INFO CoarseGrainedSchedulerBackend$DriverEndpoint: Launching task 86 on executor id: 0 hostname: 10.1.2.236.
17/01/29 07:03:07,372 INFO TaskSetManager: Starting task 41.0 in stage 2.0 (TID 87, 10.1.2.181, partition 41, PROCESS_LOCAL, 5374 bytes)
17/01/29 07:03:07,373 INFO CoarseGrainedSchedulerBackend$DriverEndpoint: Launching task 87 on executor id: 3 hostname: 10.1.2.181.
17/01/29 07:03:07,373 INFO TaskSetManager: Finished task 38.0 in stage 2.0 (TID 82) in 28 ms on 10.1.2.181 (11/59)
17/01/29 07:03:07,373 INFO TaskSetManager: Finished task 3.0 in stage 2.0 (TID 65) in 159 ms on 10.1.2.236 (12/59)
17/01/29 07:03:07,374 INFO TaskSetManager: Starting task 30.0 in stage 2.0 (TID 88, 10.1.2.63, partition 30, PROCESS_LOCAL, 5374 bytes)
17/01/29 07:03:07,374 INFO CoarseGrainedSchedulerBackend$DriverEndpoint: Launching task 88 on executor id: 1 hostname: 10.1.2.63.
17/01/29 07:03:07,374 INFO TaskSetManager: Finished task 29.0 in stage 2.0 (TID 81) in 32 ms on 10.1.2.63 (13/59)
17/01/29 07:03:07,380 INFO TaskSetManager: Starting task 21.0 in stage 2.0 (TID 89, 10.1.2.236, partition 21, PROCESS_LOCAL, 5374 bytes)
17/01/29 07:03:07,380 INFO CoarseGrainedSchedulerBackend$DriverEndpoint: Launching task 89 on executor id: 0 hostname: 10.1.2.236.
17/01/29 07:03:07,380 INFO TaskSetManager: Finished task 0.0 in stage 2.0 (TID 61) in 169 ms on 10.1.2.236 (14/59)
17/01/29 07:03:07,383 INFO TaskSetManager: Starting task 17.0 in stage 2.0 (TID 90, 10.1.2.71, partition 17, PROCESS_LOCAL, 5374 bytes)
17/01/29 07:03:07,383 INFO CoarseGrainedSchedulerBackend$DriverEndpoint: Launching task 90 on executor id: 2 hostname: 10.1.2.71.
17/01/29 07:03:07,383 INFO TaskSetManager: Finished task 9.0 in stage 2.0 (TID 71) in 165 ms on 10.1.2.71 (15/59)
17/01/29 07:03:07,389 INFO TaskSetManager: Starting task 18.0 in stage 2.0 (TID 91, 10.1.2.71, partition 18, PROCESS_LOCAL, 5374 bytes)
17/01/29 07:03:07,389 INFO CoarseGrainedSchedulerBackend$DriverEndpoint: Launching task 91 on executor id: 2 hostname: 10.1.2.71.
17/01/29 07:03:07,389 INFO TaskSetManager: Finished task 16.0 in stage 2.0 (TID 75) in 167 ms on 10.1.2.71 (16/59)
17/01/29 07:03:07,390 INFO TaskSetManager: Starting task 22.0 in stage 2.0 (TID 92, 10.1.2.236, partition 22, PROCESS_LOCAL, 5374 bytes)
17/01/29 07:03:07,390 INFO CoarseGrainedSchedulerBackend$DriverEndpoint: Launching task 92 on executor id: 0 hostname: 10.1.2.236.
17/01/29 07:03:07,390 INFO TaskSetManager: Finished task 7.0 in stage 2.0 (TID 69) in 173 ms on 10.1.2.236 (17/59)
17/01/29 07:03:07,395 INFO TaskSetManager: Starting task 23.0 in stage 2.0 (TID 93, 10.1.2.236, partition 23, PROCESS_LOCAL, 5374 bytes)
17/01/29 07:03:07,396 INFO CoarseGrainedSchedulerBackend$DriverEndpoint: Launching task 93 on executor id: 0 hostname: 10.1.2.236.
17/01/29 07:03:07,396 INFO TaskSetManager: Finished task 14.0 in stage 2.0 (TID 85) in 27 ms on 10.1.2.236 (18/59)
17/01/29 07:03:07,398 INFO TaskSetManager: Starting task 52.0 in stage 2.0 (TID 94, 10.1.2.181, partition 52, PROCESS_LOCAL, 5374 bytes)
17/01/29 07:03:07,398 INFO CoarseGrainedSchedulerBackend$DriverEndpoint: Launching task 94 on executor id: 3 hostname: 10.1.2.181.
17/01/29 07:03:07,398 INFO TaskSetManager: Finished task 40.0 in stage 2.0 (TID 84) in 33 ms on 10.1.2.181 (19/59)
17/01/29 07:03:07,401 INFO TaskSetManager: Starting task 31.0 in stage 2.0 (TID 95, 10.1.2.63, partition 31, PROCESS_LOCAL, 5374 bytes)
17/01/29 07:03:07,401 INFO CoarseGrainedSchedulerBackend$DriverEndpoint: Launching task 95 on executor id: 1 hostname: 10.1.2.63.
17/01/29 07:03:07,402 INFO TaskSetManager: Finished task 30.0 in stage 2.0 (TID 88) in 28 ms on 10.1.2.63 (20/59)
17/01/29 07:03:07,403 INFO TaskSetManager: Starting task 42.0 in stage 2.0 (TID 96, 10.1.2.63, partition 42, PROCESS_LOCAL, 5374 bytes)
17/01/29 07:03:07,403 INFO CoarseGrainedSchedulerBackend$DriverEndpoint: Launching task 96 on executor id: 1 hostname: 10.1.2.63.
17/01/29 07:03:07,403 INFO TaskSetManager: Finished task 13.0 in stage 2.0 (TID 74) in 182 ms on 10.1.2.63 (21/59)
17/01/29 07:03:07,404 INFO TaskSetManager: Starting task 53.0 in stage 2.0 (TID 97, 10.1.2.181, partition 53, PROCESS_LOCAL, 5374 bytes)
17/01/29 07:03:07,404 INFO CoarseGrainedSchedulerBackend$DriverEndpoint: Launching task 97 on executor id: 3 hostname: 10.1.2.181.
17/01/29 07:03:07,405 INFO TaskSetManager: Finished task 39.0 in stage 2.0 (TID 83) in 42 ms on 10.1.2.181 (22/59)
17/01/29 07:03:07,408 INFO TaskSetManager: Starting task 36.0 in stage 2.0 (TID 98, 10.1.2.236, partition 36, PROCESS_LOCAL, 5374 bytes)
17/01/29 07:03:07,409 INFO CoarseGrainedSchedulerBackend$DriverEndpoint: Launching task 98 on executor id: 0 hostname: 10.1.2.236.
17/01/29 07:03:07,409 INFO TaskSetManager: Finished task 20.0 in stage 2.0 (TID 86) in 38 ms on 10.1.2.236 (23/59)
17/01/29 07:03:07,413 INFO TaskSetManager: Starting task 55.0 in stage 2.0 (TID 99, 10.1.2.181, partition 55, PROCESS_LOCAL, 5374 bytes)
17/01/29 07:03:07,414 INFO CoarseGrainedSchedulerBackend$DriverEndpoint: Launching task 99 on executor id: 3 hostname: 10.1.2.181.
17/01/29 07:03:07,414 INFO TaskSetManager: Finished task 41.0 in stage 2.0 (TID 87) in 42 ms on 10.1.2.181 (24/59)
17/01/29 07:03:07,417 INFO TaskSetManager: Starting task 19.0 in stage 2.0 (TID 100, 10.1.2.71, partition 19, PROCESS_LOCAL, 5374 bytes)
17/01/29 07:03:07,417 INFO CoarseGrainedSchedulerBackend$DriverEndpoint: Launching task 100 on executor id: 2 hostname: 10.1.2.71.
17/01/29 07:03:07,417 INFO TaskSetManager: Finished task 17.0 in stage 2.0 (TID 90) in 35 ms on 10.1.2.71 (25/59)
17/01/29 07:03:07,420 INFO TaskSetManager: Starting task 37.0 in stage 2.0 (TID 101, 10.1.2.236, partition 37, PROCESS_LOCAL, 5374 bytes)
17/01/29 07:03:07,420 INFO CoarseGrainedSchedulerBackend$DriverEndpoint: Launching task 101 on executor id: 0 hostname: 10.1.2.236.
17/01/29 07:03:07,421 INFO TaskSetManager: Finished task 21.0 in stage 2.0 (TID 89) in 41 ms on 10.1.2.236 (26/59)
17/01/29 07:03:07,423 INFO TaskSetManager: Starting task 44.0 in stage 2.0 (TID 102, 10.1.2.236, partition 44, PROCESS_LOCAL, 5374 bytes)
17/01/29 07:03:07,424 INFO CoarseGrainedSchedulerBackend$DriverEndpoint: Launching task 102 on executor id: 0 hostname: 10.1.2.236.
17/01/29 07:03:07,424 INFO TaskSetManager: Finished task 23.0 in stage 2.0 (TID 93) in 29 ms on 10.1.2.236 (27/59)
17/01/29 07:03:07,425 INFO TaskSetManager: Finished task 22.0 in stage 2.0 (TID 92) in 36 ms on 10.1.2.236 (28/59)
17/01/29 07:03:07,425 INFO TaskSetManager: Starting task 46.0 in stage 2.0 (TID 103, 10.1.2.236, partition 46, PROCESS_LOCAL, 5374 bytes)
17/01/29 07:03:07,426 INFO CoarseGrainedSchedulerBackend$DriverEndpoint: Launching task 103 on executor id: 0 hostname: 10.1.2.236.
17/01/29 07:03:07,429 INFO TaskSetManager: Starting task 32.0 in stage 2.0 (TID 104, 10.1.2.71, partition 32, PROCESS_LOCAL, 5374 bytes)
17/01/29 07:03:07,429 INFO CoarseGrainedSchedulerBackend$DriverEndpoint: Launching task 104 on executor id: 2 hostname: 10.1.2.71.
17/01/29 07:03:07,429 INFO TaskSetManager: Finished task 18.0 in stage 2.0 (TID 91) in 41 ms on 10.1.2.71 (29/59)
17/01/29 07:03:07,431 INFO TaskSetManager: Starting task 43.0 in stage 2.0 (TID 105, 10.1.2.63, partition 43, PROCESS_LOCAL, 5374 bytes)
17/01/29 07:03:07,431 INFO CoarseGrainedSchedulerBackend$DriverEndpoint: Launching task 105 on executor id: 1 hostname: 10.1.2.63.
17/01/29 07:03:07,431 INFO TaskSetManager: Finished task 42.0 in stage 2.0 (TID 96) in 29 ms on 10.1.2.63 (30/59)
17/01/29 07:03:07,432 INFO TaskSetManager: Starting task 45.0 in stage 2.0 (TID 106, 10.1.2.63, partition 45, PROCESS_LOCAL, 5374 bytes)
17/01/29 07:03:07,432 INFO CoarseGrainedSchedulerBackend$DriverEndpoint: Launching task 106 on executor id: 1 hostname: 10.1.2.63.
17/01/29 07:03:07,432 INFO TaskSetManager: Finished task 31.0 in stage 2.0 (TID 95) in 31 ms on 10.1.2.63 (31/59)
17/01/29 07:03:07,439 INFO TaskSetManager: Starting task 56.0 in stage 2.0 (TID 107, 10.1.2.181, partition 56, PROCESS_LOCAL, 5374 bytes)
17/01/29 07:03:07,439 INFO CoarseGrainedSchedulerBackend$DriverEndpoint: Launching task 107 on executor id: 3 hostname: 10.1.2.181.
17/01/29 07:03:07,439 INFO TaskSetManager: Finished task 52.0 in stage 2.0 (TID 94) in 42 ms on 10.1.2.181 (32/59)
17/01/29 07:03:07,440 INFO TaskSetManager: Finished task 55.0 in stage 2.0 (TID 99) in 27 ms on 10.1.2.181 (33/59)
17/01/29 07:03:07,441 INFO TaskSetManager: Finished task 53.0 in stage 2.0 (TID 97) in 36 ms on 10.1.2.181 (34/59)
17/01/29 07:03:07,442 INFO TaskSetManager: Starting task 33.0 in stage 2.0 (TID 108, 10.1.2.71, partition 33, PROCESS_LOCAL, 5374 bytes)
17/01/29 07:03:07,442 INFO CoarseGrainedSchedulerBackend$DriverEndpoint: Launching task 108 on executor id: 2 hostname: 10.1.2.71.
17/01/29 07:03:07,442 INFO TaskSetManager: Finished task 19.0 in stage 2.0 (TID 100) in 26 ms on 10.1.2.71 (35/59)
17/01/29 07:03:07,448 INFO TaskSetManager: Starting task 54.0 in stage 2.0 (TID 109, 10.1.2.236, partition 54, PROCESS_LOCAL, 5374 bytes)
17/01/29 07:03:07,448 INFO CoarseGrainedSchedulerBackend$DriverEndpoint: Launching task 109 on executor id: 0 hostname: 10.1.2.236.
17/01/29 07:03:07,448 INFO TaskSetManager: Finished task 44.0 in stage 2.0 (TID 102) in 25 ms on 10.1.2.236 (36/59)
17/01/29 07:03:07,449 INFO TaskSetManager: Starting task 57.0 in stage 2.0 (TID 110, 10.1.2.236, partition 57, PROCESS_LOCAL, 5374 bytes)
17/01/29 07:03:07,449 INFO CoarseGrainedSchedulerBackend$DriverEndpoint: Launching task 110 on executor id: 0 hostname: 10.1.2.236.
17/01/29 07:03:07,450 INFO TaskSetManager: Finished task 36.0 in stage 2.0 (TID 98) in 41 ms on 10.1.2.236 (37/59)
17/01/29 07:03:07,454 INFO TaskSetManager: Starting task 34.0 in stage 2.0 (TID 111, 10.1.2.71, partition 34, PROCESS_LOCAL, 5374 bytes)
17/01/29 07:03:07,455 INFO CoarseGrainedSchedulerBackend$DriverEndpoint: Launching task 111 on executor id: 2 hostname: 10.1.2.71.
17/01/29 07:03:07,455 INFO TaskSetManager: Finished task 32.0 in stage 2.0 (TID 104) in 27 ms on 10.1.2.71 (38/59)
17/01/29 07:03:07,459 INFO TaskSetManager: Finished task 46.0 in stage 2.0 (TID 103) in 33 ms on 10.1.2.236 (39/59)
17/01/29 07:03:07,460 INFO TaskSetManager: Finished task 43.0 in stage 2.0 (TID 105) in 29 ms on 10.1.2.63 (40/59)
17/01/29 07:03:07,462 INFO TaskSetManager: Starting task 47.0 in stage 2.0 (TID 112, 10.1.2.63, partition 47, PROCESS_LOCAL, 5374 bytes)
17/01/29 07:03:07,462 INFO CoarseGrainedSchedulerBackend$DriverEndpoint: Launching task 112 on executor id: 1 hostname: 10.1.2.63.
17/01/29 07:03:07,463 INFO TaskSetManager: Finished task 45.0 in stage 2.0 (TID 106) in 32 ms on 10.1.2.63 (41/59)
17/01/29 07:03:07,464 INFO TaskSetManager: Finished task 56.0 in stage 2.0 (TID 107) in 25 ms on 10.1.2.181 (42/59)
17/01/29 07:03:07,464 INFO TaskSetManager: Finished task 37.0 in stage 2.0 (TID 101) in 45 ms on 10.1.2.236 (43/59)
17/01/29 07:03:07,471 INFO TaskSetManager: Finished task 57.0 in stage 2.0 (TID 110) in 22 ms on 10.1.2.236 (44/59)
17/01/29 07:03:07,475 INFO TaskSetManager: Finished task 54.0 in stage 2.0 (TID 109) in 28 ms on 10.1.2.236 (45/59)
17/01/29 07:03:07,478 INFO TaskSetManager: Starting task 35.0 in stage 2.0 (TID 113, 10.1.2.71, partition 35, PROCESS_LOCAL, 5374 bytes)
17/01/29 07:03:07,478 INFO CoarseGrainedSchedulerBackend$DriverEndpoint: Launching task 113 on executor id: 2 hostname: 10.1.2.71.
17/01/29 07:03:07,479 INFO TaskSetManager: Starting task 48.0 in stage 2.0 (TID 114, 10.1.2.71, partition 48, PROCESS_LOCAL, 5374 bytes)
17/01/29 07:03:07,479 INFO CoarseGrainedSchedulerBackend$DriverEndpoint: Launching task 114 on executor id: 2 hostname: 10.1.2.71.
17/01/29 07:03:07,479 INFO TaskSetManager: Finished task 33.0 in stage 2.0 (TID 108) in 38 ms on 10.1.2.71 (46/59)
17/01/29 07:03:07,479 INFO TaskSetManager: Finished task 5.0 in stage 2.0 (TID 67) in 264 ms on 10.1.2.71 (47/59)
17/01/29 07:03:07,481 INFO TaskSetManager: Finished task 34.0 in stage 2.0 (TID 111) in 27 ms on 10.1.2.71 (48/59)
17/01/29 07:03:07,482 INFO TaskSetManager: Starting task 49.0 in stage 2.0 (TID 115, 10.1.2.71, partition 49, PROCESS_LOCAL, 5374 bytes)
17/01/29 07:03:07,482 INFO CoarseGrainedSchedulerBackend$DriverEndpoint: Launching task 115 on executor id: 2 hostname: 10.1.2.71.
17/01/29 07:03:07,492 INFO TaskSetManager: Finished task 47.0 in stage 2.0 (TID 112) in 31 ms on 10.1.2.63 (49/59)
17/01/29 07:03:07,493 INFO TaskSetManager: Finished task 8.0 in stage 2.0 (TID 64) in 280 ms on 10.1.2.181 (50/59)
17/01/29 07:03:07,506 INFO TaskSetManager: Starting task 50.0 in stage 2.0 (TID 116, 10.1.2.71, partition 50, PROCESS_LOCAL, 5374 bytes)
17/01/29 07:03:07,506 INFO CoarseGrainedSchedulerBackend$DriverEndpoint: Launching task 116 on executor id: 2 hostname: 10.1.2.71.
17/01/29 07:03:07,507 INFO TaskSetManager: Finished task 48.0 in stage 2.0 (TID 114) in 28 ms on 10.1.2.71 (51/59)
17/01/29 07:03:07,510 INFO TaskSetManager: Starting task 51.0 in stage 2.0 (TID 117, 10.1.2.71, partition 51, PROCESS_LOCAL, 5374 bytes)
17/01/29 07:03:07,510 INFO CoarseGrainedSchedulerBackend$DriverEndpoint: Launching task 117 on executor id: 2 hostname: 10.1.2.71.
17/01/29 07:03:07,511 INFO TaskSetManager: Finished task 35.0 in stage 2.0 (TID 113) in 33 ms on 10.1.2.71 (52/59)
17/01/29 07:03:07,514 INFO TaskSetManager: Finished task 2.0 in stage 2.0 (TID 62) in 303 ms on 10.1.2.63 (53/59)
17/01/29 07:03:07,536 INFO TaskSetManager: Finished task 50.0 in stage 2.0 (TID 116) in 31 ms on 10.1.2.71 (54/59)
17/01/29 07:03:07,537 INFO TaskSetManager: Starting task 58.0 in stage 2.0 (TID 118, 10.1.2.71, partition 58, PROCESS_LOCAL, 5374 bytes)
17/01/29 07:03:07,537 INFO CoarseGrainedSchedulerBackend$DriverEndpoint: Launching task 118 on executor id: 2 hostname: 10.1.2.71.
17/01/29 07:03:07,538 INFO TaskSetManager: Finished task 49.0 in stage 2.0 (TID 115) in 57 ms on 10.1.2.71 (55/59)
17/01/29 07:03:07,548 INFO TaskSetManager: Finished task 51.0 in stage 2.0 (TID 117) in 38 ms on 10.1.2.71 (56/59)
17/01/29 07:03:07,560 INFO TaskSetManager: Finished task 58.0 in stage 2.0 (TID 118) in 24 ms on 10.1.2.71 (57/59)
17/01/29 07:03:07,562 INFO TaskSetManager: Finished task 1.0 in stage 2.0 (TID 63) in 349 ms on 10.1.2.71 (58/59)
17/01/29 07:03:07,572 INFO TaskSetManager: Finished task 10.0 in stage 2.0 (TID 70) in 355 ms on 10.1.2.63 (59/59)
17/01/29 07:03:07,573 INFO TaskSchedulerImpl: Removed TaskSet 2.0, whose tasks have all completed, from pool 
17/01/29 07:03:07,573 INFO DAGScheduler: ResultStage 2 (count at GradientDescent.scala:209) finished in 0.364 s
17/01/29 07:03:07,573 INFO DAGScheduler: Job 2 finished: count at GradientDescent.scala:209, took 0.381353 s
17/01/29 07:03:07,813 WARN BLAS: Failed to load implementation from: com.github.fommil.netlib.NativeSystemBLAS
17/01/29 07:03:07,814 WARN BLAS: Failed to load implementation from: com.github.fommil.netlib.NativeRefBLAS
17/01/29 07:03:07,836 INFO MemoryStore: Block broadcast_4 stored as values in memory (estimated size 280.0 B, free 2.1 GB)
17/01/29 07:03:07,839 INFO MemoryStore: Block broadcast_4_piece0 stored as bytes in memory (estimated size 153.0 B, free 2.1 GB)
17/01/29 07:03:07,840 INFO BlockManagerInfo: Added broadcast_4_piece0 in memory on 10.1.2.142:38331 (size: 153.0 B, free: 2.1 GB)
17/01/29 07:03:07,841 INFO SparkContext: Created broadcast 4 from broadcast at GradientDescent.scala:235
17/01/29 07:03:07,891 INFO SparkContext: Starting job: treeAggregate at GradientDescent.scala:239
17/01/29 07:03:07,896 INFO DAGScheduler: Registering RDD 11 (treeAggregate at GradientDescent.scala:239)
17/01/29 07:03:07,897 INFO DAGScheduler: Got job 3 (treeAggregate at GradientDescent.scala:239) with 7 output partitions
17/01/29 07:03:07,897 INFO DAGScheduler: Final stage: ResultStage 4 (treeAggregate at GradientDescent.scala:239)
17/01/29 07:03:07,897 INFO DAGScheduler: Parents of final stage: List(ShuffleMapStage 3)
17/01/29 07:03:07,898 INFO DAGScheduler: Missing parents: List(ShuffleMapStage 3)
17/01/29 07:03:07,903 INFO DAGScheduler: Submitting ShuffleMapStage 3 (MapPartitionsRDD[11] at treeAggregate at GradientDescent.scala:239), which has no missing parents
17/01/29 07:03:07,920 INFO MemoryStore: Block broadcast_5 stored as values in memory (estimated size 7.2 KB, free 2.1 GB)
17/01/29 07:03:07,921 INFO MemoryStore: Block broadcast_5_piece0 stored as bytes in memory (estimated size 3.7 KB, free 2.1 GB)
17/01/29 07:03:07,922 INFO BlockManagerInfo: Added broadcast_5_piece0 in memory on 10.1.2.142:38331 (size: 3.7 KB, free: 2.1 GB)
17/01/29 07:03:07,923 INFO SparkContext: Created broadcast 5 from broadcast at DAGScheduler.scala:1012
17/01/29 07:03:07,925 INFO DAGScheduler: Submitting 59 missing tasks from ShuffleMapStage 3 (MapPartitionsRDD[11] at treeAggregate at GradientDescent.scala:239)
17/01/29 07:03:07,926 INFO TaskSchedulerImpl: Adding task set 3.0 with 59 tasks
17/01/29 07:03:07,929 INFO TaskSetManager: Starting task 1.0 in stage 3.0 (TID 119, 10.1.2.71, partition 1, PROCESS_LOCAL, 5563 bytes)
17/01/29 07:03:07,929 INFO TaskSetManager: Starting task 0.0 in stage 3.0 (TID 120, 10.1.2.236, partition 0, PROCESS_LOCAL, 5563 bytes)
17/01/29 07:03:07,930 INFO TaskSetManager: Starting task 2.0 in stage 3.0 (TID 121, 10.1.2.63, partition 2, PROCESS_LOCAL, 5563 bytes)
17/01/29 07:03:07,930 INFO TaskSetManager: Starting task 4.0 in stage 3.0 (TID 122, 10.1.2.181, partition 4, PROCESS_LOCAL, 5563 bytes)
17/01/29 07:03:07,931 INFO TaskSetManager: Starting task 5.0 in stage 3.0 (TID 123, 10.1.2.71, partition 5, PROCESS_LOCAL, 5563 bytes)
17/01/29 07:03:07,931 INFO TaskSetManager: Starting task 3.0 in stage 3.0 (TID 124, 10.1.2.236, partition 3, PROCESS_LOCAL, 5563 bytes)
17/01/29 07:03:07,932 INFO TaskSetManager: Starting task 6.0 in stage 3.0 (TID 125, 10.1.2.63, partition 6, PROCESS_LOCAL, 5563 bytes)
17/01/29 07:03:07,933 INFO TaskSetManager: Starting task 8.0 in stage 3.0 (TID 126, 10.1.2.181, partition 8, PROCESS_LOCAL, 5563 bytes)
17/01/29 07:03:07,933 INFO TaskSetManager: Starting task 9.0 in stage 3.0 (TID 127, 10.1.2.71, partition 9, PROCESS_LOCAL, 5563 bytes)
17/01/29 07:03:07,933 INFO TaskSetManager: Starting task 7.0 in stage 3.0 (TID 128, 10.1.2.236, partition 7, PROCESS_LOCAL, 5563 bytes)
17/01/29 07:03:07,934 INFO TaskSetManager: Starting task 10.0 in stage 3.0 (TID 129, 10.1.2.63, partition 10, PROCESS_LOCAL, 5563 bytes)
17/01/29 07:03:07,935 INFO TaskSetManager: Starting task 12.0 in stage 3.0 (TID 130, 10.1.2.181, partition 12, PROCESS_LOCAL, 5563 bytes)
17/01/29 07:03:07,935 INFO TaskSetManager: Starting task 16.0 in stage 3.0 (TID 131, 10.1.2.71, partition 16, PROCESS_LOCAL, 5563 bytes)
17/01/29 07:03:07,936 INFO TaskSetManager: Starting task 11.0 in stage 3.0 (TID 132, 10.1.2.236, partition 11, PROCESS_LOCAL, 5563 bytes)
17/01/29 07:03:07,936 INFO TaskSetManager: Starting task 13.0 in stage 3.0 (TID 133, 10.1.2.63, partition 13, PROCESS_LOCAL, 5563 bytes)
17/01/29 07:03:07,937 INFO TaskSetManager: Starting task 15.0 in stage 3.0 (TID 134, 10.1.2.181, partition 15, PROCESS_LOCAL, 5563 bytes)
17/01/29 07:03:07,937 INFO CoarseGrainedSchedulerBackend$DriverEndpoint: Launching task 119 on executor id: 2 hostname: 10.1.2.71.
17/01/29 07:03:07,938 INFO CoarseGrainedSchedulerBackend$DriverEndpoint: Launching task 123 on executor id: 2 hostname: 10.1.2.71.
17/01/29 07:03:07,938 INFO CoarseGrainedSchedulerBackend$DriverEndpoint: Launching task 127 on executor id: 2 hostname: 10.1.2.71.
17/01/29 07:03:07,939 INFO CoarseGrainedSchedulerBackend$DriverEndpoint: Launching task 131 on executor id: 2 hostname: 10.1.2.71.
17/01/29 07:03:07,939 INFO CoarseGrainedSchedulerBackend$DriverEndpoint: Launching task 120 on executor id: 0 hostname: 10.1.2.236.
17/01/29 07:03:07,940 INFO CoarseGrainedSchedulerBackend$DriverEndpoint: Launching task 124 on executor id: 0 hostname: 10.1.2.236.
17/01/29 07:03:07,941 INFO CoarseGrainedSchedulerBackend$DriverEndpoint: Launching task 128 on executor id: 0 hostname: 10.1.2.236.
17/01/29 07:03:07,941 INFO CoarseGrainedSchedulerBackend$DriverEndpoint: Launching task 132 on executor id: 0 hostname: 10.1.2.236.
17/01/29 07:03:07,945 INFO CoarseGrainedSchedulerBackend$DriverEndpoint: Launching task 121 on executor id: 1 hostname: 10.1.2.63.
17/01/29 07:03:07,946 INFO CoarseGrainedSchedulerBackend$DriverEndpoint: Launching task 125 on executor id: 1 hostname: 10.1.2.63.
17/01/29 07:03:07,946 INFO CoarseGrainedSchedulerBackend$DriverEndpoint: Launching task 129 on executor id: 1 hostname: 10.1.2.63.
17/01/29 07:03:07,948 INFO CoarseGrainedSchedulerBackend$DriverEndpoint: Launching task 133 on executor id: 1 hostname: 10.1.2.63.
17/01/29 07:03:07,949 INFO CoarseGrainedSchedulerBackend$DriverEndpoint: Launching task 122 on executor id: 3 hostname: 10.1.2.181.
17/01/29 07:03:07,949 INFO CoarseGrainedSchedulerBackend$DriverEndpoint: Launching task 126 on executor id: 3 hostname: 10.1.2.181.
17/01/29 07:03:07,950 INFO CoarseGrainedSchedulerBackend$DriverEndpoint: Launching task 130 on executor id: 3 hostname: 10.1.2.181.
17/01/29 07:03:07,950 INFO CoarseGrainedSchedulerBackend$DriverEndpoint: Launching task 134 on executor id: 3 hostname: 10.1.2.181.
17/01/29 07:03:07,957 INFO BlockManagerInfo: Added broadcast_5_piece0 in memory on 10.1.2.71:39018 (size: 3.7 KB, free: 998.7 MB)
17/01/29 07:03:07,966 INFO BlockManagerInfo: Added broadcast_5_piece0 in memory on 10.1.2.236:34996 (size: 3.7 KB, free: 1071.3 MB)
17/01/29 07:03:07,971 INFO BlockManagerInfo: Added broadcast_5_piece0 in memory on 10.1.2.63:45151 (size: 3.7 KB, free: 1281.6 MB)
17/01/29 07:03:08,009 INFO BlockManagerInfo: Added broadcast_5_piece0 in memory on 10.1.2.181:44727 (size: 3.7 KB, free: 1001.4 MB)
17/01/29 07:03:08,262 INFO BlockManagerInfo: Added broadcast_4_piece0 in memory on 10.1.2.71:39018 (size: 153.0 B, free: 998.7 MB)
17/01/29 07:03:08,263 INFO BlockManagerInfo: Added broadcast_4_piece0 in memory on 10.1.2.63:45151 (size: 153.0 B, free: 1281.6 MB)
17/01/29 07:03:08,308 INFO BlockManagerInfo: Added broadcast_4_piece0 in memory on 10.1.2.236:34996 (size: 153.0 B, free: 1071.3 MB)
17/01/29 07:03:08,395 INFO BlockManagerInfo: Added broadcast_4_piece0 in memory on 10.1.2.181:44727 (size: 153.0 B, free: 1001.4 MB)
17/01/29 07:03:08,437 INFO TaskSetManager: Starting task 17.0 in stage 3.0 (TID 135, 10.1.2.71, partition 17, PROCESS_LOCAL, 5563 bytes)
17/01/29 07:03:08,437 INFO CoarseGrainedSchedulerBackend$DriverEndpoint: Launching task 135 on executor id: 2 hostname: 10.1.2.71.
17/01/29 07:03:08,439 INFO TaskSetManager: Finished task 16.0 in stage 3.0 (TID 131) in 504 ms on 10.1.2.71 (1/59)
17/01/29 07:03:08,440 INFO TaskSetManager: Starting task 18.0 in stage 3.0 (TID 136, 10.1.2.71, partition 18, PROCESS_LOCAL, 5563 bytes)
17/01/29 07:03:08,440 INFO CoarseGrainedSchedulerBackend$DriverEndpoint: Launching task 136 on executor id: 2 hostname: 10.1.2.71.
17/01/29 07:03:08,441 INFO TaskSetManager: Finished task 9.0 in stage 3.0 (TID 127) in 507 ms on 10.1.2.71 (2/59)
17/01/29 07:03:08,444 INFO TaskSetManager: Starting task 19.0 in stage 3.0 (TID 137, 10.1.2.71, partition 19, PROCESS_LOCAL, 5563 bytes)
17/01/29 07:03:08,444 INFO CoarseGrainedSchedulerBackend$DriverEndpoint: Launching task 137 on executor id: 2 hostname: 10.1.2.71.
17/01/29 07:03:08,445 INFO TaskSetManager: Starting task 32.0 in stage 3.0 (TID 138, 10.1.2.71, partition 32, PROCESS_LOCAL, 5563 bytes)
17/01/29 07:03:08,445 INFO CoarseGrainedSchedulerBackend$DriverEndpoint: Launching task 138 on executor id: 2 hostname: 10.1.2.71.
17/01/29 07:03:08,446 INFO TaskSetManager: Finished task 5.0 in stage 3.0 (TID 123) in 516 ms on 10.1.2.71 (3/59)
17/01/29 07:03:08,446 INFO TaskSetManager: Finished task 1.0 in stage 3.0 (TID 119) in 519 ms on 10.1.2.71 (4/59)
17/01/29 07:03:08,463 INFO TaskSetManager: Starting task 28.0 in stage 3.0 (TID 139, 10.1.2.63, partition 28, PROCESS_LOCAL, 5563 bytes)
17/01/29 07:03:08,463 INFO CoarseGrainedSchedulerBackend$DriverEndpoint: Launching task 139 on executor id: 1 hostname: 10.1.2.63.
17/01/29 07:03:08,464 INFO TaskSetManager: Finished task 13.0 in stage 3.0 (TID 133) in 528 ms on 10.1.2.63 (5/59)
17/01/29 07:03:08,465 INFO TaskSetManager: Starting task 29.0 in stage 3.0 (TID 140, 10.1.2.63, partition 29, PROCESS_LOCAL, 5563 bytes)
17/01/29 07:03:08,465 INFO CoarseGrainedSchedulerBackend$DriverEndpoint: Launching task 140 on executor id: 1 hostname: 10.1.2.63.
17/01/29 07:03:08,465 INFO TaskSetManager: Finished task 10.0 in stage 3.0 (TID 129) in 531 ms on 10.1.2.63 (6/59)
17/01/29 07:03:08,473 INFO TaskSetManager: Starting task 30.0 in stage 3.0 (TID 141, 10.1.2.63, partition 30, PROCESS_LOCAL, 5563 bytes)
17/01/29 07:03:08,473 INFO CoarseGrainedSchedulerBackend$DriverEndpoint: Launching task 141 on executor id: 1 hostname: 10.1.2.63.
17/01/29 07:03:08,473 INFO TaskSetManager: Finished task 6.0 in stage 3.0 (TID 125) in 541 ms on 10.1.2.63 (7/59)
17/01/29 07:03:08,480 INFO TaskSetManager: Starting task 31.0 in stage 3.0 (TID 142, 10.1.2.63, partition 31, PROCESS_LOCAL, 5563 bytes)
17/01/29 07:03:08,480 INFO CoarseGrainedSchedulerBackend$DriverEndpoint: Launching task 142 on executor id: 1 hostname: 10.1.2.63.
17/01/29 07:03:08,480 INFO TaskSetManager: Finished task 2.0 in stage 3.0 (TID 121) in 550 ms on 10.1.2.63 (8/59)
17/01/29 07:03:08,483 INFO TaskSetManager: Finished task 11.0 in stage 3.0 (TID 132) in 548 ms on 10.1.2.236 (9/59)
17/01/29 07:03:08,485 INFO TaskSetManager: Starting task 14.0 in stage 3.0 (TID 143, 10.1.2.236, partition 14, PROCESS_LOCAL, 5563 bytes)
17/01/29 07:03:08,485 INFO CoarseGrainedSchedulerBackend$DriverEndpoint: Launching task 143 on executor id: 0 hostname: 10.1.2.236.
17/01/29 07:03:08,486 INFO TaskSetManager: Starting task 20.0 in stage 3.0 (TID 144, 10.1.2.236, partition 20, PROCESS_LOCAL, 5563 bytes)
17/01/29 07:03:08,487 INFO CoarseGrainedSchedulerBackend$DriverEndpoint: Launching task 144 on executor id: 0 hostname: 10.1.2.236.
17/01/29 07:03:08,487 INFO TaskSetManager: Finished task 0.0 in stage 3.0 (TID 120) in 558 ms on 10.1.2.236 (10/59)
17/01/29 07:03:08,488 INFO TaskSetManager: Finished task 7.0 in stage 3.0 (TID 128) in 555 ms on 10.1.2.236 (11/59)
17/01/29 07:03:08,489 INFO TaskSetManager: Starting task 21.0 in stage 3.0 (TID 145, 10.1.2.236, partition 21, PROCESS_LOCAL, 5563 bytes)
17/01/29 07:03:08,490 INFO CoarseGrainedSchedulerBackend$DriverEndpoint: Launching task 145 on executor id: 0 hostname: 10.1.2.236.
17/01/29 07:03:08,491 INFO TaskSetManager: Starting task 22.0 in stage 3.0 (TID 146, 10.1.2.236, partition 22, PROCESS_LOCAL, 5563 bytes)
17/01/29 07:03:08,492 INFO CoarseGrainedSchedulerBackend$DriverEndpoint: Launching task 146 on executor id: 0 hostname: 10.1.2.236.
17/01/29 07:03:08,492 INFO TaskSetManager: Finished task 3.0 in stage 3.0 (TID 124) in 561 ms on 10.1.2.236 (12/59)
17/01/29 07:03:08,546 INFO TaskSetManager: Finished task 19.0 in stage 3.0 (TID 137) in 102 ms on 10.1.2.71 (13/59)
17/01/29 07:03:08,547 INFO TaskSetManager: Starting task 33.0 in stage 3.0 (TID 147, 10.1.2.71, partition 33, PROCESS_LOCAL, 5563 bytes)
17/01/29 07:03:08,548 INFO CoarseGrainedSchedulerBackend$DriverEndpoint: Launching task 147 on executor id: 2 hostname: 10.1.2.71.
17/01/29 07:03:08,567 INFO TaskSetManager: Starting task 34.0 in stage 3.0 (TID 148, 10.1.2.71, partition 34, PROCESS_LOCAL, 5563 bytes)
17/01/29 07:03:08,567 INFO CoarseGrainedSchedulerBackend$DriverEndpoint: Launching task 148 on executor id: 2 hostname: 10.1.2.71.
17/01/29 07:03:08,568 INFO TaskSetManager: Finished task 32.0 in stage 3.0 (TID 138) in 124 ms on 10.1.2.71 (14/59)
17/01/29 07:03:08,578 INFO TaskSetManager: Starting task 35.0 in stage 3.0 (TID 149, 10.1.2.71, partition 35, PROCESS_LOCAL, 5563 bytes)
17/01/29 07:03:08,579 INFO CoarseGrainedSchedulerBackend$DriverEndpoint: Launching task 149 on executor id: 2 hostname: 10.1.2.71.
17/01/29 07:03:08,580 INFO TaskSetManager: Starting task 23.0 in stage 3.0 (TID 150, 10.1.2.236, partition 23, PROCESS_LOCAL, 5563 bytes)
17/01/29 07:03:08,580 INFO CoarseGrainedSchedulerBackend$DriverEndpoint: Launching task 150 on executor id: 0 hostname: 10.1.2.236.
17/01/29 07:03:08,580 INFO TaskSetManager: Finished task 17.0 in stage 3.0 (TID 135) in 144 ms on 10.1.2.71 (15/59)
17/01/29 07:03:08,581 INFO TaskSetManager: Starting task 48.0 in stage 3.0 (TID 151, 10.1.2.71, partition 48, PROCESS_LOCAL, 5563 bytes)
17/01/29 07:03:08,581 INFO CoarseGrainedSchedulerBackend$DriverEndpoint: Launching task 151 on executor id: 2 hostname: 10.1.2.71.
17/01/29 07:03:08,582 INFO TaskSetManager: Finished task 18.0 in stage 3.0 (TID 136) in 142 ms on 10.1.2.71 (16/59)
17/01/29 07:03:08,582 INFO TaskSetManager: Finished task 20.0 in stage 3.0 (TID 144) in 96 ms on 10.1.2.236 (17/59)
17/01/29 07:03:08,585 INFO TaskSetManager: Starting task 36.0 in stage 3.0 (TID 152, 10.1.2.236, partition 36, PROCESS_LOCAL, 5563 bytes)
17/01/29 07:03:08,585 INFO CoarseGrainedSchedulerBackend$DriverEndpoint: Launching task 152 on executor id: 0 hostname: 10.1.2.236.
17/01/29 07:03:08,586 INFO TaskSetManager: Finished task 21.0 in stage 3.0 (TID 145) in 97 ms on 10.1.2.236 (18/59)
17/01/29 07:03:08,588 INFO TaskSetManager: Starting task 24.0 in stage 3.0 (TID 153, 10.1.2.181, partition 24, PROCESS_LOCAL, 5563 bytes)
17/01/29 07:03:08,589 INFO CoarseGrainedSchedulerBackend$DriverEndpoint: Launching task 153 on executor id: 3 hostname: 10.1.2.181.
17/01/29 07:03:08,589 INFO TaskSetManager: Finished task 12.0 in stage 3.0 (TID 130) in 655 ms on 10.1.2.181 (19/59)
17/01/29 07:03:08,591 INFO TaskSetManager: Starting task 25.0 in stage 3.0 (TID 154, 10.1.2.181, partition 25, PROCESS_LOCAL, 5563 bytes)
17/01/29 07:03:08,591 INFO CoarseGrainedSchedulerBackend$DriverEndpoint: Launching task 154 on executor id: 3 hostname: 10.1.2.181.
17/01/29 07:03:08,591 INFO TaskSetManager: Finished task 8.0 in stage 3.0 (TID 126) in 659 ms on 10.1.2.181 (20/59)
17/01/29 07:03:08,592 INFO TaskSetManager: Starting task 26.0 in stage 3.0 (TID 155, 10.1.2.181, partition 26, PROCESS_LOCAL, 5563 bytes)
17/01/29 07:03:08,592 INFO CoarseGrainedSchedulerBackend$DriverEndpoint: Launching task 155 on executor id: 3 hostname: 10.1.2.181.
17/01/29 07:03:08,592 INFO TaskSetManager: Finished task 4.0 in stage 3.0 (TID 122) in 662 ms on 10.1.2.181 (21/59)
17/01/29 07:03:08,593 INFO TaskSetManager: Finished task 15.0 in stage 3.0 (TID 134) in 657 ms on 10.1.2.181 (22/59)
17/01/29 07:03:08,594 INFO TaskSetManager: Starting task 27.0 in stage 3.0 (TID 156, 10.1.2.181, partition 27, PROCESS_LOCAL, 5563 bytes)
17/01/29 07:03:08,594 INFO CoarseGrainedSchedulerBackend$DriverEndpoint: Launching task 156 on executor id: 3 hostname: 10.1.2.181.
17/01/29 07:03:08,599 INFO TaskSetManager: Starting task 37.0 in stage 3.0 (TID 157, 10.1.2.236, partition 37, PROCESS_LOCAL, 5563 bytes)
17/01/29 07:03:08,600 INFO CoarseGrainedSchedulerBackend$DriverEndpoint: Launching task 157 on executor id: 0 hostname: 10.1.2.236.
17/01/29 07:03:08,600 INFO TaskSetManager: Finished task 22.0 in stage 3.0 (TID 146) in 110 ms on 10.1.2.236 (23/59)
17/01/29 07:03:08,604 INFO TaskSetManager: Starting task 44.0 in stage 3.0 (TID 158, 10.1.2.236, partition 44, PROCESS_LOCAL, 5563 bytes)
17/01/29 07:03:08,604 INFO CoarseGrainedSchedulerBackend$DriverEndpoint: Launching task 158 on executor id: 0 hostname: 10.1.2.236.
17/01/29 07:03:08,604 INFO TaskSetManager: Finished task 14.0 in stage 3.0 (TID 143) in 120 ms on 10.1.2.236 (24/59)
17/01/29 07:03:08,621 INFO TaskSetManager: Finished task 33.0 in stage 3.0 (TID 147) in 74 ms on 10.1.2.71 (25/59)
17/01/29 07:03:08,623 INFO TaskSetManager: Starting task 49.0 in stage 3.0 (TID 159, 10.1.2.71, partition 49, PROCESS_LOCAL, 5563 bytes)
17/01/29 07:03:08,623 INFO CoarseGrainedSchedulerBackend$DriverEndpoint: Launching task 159 on executor id: 2 hostname: 10.1.2.71.
17/01/29 07:03:08,628 INFO TaskSetManager: Starting task 42.0 in stage 3.0 (TID 160, 10.1.2.63, partition 42, PROCESS_LOCAL, 5563 bytes)
17/01/29 07:03:08,628 INFO CoarseGrainedSchedulerBackend$DriverEndpoint: Launching task 160 on executor id: 1 hostname: 10.1.2.63.
17/01/29 07:03:08,629 INFO TaskSetManager: Finished task 30.0 in stage 3.0 (TID 141) in 157 ms on 10.1.2.63 (26/59)
17/01/29 07:03:08,637 INFO TaskSetManager: Starting task 43.0 in stage 3.0 (TID 161, 10.1.2.63, partition 43, PROCESS_LOCAL, 5563 bytes)
17/01/29 07:03:08,637 INFO CoarseGrainedSchedulerBackend$DriverEndpoint: Launching task 161 on executor id: 1 hostname: 10.1.2.63.
17/01/29 07:03:08,638 INFO TaskSetManager: Finished task 28.0 in stage 3.0 (TID 139) in 174 ms on 10.1.2.63 (27/59)
17/01/29 07:03:08,644 INFO TaskSetManager: Starting task 46.0 in stage 3.0 (TID 162, 10.1.2.236, partition 46, PROCESS_LOCAL, 5563 bytes)
17/01/29 07:03:08,645 INFO CoarseGrainedSchedulerBackend$DriverEndpoint: Launching task 162 on executor id: 0 hostname: 10.1.2.236.
17/01/29 07:03:08,645 INFO TaskSetManager: Finished task 23.0 in stage 3.0 (TID 150) in 66 ms on 10.1.2.236 (28/59)
17/01/29 07:03:08,651 INFO TaskSetManager: Starting task 54.0 in stage 3.0 (TID 163, 10.1.2.236, partition 54, PROCESS_LOCAL, 5563 bytes)
17/01/29 07:03:08,652 INFO CoarseGrainedSchedulerBackend$DriverEndpoint: Launching task 163 on executor id: 0 hostname: 10.1.2.236.
17/01/29 07:03:08,652 INFO TaskSetManager: Finished task 36.0 in stage 3.0 (TID 152) in 67 ms on 10.1.2.236 (29/59)
17/01/29 07:03:08,658 INFO TaskSetManager: Starting task 45.0 in stage 3.0 (TID 164, 10.1.2.63, partition 45, PROCESS_LOCAL, 5563 bytes)
17/01/29 07:03:08,658 INFO CoarseGrainedSchedulerBackend$DriverEndpoint: Launching task 164 on executor id: 1 hostname: 10.1.2.63.
17/01/29 07:03:08,659 INFO TaskSetManager: Finished task 29.0 in stage 3.0 (TID 140) in 195 ms on 10.1.2.63 (30/59)
17/01/29 07:03:08,672 INFO TaskSetManager: Starting task 57.0 in stage 3.0 (TID 165, 10.1.2.236, partition 57, PROCESS_LOCAL, 5563 bytes)
17/01/29 07:03:08,673 INFO CoarseGrainedSchedulerBackend$DriverEndpoint: Launching task 165 on executor id: 0 hostname: 10.1.2.236.
17/01/29 07:03:08,673 INFO TaskSetManager: Finished task 44.0 in stage 3.0 (TID 158) in 70 ms on 10.1.2.236 (31/59)
17/01/29 07:03:08,681 INFO TaskSetManager: Starting task 50.0 in stage 3.0 (TID 166, 10.1.2.71, partition 50, PROCESS_LOCAL, 5563 bytes)
17/01/29 07:03:08,682 INFO CoarseGrainedSchedulerBackend$DriverEndpoint: Launching task 166 on executor id: 2 hostname: 10.1.2.71.
17/01/29 07:03:08,682 INFO TaskSetManager: Finished task 34.0 in stage 3.0 (TID 148) in 116 ms on 10.1.2.71 (32/59)
17/01/29 07:03:08,688 INFO TaskSetManager: Starting task 47.0 in stage 3.0 (TID 167, 10.1.2.63, partition 47, PROCESS_LOCAL, 5563 bytes)
17/01/29 07:03:08,688 INFO CoarseGrainedSchedulerBackend$DriverEndpoint: Launching task 167 on executor id: 1 hostname: 10.1.2.63.
17/01/29 07:03:08,689 INFO TaskSetManager: Finished task 31.0 in stage 3.0 (TID 142) in 210 ms on 10.1.2.63 (33/59)
17/01/29 07:03:08,693 INFO TaskSetManager: Finished task 37.0 in stage 3.0 (TID 157) in 93 ms on 10.1.2.236 (34/59)
17/01/29 07:03:08,699 INFO TaskSetManager: Starting task 51.0 in stage 3.0 (TID 168, 10.1.2.71, partition 51, PROCESS_LOCAL, 5563 bytes)
17/01/29 07:03:08,700 INFO CoarseGrainedSchedulerBackend$DriverEndpoint: Launching task 168 on executor id: 2 hostname: 10.1.2.71.
17/01/29 07:03:08,700 INFO TaskSetManager: Finished task 48.0 in stage 3.0 (TID 151) in 119 ms on 10.1.2.71 (35/59)
17/01/29 07:03:08,703 INFO TaskSetManager: Starting task 38.0 in stage 3.0 (TID 169, 10.1.2.181, partition 38, PROCESS_LOCAL, 5563 bytes)
17/01/29 07:03:08,703 INFO CoarseGrainedSchedulerBackend$DriverEndpoint: Launching task 169 on executor id: 3 hostname: 10.1.2.181.
17/01/29 07:03:08,703 INFO TaskSetManager: Finished task 24.0 in stage 3.0 (TID 153) in 115 ms on 10.1.2.181 (36/59)
17/01/29 07:03:08,708 INFO TaskSetManager: Starting task 39.0 in stage 3.0 (TID 170, 10.1.2.181, partition 39, PROCESS_LOCAL, 5563 bytes)
17/01/29 07:03:08,708 INFO CoarseGrainedSchedulerBackend$DriverEndpoint: Launching task 170 on executor id: 3 hostname: 10.1.2.181.
17/01/29 07:03:08,709 INFO TaskSetManager: Finished task 26.0 in stage 3.0 (TID 155) in 117 ms on 10.1.2.181 (37/59)
17/01/29 07:03:08,709 INFO TaskSetManager: Finished task 42.0 in stage 3.0 (TID 160) in 82 ms on 10.1.2.63 (38/59)
17/01/29 07:03:08,710 INFO TaskSetManager: Finished task 43.0 in stage 3.0 (TID 161) in 74 ms on 10.1.2.63 (39/59)
17/01/29 07:03:08,717 INFO TaskSetManager: Finished task 45.0 in stage 3.0 (TID 164) in 59 ms on 10.1.2.63 (40/59)
17/01/29 07:03:08,721 INFO TaskSetManager: Finished task 54.0 in stage 3.0 (TID 163) in 70 ms on 10.1.2.236 (41/59)
17/01/29 07:03:08,731 INFO TaskSetManager: Finished task 46.0 in stage 3.0 (TID 162) in 86 ms on 10.1.2.236 (42/59)
17/01/29 07:03:08,736 INFO TaskSetManager: Starting task 58.0 in stage 3.0 (TID 171, 10.1.2.71, partition 58, PROCESS_LOCAL, 5563 bytes)
17/01/29 07:03:08,736 INFO CoarseGrainedSchedulerBackend$DriverEndpoint: Launching task 171 on executor id: 2 hostname: 10.1.2.71.
17/01/29 07:03:08,736 INFO TaskSetManager: Finished task 35.0 in stage 3.0 (TID 149) in 158 ms on 10.1.2.71 (43/59)
17/01/29 07:03:08,751 INFO TaskSetManager: Finished task 57.0 in stage 3.0 (TID 165) in 78 ms on 10.1.2.236 (44/59)
17/01/29 07:03:08,756 INFO TaskSetManager: Finished task 49.0 in stage 3.0 (TID 159) in 133 ms on 10.1.2.71 (45/59)
17/01/29 07:03:08,756 INFO TaskSetManager: Finished task 27.0 in stage 3.0 (TID 156) in 163 ms on 10.1.2.181 (46/59)
17/01/29 07:03:08,757 INFO TaskSetManager: Starting task 40.0 in stage 3.0 (TID 172, 10.1.2.181, partition 40, PROCESS_LOCAL, 5563 bytes)
17/01/29 07:03:08,757 INFO CoarseGrainedSchedulerBackend$DriverEndpoint: Launching task 172 on executor id: 3 hostname: 10.1.2.181.
17/01/29 07:03:08,758 INFO TaskSetManager: Starting task 41.0 in stage 3.0 (TID 173, 10.1.2.181, partition 41, PROCESS_LOCAL, 5563 bytes)
17/01/29 07:03:08,759 INFO CoarseGrainedSchedulerBackend$DriverEndpoint: Launching task 173 on executor id: 3 hostname: 10.1.2.181.
17/01/29 07:03:08,759 INFO TaskSetManager: Finished task 25.0 in stage 3.0 (TID 154) in 169 ms on 10.1.2.181 (47/59)
17/01/29 07:03:08,759 INFO TaskSetManager: Finished task 47.0 in stage 3.0 (TID 167) in 71 ms on 10.1.2.63 (48/59)
17/01/29 07:03:08,768 INFO TaskSetManager: Starting task 52.0 in stage 3.0 (TID 174, 10.1.2.181, partition 52, PROCESS_LOCAL, 5563 bytes)
17/01/29 07:03:08,768 INFO CoarseGrainedSchedulerBackend$DriverEndpoint: Launching task 174 on executor id: 3 hostname: 10.1.2.181.
17/01/29 07:03:08,769 INFO TaskSetManager: Finished task 38.0 in stage 3.0 (TID 169) in 67 ms on 10.1.2.181 (49/59)
17/01/29 07:03:08,775 INFO TaskSetManager: Finished task 39.0 in stage 3.0 (TID 170) in 67 ms on 10.1.2.181 (50/59)
17/01/29 07:03:08,776 INFO TaskSetManager: Starting task 53.0 in stage 3.0 (TID 175, 10.1.2.181, partition 53, PROCESS_LOCAL, 5563 bytes)
17/01/29 07:03:08,776 INFO CoarseGrainedSchedulerBackend$DriverEndpoint: Launching task 175 on executor id: 3 hostname: 10.1.2.181.
17/01/29 07:03:08,810 INFO TaskSetManager: Finished task 51.0 in stage 3.0 (TID 168) in 110 ms on 10.1.2.71 (51/59)
17/01/29 07:03:08,811 INFO TaskSetManager: Finished task 50.0 in stage 3.0 (TID 166) in 130 ms on 10.1.2.71 (52/59)
17/01/29 07:03:08,833 INFO TaskSetManager: Finished task 52.0 in stage 3.0 (TID 174) in 64 ms on 10.1.2.181 (53/59)
17/01/29 07:03:08,833 INFO TaskSetManager: Starting task 55.0 in stage 3.0 (TID 176, 10.1.2.181, partition 55, PROCESS_LOCAL, 5563 bytes)
17/01/29 07:03:08,833 INFO CoarseGrainedSchedulerBackend$DriverEndpoint: Launching task 176 on executor id: 3 hostname: 10.1.2.181.
17/01/29 07:03:08,835 INFO TaskSetManager: Finished task 58.0 in stage 3.0 (TID 171) in 100 ms on 10.1.2.71 (54/59)
17/01/29 07:03:08,850 INFO TaskSetManager: Starting task 56.0 in stage 3.0 (TID 177, 10.1.2.181, partition 56, PROCESS_LOCAL, 5563 bytes)
17/01/29 07:03:08,850 INFO CoarseGrainedSchedulerBackend$DriverEndpoint: Launching task 177 on executor id: 3 hostname: 10.1.2.181.
17/01/29 07:03:08,850 INFO TaskSetManager: Finished task 53.0 in stage 3.0 (TID 175) in 75 ms on 10.1.2.181 (55/59)
17/01/29 07:03:08,872 INFO TaskSetManager: Finished task 41.0 in stage 3.0 (TID 173) in 114 ms on 10.1.2.181 (56/59)
17/01/29 07:03:08,892 INFO TaskSetManager: Finished task 40.0 in stage 3.0 (TID 172) in 135 ms on 10.1.2.181 (57/59)
17/01/29 07:03:08,914 INFO TaskSetManager: Finished task 56.0 in stage 3.0 (TID 177) in 65 ms on 10.1.2.181 (58/59)
17/01/29 07:03:08,921 INFO TaskSetManager: Finished task 55.0 in stage 3.0 (TID 176) in 88 ms on 10.1.2.181 (59/59)
17/01/29 07:03:08,921 INFO TaskSchedulerImpl: Removed TaskSet 3.0, whose tasks have all completed, from pool 
17/01/29 07:03:08,926 INFO DAGScheduler: ShuffleMapStage 3 (treeAggregate at GradientDescent.scala:239) finished in 0.999 s
17/01/29 07:03:08,927 INFO DAGScheduler: looking for newly runnable stages
17/01/29 07:03:08,927 INFO DAGScheduler: running: Set()
17/01/29 07:03:08,928 INFO DAGScheduler: waiting: Set(ResultStage 4)
17/01/29 07:03:08,928 INFO DAGScheduler: failed: Set()
17/01/29 07:03:08,931 INFO DAGScheduler: Submitting ResultStage 4 (MapPartitionsRDD[13] at treeAggregate at GradientDescent.scala:239), which has no missing parents
17/01/29 07:03:08,937 INFO MemoryStore: Block broadcast_6 stored as values in memory (estimated size 3.1 KB, free 2.1 GB)
17/01/29 07:03:08,940 INFO MemoryStore: Block broadcast_6_piece0 stored as bytes in memory (estimated size 1893.0 B, free 2.1 GB)
17/01/29 07:03:08,941 INFO BlockManagerInfo: Added broadcast_6_piece0 in memory on 10.1.2.142:38331 (size: 1893.0 B, free: 2.1 GB)
17/01/29 07:03:08,941 INFO SparkContext: Created broadcast 6 from broadcast at DAGScheduler.scala:1012
17/01/29 07:03:08,942 INFO DAGScheduler: Submitting 7 missing tasks from ResultStage 4 (MapPartitionsRDD[13] at treeAggregate at GradientDescent.scala:239)
17/01/29 07:03:08,942 INFO TaskSchedulerImpl: Adding task set 4.0 with 7 tasks
17/01/29 07:03:08,944 INFO TaskSetManager: Starting task 0.0 in stage 4.0 (TID 178, 10.1.2.63, partition 0, NODE_LOCAL, 5228 bytes)
17/01/29 07:03:08,944 INFO TaskSetManager: Starting task 1.0 in stage 4.0 (TID 179, 10.1.2.181, partition 1, NODE_LOCAL, 5228 bytes)
17/01/29 07:03:08,945 INFO TaskSetManager: Starting task 2.0 in stage 4.0 (TID 180, 10.1.2.71, partition 2, NODE_LOCAL, 5228 bytes)
17/01/29 07:03:08,945 INFO TaskSetManager: Starting task 4.0 in stage 4.0 (TID 181, 10.1.2.236, partition 4, NODE_LOCAL, 5228 bytes)
17/01/29 07:03:08,945 INFO TaskSetManager: Starting task 3.0 in stage 4.0 (TID 182, 10.1.2.63, partition 3, NODE_LOCAL, 5228 bytes)
17/01/29 07:03:08,946 INFO TaskSetManager: Starting task 5.0 in stage 4.0 (TID 183, 10.1.2.181, partition 5, NODE_LOCAL, 5228 bytes)
17/01/29 07:03:08,946 INFO TaskSetManager: Starting task 6.0 in stage 4.0 (TID 184, 10.1.2.71, partition 6, NODE_LOCAL, 5228 bytes)
17/01/29 07:03:08,947 INFO CoarseGrainedSchedulerBackend$DriverEndpoint: Launching task 178 on executor id: 1 hostname: 10.1.2.63.
17/01/29 07:03:08,947 INFO CoarseGrainedSchedulerBackend$DriverEndpoint: Launching task 182 on executor id: 1 hostname: 10.1.2.63.
17/01/29 07:03:08,948 INFO CoarseGrainedSchedulerBackend$DriverEndpoint: Launching task 179 on executor id: 3 hostname: 10.1.2.181.
17/01/29 07:03:08,948 INFO CoarseGrainedSchedulerBackend$DriverEndpoint: Launching task 183 on executor id: 3 hostname: 10.1.2.181.
17/01/29 07:03:08,948 INFO CoarseGrainedSchedulerBackend$DriverEndpoint: Launching task 180 on executor id: 2 hostname: 10.1.2.71.
17/01/29 07:03:08,948 INFO CoarseGrainedSchedulerBackend$DriverEndpoint: Launching task 184 on executor id: 2 hostname: 10.1.2.71.
17/01/29 07:03:08,949 INFO CoarseGrainedSchedulerBackend$DriverEndpoint: Launching task 181 on executor id: 0 hostname: 10.1.2.236.
17/01/29 07:03:08,963 INFO BlockManagerInfo: Added broadcast_6_piece0 in memory on 10.1.2.236:34996 (size: 1893.0 B, free: 1071.3 MB)
17/01/29 07:03:08,965 INFO BlockManagerInfo: Added broadcast_6_piece0 in memory on 10.1.2.71:39018 (size: 1893.0 B, free: 998.7 MB)
17/01/29 07:03:08,965 INFO BlockManagerInfo: Added broadcast_6_piece0 in memory on 10.1.2.181:44727 (size: 1893.0 B, free: 1001.4 MB)
17/01/29 07:03:08,966 INFO BlockManagerInfo: Added broadcast_6_piece0 in memory on 10.1.2.63:45151 (size: 1893.0 B, free: 1281.6 MB)
17/01/29 07:03:08,979 INFO MapOutputTrackerMasterEndpoint: Asked to send map output locations for shuffle 0 to 10.1.2.236:35212
17/01/29 07:03:08,983 INFO MapOutputTrackerMaster: Size of output statuses for shuffle 0 is 345 bytes
17/01/29 07:03:08,985 INFO MapOutputTrackerMasterEndpoint: Asked to send map output locations for shuffle 0 to 10.1.2.71:56302
17/01/29 07:03:08,987 INFO MapOutputTrackerMasterEndpoint: Asked to send map output locations for shuffle 0 to 10.1.2.63:35914
17/01/29 07:03:08,988 INFO MapOutputTrackerMasterEndpoint: Asked to send map output locations for shuffle 0 to 10.1.2.181:58576
17/01/29 07:03:09,040 INFO TaskSetManager: Finished task 4.0 in stage 4.0 (TID 181) in 95 ms on 10.1.2.236 (1/7)
17/01/29 07:03:09,065 INFO TaskSetManager: Finished task 5.0 in stage 4.0 (TID 183) in 119 ms on 10.1.2.181 (2/7)
17/01/29 07:03:09,065 INFO TaskSetManager: Finished task 1.0 in stage 4.0 (TID 179) in 121 ms on 10.1.2.181 (3/7)
