Using properties file: /home/ubuntu/spark-2.0.0/conf/spark-defaults.conf
Adding default property: spark.driver.extraJavaOptions=-XX:+PrintGCDetails -XX:+PrintGCTimeStamps -Xms4000m -Dlog4j.configuration=file:///home/ubuntu/spark-2.0.0/conf/log4j.properties
Adding default property: spark.executor.extraJavaOptions=-XX:+PrintGCDetails -XX:+PrintGCTimeStamps -Xms4000m -Dlog4j.configuration=file:///home/ubuntu/spark-2.0.0/conf/log4j.properties
Parsed arguments:
  master                  spark://euca-10-1-2-142:7077
  deployMode              client
  executorMemory          4000m
  executorCores           null
  totalExecutorCores      null
  propertiesFile          /home/ubuntu/spark-2.0.0/conf/spark-defaults.conf
  driverMemory            4000m
  driverCores             null
  driverExtraClassPath    null
  driverExtraLibraryPath  null
  driverExtraJavaOptions  -XX:+PrintGCDetails -XX:+PrintGCTimeStamps -Xms4000m -Dlog4j.configuration=file:///home/ubuntu/spark-2.0.0/conf/log4j.properties
  supervise               false
  queue                   null
  numExecutors            4
  files                   null
  pyFiles                 null
  archives                null
  mainClass               LogRegExplicitParallelism
  primaryResource         file:///home/ubuntu/jars/log-reg-explicit-parallelism_2.11-1.0.jar
  name                    LogRegExplicitParallelism
  childArgs               [cluster 28 euca-10-1-2-142 9000 higgs_0_exp 5 16]
  jars                    null
  packages                null
  packagesExclusions      null
  repositories            null
  verbose                 true

Spark properties used, including those specified through
 --conf and those from the properties file /home/ubuntu/spark-2.0.0/conf/spark-defaults.conf:
  spark.default.parallelism -> 16
  spark.driver.memory -> 4000m
  spark.executor.extraJavaOptions -> -XX:+PrintGCDetails -XX:+PrintGCTimeStamps -Xms4000m -Dlog4j.configuration=file:///home/ubuntu/spark-2.0.0/conf/log4j.properties
  spark.driver.extraJavaOptions -> -XX:+PrintGCDetails -XX:+PrintGCTimeStamps -Xms4000m -Dlog4j.configuration=file:///home/ubuntu/spark-2.0.0/conf/log4j.properties
  spark.shuffle.spill -> false

    
Main class:
LogRegExplicitParallelism
Arguments:
cluster
28
euca-10-1-2-142
9000
higgs_0_exp
5
16
System properties:
spark.default.parallelism -> 16
spark.executor.memory -> 4000m
spark.driver.memory -> 4000m
SPARK_SUBMIT -> true
spark.executor.extraJavaOptions -> -XX:+PrintGCDetails -XX:+PrintGCTimeStamps -Xms4000m -Dlog4j.configuration=file:///home/ubuntu/spark-2.0.0/conf/log4j.properties
spark.app.name -> LogRegExplicitParallelism
spark.shuffle.spill -> false
spark.driver.extraJavaOptions -> -XX:+PrintGCDetails -XX:+PrintGCTimeStamps -Xms4000m -Dlog4j.configuration=file:///home/ubuntu/spark-2.0.0/conf/log4j.properties
spark.jars -> file:///home/ubuntu/jars/log-reg-explicit-parallelism_2.11-1.0.jar
spark.submit.deployMode -> client
spark.master -> spark://euca-10-1-2-142:7077
Classpath elements:
file:///home/ubuntu/jars/log-reg-explicit-parallelism_2.11-1.0.jar


17/01/29 07:42:55,292 INFO SparkContext: Running Spark version 2.0.0
17/01/29 07:42:55,628 WARN NativeCodeLoader: Unable to load native-hadoop library for your platform... using builtin-java classes where applicable
17/01/29 07:42:55,789 INFO SecurityManager: Changing view acls to: ubuntu
17/01/29 07:42:55,790 INFO SecurityManager: Changing modify acls to: ubuntu
17/01/29 07:42:55,790 INFO SecurityManager: Changing view acls groups to: 
17/01/29 07:42:55,791 INFO SecurityManager: Changing modify acls groups to: 
17/01/29 07:42:55,791 INFO SecurityManager: SecurityManager: authentication disabled; ui acls disabled; users  with view permissions: Set(ubuntu); groups with view permissions: Set(); users  with modify permissions: Set(ubuntu); groups with modify permissions: Set()
17/01/29 07:42:59,071 WARN ThreadLocalRandom: Failed to generate a seed from SecureRandom within 3 seconds. Not enough entrophy?
17/01/29 07:42:59,121 INFO Utils: Successfully started service 'sparkDriver' on port 40092.
17/01/29 07:42:59,139 INFO SparkEnv: Registering MapOutputTracker
17/01/29 07:42:59,145 WARN SortShuffleManager: spark.shuffle.spill was set to false, but this configuration is ignored as of Spark 1.6+. Shuffle will continue to spill to disk when necessary.
17/01/29 07:42:59,157 INFO SparkEnv: Registering BlockManagerMaster
17/01/29 07:42:59,170 INFO DiskBlockManager: Created local directory at /tmp/blockmgr-86b4887b-2ff5-45b8-9780-49d9252d5d7e
17/01/29 07:42:59,188 INFO MemoryStore: MemoryStore started with capacity 2.1 GB
17/01/29 07:42:59,240 INFO SparkEnv: Registering OutputCommitCoordinator
17/01/29 07:42:59,449 INFO Utils: Successfully started service 'SparkUI' on port 4040.
17/01/29 07:42:59,451 INFO SparkUI: Bound SparkUI to 10.1.2.142, and started at http://10.1.2.142:4040
17/01/29 07:42:59,488 INFO SparkContext: Added JAR file:///home/ubuntu/jars/log-reg-explicit-parallelism_2.11-1.0.jar at spark://10.1.2.142:40092/jars/log-reg-explicit-parallelism_2.11-1.0.jar with timestamp 1485675779488
17/01/29 07:42:59,571 INFO StandaloneAppClient$ClientEndpoint: Connecting to master spark://euca-10-1-2-142:7077...
17/01/29 07:42:59,625 INFO TransportClientFactory: Successfully created connection to euca-10-1-2-142/10.1.2.142:7077 after 24 ms (0 ms spent in bootstraps)
17/01/29 07:42:59,716 INFO StandaloneSchedulerBackend: Connected to Spark cluster with app ID app-20170129074259-0000
17/01/29 07:42:59,721 INFO Utils: Successfully started service 'org.apache.spark.network.netty.NettyBlockTransferService' on port 37340.
17/01/29 07:42:59,722 INFO NettyBlockTransferService: Server created on 10.1.2.142:37340
17/01/29 07:42:59,724 INFO BlockManagerMaster: Registering BlockManager BlockManagerId(driver, 10.1.2.142, 37340)
17/01/29 07:42:59,726 INFO BlockManagerMasterEndpoint: Registering block manager 10.1.2.142:37340 with 2.1 GB RAM, BlockManagerId(driver, 10.1.2.142, 37340)
17/01/29 07:42:59,728 INFO BlockManagerMaster: Registered BlockManager BlockManagerId(driver, 10.1.2.142, 37340)
17/01/29 07:42:59,744 INFO StandaloneAppClient$ClientEndpoint: Executor added: app-20170129074259-0000/0 on worker-20170129074240-10.1.2.71-41226 (10.1.2.71:41226) with 4 cores
17/01/29 07:42:59,745 INFO StandaloneSchedulerBackend: Granted executor ID app-20170129074259-0000/0 on hostPort 10.1.2.71:41226 with 4 cores, 3.9 GB RAM
17/01/29 07:42:59,747 INFO StandaloneAppClient$ClientEndpoint: Executor added: app-20170129074259-0000/1 on worker-20170129074240-10.1.2.63-35088 (10.1.2.63:35088) with 4 cores
17/01/29 07:42:59,747 INFO StandaloneSchedulerBackend: Granted executor ID app-20170129074259-0000/1 on hostPort 10.1.2.63:35088 with 4 cores, 3.9 GB RAM
17/01/29 07:42:59,748 INFO StandaloneAppClient$ClientEndpoint: Executor added: app-20170129074259-0000/2 on worker-20170129074240-10.1.2.181-45718 (10.1.2.181:45718) with 4 cores
17/01/29 07:42:59,748 INFO StandaloneSchedulerBackend: Granted executor ID app-20170129074259-0000/2 on hostPort 10.1.2.181:45718 with 4 cores, 3.9 GB RAM
17/01/29 07:42:59,750 INFO StandaloneAppClient$ClientEndpoint: Executor added: app-20170129074259-0000/3 on worker-20170129074240-10.1.2.236-44468 (10.1.2.236:44468) with 4 cores
17/01/29 07:42:59,751 INFO StandaloneSchedulerBackend: Granted executor ID app-20170129074259-0000/3 on hostPort 10.1.2.236:44468 with 4 cores, 3.9 GB RAM
17/01/29 07:42:59,795 INFO StandaloneAppClient$ClientEndpoint: Executor updated: app-20170129074259-0000/1 is now RUNNING
17/01/29 07:42:59,799 INFO StandaloneAppClient$ClientEndpoint: Executor updated: app-20170129074259-0000/3 is now RUNNING
17/01/29 07:42:59,802 INFO StandaloneAppClient$ClientEndpoint: Executor updated: app-20170129074259-0000/0 is now RUNNING
17/01/29 07:42:59,805 INFO StandaloneAppClient$ClientEndpoint: Executor updated: app-20170129074259-0000/2 is now RUNNING
17/01/29 07:42:59,911 INFO StandaloneSchedulerBackend: SchedulerBackend is ready for scheduling beginning after reached minRegisteredResourcesRatio: 0.0
17/01/29 07:43:00,273 INFO MemoryStore: Block broadcast_0 stored as values in memory (estimated size 130.8 KB, free 2.1 GB)
17/01/29 07:43:00,331 INFO MemoryStore: Block broadcast_0_piece0 stored as bytes in memory (estimated size 16.5 KB, free 2.1 GB)
17/01/29 07:43:00,334 INFO BlockManagerInfo: Added broadcast_0_piece0 in memory on 10.1.2.142:37340 (size: 16.5 KB, free: 2.1 GB)
17/01/29 07:43:00,341 INFO SparkContext: Created broadcast 0 from textFile at MLUtils.scala:99
17/01/29 07:43:00,920 INFO FileInputFormat: Total input paths to process : 1
17/01/29 07:43:00,965 INFO NetworkTopology: Adding a new node: /default-rack/10.1.2.71:50010
17/01/29 07:43:00,966 INFO NetworkTopology: Adding a new node: /default-rack/10.1.2.236:50010
17/01/29 07:43:00,966 INFO NetworkTopology: Adding a new node: /default-rack/10.1.2.63:50010
17/01/29 07:43:01,005 INFO SparkContext: Starting job: first at GeneralizedLinearAlgorithm.scala:246
17/01/29 07:43:01,017 INFO DAGScheduler: Got job 0 (first at GeneralizedLinearAlgorithm.scala:246) with 1 output partitions
17/01/29 07:43:01,018 INFO DAGScheduler: Final stage: ResultStage 0 (first at GeneralizedLinearAlgorithm.scala:246)
17/01/29 07:43:01,018 INFO DAGScheduler: Parents of final stage: List()
17/01/29 07:43:01,024 INFO DAGScheduler: Missing parents: List()
17/01/29 07:43:01,031 INFO DAGScheduler: Submitting ResultStage 0 (MapPartitionsRDD[6] at map at GeneralizedLinearAlgorithm.scala:246), which has no missing parents
17/01/29 07:43:01,051 INFO MemoryStore: Block broadcast_1 stored as values in memory (estimated size 4.2 KB, free 2.1 GB)
17/01/29 07:43:01,053 INFO MemoryStore: Block broadcast_1_piece0 stored as bytes in memory (estimated size 2.4 KB, free 2.1 GB)
17/01/29 07:43:01,054 INFO BlockManagerInfo: Added broadcast_1_piece0 in memory on 10.1.2.142:37340 (size: 2.4 KB, free: 2.1 GB)
17/01/29 07:43:01,055 INFO SparkContext: Created broadcast 1 from broadcast at DAGScheduler.scala:1012
17/01/29 07:43:01,058 INFO DAGScheduler: Submitting 1 missing tasks from ResultStage 0 (MapPartitionsRDD[6] at map at GeneralizedLinearAlgorithm.scala:246)
17/01/29 07:43:01,059 INFO TaskSchedulerImpl: Adding task set 0.0 with 1 tasks
17/01/29 07:43:01,565 INFO CoarseGrainedSchedulerBackend$DriverEndpoint: Registered executor NettyRpcEndpointRef(null) (10.1.2.236:44136) with ID 3
17/01/29 07:43:01,595 INFO TaskSetManager: Starting task 0.0 in stage 0.0 (TID 0, 10.1.2.236, partition 0, ANY, 5456 bytes)
17/01/29 07:43:01,599 INFO CoarseGrainedSchedulerBackend$DriverEndpoint: Launching task 0 on executor id: 3 hostname: 10.1.2.236.
17/01/29 07:43:01,604 INFO CoarseGrainedSchedulerBackend$DriverEndpoint: Registered executor NettyRpcEndpointRef(null) (10.1.2.63:53222) with ID 1
17/01/29 07:43:01,618 INFO BlockManagerMasterEndpoint: Registering block manager 10.1.2.236:38599 with 2.1 GB RAM, BlockManagerId(3, 10.1.2.236, 38599)
17/01/29 07:43:01,621 INFO CoarseGrainedSchedulerBackend$DriverEndpoint: Registered executor NettyRpcEndpointRef(null) (10.1.2.71:37936) with ID 0
17/01/29 07:43:01,657 INFO BlockManagerMasterEndpoint: Registering block manager 10.1.2.63:44673 with 2.1 GB RAM, BlockManagerId(1, 10.1.2.63, 44673)
17/01/29 07:43:01,672 INFO BlockManagerMasterEndpoint: Registering block manager 10.1.2.71:38877 with 2.1 GB RAM, BlockManagerId(0, 10.1.2.71, 38877)
17/01/29 07:43:01,876 INFO BlockManagerInfo: Added broadcast_1_piece0 in memory on 10.1.2.236:38599 (size: 2.4 KB, free: 2.1 GB)
17/01/29 07:43:02,022 INFO BlockManagerInfo: Added broadcast_0_piece0 in memory on 10.1.2.236:38599 (size: 16.5 KB, free: 2.1 GB)
17/01/29 07:43:04,634 INFO CoarseGrainedSchedulerBackend$DriverEndpoint: Registered executor NettyRpcEndpointRef(null) (10.1.2.181:36088) with ID 2
17/01/29 07:43:04,683 INFO BlockManagerMasterEndpoint: Registering block manager 10.1.2.181:41485 with 2.1 GB RAM, BlockManagerId(2, 10.1.2.181, 41485)
17/01/29 07:43:09,073 INFO BlockManagerInfo: Added rdd_5_0 in memory on 10.1.2.236:38599 (size: 70.0 MB, free: 2.0 GB)
17/01/29 07:43:09,125 INFO TaskSetManager: Finished task 0.0 in stage 0.0 (TID 0) in 7553 ms on 10.1.2.236 (1/1)
17/01/29 07:43:09,127 INFO TaskSchedulerImpl: Removed TaskSet 0.0, whose tasks have all completed, from pool 
17/01/29 07:43:09,136 INFO DAGScheduler: ResultStage 0 (first at GeneralizedLinearAlgorithm.scala:246) finished in 8.067 s
17/01/29 07:43:09,142 INFO DAGScheduler: Job 0 finished: first at GeneralizedLinearAlgorithm.scala:246, took 8.135682 s
17/01/29 07:43:09,153 INFO SparkContext: Starting job: count at DataValidators.scala:40
17/01/29 07:43:09,156 INFO DAGScheduler: Got job 1 (count at DataValidators.scala:40) with 59 output partitions
17/01/29 07:43:09,156 INFO DAGScheduler: Final stage: ResultStage 1 (count at DataValidators.scala:40)
17/01/29 07:43:09,156 INFO DAGScheduler: Parents of final stage: List()
17/01/29 07:43:09,160 INFO DAGScheduler: Missing parents: List()
17/01/29 07:43:09,161 INFO DAGScheduler: Submitting ResultStage 1 (MapPartitionsRDD[7] at filter at DataValidators.scala:40), which has no missing parents
17/01/29 07:43:09,189 INFO MemoryStore: Block broadcast_2 stored as values in memory (estimated size 3.9 KB, free 2.1 GB)
17/01/29 07:43:09,192 INFO MemoryStore: Block broadcast_2_piece0 stored as bytes in memory (estimated size 2.2 KB, free 2.1 GB)
17/01/29 07:43:09,193 INFO BlockManagerInfo: Added broadcast_2_piece0 in memory on 10.1.2.142:37340 (size: 2.2 KB, free: 2.1 GB)
17/01/29 07:43:09,194 INFO SparkContext: Created broadcast 2 from broadcast at DAGScheduler.scala:1012
17/01/29 07:43:09,195 INFO DAGScheduler: Submitting 59 missing tasks from ResultStage 1 (MapPartitionsRDD[7] at filter at DataValidators.scala:40)
17/01/29 07:43:09,196 INFO TaskSchedulerImpl: Adding task set 1.0 with 59 tasks
17/01/29 07:43:09,202 INFO TaskSetManager: Starting task 0.0 in stage 1.0 (TID 1, 10.1.2.236, partition 0, PROCESS_LOCAL, 5374 bytes)
17/01/29 07:43:09,205 INFO TaskSetManager: Starting task 58.0 in stage 1.0 (TID 2, 10.1.2.236, partition 58, NODE_LOCAL, 5374 bytes)
17/01/29 07:43:09,206 INFO CoarseGrainedSchedulerBackend$DriverEndpoint: Launching task 1 on executor id: 3 hostname: 10.1.2.236.
17/01/29 07:43:09,207 INFO CoarseGrainedSchedulerBackend$DriverEndpoint: Launching task 2 on executor id: 3 hostname: 10.1.2.236.
17/01/29 07:43:09,230 INFO BlockManagerInfo: Added broadcast_2_piece0 in memory on 10.1.2.236:38599 (size: 2.2 KB, free: 2.0 GB)
17/01/29 07:43:09,296 INFO TaskSetManager: Finished task 0.0 in stage 1.0 (TID 1) in 96 ms on 10.1.2.236 (1/59)
17/01/29 07:43:12,561 INFO TaskSetManager: Starting task 1.0 in stage 1.0 (TID 3, 10.1.2.63, partition 1, ANY, 5374 bytes)
17/01/29 07:43:12,565 INFO TaskSetManager: Starting task 2.0 in stage 1.0 (TID 4, 10.1.2.181, partition 2, ANY, 5374 bytes)
17/01/29 07:43:12,567 INFO TaskSetManager: Starting task 3.0 in stage 1.0 (TID 5, 10.1.2.236, partition 3, ANY, 5374 bytes)
17/01/29 07:43:12,573 INFO TaskSetManager: Starting task 4.0 in stage 1.0 (TID 6, 10.1.2.71, partition 4, ANY, 5374 bytes)
17/01/29 07:43:12,575 INFO TaskSetManager: Starting task 5.0 in stage 1.0 (TID 7, 10.1.2.63, partition 5, ANY, 5374 bytes)
17/01/29 07:43:12,577 INFO TaskSetManager: Starting task 6.0 in stage 1.0 (TID 8, 10.1.2.181, partition 6, ANY, 5374 bytes)
17/01/29 07:43:12,580 INFO TaskSetManager: Starting task 7.0 in stage 1.0 (TID 9, 10.1.2.236, partition 7, ANY, 5374 bytes)
17/01/29 07:43:12,583 INFO TaskSetManager: Starting task 8.0 in stage 1.0 (TID 10, 10.1.2.71, partition 8, ANY, 5374 bytes)
17/01/29 07:43:12,585 INFO TaskSetManager: Starting task 9.0 in stage 1.0 (TID 11, 10.1.2.63, partition 9, ANY, 5374 bytes)
17/01/29 07:43:12,588 INFO TaskSetManager: Starting task 10.0 in stage 1.0 (TID 12, 10.1.2.181, partition 10, ANY, 5374 bytes)
17/01/29 07:43:12,590 INFO TaskSetManager: Starting task 11.0 in stage 1.0 (TID 13, 10.1.2.236, partition 11, ANY, 5374 bytes)
17/01/29 07:43:12,592 INFO TaskSetManager: Starting task 12.0 in stage 1.0 (TID 14, 10.1.2.71, partition 12, ANY, 5374 bytes)
17/01/29 07:43:12,597 INFO TaskSetManager: Starting task 13.0 in stage 1.0 (TID 15, 10.1.2.63, partition 13, ANY, 5374 bytes)
17/01/29 07:43:12,599 INFO TaskSetManager: Starting task 14.0 in stage 1.0 (TID 16, 10.1.2.181, partition 14, ANY, 5374 bytes)
17/01/29 07:43:12,601 INFO TaskSetManager: Starting task 15.0 in stage 1.0 (TID 17, 10.1.2.71, partition 15, ANY, 5374 bytes)
17/01/29 07:43:12,602 INFO CoarseGrainedSchedulerBackend$DriverEndpoint: Launching task 3 on executor id: 1 hostname: 10.1.2.63.
17/01/29 07:43:12,603 INFO CoarseGrainedSchedulerBackend$DriverEndpoint: Launching task 7 on executor id: 1 hostname: 10.1.2.63.
17/01/29 07:43:12,603 INFO CoarseGrainedSchedulerBackend$DriverEndpoint: Launching task 11 on executor id: 1 hostname: 10.1.2.63.
17/01/29 07:43:12,604 INFO CoarseGrainedSchedulerBackend$DriverEndpoint: Launching task 15 on executor id: 1 hostname: 10.1.2.63.
17/01/29 07:43:12,604 INFO CoarseGrainedSchedulerBackend$DriverEndpoint: Launching task 4 on executor id: 2 hostname: 10.1.2.181.
17/01/29 07:43:12,605 INFO CoarseGrainedSchedulerBackend$DriverEndpoint: Launching task 8 on executor id: 2 hostname: 10.1.2.181.
17/01/29 07:43:12,606 INFO CoarseGrainedSchedulerBackend$DriverEndpoint: Launching task 12 on executor id: 2 hostname: 10.1.2.181.
17/01/29 07:43:12,606 INFO CoarseGrainedSchedulerBackend$DriverEndpoint: Launching task 16 on executor id: 2 hostname: 10.1.2.181.
17/01/29 07:43:12,607 INFO CoarseGrainedSchedulerBackend$DriverEndpoint: Launching task 5 on executor id: 3 hostname: 10.1.2.236.
17/01/29 07:43:12,607 INFO CoarseGrainedSchedulerBackend$DriverEndpoint: Launching task 9 on executor id: 3 hostname: 10.1.2.236.
17/01/29 07:43:12,608 INFO CoarseGrainedSchedulerBackend$DriverEndpoint: Launching task 13 on executor id: 3 hostname: 10.1.2.236.
17/01/29 07:43:12,608 INFO CoarseGrainedSchedulerBackend$DriverEndpoint: Launching task 6 on executor id: 0 hostname: 10.1.2.71.
17/01/29 07:43:12,609 INFO CoarseGrainedSchedulerBackend$DriverEndpoint: Launching task 10 on executor id: 0 hostname: 10.1.2.71.
17/01/29 07:43:12,610 INFO CoarseGrainedSchedulerBackend$DriverEndpoint: Launching task 14 on executor id: 0 hostname: 10.1.2.71.
17/01/29 07:43:12,611 INFO CoarseGrainedSchedulerBackend$DriverEndpoint: Launching task 17 on executor id: 0 hostname: 10.1.2.71.
17/01/29 07:43:12,900 INFO BlockManagerInfo: Added broadcast_2_piece0 in memory on 10.1.2.71:38877 (size: 2.2 KB, free: 2.1 GB)
17/01/29 07:43:12,962 INFO BlockManagerInfo: Added broadcast_2_piece0 in memory on 10.1.2.63:44673 (size: 2.2 KB, free: 2.1 GB)
17/01/29 07:43:12,965 INFO BlockManagerInfo: Added broadcast_2_piece0 in memory on 10.1.2.181:41485 (size: 2.2 KB, free: 2.1 GB)
17/01/29 07:43:13,085 INFO BlockManagerInfo: Added broadcast_0_piece0 in memory on 10.1.2.71:38877 (size: 16.5 KB, free: 2.1 GB)
17/01/29 07:43:13,158 INFO BlockManagerInfo: Added broadcast_0_piece0 in memory on 10.1.2.63:44673 (size: 16.5 KB, free: 2.1 GB)
17/01/29 07:43:13,159 INFO BlockManagerInfo: Added broadcast_0_piece0 in memory on 10.1.2.181:41485 (size: 16.5 KB, free: 2.1 GB)
21.857: [GC [PSYoungGen: 1024512K->157166K(1195008K)] 1024512K->157238K(3926016K), 0.0574080 secs] [Times: user=0.07 sys=0.04, real=0.06 secs] 
17/01/29 07:43:16,626 INFO BlockManagerInfo: Removed broadcast_1_piece0 on 10.1.2.142:37340 in memory (size: 2.4 KB, free: 2.1 GB)
17/01/29 07:43:16,643 INFO BlockManagerInfo: Removed broadcast_1_piece0 on 10.1.2.236:38599 in memory (size: 2.4 KB, free: 2.0 GB)
17/01/29 07:43:21,052 INFO BlockManagerInfo: Added rdd_5_58 in memory on 10.1.2.236:38599 (size: 72.8 MB, free: 1977.6 MB)
17/01/29 07:43:21,080 INFO TaskSetManager: Starting task 16.0 in stage 1.0 (TID 18, 10.1.2.236, partition 16, ANY, 5374 bytes)
17/01/29 07:43:21,081 INFO CoarseGrainedSchedulerBackend$DriverEndpoint: Launching task 18 on executor id: 3 hostname: 10.1.2.236.
17/01/29 07:43:21,083 INFO TaskSetManager: Finished task 58.0 in stage 1.0 (TID 2) in 11878 ms on 10.1.2.236 (2/59)
17/01/29 07:43:33,080 INFO BlockManagerInfo: Added rdd_5_3 in memory on 10.1.2.236:38599 (size: 69.9 MB, free: 1907.7 MB)
17/01/29 07:43:33,100 INFO TaskSetManager: Starting task 17.0 in stage 1.0 (TID 19, 10.1.2.236, partition 17, ANY, 5374 bytes)
17/01/29 07:43:33,100 INFO CoarseGrainedSchedulerBackend$DriverEndpoint: Launching task 19 on executor id: 3 hostname: 10.1.2.236.
17/01/29 07:43:33,103 INFO TaskSetManager: Finished task 3.0 in stage 1.0 (TID 5) in 20536 ms on 10.1.2.236 (3/59)
17/01/29 07:43:33,679 INFO BlockManagerInfo: Added rdd_5_14 in memory on 10.1.2.181:41485 (size: 69.9 MB, free: 2.0 GB)
17/01/29 07:43:33,750 INFO TaskSetManager: Starting task 18.0 in stage 1.0 (TID 20, 10.1.2.181, partition 18, ANY, 5374 bytes)
17/01/29 07:43:33,750 INFO CoarseGrainedSchedulerBackend$DriverEndpoint: Launching task 20 on executor id: 2 hostname: 10.1.2.181.
17/01/29 07:43:33,750 INFO TaskSetManager: Finished task 14.0 in stage 1.0 (TID 16) in 21153 ms on 10.1.2.181 (4/59)
17/01/29 07:43:33,841 INFO BlockManagerInfo: Added rdd_5_2 in memory on 10.1.2.181:41485 (size: 69.9 MB, free: 1980.6 MB)
17/01/29 07:43:33,866 INFO BlockManagerInfo: Added rdd_5_10 in memory on 10.1.2.181:41485 (size: 70.0 MB, free: 1910.6 MB)
17/01/29 07:43:33,867 INFO TaskSetManager: Starting task 19.0 in stage 1.0 (TID 21, 10.1.2.181, partition 19, ANY, 5374 bytes)
17/01/29 07:43:33,868 INFO CoarseGrainedSchedulerBackend$DriverEndpoint: Launching task 21 on executor id: 2 hostname: 10.1.2.181.
17/01/29 07:43:33,868 INFO TaskSetManager: Finished task 2.0 in stage 1.0 (TID 4) in 21306 ms on 10.1.2.181 (5/59)
17/01/29 07:43:33,896 INFO BlockManagerInfo: Added rdd_5_11 in memory on 10.1.2.236:38599 (size: 69.9 MB, free: 1837.8 MB)
17/01/29 07:43:33,913 INFO TaskSetManager: Starting task 20.0 in stage 1.0 (TID 22, 10.1.2.236, partition 20, ANY, 5374 bytes)
17/01/29 07:43:33,914 INFO TaskSetManager: Finished task 11.0 in stage 1.0 (TID 13) in 21325 ms on 10.1.2.236 (6/59)
17/01/29 07:43:33,914 INFO CoarseGrainedSchedulerBackend$DriverEndpoint: Launching task 22 on executor id: 3 hostname: 10.1.2.236.
17/01/29 07:43:33,949 INFO TaskSetManager: Starting task 21.0 in stage 1.0 (TID 23, 10.1.2.181, partition 21, ANY, 5374 bytes)
17/01/29 07:43:33,949 INFO CoarseGrainedSchedulerBackend$DriverEndpoint: Launching task 23 on executor id: 2 hostname: 10.1.2.181.
17/01/29 07:43:33,950 INFO TaskSetManager: Finished task 10.0 in stage 1.0 (TID 12) in 21363 ms on 10.1.2.181 (7/59)
17/01/29 07:43:33,965 INFO BlockManagerInfo: Added rdd_5_6 in memory on 10.1.2.181:41485 (size: 69.9 MB, free: 1840.6 MB)
17/01/29 07:43:33,987 INFO TaskSetManager: Starting task 22.0 in stage 1.0 (TID 24, 10.1.2.181, partition 22, ANY, 5374 bytes)
17/01/29 07:43:33,988 INFO CoarseGrainedSchedulerBackend$DriverEndpoint: Launching task 24 on executor id: 2 hostname: 10.1.2.181.
17/01/29 07:43:33,988 INFO TaskSetManager: Finished task 6.0 in stage 1.0 (TID 8) in 21412 ms on 10.1.2.181 (8/59)
17/01/29 07:43:34,418 INFO BlockManagerInfo: Added rdd_5_8 in memory on 10.1.2.71:38877 (size: 70.0 MB, free: 2.0 GB)
17/01/29 07:43:34,485 INFO TaskSetManager: Finished task 8.0 in stage 1.0 (TID 10) in 21904 ms on 10.1.2.71 (9/59)
17/01/29 07:43:34,487 INFO TaskSetManager: Starting task 23.0 in stage 1.0 (TID 25, 10.1.2.71, partition 23, ANY, 5374 bytes)
17/01/29 07:43:34,488 INFO CoarseGrainedSchedulerBackend$DriverEndpoint: Launching task 25 on executor id: 0 hostname: 10.1.2.71.
17/01/29 07:43:34,655 INFO BlockManagerInfo: Added rdd_5_13 in memory on 10.1.2.63:44673 (size: 69.9 MB, free: 2.0 GB)
17/01/29 07:43:34,721 INFO TaskSetManager: Starting task 24.0 in stage 1.0 (TID 26, 10.1.2.63, partition 24, ANY, 5374 bytes)
17/01/29 07:43:34,721 INFO CoarseGrainedSchedulerBackend$DriverEndpoint: Launching task 26 on executor id: 1 hostname: 10.1.2.63.
17/01/29 07:43:34,721 INFO TaskSetManager: Finished task 13.0 in stage 1.0 (TID 15) in 22128 ms on 10.1.2.63 (10/59)
17/01/29 07:43:34,724 INFO BlockManagerInfo: Added rdd_5_15 in memory on 10.1.2.71:38877 (size: 69.9 MB, free: 1980.5 MB)
17/01/29 07:43:34,739 INFO BlockManagerInfo: Added rdd_5_12 in memory on 10.1.2.71:38877 (size: 70.0 MB, free: 1910.5 MB)
17/01/29 07:43:34,759 INFO TaskSetManager: Starting task 25.0 in stage 1.0 (TID 27, 10.1.2.71, partition 25, ANY, 5374 bytes)
17/01/29 07:43:34,759 INFO CoarseGrainedSchedulerBackend$DriverEndpoint: Launching task 27 on executor id: 0 hostname: 10.1.2.71.
17/01/29 07:43:34,759 INFO TaskSetManager: Finished task 15.0 in stage 1.0 (TID 17) in 22159 ms on 10.1.2.71 (11/59)
17/01/29 07:43:34,771 INFO TaskSetManager: Starting task 26.0 in stage 1.0 (TID 28, 10.1.2.71, partition 26, ANY, 5374 bytes)
17/01/29 07:43:34,771 INFO CoarseGrainedSchedulerBackend$DriverEndpoint: Launching task 28 on executor id: 0 hostname: 10.1.2.71.
17/01/29 07:43:34,771 INFO TaskSetManager: Finished task 12.0 in stage 1.0 (TID 14) in 22180 ms on 10.1.2.71 (12/59)
17/01/29 07:43:34,869 INFO BlockManagerInfo: Added rdd_5_4 in memory on 10.1.2.71:38877 (size: 70.0 MB, free: 1840.5 MB)
17/01/29 07:43:34,890 INFO TaskSetManager: Finished task 4.0 in stage 1.0 (TID 6) in 22322 ms on 10.1.2.71 (13/59)
17/01/29 07:43:34,892 INFO TaskSetManager: Starting task 27.0 in stage 1.0 (TID 29, 10.1.2.71, partition 27, ANY, 5374 bytes)
17/01/29 07:43:34,892 INFO CoarseGrainedSchedulerBackend$DriverEndpoint: Launching task 29 on executor id: 0 hostname: 10.1.2.71.
17/01/29 07:43:36,118 INFO BlockManagerInfo: Added rdd_5_7 in memory on 10.1.2.236:38599 (size: 70.0 MB, free: 1767.8 MB)
17/01/29 07:43:36,142 INFO TaskSetManager: Starting task 28.0 in stage 1.0 (TID 30, 10.1.2.236, partition 28, ANY, 5374 bytes)
17/01/29 07:43:36,144 INFO TaskSetManager: Finished task 7.0 in stage 1.0 (TID 9) in 23565 ms on 10.1.2.236 (14/59)
17/01/29 07:43:36,145 INFO CoarseGrainedSchedulerBackend$DriverEndpoint: Launching task 30 on executor id: 3 hostname: 10.1.2.236.
17/01/29 07:43:36,402 INFO BlockManagerInfo: Added rdd_5_9 in memory on 10.1.2.63:44673 (size: 69.9 MB, free: 1980.6 MB)
17/01/29 07:43:36,419 INFO TaskSetManager: Starting task 29.0 in stage 1.0 (TID 31, 10.1.2.63, partition 29, ANY, 5374 bytes)
17/01/29 07:43:36,419 INFO CoarseGrainedSchedulerBackend$DriverEndpoint: Launching task 31 on executor id: 1 hostname: 10.1.2.63.
17/01/29 07:43:36,420 INFO TaskSetManager: Finished task 9.0 in stage 1.0 (TID 11) in 23836 ms on 10.1.2.63 (15/59)
17/01/29 07:43:36,677 INFO BlockManagerInfo: Added rdd_5_5 in memory on 10.1.2.63:44673 (size: 70.0 MB, free: 1910.6 MB)
17/01/29 07:43:36,726 INFO TaskSetManager: Starting task 30.0 in stage 1.0 (TID 32, 10.1.2.63, partition 30, ANY, 5374 bytes)
17/01/29 07:43:36,726 INFO CoarseGrainedSchedulerBackend$DriverEndpoint: Launching task 32 on executor id: 1 hostname: 10.1.2.63.
17/01/29 07:43:36,726 INFO TaskSetManager: Finished task 5.0 in stage 1.0 (TID 7) in 24153 ms on 10.1.2.63 (16/59)
17/01/29 07:43:37,082 INFO BlockManagerInfo: Added rdd_5_1 in memory on 10.1.2.63:44673 (size: 70.0 MB, free: 1840.6 MB)
17/01/29 07:43:37,097 INFO TaskSetManager: Finished task 1.0 in stage 1.0 (TID 3) in 24537 ms on 10.1.2.63 (17/59)
17/01/29 07:43:37,098 INFO TaskSetManager: Starting task 31.0 in stage 1.0 (TID 33, 10.1.2.63, partition 31, ANY, 5374 bytes)
17/01/29 07:43:37,099 INFO CoarseGrainedSchedulerBackend$DriverEndpoint: Launching task 33 on executor id: 1 hostname: 10.1.2.63.
17/01/29 07:43:43,804 INFO BlockManagerInfo: Added rdd_5_16 in memory on 10.1.2.236:38599 (size: 70.0 MB, free: 1697.9 MB)
17/01/29 07:43:43,823 INFO TaskSetManager: Starting task 32.0 in stage 1.0 (TID 34, 10.1.2.236, partition 32, ANY, 5374 bytes)
17/01/29 07:43:43,824 INFO CoarseGrainedSchedulerBackend$DriverEndpoint: Launching task 34 on executor id: 3 hostname: 10.1.2.236.
17/01/29 07:43:43,824 INFO TaskSetManager: Finished task 16.0 in stage 1.0 (TID 18) in 22745 ms on 10.1.2.236 (18/59)
17/01/29 07:43:51,237 INFO BlockManagerInfo: Added rdd_5_22 in memory on 10.1.2.181:41485 (size: 69.8 MB, free: 1770.8 MB)
17/01/29 07:43:51,256 INFO BlockManagerInfo: Added rdd_5_23 in memory on 10.1.2.71:38877 (size: 69.9 MB, free: 1770.6 MB)
17/01/29 07:43:51,259 INFO TaskSetManager: Finished task 22.0 in stage 1.0 (TID 24) in 17273 ms on 10.1.2.181 (19/59)
17/01/29 07:43:51,261 INFO TaskSetManager: Starting task 33.0 in stage 1.0 (TID 35, 10.1.2.181, partition 33, ANY, 5374 bytes)
17/01/29 07:43:51,262 INFO CoarseGrainedSchedulerBackend$DriverEndpoint: Launching task 35 on executor id: 2 hostname: 10.1.2.181.
17/01/29 07:43:51,271 INFO BlockManagerInfo: Added rdd_5_19 in memory on 10.1.2.181:41485 (size: 70.0 MB, free: 1700.8 MB)
17/01/29 07:43:51,273 INFO TaskSetManager: Starting task 34.0 in stage 1.0 (TID 36, 10.1.2.71, partition 34, ANY, 5374 bytes)
17/01/29 07:43:51,273 INFO CoarseGrainedSchedulerBackend$DriverEndpoint: Launching task 36 on executor id: 0 hostname: 10.1.2.71.
17/01/29 07:43:51,274 INFO TaskSetManager: Finished task 23.0 in stage 1.0 (TID 25) in 16787 ms on 10.1.2.71 (20/59)
17/01/29 07:43:51,292 INFO TaskSetManager: Finished task 19.0 in stage 1.0 (TID 21) in 17429 ms on 10.1.2.181 (21/59)
17/01/29 07:43:51,294 INFO TaskSetManager: Starting task 35.0 in stage 1.0 (TID 37, 10.1.2.181, partition 35, ANY, 5374 bytes)
17/01/29 07:43:51,294 INFO CoarseGrainedSchedulerBackend$DriverEndpoint: Launching task 37 on executor id: 2 hostname: 10.1.2.181.
17/01/29 07:43:51,361 INFO BlockManagerInfo: Added rdd_5_21 in memory on 10.1.2.181:41485 (size: 69.9 MB, free: 1630.9 MB)
17/01/29 07:43:51,383 INFO TaskSetManager: Starting task 36.0 in stage 1.0 (TID 38, 10.1.2.181, partition 36, ANY, 5374 bytes)
17/01/29 07:43:51,383 INFO CoarseGrainedSchedulerBackend$DriverEndpoint: Launching task 38 on executor id: 2 hostname: 10.1.2.181.
17/01/29 07:43:51,383 INFO TaskSetManager: Finished task 21.0 in stage 1.0 (TID 23) in 17436 ms on 10.1.2.181 (22/59)
17/01/29 07:43:51,437 INFO BlockManagerInfo: Added rdd_5_27 in memory on 10.1.2.71:38877 (size: 69.9 MB, free: 1700.7 MB)
17/01/29 07:43:51,453 INFO TaskSetManager: Starting task 37.0 in stage 1.0 (TID 39, 10.1.2.71, partition 37, ANY, 5374 bytes)
17/01/29 07:43:51,453 INFO CoarseGrainedSchedulerBackend$DriverEndpoint: Launching task 39 on executor id: 0 hostname: 10.1.2.71.
17/01/29 07:43:51,453 INFO TaskSetManager: Finished task 27.0 in stage 1.0 (TID 29) in 16563 ms on 10.1.2.71 (23/59)
17/01/29 07:43:51,463 INFO BlockManagerInfo: Added rdd_5_26 in memory on 10.1.2.71:38877 (size: 69.9 MB, free: 1630.8 MB)
17/01/29 07:43:51,476 INFO BlockManagerInfo: Added rdd_5_25 in memory on 10.1.2.71:38877 (size: 70.0 MB, free: 1560.9 MB)
17/01/29 07:43:51,492 INFO TaskSetManager: Starting task 38.0 in stage 1.0 (TID 40, 10.1.2.71, partition 38, ANY, 5374 bytes)
17/01/29 07:43:51,492 INFO CoarseGrainedSchedulerBackend$DriverEndpoint: Launching task 40 on executor id: 0 hostname: 10.1.2.71.
17/01/29 07:43:51,495 INFO TaskSetManager: Starting task 39.0 in stage 1.0 (TID 41, 10.1.2.71, partition 39, ANY, 5374 bytes)
17/01/29 07:43:51,495 INFO CoarseGrainedSchedulerBackend$DriverEndpoint: Launching task 41 on executor id: 0 hostname: 10.1.2.71.
17/01/29 07:43:51,496 INFO TaskSetManager: Finished task 25.0 in stage 1.0 (TID 27) in 16740 ms on 10.1.2.71 (24/59)
17/01/29 07:43:51,496 INFO TaskSetManager: Finished task 26.0 in stage 1.0 (TID 28) in 16728 ms on 10.1.2.71 (25/59)
17/01/29 07:43:52,106 INFO BlockManagerInfo: Added rdd_5_18 in memory on 10.1.2.181:41485 (size: 70.0 MB, free: 1560.9 MB)
17/01/29 07:43:52,127 INFO TaskSetManager: Starting task 40.0 in stage 1.0 (TID 42, 10.1.2.181, partition 40, ANY, 5374 bytes)
17/01/29 07:43:52,127 INFO CoarseGrainedSchedulerBackend$DriverEndpoint: Launching task 42 on executor id: 2 hostname: 10.1.2.181.
17/01/29 07:43:52,128 INFO TaskSetManager: Finished task 18.0 in stage 1.0 (TID 20) in 18380 ms on 10.1.2.181 (26/59)
17/01/29 07:43:55,639 INFO BlockManagerInfo: Added rdd_5_28 in memory on 10.1.2.236:38599 (size: 70.0 MB, free: 1627.9 MB)
17/01/29 07:43:55,661 INFO TaskSetManager: Starting task 41.0 in stage 1.0 (TID 43, 10.1.2.236, partition 41, ANY, 5374 bytes)
17/01/29 07:43:55,661 INFO CoarseGrainedSchedulerBackend$DriverEndpoint: Launching task 43 on executor id: 3 hostname: 10.1.2.236.
17/01/29 07:43:55,662 INFO TaskSetManager: Finished task 28.0 in stage 1.0 (TID 30) in 19522 ms on 10.1.2.236 (27/59)
17/01/29 07:43:56,560 INFO BlockManagerInfo: Added rdd_5_20 in memory on 10.1.2.236:38599 (size: 69.8 MB, free: 1558.1 MB)
17/01/29 07:43:56,576 INFO TaskSetManager: Starting task 42.0 in stage 1.0 (TID 44, 10.1.2.236, partition 42, ANY, 5374 bytes)
17/01/29 07:43:56,577 INFO CoarseGrainedSchedulerBackend$DriverEndpoint: Launching task 44 on executor id: 3 hostname: 10.1.2.236.
17/01/29 07:43:56,577 INFO TaskSetManager: Finished task 20.0 in stage 1.0 (TID 22) in 22666 ms on 10.1.2.236 (28/59)
17/01/29 07:43:57,174 INFO BlockManagerInfo: Added rdd_5_24 in memory on 10.1.2.63:44673 (size: 69.8 MB, free: 1770.8 MB)
17/01/29 07:43:57,193 INFO TaskSetManager: Starting task 43.0 in stage 1.0 (TID 45, 10.1.2.63, partition 43, ANY, 5374 bytes)
17/01/29 07:43:57,193 INFO CoarseGrainedSchedulerBackend$DriverEndpoint: Launching task 45 on executor id: 1 hostname: 10.1.2.63.
17/01/29 07:43:57,193 INFO TaskSetManager: Finished task 24.0 in stage 1.0 (TID 26) in 22474 ms on 10.1.2.63 (29/59)
17/01/29 07:43:59,584 INFO BlockManagerInfo: Added rdd_5_17 in memory on 10.1.2.236:38599 (size: 69.9 MB, free: 1488.2 MB)
17/01/29 07:43:59,600 INFO TaskSetManager: Starting task 44.0 in stage 1.0 (TID 46, 10.1.2.236, partition 44, ANY, 5374 bytes)
17/01/29 07:43:59,600 INFO CoarseGrainedSchedulerBackend$DriverEndpoint: Launching task 46 on executor id: 3 hostname: 10.1.2.236.
17/01/29 07:43:59,600 INFO TaskSetManager: Finished task 17.0 in stage 1.0 (TID 19) in 26502 ms on 10.1.2.236 (30/59)
17/01/29 07:43:59,899 INFO BlockManagerInfo: Added rdd_5_30 in memory on 10.1.2.63:44673 (size: 70.0 MB, free: 1700.9 MB)
17/01/29 07:43:59,914 INFO TaskSetManager: Starting task 45.0 in stage 1.0 (TID 47, 10.1.2.63, partition 45, ANY, 5374 bytes)
17/01/29 07:43:59,914 INFO CoarseGrainedSchedulerBackend$DriverEndpoint: Launching task 47 on executor id: 1 hostname: 10.1.2.63.
17/01/29 07:43:59,915 INFO TaskSetManager: Finished task 30.0 in stage 1.0 (TID 32) in 23190 ms on 10.1.2.63 (31/59)
17/01/29 07:44:00,159 INFO BlockManagerInfo: Added rdd_5_31 in memory on 10.1.2.63:44673 (size: 69.7 MB, free: 1631.1 MB)
17/01/29 07:44:00,174 INFO TaskSetManager: Starting task 46.0 in stage 1.0 (TID 48, 10.1.2.63, partition 46, ANY, 5374 bytes)
17/01/29 07:44:00,174 INFO CoarseGrainedSchedulerBackend$DriverEndpoint: Launching task 48 on executor id: 1 hostname: 10.1.2.63.
17/01/29 07:44:00,175 INFO TaskSetManager: Finished task 31.0 in stage 1.0 (TID 33) in 23077 ms on 10.1.2.63 (32/59)
17/01/29 07:44:00,978 INFO BlockManagerInfo: Added rdd_5_29 in memory on 10.1.2.63:44673 (size: 69.9 MB, free: 1561.2 MB)
17/01/29 07:44:00,998 INFO TaskSetManager: Starting task 47.0 in stage 1.0 (TID 49, 10.1.2.63, partition 47, ANY, 5374 bytes)
17/01/29 07:44:00,999 INFO CoarseGrainedSchedulerBackend$DriverEndpoint: Launching task 49 on executor id: 1 hostname: 10.1.2.63.
17/01/29 07:44:00,999 INFO TaskSetManager: Finished task 29.0 in stage 1.0 (TID 31) in 24581 ms on 10.1.2.63 (33/59)
17/01/29 07:44:05,251 INFO BlockManagerInfo: Added rdd_5_32 in memory on 10.1.2.236:38599 (size: 69.9 MB, free: 1418.3 MB)
17/01/29 07:44:05,268 INFO TaskSetManager: Starting task 48.0 in stage 1.0 (TID 50, 10.1.2.236, partition 48, ANY, 5374 bytes)
17/01/29 07:44:05,268 INFO CoarseGrainedSchedulerBackend$DriverEndpoint: Launching task 50 on executor id: 3 hostname: 10.1.2.236.
17/01/29 07:44:05,268 INFO TaskSetManager: Finished task 32.0 in stage 1.0 (TID 34) in 21447 ms on 10.1.2.236 (34/59)
17/01/29 07:44:09,148 INFO BlockManagerInfo: Added rdd_5_36 in memory on 10.1.2.181:41485 (size: 70.0 MB, free: 1490.9 MB)
17/01/29 07:44:09,169 INFO TaskSetManager: Starting task 49.0 in stage 1.0 (TID 51, 10.1.2.181, partition 49, ANY, 5374 bytes)
17/01/29 07:44:09,170 INFO CoarseGrainedSchedulerBackend$DriverEndpoint: Launching task 51 on executor id: 2 hostname: 10.1.2.181.
17/01/29 07:44:09,170 INFO TaskSetManager: Finished task 36.0 in stage 1.0 (TID 38) in 17788 ms on 10.1.2.181 (35/59)
17/01/29 07:44:09,241 INFO BlockManagerInfo: Added rdd_5_35 in memory on 10.1.2.181:41485 (size: 70.0 MB, free: 1420.9 MB)
17/01/29 07:44:09,264 INFO TaskSetManager: Starting task 50.0 in stage 1.0 (TID 52, 10.1.2.181, partition 50, ANY, 5374 bytes)
17/01/29 07:44:09,265 INFO CoarseGrainedSchedulerBackend$DriverEndpoint: Launching task 52 on executor id: 2 hostname: 10.1.2.181.
17/01/29 07:44:09,265 INFO TaskSetManager: Finished task 35.0 in stage 1.0 (TID 37) in 17973 ms on 10.1.2.181 (36/59)
17/01/29 07:44:09,282 INFO BlockManagerInfo: Added rdd_5_33 in memory on 10.1.2.181:41485 (size: 69.9 MB, free: 1351.0 MB)
17/01/29 07:44:09,285 INFO BlockManagerInfo: Added rdd_5_40 in memory on 10.1.2.181:41485 (size: 70.0 MB, free: 1281.0 MB)
17/01/29 07:44:09,304 INFO TaskSetManager: Starting task 51.0 in stage 1.0 (TID 53, 10.1.2.181, partition 51, ANY, 5374 bytes)
17/01/29 07:44:09,304 INFO CoarseGrainedSchedulerBackend$DriverEndpoint: Launching task 53 on executor id: 2 hostname: 10.1.2.181.
17/01/29 07:44:09,305 INFO TaskSetManager: Starting task 52.0 in stage 1.0 (TID 54, 10.1.2.181, partition 52, ANY, 5374 bytes)
17/01/29 07:44:09,306 INFO CoarseGrainedSchedulerBackend$DriverEndpoint: Launching task 54 on executor id: 2 hostname: 10.1.2.181.
17/01/29 07:44:09,306 INFO TaskSetManager: Finished task 40.0 in stage 1.0 (TID 42) in 17181 ms on 10.1.2.181 (37/59)
17/01/29 07:44:09,307 INFO TaskSetManager: Finished task 33.0 in stage 1.0 (TID 35) in 18046 ms on 10.1.2.181 (38/59)
17/01/29 07:44:13,164 INFO BlockManagerInfo: Added rdd_5_34 in memory on 10.1.2.71:38877 (size: 70.0 MB, free: 1490.9 MB)
17/01/29 07:44:13,181 INFO TaskSetManager: Starting task 53.0 in stage 1.0 (TID 55, 10.1.2.71, partition 53, ANY, 5374 bytes)
17/01/29 07:44:13,181 INFO CoarseGrainedSchedulerBackend$DriverEndpoint: Launching task 55 on executor id: 0 hostname: 10.1.2.71.
17/01/29 07:44:13,182 INFO TaskSetManager: Finished task 34.0 in stage 1.0 (TID 36) in 21909 ms on 10.1.2.71 (39/59)
17/01/29 07:44:13,796 INFO BlockManagerInfo: Added rdd_5_39 in memory on 10.1.2.71:38877 (size: 70.0 MB, free: 1420.9 MB)
17/01/29 07:44:13,811 INFO TaskSetManager: Starting task 54.0 in stage 1.0 (TID 56, 10.1.2.71, partition 54, ANY, 5374 bytes)
17/01/29 07:44:13,812 INFO CoarseGrainedSchedulerBackend$DriverEndpoint: Launching task 56 on executor id: 0 hostname: 10.1.2.71.
17/01/29 07:44:13,812 INFO TaskSetManager: Finished task 39.0 in stage 1.0 (TID 41) in 22319 ms on 10.1.2.71 (40/59)
17/01/29 07:44:13,845 INFO BlockManagerInfo: Added rdd_5_37 in memory on 10.1.2.71:38877 (size: 69.9 MB, free: 1351.0 MB)
17/01/29 07:44:13,867 INFO TaskSetManager: Starting task 55.0 in stage 1.0 (TID 57, 10.1.2.71, partition 55, ANY, 5374 bytes)
17/01/29 07:44:13,867 INFO CoarseGrainedSchedulerBackend$DriverEndpoint: Launching task 57 on executor id: 0 hostname: 10.1.2.71.
17/01/29 07:44:13,868 INFO TaskSetManager: Finished task 37.0 in stage 1.0 (TID 39) in 22415 ms on 10.1.2.71 (41/59)
17/01/29 07:44:13,901 INFO BlockManagerInfo: Added rdd_5_38 in memory on 10.1.2.71:38877 (size: 70.0 MB, free: 1281.0 MB)
17/01/29 07:44:13,919 INFO TaskSetManager: Starting task 56.0 in stage 1.0 (TID 58, 10.1.2.71, partition 56, ANY, 5374 bytes)
17/01/29 07:44:13,919 INFO CoarseGrainedSchedulerBackend$DriverEndpoint: Launching task 58 on executor id: 0 hostname: 10.1.2.71.
17/01/29 07:44:13,920 INFO TaskSetManager: Finished task 38.0 in stage 1.0 (TID 40) in 22429 ms on 10.1.2.71 (42/59)
17/01/29 07:44:16,778 INFO BlockManagerInfo: Added rdd_5_42 in memory on 10.1.2.236:38599 (size: 69.8 MB, free: 1348.5 MB)
17/01/29 07:44:16,795 INFO TaskSetManager: Starting task 57.0 in stage 1.0 (TID 59, 10.1.2.236, partition 57, ANY, 5374 bytes)
17/01/29 07:44:16,796 INFO CoarseGrainedSchedulerBackend$DriverEndpoint: Launching task 59 on executor id: 3 hostname: 10.1.2.236.
17/01/29 07:44:16,796 INFO TaskSetManager: Finished task 42.0 in stage 1.0 (TID 44) in 20221 ms on 10.1.2.236 (43/59)
17/01/29 07:44:18,591 INFO BlockManagerInfo: Added rdd_5_41 in memory on 10.1.2.236:38599 (size: 70.0 MB, free: 1278.5 MB)
17/01/29 07:44:18,610 INFO TaskSetManager: Finished task 41.0 in stage 1.0 (TID 43) in 22949 ms on 10.1.2.236 (44/59)
17/01/29 07:44:18,989 INFO BlockManagerInfo: Added rdd_5_44 in memory on 10.1.2.236:38599 (size: 70.0 MB, free: 1208.5 MB)
17/01/29 07:44:19,005 INFO TaskSetManager: Finished task 44.0 in stage 1.0 (TID 46) in 19406 ms on 10.1.2.236 (45/59)
17/01/29 07:44:19,610 INFO BlockManagerInfo: Added rdd_5_43 in memory on 10.1.2.63:44673 (size: 69.8 MB, free: 1491.4 MB)
17/01/29 07:44:19,625 INFO TaskSetManager: Finished task 43.0 in stage 1.0 (TID 45) in 22433 ms on 10.1.2.63 (46/59)
17/01/29 07:44:20,966 INFO BlockManagerInfo: Added rdd_5_46 in memory on 10.1.2.63:44673 (size: 69.9 MB, free: 1421.4 MB)
17/01/29 07:44:20,982 INFO TaskSetManager: Finished task 46.0 in stage 1.0 (TID 48) in 20809 ms on 10.1.2.63 (47/59)
17/01/29 07:44:21,072 INFO BlockManagerInfo: Added rdd_5_45 in memory on 10.1.2.63:44673 (size: 69.9 MB, free: 1351.5 MB)
17/01/29 07:44:21,087 INFO TaskSetManager: Finished task 45.0 in stage 1.0 (TID 47) in 21174 ms on 10.1.2.63 (48/59)
17/01/29 07:44:21,315 INFO BlockManagerInfo: Added rdd_5_47 in memory on 10.1.2.63:44673 (size: 70.0 MB, free: 1281.6 MB)
17/01/29 07:44:21,329 INFO TaskSetManager: Finished task 47.0 in stage 1.0 (TID 49) in 20332 ms on 10.1.2.63 (49/59)
17/01/29 07:44:21,658 INFO BlockManagerInfo: Added rdd_5_48 in memory on 10.1.2.236:38599 (size: 69.9 MB, free: 1138.6 MB)
17/01/29 07:44:21,680 INFO TaskSetManager: Finished task 48.0 in stage 1.0 (TID 50) in 16412 ms on 10.1.2.236 (50/59)
17/01/29 07:44:24,815 INFO BlockManagerInfo: Added rdd_5_57 in memory on 10.1.2.236:38599 (size: 70.1 MB, free: 1068.6 MB)
17/01/29 07:44:24,836 INFO TaskSetManager: Finished task 57.0 in stage 1.0 (TID 59) in 8042 ms on 10.1.2.236 (51/59)
17/01/29 07:44:26,423 INFO BlockManagerInfo: Added rdd_5_49 in memory on 10.1.2.181:41485 (size: 69.8 MB, free: 1211.2 MB)
17/01/29 07:44:26,445 INFO TaskSetManager: Finished task 49.0 in stage 1.0 (TID 51) in 17276 ms on 10.1.2.181 (52/59)
17/01/29 07:44:26,451 INFO BlockManagerInfo: Added rdd_5_51 in memory on 10.1.2.181:41485 (size: 69.9 MB, free: 1141.3 MB)
17/01/29 07:44:26,471 INFO TaskSetManager: Finished task 51.0 in stage 1.0 (TID 53) in 17168 ms on 10.1.2.181 (53/59)
17/01/29 07:44:26,738 INFO BlockManagerInfo: Added rdd_5_52 in memory on 10.1.2.181:41485 (size: 69.9 MB, free: 1071.5 MB)
17/01/29 07:44:26,757 INFO TaskSetManager: Finished task 52.0 in stage 1.0 (TID 54) in 17451 ms on 10.1.2.181 (54/59)
17/01/29 07:44:26,861 INFO BlockManagerInfo: Added rdd_5_50 in memory on 10.1.2.181:41485 (size: 69.9 MB, free: 1001.6 MB)
17/01/29 07:44:26,880 INFO TaskSetManager: Finished task 50.0 in stage 1.0 (TID 52) in 17617 ms on 10.1.2.181 (55/59)
17/01/29 07:44:32,301 INFO BlockManagerInfo: Added rdd_5_54 in memory on 10.1.2.71:38877 (size: 69.9 MB, free: 1211.0 MB)
17/01/29 07:44:32,316 INFO TaskSetManager: Finished task 54.0 in stage 1.0 (TID 56) in 18506 ms on 10.1.2.71 (56/59)
17/01/29 07:44:33,223 INFO BlockManagerInfo: Added rdd_5_56 in memory on 10.1.2.71:38877 (size: 69.9 MB, free: 1141.1 MB)
17/01/29 07:44:33,249 INFO TaskSetManager: Finished task 56.0 in stage 1.0 (TID 58) in 19331 ms on 10.1.2.71 (57/59)
17/01/29 07:44:33,328 INFO BlockManagerInfo: Added rdd_5_53 in memory on 10.1.2.71:38877 (size: 70.0 MB, free: 1071.1 MB)
17/01/29 07:44:33,344 INFO TaskSetManager: Finished task 53.0 in stage 1.0 (TID 55) in 20164 ms on 10.1.2.71 (58/59)
17/01/29 07:44:33,380 INFO BlockManagerInfo: Added rdd_5_55 in memory on 10.1.2.71:38877 (size: 69.9 MB, free: 1001.2 MB)
17/01/29 07:44:33,394 INFO TaskSetManager: Finished task 55.0 in stage 1.0 (TID 57) in 19528 ms on 10.1.2.71 (59/59)
17/01/29 07:44:33,395 INFO TaskSchedulerImpl: Removed TaskSet 1.0, whose tasks have all completed, from pool 
17/01/29 07:44:33,395 INFO DAGScheduler: ResultStage 1 (count at DataValidators.scala:40) finished in 84.195 s
17/01/29 07:44:33,396 INFO DAGScheduler: Job 1 finished: count at DataValidators.scala:40, took 84.242597 s
17/01/29 07:44:33,405 INFO SparkContext: Starting job: count at GradientDescent.scala:209
17/01/29 07:44:33,407 INFO DAGScheduler: Got job 2 (count at GradientDescent.scala:209) with 59 output partitions
17/01/29 07:44:33,407 INFO DAGScheduler: Final stage: ResultStage 2 (count at GradientDescent.scala:209)
17/01/29 07:44:33,407 INFO DAGScheduler: Parents of final stage: List()
17/01/29 07:44:33,410 INFO DAGScheduler: Missing parents: List()
17/01/29 07:44:33,411 INFO DAGScheduler: Submitting ResultStage 2 (MapPartitionsRDD[8] at map at GeneralizedLinearAlgorithm.scala:297), which has no missing parents
17/01/29 07:44:33,417 INFO MemoryStore: Block broadcast_3 stored as values in memory (estimated size 3.9 KB, free 2.1 GB)
17/01/29 07:44:33,421 INFO MemoryStore: Block broadcast_3_piece0 stored as bytes in memory (estimated size 2.2 KB, free 2.1 GB)
17/01/29 07:44:33,422 INFO BlockManagerInfo: Added broadcast_3_piece0 in memory on 10.1.2.142:37340 (size: 2.2 KB, free: 2.1 GB)
17/01/29 07:44:33,423 INFO SparkContext: Created broadcast 3 from broadcast at DAGScheduler.scala:1012
17/01/29 07:44:33,424 INFO DAGScheduler: Submitting 59 missing tasks from ResultStage 2 (MapPartitionsRDD[8] at map at GeneralizedLinearAlgorithm.scala:297)
17/01/29 07:44:33,425 INFO TaskSchedulerImpl: Adding task set 2.0 with 59 tasks
17/01/29 07:44:33,431 INFO TaskSetManager: Starting task 0.0 in stage 2.0 (TID 60, 10.1.2.236, partition 0, PROCESS_LOCAL, 5374 bytes)
17/01/29 07:44:33,431 INFO TaskSetManager: Starting task 1.0 in stage 2.0 (TID 61, 10.1.2.63, partition 1, PROCESS_LOCAL, 5374 bytes)
17/01/29 07:44:33,432 INFO TaskSetManager: Starting task 4.0 in stage 2.0 (TID 62, 10.1.2.71, partition 4, PROCESS_LOCAL, 5374 bytes)
17/01/29 07:44:33,433 INFO TaskSetManager: Starting task 2.0 in stage 2.0 (TID 63, 10.1.2.181, partition 2, PROCESS_LOCAL, 5374 bytes)
17/01/29 07:44:33,434 INFO TaskSetManager: Starting task 3.0 in stage 2.0 (TID 64, 10.1.2.236, partition 3, PROCESS_LOCAL, 5374 bytes)
17/01/29 07:44:33,435 INFO TaskSetManager: Starting task 5.0 in stage 2.0 (TID 65, 10.1.2.63, partition 5, PROCESS_LOCAL, 5374 bytes)
17/01/29 07:44:33,436 INFO TaskSetManager: Starting task 8.0 in stage 2.0 (TID 66, 10.1.2.71, partition 8, PROCESS_LOCAL, 5374 bytes)
17/01/29 07:44:33,436 INFO TaskSetManager: Starting task 6.0 in stage 2.0 (TID 67, 10.1.2.181, partition 6, PROCESS_LOCAL, 5374 bytes)
17/01/29 07:44:33,437 INFO TaskSetManager: Starting task 7.0 in stage 2.0 (TID 68, 10.1.2.236, partition 7, PROCESS_LOCAL, 5374 bytes)
17/01/29 07:44:33,438 INFO TaskSetManager: Starting task 9.0 in stage 2.0 (TID 69, 10.1.2.63, partition 9, PROCESS_LOCAL, 5374 bytes)
17/01/29 07:44:33,439 INFO TaskSetManager: Starting task 12.0 in stage 2.0 (TID 70, 10.1.2.71, partition 12, PROCESS_LOCAL, 5374 bytes)
17/01/29 07:44:33,439 INFO TaskSetManager: Starting task 10.0 in stage 2.0 (TID 71, 10.1.2.181, partition 10, PROCESS_LOCAL, 5374 bytes)
17/01/29 07:44:33,441 INFO TaskSetManager: Starting task 11.0 in stage 2.0 (TID 72, 10.1.2.236, partition 11, PROCESS_LOCAL, 5374 bytes)
17/01/29 07:44:33,442 INFO TaskSetManager: Starting task 13.0 in stage 2.0 (TID 73, 10.1.2.63, partition 13, PROCESS_LOCAL, 5374 bytes)
17/01/29 07:44:33,443 INFO TaskSetManager: Starting task 15.0 in stage 2.0 (TID 74, 10.1.2.71, partition 15, PROCESS_LOCAL, 5374 bytes)
17/01/29 07:44:33,444 INFO TaskSetManager: Starting task 14.0 in stage 2.0 (TID 75, 10.1.2.181, partition 14, PROCESS_LOCAL, 5374 bytes)
17/01/29 07:44:33,444 INFO CoarseGrainedSchedulerBackend$DriverEndpoint: Launching task 60 on executor id: 3 hostname: 10.1.2.236.
17/01/29 07:44:33,445 INFO CoarseGrainedSchedulerBackend$DriverEndpoint: Launching task 64 on executor id: 3 hostname: 10.1.2.236.
17/01/29 07:44:33,446 INFO CoarseGrainedSchedulerBackend$DriverEndpoint: Launching task 68 on executor id: 3 hostname: 10.1.2.236.
17/01/29 07:44:33,446 INFO CoarseGrainedSchedulerBackend$DriverEndpoint: Launching task 72 on executor id: 3 hostname: 10.1.2.236.
17/01/29 07:44:33,447 INFO CoarseGrainedSchedulerBackend$DriverEndpoint: Launching task 61 on executor id: 1 hostname: 10.1.2.63.
17/01/29 07:44:33,448 INFO CoarseGrainedSchedulerBackend$DriverEndpoint: Launching task 65 on executor id: 1 hostname: 10.1.2.63.
17/01/29 07:44:33,448 INFO CoarseGrainedSchedulerBackend$DriverEndpoint: Launching task 69 on executor id: 1 hostname: 10.1.2.63.
17/01/29 07:44:33,449 INFO CoarseGrainedSchedulerBackend$DriverEndpoint: Launching task 73 on executor id: 1 hostname: 10.1.2.63.
17/01/29 07:44:33,449 INFO CoarseGrainedSchedulerBackend$DriverEndpoint: Launching task 62 on executor id: 0 hostname: 10.1.2.71.
17/01/29 07:44:33,450 INFO CoarseGrainedSchedulerBackend$DriverEndpoint: Launching task 66 on executor id: 0 hostname: 10.1.2.71.
17/01/29 07:44:33,451 INFO CoarseGrainedSchedulerBackend$DriverEndpoint: Launching task 70 on executor id: 0 hostname: 10.1.2.71.
17/01/29 07:44:33,451 INFO CoarseGrainedSchedulerBackend$DriverEndpoint: Launching task 74 on executor id: 0 hostname: 10.1.2.71.
17/01/29 07:44:33,452 INFO CoarseGrainedSchedulerBackend$DriverEndpoint: Launching task 63 on executor id: 2 hostname: 10.1.2.181.
17/01/29 07:44:33,453 INFO CoarseGrainedSchedulerBackend$DriverEndpoint: Launching task 67 on executor id: 2 hostname: 10.1.2.181.
17/01/29 07:44:33,453 INFO CoarseGrainedSchedulerBackend$DriverEndpoint: Launching task 71 on executor id: 2 hostname: 10.1.2.181.
17/01/29 07:44:33,454 INFO CoarseGrainedSchedulerBackend$DriverEndpoint: Launching task 75 on executor id: 2 hostname: 10.1.2.181.
17/01/29 07:44:33,477 INFO BlockManagerInfo: Added broadcast_3_piece0 in memory on 10.1.2.236:38599 (size: 2.2 KB, free: 1068.6 MB)
17/01/29 07:44:33,479 INFO BlockManagerInfo: Added broadcast_3_piece0 in memory on 10.1.2.71:38877 (size: 2.2 KB, free: 1001.2 MB)
17/01/29 07:44:33,511 INFO TaskSetManager: Starting task 16.0 in stage 2.0 (TID 76, 10.1.2.236, partition 16, PROCESS_LOCAL, 5374 bytes)
17/01/29 07:44:33,511 INFO CoarseGrainedSchedulerBackend$DriverEndpoint: Launching task 76 on executor id: 3 hostname: 10.1.2.236.
17/01/29 07:44:33,511 INFO TaskSetManager: Finished task 11.0 in stage 2.0 (TID 72) in 71 ms on 10.1.2.236 (1/59)
17/01/29 07:44:33,512 INFO TaskSetManager: Starting task 17.0 in stage 2.0 (TID 77, 10.1.2.236, partition 17, PROCESS_LOCAL, 5374 bytes)
17/01/29 07:44:33,512 INFO CoarseGrainedSchedulerBackend$DriverEndpoint: Launching task 77 on executor id: 3 hostname: 10.1.2.236.
17/01/29 07:44:33,513 INFO TaskSetManager: Finished task 7.0 in stage 2.0 (TID 68) in 76 ms on 10.1.2.236 (2/59)
17/01/29 07:44:33,514 INFO TaskSetManager: Starting task 20.0 in stage 2.0 (TID 78, 10.1.2.236, partition 20, PROCESS_LOCAL, 5374 bytes)
17/01/29 07:44:33,514 INFO CoarseGrainedSchedulerBackend$DriverEndpoint: Launching task 78 on executor id: 3 hostname: 10.1.2.236.
17/01/29 07:44:33,514 INFO TaskSetManager: Finished task 0.0 in stage 2.0 (TID 60) in 87 ms on 10.1.2.236 (3/59)
17/01/29 07:44:33,518 INFO TaskSetManager: Starting task 28.0 in stage 2.0 (TID 79, 10.1.2.236, partition 28, PROCESS_LOCAL, 5374 bytes)
17/01/29 07:44:33,519 INFO CoarseGrainedSchedulerBackend$DriverEndpoint: Launching task 79 on executor id: 3 hostname: 10.1.2.236.
17/01/29 07:44:33,519 INFO TaskSetManager: Finished task 3.0 in stage 2.0 (TID 64) in 86 ms on 10.1.2.236 (4/59)
17/01/29 07:44:33,523 INFO BlockManagerInfo: Added broadcast_3_piece0 in memory on 10.1.2.63:44673 (size: 2.2 KB, free: 1281.6 MB)
17/01/29 07:44:33,523 INFO TaskSetManager: Starting task 23.0 in stage 2.0 (TID 80, 10.1.2.71, partition 23, PROCESS_LOCAL, 5374 bytes)
17/01/29 07:44:33,523 INFO CoarseGrainedSchedulerBackend$DriverEndpoint: Launching task 80 on executor id: 0 hostname: 10.1.2.71.
17/01/29 07:44:33,524 INFO TaskSetManager: Finished task 8.0 in stage 2.0 (TID 66) in 89 ms on 10.1.2.71 (5/59)
17/01/29 07:44:33,527 INFO TaskSetManager: Starting task 25.0 in stage 2.0 (TID 81, 10.1.2.71, partition 25, PROCESS_LOCAL, 5374 bytes)
17/01/29 07:44:33,527 INFO BlockManagerInfo: Added broadcast_3_piece0 in memory on 10.1.2.181:41485 (size: 2.2 KB, free: 1001.6 MB)
17/01/29 07:44:33,527 INFO CoarseGrainedSchedulerBackend$DriverEndpoint: Launching task 81 on executor id: 0 hostname: 10.1.2.71.
17/01/29 07:44:33,527 INFO TaskSetManager: Finished task 4.0 in stage 2.0 (TID 62) in 96 ms on 10.1.2.71 (6/59)
17/01/29 07:44:33,540 INFO TaskSetManager: Starting task 32.0 in stage 2.0 (TID 82, 10.1.2.236, partition 32, PROCESS_LOCAL, 5374 bytes)
17/01/29 07:44:33,540 INFO CoarseGrainedSchedulerBackend$DriverEndpoint: Launching task 82 on executor id: 3 hostname: 10.1.2.236.
17/01/29 07:44:33,541 INFO TaskSetManager: Finished task 20.0 in stage 2.0 (TID 78) in 27 ms on 10.1.2.236 (7/59)
17/01/29 07:44:33,541 INFO TaskSetManager: Starting task 41.0 in stage 2.0 (TID 83, 10.1.2.236, partition 41, PROCESS_LOCAL, 5374 bytes)
17/01/29 07:44:33,542 INFO CoarseGrainedSchedulerBackend$DriverEndpoint: Launching task 83 on executor id: 3 hostname: 10.1.2.236.
17/01/29 07:44:33,542 INFO TaskSetManager: Finished task 17.0 in stage 2.0 (TID 77) in 30 ms on 10.1.2.236 (8/59)
17/01/29 07:44:33,544 INFO TaskSetManager: Starting task 42.0 in stage 2.0 (TID 84, 10.1.2.236, partition 42, PROCESS_LOCAL, 5374 bytes)
17/01/29 07:44:33,544 INFO CoarseGrainedSchedulerBackend$DriverEndpoint: Launching task 84 on executor id: 3 hostname: 10.1.2.236.
17/01/29 07:44:33,544 INFO TaskSetManager: Finished task 16.0 in stage 2.0 (TID 76) in 35 ms on 10.1.2.236 (9/59)
17/01/29 07:44:33,549 INFO TaskSetManager: Starting task 44.0 in stage 2.0 (TID 85, 10.1.2.236, partition 44, PROCESS_LOCAL, 5374 bytes)
17/01/29 07:44:33,550 INFO CoarseGrainedSchedulerBackend$DriverEndpoint: Launching task 85 on executor id: 3 hostname: 10.1.2.236.
17/01/29 07:44:33,550 INFO TaskSetManager: Finished task 28.0 in stage 2.0 (TID 79) in 32 ms on 10.1.2.236 (10/59)
17/01/29 07:44:33,555 INFO TaskSetManager: Starting task 26.0 in stage 2.0 (TID 86, 10.1.2.71, partition 26, PROCESS_LOCAL, 5374 bytes)
17/01/29 07:44:33,556 INFO CoarseGrainedSchedulerBackend$DriverEndpoint: Launching task 86 on executor id: 0 hostname: 10.1.2.71.
17/01/29 07:44:33,556 INFO TaskSetManager: Finished task 12.0 in stage 2.0 (TID 70) in 118 ms on 10.1.2.71 (11/59)
17/01/29 07:44:33,557 INFO TaskSetManager: Starting task 27.0 in stage 2.0 (TID 87, 10.1.2.71, partition 27, PROCESS_LOCAL, 5374 bytes)
17/01/29 07:44:33,558 INFO CoarseGrainedSchedulerBackend$DriverEndpoint: Launching task 87 on executor id: 0 hostname: 10.1.2.71.
17/01/29 07:44:33,559 INFO TaskSetManager: Finished task 23.0 in stage 2.0 (TID 80) in 35 ms on 10.1.2.71 (12/59)
17/01/29 07:44:33,560 INFO TaskSetManager: Starting task 34.0 in stage 2.0 (TID 88, 10.1.2.71, partition 34, PROCESS_LOCAL, 5374 bytes)
17/01/29 07:44:33,560 INFO CoarseGrainedSchedulerBackend$DriverEndpoint: Launching task 88 on executor id: 0 hostname: 10.1.2.71.
17/01/29 07:44:33,561 INFO TaskSetManager: Finished task 25.0 in stage 2.0 (TID 81) in 35 ms on 10.1.2.71 (13/59)
17/01/29 07:44:33,575 INFO TaskSetManager: Starting task 48.0 in stage 2.0 (TID 89, 10.1.2.236, partition 48, PROCESS_LOCAL, 5374 bytes)
17/01/29 07:44:33,575 INFO CoarseGrainedSchedulerBackend$DriverEndpoint: Launching task 89 on executor id: 3 hostname: 10.1.2.236.
17/01/29 07:44:33,575 INFO TaskSetManager: Finished task 44.0 in stage 2.0 (TID 85) in 26 ms on 10.1.2.236 (14/59)
17/01/29 07:44:33,577 INFO TaskSetManager: Starting task 57.0 in stage 2.0 (TID 90, 10.1.2.236, partition 57, PROCESS_LOCAL, 5374 bytes)
17/01/29 07:44:33,578 INFO CoarseGrainedSchedulerBackend$DriverEndpoint: Launching task 90 on executor id: 3 hostname: 10.1.2.236.
17/01/29 07:44:33,578 INFO TaskSetManager: Finished task 32.0 in stage 2.0 (TID 82) in 39 ms on 10.1.2.236 (15/59)
17/01/29 07:44:33,580 INFO TaskSetManager: Starting task 58.0 in stage 2.0 (TID 91, 10.1.2.236, partition 58, PROCESS_LOCAL, 5374 bytes)
17/01/29 07:44:33,581 INFO CoarseGrainedSchedulerBackend$DriverEndpoint: Launching task 91 on executor id: 3 hostname: 10.1.2.236.
17/01/29 07:44:33,581 INFO TaskSetManager: Finished task 41.0 in stage 2.0 (TID 83) in 40 ms on 10.1.2.236 (16/59)
17/01/29 07:44:33,582 INFO TaskSetManager: Starting task 18.0 in stage 2.0 (TID 92, 10.1.2.181, partition 18, PROCESS_LOCAL, 5374 bytes)
17/01/29 07:44:33,583 INFO CoarseGrainedSchedulerBackend$DriverEndpoint: Launching task 92 on executor id: 2 hostname: 10.1.2.181.
17/01/29 07:44:33,583 INFO TaskSetManager: Finished task 42.0 in stage 2.0 (TID 84) in 40 ms on 10.1.2.236 (17/59)
17/01/29 07:44:33,583 INFO TaskSetManager: Finished task 6.0 in stage 2.0 (TID 67) in 147 ms on 10.1.2.181 (18/59)
17/01/29 07:44:33,587 INFO TaskSetManager: Starting task 37.0 in stage 2.0 (TID 93, 10.1.2.71, partition 37, PROCESS_LOCAL, 5374 bytes)
17/01/29 07:44:33,588 INFO CoarseGrainedSchedulerBackend$DriverEndpoint: Launching task 93 on executor id: 0 hostname: 10.1.2.71.
17/01/29 07:44:33,588 INFO TaskSetManager: Finished task 34.0 in stage 2.0 (TID 88) in 28 ms on 10.1.2.71 (19/59)
17/01/29 07:44:33,592 INFO TaskSetManager: Starting task 38.0 in stage 2.0 (TID 94, 10.1.2.71, partition 38, PROCESS_LOCAL, 5374 bytes)
17/01/29 07:44:33,592 INFO CoarseGrainedSchedulerBackend$DriverEndpoint: Launching task 94 on executor id: 0 hostname: 10.1.2.71.
17/01/29 07:44:33,593 INFO TaskSetManager: Starting task 39.0 in stage 2.0 (TID 95, 10.1.2.71, partition 39, PROCESS_LOCAL, 5374 bytes)
17/01/29 07:44:33,594 INFO CoarseGrainedSchedulerBackend$DriverEndpoint: Launching task 95 on executor id: 0 hostname: 10.1.2.71.
17/01/29 07:44:33,594 INFO TaskSetManager: Finished task 26.0 in stage 2.0 (TID 86) in 38 ms on 10.1.2.71 (20/59)
17/01/29 07:44:33,594 INFO TaskSetManager: Finished task 27.0 in stage 2.0 (TID 87) in 37 ms on 10.1.2.71 (21/59)
17/01/29 07:44:33,595 INFO TaskSetManager: Finished task 9.0 in stage 2.0 (TID 69) in 158 ms on 10.1.2.63 (22/59)
17/01/29 07:44:33,596 INFO TaskSetManager: Starting task 24.0 in stage 2.0 (TID 96, 10.1.2.63, partition 24, PROCESS_LOCAL, 5374 bytes)
17/01/29 07:44:33,597 INFO CoarseGrainedSchedulerBackend$DriverEndpoint: Launching task 96 on executor id: 1 hostname: 10.1.2.63.
17/01/29 07:44:33,597 INFO TaskSetManager: Finished task 48.0 in stage 2.0 (TID 89) in 23 ms on 10.1.2.236 (23/59)
17/01/29 07:44:33,601 INFO TaskSetManager: Starting task 29.0 in stage 2.0 (TID 97, 10.1.2.63, partition 29, PROCESS_LOCAL, 5374 bytes)
17/01/29 07:44:33,601 INFO CoarseGrainedSchedulerBackend$DriverEndpoint: Launching task 97 on executor id: 1 hostname: 10.1.2.63.
17/01/29 07:44:33,601 INFO TaskSetManager: Finished task 5.0 in stage 2.0 (TID 65) in 167 ms on 10.1.2.63 (24/59)
17/01/29 07:44:33,603 INFO TaskSetManager: Finished task 58.0 in stage 2.0 (TID 91) in 23 ms on 10.1.2.236 (25/59)
17/01/29 07:44:33,610 INFO TaskSetManager: Finished task 57.0 in stage 2.0 (TID 90) in 33 ms on 10.1.2.236 (26/59)
17/01/29 07:44:33,615 INFO TaskSetManager: Starting task 30.0 in stage 2.0 (TID 98, 10.1.2.63, partition 30, PROCESS_LOCAL, 5374 bytes)
17/01/29 07:44:33,616 INFO CoarseGrainedSchedulerBackend$DriverEndpoint: Launching task 98 on executor id: 1 hostname: 10.1.2.63.
17/01/29 07:44:33,616 INFO TaskSetManager: Finished task 13.0 in stage 2.0 (TID 73) in 175 ms on 10.1.2.63 (27/59)
17/01/29 07:44:33,621 INFO TaskSetManager: Starting task 19.0 in stage 2.0 (TID 99, 10.1.2.181, partition 19, PROCESS_LOCAL, 5374 bytes)
17/01/29 07:44:33,621 INFO CoarseGrainedSchedulerBackend$DriverEndpoint: Launching task 99 on executor id: 2 hostname: 10.1.2.181.
17/01/29 07:44:33,621 INFO TaskSetManager: Finished task 18.0 in stage 2.0 (TID 92) in 39 ms on 10.1.2.181 (28/59)
17/01/29 07:44:33,622 INFO TaskSetManager: Starting task 31.0 in stage 2.0 (TID 100, 10.1.2.63, partition 31, PROCESS_LOCAL, 5374 bytes)
17/01/29 07:44:33,623 INFO CoarseGrainedSchedulerBackend$DriverEndpoint: Launching task 100 on executor id: 1 hostname: 10.1.2.63.
17/01/29 07:44:33,623 INFO TaskSetManager: Finished task 24.0 in stage 2.0 (TID 96) in 27 ms on 10.1.2.63 (29/59)
17/01/29 07:44:33,625 INFO TaskSetManager: Starting task 21.0 in stage 2.0 (TID 101, 10.1.2.181, partition 21, PROCESS_LOCAL, 5374 bytes)
17/01/29 07:44:33,625 INFO CoarseGrainedSchedulerBackend$DriverEndpoint: Launching task 101 on executor id: 2 hostname: 10.1.2.181.
17/01/29 07:44:33,625 INFO TaskSetManager: Finished task 14.0 in stage 2.0 (TID 75) in 182 ms on 10.1.2.181 (30/59)
17/01/29 07:44:33,627 INFO TaskSetManager: Starting task 53.0 in stage 2.0 (TID 102, 10.1.2.71, partition 53, PROCESS_LOCAL, 5374 bytes)
17/01/29 07:44:33,628 INFO CoarseGrainedSchedulerBackend$DriverEndpoint: Launching task 102 on executor id: 0 hostname: 10.1.2.71.
17/01/29 07:44:33,628 INFO TaskSetManager: Finished task 37.0 in stage 2.0 (TID 93) in 40 ms on 10.1.2.71 (31/59)
17/01/29 07:44:33,629 INFO TaskSetManager: Starting task 54.0 in stage 2.0 (TID 103, 10.1.2.71, partition 54, PROCESS_LOCAL, 5374 bytes)
17/01/29 07:44:33,629 INFO CoarseGrainedSchedulerBackend$DriverEndpoint: Launching task 103 on executor id: 0 hostname: 10.1.2.71.
17/01/29 07:44:33,629 INFO TaskSetManager: Finished task 39.0 in stage 2.0 (TID 95) in 36 ms on 10.1.2.71 (32/59)
17/01/29 07:44:33,634 INFO TaskSetManager: Starting task 43.0 in stage 2.0 (TID 104, 10.1.2.63, partition 43, PROCESS_LOCAL, 5374 bytes)
17/01/29 07:44:33,634 INFO CoarseGrainedSchedulerBackend$DriverEndpoint: Launching task 104 on executor id: 1 hostname: 10.1.2.63.
17/01/29 07:44:33,635 INFO TaskSetManager: Finished task 29.0 in stage 2.0 (TID 97) in 34 ms on 10.1.2.63 (33/59)
17/01/29 07:44:33,644 INFO TaskSetManager: Starting task 45.0 in stage 2.0 (TID 105, 10.1.2.63, partition 45, PROCESS_LOCAL, 5374 bytes)
17/01/29 07:44:33,644 INFO CoarseGrainedSchedulerBackend$DriverEndpoint: Launching task 105 on executor id: 1 hostname: 10.1.2.63.
17/01/29 07:44:33,644 INFO TaskSetManager: Finished task 30.0 in stage 2.0 (TID 98) in 29 ms on 10.1.2.63 (34/59)
17/01/29 07:44:33,651 INFO TaskSetManager: Starting task 55.0 in stage 2.0 (TID 106, 10.1.2.71, partition 55, PROCESS_LOCAL, 5374 bytes)
17/01/29 07:44:33,651 INFO CoarseGrainedSchedulerBackend$DriverEndpoint: Launching task 106 on executor id: 0 hostname: 10.1.2.71.
17/01/29 07:44:33,651 INFO TaskSetManager: Finished task 38.0 in stage 2.0 (TID 94) in 59 ms on 10.1.2.71 (35/59)
17/01/29 07:44:33,653 INFO TaskSetManager: Starting task 46.0 in stage 2.0 (TID 107, 10.1.2.63, partition 46, PROCESS_LOCAL, 5374 bytes)
17/01/29 07:44:33,653 INFO CoarseGrainedSchedulerBackend$DriverEndpoint: Launching task 107 on executor id: 1 hostname: 10.1.2.63.
17/01/29 07:44:33,654 INFO TaskSetManager: Finished task 1.0 in stage 2.0 (TID 61) in 222 ms on 10.1.2.63 (36/59)
17/01/29 07:44:33,655 INFO TaskSetManager: Starting task 22.0 in stage 2.0 (TID 108, 10.1.2.181, partition 22, PROCESS_LOCAL, 5374 bytes)
17/01/29 07:44:33,655 INFO CoarseGrainedSchedulerBackend$DriverEndpoint: Launching task 108 on executor id: 2 hostname: 10.1.2.181.
17/01/29 07:44:33,655 INFO TaskSetManager: Finished task 21.0 in stage 2.0 (TID 101) in 31 ms on 10.1.2.181 (37/59)
17/01/29 07:44:33,656 INFO TaskSetManager: Starting task 47.0 in stage 2.0 (TID 109, 10.1.2.63, partition 47, PROCESS_LOCAL, 5374 bytes)
17/01/29 07:44:33,656 INFO CoarseGrainedSchedulerBackend$DriverEndpoint: Launching task 109 on executor id: 1 hostname: 10.1.2.63.
17/01/29 07:44:33,656 INFO TaskSetManager: Finished task 31.0 in stage 2.0 (TID 100) in 34 ms on 10.1.2.63 (38/59)
17/01/29 07:44:33,657 INFO TaskSetManager: Starting task 33.0 in stage 2.0 (TID 110, 10.1.2.181, partition 33, PROCESS_LOCAL, 5374 bytes)
17/01/29 07:44:33,658 INFO CoarseGrainedSchedulerBackend$DriverEndpoint: Launching task 110 on executor id: 2 hostname: 10.1.2.181.
17/01/29 07:44:33,658 INFO TaskSetManager: Finished task 10.0 in stage 2.0 (TID 71) in 219 ms on 10.1.2.181 (39/59)
17/01/29 07:44:33,661 INFO TaskSetManager: Finished task 43.0 in stage 2.0 (TID 104) in 27 ms on 10.1.2.63 (40/59)
17/01/29 07:44:33,662 INFO TaskSetManager: Finished task 53.0 in stage 2.0 (TID 102) in 36 ms on 10.1.2.71 (41/59)
17/01/29 07:44:33,663 INFO TaskSetManager: Starting task 56.0 in stage 2.0 (TID 111, 10.1.2.71, partition 56, PROCESS_LOCAL, 5374 bytes)
17/01/29 07:44:33,663 INFO CoarseGrainedSchedulerBackend$DriverEndpoint: Launching task 111 on executor id: 0 hostname: 10.1.2.71.
17/01/29 07:44:33,664 INFO TaskSetManager: Starting task 35.0 in stage 2.0 (TID 112, 10.1.2.181, partition 35, PROCESS_LOCAL, 5374 bytes)
17/01/29 07:44:33,664 INFO CoarseGrainedSchedulerBackend$DriverEndpoint: Launching task 112 on executor id: 2 hostname: 10.1.2.181.
17/01/29 07:44:33,665 INFO TaskSetManager: Finished task 19.0 in stage 2.0 (TID 99) in 44 ms on 10.1.2.181 (42/59)
17/01/29 07:44:33,669 INFO TaskSetManager: Finished task 54.0 in stage 2.0 (TID 103) in 41 ms on 10.1.2.71 (43/59)
17/01/29 07:44:33,672 INFO TaskSetManager: Finished task 45.0 in stage 2.0 (TID 105) in 28 ms on 10.1.2.63 (44/59)
17/01/29 07:44:33,681 INFO TaskSetManager: Finished task 46.0 in stage 2.0 (TID 107) in 27 ms on 10.1.2.63 (45/59)
17/01/29 07:44:33,682 INFO TaskSetManager: Finished task 47.0 in stage 2.0 (TID 109) in 27 ms on 10.1.2.63 (46/59)
17/01/29 07:44:33,688 INFO TaskSetManager: Starting task 36.0 in stage 2.0 (TID 113, 10.1.2.181, partition 36, PROCESS_LOCAL, 5374 bytes)
17/01/29 07:44:33,688 INFO CoarseGrainedSchedulerBackend$DriverEndpoint: Launching task 113 on executor id: 2 hostname: 10.1.2.181.
17/01/29 07:44:33,688 INFO TaskSetManager: Finished task 35.0 in stage 2.0 (TID 112) in 25 ms on 10.1.2.181 (47/59)
17/01/29 07:44:33,689 INFO TaskSetManager: Starting task 40.0 in stage 2.0 (TID 114, 10.1.2.181, partition 40, PROCESS_LOCAL, 5374 bytes)
17/01/29 07:44:33,689 INFO CoarseGrainedSchedulerBackend$DriverEndpoint: Launching task 114 on executor id: 2 hostname: 10.1.2.181.
17/01/29 07:44:33,689 INFO TaskSetManager: Finished task 22.0 in stage 2.0 (TID 108) in 35 ms on 10.1.2.181 (48/59)
17/01/29 07:44:33,690 INFO TaskSetManager: Finished task 55.0 in stage 2.0 (TID 106) in 40 ms on 10.1.2.71 (49/59)
17/01/29 07:44:33,697 INFO TaskSetManager: Starting task 49.0 in stage 2.0 (TID 115, 10.1.2.181, partition 49, PROCESS_LOCAL, 5374 bytes)
17/01/29 07:44:33,697 INFO CoarseGrainedSchedulerBackend$DriverEndpoint: Launching task 115 on executor id: 2 hostname: 10.1.2.181.
17/01/29 07:44:33,697 INFO TaskSetManager: Finished task 33.0 in stage 2.0 (TID 110) in 40 ms on 10.1.2.181 (50/59)
17/01/29 07:44:33,700 INFO TaskSetManager: Finished task 56.0 in stage 2.0 (TID 111) in 38 ms on 10.1.2.71 (51/59)
17/01/29 07:44:33,709 INFO TaskSetManager: Starting task 50.0 in stage 2.0 (TID 116, 10.1.2.181, partition 50, PROCESS_LOCAL, 5374 bytes)
17/01/29 07:44:33,709 INFO CoarseGrainedSchedulerBackend$DriverEndpoint: Launching task 116 on executor id: 2 hostname: 10.1.2.181.
17/01/29 07:44:33,709 INFO TaskSetManager: Finished task 2.0 in stage 2.0 (TID 63) in 277 ms on 10.1.2.181 (52/59)
17/01/29 07:44:33,710 INFO TaskSetManager: Finished task 15.0 in stage 2.0 (TID 74) in 268 ms on 10.1.2.71 (53/59)
17/01/29 07:44:33,714 INFO TaskSetManager: Starting task 51.0 in stage 2.0 (TID 117, 10.1.2.181, partition 51, PROCESS_LOCAL, 5374 bytes)
17/01/29 07:44:33,714 INFO CoarseGrainedSchedulerBackend$DriverEndpoint: Launching task 117 on executor id: 2 hostname: 10.1.2.181.
17/01/29 07:44:33,715 INFO TaskSetManager: Finished task 40.0 in stage 2.0 (TID 114) in 26 ms on 10.1.2.181 (54/59)
17/01/29 07:44:33,723 INFO TaskSetManager: Starting task 52.0 in stage 2.0 (TID 118, 10.1.2.181, partition 52, PROCESS_LOCAL, 5374 bytes)
17/01/29 07:44:33,724 INFO CoarseGrainedSchedulerBackend$DriverEndpoint: Launching task 118 on executor id: 2 hostname: 10.1.2.181.
17/01/29 07:44:33,724 INFO TaskSetManager: Finished task 36.0 in stage 2.0 (TID 113) in 37 ms on 10.1.2.181 (55/59)
17/01/29 07:44:33,745 INFO TaskSetManager: Finished task 52.0 in stage 2.0 (TID 118) in 22 ms on 10.1.2.181 (56/59)
17/01/29 07:44:33,749 INFO TaskSetManager: Finished task 50.0 in stage 2.0 (TID 116) in 41 ms on 10.1.2.181 (57/59)
17/01/29 07:44:33,757 INFO TaskSetManager: Finished task 49.0 in stage 2.0 (TID 115) in 60 ms on 10.1.2.181 (58/59)
17/01/29 07:44:33,758 INFO TaskSetManager: Finished task 51.0 in stage 2.0 (TID 117) in 44 ms on 10.1.2.181 (59/59)
17/01/29 07:44:33,758 INFO TaskSchedulerImpl: Removed TaskSet 2.0, whose tasks have all completed, from pool 
17/01/29 07:44:33,759 INFO DAGScheduler: ResultStage 2 (count at GradientDescent.scala:209) finished in 0.331 s
17/01/29 07:44:33,759 INFO DAGScheduler: Job 2 finished: count at GradientDescent.scala:209, took 0.353853 s
17/01/29 07:44:33,994 WARN BLAS: Failed to load implementation from: com.github.fommil.netlib.NativeSystemBLAS
17/01/29 07:44:33,995 WARN BLAS: Failed to load implementation from: com.github.fommil.netlib.NativeRefBLAS
17/01/29 07:44:34,018 INFO MemoryStore: Block broadcast_4 stored as values in memory (estimated size 280.0 B, free 2.1 GB)
17/01/29 07:44:34,021 INFO MemoryStore: Block broadcast_4_piece0 stored as bytes in memory (estimated size 153.0 B, free 2.1 GB)
17/01/29 07:44:34,022 INFO BlockManagerInfo: Added broadcast_4_piece0 in memory on 10.1.2.142:37340 (size: 153.0 B, free: 2.1 GB)
17/01/29 07:44:34,023 INFO SparkContext: Created broadcast 4 from broadcast at GradientDescent.scala:235
17/01/29 07:44:34,072 INFO SparkContext: Starting job: treeAggregate at GradientDescent.scala:239
17/01/29 07:44:34,078 INFO DAGScheduler: Registering RDD 11 (treeAggregate at GradientDescent.scala:239)
17/01/29 07:44:34,079 INFO DAGScheduler: Got job 3 (treeAggregate at GradientDescent.scala:239) with 7 output partitions
17/01/29 07:44:34,079 INFO DAGScheduler: Final stage: ResultStage 4 (treeAggregate at GradientDescent.scala:239)
17/01/29 07:44:34,079 INFO DAGScheduler: Parents of final stage: List(ShuffleMapStage 3)
17/01/29 07:44:34,079 INFO DAGScheduler: Missing parents: List(ShuffleMapStage 3)
17/01/29 07:44:34,084 INFO DAGScheduler: Submitting ShuffleMapStage 3 (MapPartitionsRDD[11] at treeAggregate at GradientDescent.scala:239), which has no missing parents
17/01/29 07:44:34,101 INFO MemoryStore: Block broadcast_5 stored as values in memory (estimated size 7.2 KB, free 2.1 GB)
17/01/29 07:44:34,103 INFO MemoryStore: Block broadcast_5_piece0 stored as bytes in memory (estimated size 3.7 KB, free 2.1 GB)
17/01/29 07:44:34,104 INFO BlockManagerInfo: Added broadcast_5_piece0 in memory on 10.1.2.142:37340 (size: 3.7 KB, free: 2.1 GB)
17/01/29 07:44:34,104 INFO SparkContext: Created broadcast 5 from broadcast at DAGScheduler.scala:1012
17/01/29 07:44:34,107 INFO DAGScheduler: Submitting 59 missing tasks from ShuffleMapStage 3 (MapPartitionsRDD[11] at treeAggregate at GradientDescent.scala:239)
17/01/29 07:44:34,107 INFO TaskSchedulerImpl: Adding task set 3.0 with 59 tasks
17/01/29 07:44:34,111 INFO TaskSetManager: Starting task 4.0 in stage 3.0 (TID 119, 10.1.2.71, partition 4, PROCESS_LOCAL, 5563 bytes)
17/01/29 07:44:34,111 INFO TaskSetManager: Starting task 1.0 in stage 3.0 (TID 120, 10.1.2.63, partition 1, PROCESS_LOCAL, 5563 bytes)
17/01/29 07:44:34,111 INFO TaskSetManager: Starting task 0.0 in stage 3.0 (TID 121, 10.1.2.236, partition 0, PROCESS_LOCAL, 5563 bytes)
17/01/29 07:44:34,112 INFO TaskSetManager: Starting task 2.0 in stage 3.0 (TID 122, 10.1.2.181, partition 2, PROCESS_LOCAL, 5563 bytes)
17/01/29 07:44:34,112 INFO TaskSetManager: Starting task 8.0 in stage 3.0 (TID 123, 10.1.2.71, partition 8, PROCESS_LOCAL, 5563 bytes)
17/01/29 07:44:34,113 INFO TaskSetManager: Starting task 5.0 in stage 3.0 (TID 124, 10.1.2.63, partition 5, PROCESS_LOCAL, 5563 bytes)
17/01/29 07:44:34,113 INFO TaskSetManager: Starting task 3.0 in stage 3.0 (TID 125, 10.1.2.236, partition 3, PROCESS_LOCAL, 5563 bytes)
17/01/29 07:44:34,114 INFO TaskSetManager: Starting task 6.0 in stage 3.0 (TID 126, 10.1.2.181, partition 6, PROCESS_LOCAL, 5563 bytes)
17/01/29 07:44:34,114 INFO TaskSetManager: Starting task 12.0 in stage 3.0 (TID 127, 10.1.2.71, partition 12, PROCESS_LOCAL, 5563 bytes)
17/01/29 07:44:34,115 INFO TaskSetManager: Starting task 9.0 in stage 3.0 (TID 128, 10.1.2.63, partition 9, PROCESS_LOCAL, 5563 bytes)
17/01/29 07:44:34,115 INFO TaskSetManager: Starting task 7.0 in stage 3.0 (TID 129, 10.1.2.236, partition 7, PROCESS_LOCAL, 5563 bytes)
17/01/29 07:44:34,116 INFO TaskSetManager: Starting task 10.0 in stage 3.0 (TID 130, 10.1.2.181, partition 10, PROCESS_LOCAL, 5563 bytes)
17/01/29 07:44:34,116 INFO TaskSetManager: Starting task 15.0 in stage 3.0 (TID 131, 10.1.2.71, partition 15, PROCESS_LOCAL, 5563 bytes)
17/01/29 07:44:34,117 INFO TaskSetManager: Starting task 13.0 in stage 3.0 (TID 132, 10.1.2.63, partition 13, PROCESS_LOCAL, 5563 bytes)
17/01/29 07:44:34,117 INFO TaskSetManager: Starting task 11.0 in stage 3.0 (TID 133, 10.1.2.236, partition 11, PROCESS_LOCAL, 5563 bytes)
17/01/29 07:44:34,118 INFO TaskSetManager: Starting task 14.0 in stage 3.0 (TID 134, 10.1.2.181, partition 14, PROCESS_LOCAL, 5563 bytes)
17/01/29 07:44:34,118 INFO CoarseGrainedSchedulerBackend$DriverEndpoint: Launching task 119 on executor id: 0 hostname: 10.1.2.71.
17/01/29 07:44:34,118 INFO CoarseGrainedSchedulerBackend$DriverEndpoint: Launching task 123 on executor id: 0 hostname: 10.1.2.71.
17/01/29 07:44:34,119 INFO CoarseGrainedSchedulerBackend$DriverEndpoint: Launching task 127 on executor id: 0 hostname: 10.1.2.71.
17/01/29 07:44:34,119 INFO CoarseGrainedSchedulerBackend$DriverEndpoint: Launching task 131 on executor id: 0 hostname: 10.1.2.71.
17/01/29 07:44:34,119 INFO CoarseGrainedSchedulerBackend$DriverEndpoint: Launching task 120 on executor id: 1 hostname: 10.1.2.63.
17/01/29 07:44:34,120 INFO CoarseGrainedSchedulerBackend$DriverEndpoint: Launching task 124 on executor id: 1 hostname: 10.1.2.63.
17/01/29 07:44:34,120 INFO CoarseGrainedSchedulerBackend$DriverEndpoint: Launching task 128 on executor id: 1 hostname: 10.1.2.63.
17/01/29 07:44:34,121 INFO CoarseGrainedSchedulerBackend$DriverEndpoint: Launching task 132 on executor id: 1 hostname: 10.1.2.63.
17/01/29 07:44:34,121 INFO CoarseGrainedSchedulerBackend$DriverEndpoint: Launching task 121 on executor id: 3 hostname: 10.1.2.236.
17/01/29 07:44:34,122 INFO CoarseGrainedSchedulerBackend$DriverEndpoint: Launching task 125 on executor id: 3 hostname: 10.1.2.236.
17/01/29 07:44:34,123 INFO CoarseGrainedSchedulerBackend$DriverEndpoint: Launching task 129 on executor id: 3 hostname: 10.1.2.236.
17/01/29 07:44:34,123 INFO CoarseGrainedSchedulerBackend$DriverEndpoint: Launching task 133 on executor id: 3 hostname: 10.1.2.236.
17/01/29 07:44:34,124 INFO CoarseGrainedSchedulerBackend$DriverEndpoint: Launching task 122 on executor id: 2 hostname: 10.1.2.181.
17/01/29 07:44:34,124 INFO CoarseGrainedSchedulerBackend$DriverEndpoint: Launching task 126 on executor id: 2 hostname: 10.1.2.181.
17/01/29 07:44:34,125 INFO CoarseGrainedSchedulerBackend$DriverEndpoint: Launching task 130 on executor id: 2 hostname: 10.1.2.181.
17/01/29 07:44:34,127 INFO CoarseGrainedSchedulerBackend$DriverEndpoint: Launching task 134 on executor id: 2 hostname: 10.1.2.181.
17/01/29 07:44:34,141 INFO BlockManagerInfo: Added broadcast_5_piece0 in memory on 10.1.2.71:38877 (size: 3.7 KB, free: 1001.2 MB)
17/01/29 07:44:34,147 INFO BlockManagerInfo: Added broadcast_5_piece0 in memory on 10.1.2.181:41485 (size: 3.7 KB, free: 1001.6 MB)
17/01/29 07:44:34,148 INFO BlockManagerInfo: Added broadcast_5_piece0 in memory on 10.1.2.63:44673 (size: 3.7 KB, free: 1281.6 MB)
17/01/29 07:44:34,175 INFO BlockManagerInfo: Added broadcast_5_piece0 in memory on 10.1.2.236:38599 (size: 3.7 KB, free: 1068.6 MB)
17/01/29 07:44:34,422 INFO BlockManagerInfo: Added broadcast_4_piece0 in memory on 10.1.2.71:38877 (size: 153.0 B, free: 1001.2 MB)
17/01/29 07:44:34,428 INFO BlockManagerInfo: Added broadcast_4_piece0 in memory on 10.1.2.63:44673 (size: 153.0 B, free: 1281.6 MB)
17/01/29 07:44:34,436 INFO BlockManagerInfo: Added broadcast_4_piece0 in memory on 10.1.2.181:41485 (size: 153.0 B, free: 1001.6 MB)
17/01/29 07:44:34,450 INFO BlockManagerInfo: Added broadcast_4_piece0 in memory on 10.1.2.236:38599 (size: 153.0 B, free: 1068.6 MB)
17/01/29 07:44:34,607 INFO TaskSetManager: Starting task 24.0 in stage 3.0 (TID 135, 10.1.2.63, partition 24, PROCESS_LOCAL, 5563 bytes)
17/01/29 07:44:34,607 INFO CoarseGrainedSchedulerBackend$DriverEndpoint: Launching task 135 on executor id: 1 hostname: 10.1.2.63.
17/01/29 07:44:34,608 INFO TaskSetManager: Finished task 5.0 in stage 3.0 (TID 124) in 495 ms on 10.1.2.63 (1/59)
17/01/29 07:44:34,609 INFO TaskSetManager: Finished task 6.0 in stage 3.0 (TID 126) in 496 ms on 10.1.2.181 (2/59)
17/01/29 07:44:34,610 INFO TaskSetManager: Starting task 18.0 in stage 3.0 (TID 136, 10.1.2.181, partition 18, PROCESS_LOCAL, 5563 bytes)
17/01/29 07:44:34,610 INFO CoarseGrainedSchedulerBackend$DriverEndpoint: Launching task 136 on executor id: 2 hostname: 10.1.2.181.
17/01/29 07:44:34,611 INFO TaskSetManager: Starting task 19.0 in stage 3.0 (TID 137, 10.1.2.181, partition 19, PROCESS_LOCAL, 5563 bytes)
17/01/29 07:44:34,612 INFO CoarseGrainedSchedulerBackend$DriverEndpoint: Launching task 137 on executor id: 2 hostname: 10.1.2.181.
17/01/29 07:44:34,612 INFO TaskSetManager: Finished task 14.0 in stage 3.0 (TID 134) in 495 ms on 10.1.2.181 (3/59)
17/01/29 07:44:34,613 INFO TaskSetManager: Starting task 21.0 in stage 3.0 (TID 138, 10.1.2.181, partition 21, PROCESS_LOCAL, 5563 bytes)
17/01/29 07:44:34,613 INFO CoarseGrainedSchedulerBackend$DriverEndpoint: Launching task 138 on executor id: 2 hostname: 10.1.2.181.
17/01/29 07:44:34,614 INFO TaskSetManager: Finished task 10.0 in stage 3.0 (TID 130) in 499 ms on 10.1.2.181 (4/59)
17/01/29 07:44:34,615 INFO TaskSetManager: Starting task 22.0 in stage 3.0 (TID 139, 10.1.2.181, partition 22, PROCESS_LOCAL, 5563 bytes)
17/01/29 07:44:34,616 INFO CoarseGrainedSchedulerBackend$DriverEndpoint: Launching task 139 on executor id: 2 hostname: 10.1.2.181.
17/01/29 07:44:34,616 INFO TaskSetManager: Finished task 2.0 in stage 3.0 (TID 122) in 504 ms on 10.1.2.181 (5/59)
17/01/29 07:44:34,617 INFO TaskSetManager: Starting task 29.0 in stage 3.0 (TID 140, 10.1.2.63, partition 29, PROCESS_LOCAL, 5563 bytes)
17/01/29 07:44:34,617 INFO CoarseGrainedSchedulerBackend$DriverEndpoint: Launching task 140 on executor id: 1 hostname: 10.1.2.63.
17/01/29 07:44:34,617 INFO TaskSetManager: Finished task 13.0 in stage 3.0 (TID 132) in 501 ms on 10.1.2.63 (6/59)
17/01/29 07:44:34,618 INFO TaskSetManager: Starting task 30.0 in stage 3.0 (TID 141, 10.1.2.63, partition 30, PROCESS_LOCAL, 5563 bytes)
17/01/29 07:44:34,618 INFO CoarseGrainedSchedulerBackend$DriverEndpoint: Launching task 141 on executor id: 1 hostname: 10.1.2.63.
17/01/29 07:44:34,618 INFO TaskSetManager: Finished task 9.0 in stage 3.0 (TID 128) in 504 ms on 10.1.2.63 (7/59)
17/01/29 07:44:34,619 INFO TaskSetManager: Starting task 31.0 in stage 3.0 (TID 142, 10.1.2.63, partition 31, PROCESS_LOCAL, 5563 bytes)
17/01/29 07:44:34,619 INFO CoarseGrainedSchedulerBackend$DriverEndpoint: Launching task 142 on executor id: 1 hostname: 10.1.2.63.
17/01/29 07:44:34,620 INFO TaskSetManager: Finished task 1.0 in stage 3.0 (TID 120) in 508 ms on 10.1.2.63 (8/59)
17/01/29 07:44:34,625 INFO TaskSetManager: Finished task 3.0 in stage 3.0 (TID 125) in 512 ms on 10.1.2.236 (9/59)
17/01/29 07:44:34,626 INFO TaskSetManager: Starting task 16.0 in stage 3.0 (TID 143, 10.1.2.236, partition 16, PROCESS_LOCAL, 5563 bytes)
17/01/29 07:44:34,627 INFO CoarseGrainedSchedulerBackend$DriverEndpoint: Launching task 143 on executor id: 3 hostname: 10.1.2.236.
17/01/29 07:44:34,628 INFO TaskSetManager: Starting task 17.0 in stage 3.0 (TID 144, 10.1.2.236, partition 17, PROCESS_LOCAL, 5563 bytes)
17/01/29 07:44:34,629 INFO CoarseGrainedSchedulerBackend$DriverEndpoint: Launching task 144 on executor id: 3 hostname: 10.1.2.236.
17/01/29 07:44:34,629 INFO TaskSetManager: Finished task 7.0 in stage 3.0 (TID 129) in 514 ms on 10.1.2.236 (10/59)
17/01/29 07:44:34,631 INFO TaskSetManager: Starting task 20.0 in stage 3.0 (TID 145, 10.1.2.236, partition 20, PROCESS_LOCAL, 5563 bytes)
17/01/29 07:44:34,631 INFO CoarseGrainedSchedulerBackend$DriverEndpoint: Launching task 145 on executor id: 3 hostname: 10.1.2.236.
17/01/29 07:44:34,632 INFO TaskSetManager: Finished task 0.0 in stage 3.0 (TID 121) in 520 ms on 10.1.2.236 (11/59)
17/01/29 07:44:34,632 INFO TaskSetManager: Finished task 11.0 in stage 3.0 (TID 133) in 515 ms on 10.1.2.236 (12/59)
17/01/29 07:44:34,633 INFO TaskSetManager: Starting task 28.0 in stage 3.0 (TID 146, 10.1.2.236, partition 28, PROCESS_LOCAL, 5563 bytes)
17/01/29 07:44:34,634 INFO CoarseGrainedSchedulerBackend$DriverEndpoint: Launching task 146 on executor id: 3 hostname: 10.1.2.236.
17/01/29 07:44:34,648 INFO TaskSetManager: Starting task 23.0 in stage 3.0 (TID 147, 10.1.2.71, partition 23, PROCESS_LOCAL, 5563 bytes)
17/01/29 07:44:34,648 INFO CoarseGrainedSchedulerBackend$DriverEndpoint: Launching task 147 on executor id: 0 hostname: 10.1.2.71.
17/01/29 07:44:34,649 INFO TaskSetManager: Finished task 4.0 in stage 3.0 (TID 119) in 539 ms on 10.1.2.71 (13/59)
17/01/29 07:44:34,649 INFO TaskSetManager: Starting task 25.0 in stage 3.0 (TID 148, 10.1.2.71, partition 25, PROCESS_LOCAL, 5563 bytes)
17/01/29 07:44:34,649 INFO CoarseGrainedSchedulerBackend$DriverEndpoint: Launching task 148 on executor id: 0 hostname: 10.1.2.71.
17/01/29 07:44:34,650 INFO TaskSetManager: Finished task 15.0 in stage 3.0 (TID 131) in 533 ms on 10.1.2.71 (14/59)
17/01/29 07:44:34,651 INFO TaskSetManager: Starting task 26.0 in stage 3.0 (TID 149, 10.1.2.71, partition 26, PROCESS_LOCAL, 5563 bytes)
17/01/29 07:44:34,651 INFO CoarseGrainedSchedulerBackend$DriverEndpoint: Launching task 149 on executor id: 0 hostname: 10.1.2.71.
17/01/29 07:44:34,651 INFO TaskSetManager: Starting task 27.0 in stage 3.0 (TID 150, 10.1.2.71, partition 27, PROCESS_LOCAL, 5563 bytes)
17/01/29 07:44:34,652 INFO CoarseGrainedSchedulerBackend$DriverEndpoint: Launching task 150 on executor id: 0 hostname: 10.1.2.71.
17/01/29 07:44:34,652 INFO TaskSetManager: Finished task 8.0 in stage 3.0 (TID 123) in 540 ms on 10.1.2.71 (15/59)
17/01/29 07:44:34,653 INFO TaskSetManager: Finished task 12.0 in stage 3.0 (TID 127) in 539 ms on 10.1.2.71 (16/59)
17/01/29 07:44:34,710 INFO TaskSetManager: Starting task 32.0 in stage 3.0 (TID 151, 10.1.2.236, partition 32, PROCESS_LOCAL, 5563 bytes)
17/01/29 07:44:34,710 INFO CoarseGrainedSchedulerBackend$DriverEndpoint: Launching task 151 on executor id: 3 hostname: 10.1.2.236.
17/01/29 07:44:34,711 INFO TaskSetManager: Finished task 20.0 in stage 3.0 (TID 145) in 82 ms on 10.1.2.236 (17/59)
17/01/29 07:44:34,719 INFO TaskSetManager: Starting task 41.0 in stage 3.0 (TID 152, 10.1.2.236, partition 41, PROCESS_LOCAL, 5563 bytes)
17/01/29 07:44:34,720 INFO CoarseGrainedSchedulerBackend$DriverEndpoint: Launching task 152 on executor id: 3 hostname: 10.1.2.236.
17/01/29 07:44:34,720 INFO TaskSetManager: Finished task 17.0 in stage 3.0 (TID 144) in 92 ms on 10.1.2.236 (18/59)
17/01/29 07:44:34,721 INFO TaskSetManager: Starting task 43.0 in stage 3.0 (TID 153, 10.1.2.63, partition 43, PROCESS_LOCAL, 5563 bytes)
17/01/29 07:44:34,721 INFO CoarseGrainedSchedulerBackend$DriverEndpoint: Launching task 153 on executor id: 1 hostname: 10.1.2.63.
17/01/29 07:44:34,721 INFO TaskSetManager: Finished task 30.0 in stage 3.0 (TID 141) in 104 ms on 10.1.2.63 (19/59)
17/01/29 07:44:34,722 INFO TaskSetManager: Starting task 33.0 in stage 3.0 (TID 154, 10.1.2.181, partition 33, PROCESS_LOCAL, 5563 bytes)
17/01/29 07:44:34,722 INFO CoarseGrainedSchedulerBackend$DriverEndpoint: Launching task 154 on executor id: 2 hostname: 10.1.2.181.
17/01/29 07:44:34,723 INFO TaskSetManager: Finished task 19.0 in stage 3.0 (TID 137) in 111 ms on 10.1.2.181 (20/59)
17/01/29 07:44:34,724 INFO TaskSetManager: Finished task 21.0 in stage 3.0 (TID 138) in 111 ms on 10.1.2.181 (21/59)
17/01/29 07:44:34,725 INFO TaskSetManager: Starting task 35.0 in stage 3.0 (TID 155, 10.1.2.181, partition 35, PROCESS_LOCAL, 5563 bytes)
17/01/29 07:44:34,725 INFO CoarseGrainedSchedulerBackend$DriverEndpoint: Launching task 155 on executor id: 2 hostname: 10.1.2.181.
17/01/29 07:44:34,727 INFO TaskSetManager: Starting task 45.0 in stage 3.0 (TID 156, 10.1.2.63, partition 45, PROCESS_LOCAL, 5563 bytes)
17/01/29 07:44:34,727 INFO CoarseGrainedSchedulerBackend$DriverEndpoint: Launching task 156 on executor id: 1 hostname: 10.1.2.63.
17/01/29 07:44:34,727 INFO TaskSetManager: Finished task 29.0 in stage 3.0 (TID 140) in 111 ms on 10.1.2.63 (22/59)
17/01/29 07:44:34,731 INFO TaskSetManager: Starting task 42.0 in stage 3.0 (TID 157, 10.1.2.236, partition 42, PROCESS_LOCAL, 5563 bytes)
17/01/29 07:44:34,731 INFO CoarseGrainedSchedulerBackend$DriverEndpoint: Launching task 157 on executor id: 3 hostname: 10.1.2.236.
17/01/29 07:44:34,732 INFO TaskSetManager: Finished task 16.0 in stage 3.0 (TID 143) in 105 ms on 10.1.2.236 (23/59)
17/01/29 07:44:34,733 INFO TaskSetManager: Starting task 36.0 in stage 3.0 (TID 158, 10.1.2.181, partition 36, PROCESS_LOCAL, 5563 bytes)
17/01/29 07:44:34,734 INFO CoarseGrainedSchedulerBackend$DriverEndpoint: Launching task 158 on executor id: 2 hostname: 10.1.2.181.
17/01/29 07:44:34,734 INFO TaskSetManager: Finished task 22.0 in stage 3.0 (TID 139) in 119 ms on 10.1.2.181 (24/59)
17/01/29 07:44:34,736 INFO TaskSetManager: Finished task 24.0 in stage 3.0 (TID 135) in 129 ms on 10.1.2.63 (25/59)
17/01/29 07:44:34,737 INFO TaskSetManager: Starting task 46.0 in stage 3.0 (TID 159, 10.1.2.63, partition 46, PROCESS_LOCAL, 5563 bytes)
17/01/29 07:44:34,737 INFO CoarseGrainedSchedulerBackend$DriverEndpoint: Launching task 159 on executor id: 1 hostname: 10.1.2.63.
17/01/29 07:44:34,738 INFO TaskSetManager: Finished task 18.0 in stage 3.0 (TID 136) in 129 ms on 10.1.2.181 (26/59)
17/01/29 07:44:34,739 INFO TaskSetManager: Starting task 40.0 in stage 3.0 (TID 160, 10.1.2.181, partition 40, PROCESS_LOCAL, 5563 bytes)
17/01/29 07:44:34,739 INFO CoarseGrainedSchedulerBackend$DriverEndpoint: Launching task 160 on executor id: 2 hostname: 10.1.2.181.
17/01/29 07:44:34,742 INFO TaskSetManager: Starting task 44.0 in stage 3.0 (TID 161, 10.1.2.236, partition 44, PROCESS_LOCAL, 5563 bytes)
17/01/29 07:44:34,742 INFO CoarseGrainedSchedulerBackend$DriverEndpoint: Launching task 161 on executor id: 3 hostname: 10.1.2.236.
17/01/29 07:44:34,742 INFO TaskSetManager: Finished task 28.0 in stage 3.0 (TID 146) in 109 ms on 10.1.2.236 (27/59)
17/01/29 07:44:34,748 INFO TaskSetManager: Starting task 34.0 in stage 3.0 (TID 162, 10.1.2.71, partition 34, PROCESS_LOCAL, 5563 bytes)
17/01/29 07:44:34,749 INFO CoarseGrainedSchedulerBackend$DriverEndpoint: Launching task 162 on executor id: 0 hostname: 10.1.2.71.
17/01/29 07:44:34,749 INFO TaskSetManager: Finished task 23.0 in stage 3.0 (TID 147) in 102 ms on 10.1.2.71 (28/59)
17/01/29 07:44:34,752 INFO TaskSetManager: Starting task 37.0 in stage 3.0 (TID 163, 10.1.2.71, partition 37, PROCESS_LOCAL, 5563 bytes)
17/01/29 07:44:34,752 INFO CoarseGrainedSchedulerBackend$DriverEndpoint: Launching task 163 on executor id: 0 hostname: 10.1.2.71.
17/01/29 07:44:34,752 INFO TaskSetManager: Finished task 27.0 in stage 3.0 (TID 150) in 101 ms on 10.1.2.71 (29/59)
17/01/29 07:44:34,756 INFO TaskSetManager: Starting task 38.0 in stage 3.0 (TID 164, 10.1.2.71, partition 38, PROCESS_LOCAL, 5563 bytes)
17/01/29 07:44:34,756 INFO CoarseGrainedSchedulerBackend$DriverEndpoint: Launching task 164 on executor id: 0 hostname: 10.1.2.71.
17/01/29 07:44:34,757 INFO TaskSetManager: Finished task 26.0 in stage 3.0 (TID 149) in 106 ms on 10.1.2.71 (30/59)
17/01/29 07:44:34,773 INFO TaskSetManager: Starting task 48.0 in stage 3.0 (TID 165, 10.1.2.236, partition 48, PROCESS_LOCAL, 5563 bytes)
17/01/29 07:44:34,773 INFO CoarseGrainedSchedulerBackend$DriverEndpoint: Launching task 165 on executor id: 3 hostname: 10.1.2.236.
17/01/29 07:44:34,773 INFO TaskSetManager: Finished task 32.0 in stage 3.0 (TID 151) in 64 ms on 10.1.2.236 (31/59)
17/01/29 07:44:34,775 INFO TaskSetManager: Starting task 39.0 in stage 3.0 (TID 166, 10.1.2.71, partition 39, PROCESS_LOCAL, 5563 bytes)
17/01/29 07:44:34,775 INFO CoarseGrainedSchedulerBackend$DriverEndpoint: Launching task 166 on executor id: 0 hostname: 10.1.2.71.
17/01/29 07:44:34,775 INFO TaskSetManager: Finished task 25.0 in stage 3.0 (TID 148) in 126 ms on 10.1.2.71 (32/59)
17/01/29 07:44:34,787 INFO TaskSetManager: Finished task 41.0 in stage 3.0 (TID 152) in 68 ms on 10.1.2.236 (33/59)
17/01/29 07:44:34,788 INFO TaskSetManager: Starting task 57.0 in stage 3.0 (TID 167, 10.1.2.236, partition 57, PROCESS_LOCAL, 5563 bytes)
17/01/29 07:44:34,788 INFO CoarseGrainedSchedulerBackend$DriverEndpoint: Launching task 167 on executor id: 3 hostname: 10.1.2.236.
17/01/29 07:44:34,789 INFO TaskSetManager: Starting task 49.0 in stage 3.0 (TID 168, 10.1.2.181, partition 49, PROCESS_LOCAL, 5563 bytes)
17/01/29 07:44:34,789 INFO CoarseGrainedSchedulerBackend$DriverEndpoint: Launching task 168 on executor id: 2 hostname: 10.1.2.181.
17/01/29 07:44:34,789 INFO TaskSetManager: Finished task 33.0 in stage 3.0 (TID 154) in 67 ms on 10.1.2.181 (34/59)
17/01/29 07:44:34,799 INFO TaskSetManager: Starting task 50.0 in stage 3.0 (TID 169, 10.1.2.181, partition 50, PROCESS_LOCAL, 5563 bytes)
17/01/29 07:44:34,799 INFO CoarseGrainedSchedulerBackend$DriverEndpoint: Launching task 169 on executor id: 2 hostname: 10.1.2.181.
17/01/29 07:44:34,799 INFO TaskSetManager: Finished task 35.0 in stage 3.0 (TID 155) in 75 ms on 10.1.2.181 (35/59)
17/01/29 07:44:34,806 INFO TaskSetManager: Starting task 47.0 in stage 3.0 (TID 170, 10.1.2.63, partition 47, PROCESS_LOCAL, 5563 bytes)
17/01/29 07:44:34,806 INFO CoarseGrainedSchedulerBackend$DriverEndpoint: Launching task 170 on executor id: 1 hostname: 10.1.2.63.
17/01/29 07:44:34,806 INFO TaskSetManager: Finished task 31.0 in stage 3.0 (TID 142) in 187 ms on 10.1.2.63 (36/59)
17/01/29 07:44:34,812 INFO TaskSetManager: Starting task 51.0 in stage 3.0 (TID 171, 10.1.2.181, partition 51, PROCESS_LOCAL, 5563 bytes)
17/01/29 07:44:34,812 INFO CoarseGrainedSchedulerBackend$DriverEndpoint: Launching task 171 on executor id: 2 hostname: 10.1.2.181.
17/01/29 07:44:34,813 INFO TaskSetManager: Finished task 40.0 in stage 3.0 (TID 160) in 74 ms on 10.1.2.181 (37/59)
17/01/29 07:44:34,815 INFO TaskSetManager: Starting task 58.0 in stage 3.0 (TID 172, 10.1.2.236, partition 58, PROCESS_LOCAL, 5563 bytes)
17/01/29 07:44:34,815 INFO CoarseGrainedSchedulerBackend$DriverEndpoint: Launching task 172 on executor id: 3 hostname: 10.1.2.236.
17/01/29 07:44:34,815 INFO TaskSetManager: Finished task 42.0 in stage 3.0 (TID 157) in 85 ms on 10.1.2.236 (38/59)
17/01/29 07:44:34,822 INFO TaskSetManager: Starting task 53.0 in stage 3.0 (TID 173, 10.1.2.71, partition 53, PROCESS_LOCAL, 5563 bytes)
17/01/29 07:44:34,822 INFO CoarseGrainedSchedulerBackend$DriverEndpoint: Launching task 173 on executor id: 0 hostname: 10.1.2.71.
17/01/29 07:44:34,822 INFO TaskSetManager: Finished task 34.0 in stage 3.0 (TID 162) in 74 ms on 10.1.2.71 (39/59)
17/01/29 07:44:34,825 INFO TaskSetManager: Starting task 54.0 in stage 3.0 (TID 174, 10.1.2.71, partition 54, PROCESS_LOCAL, 5563 bytes)
17/01/29 07:44:34,825 INFO CoarseGrainedSchedulerBackend$DriverEndpoint: Launching task 174 on executor id: 0 hostname: 10.1.2.71.
17/01/29 07:44:34,826 INFO TaskSetManager: Finished task 38.0 in stage 3.0 (TID 164) in 69 ms on 10.1.2.71 (40/59)
17/01/29 07:44:34,826 INFO TaskSetManager: Starting task 55.0 in stage 3.0 (TID 175, 10.1.2.71, partition 55, PROCESS_LOCAL, 5563 bytes)
17/01/29 07:44:34,827 INFO CoarseGrainedSchedulerBackend$DriverEndpoint: Launching task 175 on executor id: 0 hostname: 10.1.2.71.
17/01/29 07:44:34,827 INFO TaskSetManager: Finished task 37.0 in stage 3.0 (TID 163) in 76 ms on 10.1.2.71 (41/59)
17/01/29 07:44:34,833 INFO TaskSetManager: Finished task 44.0 in stage 3.0 (TID 161) in 92 ms on 10.1.2.236 (42/59)
17/01/29 07:44:34,835 INFO TaskSetManager: Finished task 43.0 in stage 3.0 (TID 153) in 115 ms on 10.1.2.63 (43/59)
17/01/29 07:44:34,836 INFO TaskSetManager: Finished task 48.0 in stage 3.0 (TID 165) in 63 ms on 10.1.2.236 (44/59)
17/01/29 07:44:34,840 INFO TaskSetManager: Finished task 45.0 in stage 3.0 (TID 156) in 114 ms on 10.1.2.63 (45/59)
17/01/29 07:44:34,855 INFO TaskSetManager: Finished task 46.0 in stage 3.0 (TID 159) in 119 ms on 10.1.2.63 (46/59)
17/01/29 07:44:34,859 INFO TaskSetManager: Finished task 57.0 in stage 3.0 (TID 167) in 72 ms on 10.1.2.236 (47/59)
17/01/29 07:44:34,866 INFO TaskSetManager: Finished task 49.0 in stage 3.0 (TID 168) in 78 ms on 10.1.2.181 (48/59)
17/01/29 07:44:34,867 INFO TaskSetManager: Starting task 52.0 in stage 3.0 (TID 176, 10.1.2.181, partition 52, PROCESS_LOCAL, 5563 bytes)
17/01/29 07:44:34,867 INFO CoarseGrainedSchedulerBackend$DriverEndpoint: Launching task 176 on executor id: 2 hostname: 10.1.2.181.
17/01/29 07:44:34,877 INFO TaskSetManager: Finished task 47.0 in stage 3.0 (TID 170) in 71 ms on 10.1.2.63 (49/59)
17/01/29 07:44:34,881 INFO TaskSetManager: Finished task 58.0 in stage 3.0 (TID 172) in 67 ms on 10.1.2.236 (50/59)
17/01/29 07:44:34,886 INFO TaskSetManager: Finished task 51.0 in stage 3.0 (TID 171) in 73 ms on 10.1.2.181 (51/59)
17/01/29 07:44:34,890 INFO TaskSetManager: Starting task 56.0 in stage 3.0 (TID 177, 10.1.2.71, partition 56, PROCESS_LOCAL, 5563 bytes)
17/01/29 07:44:34,891 INFO CoarseGrainedSchedulerBackend$DriverEndpoint: Launching task 177 on executor id: 0 hostname: 10.1.2.71.
17/01/29 07:44:34,891 INFO TaskSetManager: Finished task 54.0 in stage 3.0 (TID 174) in 66 ms on 10.1.2.71 (52/59)
17/01/29 07:44:34,894 INFO TaskSetManager: Finished task 36.0 in stage 3.0 (TID 158) in 161 ms on 10.1.2.181 (53/59)
17/01/29 07:44:34,901 INFO TaskSetManager: Finished task 39.0 in stage 3.0 (TID 166) in 127 ms on 10.1.2.71 (54/59)
17/01/29 07:44:34,913 INFO TaskSetManager: Finished task 50.0 in stage 3.0 (TID 169) in 114 ms on 10.1.2.181 (55/59)
17/01/29 07:44:34,926 INFO TaskSetManager: Finished task 55.0 in stage 3.0 (TID 175) in 100 ms on 10.1.2.71 (56/59)
17/01/29 07:44:34,930 INFO TaskSetManager: Finished task 53.0 in stage 3.0 (TID 173) in 109 ms on 10.1.2.71 (57/59)
17/01/29 07:44:34,946 INFO TaskSetManager: Finished task 52.0 in stage 3.0 (TID 176) in 80 ms on 10.1.2.181 (58/59)
17/01/29 07:44:34,957 INFO TaskSetManager: Finished task 56.0 in stage 3.0 (TID 177) in 67 ms on 10.1.2.71 (59/59)
17/01/29 07:44:34,957 INFO TaskSchedulerImpl: Removed TaskSet 3.0, whose tasks have all completed, from pool 
17/01/29 07:44:34,958 INFO DAGScheduler: ShuffleMapStage 3 (treeAggregate at GradientDescent.scala:239) finished in 0.849 s
17/01/29 07:44:34,958 INFO DAGScheduler: looking for newly runnable stages
17/01/29 07:44:34,958 INFO DAGScheduler: running: Set()
17/01/29 07:44:34,959 INFO DAGScheduler: waiting: Set(ResultStage 4)
17/01/29 07:44:34,959 INFO DAGScheduler: failed: Set()
17/01/29 07:44:34,961 INFO DAGScheduler: Submitting ResultStage 4 (MapPartitionsRDD[13] at treeAggregate at GradientDescent.scala:239), which has no missing parents
17/01/29 07:44:34,965 INFO MemoryStore: Block broadcast_6 stored as values in memory (estimated size 3.1 KB, free 2.1 GB)
17/01/29 07:44:34,970 INFO MemoryStore: Block broadcast_6_piece0 stored as bytes in memory (estimated size 1893.0 B, free 2.1 GB)
17/01/29 07:44:34,970 INFO BlockManagerInfo: Added broadcast_6_piece0 in memory on 10.1.2.142:37340 (size: 1893.0 B, free: 2.1 GB)
17/01/29 07:44:34,971 INFO SparkContext: Created broadcast 6 from broadcast at DAGScheduler.scala:1012
17/01/29 07:44:34,971 INFO DAGScheduler: Submitting 7 missing tasks from ResultStage 4 (MapPartitionsRDD[13] at treeAggregate at GradientDescent.scala:239)
17/01/29 07:44:34,971 INFO TaskSchedulerImpl: Adding task set 4.0 with 7 tasks
17/01/29 07:44:34,973 INFO TaskSetManager: Starting task 0.0 in stage 4.0 (TID 178, 10.1.2.181, partition 0, NODE_LOCAL, 5228 bytes)
17/01/29 07:44:34,974 INFO TaskSetManager: Starting task 1.0 in stage 4.0 (TID 179, 10.1.2.63, partition 1, NODE_LOCAL, 5228 bytes)
17/01/29 07:44:34,974 INFO TaskSetManager: Starting task 2.0 in stage 4.0 (TID 180, 10.1.2.71, partition 2, NODE_LOCAL, 5228 bytes)
17/01/29 07:44:34,974 INFO TaskSetManager: Starting task 3.0 in stage 4.0 (TID 181, 10.1.2.236, partition 3, NODE_LOCAL, 5228 bytes)
17/01/29 07:44:34,975 INFO TaskSetManager: Starting task 5.0 in stage 4.0 (TID 182, 10.1.2.181, partition 5, NODE_LOCAL, 5228 bytes)
17/01/29 07:44:34,975 INFO TaskSetManager: Starting task 4.0 in stage 4.0 (TID 183, 10.1.2.71, partition 4, NODE_LOCAL, 5228 bytes)
17/01/29 07:44:34,975 INFO TaskSetManager: Starting task 6.0 in stage 4.0 (TID 184, 10.1.2.236, partition 6, NODE_LOCAL, 5228 bytes)
17/01/29 07:44:34,976 INFO CoarseGrainedSchedulerBackend$DriverEndpoint: Launching task 178 on executor id: 2 hostname: 10.1.2.181.
17/01/29 07:44:34,976 INFO CoarseGrainedSchedulerBackend$DriverEndpoint: Launching task 182 on executor id: 2 hostname: 10.1.2.181.
17/01/29 07:44:34,976 INFO CoarseGrainedSchedulerBackend$DriverEndpoint: Launching task 179 on executor id: 1 hostname: 10.1.2.63.
17/01/29 07:44:34,976 INFO CoarseGrainedSchedulerBackend$DriverEndpoint: Launching task 180 on executor id: 0 hostname: 10.1.2.71.
17/01/29 07:44:34,977 INFO CoarseGrainedSchedulerBackend$DriverEndpoint: Launching task 183 on executor id: 0 hostname: 10.1.2.71.
17/01/29 07:44:34,977 INFO CoarseGrainedSchedulerBackend$DriverEndpoint: Launching task 181 on executor id: 3 hostname: 10.1.2.236.
17/01/29 07:44:34,978 INFO CoarseGrainedSchedulerBackend$DriverEndpoint: Launching task 184 on executor id: 3 hostname: 10.1.2.236.
17/01/29 07:44:34,991 INFO BlockManagerInfo: Added broadcast_6_piece0 in memory on 10.1.2.63:44673 (size: 1893.0 B, free: 1281.6 MB)
17/01/29 07:44:34,991 INFO BlockManagerInfo: Added broadcast_6_piece0 in memory on 10.1.2.71:38877 (size: 1893.0 B, free: 1001.2 MB)
17/01/29 07:44:34,991 INFO BlockManagerInfo: Added broadcast_6_piece0 in memory on 10.1.2.181:41485 (size: 1893.0 B, free: 1001.6 MB)
17/01/29 07:44:34,992 INFO BlockManagerInfo: Added broadcast_6_piece0 in memory on 10.1.2.236:38599 (size: 1893.0 B, free: 1068.6 MB)
17/01/29 07:44:35,007 INFO MapOutputTrackerMasterEndpoint: Asked to send map output locations for shuffle 0 to 10.1.2.63:53222
17/01/29 07:44:35,010 INFO MapOutputTrackerMasterEndpoint: Asked to send map output locations for shuffle 0 to 10.1.2.181:36088
17/01/29 07:44:35,010 INFO MapOutputTrackerMasterEndpoint: Asked to send map output locations for shuffle 0 to 10.1.2.236:44136
17/01/29 07:44:35,011 INFO MapOutputTrackerMaster: Size of output statuses for shuffle 0 is 366 bytes
17/01/29 07:44:35,014 INFO MapOutputTrackerMasterEndpoint: Asked to send map output locations for shuffle 0 to 10.1.2.71:37936
17/01/29 07:44:35,148 INFO TaskSetManager: Finished task 5.0 in stage 4.0 (TID 182) in 174 ms on 10.1.2.181 (1/7)
17/01/29 07:44:35,150 INFO TaskSetManager: Finished task 0.0 in stage 4.0 (TID 178) in 178 ms on 10.1.2.181 (2/7)
