Using properties file: /home/ubuntu/spark-2.0.0/conf/spark-defaults.conf
Adding default property: spark.driver.extraJavaOptions=-XX:+PrintGCDetails -XX:+PrintGCTimeStamps -Xms4000m -Dlog4j.configuration=file:///home/ubuntu/spark-2.0.0/conf/log4j.properties
Adding default property: spark.executor.extraJavaOptions=-XX:+PrintGCDetails -XX:+PrintGCTimeStamps -Xms4000m -Dlog4j.configuration=file:///home/ubuntu/spark-2.0.0/conf/log4j.properties
Parsed arguments:
  master                  spark://euca-10-1-2-241:7077
  deployMode              client
  executorMemory          4000m
  executorCores           null
  totalExecutorCores      null
  propertiesFile          /home/ubuntu/spark-2.0.0/conf/spark-defaults.conf
  driverMemory            4000m
  driverCores             null
  driverExtraClassPath    null
  driverExtraLibraryPath  null
  driverExtraJavaOptions  -XX:+PrintGCDetails -XX:+PrintGCTimeStamps -Xms4000m -Dlog4j.configuration=file:///home/ubuntu/spark-2.0.0/conf/log4j.properties
  supervise               false
  queue                   null
  numExecutors            8
  files                   null
  pyFiles                 null
  archives                null
  mainClass               LogRegExplicitParallelism
  primaryResource         file:///home/ubuntu/jars/log-reg-explicit-parallelism_2.11-1.0.jar
  name                    LogRegExplicitParallelism
  childArgs               [cluster 28 euca-10-1-2-241 9000 higgs_0_exp 5 32]
  jars                    null
  packages                null
  packagesExclusions      null
  repositories            null
  verbose                 true

Spark properties used, including those specified through
 --conf and those from the properties file /home/ubuntu/spark-2.0.0/conf/spark-defaults.conf:
  spark.default.parallelism -> 32
  spark.driver.memory -> 4000m
  spark.executor.extraJavaOptions -> -XX:+PrintGCDetails -XX:+PrintGCTimeStamps -Xms4000m -Dlog4j.configuration=file:///home/ubuntu/spark-2.0.0/conf/log4j.properties
  spark.driver.extraJavaOptions -> -XX:+PrintGCDetails -XX:+PrintGCTimeStamps -Xms4000m -Dlog4j.configuration=file:///home/ubuntu/spark-2.0.0/conf/log4j.properties
  spark.shuffle.spill -> false

    
Main class:
LogRegExplicitParallelism
Arguments:
cluster
28
euca-10-1-2-241
9000
higgs_0_exp
5
32
System properties:
spark.default.parallelism -> 32
spark.executor.memory -> 4000m
spark.driver.memory -> 4000m
SPARK_SUBMIT -> true
spark.executor.extraJavaOptions -> -XX:+PrintGCDetails -XX:+PrintGCTimeStamps -Xms4000m -Dlog4j.configuration=file:///home/ubuntu/spark-2.0.0/conf/log4j.properties
spark.app.name -> LogRegExplicitParallelism
spark.shuffle.spill -> false
spark.driver.extraJavaOptions -> -XX:+PrintGCDetails -XX:+PrintGCTimeStamps -Xms4000m -Dlog4j.configuration=file:///home/ubuntu/spark-2.0.0/conf/log4j.properties
spark.jars -> file:///home/ubuntu/jars/log-reg-explicit-parallelism_2.11-1.0.jar
spark.submit.deployMode -> client
spark.master -> spark://euca-10-1-2-241:7077
Classpath elements:
file:///home/ubuntu/jars/log-reg-explicit-parallelism_2.11-1.0.jar


17/01/29 08:56:47,595 INFO SparkContext: Running Spark version 2.0.0
17/01/29 08:56:47,925 WARN NativeCodeLoader: Unable to load native-hadoop library for your platform... using builtin-java classes where applicable
17/01/29 08:56:48,090 INFO SecurityManager: Changing view acls to: ubuntu
17/01/29 08:56:48,091 INFO SecurityManager: Changing modify acls to: ubuntu
17/01/29 08:56:48,091 INFO SecurityManager: Changing view acls groups to: 
17/01/29 08:56:48,092 INFO SecurityManager: Changing modify acls groups to: 
17/01/29 08:56:48,092 INFO SecurityManager: SecurityManager: authentication disabled; ui acls disabled; users  with view permissions: Set(ubuntu); groups with view permissions: Set(); users  with modify permissions: Set(ubuntu); groups with modify permissions: Set()
17/01/29 08:56:51,353 WARN ThreadLocalRandom: Failed to generate a seed from SecureRandom within 3 seconds. Not enough entrophy?
17/01/29 08:56:51,400 INFO Utils: Successfully started service 'sparkDriver' on port 45598.
17/01/29 08:56:51,419 INFO SparkEnv: Registering MapOutputTracker
17/01/29 08:56:51,425 WARN SortShuffleManager: spark.shuffle.spill was set to false, but this configuration is ignored as of Spark 1.6+. Shuffle will continue to spill to disk when necessary.
17/01/29 08:56:51,436 INFO SparkEnv: Registering BlockManagerMaster
17/01/29 08:56:51,449 INFO DiskBlockManager: Created local directory at /tmp/blockmgr-a4895b23-c432-4c0a-b6cb-35afb3f89ee0
17/01/29 08:56:51,467 INFO MemoryStore: MemoryStore started with capacity 2.1 GB
17/01/29 08:56:51,527 INFO SparkEnv: Registering OutputCommitCoordinator
17/01/29 08:56:51,724 INFO Utils: Successfully started service 'SparkUI' on port 4040.
17/01/29 08:56:51,727 INFO SparkUI: Bound SparkUI to 10.1.2.241, and started at http://10.1.2.241:4040
17/01/29 08:56:51,761 INFO SparkContext: Added JAR file:///home/ubuntu/jars/log-reg-explicit-parallelism_2.11-1.0.jar at spark://10.1.2.241:45598/jars/log-reg-explicit-parallelism_2.11-1.0.jar with timestamp 1485680211761
17/01/29 08:56:51,841 INFO StandaloneAppClient$ClientEndpoint: Connecting to master spark://euca-10-1-2-241:7077...
17/01/29 08:56:51,888 INFO TransportClientFactory: Successfully created connection to euca-10-1-2-241/10.1.2.241:7077 after 23 ms (0 ms spent in bootstraps)
17/01/29 08:56:51,979 INFO StandaloneSchedulerBackend: Connected to Spark cluster with app ID app-20170129085651-0000
17/01/29 08:56:51,985 INFO Utils: Successfully started service 'org.apache.spark.network.netty.NettyBlockTransferService' on port 40816.
17/01/29 08:56:51,985 INFO NettyBlockTransferService: Server created on 10.1.2.241:40816
17/01/29 08:56:51,987 INFO BlockManagerMaster: Registering BlockManager BlockManagerId(driver, 10.1.2.241, 40816)
17/01/29 08:56:51,989 INFO BlockManagerMasterEndpoint: Registering block manager 10.1.2.241:40816 with 2.1 GB RAM, BlockManagerId(driver, 10.1.2.241, 40816)
17/01/29 08:56:51,991 INFO BlockManagerMaster: Registered BlockManager BlockManagerId(driver, 10.1.2.241, 40816)
17/01/29 08:56:52,007 INFO StandaloneAppClient$ClientEndpoint: Executor added: app-20170129085651-0000/0 on worker-20170129085624-10.1.2.26-37280 (10.1.2.26:37280) with 4 cores
17/01/29 08:56:52,008 INFO StandaloneSchedulerBackend: Granted executor ID app-20170129085651-0000/0 on hostPort 10.1.2.26:37280 with 4 cores, 3.9 GB RAM
17/01/29 08:56:52,008 INFO StandaloneAppClient$ClientEndpoint: Executor added: app-20170129085651-0000/1 on worker-20170129085624-10.1.2.182-36270 (10.1.2.182:36270) with 4 cores
17/01/29 08:56:52,008 INFO StandaloneSchedulerBackend: Granted executor ID app-20170129085651-0000/1 on hostPort 10.1.2.182:36270 with 4 cores, 3.9 GB RAM
17/01/29 08:56:52,010 INFO StandaloneAppClient$ClientEndpoint: Executor added: app-20170129085651-0000/2 on worker-20170129085624-10.1.2.27-36144 (10.1.2.27:36144) with 4 cores
17/01/29 08:56:52,011 INFO StandaloneSchedulerBackend: Granted executor ID app-20170129085651-0000/2 on hostPort 10.1.2.27:36144 with 4 cores, 3.9 GB RAM
17/01/29 08:56:52,012 INFO StandaloneAppClient$ClientEndpoint: Executor added: app-20170129085651-0000/3 on worker-20170129085624-10.1.2.194-33816 (10.1.2.194:33816) with 4 cores
17/01/29 08:56:52,012 INFO StandaloneSchedulerBackend: Granted executor ID app-20170129085651-0000/3 on hostPort 10.1.2.194:33816 with 4 cores, 3.9 GB RAM
17/01/29 08:56:52,015 INFO StandaloneAppClient$ClientEndpoint: Executor added: app-20170129085651-0000/4 on worker-20170129085624-10.1.2.131-38207 (10.1.2.131:38207) with 4 cores
17/01/29 08:56:52,015 INFO StandaloneSchedulerBackend: Granted executor ID app-20170129085651-0000/4 on hostPort 10.1.2.131:38207 with 4 cores, 3.9 GB RAM
17/01/29 08:56:52,017 INFO StandaloneAppClient$ClientEndpoint: Executor added: app-20170129085651-0000/5 on worker-20170129085624-10.1.2.111-35458 (10.1.2.111:35458) with 4 cores
17/01/29 08:56:52,018 INFO StandaloneSchedulerBackend: Granted executor ID app-20170129085651-0000/5 on hostPort 10.1.2.111:35458 with 4 cores, 3.9 GB RAM
17/01/29 08:56:52,019 INFO StandaloneAppClient$ClientEndpoint: Executor added: app-20170129085651-0000/6 on worker-20170129085624-10.1.2.29-38857 (10.1.2.29:38857) with 4 cores
17/01/29 08:56:52,020 INFO StandaloneSchedulerBackend: Granted executor ID app-20170129085651-0000/6 on hostPort 10.1.2.29:38857 with 4 cores, 3.9 GB RAM
17/01/29 08:56:52,021 INFO StandaloneAppClient$ClientEndpoint: Executor added: app-20170129085651-0000/7 on worker-20170129085624-10.1.2.122-37529 (10.1.2.122:37529) with 4 cores
17/01/29 08:56:52,021 INFO StandaloneSchedulerBackend: Granted executor ID app-20170129085651-0000/7 on hostPort 10.1.2.122:37529 with 4 cores, 3.9 GB RAM
17/01/29 08:56:52,080 INFO StandaloneAppClient$ClientEndpoint: Executor updated: app-20170129085651-0000/1 is now RUNNING
17/01/29 08:56:52,083 INFO StandaloneAppClient$ClientEndpoint: Executor updated: app-20170129085651-0000/2 is now RUNNING
17/01/29 08:56:52,086 INFO StandaloneAppClient$ClientEndpoint: Executor updated: app-20170129085651-0000/4 is now RUNNING
17/01/29 08:56:52,088 INFO StandaloneAppClient$ClientEndpoint: Executor updated: app-20170129085651-0000/6 is now RUNNING
17/01/29 08:56:52,091 INFO StandaloneAppClient$ClientEndpoint: Executor updated: app-20170129085651-0000/3 is now RUNNING
17/01/29 08:56:52,094 INFO StandaloneAppClient$ClientEndpoint: Executor updated: app-20170129085651-0000/5 is now RUNNING
17/01/29 08:56:52,096 INFO StandaloneAppClient$ClientEndpoint: Executor updated: app-20170129085651-0000/0 is now RUNNING
17/01/29 08:56:52,099 INFO StandaloneAppClient$ClientEndpoint: Executor updated: app-20170129085651-0000/7 is now RUNNING
17/01/29 08:56:52,209 INFO StandaloneSchedulerBackend: SchedulerBackend is ready for scheduling beginning after reached minRegisteredResourcesRatio: 0.0
17/01/29 08:56:52,616 INFO MemoryStore: Block broadcast_0 stored as values in memory (estimated size 130.8 KB, free 2.1 GB)
17/01/29 08:56:52,684 INFO MemoryStore: Block broadcast_0_piece0 stored as bytes in memory (estimated size 16.5 KB, free 2.1 GB)
17/01/29 08:56:52,686 INFO BlockManagerInfo: Added broadcast_0_piece0 in memory on 10.1.2.241:40816 (size: 16.5 KB, free: 2.1 GB)
17/01/29 08:56:52,696 INFO SparkContext: Created broadcast 0 from textFile at MLUtils.scala:99
17/01/29 08:56:53,334 INFO FileInputFormat: Total input paths to process : 1
17/01/29 08:56:53,374 INFO NetworkTopology: Adding a new node: /default-rack/10.1.2.111:50010
17/01/29 08:56:53,374 INFO NetworkTopology: Adding a new node: /default-rack/10.1.2.182:50010
17/01/29 08:56:53,375 INFO NetworkTopology: Adding a new node: /default-rack/10.1.2.29:50010
17/01/29 08:56:53,375 INFO NetworkTopology: Adding a new node: /default-rack/10.1.2.26:50010
17/01/29 08:56:53,375 INFO NetworkTopology: Adding a new node: /default-rack/10.1.2.194:50010
17/01/29 08:56:53,375 INFO NetworkTopology: Adding a new node: /default-rack/10.1.2.122:50010
17/01/29 08:56:53,411 INFO SparkContext: Starting job: first at GeneralizedLinearAlgorithm.scala:246
17/01/29 08:56:53,423 INFO DAGScheduler: Got job 0 (first at GeneralizedLinearAlgorithm.scala:246) with 1 output partitions
17/01/29 08:56:53,423 INFO DAGScheduler: Final stage: ResultStage 0 (first at GeneralizedLinearAlgorithm.scala:246)
17/01/29 08:56:53,424 INFO DAGScheduler: Parents of final stage: List()
17/01/29 08:56:53,429 INFO DAGScheduler: Missing parents: List()
17/01/29 08:56:53,448 INFO DAGScheduler: Submitting ResultStage 0 (MapPartitionsRDD[6] at map at GeneralizedLinearAlgorithm.scala:246), which has no missing parents
17/01/29 08:56:53,471 INFO MemoryStore: Block broadcast_1 stored as values in memory (estimated size 4.2 KB, free 2.1 GB)
17/01/29 08:56:53,474 INFO MemoryStore: Block broadcast_1_piece0 stored as bytes in memory (estimated size 2.4 KB, free 2.1 GB)
17/01/29 08:56:53,474 INFO BlockManagerInfo: Added broadcast_1_piece0 in memory on 10.1.2.241:40816 (size: 2.4 KB, free: 2.1 GB)
17/01/29 08:56:53,476 INFO SparkContext: Created broadcast 1 from broadcast at DAGScheduler.scala:1012
17/01/29 08:56:53,478 INFO DAGScheduler: Submitting 1 missing tasks from ResultStage 0 (MapPartitionsRDD[6] at map at GeneralizedLinearAlgorithm.scala:246)
17/01/29 08:56:53,480 INFO TaskSchedulerImpl: Adding task set 0.0 with 1 tasks
17/01/29 08:56:53,873 INFO CoarseGrainedSchedulerBackend$DriverEndpoint: Registered executor NettyRpcEndpointRef(null) (10.1.2.27:46714) with ID 2
17/01/29 08:56:53,915 INFO TaskSetManager: Starting task 0.0 in stage 0.0 (TID 0, 10.1.2.27, partition 0, ANY, 5456 bytes)
17/01/29 08:56:53,920 INFO BlockManagerMasterEndpoint: Registering block manager 10.1.2.27:38845 with 2.1 GB RAM, BlockManagerId(2, 10.1.2.27, 38845)
17/01/29 08:56:53,925 INFO CoarseGrainedSchedulerBackend$DriverEndpoint: Launching task 0 on executor id: 2 hostname: 10.1.2.27.
17/01/29 08:56:53,927 INFO CoarseGrainedSchedulerBackend$DriverEndpoint: Registered executor NettyRpcEndpointRef(null) (10.1.2.122:39408) with ID 7
17/01/29 08:56:53,929 INFO CoarseGrainedSchedulerBackend$DriverEndpoint: Registered executor NettyRpcEndpointRef(null) (10.1.2.182:52922) with ID 1
17/01/29 08:56:53,930 INFO CoarseGrainedSchedulerBackend$DriverEndpoint: Registered executor NettyRpcEndpointRef(null) (10.1.2.131:60174) with ID 4
17/01/29 08:56:53,971 INFO BlockManagerMasterEndpoint: Registering block manager 10.1.2.182:38091 with 2.1 GB RAM, BlockManagerId(1, 10.1.2.182, 38091)
17/01/29 08:56:53,980 INFO BlockManagerMasterEndpoint: Registering block manager 10.1.2.131:41486 with 2.1 GB RAM, BlockManagerId(4, 10.1.2.131, 41486)
17/01/29 08:56:53,980 INFO CoarseGrainedSchedulerBackend$DriverEndpoint: Registered executor NettyRpcEndpointRef(null) (10.1.2.111:33266) with ID 5
17/01/29 08:56:53,982 INFO BlockManagerMasterEndpoint: Registering block manager 10.1.2.122:38089 with 2.1 GB RAM, BlockManagerId(7, 10.1.2.122, 38089)
17/01/29 08:56:54,031 INFO BlockManagerMasterEndpoint: Registering block manager 10.1.2.111:35778 with 2.1 GB RAM, BlockManagerId(5, 10.1.2.111, 35778)
17/01/29 08:56:54,050 INFO CoarseGrainedSchedulerBackend$DriverEndpoint: Registered executor NettyRpcEndpointRef(null) (10.1.2.26:54428) with ID 0
17/01/29 08:56:54,093 INFO BlockManagerMasterEndpoint: Registering block manager 10.1.2.26:39210 with 2.1 GB RAM, BlockManagerId(0, 10.1.2.26, 39210)
17/01/29 08:56:54,171 INFO BlockManagerInfo: Added broadcast_1_piece0 in memory on 10.1.2.27:38845 (size: 2.4 KB, free: 2.1 GB)
17/01/29 08:56:54,316 INFO BlockManagerInfo: Added broadcast_0_piece0 in memory on 10.1.2.27:38845 (size: 16.5 KB, free: 2.1 GB)
17/01/29 08:56:56,918 INFO CoarseGrainedSchedulerBackend$DriverEndpoint: Registered executor NettyRpcEndpointRef(null) (10.1.2.29:50736) with ID 6
17/01/29 08:56:56,966 INFO BlockManagerMasterEndpoint: Registering block manager 10.1.2.29:39424 with 2.1 GB RAM, BlockManagerId(6, 10.1.2.29, 39424)
17/01/29 08:56:57,012 INFO CoarseGrainedSchedulerBackend$DriverEndpoint: Registered executor NettyRpcEndpointRef(null) (10.1.2.194:39260) with ID 3
17/01/29 08:56:57,076 INFO BlockManagerMasterEndpoint: Registering block manager 10.1.2.194:34076 with 2.1 GB RAM, BlockManagerId(3, 10.1.2.194, 34076)
17/01/29 08:57:01,418 INFO BlockManagerInfo: Added rdd_5_0 in memory on 10.1.2.27:38845 (size: 70.0 MB, free: 2.0 GB)
17/01/29 08:57:01,476 INFO DAGScheduler: ResultStage 0 (first at GeneralizedLinearAlgorithm.scala:246) finished in 7.985 s
17/01/29 08:57:01,475 INFO TaskSetManager: Finished task 0.0 in stage 0.0 (TID 0) in 7581 ms on 10.1.2.27 (1/1)
17/01/29 08:57:01,480 INFO DAGScheduler: Job 0 finished: first at GeneralizedLinearAlgorithm.scala:246, took 8.068276 s
17/01/29 08:57:01,483 INFO TaskSchedulerImpl: Removed TaskSet 0.0, whose tasks have all completed, from pool 
17/01/29 08:57:01,492 INFO SparkContext: Starting job: count at DataValidators.scala:40
17/01/29 08:57:01,494 INFO DAGScheduler: Got job 1 (count at DataValidators.scala:40) with 59 output partitions
17/01/29 08:57:01,494 INFO DAGScheduler: Final stage: ResultStage 1 (count at DataValidators.scala:40)
17/01/29 08:57:01,494 INFO DAGScheduler: Parents of final stage: List()
17/01/29 08:57:01,497 INFO DAGScheduler: Missing parents: List()
17/01/29 08:57:01,498 INFO DAGScheduler: Submitting ResultStage 1 (MapPartitionsRDD[7] at filter at DataValidators.scala:40), which has no missing parents
17/01/29 08:57:01,523 INFO MemoryStore: Block broadcast_2 stored as values in memory (estimated size 3.9 KB, free 2.1 GB)
17/01/29 08:57:01,525 INFO MemoryStore: Block broadcast_2_piece0 stored as bytes in memory (estimated size 2.2 KB, free 2.1 GB)
17/01/29 08:57:01,526 INFO BlockManagerInfo: Added broadcast_2_piece0 in memory on 10.1.2.241:40816 (size: 2.2 KB, free: 2.1 GB)
17/01/29 08:57:01,526 INFO SparkContext: Created broadcast 2 from broadcast at DAGScheduler.scala:1012
17/01/29 08:57:01,528 INFO DAGScheduler: Submitting 59 missing tasks from ResultStage 1 (MapPartitionsRDD[7] at filter at DataValidators.scala:40)
17/01/29 08:57:01,529 INFO TaskSchedulerImpl: Adding task set 1.0 with 59 tasks
17/01/29 08:57:01,535 INFO TaskSetManager: Starting task 0.0 in stage 1.0 (TID 1, 10.1.2.27, partition 0, PROCESS_LOCAL, 5374 bytes)
17/01/29 08:57:01,538 INFO TaskSetManager: Starting task 58.0 in stage 1.0 (TID 2, 10.1.2.182, partition 58, NODE_LOCAL, 5374 bytes)
17/01/29 08:57:01,540 INFO CoarseGrainedSchedulerBackend$DriverEndpoint: Launching task 2 on executor id: 1 hostname: 10.1.2.182.
17/01/29 08:57:01,540 INFO CoarseGrainedSchedulerBackend$DriverEndpoint: Launching task 1 on executor id: 2 hostname: 10.1.2.27.
17/01/29 08:57:01,560 INFO BlockManagerInfo: Added broadcast_2_piece0 in memory on 10.1.2.27:38845 (size: 2.2 KB, free: 2.0 GB)
17/01/29 08:57:01,618 INFO TaskSetManager: Finished task 0.0 in stage 1.0 (TID 1) in 85 ms on 10.1.2.27 (1/59)
17/01/29 08:57:01,807 INFO BlockManagerInfo: Added broadcast_2_piece0 in memory on 10.1.2.182:38091 (size: 2.2 KB, free: 2.1 GB)
17/01/29 08:57:01,951 INFO BlockManagerInfo: Added broadcast_0_piece0 in memory on 10.1.2.182:38091 (size: 16.5 KB, free: 2.1 GB)
17/01/29 08:57:04,830 INFO TaskSetManager: Starting task 1.0 in stage 1.0 (TID 3, 10.1.2.111, partition 1, ANY, 5374 bytes)
17/01/29 08:57:04,835 INFO TaskSetManager: Starting task 2.0 in stage 1.0 (TID 4, 10.1.2.182, partition 2, ANY, 5374 bytes)
17/01/29 08:57:04,836 INFO TaskSetManager: Starting task 3.0 in stage 1.0 (TID 5, 10.1.2.131, partition 3, ANY, 5374 bytes)
17/01/29 08:57:04,841 INFO TaskSetManager: Starting task 4.0 in stage 1.0 (TID 6, 10.1.2.194, partition 4, ANY, 5374 bytes)
17/01/29 08:57:04,843 INFO TaskSetManager: Starting task 5.0 in stage 1.0 (TID 7, 10.1.2.122, partition 5, ANY, 5374 bytes)
17/01/29 08:57:04,845 INFO TaskSetManager: Starting task 6.0 in stage 1.0 (TID 8, 10.1.2.29, partition 6, ANY, 5374 bytes)
17/01/29 08:57:04,847 INFO TaskSetManager: Starting task 7.0 in stage 1.0 (TID 9, 10.1.2.27, partition 7, ANY, 5374 bytes)
17/01/29 08:57:04,849 INFO TaskSetManager: Starting task 8.0 in stage 1.0 (TID 10, 10.1.2.26, partition 8, ANY, 5374 bytes)
17/01/29 08:57:04,851 INFO TaskSetManager: Starting task 9.0 in stage 1.0 (TID 11, 10.1.2.111, partition 9, ANY, 5374 bytes)
17/01/29 08:57:04,855 INFO TaskSetManager: Starting task 10.0 in stage 1.0 (TID 12, 10.1.2.182, partition 10, ANY, 5374 bytes)
17/01/29 08:57:04,857 INFO TaskSetManager: Starting task 11.0 in stage 1.0 (TID 13, 10.1.2.131, partition 11, ANY, 5374 bytes)
17/01/29 08:57:04,858 INFO TaskSetManager: Starting task 12.0 in stage 1.0 (TID 14, 10.1.2.194, partition 12, ANY, 5374 bytes)
17/01/29 08:57:04,860 INFO TaskSetManager: Starting task 13.0 in stage 1.0 (TID 15, 10.1.2.122, partition 13, ANY, 5374 bytes)
17/01/29 08:57:04,862 INFO TaskSetManager: Starting task 14.0 in stage 1.0 (TID 16, 10.1.2.29, partition 14, ANY, 5374 bytes)
17/01/29 08:57:04,863 INFO TaskSetManager: Starting task 15.0 in stage 1.0 (TID 17, 10.1.2.27, partition 15, ANY, 5374 bytes)
17/01/29 08:57:04,865 INFO TaskSetManager: Starting task 16.0 in stage 1.0 (TID 18, 10.1.2.26, partition 16, ANY, 5374 bytes)
17/01/29 08:57:04,868 INFO TaskSetManager: Starting task 17.0 in stage 1.0 (TID 19, 10.1.2.111, partition 17, ANY, 5374 bytes)
17/01/29 08:57:04,869 INFO TaskSetManager: Starting task 18.0 in stage 1.0 (TID 20, 10.1.2.182, partition 18, ANY, 5374 bytes)
17/01/29 08:57:04,871 INFO TaskSetManager: Starting task 19.0 in stage 1.0 (TID 21, 10.1.2.131, partition 19, ANY, 5374 bytes)
17/01/29 08:57:04,872 INFO TaskSetManager: Starting task 20.0 in stage 1.0 (TID 22, 10.1.2.194, partition 20, ANY, 5374 bytes)
17/01/29 08:57:04,874 INFO TaskSetManager: Starting task 21.0 in stage 1.0 (TID 23, 10.1.2.122, partition 21, ANY, 5374 bytes)
17/01/29 08:57:04,875 INFO TaskSetManager: Starting task 22.0 in stage 1.0 (TID 24, 10.1.2.29, partition 22, ANY, 5374 bytes)
17/01/29 08:57:04,877 INFO TaskSetManager: Starting task 23.0 in stage 1.0 (TID 25, 10.1.2.27, partition 23, ANY, 5374 bytes)
17/01/29 08:57:04,878 INFO TaskSetManager: Starting task 24.0 in stage 1.0 (TID 26, 10.1.2.26, partition 24, ANY, 5374 bytes)
17/01/29 08:57:04,880 INFO TaskSetManager: Starting task 25.0 in stage 1.0 (TID 27, 10.1.2.111, partition 25, ANY, 5374 bytes)
17/01/29 08:57:04,881 INFO TaskSetManager: Starting task 26.0 in stage 1.0 (TID 28, 10.1.2.131, partition 26, ANY, 5374 bytes)
17/01/29 08:57:04,883 INFO TaskSetManager: Starting task 27.0 in stage 1.0 (TID 29, 10.1.2.194, partition 27, ANY, 5374 bytes)
17/01/29 08:57:04,884 INFO TaskSetManager: Starting task 28.0 in stage 1.0 (TID 30, 10.1.2.122, partition 28, ANY, 5374 bytes)
17/01/29 08:57:04,886 INFO TaskSetManager: Starting task 29.0 in stage 1.0 (TID 31, 10.1.2.29, partition 29, ANY, 5374 bytes)
17/01/29 08:57:04,887 INFO TaskSetManager: Starting task 30.0 in stage 1.0 (TID 32, 10.1.2.27, partition 30, ANY, 5374 bytes)
17/01/29 08:57:04,889 INFO TaskSetManager: Starting task 31.0 in stage 1.0 (TID 33, 10.1.2.26, partition 31, ANY, 5374 bytes)
17/01/29 08:57:04,889 INFO CoarseGrainedSchedulerBackend$DriverEndpoint: Launching task 3 on executor id: 5 hostname: 10.1.2.111.
17/01/29 08:57:04,890 INFO CoarseGrainedSchedulerBackend$DriverEndpoint: Launching task 11 on executor id: 5 hostname: 10.1.2.111.
17/01/29 08:57:04,890 INFO CoarseGrainedSchedulerBackend$DriverEndpoint: Launching task 19 on executor id: 5 hostname: 10.1.2.111.
17/01/29 08:57:04,891 INFO CoarseGrainedSchedulerBackend$DriverEndpoint: Launching task 27 on executor id: 5 hostname: 10.1.2.111.
17/01/29 08:57:04,892 INFO CoarseGrainedSchedulerBackend$DriverEndpoint: Launching task 4 on executor id: 1 hostname: 10.1.2.182.
17/01/29 08:57:04,893 INFO CoarseGrainedSchedulerBackend$DriverEndpoint: Launching task 12 on executor id: 1 hostname: 10.1.2.182.
17/01/29 08:57:04,894 INFO CoarseGrainedSchedulerBackend$DriverEndpoint: Launching task 20 on executor id: 1 hostname: 10.1.2.182.
17/01/29 08:57:04,894 INFO CoarseGrainedSchedulerBackend$DriverEndpoint: Launching task 5 on executor id: 4 hostname: 10.1.2.131.
17/01/29 08:57:04,895 INFO CoarseGrainedSchedulerBackend$DriverEndpoint: Launching task 13 on executor id: 4 hostname: 10.1.2.131.
17/01/29 08:57:04,896 INFO CoarseGrainedSchedulerBackend$DriverEndpoint: Launching task 21 on executor id: 4 hostname: 10.1.2.131.
17/01/29 08:57:04,897 INFO CoarseGrainedSchedulerBackend$DriverEndpoint: Launching task 28 on executor id: 4 hostname: 10.1.2.131.
17/01/29 08:57:04,899 INFO CoarseGrainedSchedulerBackend$DriverEndpoint: Launching task 6 on executor id: 3 hostname: 10.1.2.194.
17/01/29 08:57:04,900 INFO CoarseGrainedSchedulerBackend$DriverEndpoint: Launching task 14 on executor id: 3 hostname: 10.1.2.194.
17/01/29 08:57:04,900 INFO CoarseGrainedSchedulerBackend$DriverEndpoint: Launching task 22 on executor id: 3 hostname: 10.1.2.194.
17/01/29 08:57:04,901 INFO CoarseGrainedSchedulerBackend$DriverEndpoint: Launching task 29 on executor id: 3 hostname: 10.1.2.194.
17/01/29 08:57:04,903 INFO CoarseGrainedSchedulerBackend$DriverEndpoint: Launching task 7 on executor id: 7 hostname: 10.1.2.122.
17/01/29 08:57:04,904 INFO CoarseGrainedSchedulerBackend$DriverEndpoint: Launching task 15 on executor id: 7 hostname: 10.1.2.122.
17/01/29 08:57:04,905 INFO CoarseGrainedSchedulerBackend$DriverEndpoint: Launching task 23 on executor id: 7 hostname: 10.1.2.122.
17/01/29 08:57:04,905 INFO CoarseGrainedSchedulerBackend$DriverEndpoint: Launching task 30 on executor id: 7 hostname: 10.1.2.122.
17/01/29 08:57:04,906 INFO CoarseGrainedSchedulerBackend$DriverEndpoint: Launching task 8 on executor id: 6 hostname: 10.1.2.29.
17/01/29 08:57:04,906 INFO CoarseGrainedSchedulerBackend$DriverEndpoint: Launching task 16 on executor id: 6 hostname: 10.1.2.29.
17/01/29 08:57:04,907 INFO CoarseGrainedSchedulerBackend$DriverEndpoint: Launching task 24 on executor id: 6 hostname: 10.1.2.29.
17/01/29 08:57:04,907 INFO CoarseGrainedSchedulerBackend$DriverEndpoint: Launching task 31 on executor id: 6 hostname: 10.1.2.29.
17/01/29 08:57:04,908 INFO CoarseGrainedSchedulerBackend$DriverEndpoint: Launching task 9 on executor id: 2 hostname: 10.1.2.27.
17/01/29 08:57:04,908 INFO CoarseGrainedSchedulerBackend$DriverEndpoint: Launching task 17 on executor id: 2 hostname: 10.1.2.27.
17/01/29 08:57:04,909 INFO CoarseGrainedSchedulerBackend$DriverEndpoint: Launching task 25 on executor id: 2 hostname: 10.1.2.27.
17/01/29 08:57:04,909 INFO CoarseGrainedSchedulerBackend$DriverEndpoint: Launching task 32 on executor id: 2 hostname: 10.1.2.27.
17/01/29 08:57:04,910 INFO CoarseGrainedSchedulerBackend$DriverEndpoint: Launching task 10 on executor id: 0 hostname: 10.1.2.26.
17/01/29 08:57:04,912 INFO CoarseGrainedSchedulerBackend$DriverEndpoint: Launching task 18 on executor id: 0 hostname: 10.1.2.26.
17/01/29 08:57:04,913 INFO CoarseGrainedSchedulerBackend$DriverEndpoint: Launching task 26 on executor id: 0 hostname: 10.1.2.26.
17/01/29 08:57:04,915 INFO CoarseGrainedSchedulerBackend$DriverEndpoint: Launching task 33 on executor id: 0 hostname: 10.1.2.26.
17/01/29 08:57:05,190 INFO BlockManagerInfo: Added broadcast_2_piece0 in memory on 10.1.2.131:41486 (size: 2.2 KB, free: 2.1 GB)
17/01/29 08:57:05,239 INFO BlockManagerInfo: Added broadcast_2_piece0 in memory on 10.1.2.122:38089 (size: 2.2 KB, free: 2.1 GB)
17/01/29 08:57:05,245 INFO BlockManagerInfo: Added broadcast_2_piece0 in memory on 10.1.2.194:34076 (size: 2.2 KB, free: 2.1 GB)
17/01/29 08:57:05,254 INFO BlockManagerInfo: Added broadcast_2_piece0 in memory on 10.1.2.29:39424 (size: 2.2 KB, free: 2.1 GB)
17/01/29 08:57:05,287 INFO BlockManagerInfo: Added broadcast_2_piece0 in memory on 10.1.2.111:35778 (size: 2.2 KB, free: 2.1 GB)
17/01/29 08:57:05,320 INFO BlockManagerInfo: Added broadcast_2_piece0 in memory on 10.1.2.26:39210 (size: 2.2 KB, free: 2.1 GB)
17/01/29 08:57:05,370 INFO BlockManagerInfo: Added broadcast_0_piece0 in memory on 10.1.2.131:41486 (size: 16.5 KB, free: 2.1 GB)
17/01/29 08:57:05,398 INFO BlockManagerInfo: Added broadcast_0_piece0 in memory on 10.1.2.122:38089 (size: 16.5 KB, free: 2.1 GB)
17/01/29 08:57:05,429 INFO BlockManagerInfo: Added broadcast_0_piece0 in memory on 10.1.2.29:39424 (size: 16.5 KB, free: 2.1 GB)
17/01/29 08:57:05,432 INFO BlockManagerInfo: Added broadcast_0_piece0 in memory on 10.1.2.194:34076 (size: 16.5 KB, free: 2.1 GB)
17/01/29 08:57:05,456 INFO BlockManagerInfo: Added broadcast_0_piece0 in memory on 10.1.2.111:35778 (size: 16.5 KB, free: 2.1 GB)
17/01/29 08:57:05,530 INFO BlockManagerInfo: Added broadcast_0_piece0 in memory on 10.1.2.26:39210 (size: 16.5 KB, free: 2.1 GB)
18.729: [GC [PSYoungGen: 1024512K->157102K(1195008K)] 1024512K->157174K(3926016K), 0.0726380 secs] [Times: user=0.09 sys=0.03, real=0.08 secs] 
17/01/29 08:57:05,835 INFO BlockManagerInfo: Removed broadcast_1_piece0 on 10.1.2.241:40816 in memory (size: 2.4 KB, free: 2.1 GB)
17/01/29 08:57:05,837 INFO BlockManagerInfo: Removed broadcast_1_piece0 on 10.1.2.27:38845 in memory (size: 2.4 KB, free: 2.0 GB)
17/01/29 08:57:20,629 INFO BlockManagerInfo: Added rdd_5_58 in memory on 10.1.2.182:38091 (size: 72.8 MB, free: 2047.6 MB)
17/01/29 08:57:20,692 INFO TaskSetManager: Starting task 32.0 in stage 1.0 (TID 34, 10.1.2.182, partition 32, ANY, 5374 bytes)
17/01/29 08:57:20,692 INFO CoarseGrainedSchedulerBackend$DriverEndpoint: Launching task 34 on executor id: 1 hostname: 10.1.2.182.
17/01/29 08:57:20,695 INFO TaskSetManager: Finished task 58.0 in stage 1.0 (TID 2) in 19157 ms on 10.1.2.182 (2/59)
17/01/29 08:57:22,904 INFO BlockManagerInfo: Added rdd_5_19 in memory on 10.1.2.131:41486 (size: 70.0 MB, free: 2.0 GB)
17/01/29 08:57:22,967 INFO TaskSetManager: Starting task 33.0 in stage 1.0 (TID 35, 10.1.2.131, partition 33, ANY, 5374 bytes)
17/01/29 08:57:22,967 INFO CoarseGrainedSchedulerBackend$DriverEndpoint: Launching task 35 on executor id: 4 hostname: 10.1.2.131.
17/01/29 08:57:22,968 INFO TaskSetManager: Finished task 19.0 in stage 1.0 (TID 21) in 18098 ms on 10.1.2.131 (3/59)
17/01/29 08:57:23,078 INFO BlockManagerInfo: Added rdd_5_26 in memory on 10.1.2.131:41486 (size: 69.9 MB, free: 1980.5 MB)
17/01/29 08:57:23,112 INFO TaskSetManager: Starting task 34.0 in stage 1.0 (TID 36, 10.1.2.131, partition 34, ANY, 5374 bytes)
17/01/29 08:57:23,113 INFO CoarseGrainedSchedulerBackend$DriverEndpoint: Launching task 36 on executor id: 4 hostname: 10.1.2.131.
17/01/29 08:57:23,113 INFO TaskSetManager: Finished task 26.0 in stage 1.0 (TID 28) in 18233 ms on 10.1.2.131 (4/59)
17/01/29 08:57:23,317 INFO BlockManagerInfo: Added rdd_5_3 in memory on 10.1.2.131:41486 (size: 69.9 MB, free: 1910.6 MB)
17/01/29 08:57:23,351 INFO TaskSetManager: Starting task 35.0 in stage 1.0 (TID 37, 10.1.2.131, partition 35, ANY, 5374 bytes)
17/01/29 08:57:23,351 INFO CoarseGrainedSchedulerBackend$DriverEndpoint: Launching task 37 on executor id: 4 hostname: 10.1.2.131.
17/01/29 08:57:23,352 INFO TaskSetManager: Finished task 3.0 in stage 1.0 (TID 5) in 18516 ms on 10.1.2.131 (5/59)
17/01/29 08:57:23,357 INFO BlockManagerInfo: Added rdd_5_11 in memory on 10.1.2.131:41486 (size: 69.9 MB, free: 1840.7 MB)
17/01/29 08:57:23,382 INFO TaskSetManager: Starting task 36.0 in stage 1.0 (TID 38, 10.1.2.131, partition 36, ANY, 5374 bytes)
17/01/29 08:57:23,382 INFO CoarseGrainedSchedulerBackend$DriverEndpoint: Launching task 38 on executor id: 4 hostname: 10.1.2.131.
17/01/29 08:57:23,383 INFO TaskSetManager: Finished task 11.0 in stage 1.0 (TID 13) in 18527 ms on 10.1.2.131 (6/59)
17/01/29 08:57:23,864 INFO BlockManagerInfo: Added rdd_5_18 in memory on 10.1.2.182:38091 (size: 70.0 MB, free: 1977.6 MB)
17/01/29 08:57:23,883 INFO TaskSetManager: Starting task 37.0 in stage 1.0 (TID 39, 10.1.2.182, partition 37, ANY, 5374 bytes)
17/01/29 08:57:23,883 INFO CoarseGrainedSchedulerBackend$DriverEndpoint: Launching task 39 on executor id: 1 hostname: 10.1.2.182.
17/01/29 08:57:23,883 INFO TaskSetManager: Finished task 18.0 in stage 1.0 (TID 20) in 19015 ms on 10.1.2.182 (7/59)
17/01/29 08:57:24,398 INFO BlockManagerInfo: Added rdd_5_15 in memory on 10.1.2.27:38845 (size: 69.9 MB, free: 1980.5 MB)
17/01/29 08:57:24,432 INFO TaskSetManager: Starting task 38.0 in stage 1.0 (TID 40, 10.1.2.27, partition 38, ANY, 5374 bytes)
17/01/29 08:57:24,432 INFO CoarseGrainedSchedulerBackend$DriverEndpoint: Launching task 40 on executor id: 2 hostname: 10.1.2.27.
17/01/29 08:57:24,433 INFO TaskSetManager: Finished task 15.0 in stage 1.0 (TID 17) in 19570 ms on 10.1.2.27 (8/59)
17/01/29 08:57:24,628 INFO BlockManagerInfo: Added rdd_5_31 in memory on 10.1.2.26:39210 (size: 69.7 MB, free: 2.0 GB)
17/01/29 08:57:24,643 INFO BlockManagerInfo: Added rdd_5_23 in memory on 10.1.2.27:38845 (size: 69.9 MB, free: 1910.6 MB)
17/01/29 08:57:24,664 INFO TaskSetManager: Starting task 39.0 in stage 1.0 (TID 41, 10.1.2.27, partition 39, ANY, 5374 bytes)
17/01/29 08:57:24,664 INFO CoarseGrainedSchedulerBackend$DriverEndpoint: Launching task 41 on executor id: 2 hostname: 10.1.2.27.
17/01/29 08:57:24,664 INFO TaskSetManager: Finished task 23.0 in stage 1.0 (TID 25) in 19789 ms on 10.1.2.27 (9/59)
17/01/29 08:57:24,694 INFO TaskSetManager: Starting task 40.0 in stage 1.0 (TID 42, 10.1.2.26, partition 40, ANY, 5374 bytes)
17/01/29 08:57:24,695 INFO CoarseGrainedSchedulerBackend$DriverEndpoint: Launching task 42 on executor id: 0 hostname: 10.1.2.26.
17/01/29 08:57:24,695 INFO TaskSetManager: Finished task 31.0 in stage 1.0 (TID 33) in 19808 ms on 10.1.2.26 (10/59)
17/01/29 08:57:24,769 INFO BlockManagerInfo: Added rdd_5_24 in memory on 10.1.2.26:39210 (size: 69.8 MB, free: 1980.9 MB)
17/01/29 08:57:24,787 INFO TaskSetManager: Starting task 41.0 in stage 1.0 (TID 43, 10.1.2.26, partition 41, ANY, 5374 bytes)
17/01/29 08:57:24,787 INFO CoarseGrainedSchedulerBackend$DriverEndpoint: Launching task 43 on executor id: 0 hostname: 10.1.2.26.
17/01/29 08:57:24,788 INFO TaskSetManager: Finished task 24.0 in stage 1.0 (TID 26) in 19910 ms on 10.1.2.26 (11/59)
17/01/29 08:57:24,854 INFO BlockManagerInfo: Added rdd_5_2 in memory on 10.1.2.182:38091 (size: 69.9 MB, free: 1907.7 MB)
17/01/29 08:57:24,878 INFO TaskSetManager: Starting task 42.0 in stage 1.0 (TID 44, 10.1.2.182, partition 42, ANY, 5374 bytes)
17/01/29 08:57:24,878 INFO CoarseGrainedSchedulerBackend$DriverEndpoint: Launching task 44 on executor id: 1 hostname: 10.1.2.182.
17/01/29 08:57:24,878 INFO TaskSetManager: Finished task 2.0 in stage 1.0 (TID 4) in 20045 ms on 10.1.2.182 (12/59)
17/01/29 08:57:24,898 INFO BlockManagerInfo: Added rdd_5_8 in memory on 10.1.2.26:39210 (size: 70.0 MB, free: 1910.9 MB)
17/01/29 08:57:24,952 INFO TaskSetManager: Starting task 43.0 in stage 1.0 (TID 45, 10.1.2.26, partition 43, ANY, 5374 bytes)
17/01/29 08:57:24,953 INFO CoarseGrainedSchedulerBackend$DriverEndpoint: Launching task 45 on executor id: 0 hostname: 10.1.2.26.
17/01/29 08:57:24,953 INFO TaskSetManager: Finished task 8.0 in stage 1.0 (TID 10) in 20106 ms on 10.1.2.26 (13/59)
17/01/29 08:57:24,993 INFO BlockManagerInfo: Added rdd_5_16 in memory on 10.1.2.26:39210 (size: 70.0 MB, free: 1841.0 MB)
17/01/29 08:57:25,013 INFO TaskSetManager: Starting task 44.0 in stage 1.0 (TID 46, 10.1.2.26, partition 44, ANY, 5374 bytes)
17/01/29 08:57:25,013 INFO TaskSetManager: Finished task 16.0 in stage 1.0 (TID 18) in 20150 ms on 10.1.2.26 (14/59)
17/01/29 08:57:25,014 INFO CoarseGrainedSchedulerBackend$DriverEndpoint: Launching task 46 on executor id: 0 hostname: 10.1.2.26.
17/01/29 08:57:26,063 INFO BlockManagerInfo: Added rdd_5_7 in memory on 10.1.2.27:38845 (size: 70.0 MB, free: 1840.6 MB)
17/01/29 08:57:26,084 INFO TaskSetManager: Starting task 45.0 in stage 1.0 (TID 47, 10.1.2.27, partition 45, ANY, 5374 bytes)
17/01/29 08:57:26,084 INFO CoarseGrainedSchedulerBackend$DriverEndpoint: Launching task 47 on executor id: 2 hostname: 10.1.2.27.
17/01/29 08:57:26,085 INFO TaskSetManager: Finished task 7.0 in stage 1.0 (TID 9) in 21240 ms on 10.1.2.27 (15/59)
17/01/29 08:57:26,087 INFO BlockManagerInfo: Added rdd_5_10 in memory on 10.1.2.182:38091 (size: 70.0 MB, free: 1837.8 MB)
17/01/29 08:57:26,102 INFO TaskSetManager: Starting task 46.0 in stage 1.0 (TID 48, 10.1.2.182, partition 46, ANY, 5374 bytes)
17/01/29 08:57:26,102 INFO CoarseGrainedSchedulerBackend$DriverEndpoint: Launching task 48 on executor id: 1 hostname: 10.1.2.182.
17/01/29 08:57:26,103 INFO TaskSetManager: Finished task 10.0 in stage 1.0 (TID 12) in 21252 ms on 10.1.2.182 (16/59)
17/01/29 08:57:26,163 INFO BlockManagerInfo: Added rdd_5_21 in memory on 10.1.2.122:38089 (size: 69.9 MB, free: 2.0 GB)
17/01/29 08:57:26,234 INFO TaskSetManager: Starting task 47.0 in stage 1.0 (TID 49, 10.1.2.122, partition 47, ANY, 5374 bytes)
17/01/29 08:57:26,235 INFO CoarseGrainedSchedulerBackend$DriverEndpoint: Launching task 49 on executor id: 7 hostname: 10.1.2.122.
17/01/29 08:57:26,235 INFO TaskSetManager: Finished task 21.0 in stage 1.0 (TID 23) in 21363 ms on 10.1.2.122 (17/59)
17/01/29 08:57:26,579 INFO BlockManagerInfo: Added rdd_5_22 in memory on 10.1.2.29:39424 (size: 69.8 MB, free: 2.0 GB)
17/01/29 08:57:26,647 INFO TaskSetManager: Starting task 48.0 in stage 1.0 (TID 50, 10.1.2.29, partition 48, ANY, 5374 bytes)
17/01/29 08:57:26,647 INFO CoarseGrainedSchedulerBackend$DriverEndpoint: Launching task 50 on executor id: 6 hostname: 10.1.2.29.
17/01/29 08:57:26,647 INFO TaskSetManager: Finished task 22.0 in stage 1.0 (TID 24) in 21773 ms on 10.1.2.29 (18/59)
17/01/29 08:57:26,720 INFO BlockManagerInfo: Added rdd_5_6 in memory on 10.1.2.29:39424 (size: 69.9 MB, free: 1980.6 MB)
17/01/29 08:57:26,743 INFO TaskSetManager: Starting task 49.0 in stage 1.0 (TID 51, 10.1.2.29, partition 49, ANY, 5374 bytes)
17/01/29 08:57:26,743 INFO CoarseGrainedSchedulerBackend$DriverEndpoint: Launching task 51 on executor id: 6 hostname: 10.1.2.29.
17/01/29 08:57:26,743 INFO TaskSetManager: Finished task 6.0 in stage 1.0 (TID 8) in 21900 ms on 10.1.2.29 (19/59)
17/01/29 08:57:26,851 INFO BlockManagerInfo: Added rdd_5_17 in memory on 10.1.2.111:35778 (size: 69.9 MB, free: 2.0 GB)
17/01/29 08:57:26,901 INFO BlockManagerInfo: Added rdd_5_9 in memory on 10.1.2.111:35778 (size: 69.9 MB, free: 1980.6 MB)
17/01/29 08:57:26,929 INFO TaskSetManager: Starting task 50.0 in stage 1.0 (TID 52, 10.1.2.111, partition 50, ANY, 5374 bytes)
17/01/29 08:57:26,930 INFO CoarseGrainedSchedulerBackend$DriverEndpoint: Launching task 52 on executor id: 5 hostname: 10.1.2.111.
17/01/29 08:57:26,930 INFO TaskSetManager: Finished task 17.0 in stage 1.0 (TID 19) in 22065 ms on 10.1.2.111 (20/59)
17/01/29 08:57:26,936 INFO TaskSetManager: Starting task 51.0 in stage 1.0 (TID 53, 10.1.2.111, partition 51, ANY, 5374 bytes)
17/01/29 08:57:26,936 INFO CoarseGrainedSchedulerBackend$DriverEndpoint: Launching task 53 on executor id: 5 hostname: 10.1.2.111.
17/01/29 08:57:26,937 INFO TaskSetManager: Finished task 9.0 in stage 1.0 (TID 11) in 22087 ms on 10.1.2.111 (21/59)
17/01/29 08:57:26,975 INFO BlockManagerInfo: Added rdd_5_30 in memory on 10.1.2.27:38845 (size: 70.0 MB, free: 1770.6 MB)
17/01/29 08:57:26,997 INFO TaskSetManager: Starting task 52.0 in stage 1.0 (TID 54, 10.1.2.27, partition 52, ANY, 5374 bytes)
17/01/29 08:57:26,998 INFO CoarseGrainedSchedulerBackend$DriverEndpoint: Launching task 54 on executor id: 2 hostname: 10.1.2.27.
17/01/29 08:57:26,998 INFO TaskSetManager: Finished task 30.0 in stage 1.0 (TID 32) in 22112 ms on 10.1.2.27 (22/59)
17/01/29 08:57:27,083 INFO BlockManagerInfo: Added rdd_5_28 in memory on 10.1.2.122:38089 (size: 70.0 MB, free: 1980.5 MB)
17/01/29 08:57:27,118 INFO TaskSetManager: Starting task 53.0 in stage 1.0 (TID 55, 10.1.2.122, partition 53, ANY, 5374 bytes)
17/01/29 08:57:27,118 INFO CoarseGrainedSchedulerBackend$DriverEndpoint: Launching task 55 on executor id: 7 hostname: 10.1.2.122.
17/01/29 08:57:27,119 INFO TaskSetManager: Finished task 28.0 in stage 1.0 (TID 30) in 22235 ms on 10.1.2.122 (23/59)
17/01/29 08:57:27,193 INFO BlockManagerInfo: Added rdd_5_29 in memory on 10.1.2.29:39424 (size: 69.9 MB, free: 1910.7 MB)
17/01/29 08:57:27,217 INFO TaskSetManager: Starting task 54.0 in stage 1.0 (TID 56, 10.1.2.29, partition 54, ANY, 5374 bytes)
17/01/29 08:57:27,217 INFO CoarseGrainedSchedulerBackend$DriverEndpoint: Launching task 56 on executor id: 6 hostname: 10.1.2.29.
17/01/29 08:57:27,217 INFO TaskSetManager: Finished task 29.0 in stage 1.0 (TID 31) in 22333 ms on 10.1.2.29 (24/59)
17/01/29 08:57:27,337 INFO BlockManagerInfo: Added rdd_5_1 in memory on 10.1.2.111:35778 (size: 70.0 MB, free: 1910.6 MB)
17/01/29 08:57:27,353 INFO BlockManagerInfo: Added rdd_5_25 in memory on 10.1.2.111:35778 (size: 70.0 MB, free: 1840.6 MB)
17/01/29 08:57:27,372 INFO TaskSetManager: Starting task 55.0 in stage 1.0 (TID 57, 10.1.2.111, partition 55, ANY, 5374 bytes)
17/01/29 08:57:27,372 INFO CoarseGrainedSchedulerBackend$DriverEndpoint: Launching task 57 on executor id: 5 hostname: 10.1.2.111.
17/01/29 08:57:27,373 INFO TaskSetManager: Finished task 1.0 in stage 1.0 (TID 3) in 22544 ms on 10.1.2.111 (25/59)
17/01/29 08:57:27,390 INFO TaskSetManager: Starting task 56.0 in stage 1.0 (TID 58, 10.1.2.111, partition 56, ANY, 5374 bytes)
17/01/29 08:57:27,391 INFO CoarseGrainedSchedulerBackend$DriverEndpoint: Launching task 58 on executor id: 5 hostname: 10.1.2.111.
17/01/29 08:57:27,391 INFO TaskSetManager: Finished task 25.0 in stage 1.0 (TID 27) in 22512 ms on 10.1.2.111 (26/59)
17/01/29 08:57:27,411 INFO BlockManagerInfo: Added rdd_5_13 in memory on 10.1.2.122:38089 (size: 69.9 MB, free: 1910.6 MB)
17/01/29 08:57:27,435 INFO TaskSetManager: Starting task 57.0 in stage 1.0 (TID 59, 10.1.2.122, partition 57, ANY, 5374 bytes)
17/01/29 08:57:27,435 INFO CoarseGrainedSchedulerBackend$DriverEndpoint: Launching task 59 on executor id: 7 hostname: 10.1.2.122.
17/01/29 08:57:27,435 INFO TaskSetManager: Finished task 13.0 in stage 1.0 (TID 15) in 22576 ms on 10.1.2.122 (27/59)
17/01/29 08:57:27,818 INFO BlockManagerInfo: Added rdd_5_14 in memory on 10.1.2.29:39424 (size: 69.9 MB, free: 1840.7 MB)
17/01/29 08:57:27,837 INFO TaskSetManager: Finished task 14.0 in stage 1.0 (TID 16) in 22977 ms on 10.1.2.29 (28/59)
17/01/29 08:57:28,004 INFO BlockManagerInfo: Added rdd_5_5 in memory on 10.1.2.122:38089 (size: 70.0 MB, free: 1840.6 MB)
17/01/29 08:57:28,025 INFO TaskSetManager: Finished task 5.0 in stage 1.0 (TID 7) in 23184 ms on 10.1.2.122 (29/59)
17/01/29 08:57:28,398 INFO BlockManagerInfo: Added rdd_5_20 in memory on 10.1.2.194:34076 (size: 69.8 MB, free: 2.0 GB)
17/01/29 08:57:28,482 INFO TaskSetManager: Finished task 20.0 in stage 1.0 (TID 22) in 23611 ms on 10.1.2.194 (30/59)
17/01/29 08:57:28,873 INFO BlockManagerInfo: Added rdd_5_12 in memory on 10.1.2.194:34076 (size: 70.0 MB, free: 1980.6 MB)
17/01/29 08:57:28,895 INFO TaskSetManager: Finished task 12.0 in stage 1.0 (TID 14) in 24038 ms on 10.1.2.194 (31/59)
17/01/29 08:57:28,899 INFO BlockManagerInfo: Added rdd_5_4 in memory on 10.1.2.194:34076 (size: 70.0 MB, free: 1910.6 MB)
17/01/29 08:57:28,927 INFO TaskSetManager: Finished task 4.0 in stage 1.0 (TID 6) in 24088 ms on 10.1.2.194 (32/59)
17/01/29 08:57:29,267 INFO BlockManagerInfo: Added rdd_5_27 in memory on 10.1.2.194:34076 (size: 69.9 MB, free: 1840.7 MB)
17/01/29 08:57:29,285 INFO TaskSetManager: Finished task 27.0 in stage 1.0 (TID 29) in 24403 ms on 10.1.2.194 (33/59)
17/01/29 08:57:40,548 INFO BlockManagerInfo: Added rdd_5_33 in memory on 10.1.2.131:41486 (size: 69.9 MB, free: 1770.8 MB)
17/01/29 08:57:40,568 INFO TaskSetManager: Finished task 33.0 in stage 1.0 (TID 35) in 17602 ms on 10.1.2.131 (34/59)
17/01/29 08:57:40,787 INFO BlockManagerInfo: Added rdd_5_35 in memory on 10.1.2.131:41486 (size: 70.0 MB, free: 1700.8 MB)
17/01/29 08:57:40,807 INFO TaskSetManager: Finished task 35.0 in stage 1.0 (TID 37) in 17458 ms on 10.1.2.131 (35/59)
17/01/29 08:57:40,902 INFO BlockManagerInfo: Added rdd_5_36 in memory on 10.1.2.131:41486 (size: 70.0 MB, free: 1630.8 MB)
17/01/29 08:57:40,921 INFO TaskSetManager: Finished task 36.0 in stage 1.0 (TID 38) in 17541 ms on 10.1.2.131 (36/59)
17/01/29 08:57:40,940 INFO BlockManagerInfo: Added rdd_5_34 in memory on 10.1.2.131:41486 (size: 70.0 MB, free: 1560.8 MB)
17/01/29 08:57:40,957 INFO TaskSetManager: Finished task 34.0 in stage 1.0 (TID 36) in 17847 ms on 10.1.2.131 (37/59)
17/01/29 08:57:41,740 INFO BlockManagerInfo: Added rdd_5_32 in memory on 10.1.2.182:38091 (size: 69.9 MB, free: 1767.8 MB)
17/01/29 08:57:41,760 INFO TaskSetManager: Finished task 32.0 in stage 1.0 (TID 34) in 21069 ms on 10.1.2.182 (38/59)
17/01/29 08:57:42,217 INFO BlockManagerInfo: Added rdd_5_42 in memory on 10.1.2.182:38091 (size: 69.8 MB, free: 1698.0 MB)
17/01/29 08:57:42,232 INFO TaskSetManager: Finished task 42.0 in stage 1.0 (TID 44) in 17355 ms on 10.1.2.182 (39/59)
17/01/29 08:57:42,363 INFO BlockManagerInfo: Added rdd_5_37 in memory on 10.1.2.182:38091 (size: 69.9 MB, free: 1628.1 MB)
17/01/29 08:57:42,378 INFO TaskSetManager: Finished task 37.0 in stage 1.0 (TID 39) in 18495 ms on 10.1.2.182 (40/59)
17/01/29 08:57:42,471 INFO BlockManagerInfo: Added rdd_5_47 in memory on 10.1.2.122:38089 (size: 70.0 MB, free: 1770.6 MB)
17/01/29 08:57:42,538 INFO TaskSetManager: Finished task 47.0 in stage 1.0 (TID 49) in 16305 ms on 10.1.2.122 (41/59)
17/01/29 08:57:42,749 INFO BlockManagerInfo: Added rdd_5_49 in memory on 10.1.2.29:39424 (size: 69.8 MB, free: 1770.9 MB)
17/01/29 08:57:42,760 INFO BlockManagerInfo: Added rdd_5_48 in memory on 10.1.2.29:39424 (size: 69.9 MB, free: 1701.0 MB)
17/01/29 08:57:42,775 INFO TaskSetManager: Finished task 49.0 in stage 1.0 (TID 51) in 16033 ms on 10.1.2.29 (42/59)
17/01/29 08:57:42,779 INFO TaskSetManager: Finished task 48.0 in stage 1.0 (TID 50) in 16133 ms on 10.1.2.29 (43/59)
17/01/29 08:57:42,855 INFO BlockManagerInfo: Added rdd_5_46 in memory on 10.1.2.182:38091 (size: 69.9 MB, free: 1558.2 MB)
17/01/29 08:57:42,869 INFO TaskSetManager: Finished task 46.0 in stage 1.0 (TID 48) in 16768 ms on 10.1.2.182 (44/59)
17/01/29 08:57:43,088 INFO BlockManagerInfo: Added rdd_5_53 in memory on 10.1.2.122:38089 (size: 70.0 MB, free: 1700.6 MB)
17/01/29 08:57:43,092 INFO BlockManagerInfo: Added rdd_5_54 in memory on 10.1.2.29:39424 (size: 69.9 MB, free: 1631.1 MB)
17/01/29 08:57:43,111 INFO TaskSetManager: Finished task 54.0 in stage 1.0 (TID 56) in 15895 ms on 10.1.2.29 (45/59)
17/01/29 08:57:43,113 INFO TaskSetManager: Finished task 53.0 in stage 1.0 (TID 55) in 15996 ms on 10.1.2.122 (46/59)
17/01/29 08:57:43,153 INFO BlockManagerInfo: Added rdd_5_57 in memory on 10.1.2.122:38089 (size: 70.1 MB, free: 1630.5 MB)
17/01/29 08:57:43,171 INFO TaskSetManager: Finished task 57.0 in stage 1.0 (TID 59) in 15737 ms on 10.1.2.122 (47/59)
17/01/29 08:57:43,391 INFO BlockManagerInfo: Added rdd_5_38 in memory on 10.1.2.27:38845 (size: 70.0 MB, free: 1700.7 MB)
17/01/29 08:57:43,413 INFO TaskSetManager: Finished task 38.0 in stage 1.0 (TID 40) in 18981 ms on 10.1.2.27 (48/59)
17/01/29 08:57:43,471 INFO BlockManagerInfo: Added rdd_5_39 in memory on 10.1.2.27:38845 (size: 70.0 MB, free: 1630.7 MB)
17/01/29 08:57:43,487 INFO TaskSetManager: Finished task 39.0 in stage 1.0 (TID 41) in 18825 ms on 10.1.2.27 (49/59)
17/01/29 08:57:43,721 INFO BlockManagerInfo: Added rdd_5_40 in memory on 10.1.2.26:39210 (size: 70.0 MB, free: 1771.0 MB)
17/01/29 08:57:43,739 INFO TaskSetManager: Finished task 40.0 in stage 1.0 (TID 42) in 19045 ms on 10.1.2.26 (50/59)
17/01/29 08:57:43,758 INFO BlockManagerInfo: Added rdd_5_45 in memory on 10.1.2.27:38845 (size: 69.9 MB, free: 1560.8 MB)
17/01/29 08:57:43,777 INFO TaskSetManager: Finished task 45.0 in stage 1.0 (TID 47) in 17693 ms on 10.1.2.27 (51/59)
17/01/29 08:57:43,896 INFO BlockManagerInfo: Added rdd_5_43 in memory on 10.1.2.26:39210 (size: 69.8 MB, free: 1701.1 MB)
17/01/29 08:57:43,914 INFO TaskSetManager: Finished task 43.0 in stage 1.0 (TID 45) in 18963 ms on 10.1.2.26 (52/59)
17/01/29 08:57:44,094 INFO BlockManagerInfo: Added rdd_5_52 in memory on 10.1.2.27:38845 (size: 69.9 MB, free: 1491.0 MB)
17/01/29 08:57:44,112 INFO TaskSetManager: Finished task 52.0 in stage 1.0 (TID 54) in 17114 ms on 10.1.2.27 (53/59)
17/01/29 08:57:44,142 INFO BlockManagerInfo: Added rdd_5_44 in memory on 10.1.2.26:39210 (size: 70.0 MB, free: 1631.2 MB)
17/01/29 08:57:44,161 INFO TaskSetManager: Finished task 44.0 in stage 1.0 (TID 46) in 19150 ms on 10.1.2.26 (54/59)
17/01/29 08:57:44,420 INFO BlockManagerInfo: Added rdd_5_41 in memory on 10.1.2.26:39210 (size: 70.0 MB, free: 1561.2 MB)
17/01/29 08:57:44,437 INFO TaskSetManager: Finished task 41.0 in stage 1.0 (TID 43) in 19651 ms on 10.1.2.26 (55/59)
17/01/29 08:57:45,328 INFO BlockManagerInfo: Added rdd_5_50 in memory on 10.1.2.111:35778 (size: 69.9 MB, free: 1770.8 MB)
17/01/29 08:57:45,344 INFO TaskSetManager: Finished task 50.0 in stage 1.0 (TID 52) in 18416 ms on 10.1.2.111 (56/59)
17/01/29 08:57:45,548 INFO BlockManagerInfo: Added rdd_5_51 in memory on 10.1.2.111:35778 (size: 69.9 MB, free: 1700.9 MB)
17/01/29 08:57:45,564 INFO TaskSetManager: Finished task 51.0 in stage 1.0 (TID 53) in 18629 ms on 10.1.2.111 (57/59)
17/01/29 08:57:45,754 INFO BlockManagerInfo: Added rdd_5_55 in memory on 10.1.2.111:35778 (size: 69.9 MB, free: 1631.1 MB)
17/01/29 08:57:45,770 INFO TaskSetManager: Finished task 55.0 in stage 1.0 (TID 57) in 18398 ms on 10.1.2.111 (58/59)
17/01/29 08:57:45,838 INFO BlockManagerInfo: Added rdd_5_56 in memory on 10.1.2.111:35778 (size: 69.9 MB, free: 1561.1 MB)
17/01/29 08:57:45,853 INFO TaskSetManager: Finished task 56.0 in stage 1.0 (TID 58) in 18464 ms on 10.1.2.111 (59/59)
17/01/29 08:57:45,853 INFO TaskSchedulerImpl: Removed TaskSet 1.0, whose tasks have all completed, from pool 
17/01/29 08:57:45,853 INFO DAGScheduler: ResultStage 1 (count at DataValidators.scala:40) finished in 44.321 s
17/01/29 08:57:45,854 INFO DAGScheduler: Job 1 finished: count at DataValidators.scala:40, took 44.361421 s
17/01/29 08:57:45,865 INFO SparkContext: Starting job: count at GradientDescent.scala:209
17/01/29 08:57:45,867 INFO DAGScheduler: Got job 2 (count at GradientDescent.scala:209) with 59 output partitions
17/01/29 08:57:45,867 INFO DAGScheduler: Final stage: ResultStage 2 (count at GradientDescent.scala:209)
17/01/29 08:57:45,867 INFO DAGScheduler: Parents of final stage: List()
17/01/29 08:57:45,870 INFO DAGScheduler: Missing parents: List()
17/01/29 08:57:45,870 INFO DAGScheduler: Submitting ResultStage 2 (MapPartitionsRDD[8] at map at GeneralizedLinearAlgorithm.scala:297), which has no missing parents
17/01/29 08:57:45,876 INFO MemoryStore: Block broadcast_3 stored as values in memory (estimated size 3.9 KB, free 2.1 GB)
17/01/29 08:57:45,878 INFO MemoryStore: Block broadcast_3_piece0 stored as bytes in memory (estimated size 2.2 KB, free 2.1 GB)
17/01/29 08:57:45,879 INFO BlockManagerInfo: Added broadcast_3_piece0 in memory on 10.1.2.241:40816 (size: 2.2 KB, free: 2.1 GB)
17/01/29 08:57:45,886 INFO SparkContext: Created broadcast 3 from broadcast at DAGScheduler.scala:1012
17/01/29 08:57:45,887 INFO DAGScheduler: Submitting 59 missing tasks from ResultStage 2 (MapPartitionsRDD[8] at map at GeneralizedLinearAlgorithm.scala:297)
17/01/29 08:57:45,887 INFO TaskSchedulerImpl: Adding task set 2.0 with 59 tasks
17/01/29 08:57:45,890 INFO TaskSetManager: Starting task 6.0 in stage 2.0 (TID 60, 10.1.2.29, partition 6, PROCESS_LOCAL, 5374 bytes)
17/01/29 08:57:45,891 INFO TaskSetManager: Starting task 8.0 in stage 2.0 (TID 61, 10.1.2.26, partition 8, PROCESS_LOCAL, 5374 bytes)
17/01/29 08:57:45,892 INFO TaskSetManager: Starting task 5.0 in stage 2.0 (TID 62, 10.1.2.122, partition 5, PROCESS_LOCAL, 5374 bytes)
17/01/29 08:57:45,893 INFO TaskSetManager: Starting task 3.0 in stage 2.0 (TID 63, 10.1.2.131, partition 3, PROCESS_LOCAL, 5374 bytes)
17/01/29 08:57:45,893 INFO TaskSetManager: Starting task 1.0 in stage 2.0 (TID 64, 10.1.2.111, partition 1, PROCESS_LOCAL, 5374 bytes)
17/01/29 08:57:45,894 INFO TaskSetManager: Starting task 0.0 in stage 2.0 (TID 65, 10.1.2.27, partition 0, PROCESS_LOCAL, 5374 bytes)
17/01/29 08:57:45,895 INFO TaskSetManager: Starting task 2.0 in stage 2.0 (TID 66, 10.1.2.182, partition 2, PROCESS_LOCAL, 5374 bytes)
17/01/29 08:57:45,896 INFO TaskSetManager: Starting task 4.0 in stage 2.0 (TID 67, 10.1.2.194, partition 4, PROCESS_LOCAL, 5374 bytes)
17/01/29 08:57:45,897 INFO TaskSetManager: Starting task 14.0 in stage 2.0 (TID 68, 10.1.2.29, partition 14, PROCESS_LOCAL, 5374 bytes)
17/01/29 08:57:45,897 INFO TaskSetManager: Starting task 16.0 in stage 2.0 (TID 69, 10.1.2.26, partition 16, PROCESS_LOCAL, 5374 bytes)
17/01/29 08:57:45,898 INFO TaskSetManager: Starting task 13.0 in stage 2.0 (TID 70, 10.1.2.122, partition 13, PROCESS_LOCAL, 5374 bytes)
17/01/29 08:57:45,899 INFO TaskSetManager: Starting task 11.0 in stage 2.0 (TID 71, 10.1.2.131, partition 11, PROCESS_LOCAL, 5374 bytes)
17/01/29 08:57:45,900 INFO TaskSetManager: Starting task 9.0 in stage 2.0 (TID 72, 10.1.2.111, partition 9, PROCESS_LOCAL, 5374 bytes)
17/01/29 08:57:45,901 INFO TaskSetManager: Starting task 7.0 in stage 2.0 (TID 73, 10.1.2.27, partition 7, PROCESS_LOCAL, 5374 bytes)
17/01/29 08:57:45,902 INFO TaskSetManager: Starting task 10.0 in stage 2.0 (TID 74, 10.1.2.182, partition 10, PROCESS_LOCAL, 5374 bytes)
17/01/29 08:57:45,902 INFO TaskSetManager: Starting task 12.0 in stage 2.0 (TID 75, 10.1.2.194, partition 12, PROCESS_LOCAL, 5374 bytes)
17/01/29 08:57:45,903 INFO TaskSetManager: Starting task 22.0 in stage 2.0 (TID 76, 10.1.2.29, partition 22, PROCESS_LOCAL, 5374 bytes)
17/01/29 08:57:45,904 INFO TaskSetManager: Starting task 24.0 in stage 2.0 (TID 77, 10.1.2.26, partition 24, PROCESS_LOCAL, 5374 bytes)
17/01/29 08:57:45,905 INFO TaskSetManager: Starting task 21.0 in stage 2.0 (TID 78, 10.1.2.122, partition 21, PROCESS_LOCAL, 5374 bytes)
17/01/29 08:57:45,905 INFO TaskSetManager: Starting task 19.0 in stage 2.0 (TID 79, 10.1.2.131, partition 19, PROCESS_LOCAL, 5374 bytes)
17/01/29 08:57:45,906 INFO TaskSetManager: Starting task 17.0 in stage 2.0 (TID 80, 10.1.2.111, partition 17, PROCESS_LOCAL, 5374 bytes)
17/01/29 08:57:45,907 INFO TaskSetManager: Starting task 15.0 in stage 2.0 (TID 81, 10.1.2.27, partition 15, PROCESS_LOCAL, 5374 bytes)
17/01/29 08:57:45,908 INFO TaskSetManager: Starting task 18.0 in stage 2.0 (TID 82, 10.1.2.182, partition 18, PROCESS_LOCAL, 5374 bytes)
17/01/29 08:57:45,908 INFO TaskSetManager: Starting task 20.0 in stage 2.0 (TID 83, 10.1.2.194, partition 20, PROCESS_LOCAL, 5374 bytes)
17/01/29 08:57:45,909 INFO TaskSetManager: Starting task 29.0 in stage 2.0 (TID 84, 10.1.2.29, partition 29, PROCESS_LOCAL, 5374 bytes)
17/01/29 08:57:45,910 INFO TaskSetManager: Starting task 31.0 in stage 2.0 (TID 85, 10.1.2.26, partition 31, PROCESS_LOCAL, 5374 bytes)
17/01/29 08:57:45,911 INFO TaskSetManager: Starting task 28.0 in stage 2.0 (TID 86, 10.1.2.122, partition 28, PROCESS_LOCAL, 5374 bytes)
17/01/29 08:57:45,912 INFO TaskSetManager: Starting task 26.0 in stage 2.0 (TID 87, 10.1.2.131, partition 26, PROCESS_LOCAL, 5374 bytes)
17/01/29 08:57:45,912 INFO TaskSetManager: Starting task 25.0 in stage 2.0 (TID 88, 10.1.2.111, partition 25, PROCESS_LOCAL, 5374 bytes)
17/01/29 08:57:45,914 INFO TaskSetManager: Starting task 23.0 in stage 2.0 (TID 89, 10.1.2.27, partition 23, PROCESS_LOCAL, 5374 bytes)
17/01/29 08:57:45,915 INFO TaskSetManager: Starting task 32.0 in stage 2.0 (TID 90, 10.1.2.182, partition 32, PROCESS_LOCAL, 5374 bytes)
17/01/29 08:57:45,916 INFO TaskSetManager: Starting task 27.0 in stage 2.0 (TID 91, 10.1.2.194, partition 27, PROCESS_LOCAL, 5374 bytes)
17/01/29 08:57:45,916 INFO CoarseGrainedSchedulerBackend$DriverEndpoint: Launching task 60 on executor id: 6 hostname: 10.1.2.29.
17/01/29 08:57:45,917 INFO CoarseGrainedSchedulerBackend$DriverEndpoint: Launching task 68 on executor id: 6 hostname: 10.1.2.29.
17/01/29 08:57:45,918 INFO CoarseGrainedSchedulerBackend$DriverEndpoint: Launching task 76 on executor id: 6 hostname: 10.1.2.29.
17/01/29 08:57:45,918 INFO CoarseGrainedSchedulerBackend$DriverEndpoint: Launching task 84 on executor id: 6 hostname: 10.1.2.29.
17/01/29 08:57:45,919 INFO CoarseGrainedSchedulerBackend$DriverEndpoint: Launching task 61 on executor id: 0 hostname: 10.1.2.26.
17/01/29 08:57:45,920 INFO CoarseGrainedSchedulerBackend$DriverEndpoint: Launching task 69 on executor id: 0 hostname: 10.1.2.26.
17/01/29 08:57:45,921 INFO CoarseGrainedSchedulerBackend$DriverEndpoint: Launching task 77 on executor id: 0 hostname: 10.1.2.26.
17/01/29 08:57:45,922 INFO CoarseGrainedSchedulerBackend$DriverEndpoint: Launching task 85 on executor id: 0 hostname: 10.1.2.26.
17/01/29 08:57:45,922 INFO CoarseGrainedSchedulerBackend$DriverEndpoint: Launching task 62 on executor id: 7 hostname: 10.1.2.122.
17/01/29 08:57:45,923 INFO CoarseGrainedSchedulerBackend$DriverEndpoint: Launching task 70 on executor id: 7 hostname: 10.1.2.122.
17/01/29 08:57:45,923 INFO CoarseGrainedSchedulerBackend$DriverEndpoint: Launching task 78 on executor id: 7 hostname: 10.1.2.122.
17/01/29 08:57:45,923 INFO CoarseGrainedSchedulerBackend$DriverEndpoint: Launching task 86 on executor id: 7 hostname: 10.1.2.122.
17/01/29 08:57:45,924 INFO CoarseGrainedSchedulerBackend$DriverEndpoint: Launching task 63 on executor id: 4 hostname: 10.1.2.131.
17/01/29 08:57:45,924 INFO CoarseGrainedSchedulerBackend$DriverEndpoint: Launching task 71 on executor id: 4 hostname: 10.1.2.131.
17/01/29 08:57:45,925 INFO CoarseGrainedSchedulerBackend$DriverEndpoint: Launching task 79 on executor id: 4 hostname: 10.1.2.131.
17/01/29 08:57:45,926 INFO CoarseGrainedSchedulerBackend$DriverEndpoint: Launching task 87 on executor id: 4 hostname: 10.1.2.131.
17/01/29 08:57:45,926 INFO CoarseGrainedSchedulerBackend$DriverEndpoint: Launching task 64 on executor id: 5 hostname: 10.1.2.111.
17/01/29 08:57:45,926 INFO CoarseGrainedSchedulerBackend$DriverEndpoint: Launching task 72 on executor id: 5 hostname: 10.1.2.111.
17/01/29 08:57:45,927 INFO CoarseGrainedSchedulerBackend$DriverEndpoint: Launching task 80 on executor id: 5 hostname: 10.1.2.111.
17/01/29 08:57:45,927 INFO CoarseGrainedSchedulerBackend$DriverEndpoint: Launching task 88 on executor id: 5 hostname: 10.1.2.111.
17/01/29 08:57:45,927 INFO CoarseGrainedSchedulerBackend$DriverEndpoint: Launching task 65 on executor id: 2 hostname: 10.1.2.27.
17/01/29 08:57:45,928 INFO CoarseGrainedSchedulerBackend$DriverEndpoint: Launching task 73 on executor id: 2 hostname: 10.1.2.27.
17/01/29 08:57:45,931 INFO CoarseGrainedSchedulerBackend$DriverEndpoint: Launching task 81 on executor id: 2 hostname: 10.1.2.27.
17/01/29 08:57:45,933 INFO CoarseGrainedSchedulerBackend$DriverEndpoint: Launching task 89 on executor id: 2 hostname: 10.1.2.27.
17/01/29 08:57:45,934 INFO CoarseGrainedSchedulerBackend$DriverEndpoint: Launching task 66 on executor id: 1 hostname: 10.1.2.182.
17/01/29 08:57:45,934 INFO CoarseGrainedSchedulerBackend$DriverEndpoint: Launching task 74 on executor id: 1 hostname: 10.1.2.182.
17/01/29 08:57:45,934 INFO CoarseGrainedSchedulerBackend$DriverEndpoint: Launching task 82 on executor id: 1 hostname: 10.1.2.182.
17/01/29 08:57:45,935 INFO CoarseGrainedSchedulerBackend$DriverEndpoint: Launching task 90 on executor id: 1 hostname: 10.1.2.182.
17/01/29 08:57:45,935 INFO CoarseGrainedSchedulerBackend$DriverEndpoint: Launching task 67 on executor id: 3 hostname: 10.1.2.194.
17/01/29 08:57:45,935 INFO CoarseGrainedSchedulerBackend$DriverEndpoint: Launching task 75 on executor id: 3 hostname: 10.1.2.194.
17/01/29 08:57:45,936 INFO CoarseGrainedSchedulerBackend$DriverEndpoint: Launching task 83 on executor id: 3 hostname: 10.1.2.194.
17/01/29 08:57:45,936 INFO CoarseGrainedSchedulerBackend$DriverEndpoint: Launching task 91 on executor id: 3 hostname: 10.1.2.194.
17/01/29 08:57:45,945 INFO BlockManagerInfo: Added broadcast_3_piece0 in memory on 10.1.2.131:41486 (size: 2.2 KB, free: 1560.8 MB)
17/01/29 08:57:45,975 INFO BlockManagerInfo: Added broadcast_3_piece0 in memory on 10.1.2.122:38089 (size: 2.2 KB, free: 1630.5 MB)
17/01/29 08:57:45,980 INFO BlockManagerInfo: Added broadcast_3_piece0 in memory on 10.1.2.29:39424 (size: 2.2 KB, free: 1631.1 MB)
17/01/29 08:57:45,989 INFO TaskSetManager: Starting task 33.0 in stage 2.0 (TID 92, 10.1.2.131, partition 33, PROCESS_LOCAL, 5374 bytes)
17/01/29 08:57:45,989 INFO CoarseGrainedSchedulerBackend$DriverEndpoint: Launching task 92 on executor id: 4 hostname: 10.1.2.131.
17/01/29 08:57:45,989 INFO TaskSetManager: Finished task 19.0 in stage 2.0 (TID 79) in 84 ms on 10.1.2.131 (1/59)
17/01/29 08:57:45,995 INFO BlockManagerInfo: Added broadcast_3_piece0 in memory on 10.1.2.26:39210 (size: 2.2 KB, free: 1561.2 MB)
17/01/29 08:57:45,997 INFO BlockManagerInfo: Added broadcast_3_piece0 in memory on 10.1.2.111:35778 (size: 2.2 KB, free: 1561.1 MB)
17/01/29 08:57:46,013 INFO TaskSetManager: Starting task 34.0 in stage 2.0 (TID 93, 10.1.2.131, partition 34, PROCESS_LOCAL, 5374 bytes)
17/01/29 08:57:46,013 INFO CoarseGrainedSchedulerBackend$DriverEndpoint: Launching task 93 on executor id: 4 hostname: 10.1.2.131.
17/01/29 08:57:46,014 INFO TaskSetManager: Finished task 26.0 in stage 2.0 (TID 87) in 102 ms on 10.1.2.131 (2/59)
17/01/29 08:57:46,023 INFO TaskSetManager: Starting task 47.0 in stage 2.0 (TID 94, 10.1.2.122, partition 47, PROCESS_LOCAL, 5374 bytes)
17/01/29 08:57:46,023 INFO TaskSetManager: Finished task 13.0 in stage 2.0 (TID 70) in 126 ms on 10.1.2.122 (3/59)
17/01/29 08:57:46,024 INFO CoarseGrainedSchedulerBackend$DriverEndpoint: Launching task 94 on executor id: 7 hostname: 10.1.2.122.
17/01/29 08:57:46,025 INFO TaskSetManager: Starting task 35.0 in stage 2.0 (TID 95, 10.1.2.131, partition 35, PROCESS_LOCAL, 5374 bytes)
17/01/29 08:57:46,026 INFO CoarseGrainedSchedulerBackend$DriverEndpoint: Launching task 95 on executor id: 4 hostname: 10.1.2.131.
17/01/29 08:57:46,026 INFO TaskSetManager: Finished task 11.0 in stage 2.0 (TID 71) in 128 ms on 10.1.2.131 (4/59)
17/01/29 08:57:46,027 INFO TaskSetManager: Finished task 33.0 in stage 2.0 (TID 92) in 39 ms on 10.1.2.131 (5/59)
17/01/29 08:57:46,029 INFO TaskSetManager: Starting task 36.0 in stage 2.0 (TID 96, 10.1.2.131, partition 36, PROCESS_LOCAL, 5374 bytes)
17/01/29 08:57:46,029 INFO CoarseGrainedSchedulerBackend$DriverEndpoint: Launching task 96 on executor id: 4 hostname: 10.1.2.131.
17/01/29 08:57:46,030 INFO TaskSetManager: Starting task 48.0 in stage 2.0 (TID 97, 10.1.2.29, partition 48, PROCESS_LOCAL, 5374 bytes)
17/01/29 08:57:46,031 INFO CoarseGrainedSchedulerBackend$DriverEndpoint: Launching task 97 on executor id: 6 hostname: 10.1.2.29.
17/01/29 08:57:46,031 INFO TaskSetManager: Finished task 22.0 in stage 2.0 (TID 76) in 129 ms on 10.1.2.29 (6/59)
17/01/29 08:57:46,036 INFO BlockManagerInfo: Added broadcast_3_piece0 in memory on 10.1.2.182:38091 (size: 2.2 KB, free: 1558.2 MB)
17/01/29 08:57:46,039 INFO BlockManagerInfo: Added broadcast_3_piece0 in memory on 10.1.2.27:38845 (size: 2.2 KB, free: 1491.0 MB)
17/01/29 08:57:46,044 INFO TaskSetManager: Starting task 40.0 in stage 2.0 (TID 98, 10.1.2.26, partition 40, PROCESS_LOCAL, 5374 bytes)
17/01/29 08:57:46,044 INFO CoarseGrainedSchedulerBackend$DriverEndpoint: Launching task 98 on executor id: 0 hostname: 10.1.2.26.
17/01/29 08:57:46,045 INFO TaskSetManager: Finished task 31.0 in stage 2.0 (TID 85) in 136 ms on 10.1.2.26 (7/59)
17/01/29 08:57:46,049 INFO TaskSetManager: Starting task 50.0 in stage 2.0 (TID 99, 10.1.2.111, partition 50, PROCESS_LOCAL, 5374 bytes)
17/01/29 08:57:46,050 INFO CoarseGrainedSchedulerBackend$DriverEndpoint: Launching task 99 on executor id: 5 hostname: 10.1.2.111.
17/01/29 08:57:46,051 INFO TaskSetManager: Starting task 51.0 in stage 2.0 (TID 100, 10.1.2.111, partition 51, PROCESS_LOCAL, 5374 bytes)
17/01/29 08:57:46,051 INFO CoarseGrainedSchedulerBackend$DriverEndpoint: Launching task 100 on executor id: 5 hostname: 10.1.2.111.
17/01/29 08:57:46,052 INFO TaskSetManager: Starting task 53.0 in stage 2.0 (TID 101, 10.1.2.122, partition 53, PROCESS_LOCAL, 5374 bytes)
17/01/29 08:57:46,053 INFO CoarseGrainedSchedulerBackend$DriverEndpoint: Launching task 101 on executor id: 7 hostname: 10.1.2.122.
17/01/29 08:57:46,053 INFO TaskSetManager: Finished task 17.0 in stage 2.0 (TID 80) in 148 ms on 10.1.2.111 (8/59)
17/01/29 08:57:46,054 INFO TaskSetManager: Starting task 41.0 in stage 2.0 (TID 102, 10.1.2.26, partition 41, PROCESS_LOCAL, 5374 bytes)
17/01/29 08:57:46,054 INFO CoarseGrainedSchedulerBackend$DriverEndpoint: Launching task 102 on executor id: 0 hostname: 10.1.2.26.
17/01/29 08:57:46,054 INFO TaskSetManager: Finished task 21.0 in stage 2.0 (TID 78) in 150 ms on 10.1.2.122 (9/59)
17/01/29 08:57:46,055 INFO BlockManagerInfo: Added broadcast_3_piece0 in memory on 10.1.2.194:34076 (size: 2.2 KB, free: 1840.7 MB)
17/01/29 08:57:46,055 INFO TaskSetManager: Finished task 24.0 in stage 2.0 (TID 77) in 152 ms on 10.1.2.26 (10/59)
17/01/29 08:57:46,055 INFO TaskSetManager: Finished task 1.0 in stage 2.0 (TID 64) in 162 ms on 10.1.2.111 (11/59)
17/01/29 08:57:46,056 INFO TaskSetManager: Starting task 57.0 in stage 2.0 (TID 103, 10.1.2.122, partition 57, PROCESS_LOCAL, 5374 bytes)
17/01/29 08:57:46,057 INFO CoarseGrainedSchedulerBackend$DriverEndpoint: Launching task 103 on executor id: 7 hostname: 10.1.2.122.
17/01/29 08:57:46,057 INFO TaskSetManager: Finished task 47.0 in stage 2.0 (TID 94) in 35 ms on 10.1.2.122 (12/59)
17/01/29 08:57:46,061 INFO TaskSetManager: Finished task 3.0 in stage 2.0 (TID 63) in 169 ms on 10.1.2.131 (13/59)
17/01/29 08:57:46,063 INFO TaskSetManager: Starting task 49.0 in stage 2.0 (TID 104, 10.1.2.29, partition 49, PROCESS_LOCAL, 5374 bytes)
17/01/29 08:57:46,063 INFO CoarseGrainedSchedulerBackend$DriverEndpoint: Launching task 104 on executor id: 6 hostname: 10.1.2.29.
17/01/29 08:57:46,063 INFO TaskSetManager: Finished task 35.0 in stage 2.0 (TID 95) in 39 ms on 10.1.2.131 (14/59)
17/01/29 08:57:46,063 INFO TaskSetManager: Finished task 14.0 in stage 2.0 (TID 68) in 167 ms on 10.1.2.29 (15/59)
17/01/29 08:57:46,064 INFO TaskSetManager: Finished task 36.0 in stage 2.0 (TID 96) in 36 ms on 10.1.2.131 (16/59)
17/01/29 08:57:46,068 INFO TaskSetManager: Finished task 34.0 in stage 2.0 (TID 93) in 55 ms on 10.1.2.131 (17/59)
17/01/29 08:57:46,070 INFO TaskSetManager: Starting task 54.0 in stage 2.0 (TID 105, 10.1.2.29, partition 54, PROCESS_LOCAL, 5374 bytes)
17/01/29 08:57:46,070 INFO CoarseGrainedSchedulerBackend$DriverEndpoint: Launching task 105 on executor id: 6 hostname: 10.1.2.29.
17/01/29 08:57:46,071 INFO TaskSetManager: Finished task 48.0 in stage 2.0 (TID 97) in 40 ms on 10.1.2.29 (18/59)
17/01/29 08:57:46,079 INFO TaskSetManager: Starting task 37.0 in stage 2.0 (TID 106, 10.1.2.182, partition 37, PROCESS_LOCAL, 5374 bytes)
17/01/29 08:57:46,080 INFO CoarseGrainedSchedulerBackend$DriverEndpoint: Launching task 106 on executor id: 1 hostname: 10.1.2.182.
17/01/29 08:57:46,080 INFO TaskSetManager: Finished task 32.0 in stage 2.0 (TID 90) in 166 ms on 10.1.2.182 (19/59)
17/01/29 08:57:46,081 INFO TaskSetManager: Starting task 42.0 in stage 2.0 (TID 107, 10.1.2.182, partition 42, PROCESS_LOCAL, 5374 bytes)
17/01/29 08:57:46,081 INFO CoarseGrainedSchedulerBackend$DriverEndpoint: Launching task 107 on executor id: 1 hostname: 10.1.2.182.
17/01/29 08:57:46,082 INFO TaskSetManager: Finished task 2.0 in stage 2.0 (TID 66) in 187 ms on 10.1.2.182 (20/59)
17/01/29 08:57:46,084 INFO TaskSetManager: Starting task 43.0 in stage 2.0 (TID 108, 10.1.2.26, partition 43, PROCESS_LOCAL, 5374 bytes)
17/01/29 08:57:46,084 INFO CoarseGrainedSchedulerBackend$DriverEndpoint: Launching task 108 on executor id: 0 hostname: 10.1.2.26.
17/01/29 08:57:46,085 INFO TaskSetManager: Finished task 40.0 in stage 2.0 (TID 98) in 41 ms on 10.1.2.26 (21/59)
17/01/29 08:57:46,085 INFO TaskSetManager: Starting task 55.0 in stage 2.0 (TID 109, 10.1.2.111, partition 55, PROCESS_LOCAL, 5374 bytes)
17/01/29 08:57:46,086 INFO CoarseGrainedSchedulerBackend$DriverEndpoint: Launching task 109 on executor id: 5 hostname: 10.1.2.111.
17/01/29 08:57:46,086 INFO TaskSetManager: Finished task 50.0 in stage 2.0 (TID 99) in 38 ms on 10.1.2.111 (22/59)
17/01/29 08:57:46,087 INFO TaskSetManager: Finished task 53.0 in stage 2.0 (TID 101) in 34 ms on 10.1.2.122 (23/59)
17/01/29 08:57:46,088 INFO TaskSetManager: Starting task 30.0 in stage 2.0 (TID 110, 10.1.2.27, partition 30, PROCESS_LOCAL, 5374 bytes)
17/01/29 08:57:46,088 INFO CoarseGrainedSchedulerBackend$DriverEndpoint: Launching task 110 on executor id: 2 hostname: 10.1.2.27.
17/01/29 08:57:46,088 INFO TaskSetManager: Finished task 7.0 in stage 2.0 (TID 73) in 188 ms on 10.1.2.27 (24/59)
17/01/29 08:57:46,091 INFO TaskSetManager: Starting task 38.0 in stage 2.0 (TID 111, 10.1.2.27, partition 38, PROCESS_LOCAL, 5374 bytes)
17/01/29 08:57:46,092 INFO CoarseGrainedSchedulerBackend$DriverEndpoint: Launching task 111 on executor id: 2 hostname: 10.1.2.27.
17/01/29 08:57:46,092 INFO TaskSetManager: Finished task 15.0 in stage 2.0 (TID 81) in 186 ms on 10.1.2.27 (25/59)
17/01/29 08:57:46,093 INFO TaskSetManager: Finished task 41.0 in stage 2.0 (TID 102) in 40 ms on 10.1.2.26 (26/59)
17/01/29 08:57:46,094 INFO TaskSetManager: Starting task 44.0 in stage 2.0 (TID 112, 10.1.2.26, partition 44, PROCESS_LOCAL, 5374 bytes)
17/01/29 08:57:46,094 INFO CoarseGrainedSchedulerBackend$DriverEndpoint: Launching task 112 on executor id: 0 hostname: 10.1.2.26.
17/01/29 08:57:46,095 INFO TaskSetManager: Finished task 51.0 in stage 2.0 (TID 100) in 45 ms on 10.1.2.111 (27/59)
17/01/29 08:57:46,096 INFO TaskSetManager: Starting task 56.0 in stage 2.0 (TID 113, 10.1.2.111, partition 56, PROCESS_LOCAL, 5374 bytes)
17/01/29 08:57:46,096 INFO CoarseGrainedSchedulerBackend$DriverEndpoint: Launching task 113 on executor id: 5 hostname: 10.1.2.111.
17/01/29 08:57:46,097 INFO TaskSetManager: Starting task 46.0 in stage 2.0 (TID 114, 10.1.2.182, partition 46, PROCESS_LOCAL, 5374 bytes)
17/01/29 08:57:46,098 INFO CoarseGrainedSchedulerBackend$DriverEndpoint: Launching task 114 on executor id: 1 hostname: 10.1.2.182.
17/01/29 08:57:46,098 INFO TaskSetManager: Finished task 18.0 in stage 2.0 (TID 82) in 191 ms on 10.1.2.182 (28/59)
17/01/29 08:57:46,098 INFO TaskSetManager: Finished task 57.0 in stage 2.0 (TID 103) in 42 ms on 10.1.2.122 (29/59)
17/01/29 08:57:46,099 INFO TaskSetManager: Finished task 10.0 in stage 2.0 (TID 74) in 198 ms on 10.1.2.182 (30/59)
17/01/29 08:57:46,100 INFO TaskSetManager: Starting task 58.0 in stage 2.0 (TID 115, 10.1.2.182, partition 58, PROCESS_LOCAL, 5374 bytes)
17/01/29 08:57:46,100 INFO CoarseGrainedSchedulerBackend$DriverEndpoint: Launching task 115 on executor id: 1 hostname: 10.1.2.182.
17/01/29 08:57:46,101 INFO TaskSetManager: Finished task 23.0 in stage 2.0 (TID 89) in 189 ms on 10.1.2.27 (31/59)
17/01/29 08:57:46,103 INFO TaskSetManager: Starting task 39.0 in stage 2.0 (TID 116, 10.1.2.27, partition 39, PROCESS_LOCAL, 5374 bytes)
17/01/29 08:57:46,104 INFO CoarseGrainedSchedulerBackend$DriverEndpoint: Launching task 116 on executor id: 2 hostname: 10.1.2.27.
17/01/29 08:57:46,105 INFO TaskSetManager: Starting task 45.0 in stage 2.0 (TID 117, 10.1.2.27, partition 45, PROCESS_LOCAL, 5374 bytes)
17/01/29 08:57:46,106 INFO CoarseGrainedSchedulerBackend$DriverEndpoint: Launching task 117 on executor id: 2 hostname: 10.1.2.27.
17/01/29 08:57:46,106 INFO TaskSetManager: Finished task 0.0 in stage 2.0 (TID 65) in 213 ms on 10.1.2.27 (32/59)
17/01/29 08:57:46,107 INFO TaskSetManager: Finished task 4.0 in stage 2.0 (TID 67) in 212 ms on 10.1.2.194 (33/59)
17/01/29 08:57:46,109 INFO TaskSetManager: Finished task 49.0 in stage 2.0 (TID 104) in 46 ms on 10.1.2.29 (34/59)
17/01/29 08:57:46,109 INFO TaskSetManager: Finished task 54.0 in stage 2.0 (TID 105) in 40 ms on 10.1.2.29 (35/59)
17/01/29 08:57:46,112 INFO TaskSetManager: Finished task 37.0 in stage 2.0 (TID 106) in 34 ms on 10.1.2.182 (36/59)
17/01/29 08:57:46,114 INFO TaskSetManager: Finished task 43.0 in stage 2.0 (TID 108) in 32 ms on 10.1.2.26 (37/59)
17/01/29 08:57:46,115 INFO TaskSetManager: Finished task 42.0 in stage 2.0 (TID 107) in 35 ms on 10.1.2.182 (38/59)
17/01/29 08:57:46,122 INFO TaskSetManager: Starting task 52.0 in stage 2.0 (TID 118, 10.1.2.27, partition 52, PROCESS_LOCAL, 5374 bytes)
17/01/29 08:57:46,122 INFO CoarseGrainedSchedulerBackend$DriverEndpoint: Launching task 118 on executor id: 2 hostname: 10.1.2.27.
17/01/29 08:57:46,124 INFO TaskSetManager: Finished task 38.0 in stage 2.0 (TID 111) in 32 ms on 10.1.2.27 (39/59)
17/01/29 08:57:46,124 INFO TaskSetManager: Finished task 55.0 in stage 2.0 (TID 109) in 39 ms on 10.1.2.111 (40/59)
17/01/29 08:57:46,124 INFO TaskSetManager: Finished task 30.0 in stage 2.0 (TID 110) in 37 ms on 10.1.2.27 (41/59)
17/01/29 08:57:46,125 INFO TaskSetManager: Finished task 56.0 in stage 2.0 (TID 113) in 30 ms on 10.1.2.111 (42/59)
17/01/29 08:57:46,129 INFO TaskSetManager: Finished task 45.0 in stage 2.0 (TID 117) in 24 ms on 10.1.2.27 (43/59)
17/01/29 08:57:46,130 INFO TaskSetManager: Finished task 44.0 in stage 2.0 (TID 112) in 36 ms on 10.1.2.26 (44/59)
17/01/29 08:57:46,133 INFO TaskSetManager: Finished task 46.0 in stage 2.0 (TID 114) in 36 ms on 10.1.2.182 (45/59)
17/01/29 08:57:46,135 INFO TaskSetManager: Finished task 39.0 in stage 2.0 (TID 116) in 34 ms on 10.1.2.27 (46/59)
17/01/29 08:57:46,137 INFO TaskSetManager: Finished task 58.0 in stage 2.0 (TID 115) in 38 ms on 10.1.2.182 (47/59)
17/01/29 08:57:46,138 INFO TaskSetManager: Finished task 9.0 in stage 2.0 (TID 72) in 239 ms on 10.1.2.111 (48/59)
17/01/29 08:57:46,148 INFO TaskSetManager: Finished task 8.0 in stage 2.0 (TID 61) in 257 ms on 10.1.2.26 (49/59)
17/01/29 08:57:46,150 INFO TaskSetManager: Finished task 52.0 in stage 2.0 (TID 118) in 28 ms on 10.1.2.27 (50/59)
17/01/29 08:57:46,186 INFO TaskSetManager: Finished task 28.0 in stage 2.0 (TID 86) in 276 ms on 10.1.2.122 (51/59)
17/01/29 08:57:46,205 INFO TaskSetManager: Finished task 16.0 in stage 2.0 (TID 69) in 308 ms on 10.1.2.26 (52/59)
17/01/29 08:57:46,218 INFO TaskSetManager: Finished task 12.0 in stage 2.0 (TID 75) in 316 ms on 10.1.2.194 (53/59)
17/01/29 08:57:46,236 INFO TaskSetManager: Finished task 27.0 in stage 2.0 (TID 91) in 321 ms on 10.1.2.194 (54/59)
17/01/29 08:57:46,237 INFO TaskSetManager: Finished task 20.0 in stage 2.0 (TID 83) in 329 ms on 10.1.2.194 (55/59)
17/01/29 08:57:46,244 INFO TaskSetManager: Finished task 25.0 in stage 2.0 (TID 88) in 331 ms on 10.1.2.111 (56/59)
17/01/29 08:57:46,256 INFO TaskSetManager: Finished task 6.0 in stage 2.0 (TID 60) in 367 ms on 10.1.2.29 (57/59)
17/01/29 08:57:46,286 INFO TaskSetManager: Finished task 29.0 in stage 2.0 (TID 84) in 377 ms on 10.1.2.29 (58/59)
17/01/29 08:57:46,346 INFO TaskSetManager: Finished task 5.0 in stage 2.0 (TID 62) in 455 ms on 10.1.2.122 (59/59)
17/01/29 08:57:46,347 INFO TaskSchedulerImpl: Removed TaskSet 2.0, whose tasks have all completed, from pool 
17/01/29 08:57:46,347 INFO DAGScheduler: ResultStage 2 (count at GradientDescent.scala:209) finished in 0.458 s
17/01/29 08:57:46,348 INFO DAGScheduler: Job 2 finished: count at GradientDescent.scala:209, took 0.482210 s
17/01/29 08:57:46,577 WARN BLAS: Failed to load implementation from: com.github.fommil.netlib.NativeSystemBLAS
17/01/29 08:57:46,577 WARN BLAS: Failed to load implementation from: com.github.fommil.netlib.NativeRefBLAS
17/01/29 08:57:46,601 INFO MemoryStore: Block broadcast_4 stored as values in memory (estimated size 280.0 B, free 2.1 GB)
17/01/29 08:57:46,604 INFO MemoryStore: Block broadcast_4_piece0 stored as bytes in memory (estimated size 153.0 B, free 2.1 GB)
17/01/29 08:57:46,605 INFO BlockManagerInfo: Added broadcast_4_piece0 in memory on 10.1.2.241:40816 (size: 153.0 B, free: 2.1 GB)
17/01/29 08:57:46,607 INFO SparkContext: Created broadcast 4 from broadcast at GradientDescent.scala:235
17/01/29 08:57:46,656 INFO SparkContext: Starting job: treeAggregate at GradientDescent.scala:239
17/01/29 08:57:46,662 INFO DAGScheduler: Registering RDD 11 (treeAggregate at GradientDescent.scala:239)
17/01/29 08:57:46,663 INFO DAGScheduler: Got job 3 (treeAggregate at GradientDescent.scala:239) with 7 output partitions
17/01/29 08:57:46,663 INFO DAGScheduler: Final stage: ResultStage 4 (treeAggregate at GradientDescent.scala:239)
17/01/29 08:57:46,663 INFO DAGScheduler: Parents of final stage: List(ShuffleMapStage 3)
17/01/29 08:57:46,663 INFO DAGScheduler: Missing parents: List(ShuffleMapStage 3)
17/01/29 08:57:46,666 INFO DAGScheduler: Submitting ShuffleMapStage 3 (MapPartitionsRDD[11] at treeAggregate at GradientDescent.scala:239), which has no missing parents
17/01/29 08:57:46,683 INFO MemoryStore: Block broadcast_5 stored as values in memory (estimated size 7.2 KB, free 2.1 GB)
17/01/29 08:57:46,684 INFO MemoryStore: Block broadcast_5_piece0 stored as bytes in memory (estimated size 3.7 KB, free 2.1 GB)
17/01/29 08:57:46,685 INFO BlockManagerInfo: Added broadcast_5_piece0 in memory on 10.1.2.241:40816 (size: 3.7 KB, free: 2.1 GB)
17/01/29 08:57:46,686 INFO SparkContext: Created broadcast 5 from broadcast at DAGScheduler.scala:1012
17/01/29 08:57:46,688 INFO DAGScheduler: Submitting 59 missing tasks from ShuffleMapStage 3 (MapPartitionsRDD[11] at treeAggregate at GradientDescent.scala:239)
17/01/29 08:57:46,688 INFO TaskSchedulerImpl: Adding task set 3.0 with 59 tasks
17/01/29 08:57:46,692 INFO TaskSetManager: Starting task 6.0 in stage 3.0 (TID 119, 10.1.2.29, partition 6, PROCESS_LOCAL, 5563 bytes)
17/01/29 08:57:46,692 INFO TaskSetManager: Starting task 8.0 in stage 3.0 (TID 120, 10.1.2.26, partition 8, PROCESS_LOCAL, 5563 bytes)
17/01/29 08:57:46,693 INFO TaskSetManager: Starting task 5.0 in stage 3.0 (TID 121, 10.1.2.122, partition 5, PROCESS_LOCAL, 5563 bytes)
17/01/29 08:57:46,693 INFO TaskSetManager: Starting task 0.0 in stage 3.0 (TID 122, 10.1.2.27, partition 0, PROCESS_LOCAL, 5563 bytes)
17/01/29 08:57:46,694 INFO TaskSetManager: Starting task 1.0 in stage 3.0 (TID 123, 10.1.2.111, partition 1, PROCESS_LOCAL, 5563 bytes)
17/01/29 08:57:46,694 INFO TaskSetManager: Starting task 2.0 in stage 3.0 (TID 124, 10.1.2.182, partition 2, PROCESS_LOCAL, 5563 bytes)
17/01/29 08:57:46,695 INFO TaskSetManager: Starting task 3.0 in stage 3.0 (TID 125, 10.1.2.131, partition 3, PROCESS_LOCAL, 5563 bytes)
17/01/29 08:57:46,695 INFO TaskSetManager: Starting task 4.0 in stage 3.0 (TID 126, 10.1.2.194, partition 4, PROCESS_LOCAL, 5563 bytes)
17/01/29 08:57:46,695 INFO TaskSetManager: Starting task 14.0 in stage 3.0 (TID 127, 10.1.2.29, partition 14, PROCESS_LOCAL, 5563 bytes)
17/01/29 08:57:46,696 INFO TaskSetManager: Starting task 16.0 in stage 3.0 (TID 128, 10.1.2.26, partition 16, PROCESS_LOCAL, 5563 bytes)
17/01/29 08:57:46,696 INFO TaskSetManager: Starting task 13.0 in stage 3.0 (TID 129, 10.1.2.122, partition 13, PROCESS_LOCAL, 5563 bytes)
17/01/29 08:57:46,697 INFO TaskSetManager: Starting task 7.0 in stage 3.0 (TID 130, 10.1.2.27, partition 7, PROCESS_LOCAL, 5563 bytes)
17/01/29 08:57:46,697 INFO TaskSetManager: Starting task 9.0 in stage 3.0 (TID 131, 10.1.2.111, partition 9, PROCESS_LOCAL, 5563 bytes)
17/01/29 08:57:46,698 INFO TaskSetManager: Starting task 10.0 in stage 3.0 (TID 132, 10.1.2.182, partition 10, PROCESS_LOCAL, 5563 bytes)
17/01/29 08:57:46,698 INFO TaskSetManager: Starting task 11.0 in stage 3.0 (TID 133, 10.1.2.131, partition 11, PROCESS_LOCAL, 5563 bytes)
17/01/29 08:57:46,699 INFO TaskSetManager: Starting task 12.0 in stage 3.0 (TID 134, 10.1.2.194, partition 12, PROCESS_LOCAL, 5563 bytes)
17/01/29 08:57:46,699 INFO TaskSetManager: Starting task 22.0 in stage 3.0 (TID 135, 10.1.2.29, partition 22, PROCESS_LOCAL, 5563 bytes)
17/01/29 08:57:46,700 INFO TaskSetManager: Starting task 24.0 in stage 3.0 (TID 136, 10.1.2.26, partition 24, PROCESS_LOCAL, 5563 bytes)
17/01/29 08:57:46,700 INFO TaskSetManager: Starting task 21.0 in stage 3.0 (TID 137, 10.1.2.122, partition 21, PROCESS_LOCAL, 5563 bytes)
17/01/29 08:57:46,700 INFO TaskSetManager: Starting task 15.0 in stage 3.0 (TID 138, 10.1.2.27, partition 15, PROCESS_LOCAL, 5563 bytes)
17/01/29 08:57:46,701 INFO TaskSetManager: Starting task 17.0 in stage 3.0 (TID 139, 10.1.2.111, partition 17, PROCESS_LOCAL, 5563 bytes)
17/01/29 08:57:46,701 INFO TaskSetManager: Starting task 18.0 in stage 3.0 (TID 140, 10.1.2.182, partition 18, PROCESS_LOCAL, 5563 bytes)
17/01/29 08:57:46,702 INFO TaskSetManager: Starting task 19.0 in stage 3.0 (TID 141, 10.1.2.131, partition 19, PROCESS_LOCAL, 5563 bytes)
17/01/29 08:57:46,702 INFO TaskSetManager: Starting task 20.0 in stage 3.0 (TID 142, 10.1.2.194, partition 20, PROCESS_LOCAL, 5563 bytes)
17/01/29 08:57:46,703 INFO TaskSetManager: Starting task 29.0 in stage 3.0 (TID 143, 10.1.2.29, partition 29, PROCESS_LOCAL, 5563 bytes)
17/01/29 08:57:46,703 INFO TaskSetManager: Starting task 31.0 in stage 3.0 (TID 144, 10.1.2.26, partition 31, PROCESS_LOCAL, 5563 bytes)
17/01/29 08:57:46,704 INFO TaskSetManager: Starting task 28.0 in stage 3.0 (TID 145, 10.1.2.122, partition 28, PROCESS_LOCAL, 5563 bytes)
17/01/29 08:57:46,704 INFO TaskSetManager: Starting task 23.0 in stage 3.0 (TID 146, 10.1.2.27, partition 23, PROCESS_LOCAL, 5563 bytes)
17/01/29 08:57:46,705 INFO TaskSetManager: Starting task 25.0 in stage 3.0 (TID 147, 10.1.2.111, partition 25, PROCESS_LOCAL, 5563 bytes)
17/01/29 08:57:46,705 INFO TaskSetManager: Starting task 32.0 in stage 3.0 (TID 148, 10.1.2.182, partition 32, PROCESS_LOCAL, 5563 bytes)
17/01/29 08:57:46,705 INFO TaskSetManager: Starting task 26.0 in stage 3.0 (TID 149, 10.1.2.131, partition 26, PROCESS_LOCAL, 5563 bytes)
17/01/29 08:57:46,706 INFO TaskSetManager: Starting task 27.0 in stage 3.0 (TID 150, 10.1.2.194, partition 27, PROCESS_LOCAL, 5563 bytes)
17/01/29 08:57:46,706 INFO CoarseGrainedSchedulerBackend$DriverEndpoint: Launching task 119 on executor id: 6 hostname: 10.1.2.29.
17/01/29 08:57:46,706 INFO CoarseGrainedSchedulerBackend$DriverEndpoint: Launching task 127 on executor id: 6 hostname: 10.1.2.29.
17/01/29 08:57:46,707 INFO CoarseGrainedSchedulerBackend$DriverEndpoint: Launching task 135 on executor id: 6 hostname: 10.1.2.29.
17/01/29 08:57:46,707 INFO CoarseGrainedSchedulerBackend$DriverEndpoint: Launching task 143 on executor id: 6 hostname: 10.1.2.29.
17/01/29 08:57:46,707 INFO CoarseGrainedSchedulerBackend$DriverEndpoint: Launching task 120 on executor id: 0 hostname: 10.1.2.26.
17/01/29 08:57:46,707 INFO CoarseGrainedSchedulerBackend$DriverEndpoint: Launching task 128 on executor id: 0 hostname: 10.1.2.26.
17/01/29 08:57:46,708 INFO CoarseGrainedSchedulerBackend$DriverEndpoint: Launching task 136 on executor id: 0 hostname: 10.1.2.26.
17/01/29 08:57:46,708 INFO CoarseGrainedSchedulerBackend$DriverEndpoint: Launching task 144 on executor id: 0 hostname: 10.1.2.26.
17/01/29 08:57:46,709 INFO CoarseGrainedSchedulerBackend$DriverEndpoint: Launching task 121 on executor id: 7 hostname: 10.1.2.122.
17/01/29 08:57:46,709 INFO CoarseGrainedSchedulerBackend$DriverEndpoint: Launching task 129 on executor id: 7 hostname: 10.1.2.122.
17/01/29 08:57:46,709 INFO CoarseGrainedSchedulerBackend$DriverEndpoint: Launching task 137 on executor id: 7 hostname: 10.1.2.122.
17/01/29 08:57:46,710 INFO CoarseGrainedSchedulerBackend$DriverEndpoint: Launching task 145 on executor id: 7 hostname: 10.1.2.122.
17/01/29 08:57:46,710 INFO CoarseGrainedSchedulerBackend$DriverEndpoint: Launching task 122 on executor id: 2 hostname: 10.1.2.27.
17/01/29 08:57:46,711 INFO CoarseGrainedSchedulerBackend$DriverEndpoint: Launching task 130 on executor id: 2 hostname: 10.1.2.27.
17/01/29 08:57:46,711 INFO CoarseGrainedSchedulerBackend$DriverEndpoint: Launching task 138 on executor id: 2 hostname: 10.1.2.27.
17/01/29 08:57:46,711 INFO CoarseGrainedSchedulerBackend$DriverEndpoint: Launching task 146 on executor id: 2 hostname: 10.1.2.27.
17/01/29 08:57:46,712 INFO CoarseGrainedSchedulerBackend$DriverEndpoint: Launching task 123 on executor id: 5 hostname: 10.1.2.111.
17/01/29 08:57:46,712 INFO CoarseGrainedSchedulerBackend$DriverEndpoint: Launching task 131 on executor id: 5 hostname: 10.1.2.111.
17/01/29 08:57:46,713 INFO CoarseGrainedSchedulerBackend$DriverEndpoint: Launching task 139 on executor id: 5 hostname: 10.1.2.111.
17/01/29 08:57:46,713 INFO CoarseGrainedSchedulerBackend$DriverEndpoint: Launching task 147 on executor id: 5 hostname: 10.1.2.111.
17/01/29 08:57:46,713 INFO CoarseGrainedSchedulerBackend$DriverEndpoint: Launching task 124 on executor id: 1 hostname: 10.1.2.182.
17/01/29 08:57:46,714 INFO CoarseGrainedSchedulerBackend$DriverEndpoint: Launching task 132 on executor id: 1 hostname: 10.1.2.182.
17/01/29 08:57:46,715 INFO CoarseGrainedSchedulerBackend$DriverEndpoint: Launching task 140 on executor id: 1 hostname: 10.1.2.182.
17/01/29 08:57:46,716 INFO CoarseGrainedSchedulerBackend$DriverEndpoint: Launching task 148 on executor id: 1 hostname: 10.1.2.182.
17/01/29 08:57:46,716 INFO CoarseGrainedSchedulerBackend$DriverEndpoint: Launching task 125 on executor id: 4 hostname: 10.1.2.131.
17/01/29 08:57:46,716 INFO CoarseGrainedSchedulerBackend$DriverEndpoint: Launching task 133 on executor id: 4 hostname: 10.1.2.131.
17/01/29 08:57:46,717 INFO CoarseGrainedSchedulerBackend$DriverEndpoint: Launching task 141 on executor id: 4 hostname: 10.1.2.131.
17/01/29 08:57:46,717 INFO CoarseGrainedSchedulerBackend$DriverEndpoint: Launching task 149 on executor id: 4 hostname: 10.1.2.131.
17/01/29 08:57:46,717 INFO CoarseGrainedSchedulerBackend$DriverEndpoint: Launching task 126 on executor id: 3 hostname: 10.1.2.194.
17/01/29 08:57:46,718 INFO CoarseGrainedSchedulerBackend$DriverEndpoint: Launching task 134 on executor id: 3 hostname: 10.1.2.194.
17/01/29 08:57:46,718 INFO CoarseGrainedSchedulerBackend$DriverEndpoint: Launching task 142 on executor id: 3 hostname: 10.1.2.194.
17/01/29 08:57:46,718 INFO CoarseGrainedSchedulerBackend$DriverEndpoint: Launching task 150 on executor id: 3 hostname: 10.1.2.194.
17/01/29 08:57:46,733 INFO BlockManagerInfo: Added broadcast_5_piece0 in memory on 10.1.2.27:38845 (size: 3.7 KB, free: 1490.9 MB)
17/01/29 08:57:46,735 INFO BlockManagerInfo: Added broadcast_5_piece0 in memory on 10.1.2.122:38089 (size: 3.7 KB, free: 1630.5 MB)
17/01/29 08:57:46,736 INFO BlockManagerInfo: Added broadcast_5_piece0 in memory on 10.1.2.26:39210 (size: 3.7 KB, free: 1561.2 MB)
17/01/29 08:57:46,738 INFO BlockManagerInfo: Added broadcast_5_piece0 in memory on 10.1.2.29:39424 (size: 3.7 KB, free: 1631.1 MB)
17/01/29 08:57:46,742 INFO BlockManagerInfo: Added broadcast_5_piece0 in memory on 10.1.2.131:41486 (size: 3.7 KB, free: 1560.8 MB)
17/01/29 08:57:46,746 INFO BlockManagerInfo: Added broadcast_5_piece0 in memory on 10.1.2.182:38091 (size: 3.7 KB, free: 1558.2 MB)
17/01/29 08:57:46,753 INFO BlockManagerInfo: Added broadcast_5_piece0 in memory on 10.1.2.194:34076 (size: 3.7 KB, free: 1840.7 MB)
17/01/29 08:57:46,783 INFO BlockManagerInfo: Added broadcast_5_piece0 in memory on 10.1.2.111:35778 (size: 3.7 KB, free: 1561.1 MB)
17/01/29 08:57:47,025 INFO BlockManagerInfo: Added broadcast_4_piece0 in memory on 10.1.2.122:38089 (size: 153.0 B, free: 1630.5 MB)
17/01/29 08:57:47,028 INFO BlockManagerInfo: Added broadcast_4_piece0 in memory on 10.1.2.27:38845 (size: 153.0 B, free: 1490.9 MB)
17/01/29 08:57:47,048 INFO BlockManagerInfo: Added broadcast_4_piece0 in memory on 10.1.2.182:38091 (size: 153.0 B, free: 1558.2 MB)
17/01/29 08:57:47,049 INFO BlockManagerInfo: Added broadcast_4_piece0 in memory on 10.1.2.131:41486 (size: 153.0 B, free: 1560.8 MB)
17/01/29 08:57:47,052 INFO BlockManagerInfo: Added broadcast_4_piece0 in memory on 10.1.2.194:34076 (size: 153.0 B, free: 1840.7 MB)
17/01/29 08:57:47,063 INFO BlockManagerInfo: Added broadcast_4_piece0 in memory on 10.1.2.29:39424 (size: 153.0 B, free: 1631.1 MB)
17/01/29 08:57:47,075 INFO BlockManagerInfo: Added broadcast_4_piece0 in memory on 10.1.2.26:39210 (size: 153.0 B, free: 1561.2 MB)
17/01/29 08:57:47,083 INFO BlockManagerInfo: Added broadcast_4_piece0 in memory on 10.1.2.111:35778 (size: 153.0 B, free: 1561.1 MB)
17/01/29 08:57:47,209 INFO TaskSetManager: Starting task 47.0 in stage 3.0 (TID 151, 10.1.2.122, partition 47, PROCESS_LOCAL, 5563 bytes)
17/01/29 08:57:47,210 INFO CoarseGrainedSchedulerBackend$DriverEndpoint: Launching task 151 on executor id: 7 hostname: 10.1.2.122.
17/01/29 08:57:47,211 INFO TaskSetManager: Starting task 53.0 in stage 3.0 (TID 152, 10.1.2.122, partition 53, PROCESS_LOCAL, 5563 bytes)
17/01/29 08:57:47,211 INFO CoarseGrainedSchedulerBackend$DriverEndpoint: Launching task 152 on executor id: 7 hostname: 10.1.2.122.
17/01/29 08:57:47,212 INFO TaskSetManager: Finished task 28.0 in stage 3.0 (TID 145) in 508 ms on 10.1.2.122 (1/59)
17/01/29 08:57:47,213 INFO TaskSetManager: Finished task 21.0 in stage 3.0 (TID 137) in 513 ms on 10.1.2.122 (2/59)
17/01/29 08:57:47,214 INFO TaskSetManager: Starting task 57.0 in stage 3.0 (TID 153, 10.1.2.122, partition 57, PROCESS_LOCAL, 5563 bytes)
17/01/29 08:57:47,214 INFO CoarseGrainedSchedulerBackend$DriverEndpoint: Launching task 153 on executor id: 7 hostname: 10.1.2.122.
17/01/29 08:57:47,215 INFO TaskSetManager: Finished task 5.0 in stage 3.0 (TID 121) in 522 ms on 10.1.2.122 (3/59)
17/01/29 08:57:47,216 INFO TaskSetManager: Starting task 30.0 in stage 3.0 (TID 154, 10.1.2.27, partition 30, PROCESS_LOCAL, 5563 bytes)
17/01/29 08:57:47,216 INFO CoarseGrainedSchedulerBackend$DriverEndpoint: Launching task 154 on executor id: 2 hostname: 10.1.2.27.
17/01/29 08:57:47,216 INFO TaskSetManager: Finished task 0.0 in stage 3.0 (TID 122) in 523 ms on 10.1.2.27 (4/59)
17/01/29 08:57:47,217 INFO TaskSetManager: Starting task 38.0 in stage 3.0 (TID 155, 10.1.2.27, partition 38, PROCESS_LOCAL, 5563 bytes)
17/01/29 08:57:47,218 INFO CoarseGrainedSchedulerBackend$DriverEndpoint: Launching task 155 on executor id: 2 hostname: 10.1.2.27.
17/01/29 08:57:47,218 INFO TaskSetManager: Finished task 13.0 in stage 3.0 (TID 129) in 522 ms on 10.1.2.122 (5/59)
17/01/29 08:57:47,220 INFO TaskSetManager: Starting task 39.0 in stage 3.0 (TID 156, 10.1.2.27, partition 39, PROCESS_LOCAL, 5563 bytes)
17/01/29 08:57:47,221 INFO CoarseGrainedSchedulerBackend$DriverEndpoint: Launching task 156 on executor id: 2 hostname: 10.1.2.27.
17/01/29 08:57:47,221 INFO TaskSetManager: Finished task 15.0 in stage 3.0 (TID 138) in 521 ms on 10.1.2.27 (6/59)
17/01/29 08:57:47,222 INFO TaskSetManager: Starting task 37.0 in stage 3.0 (TID 157, 10.1.2.182, partition 37, PROCESS_LOCAL, 5563 bytes)
17/01/29 08:57:47,222 INFO CoarseGrainedSchedulerBackend$DriverEndpoint: Launching task 157 on executor id: 1 hostname: 10.1.2.182.
17/01/29 08:57:47,222 INFO TaskSetManager: Finished task 23.0 in stage 3.0 (TID 146) in 518 ms on 10.1.2.27 (7/59)
17/01/29 08:57:47,223 INFO TaskSetManager: Finished task 10.0 in stage 3.0 (TID 132) in 526 ms on 10.1.2.182 (8/59)
17/01/29 08:57:47,224 INFO TaskSetManager: Starting task 42.0 in stage 3.0 (TID 158, 10.1.2.182, partition 42, PROCESS_LOCAL, 5563 bytes)
17/01/29 08:57:47,225 INFO CoarseGrainedSchedulerBackend$DriverEndpoint: Launching task 158 on executor id: 1 hostname: 10.1.2.182.
17/01/29 08:57:47,225 INFO TaskSetManager: Finished task 2.0 in stage 3.0 (TID 124) in 531 ms on 10.1.2.182 (9/59)
17/01/29 08:57:47,225 INFO TaskSetManager: Starting task 46.0 in stage 3.0 (TID 159, 10.1.2.182, partition 46, PROCESS_LOCAL, 5563 bytes)
17/01/29 08:57:47,227 INFO TaskSetManager: Finished task 32.0 in stage 3.0 (TID 148) in 522 ms on 10.1.2.182 (10/59)
17/01/29 08:57:47,228 INFO CoarseGrainedSchedulerBackend$DriverEndpoint: Launching task 159 on executor id: 1 hostname: 10.1.2.182.
17/01/29 08:57:47,228 INFO TaskSetManager: Starting task 58.0 in stage 3.0 (TID 160, 10.1.2.182, partition 58, PROCESS_LOCAL, 5563 bytes)
17/01/29 08:57:47,229 INFO CoarseGrainedSchedulerBackend$DriverEndpoint: Launching task 160 on executor id: 1 hostname: 10.1.2.182.
17/01/29 08:57:47,229 INFO TaskSetManager: Finished task 18.0 in stage 3.0 (TID 140) in 528 ms on 10.1.2.182 (11/59)
17/01/29 08:57:47,230 INFO TaskSetManager: Finished task 12.0 in stage 3.0 (TID 134) in 532 ms on 10.1.2.194 (12/59)
17/01/29 08:57:47,230 INFO TaskSetManager: Finished task 4.0 in stage 3.0 (TID 126) in 535 ms on 10.1.2.194 (13/59)
17/01/29 08:57:47,231 INFO TaskSetManager: Finished task 7.0 in stage 3.0 (TID 130) in 535 ms on 10.1.2.27 (14/59)
17/01/29 08:57:47,231 INFO TaskSetManager: Starting task 45.0 in stage 3.0 (TID 161, 10.1.2.27, partition 45, PROCESS_LOCAL, 5563 bytes)
17/01/29 08:57:47,232 INFO CoarseGrainedSchedulerBackend$DriverEndpoint: Launching task 161 on executor id: 2 hostname: 10.1.2.27.
17/01/29 08:57:47,233 INFO TaskSetManager: Finished task 20.0 in stage 3.0 (TID 142) in 531 ms on 10.1.2.194 (15/59)
17/01/29 08:57:47,234 INFO TaskSetManager: Finished task 27.0 in stage 3.0 (TID 150) in 528 ms on 10.1.2.194 (16/59)
17/01/29 08:57:47,238 INFO TaskSetManager: Starting task 33.0 in stage 3.0 (TID 162, 10.1.2.131, partition 33, PROCESS_LOCAL, 5563 bytes)
17/01/29 08:57:47,238 INFO CoarseGrainedSchedulerBackend$DriverEndpoint: Launching task 162 on executor id: 4 hostname: 10.1.2.131.
17/01/29 08:57:47,239 INFO TaskSetManager: Starting task 34.0 in stage 3.0 (TID 163, 10.1.2.131, partition 34, PROCESS_LOCAL, 5563 bytes)
17/01/29 08:57:47,240 INFO CoarseGrainedSchedulerBackend$DriverEndpoint: Launching task 163 on executor id: 4 hostname: 10.1.2.131.
17/01/29 08:57:47,240 INFO TaskSetManager: Finished task 19.0 in stage 3.0 (TID 141) in 538 ms on 10.1.2.131 (17/59)
17/01/29 08:57:47,240 INFO TaskSetManager: Finished task 11.0 in stage 3.0 (TID 133) in 542 ms on 10.1.2.131 (18/59)
17/01/29 08:57:47,241 INFO TaskSetManager: Starting task 35.0 in stage 3.0 (TID 164, 10.1.2.131, partition 35, PROCESS_LOCAL, 5563 bytes)
17/01/29 08:57:47,241 INFO CoarseGrainedSchedulerBackend$DriverEndpoint: Launching task 164 on executor id: 4 hostname: 10.1.2.131.
17/01/29 08:57:47,241 INFO TaskSetManager: Finished task 3.0 in stage 3.0 (TID 125) in 547 ms on 10.1.2.131 (19/59)
17/01/29 08:57:47,242 INFO TaskSetManager: Starting task 36.0 in stage 3.0 (TID 165, 10.1.2.131, partition 36, PROCESS_LOCAL, 5563 bytes)
17/01/29 08:57:47,242 INFO CoarseGrainedSchedulerBackend$DriverEndpoint: Launching task 165 on executor id: 4 hostname: 10.1.2.131.
17/01/29 08:57:47,242 INFO TaskSetManager: Finished task 26.0 in stage 3.0 (TID 149) in 537 ms on 10.1.2.131 (20/59)
17/01/29 08:57:47,255 INFO TaskSetManager: Starting task 40.0 in stage 3.0 (TID 166, 10.1.2.26, partition 40, PROCESS_LOCAL, 5563 bytes)
17/01/29 08:57:47,255 INFO CoarseGrainedSchedulerBackend$DriverEndpoint: Launching task 166 on executor id: 0 hostname: 10.1.2.26.
17/01/29 08:57:47,256 INFO TaskSetManager: Finished task 31.0 in stage 3.0 (TID 144) in 552 ms on 10.1.2.26 (21/59)
17/01/29 08:57:47,256 INFO TaskSetManager: Starting task 41.0 in stage 3.0 (TID 167, 10.1.2.26, partition 41, PROCESS_LOCAL, 5563 bytes)
17/01/29 08:57:47,257 INFO CoarseGrainedSchedulerBackend$DriverEndpoint: Launching task 167 on executor id: 0 hostname: 10.1.2.26.
17/01/29 08:57:47,257 INFO TaskSetManager: Finished task 16.0 in stage 3.0 (TID 128) in 561 ms on 10.1.2.26 (22/59)
17/01/29 08:57:47,258 INFO TaskSetManager: Starting task 43.0 in stage 3.0 (TID 168, 10.1.2.26, partition 43, PROCESS_LOCAL, 5563 bytes)
17/01/29 08:57:47,258 INFO CoarseGrainedSchedulerBackend$DriverEndpoint: Launching task 168 on executor id: 0 hostname: 10.1.2.26.
17/01/29 08:57:47,260 INFO TaskSetManager: Finished task 24.0 in stage 3.0 (TID 136) in 561 ms on 10.1.2.26 (23/59)
17/01/29 08:57:47,261 INFO TaskSetManager: Starting task 44.0 in stage 3.0 (TID 169, 10.1.2.26, partition 44, PROCESS_LOCAL, 5563 bytes)
17/01/29 08:57:47,264 INFO CoarseGrainedSchedulerBackend$DriverEndpoint: Launching task 169 on executor id: 0 hostname: 10.1.2.26.
17/01/29 08:57:47,264 INFO TaskSetManager: Finished task 8.0 in stage 3.0 (TID 120) in 572 ms on 10.1.2.26 (24/59)
17/01/29 08:57:47,265 INFO TaskSetManager: Starting task 48.0 in stage 3.0 (TID 170, 10.1.2.29, partition 48, PROCESS_LOCAL, 5563 bytes)
17/01/29 08:57:47,265 INFO CoarseGrainedSchedulerBackend$DriverEndpoint: Launching task 170 on executor id: 6 hostname: 10.1.2.29.
17/01/29 08:57:47,265 INFO TaskSetManager: Finished task 6.0 in stage 3.0 (TID 119) in 575 ms on 10.1.2.29 (25/59)
17/01/29 08:57:47,269 INFO TaskSetManager: Starting task 49.0 in stage 3.0 (TID 171, 10.1.2.29, partition 49, PROCESS_LOCAL, 5563 bytes)
17/01/29 08:57:47,269 INFO CoarseGrainedSchedulerBackend$DriverEndpoint: Launching task 171 on executor id: 6 hostname: 10.1.2.29.
17/01/29 08:57:47,269 INFO TaskSetManager: Finished task 29.0 in stage 3.0 (TID 143) in 567 ms on 10.1.2.29 (26/59)
17/01/29 08:57:47,270 INFO TaskSetManager: Starting task 54.0 in stage 3.0 (TID 172, 10.1.2.29, partition 54, PROCESS_LOCAL, 5563 bytes)
17/01/29 08:57:47,270 INFO CoarseGrainedSchedulerBackend$DriverEndpoint: Launching task 172 on executor id: 6 hostname: 10.1.2.29.
17/01/29 08:57:47,270 INFO TaskSetManager: Finished task 14.0 in stage 3.0 (TID 127) in 575 ms on 10.1.2.29 (27/59)
17/01/29 08:57:47,272 INFO TaskSetManager: Finished task 22.0 in stage 3.0 (TID 135) in 572 ms on 10.1.2.29 (28/59)
17/01/29 08:57:47,274 INFO TaskSetManager: Starting task 50.0 in stage 3.0 (TID 173, 10.1.2.111, partition 50, PROCESS_LOCAL, 5563 bytes)
17/01/29 08:57:47,275 INFO CoarseGrainedSchedulerBackend$DriverEndpoint: Launching task 173 on executor id: 5 hostname: 10.1.2.111.
17/01/29 08:57:47,275 INFO TaskSetManager: Finished task 25.0 in stage 3.0 (TID 147) in 571 ms on 10.1.2.111 (29/59)
17/01/29 08:57:47,276 INFO TaskSetManager: Finished task 1.0 in stage 3.0 (TID 123) in 582 ms on 10.1.2.111 (30/59)
17/01/29 08:57:47,276 INFO TaskSetManager: Starting task 51.0 in stage 3.0 (TID 174, 10.1.2.111, partition 51, PROCESS_LOCAL, 5563 bytes)
17/01/29 08:57:47,277 INFO CoarseGrainedSchedulerBackend$DriverEndpoint: Launching task 174 on executor id: 5 hostname: 10.1.2.111.
17/01/29 08:57:47,278 INFO TaskSetManager: Starting task 55.0 in stage 3.0 (TID 175, 10.1.2.111, partition 55, PROCESS_LOCAL, 5563 bytes)
17/01/29 08:57:47,278 INFO CoarseGrainedSchedulerBackend$DriverEndpoint: Launching task 175 on executor id: 5 hostname: 10.1.2.111.
17/01/29 08:57:47,278 INFO TaskSetManager: Finished task 9.0 in stage 3.0 (TID 131) in 581 ms on 10.1.2.111 (31/59)
17/01/29 08:57:47,279 INFO TaskSetManager: Starting task 56.0 in stage 3.0 (TID 176, 10.1.2.111, partition 56, PROCESS_LOCAL, 5563 bytes)
17/01/29 08:57:47,279 INFO CoarseGrainedSchedulerBackend$DriverEndpoint: Launching task 176 on executor id: 5 hostname: 10.1.2.111.
17/01/29 08:57:47,279 INFO TaskSetManager: Finished task 17.0 in stage 3.0 (TID 139) in 578 ms on 10.1.2.111 (32/59)
17/01/29 08:57:47,322 INFO TaskSetManager: Finished task 58.0 in stage 3.0 (TID 160) in 94 ms on 10.1.2.182 (33/59)
17/01/29 08:57:47,323 INFO TaskSetManager: Starting task 52.0 in stage 3.0 (TID 177, 10.1.2.27, partition 52, PROCESS_LOCAL, 5563 bytes)
17/01/29 08:57:47,324 INFO CoarseGrainedSchedulerBackend$DriverEndpoint: Launching task 177 on executor id: 2 hostname: 10.1.2.27.
17/01/29 08:57:47,324 INFO TaskSetManager: Finished task 30.0 in stage 3.0 (TID 154) in 109 ms on 10.1.2.27 (34/59)
17/01/29 08:57:47,326 INFO TaskSetManager: Finished task 46.0 in stage 3.0 (TID 159) in 100 ms on 10.1.2.182 (35/59)
17/01/29 08:57:47,326 INFO TaskSetManager: Finished task 37.0 in stage 3.0 (TID 157) in 105 ms on 10.1.2.182 (36/59)
17/01/29 08:57:47,329 INFO TaskSetManager: Finished task 34.0 in stage 3.0 (TID 163) in 89 ms on 10.1.2.131 (37/59)
17/01/29 08:57:47,329 INFO TaskSetManager: Finished task 42.0 in stage 3.0 (TID 158) in 105 ms on 10.1.2.182 (38/59)
17/01/29 08:57:47,330 INFO TaskSetManager: Finished task 39.0 in stage 3.0 (TID 156) in 110 ms on 10.1.2.27 (39/59)
17/01/29 08:57:47,335 INFO TaskSetManager: Finished task 36.0 in stage 3.0 (TID 165) in 94 ms on 10.1.2.131 (40/59)
17/01/29 08:57:47,336 INFO TaskSetManager: Finished task 53.0 in stage 3.0 (TID 152) in 126 ms on 10.1.2.122 (41/59)
17/01/29 08:57:47,337 INFO TaskSetManager: Finished task 47.0 in stage 3.0 (TID 151) in 128 ms on 10.1.2.122 (42/59)
17/01/29 08:57:47,337 INFO TaskSetManager: Finished task 38.0 in stage 3.0 (TID 155) in 120 ms on 10.1.2.27 (43/59)
17/01/29 08:57:47,337 INFO TaskSetManager: Finished task 57.0 in stage 3.0 (TID 153) in 123 ms on 10.1.2.122 (44/59)
17/01/29 08:57:47,338 INFO TaskSetManager: Finished task 48.0 in stage 3.0 (TID 170) in 74 ms on 10.1.2.29 (45/59)
17/01/29 08:57:47,343 INFO TaskSetManager: Finished task 49.0 in stage 3.0 (TID 171) in 75 ms on 10.1.2.29 (46/59)
17/01/29 08:57:47,345 INFO TaskSetManager: Finished task 41.0 in stage 3.0 (TID 167) in 89 ms on 10.1.2.26 (47/59)
