Using properties file: /home/ubuntu/spark-2.0.0/conf/spark-defaults.conf
Adding default property: spark.driver.extraJavaOptions=-XX:+PrintGCDetails -XX:+PrintGCTimeStamps -Xms4000m -Dlog4j.configuration=file:///home/ubuntu/spark-2.0.0/conf/log4j.properties
Adding default property: spark.executor.extraJavaOptions=-XX:+PrintGCDetails -XX:+PrintGCTimeStamps -Xms4000m -Dlog4j.configuration=file:///home/ubuntu/spark-2.0.0/conf/log4j.properties
Parsed arguments:
  master                  spark://euca-10-1-2-241:7077
  deployMode              client
  executorMemory          4000m
  executorCores           null
  totalExecutorCores      null
  propertiesFile          /home/ubuntu/spark-2.0.0/conf/spark-defaults.conf
  driverMemory            4000m
  driverCores             null
  driverExtraClassPath    null
  driverExtraLibraryPath  null
  driverExtraJavaOptions  -XX:+PrintGCDetails -XX:+PrintGCTimeStamps -Xms4000m -Dlog4j.configuration=file:///home/ubuntu/spark-2.0.0/conf/log4j.properties
  supervise               false
  queue                   null
  numExecutors            8
  files                   null
  pyFiles                 null
  archives                null
  mainClass               LogRegExplicitParallelism
  primaryResource         file:///home/ubuntu/jars/log-reg-explicit-parallelism_2.11-1.0.jar
  name                    LogRegExplicitParallelism
  childArgs               [cluster 28 euca-10-1-2-241 9000 higgs_0_exp 5 32]
  jars                    null
  packages                null
  packagesExclusions      null
  repositories            null
  verbose                 true

Spark properties used, including those specified through
 --conf and those from the properties file /home/ubuntu/spark-2.0.0/conf/spark-defaults.conf:
  spark.default.parallelism -> 32
  spark.driver.memory -> 4000m
  spark.executor.extraJavaOptions -> -XX:+PrintGCDetails -XX:+PrintGCTimeStamps -Xms4000m -Dlog4j.configuration=file:///home/ubuntu/spark-2.0.0/conf/log4j.properties
  spark.driver.extraJavaOptions -> -XX:+PrintGCDetails -XX:+PrintGCTimeStamps -Xms4000m -Dlog4j.configuration=file:///home/ubuntu/spark-2.0.0/conf/log4j.properties
  spark.shuffle.spill -> false

    
Main class:
LogRegExplicitParallelism
Arguments:
cluster
28
euca-10-1-2-241
9000
higgs_0_exp
5
32
System properties:
spark.default.parallelism -> 32
spark.executor.memory -> 4000m
spark.driver.memory -> 4000m
SPARK_SUBMIT -> true
spark.executor.extraJavaOptions -> -XX:+PrintGCDetails -XX:+PrintGCTimeStamps -Xms4000m -Dlog4j.configuration=file:///home/ubuntu/spark-2.0.0/conf/log4j.properties
spark.app.name -> LogRegExplicitParallelism
spark.shuffle.spill -> false
spark.driver.extraJavaOptions -> -XX:+PrintGCDetails -XX:+PrintGCTimeStamps -Xms4000m -Dlog4j.configuration=file:///home/ubuntu/spark-2.0.0/conf/log4j.properties
spark.jars -> file:///home/ubuntu/jars/log-reg-explicit-parallelism_2.11-1.0.jar
spark.submit.deployMode -> client
spark.master -> spark://euca-10-1-2-241:7077
Classpath elements:
file:///home/ubuntu/jars/log-reg-explicit-parallelism_2.11-1.0.jar


17/01/29 08:50:37,866 INFO SparkContext: Running Spark version 2.0.0
17/01/29 08:50:38,204 WARN NativeCodeLoader: Unable to load native-hadoop library for your platform... using builtin-java classes where applicable
17/01/29 08:50:38,366 INFO SecurityManager: Changing view acls to: ubuntu
17/01/29 08:50:38,366 INFO SecurityManager: Changing modify acls to: ubuntu
17/01/29 08:50:38,367 INFO SecurityManager: Changing view acls groups to: 
17/01/29 08:50:38,367 INFO SecurityManager: Changing modify acls groups to: 
17/01/29 08:50:38,368 INFO SecurityManager: SecurityManager: authentication disabled; ui acls disabled; users  with view permissions: Set(ubuntu); groups with view permissions: Set(); users  with modify permissions: Set(ubuntu); groups with modify permissions: Set()
17/01/29 08:50:41,636 WARN ThreadLocalRandom: Failed to generate a seed from SecureRandom within 3 seconds. Not enough entrophy?
17/01/29 08:50:41,689 INFO Utils: Successfully started service 'sparkDriver' on port 46792.
17/01/29 08:50:41,709 INFO SparkEnv: Registering MapOutputTracker
17/01/29 08:50:41,715 WARN SortShuffleManager: spark.shuffle.spill was set to false, but this configuration is ignored as of Spark 1.6+. Shuffle will continue to spill to disk when necessary.
17/01/29 08:50:41,726 INFO SparkEnv: Registering BlockManagerMaster
17/01/29 08:50:41,739 INFO DiskBlockManager: Created local directory at /tmp/blockmgr-c80b8bef-5688-4b04-9333-1a86c554544f
17/01/29 08:50:41,757 INFO MemoryStore: MemoryStore started with capacity 2.1 GB
17/01/29 08:50:41,809 INFO SparkEnv: Registering OutputCommitCoordinator
17/01/29 08:50:42,007 INFO Utils: Successfully started service 'SparkUI' on port 4040.
17/01/29 08:50:42,009 INFO SparkUI: Bound SparkUI to 10.1.2.241, and started at http://10.1.2.241:4040
17/01/29 08:50:42,042 INFO SparkContext: Added JAR file:///home/ubuntu/jars/log-reg-explicit-parallelism_2.11-1.0.jar at spark://10.1.2.241:46792/jars/log-reg-explicit-parallelism_2.11-1.0.jar with timestamp 1485679842041
17/01/29 08:50:42,117 INFO StandaloneAppClient$ClientEndpoint: Connecting to master spark://euca-10-1-2-241:7077...
17/01/29 08:50:42,169 INFO TransportClientFactory: Successfully created connection to euca-10-1-2-241/10.1.2.241:7077 after 23 ms (0 ms spent in bootstraps)
17/01/29 08:50:42,266 INFO StandaloneSchedulerBackend: Connected to Spark cluster with app ID app-20170129085042-0000
17/01/29 08:50:42,271 INFO Utils: Successfully started service 'org.apache.spark.network.netty.NettyBlockTransferService' on port 44852.
17/01/29 08:50:42,272 INFO NettyBlockTransferService: Server created on 10.1.2.241:44852
17/01/29 08:50:42,278 INFO BlockManagerMaster: Registering BlockManager BlockManagerId(driver, 10.1.2.241, 44852)
17/01/29 08:50:42,285 INFO BlockManagerMasterEndpoint: Registering block manager 10.1.2.241:44852 with 2.1 GB RAM, BlockManagerId(driver, 10.1.2.241, 44852)
17/01/29 08:50:42,291 INFO StandaloneAppClient$ClientEndpoint: Executor added: app-20170129085042-0000/0 on worker-20170129085014-10.1.2.29-43972 (10.1.2.29:43972) with 4 cores
17/01/29 08:50:42,292 INFO StandaloneSchedulerBackend: Granted executor ID app-20170129085042-0000/0 on hostPort 10.1.2.29:43972 with 4 cores, 3.9 GB RAM
17/01/29 08:50:42,293 INFO StandaloneAppClient$ClientEndpoint: Executor added: app-20170129085042-0000/1 on worker-20170129085014-10.1.2.131-42089 (10.1.2.131:42089) with 4 cores
17/01/29 08:50:42,293 INFO BlockManagerMaster: Registered BlockManager BlockManagerId(driver, 10.1.2.241, 44852)
17/01/29 08:50:42,293 INFO StandaloneSchedulerBackend: Granted executor ID app-20170129085042-0000/1 on hostPort 10.1.2.131:42089 with 4 cores, 3.9 GB RAM
17/01/29 08:50:42,293 INFO StandaloneAppClient$ClientEndpoint: Executor added: app-20170129085042-0000/2 on worker-20170129085014-10.1.2.122-45954 (10.1.2.122:45954) with 4 cores
17/01/29 08:50:42,294 INFO StandaloneSchedulerBackend: Granted executor ID app-20170129085042-0000/2 on hostPort 10.1.2.122:45954 with 4 cores, 3.9 GB RAM
17/01/29 08:50:42,294 INFO StandaloneAppClient$ClientEndpoint: Executor added: app-20170129085042-0000/3 on worker-20170129085013-10.1.2.182-40494 (10.1.2.182:40494) with 4 cores
17/01/29 08:50:42,295 INFO StandaloneSchedulerBackend: Granted executor ID app-20170129085042-0000/3 on hostPort 10.1.2.182:40494 with 4 cores, 3.9 GB RAM
17/01/29 08:50:42,295 INFO StandaloneAppClient$ClientEndpoint: Executor added: app-20170129085042-0000/4 on worker-20170129085013-10.1.2.27-33360 (10.1.2.27:33360) with 4 cores
17/01/29 08:50:42,296 INFO StandaloneSchedulerBackend: Granted executor ID app-20170129085042-0000/4 on hostPort 10.1.2.27:33360 with 4 cores, 3.9 GB RAM
17/01/29 08:50:42,308 INFO StandaloneAppClient$ClientEndpoint: Executor added: app-20170129085042-0000/5 on worker-20170129085013-10.1.2.194-44496 (10.1.2.194:44496) with 4 cores
17/01/29 08:50:42,308 INFO StandaloneSchedulerBackend: Granted executor ID app-20170129085042-0000/5 on hostPort 10.1.2.194:44496 with 4 cores, 3.9 GB RAM
17/01/29 08:50:42,309 INFO StandaloneAppClient$ClientEndpoint: Executor added: app-20170129085042-0000/6 on worker-20170129085014-10.1.2.111-38672 (10.1.2.111:38672) with 4 cores
17/01/29 08:50:42,309 INFO StandaloneSchedulerBackend: Granted executor ID app-20170129085042-0000/6 on hostPort 10.1.2.111:38672 with 4 cores, 3.9 GB RAM
17/01/29 08:50:42,316 INFO StandaloneAppClient$ClientEndpoint: Executor added: app-20170129085042-0000/7 on worker-20170129085014-10.1.2.26-39903 (10.1.2.26:39903) with 4 cores
17/01/29 08:50:42,316 INFO StandaloneSchedulerBackend: Granted executor ID app-20170129085042-0000/7 on hostPort 10.1.2.26:39903 with 4 cores, 3.9 GB RAM
17/01/29 08:50:42,354 INFO StandaloneAppClient$ClientEndpoint: Executor updated: app-20170129085042-0000/4 is now RUNNING
17/01/29 08:50:42,368 INFO StandaloneAppClient$ClientEndpoint: Executor updated: app-20170129085042-0000/1 is now RUNNING
17/01/29 08:50:42,369 INFO StandaloneAppClient$ClientEndpoint: Executor updated: app-20170129085042-0000/0 is now RUNNING
17/01/29 08:50:42,372 INFO StandaloneAppClient$ClientEndpoint: Executor updated: app-20170129085042-0000/7 is now RUNNING
17/01/29 08:50:42,375 INFO StandaloneAppClient$ClientEndpoint: Executor updated: app-20170129085042-0000/2 is now RUNNING
17/01/29 08:50:42,378 INFO StandaloneAppClient$ClientEndpoint: Executor updated: app-20170129085042-0000/5 is now RUNNING
17/01/29 08:50:42,381 INFO StandaloneAppClient$ClientEndpoint: Executor updated: app-20170129085042-0000/3 is now RUNNING
17/01/29 08:50:42,384 INFO StandaloneAppClient$ClientEndpoint: Executor updated: app-20170129085042-0000/6 is now RUNNING
17/01/29 08:50:42,507 INFO StandaloneSchedulerBackend: SchedulerBackend is ready for scheduling beginning after reached minRegisteredResourcesRatio: 0.0
17/01/29 08:50:42,899 INFO MemoryStore: Block broadcast_0 stored as values in memory (estimated size 130.8 KB, free 2.1 GB)
17/01/29 08:50:42,965 INFO MemoryStore: Block broadcast_0_piece0 stored as bytes in memory (estimated size 16.5 KB, free 2.1 GB)
17/01/29 08:50:42,969 INFO BlockManagerInfo: Added broadcast_0_piece0 in memory on 10.1.2.241:44852 (size: 16.5 KB, free: 2.1 GB)
17/01/29 08:50:42,982 INFO SparkContext: Created broadcast 0 from textFile at MLUtils.scala:99
17/01/29 08:50:43,635 INFO FileInputFormat: Total input paths to process : 1
17/01/29 08:50:43,678 INFO NetworkTopology: Adding a new node: /default-rack/10.1.2.111:50010
17/01/29 08:50:43,679 INFO NetworkTopology: Adding a new node: /default-rack/10.1.2.182:50010
17/01/29 08:50:43,679 INFO NetworkTopology: Adding a new node: /default-rack/10.1.2.29:50010
17/01/29 08:50:43,679 INFO NetworkTopology: Adding a new node: /default-rack/10.1.2.122:50010
17/01/29 08:50:43,680 INFO NetworkTopology: Adding a new node: /default-rack/10.1.2.194:50010
17/01/29 08:50:43,680 INFO NetworkTopology: Adding a new node: /default-rack/10.1.2.26:50010
17/01/29 08:50:43,721 INFO SparkContext: Starting job: first at GeneralizedLinearAlgorithm.scala:246
17/01/29 08:50:43,737 INFO DAGScheduler: Got job 0 (first at GeneralizedLinearAlgorithm.scala:246) with 1 output partitions
17/01/29 08:50:43,737 INFO DAGScheduler: Final stage: ResultStage 0 (first at GeneralizedLinearAlgorithm.scala:246)
17/01/29 08:50:43,738 INFO DAGScheduler: Parents of final stage: List()
17/01/29 08:50:43,745 INFO DAGScheduler: Missing parents: List()
17/01/29 08:50:43,753 INFO DAGScheduler: Submitting ResultStage 0 (MapPartitionsRDD[6] at map at GeneralizedLinearAlgorithm.scala:246), which has no missing parents
17/01/29 08:50:43,783 INFO MemoryStore: Block broadcast_1 stored as values in memory (estimated size 4.2 KB, free 2.1 GB)
17/01/29 08:50:43,785 INFO MemoryStore: Block broadcast_1_piece0 stored as bytes in memory (estimated size 2.4 KB, free 2.1 GB)
17/01/29 08:50:43,786 INFO BlockManagerInfo: Added broadcast_1_piece0 in memory on 10.1.2.241:44852 (size: 2.4 KB, free: 2.1 GB)
17/01/29 08:50:43,788 INFO SparkContext: Created broadcast 1 from broadcast at DAGScheduler.scala:1012
17/01/29 08:50:43,791 INFO DAGScheduler: Submitting 1 missing tasks from ResultStage 0 (MapPartitionsRDD[6] at map at GeneralizedLinearAlgorithm.scala:246)
17/01/29 08:50:43,793 INFO TaskSchedulerImpl: Adding task set 0.0 with 1 tasks
17/01/29 08:50:44,139 INFO CoarseGrainedSchedulerBackend$DriverEndpoint: Registered executor NettyRpcEndpointRef(null) (10.1.2.182:32930) with ID 3
17/01/29 08:50:44,169 INFO TaskSetManager: Starting task 0.0 in stage 0.0 (TID 0, 10.1.2.182, partition 0, ANY, 5456 bytes)
17/01/29 08:50:44,180 INFO CoarseGrainedSchedulerBackend$DriverEndpoint: Launching task 0 on executor id: 3 hostname: 10.1.2.182.
17/01/29 08:50:44,195 INFO BlockManagerMasterEndpoint: Registering block manager 10.1.2.182:45671 with 2.1 GB RAM, BlockManagerId(3, 10.1.2.182, 45671)
17/01/29 08:50:44,222 INFO CoarseGrainedSchedulerBackend$DriverEndpoint: Registered executor NettyRpcEndpointRef(null) (10.1.2.111:52946) with ID 6
17/01/29 08:50:44,232 INFO CoarseGrainedSchedulerBackend$DriverEndpoint: Registered executor NettyRpcEndpointRef(null) (10.1.2.122:45224) with ID 2
17/01/29 08:50:44,237 INFO CoarseGrainedSchedulerBackend$DriverEndpoint: Registered executor NettyRpcEndpointRef(null) (10.1.2.29:55590) with ID 0
17/01/29 08:50:44,281 INFO BlockManagerMasterEndpoint: Registering block manager 10.1.2.122:34160 with 2.1 GB RAM, BlockManagerId(2, 10.1.2.122, 34160)
17/01/29 08:50:44,285 INFO BlockManagerMasterEndpoint: Registering block manager 10.1.2.111:33151 with 2.1 GB RAM, BlockManagerId(6, 10.1.2.111, 33151)
17/01/29 08:50:44,289 INFO BlockManagerMasterEndpoint: Registering block manager 10.1.2.29:40162 with 2.1 GB RAM, BlockManagerId(0, 10.1.2.29, 40162)
17/01/29 08:50:44,292 INFO CoarseGrainedSchedulerBackend$DriverEndpoint: Registered executor NettyRpcEndpointRef(null) (10.1.2.131:34520) with ID 1
17/01/29 08:50:44,327 INFO CoarseGrainedSchedulerBackend$DriverEndpoint: Registered executor NettyRpcEndpointRef(null) (10.1.2.26:39030) with ID 7
17/01/29 08:50:44,350 INFO BlockManagerMasterEndpoint: Registering block manager 10.1.2.131:37424 with 2.1 GB RAM, BlockManagerId(1, 10.1.2.131, 37424)
17/01/29 08:50:44,379 INFO BlockManagerMasterEndpoint: Registering block manager 10.1.2.26:36963 with 2.1 GB RAM, BlockManagerId(7, 10.1.2.26, 36963)
17/01/29 08:50:44,465 INFO BlockManagerInfo: Added broadcast_1_piece0 in memory on 10.1.2.182:45671 (size: 2.4 KB, free: 2.1 GB)
17/01/29 08:50:44,609 INFO BlockManagerInfo: Added broadcast_0_piece0 in memory on 10.1.2.182:45671 (size: 16.5 KB, free: 2.1 GB)
17/01/29 08:50:47,068 INFO CoarseGrainedSchedulerBackend$DriverEndpoint: Registered executor NettyRpcEndpointRef(null) (10.1.2.27:53914) with ID 4
17/01/29 08:50:47,119 INFO BlockManagerMasterEndpoint: Registering block manager 10.1.2.27:36131 with 2.1 GB RAM, BlockManagerId(4, 10.1.2.27, 36131)
17/01/29 08:50:47,132 INFO CoarseGrainedSchedulerBackend$DriverEndpoint: Registered executor NettyRpcEndpointRef(null) (10.1.2.194:56100) with ID 5
17/01/29 08:50:47,185 INFO BlockManagerMasterEndpoint: Registering block manager 10.1.2.194:35157 with 2.1 GB RAM, BlockManagerId(5, 10.1.2.194, 35157)
17/01/29 08:50:51,682 INFO BlockManagerInfo: Added rdd_5_0 in memory on 10.1.2.182:45671 (size: 70.0 MB, free: 2.0 GB)
17/01/29 08:50:51,731 INFO TaskSetManager: Finished task 0.0 in stage 0.0 (TID 0) in 7585 ms on 10.1.2.182 (1/1)
17/01/29 08:50:51,733 INFO TaskSchedulerImpl: Removed TaskSet 0.0, whose tasks have all completed, from pool 
17/01/29 08:50:51,736 INFO DAGScheduler: ResultStage 0 (first at GeneralizedLinearAlgorithm.scala:246) finished in 7.922 s
17/01/29 08:50:51,740 INFO DAGScheduler: Job 0 finished: first at GeneralizedLinearAlgorithm.scala:246, took 8.018998 s
17/01/29 08:50:51,752 INFO SparkContext: Starting job: count at DataValidators.scala:40
17/01/29 08:50:51,753 INFO DAGScheduler: Got job 1 (count at DataValidators.scala:40) with 59 output partitions
17/01/29 08:50:51,753 INFO DAGScheduler: Final stage: ResultStage 1 (count at DataValidators.scala:40)
17/01/29 08:50:51,753 INFO DAGScheduler: Parents of final stage: List()
17/01/29 08:50:51,756 INFO DAGScheduler: Missing parents: List()
17/01/29 08:50:51,757 INFO DAGScheduler: Submitting ResultStage 1 (MapPartitionsRDD[7] at filter at DataValidators.scala:40), which has no missing parents
17/01/29 08:50:51,782 INFO MemoryStore: Block broadcast_2 stored as values in memory (estimated size 3.9 KB, free 2.1 GB)
17/01/29 08:50:51,784 INFO MemoryStore: Block broadcast_2_piece0 stored as bytes in memory (estimated size 2.2 KB, free 2.1 GB)
17/01/29 08:50:51,785 INFO BlockManagerInfo: Added broadcast_2_piece0 in memory on 10.1.2.241:44852 (size: 2.2 KB, free: 2.1 GB)
17/01/29 08:50:51,786 INFO SparkContext: Created broadcast 2 from broadcast at DAGScheduler.scala:1012
17/01/29 08:50:51,788 INFO DAGScheduler: Submitting 59 missing tasks from ResultStage 1 (MapPartitionsRDD[7] at filter at DataValidators.scala:40)
17/01/29 08:50:51,788 INFO TaskSchedulerImpl: Adding task set 1.0 with 59 tasks
17/01/29 08:50:51,795 INFO TaskSetManager: Starting task 0.0 in stage 1.0 (TID 1, 10.1.2.182, partition 0, PROCESS_LOCAL, 5374 bytes)
17/01/29 08:50:51,798 INFO TaskSetManager: Starting task 58.0 in stage 1.0 (TID 2, 10.1.2.29, partition 58, NODE_LOCAL, 5374 bytes)
17/01/29 08:50:51,799 INFO CoarseGrainedSchedulerBackend$DriverEndpoint: Launching task 2 on executor id: 0 hostname: 10.1.2.29.
17/01/29 08:50:51,800 INFO CoarseGrainedSchedulerBackend$DriverEndpoint: Launching task 1 on executor id: 3 hostname: 10.1.2.182.
17/01/29 08:50:51,818 INFO BlockManagerInfo: Added broadcast_2_piece0 in memory on 10.1.2.182:45671 (size: 2.2 KB, free: 2.0 GB)
17/01/29 08:50:51,867 INFO TaskSetManager: Finished task 0.0 in stage 1.0 (TID 1) in 75 ms on 10.1.2.182 (1/59)
17/01/29 08:50:52,087 INFO BlockManagerInfo: Added broadcast_2_piece0 in memory on 10.1.2.29:40162 (size: 2.2 KB, free: 2.1 GB)
17/01/29 08:50:52,268 INFO BlockManagerInfo: Added broadcast_0_piece0 in memory on 10.1.2.29:40162 (size: 16.5 KB, free: 2.1 GB)
17/01/29 08:50:55,109 INFO TaskSetManager: Starting task 1.0 in stage 1.0 (TID 3, 10.1.2.26, partition 1, ANY, 5374 bytes)
17/01/29 08:50:55,112 INFO TaskSetManager: Starting task 2.0 in stage 1.0 (TID 4, 10.1.2.182, partition 2, ANY, 5374 bytes)
17/01/29 08:50:55,116 INFO TaskSetManager: Starting task 3.0 in stage 1.0 (TID 5, 10.1.2.27, partition 3, ANY, 5374 bytes)
17/01/29 08:50:55,118 INFO TaskSetManager: Starting task 4.0 in stage 1.0 (TID 6, 10.1.2.111, partition 4, ANY, 5374 bytes)
17/01/29 08:50:55,120 INFO TaskSetManager: Starting task 5.0 in stage 1.0 (TID 7, 10.1.2.194, partition 5, ANY, 5374 bytes)
17/01/29 08:50:55,122 INFO TaskSetManager: Starting task 6.0 in stage 1.0 (TID 8, 10.1.2.122, partition 6, ANY, 5374 bytes)
17/01/29 08:50:55,124 INFO TaskSetManager: Starting task 7.0 in stage 1.0 (TID 9, 10.1.2.131, partition 7, ANY, 5374 bytes)
17/01/29 08:50:55,126 INFO TaskSetManager: Starting task 8.0 in stage 1.0 (TID 10, 10.1.2.29, partition 8, ANY, 5374 bytes)
17/01/29 08:50:55,129 INFO TaskSetManager: Starting task 9.0 in stage 1.0 (TID 11, 10.1.2.26, partition 9, ANY, 5374 bytes)
17/01/29 08:50:55,130 INFO TaskSetManager: Starting task 10.0 in stage 1.0 (TID 12, 10.1.2.182, partition 10, ANY, 5374 bytes)
17/01/29 08:50:55,132 INFO TaskSetManager: Starting task 11.0 in stage 1.0 (TID 13, 10.1.2.27, partition 11, ANY, 5374 bytes)
17/01/29 08:50:55,134 INFO TaskSetManager: Starting task 12.0 in stage 1.0 (TID 14, 10.1.2.111, partition 12, ANY, 5374 bytes)
17/01/29 08:50:55,138 INFO TaskSetManager: Starting task 13.0 in stage 1.0 (TID 15, 10.1.2.194, partition 13, ANY, 5374 bytes)
17/01/29 08:50:55,139 INFO TaskSetManager: Starting task 14.0 in stage 1.0 (TID 16, 10.1.2.122, partition 14, ANY, 5374 bytes)
17/01/29 08:50:55,141 INFO TaskSetManager: Starting task 15.0 in stage 1.0 (TID 17, 10.1.2.131, partition 15, ANY, 5374 bytes)
17/01/29 08:50:55,143 INFO TaskSetManager: Starting task 16.0 in stage 1.0 (TID 18, 10.1.2.29, partition 16, ANY, 5374 bytes)
17/01/29 08:50:55,145 INFO TaskSetManager: Starting task 17.0 in stage 1.0 (TID 19, 10.1.2.26, partition 17, ANY, 5374 bytes)
17/01/29 08:50:55,148 INFO TaskSetManager: Starting task 18.0 in stage 1.0 (TID 20, 10.1.2.182, partition 18, ANY, 5374 bytes)
17/01/29 08:50:55,149 INFO TaskSetManager: Starting task 19.0 in stage 1.0 (TID 21, 10.1.2.27, partition 19, ANY, 5374 bytes)
17/01/29 08:50:55,152 INFO TaskSetManager: Starting task 20.0 in stage 1.0 (TID 22, 10.1.2.111, partition 20, ANY, 5374 bytes)
17/01/29 08:50:55,154 INFO TaskSetManager: Starting task 21.0 in stage 1.0 (TID 23, 10.1.2.194, partition 21, ANY, 5374 bytes)
17/01/29 08:50:55,155 INFO TaskSetManager: Starting task 22.0 in stage 1.0 (TID 24, 10.1.2.122, partition 22, ANY, 5374 bytes)
17/01/29 08:50:55,157 INFO TaskSetManager: Starting task 23.0 in stage 1.0 (TID 25, 10.1.2.131, partition 23, ANY, 5374 bytes)
17/01/29 08:50:55,159 INFO TaskSetManager: Starting task 24.0 in stage 1.0 (TID 26, 10.1.2.29, partition 24, ANY, 5374 bytes)
17/01/29 08:50:55,160 INFO TaskSetManager: Starting task 25.0 in stage 1.0 (TID 27, 10.1.2.26, partition 25, ANY, 5374 bytes)
17/01/29 08:50:55,162 INFO TaskSetManager: Starting task 26.0 in stage 1.0 (TID 28, 10.1.2.182, partition 26, ANY, 5374 bytes)
17/01/29 08:50:55,163 INFO TaskSetManager: Starting task 27.0 in stage 1.0 (TID 29, 10.1.2.27, partition 27, ANY, 5374 bytes)
17/01/29 08:50:55,165 INFO TaskSetManager: Starting task 28.0 in stage 1.0 (TID 30, 10.1.2.111, partition 28, ANY, 5374 bytes)
17/01/29 08:50:55,166 INFO TaskSetManager: Starting task 29.0 in stage 1.0 (TID 31, 10.1.2.194, partition 29, ANY, 5374 bytes)
17/01/29 08:50:55,168 INFO TaskSetManager: Starting task 30.0 in stage 1.0 (TID 32, 10.1.2.122, partition 30, ANY, 5374 bytes)
17/01/29 08:50:55,169 INFO TaskSetManager: Starting task 31.0 in stage 1.0 (TID 33, 10.1.2.131, partition 31, ANY, 5374 bytes)
17/01/29 08:50:55,170 INFO CoarseGrainedSchedulerBackend$DriverEndpoint: Launching task 3 on executor id: 7 hostname: 10.1.2.26.
17/01/29 08:50:55,171 INFO CoarseGrainedSchedulerBackend$DriverEndpoint: Launching task 11 on executor id: 7 hostname: 10.1.2.26.
17/01/29 08:50:55,172 INFO CoarseGrainedSchedulerBackend$DriverEndpoint: Launching task 19 on executor id: 7 hostname: 10.1.2.26.
17/01/29 08:50:55,173 INFO CoarseGrainedSchedulerBackend$DriverEndpoint: Launching task 27 on executor id: 7 hostname: 10.1.2.26.
17/01/29 08:50:55,173 INFO CoarseGrainedSchedulerBackend$DriverEndpoint: Launching task 4 on executor id: 3 hostname: 10.1.2.182.
17/01/29 08:50:55,174 INFO CoarseGrainedSchedulerBackend$DriverEndpoint: Launching task 12 on executor id: 3 hostname: 10.1.2.182.
17/01/29 08:50:55,175 INFO CoarseGrainedSchedulerBackend$DriverEndpoint: Launching task 20 on executor id: 3 hostname: 10.1.2.182.
17/01/29 08:50:55,176 INFO CoarseGrainedSchedulerBackend$DriverEndpoint: Launching task 28 on executor id: 3 hostname: 10.1.2.182.
17/01/29 08:50:55,177 INFO CoarseGrainedSchedulerBackend$DriverEndpoint: Launching task 5 on executor id: 4 hostname: 10.1.2.27.
17/01/29 08:50:55,177 INFO CoarseGrainedSchedulerBackend$DriverEndpoint: Launching task 13 on executor id: 4 hostname: 10.1.2.27.
17/01/29 08:50:55,178 INFO CoarseGrainedSchedulerBackend$DriverEndpoint: Launching task 21 on executor id: 4 hostname: 10.1.2.27.
17/01/29 08:50:55,179 INFO CoarseGrainedSchedulerBackend$DriverEndpoint: Launching task 29 on executor id: 4 hostname: 10.1.2.27.
17/01/29 08:50:55,180 INFO CoarseGrainedSchedulerBackend$DriverEndpoint: Launching task 6 on executor id: 6 hostname: 10.1.2.111.
17/01/29 08:50:55,183 INFO CoarseGrainedSchedulerBackend$DriverEndpoint: Launching task 14 on executor id: 6 hostname: 10.1.2.111.
17/01/29 08:50:55,184 INFO CoarseGrainedSchedulerBackend$DriverEndpoint: Launching task 22 on executor id: 6 hostname: 10.1.2.111.
17/01/29 08:50:55,184 INFO CoarseGrainedSchedulerBackend$DriverEndpoint: Launching task 30 on executor id: 6 hostname: 10.1.2.111.
17/01/29 08:50:55,185 INFO CoarseGrainedSchedulerBackend$DriverEndpoint: Launching task 7 on executor id: 5 hostname: 10.1.2.194.
17/01/29 08:50:55,186 INFO CoarseGrainedSchedulerBackend$DriverEndpoint: Launching task 15 on executor id: 5 hostname: 10.1.2.194.
17/01/29 08:50:55,187 INFO CoarseGrainedSchedulerBackend$DriverEndpoint: Launching task 23 on executor id: 5 hostname: 10.1.2.194.
17/01/29 08:50:55,188 INFO CoarseGrainedSchedulerBackend$DriverEndpoint: Launching task 31 on executor id: 5 hostname: 10.1.2.194.
17/01/29 08:50:55,189 INFO CoarseGrainedSchedulerBackend$DriverEndpoint: Launching task 8 on executor id: 2 hostname: 10.1.2.122.
17/01/29 08:50:55,190 INFO CoarseGrainedSchedulerBackend$DriverEndpoint: Launching task 16 on executor id: 2 hostname: 10.1.2.122.
17/01/29 08:50:55,191 INFO CoarseGrainedSchedulerBackend$DriverEndpoint: Launching task 24 on executor id: 2 hostname: 10.1.2.122.
17/01/29 08:50:55,191 INFO CoarseGrainedSchedulerBackend$DriverEndpoint: Launching task 32 on executor id: 2 hostname: 10.1.2.122.
17/01/29 08:50:55,192 INFO CoarseGrainedSchedulerBackend$DriverEndpoint: Launching task 9 on executor id: 1 hostname: 10.1.2.131.
17/01/29 08:50:55,193 INFO CoarseGrainedSchedulerBackend$DriverEndpoint: Launching task 17 on executor id: 1 hostname: 10.1.2.131.
17/01/29 08:50:55,193 INFO CoarseGrainedSchedulerBackend$DriverEndpoint: Launching task 25 on executor id: 1 hostname: 10.1.2.131.
17/01/29 08:50:55,194 INFO CoarseGrainedSchedulerBackend$DriverEndpoint: Launching task 33 on executor id: 1 hostname: 10.1.2.131.
17/01/29 08:50:55,194 INFO CoarseGrainedSchedulerBackend$DriverEndpoint: Launching task 10 on executor id: 0 hostname: 10.1.2.29.
17/01/29 08:50:55,195 INFO CoarseGrainedSchedulerBackend$DriverEndpoint: Launching task 18 on executor id: 0 hostname: 10.1.2.29.
17/01/29 08:50:55,195 INFO CoarseGrainedSchedulerBackend$DriverEndpoint: Launching task 26 on executor id: 0 hostname: 10.1.2.29.
17.952: [GC [PSYoungGen: 1024512K->157084K(1195008K)] 1024512K->157092K(3926016K), 0.0592700 secs] [Times: user=0.10 sys=0.03, real=0.06 secs] 
17/01/29 08:50:55,344 INFO BlockManagerInfo: Removed broadcast_1_piece0 on 10.1.2.241:44852 in memory (size: 2.4 KB, free: 2.1 GB)
17/01/29 08:50:55,386 INFO BlockManagerInfo: Removed broadcast_1_piece0 on 10.1.2.182:45671 in memory (size: 2.4 KB, free: 2.0 GB)
17/01/29 08:50:55,534 INFO BlockManagerInfo: Added broadcast_2_piece0 in memory on 10.1.2.131:37424 (size: 2.2 KB, free: 2.1 GB)
17/01/29 08:50:55,541 INFO BlockManagerInfo: Added broadcast_2_piece0 in memory on 10.1.2.26:36963 (size: 2.2 KB, free: 2.1 GB)
17/01/29 08:50:55,543 INFO BlockManagerInfo: Added broadcast_2_piece0 in memory on 10.1.2.194:35157 (size: 2.2 KB, free: 2.1 GB)
17/01/29 08:50:55,548 INFO BlockManagerInfo: Added broadcast_2_piece0 in memory on 10.1.2.122:34160 (size: 2.2 KB, free: 2.1 GB)
17/01/29 08:50:55,582 INFO BlockManagerInfo: Added broadcast_2_piece0 in memory on 10.1.2.111:33151 (size: 2.2 KB, free: 2.1 GB)
17/01/29 08:50:55,585 INFO BlockManagerInfo: Added broadcast_2_piece0 in memory on 10.1.2.27:36131 (size: 2.2 KB, free: 2.1 GB)
17/01/29 08:50:55,711 INFO BlockManagerInfo: Added broadcast_0_piece0 in memory on 10.1.2.26:36963 (size: 16.5 KB, free: 2.1 GB)
17/01/29 08:50:55,720 INFO BlockManagerInfo: Added broadcast_0_piece0 in memory on 10.1.2.131:37424 (size: 16.5 KB, free: 2.1 GB)
17/01/29 08:50:55,727 INFO BlockManagerInfo: Added broadcast_0_piece0 in memory on 10.1.2.194:35157 (size: 16.5 KB, free: 2.1 GB)
17/01/29 08:50:55,735 INFO BlockManagerInfo: Added broadcast_0_piece0 in memory on 10.1.2.111:33151 (size: 16.5 KB, free: 2.1 GB)
17/01/29 08:50:55,747 INFO BlockManagerInfo: Added broadcast_0_piece0 in memory on 10.1.2.122:34160 (size: 16.5 KB, free: 2.1 GB)
17/01/29 08:50:55,783 INFO BlockManagerInfo: Added broadcast_0_piece0 in memory on 10.1.2.27:36131 (size: 16.5 KB, free: 2.1 GB)
17/01/29 08:51:11,384 INFO BlockManagerInfo: Added rdd_5_26 in memory on 10.1.2.182:45671 (size: 69.9 MB, free: 1980.5 MB)
17/01/29 08:51:11,429 INFO TaskSetManager: Starting task 32.0 in stage 1.0 (TID 34, 10.1.2.182, partition 32, ANY, 5374 bytes)
17/01/29 08:51:11,430 INFO CoarseGrainedSchedulerBackend$DriverEndpoint: Launching task 34 on executor id: 3 hostname: 10.1.2.182.
17/01/29 08:51:11,430 INFO TaskSetManager: Finished task 26.0 in stage 1.0 (TID 28) in 16270 ms on 10.1.2.182 (2/59)
17/01/29 08:51:12,356 INFO BlockManagerInfo: Added rdd_5_18 in memory on 10.1.2.182:45671 (size: 70.0 MB, free: 1910.5 MB)
17/01/29 08:51:12,383 INFO TaskSetManager: Starting task 33.0 in stage 1.0 (TID 35, 10.1.2.182, partition 33, ANY, 5374 bytes)
17/01/29 08:51:12,384 INFO CoarseGrainedSchedulerBackend$DriverEndpoint: Launching task 35 on executor id: 3 hostname: 10.1.2.182.
17/01/29 08:51:12,388 INFO TaskSetManager: Finished task 18.0 in stage 1.0 (TID 20) in 17242 ms on 10.1.2.182 (3/59)
17/01/29 08:51:12,524 INFO BlockManagerInfo: Added rdd_5_2 in memory on 10.1.2.182:45671 (size: 69.9 MB, free: 1840.6 MB)
17/01/29 08:51:12,547 INFO TaskSetManager: Starting task 34.0 in stage 1.0 (TID 36, 10.1.2.182, partition 34, ANY, 5374 bytes)
17/01/29 08:51:12,548 INFO CoarseGrainedSchedulerBackend$DriverEndpoint: Launching task 36 on executor id: 3 hostname: 10.1.2.182.
17/01/29 08:51:12,548 INFO TaskSetManager: Finished task 2.0 in stage 1.0 (TID 4) in 17439 ms on 10.1.2.182 (4/59)
17/01/29 08:51:12,809 INFO BlockManagerInfo: Added rdd_5_10 in memory on 10.1.2.182:45671 (size: 70.0 MB, free: 1770.6 MB)
17/01/29 08:51:12,830 INFO TaskSetManager: Starting task 35.0 in stage 1.0 (TID 37, 10.1.2.182, partition 35, ANY, 5374 bytes)
17/01/29 08:51:12,831 INFO CoarseGrainedSchedulerBackend$DriverEndpoint: Launching task 37 on executor id: 3 hostname: 10.1.2.182.
17/01/29 08:51:12,837 INFO TaskSetManager: Finished task 10.0 in stage 1.0 (TID 12) in 17707 ms on 10.1.2.182 (5/59)
17/01/29 08:51:13,799 INFO BlockManagerInfo: Added rdd_5_5 in memory on 10.1.2.194:35157 (size: 70.0 MB, free: 2.0 GB)
17/01/29 08:51:13,883 INFO TaskSetManager: Starting task 36.0 in stage 1.0 (TID 38, 10.1.2.194, partition 36, ANY, 5374 bytes)
17/01/29 08:51:13,883 INFO CoarseGrainedSchedulerBackend$DriverEndpoint: Launching task 38 on executor id: 5 hostname: 10.1.2.194.
17/01/29 08:51:13,884 INFO TaskSetManager: Finished task 5.0 in stage 1.0 (TID 7) in 18765 ms on 10.1.2.194 (6/59)
17/01/29 08:51:13,898 INFO BlockManagerInfo: Added rdd_5_14 in memory on 10.1.2.122:34160 (size: 69.9 MB, free: 2.0 GB)
17/01/29 08:51:13,966 INFO TaskSetManager: Starting task 37.0 in stage 1.0 (TID 39, 10.1.2.122, partition 37, ANY, 5374 bytes)
17/01/29 08:51:13,966 INFO CoarseGrainedSchedulerBackend$DriverEndpoint: Launching task 39 on executor id: 2 hostname: 10.1.2.122.
17/01/29 08:51:13,968 INFO TaskSetManager: Finished task 14.0 in stage 1.0 (TID 16) in 18830 ms on 10.1.2.122 (7/59)
17/01/29 08:51:14,187 INFO BlockManagerInfo: Added rdd_5_30 in memory on 10.1.2.122:34160 (size: 70.0 MB, free: 1980.5 MB)
17/01/29 08:51:14,234 INFO TaskSetManager: Starting task 38.0 in stage 1.0 (TID 40, 10.1.2.122, partition 38, ANY, 5374 bytes)
17/01/29 08:51:14,234 INFO CoarseGrainedSchedulerBackend$DriverEndpoint: Launching task 40 on executor id: 2 hostname: 10.1.2.122.
17/01/29 08:51:14,235 INFO TaskSetManager: Finished task 30.0 in stage 1.0 (TID 32) in 19068 ms on 10.1.2.122 (8/59)
17/01/29 08:51:14,388 INFO BlockManagerInfo: Added rdd_5_22 in memory on 10.1.2.122:34160 (size: 69.8 MB, free: 1910.7 MB)
17/01/29 08:51:14,449 INFO TaskSetManager: Starting task 39.0 in stage 1.0 (TID 41, 10.1.2.122, partition 39, ANY, 5374 bytes)
17/01/29 08:51:14,449 INFO CoarseGrainedSchedulerBackend$DriverEndpoint: Launching task 41 on executor id: 2 hostname: 10.1.2.122.
17/01/29 08:51:14,449 INFO TaskSetManager: Finished task 22.0 in stage 1.0 (TID 24) in 19295 ms on 10.1.2.122 (9/59)
17/01/29 08:51:15,152 INFO BlockManagerInfo: Added rdd_5_29 in memory on 10.1.2.194:35157 (size: 69.9 MB, free: 1980.4 MB)
17/01/29 08:51:15,179 INFO TaskSetManager: Starting task 40.0 in stage 1.0 (TID 42, 10.1.2.194, partition 40, ANY, 5374 bytes)
17/01/29 08:51:15,179 INFO CoarseGrainedSchedulerBackend$DriverEndpoint: Launching task 42 on executor id: 5 hostname: 10.1.2.194.
17/01/29 08:51:15,179 INFO TaskSetManager: Finished task 29.0 in stage 1.0 (TID 31) in 20014 ms on 10.1.2.194 (10/59)
17/01/29 08:51:15,343 INFO BlockManagerInfo: Added rdd_5_6 in memory on 10.1.2.122:34160 (size: 69.9 MB, free: 1840.7 MB)
17/01/29 08:51:15,362 INFO TaskSetManager: Finished task 6.0 in stage 1.0 (TID 8) in 20241 ms on 10.1.2.122 (11/59)
17/01/29 08:51:15,364 INFO TaskSetManager: Starting task 41.0 in stage 1.0 (TID 43, 10.1.2.122, partition 41, ANY, 5374 bytes)
17/01/29 08:51:15,364 INFO CoarseGrainedSchedulerBackend$DriverEndpoint: Launching task 43 on executor id: 2 hostname: 10.1.2.122.
17/01/29 08:51:15,407 INFO BlockManagerInfo: Added rdd_5_20 in memory on 10.1.2.111:33151 (size: 69.8 MB, free: 2.0 GB)
17/01/29 08:51:15,475 INFO TaskSetManager: Starting task 42.0 in stage 1.0 (TID 44, 10.1.2.111, partition 42, ANY, 5374 bytes)
17/01/29 08:51:15,476 INFO CoarseGrainedSchedulerBackend$DriverEndpoint: Launching task 44 on executor id: 6 hostname: 10.1.2.111.
17/01/29 08:51:15,476 INFO TaskSetManager: Finished task 20.0 in stage 1.0 (TID 22) in 20327 ms on 10.1.2.111 (12/59)
17/01/29 08:51:15,545 INFO BlockManagerInfo: Added rdd_5_58 in memory on 10.1.2.29:40162 (size: 72.8 MB, free: 2047.6 MB)
17/01/29 08:51:15,606 INFO BlockManagerInfo: Added rdd_5_13 in memory on 10.1.2.194:35157 (size: 69.9 MB, free: 1910.5 MB)
17/01/29 08:51:15,619 INFO TaskSetManager: Starting task 43.0 in stage 1.0 (TID 45, 10.1.2.29, partition 43, ANY, 5374 bytes)
17/01/29 08:51:15,620 INFO CoarseGrainedSchedulerBackend$DriverEndpoint: Launching task 45 on executor id: 0 hostname: 10.1.2.29.
17/01/29 08:51:15,620 INFO TaskSetManager: Finished task 58.0 in stage 1.0 (TID 2) in 23824 ms on 10.1.2.29 (13/59)
17/01/29 08:51:15,631 INFO BlockManagerInfo: Added rdd_5_1 in memory on 10.1.2.26:36963 (size: 70.0 MB, free: 2.0 GB)
17/01/29 08:51:15,635 INFO TaskSetManager: Starting task 44.0 in stage 1.0 (TID 46, 10.1.2.194, partition 44, ANY, 5374 bytes)
17/01/29 08:51:15,635 INFO CoarseGrainedSchedulerBackend$DriverEndpoint: Launching task 46 on executor id: 5 hostname: 10.1.2.194.
17/01/29 08:51:15,635 INFO TaskSetManager: Finished task 13.0 in stage 1.0 (TID 15) in 20501 ms on 10.1.2.194 (14/59)
17/01/29 08:51:15,677 INFO BlockManagerInfo: Added rdd_5_21 in memory on 10.1.2.194:35157 (size: 69.9 MB, free: 1840.6 MB)
17/01/29 08:51:15,697 INFO TaskSetManager: Starting task 45.0 in stage 1.0 (TID 47, 10.1.2.194, partition 45, ANY, 5374 bytes)
17/01/29 08:51:15,698 INFO CoarseGrainedSchedulerBackend$DriverEndpoint: Launching task 47 on executor id: 5 hostname: 10.1.2.194.
17/01/29 08:51:15,698 INFO TaskSetManager: Finished task 21.0 in stage 1.0 (TID 23) in 20546 ms on 10.1.2.194 (15/59)
17/01/29 08:51:15,705 INFO TaskSetManager: Starting task 46.0 in stage 1.0 (TID 48, 10.1.2.26, partition 46, ANY, 5374 bytes)
17/01/29 08:51:15,705 INFO CoarseGrainedSchedulerBackend$DriverEndpoint: Launching task 48 on executor id: 7 hostname: 10.1.2.26.
17/01/29 08:51:15,705 INFO TaskSetManager: Finished task 1.0 in stage 1.0 (TID 3) in 20598 ms on 10.1.2.26 (16/59)
17/01/29 08:51:15,946 INFO BlockManagerInfo: Added rdd_5_12 in memory on 10.1.2.111:33151 (size: 70.0 MB, free: 1980.6 MB)
17/01/29 08:51:15,977 INFO TaskSetManager: Starting task 47.0 in stage 1.0 (TID 49, 10.1.2.111, partition 47, ANY, 5374 bytes)
17/01/29 08:51:15,977 INFO CoarseGrainedSchedulerBackend$DriverEndpoint: Launching task 49 on executor id: 6 hostname: 10.1.2.111.
17/01/29 08:51:15,977 INFO TaskSetManager: Finished task 12.0 in stage 1.0 (TID 14) in 20845 ms on 10.1.2.111 (17/59)
17/01/29 08:51:16,021 INFO BlockManagerInfo: Added rdd_5_28 in memory on 10.1.2.111:33151 (size: 70.0 MB, free: 1910.6 MB)
17/01/29 08:51:16,061 INFO TaskSetManager: Starting task 48.0 in stage 1.0 (TID 50, 10.1.2.111, partition 48, ANY, 5374 bytes)
17/01/29 08:51:16,061 INFO CoarseGrainedSchedulerBackend$DriverEndpoint: Launching task 50 on executor id: 6 hostname: 10.1.2.111.
17/01/29 08:51:16,062 INFO TaskSetManager: Finished task 28.0 in stage 1.0 (TID 30) in 20898 ms on 10.1.2.111 (18/59)
17/01/29 08:51:16,300 INFO BlockManagerInfo: Added rdd_5_25 in memory on 10.1.2.26:36963 (size: 70.0 MB, free: 1980.5 MB)
17/01/29 08:51:16,322 INFO TaskSetManager: Starting task 49.0 in stage 1.0 (TID 51, 10.1.2.26, partition 49, ANY, 5374 bytes)
17/01/29 08:51:16,323 INFO CoarseGrainedSchedulerBackend$DriverEndpoint: Launching task 51 on executor id: 7 hostname: 10.1.2.26.
17/01/29 08:51:16,323 INFO TaskSetManager: Finished task 25.0 in stage 1.0 (TID 27) in 21164 ms on 10.1.2.26 (19/59)
17/01/29 08:51:16,429 INFO BlockManagerInfo: Added rdd_5_4 in memory on 10.1.2.111:33151 (size: 70.0 MB, free: 1840.6 MB)
17/01/29 08:51:16,449 INFO TaskSetManager: Starting task 50.0 in stage 1.0 (TID 52, 10.1.2.111, partition 50, ANY, 5374 bytes)
17/01/29 08:51:16,450 INFO CoarseGrainedSchedulerBackend$DriverEndpoint: Launching task 52 on executor id: 6 hostname: 10.1.2.111.
17/01/29 08:51:16,450 INFO TaskSetManager: Finished task 4.0 in stage 1.0 (TID 6) in 21333 ms on 10.1.2.111 (20/59)
17/01/29 08:51:16,502 INFO BlockManagerInfo: Added rdd_5_9 in memory on 10.1.2.26:36963 (size: 69.9 MB, free: 1910.5 MB)
17/01/29 08:51:16,556 INFO TaskSetManager: Starting task 51.0 in stage 1.0 (TID 53, 10.1.2.26, partition 51, ANY, 5374 bytes)
17/01/29 08:51:16,557 INFO CoarseGrainedSchedulerBackend$DriverEndpoint: Launching task 53 on executor id: 7 hostname: 10.1.2.26.
17/01/29 08:51:16,557 INFO TaskSetManager: Finished task 9.0 in stage 1.0 (TID 11) in 21430 ms on 10.1.2.26 (21/59)
17/01/29 08:51:16,972 INFO BlockManagerInfo: Added rdd_5_11 in memory on 10.1.2.27:36131 (size: 69.9 MB, free: 2.0 GB)
17/01/29 08:51:17,040 INFO TaskSetManager: Starting task 52.0 in stage 1.0 (TID 54, 10.1.2.27, partition 52, ANY, 5374 bytes)
17/01/29 08:51:17,040 INFO CoarseGrainedSchedulerBackend$DriverEndpoint: Launching task 54 on executor id: 4 hostname: 10.1.2.27.
17/01/29 08:51:17,041 INFO TaskSetManager: Finished task 11.0 in stage 1.0 (TID 13) in 21909 ms on 10.1.2.27 (22/59)
17/01/29 08:51:17,103 INFO BlockManagerInfo: Added rdd_5_3 in memory on 10.1.2.27:36131 (size: 69.9 MB, free: 1980.6 MB)
17/01/29 08:51:17,146 INFO BlockManagerInfo: Added rdd_5_27 in memory on 10.1.2.27:36131 (size: 69.9 MB, free: 1910.6 MB)
17/01/29 08:51:17,149 INFO TaskSetManager: Starting task 53.0 in stage 1.0 (TID 55, 10.1.2.27, partition 53, ANY, 5374 bytes)
17/01/29 08:51:17,149 INFO CoarseGrainedSchedulerBackend$DriverEndpoint: Launching task 55 on executor id: 4 hostname: 10.1.2.27.
17/01/29 08:51:17,150 INFO TaskSetManager: Finished task 3.0 in stage 1.0 (TID 5) in 22037 ms on 10.1.2.27 (23/59)
17/01/29 08:51:17,187 INFO TaskSetManager: Starting task 54.0 in stage 1.0 (TID 56, 10.1.2.27, partition 54, ANY, 5374 bytes)
17/01/29 08:51:17,188 INFO CoarseGrainedSchedulerBackend$DriverEndpoint: Launching task 56 on executor id: 4 hostname: 10.1.2.27.
17/01/29 08:51:17,188 INFO TaskSetManager: Finished task 27.0 in stage 1.0 (TID 29) in 22026 ms on 10.1.2.27 (24/59)
17/01/29 08:51:17,286 INFO BlockManagerInfo: Added rdd_5_19 in memory on 10.1.2.27:36131 (size: 70.0 MB, free: 1840.7 MB)
17/01/29 08:51:17,303 INFO TaskSetManager: Starting task 55.0 in stage 1.0 (TID 57, 10.1.2.27, partition 55, ANY, 5374 bytes)
17/01/29 08:51:17,304 INFO CoarseGrainedSchedulerBackend$DriverEndpoint: Launching task 57 on executor id: 4 hostname: 10.1.2.27.
17/01/29 08:51:17,304 INFO TaskSetManager: Finished task 19.0 in stage 1.0 (TID 21) in 22156 ms on 10.1.2.27 (25/59)
17/01/29 08:51:18,054 INFO BlockManagerInfo: Added rdd_5_17 in memory on 10.1.2.26:36963 (size: 69.9 MB, free: 1840.6 MB)
17/01/29 08:51:18,073 INFO TaskSetManager: Starting task 56.0 in stage 1.0 (TID 58, 10.1.2.26, partition 56, ANY, 5374 bytes)
17/01/29 08:51:18,073 INFO CoarseGrainedSchedulerBackend$DriverEndpoint: Launching task 58 on executor id: 7 hostname: 10.1.2.26.
17/01/29 08:51:18,074 INFO TaskSetManager: Finished task 17.0 in stage 1.0 (TID 19) in 22931 ms on 10.1.2.26 (26/59)
17/01/29 08:51:19,649 INFO BlockManagerInfo: Added rdd_5_7 in memory on 10.1.2.131:37424 (size: 70.0 MB, free: 2.0 GB)
17/01/29 08:51:19,713 INFO TaskSetManager: Starting task 57.0 in stage 1.0 (TID 59, 10.1.2.131, partition 57, ANY, 5374 bytes)
17/01/29 08:51:19,714 INFO CoarseGrainedSchedulerBackend$DriverEndpoint: Launching task 59 on executor id: 1 hostname: 10.1.2.131.
17/01/29 08:51:19,715 INFO TaskSetManager: Finished task 7.0 in stage 1.0 (TID 9) in 24593 ms on 10.1.2.131 (27/59)
17/01/29 08:51:19,989 INFO BlockManagerInfo: Added rdd_5_23 in memory on 10.1.2.131:37424 (size: 69.9 MB, free: 1980.5 MB)
17/01/29 08:51:20,009 INFO TaskSetManager: Finished task 23.0 in stage 1.0 (TID 25) in 24853 ms on 10.1.2.131 (28/59)
17/01/29 08:51:20,092 INFO BlockManagerInfo: Added rdd_5_15 in memory on 10.1.2.131:37424 (size: 69.9 MB, free: 1910.6 MB)
17/01/29 08:51:20,118 INFO TaskSetManager: Finished task 15.0 in stage 1.0 (TID 17) in 24978 ms on 10.1.2.131 (29/59)
17/01/29 08:51:20,487 INFO BlockManagerInfo: Added rdd_5_31 in memory on 10.1.2.131:37424 (size: 69.7 MB, free: 1840.8 MB)
17/01/29 08:51:20,506 INFO TaskSetManager: Finished task 31.0 in stage 1.0 (TID 33) in 25338 ms on 10.1.2.131 (30/59)
17/01/29 08:51:21,728 INFO BlockManagerInfo: Added rdd_5_24 in memory on 10.1.2.29:40162 (size: 69.8 MB, free: 1977.9 MB)
17/01/29 08:51:21,762 INFO TaskSetManager: Finished task 24.0 in stage 1.0 (TID 26) in 26605 ms on 10.1.2.29 (31/59)
17/01/29 08:51:22,230 INFO BlockManagerInfo: Added rdd_5_8 in memory on 10.1.2.29:40162 (size: 70.0 MB, free: 1907.9 MB)
17/01/29 08:51:22,257 INFO TaskSetManager: Finished task 8.0 in stage 1.0 (TID 10) in 27132 ms on 10.1.2.29 (32/59)
17/01/29 08:51:22,413 INFO BlockManagerInfo: Added rdd_5_16 in memory on 10.1.2.29:40162 (size: 70.0 MB, free: 1837.9 MB)
17/01/29 08:51:22,433 INFO TaskSetManager: Finished task 16.0 in stage 1.0 (TID 18) in 27292 ms on 10.1.2.29 (33/59)
17/01/29 08:51:26,265 INFO BlockManagerInfo: Added rdd_5_57 in memory on 10.1.2.131:37424 (size: 70.1 MB, free: 1770.8 MB)
17/01/29 08:51:26,281 INFO TaskSetManager: Finished task 57.0 in stage 1.0 (TID 59) in 6568 ms on 10.1.2.131 (34/59)
17/01/29 08:51:27,081 INFO BlockManagerInfo: Added rdd_5_43 in memory on 10.1.2.29:40162 (size: 69.8 MB, free: 1768.1 MB)
17/01/29 08:51:27,099 INFO TaskSetManager: Finished task 43.0 in stage 1.0 (TID 45) in 11480 ms on 10.1.2.29 (35/59)
17/01/29 08:51:28,666 INFO BlockManagerInfo: Added rdd_5_32 in memory on 10.1.2.182:45671 (size: 69.9 MB, free: 1700.7 MB)
17/01/29 08:51:28,683 INFO TaskSetManager: Finished task 32.0 in stage 1.0 (TID 34) in 17259 ms on 10.1.2.182 (36/59)
17/01/29 08:51:29,575 INFO BlockManagerInfo: Added rdd_5_34 in memory on 10.1.2.182:45671 (size: 70.0 MB, free: 1630.7 MB)
17/01/29 08:51:29,592 INFO TaskSetManager: Finished task 34.0 in stage 1.0 (TID 36) in 17046 ms on 10.1.2.182 (37/59)
17/01/29 08:51:29,617 INFO BlockManagerInfo: Added rdd_5_35 in memory on 10.1.2.182:45671 (size: 70.0 MB, free: 1560.7 MB)
17/01/29 08:51:29,633 INFO TaskSetManager: Finished task 35.0 in stage 1.0 (TID 37) in 16804 ms on 10.1.2.182 (38/59)
17/01/29 08:51:29,690 INFO BlockManagerInfo: Added rdd_5_33 in memory on 10.1.2.182:45671 (size: 69.9 MB, free: 1490.8 MB)
17/01/29 08:51:29,706 INFO TaskSetManager: Finished task 33.0 in stage 1.0 (TID 35) in 17324 ms on 10.1.2.182 (39/59)
17/01/29 08:51:33,017 INFO BlockManagerInfo: Added rdd_5_39 in memory on 10.1.2.122:34160 (size: 70.0 MB, free: 1770.8 MB)
17/01/29 08:51:33,038 INFO TaskSetManager: Finished task 39.0 in stage 1.0 (TID 41) in 18591 ms on 10.1.2.122 (40/59)
17/01/29 08:51:33,145 INFO BlockManagerInfo: Added rdd_5_38 in memory on 10.1.2.122:34160 (size: 70.0 MB, free: 1700.8 MB)
17/01/29 08:51:33,162 INFO TaskSetManager: Finished task 38.0 in stage 1.0 (TID 40) in 18929 ms on 10.1.2.122 (41/59)
17/01/29 08:51:33,564 INFO BlockManagerInfo: Added rdd_5_37 in memory on 10.1.2.122:34160 (size: 69.9 MB, free: 1630.9 MB)
17/01/29 08:51:33,585 INFO TaskSetManager: Finished task 37.0 in stage 1.0 (TID 39) in 19621 ms on 10.1.2.122 (42/59)
17/01/29 08:51:34,361 INFO BlockManagerInfo: Added rdd_5_36 in memory on 10.1.2.194:35157 (size: 70.0 MB, free: 1770.6 MB)
17/01/29 08:51:34,380 INFO TaskSetManager: Finished task 36.0 in stage 1.0 (TID 38) in 20498 ms on 10.1.2.194 (43/59)
17/01/29 08:51:34,390 INFO BlockManagerInfo: Added rdd_5_41 in memory on 10.1.2.122:34160 (size: 70.0 MB, free: 1560.9 MB)
17/01/29 08:51:34,411 INFO TaskSetManager: Finished task 41.0 in stage 1.0 (TID 43) in 19047 ms on 10.1.2.122 (44/59)
17/01/29 08:51:34,430 INFO BlockManagerInfo: Added rdd_5_40 in memory on 10.1.2.194:35157 (size: 70.0 MB, free: 1700.6 MB)
17/01/29 08:51:34,451 INFO TaskSetManager: Finished task 40.0 in stage 1.0 (TID 42) in 19274 ms on 10.1.2.194 (45/59)
17/01/29 08:51:34,522 INFO BlockManagerInfo: Added rdd_5_45 in memory on 10.1.2.194:35157 (size: 69.9 MB, free: 1630.7 MB)
17/01/29 08:51:34,540 INFO TaskSetManager: Finished task 45.0 in stage 1.0 (TID 47) in 18843 ms on 10.1.2.194 (46/59)
17/01/29 08:51:34,832 INFO BlockManagerInfo: Added rdd_5_44 in memory on 10.1.2.194:35157 (size: 70.0 MB, free: 1560.7 MB)
17/01/29 08:51:34,850 INFO TaskSetManager: Finished task 44.0 in stage 1.0 (TID 46) in 19217 ms on 10.1.2.194 (47/59)
17/01/29 08:51:35,009 INFO BlockManagerInfo: Added rdd_5_49 in memory on 10.1.2.26:36963 (size: 69.8 MB, free: 1770.8 MB)
17/01/29 08:51:35,024 INFO BlockManagerInfo: Added rdd_5_47 in memory on 10.1.2.111:33151 (size: 70.0 MB, free: 1770.7 MB)
17/01/29 08:51:35,028 INFO TaskSetManager: Finished task 49.0 in stage 1.0 (TID 51) in 18707 ms on 10.1.2.26 (48/59)
17/01/29 08:51:35,049 INFO TaskSetManager: Finished task 47.0 in stage 1.0 (TID 49) in 19074 ms on 10.1.2.111 (49/59)
17/01/29 08:51:35,056 INFO BlockManagerInfo: Added rdd_5_48 in memory on 10.1.2.111:33151 (size: 69.9 MB, free: 1700.8 MB)
17/01/29 08:51:35,094 INFO TaskSetManager: Finished task 48.0 in stage 1.0 (TID 50) in 19034 ms on 10.1.2.111 (50/59)
17/01/29 08:51:35,112 INFO BlockManagerInfo: Added rdd_5_42 in memory on 10.1.2.111:33151 (size: 69.8 MB, free: 1631.0 MB)
17/01/29 08:51:35,129 INFO TaskSetManager: Finished task 42.0 in stage 1.0 (TID 44) in 19654 ms on 10.1.2.111 (51/59)
17/01/29 08:51:35,275 INFO BlockManagerInfo: Added rdd_5_50 in memory on 10.1.2.111:33151 (size: 69.9 MB, free: 1561.1 MB)
17/01/29 08:51:35,298 INFO TaskSetManager: Finished task 50.0 in stage 1.0 (TID 52) in 18849 ms on 10.1.2.111 (52/59)
17/01/29 08:51:35,606 INFO BlockManagerInfo: Added rdd_5_46 in memory on 10.1.2.26:36963 (size: 69.9 MB, free: 1700.9 MB)
17/01/29 08:51:35,624 INFO TaskSetManager: Finished task 46.0 in stage 1.0 (TID 48) in 19919 ms on 10.1.2.26 (53/59)
17/01/29 08:51:36,131 INFO BlockManagerInfo: Added rdd_5_55 in memory on 10.1.2.27:36131 (size: 69.9 MB, free: 1770.8 MB)
17/01/29 08:51:36,132 INFO BlockManagerInfo: Added rdd_5_51 in memory on 10.1.2.26:36963 (size: 69.9 MB, free: 1631.0 MB)
17/01/29 08:51:36,148 INFO TaskSetManager: Finished task 55.0 in stage 1.0 (TID 57) in 18846 ms on 10.1.2.27 (54/59)
17/01/29 08:51:36,150 INFO TaskSetManager: Finished task 51.0 in stage 1.0 (TID 53) in 19595 ms on 10.1.2.26 (55/59)
17/01/29 08:51:36,236 INFO BlockManagerInfo: Added rdd_5_56 in memory on 10.1.2.26:36963 (size: 69.9 MB, free: 1561.1 MB)
17/01/29 08:51:36,254 INFO TaskSetManager: Finished task 56.0 in stage 1.0 (TID 58) in 18181 ms on 10.1.2.26 (56/59)
17/01/29 08:51:36,442 INFO BlockManagerInfo: Added rdd_5_53 in memory on 10.1.2.27:36131 (size: 70.0 MB, free: 1700.7 MB)
17/01/29 08:51:36,456 INFO TaskSetManager: Finished task 53.0 in stage 1.0 (TID 55) in 19309 ms on 10.1.2.27 (57/59)
17/01/29 08:51:36,698 INFO BlockManagerInfo: Added rdd_5_52 in memory on 10.1.2.27:36131 (size: 69.9 MB, free: 1630.9 MB)
17/01/29 08:51:36,714 INFO TaskSetManager: Finished task 52.0 in stage 1.0 (TID 54) in 19675 ms on 10.1.2.27 (58/59)
17/01/29 08:51:36,792 INFO BlockManagerInfo: Added rdd_5_54 in memory on 10.1.2.27:36131 (size: 69.9 MB, free: 1561.0 MB)
17/01/29 08:51:36,807 INFO TaskSetManager: Finished task 54.0 in stage 1.0 (TID 56) in 19621 ms on 10.1.2.27 (59/59)
17/01/29 08:51:36,807 INFO TaskSchedulerImpl: Removed TaskSet 1.0, whose tasks have all completed, from pool 
17/01/29 08:51:36,808 INFO DAGScheduler: ResultStage 1 (count at DataValidators.scala:40) finished in 45.015 s
17/01/29 08:51:36,808 INFO DAGScheduler: Job 1 finished: count at DataValidators.scala:40, took 45.056545 s
17/01/29 08:51:36,817 INFO SparkContext: Starting job: count at GradientDescent.scala:209
17/01/29 08:51:36,818 INFO DAGScheduler: Got job 2 (count at GradientDescent.scala:209) with 59 output partitions
17/01/29 08:51:36,819 INFO DAGScheduler: Final stage: ResultStage 2 (count at GradientDescent.scala:209)
17/01/29 08:51:36,819 INFO DAGScheduler: Parents of final stage: List()
17/01/29 08:51:36,821 INFO DAGScheduler: Missing parents: List()
17/01/29 08:51:36,822 INFO DAGScheduler: Submitting ResultStage 2 (MapPartitionsRDD[8] at map at GeneralizedLinearAlgorithm.scala:297), which has no missing parents
17/01/29 08:51:36,828 INFO MemoryStore: Block broadcast_3 stored as values in memory (estimated size 3.9 KB, free 2.1 GB)
17/01/29 08:51:36,829 INFO MemoryStore: Block broadcast_3_piece0 stored as bytes in memory (estimated size 2.2 KB, free 2.1 GB)
17/01/29 08:51:36,830 INFO BlockManagerInfo: Added broadcast_3_piece0 in memory on 10.1.2.241:44852 (size: 2.2 KB, free: 2.1 GB)
17/01/29 08:51:36,831 INFO SparkContext: Created broadcast 3 from broadcast at DAGScheduler.scala:1012
17/01/29 08:51:36,832 INFO DAGScheduler: Submitting 59 missing tasks from ResultStage 2 (MapPartitionsRDD[8] at map at GeneralizedLinearAlgorithm.scala:297)
17/01/29 08:51:36,833 INFO TaskSchedulerImpl: Adding task set 2.0 with 59 tasks
17/01/29 08:51:36,835 INFO TaskSetManager: Starting task 0.0 in stage 2.0 (TID 60, 10.1.2.182, partition 0, PROCESS_LOCAL, 5374 bytes)
17/01/29 08:51:36,836 INFO TaskSetManager: Starting task 7.0 in stage 2.0 (TID 61, 10.1.2.131, partition 7, PROCESS_LOCAL, 5374 bytes)
17/01/29 08:51:36,837 INFO TaskSetManager: Starting task 1.0 in stage 2.0 (TID 62, 10.1.2.26, partition 1, PROCESS_LOCAL, 5374 bytes)
17/01/29 08:51:36,838 INFO TaskSetManager: Starting task 6.0 in stage 2.0 (TID 63, 10.1.2.122, partition 6, PROCESS_LOCAL, 5374 bytes)
17/01/29 08:51:36,839 INFO TaskSetManager: Starting task 5.0 in stage 2.0 (TID 64, 10.1.2.194, partition 5, PROCESS_LOCAL, 5374 bytes)
17/01/29 08:51:36,840 INFO TaskSetManager: Starting task 4.0 in stage 2.0 (TID 65, 10.1.2.111, partition 4, PROCESS_LOCAL, 5374 bytes)
17/01/29 08:51:36,842 INFO TaskSetManager: Starting task 8.0 in stage 2.0 (TID 66, 10.1.2.29, partition 8, PROCESS_LOCAL, 5374 bytes)
17/01/29 08:51:36,843 INFO TaskSetManager: Starting task 3.0 in stage 2.0 (TID 67, 10.1.2.27, partition 3, PROCESS_LOCAL, 5374 bytes)
17/01/29 08:51:36,844 INFO TaskSetManager: Starting task 2.0 in stage 2.0 (TID 68, 10.1.2.182, partition 2, PROCESS_LOCAL, 5374 bytes)
17/01/29 08:51:36,845 INFO TaskSetManager: Starting task 15.0 in stage 2.0 (TID 69, 10.1.2.131, partition 15, PROCESS_LOCAL, 5374 bytes)
17/01/29 08:51:36,846 INFO TaskSetManager: Starting task 9.0 in stage 2.0 (TID 70, 10.1.2.26, partition 9, PROCESS_LOCAL, 5374 bytes)
17/01/29 08:51:36,847 INFO TaskSetManager: Starting task 14.0 in stage 2.0 (TID 71, 10.1.2.122, partition 14, PROCESS_LOCAL, 5374 bytes)
17/01/29 08:51:36,849 INFO TaskSetManager: Starting task 13.0 in stage 2.0 (TID 72, 10.1.2.194, partition 13, PROCESS_LOCAL, 5374 bytes)
17/01/29 08:51:36,850 INFO TaskSetManager: Starting task 12.0 in stage 2.0 (TID 73, 10.1.2.111, partition 12, PROCESS_LOCAL, 5374 bytes)
17/01/29 08:51:36,851 INFO TaskSetManager: Starting task 16.0 in stage 2.0 (TID 74, 10.1.2.29, partition 16, PROCESS_LOCAL, 5374 bytes)
17/01/29 08:51:36,853 INFO TaskSetManager: Starting task 11.0 in stage 2.0 (TID 75, 10.1.2.27, partition 11, PROCESS_LOCAL, 5374 bytes)
17/01/29 08:51:36,854 INFO TaskSetManager: Starting task 10.0 in stage 2.0 (TID 76, 10.1.2.182, partition 10, PROCESS_LOCAL, 5374 bytes)
17/01/29 08:51:36,855 INFO TaskSetManager: Starting task 23.0 in stage 2.0 (TID 77, 10.1.2.131, partition 23, PROCESS_LOCAL, 5374 bytes)
17/01/29 08:51:36,857 INFO TaskSetManager: Starting task 17.0 in stage 2.0 (TID 78, 10.1.2.26, partition 17, PROCESS_LOCAL, 5374 bytes)
17/01/29 08:51:36,858 INFO TaskSetManager: Starting task 22.0 in stage 2.0 (TID 79, 10.1.2.122, partition 22, PROCESS_LOCAL, 5374 bytes)
17/01/29 08:51:36,859 INFO TaskSetManager: Starting task 21.0 in stage 2.0 (TID 80, 10.1.2.194, partition 21, PROCESS_LOCAL, 5374 bytes)
17/01/29 08:51:36,860 INFO TaskSetManager: Starting task 20.0 in stage 2.0 (TID 81, 10.1.2.111, partition 20, PROCESS_LOCAL, 5374 bytes)
17/01/29 08:51:36,862 INFO TaskSetManager: Starting task 24.0 in stage 2.0 (TID 82, 10.1.2.29, partition 24, PROCESS_LOCAL, 5374 bytes)
17/01/29 08:51:36,863 INFO TaskSetManager: Starting task 19.0 in stage 2.0 (TID 83, 10.1.2.27, partition 19, PROCESS_LOCAL, 5374 bytes)
17/01/29 08:51:36,865 INFO TaskSetManager: Starting task 18.0 in stage 2.0 (TID 84, 10.1.2.182, partition 18, PROCESS_LOCAL, 5374 bytes)
17/01/29 08:51:36,866 INFO TaskSetManager: Starting task 31.0 in stage 2.0 (TID 85, 10.1.2.131, partition 31, PROCESS_LOCAL, 5374 bytes)
17/01/29 08:51:36,867 INFO TaskSetManager: Starting task 25.0 in stage 2.0 (TID 86, 10.1.2.26, partition 25, PROCESS_LOCAL, 5374 bytes)
17/01/29 08:51:36,869 INFO TaskSetManager: Starting task 30.0 in stage 2.0 (TID 87, 10.1.2.122, partition 30, PROCESS_LOCAL, 5374 bytes)
17/01/29 08:51:36,870 INFO TaskSetManager: Starting task 29.0 in stage 2.0 (TID 88, 10.1.2.194, partition 29, PROCESS_LOCAL, 5374 bytes)
17/01/29 08:51:36,871 INFO TaskSetManager: Starting task 28.0 in stage 2.0 (TID 89, 10.1.2.111, partition 28, PROCESS_LOCAL, 5374 bytes)
17/01/29 08:51:36,872 INFO TaskSetManager: Starting task 43.0 in stage 2.0 (TID 90, 10.1.2.29, partition 43, PROCESS_LOCAL, 5374 bytes)
17/01/29 08:51:36,873 INFO TaskSetManager: Starting task 27.0 in stage 2.0 (TID 91, 10.1.2.27, partition 27, PROCESS_LOCAL, 5374 bytes)
17/01/29 08:51:36,874 INFO CoarseGrainedSchedulerBackend$DriverEndpoint: Launching task 60 on executor id: 3 hostname: 10.1.2.182.
17/01/29 08:51:36,875 INFO CoarseGrainedSchedulerBackend$DriverEndpoint: Launching task 68 on executor id: 3 hostname: 10.1.2.182.
17/01/29 08:51:36,875 INFO CoarseGrainedSchedulerBackend$DriverEndpoint: Launching task 76 on executor id: 3 hostname: 10.1.2.182.
17/01/29 08:51:36,876 INFO CoarseGrainedSchedulerBackend$DriverEndpoint: Launching task 84 on executor id: 3 hostname: 10.1.2.182.
17/01/29 08:51:36,877 INFO CoarseGrainedSchedulerBackend$DriverEndpoint: Launching task 61 on executor id: 1 hostname: 10.1.2.131.
17/01/29 08:51:36,878 INFO CoarseGrainedSchedulerBackend$DriverEndpoint: Launching task 69 on executor id: 1 hostname: 10.1.2.131.
17/01/29 08:51:36,879 INFO CoarseGrainedSchedulerBackend$DriverEndpoint: Launching task 77 on executor id: 1 hostname: 10.1.2.131.
17/01/29 08:51:36,880 INFO CoarseGrainedSchedulerBackend$DriverEndpoint: Launching task 85 on executor id: 1 hostname: 10.1.2.131.
17/01/29 08:51:36,881 INFO CoarseGrainedSchedulerBackend$DriverEndpoint: Launching task 62 on executor id: 7 hostname: 10.1.2.26.
17/01/29 08:51:36,882 INFO CoarseGrainedSchedulerBackend$DriverEndpoint: Launching task 70 on executor id: 7 hostname: 10.1.2.26.
17/01/29 08:51:36,882 INFO CoarseGrainedSchedulerBackend$DriverEndpoint: Launching task 78 on executor id: 7 hostname: 10.1.2.26.
17/01/29 08:51:36,883 INFO CoarseGrainedSchedulerBackend$DriverEndpoint: Launching task 86 on executor id: 7 hostname: 10.1.2.26.
17/01/29 08:51:36,884 INFO CoarseGrainedSchedulerBackend$DriverEndpoint: Launching task 63 on executor id: 2 hostname: 10.1.2.122.
17/01/29 08:51:36,884 INFO CoarseGrainedSchedulerBackend$DriverEndpoint: Launching task 71 on executor id: 2 hostname: 10.1.2.122.
17/01/29 08:51:36,885 INFO CoarseGrainedSchedulerBackend$DriverEndpoint: Launching task 79 on executor id: 2 hostname: 10.1.2.122.
17/01/29 08:51:36,885 INFO CoarseGrainedSchedulerBackend$DriverEndpoint: Launching task 87 on executor id: 2 hostname: 10.1.2.122.
17/01/29 08:51:36,886 INFO CoarseGrainedSchedulerBackend$DriverEndpoint: Launching task 64 on executor id: 5 hostname: 10.1.2.194.
17/01/29 08:51:36,886 INFO CoarseGrainedSchedulerBackend$DriverEndpoint: Launching task 72 on executor id: 5 hostname: 10.1.2.194.
17/01/29 08:51:36,887 INFO CoarseGrainedSchedulerBackend$DriverEndpoint: Launching task 80 on executor id: 5 hostname: 10.1.2.194.
17/01/29 08:51:36,887 INFO CoarseGrainedSchedulerBackend$DriverEndpoint: Launching task 88 on executor id: 5 hostname: 10.1.2.194.
17/01/29 08:51:36,888 INFO CoarseGrainedSchedulerBackend$DriverEndpoint: Launching task 65 on executor id: 6 hostname: 10.1.2.111.
17/01/29 08:51:36,888 INFO CoarseGrainedSchedulerBackend$DriverEndpoint: Launching task 73 on executor id: 6 hostname: 10.1.2.111.
17/01/29 08:51:36,889 INFO CoarseGrainedSchedulerBackend$DriverEndpoint: Launching task 81 on executor id: 6 hostname: 10.1.2.111.
17/01/29 08:51:36,890 INFO CoarseGrainedSchedulerBackend$DriverEndpoint: Launching task 89 on executor id: 6 hostname: 10.1.2.111.
17/01/29 08:51:36,891 INFO CoarseGrainedSchedulerBackend$DriverEndpoint: Launching task 66 on executor id: 0 hostname: 10.1.2.29.
17/01/29 08:51:36,891 INFO CoarseGrainedSchedulerBackend$DriverEndpoint: Launching task 74 on executor id: 0 hostname: 10.1.2.29.
17/01/29 08:51:36,892 INFO CoarseGrainedSchedulerBackend$DriverEndpoint: Launching task 82 on executor id: 0 hostname: 10.1.2.29.
17/01/29 08:51:36,892 INFO CoarseGrainedSchedulerBackend$DriverEndpoint: Launching task 90 on executor id: 0 hostname: 10.1.2.29.
17/01/29 08:51:36,892 INFO CoarseGrainedSchedulerBackend$DriverEndpoint: Launching task 67 on executor id: 4 hostname: 10.1.2.27.
17/01/29 08:51:36,893 INFO CoarseGrainedSchedulerBackend$DriverEndpoint: Launching task 75 on executor id: 4 hostname: 10.1.2.27.
17/01/29 08:51:36,894 INFO CoarseGrainedSchedulerBackend$DriverEndpoint: Launching task 83 on executor id: 4 hostname: 10.1.2.27.
17/01/29 08:51:36,897 INFO CoarseGrainedSchedulerBackend$DriverEndpoint: Launching task 91 on executor id: 4 hostname: 10.1.2.27.
17/01/29 08:51:36,918 INFO BlockManagerInfo: Added broadcast_3_piece0 in memory on 10.1.2.122:34160 (size: 2.2 KB, free: 1560.9 MB)
17/01/29 08:51:36,928 INFO BlockManagerInfo: Added broadcast_3_piece0 in memory on 10.1.2.194:35157 (size: 2.2 KB, free: 1560.7 MB)
17/01/29 08:51:36,934 INFO BlockManagerInfo: Added broadcast_3_piece0 in memory on 10.1.2.27:36131 (size: 2.2 KB, free: 1561.0 MB)
17/01/29 08:51:36,935 INFO BlockManagerInfo: Added broadcast_3_piece0 in memory on 10.1.2.26:36963 (size: 2.2 KB, free: 1561.1 MB)
17/01/29 08:51:36,938 INFO BlockManagerInfo: Added broadcast_3_piece0 in memory on 10.1.2.131:37424 (size: 2.2 KB, free: 1770.8 MB)
17/01/29 08:51:36,945 INFO BlockManagerInfo: Added broadcast_3_piece0 in memory on 10.1.2.111:33151 (size: 2.2 KB, free: 1561.1 MB)
17/01/29 08:51:36,973 INFO TaskSetManager: Finished task 3.0 in stage 2.0 (TID 67) in 130 ms on 10.1.2.27 (1/59)
17/01/29 08:51:36,974 INFO TaskSetManager: Starting task 52.0 in stage 2.0 (TID 92, 10.1.2.27, partition 52, PROCESS_LOCAL, 5374 bytes)
17/01/29 08:51:36,975 INFO CoarseGrainedSchedulerBackend$DriverEndpoint: Launching task 92 on executor id: 4 hostname: 10.1.2.27.
17/01/29 08:51:36,976 INFO TaskSetManager: Starting task 37.0 in stage 2.0 (TID 93, 10.1.2.122, partition 37, PROCESS_LOCAL, 5374 bytes)
17/01/29 08:51:36,976 INFO CoarseGrainedSchedulerBackend$DriverEndpoint: Launching task 93 on executor id: 2 hostname: 10.1.2.122.
17/01/29 08:51:36,977 INFO TaskSetManager: Finished task 14.0 in stage 2.0 (TID 71) in 130 ms on 10.1.2.122 (2/59)
17/01/29 08:51:36,978 INFO TaskSetManager: Starting task 38.0 in stage 2.0 (TID 94, 10.1.2.122, partition 38, PROCESS_LOCAL, 5374 bytes)
17/01/29 08:51:36,978 INFO CoarseGrainedSchedulerBackend$DriverEndpoint: Launching task 94 on executor id: 2 hostname: 10.1.2.122.
17/01/29 08:51:36,979 INFO TaskSetManager: Finished task 22.0 in stage 2.0 (TID 79) in 121 ms on 10.1.2.122 (3/59)
17/01/29 08:51:36,980 INFO TaskSetManager: Finished task 30.0 in stage 2.0 (TID 87) in 111 ms on 10.1.2.122 (4/59)
17/01/29 08:51:36,981 INFO TaskSetManager: Starting task 39.0 in stage 2.0 (TID 95, 10.1.2.122, partition 39, PROCESS_LOCAL, 5374 bytes)
17/01/29 08:51:36,981 INFO CoarseGrainedSchedulerBackend$DriverEndpoint: Launching task 95 on executor id: 2 hostname: 10.1.2.122.
17/01/29 08:51:36,982 INFO BlockManagerInfo: Added broadcast_3_piece0 in memory on 10.1.2.182:45671 (size: 2.2 KB, free: 1490.8 MB)
17/01/29 08:51:36,982 INFO TaskSetManager: Finished task 21.0 in stage 2.0 (TID 80) in 124 ms on 10.1.2.194 (5/59)
17/01/29 08:51:36,984 INFO TaskSetManager: Starting task 36.0 in stage 2.0 (TID 96, 10.1.2.194, partition 36, PROCESS_LOCAL, 5374 bytes)
17/01/29 08:51:36,984 INFO CoarseGrainedSchedulerBackend$DriverEndpoint: Launching task 96 on executor id: 5 hostname: 10.1.2.194.
17/01/29 08:51:36,985 INFO TaskSetManager: Starting task 53.0 in stage 2.0 (TID 97, 10.1.2.27, partition 53, PROCESS_LOCAL, 5374 bytes)
17/01/29 08:51:36,986 INFO CoarseGrainedSchedulerBackend$DriverEndpoint: Launching task 97 on executor id: 4 hostname: 10.1.2.27.
17/01/29 08:51:36,986 INFO TaskSetManager: Finished task 27.0 in stage 2.0 (TID 91) in 114 ms on 10.1.2.27 (6/59)
17/01/29 08:51:36,987 INFO TaskSetManager: Starting task 46.0 in stage 2.0 (TID 98, 10.1.2.26, partition 46, PROCESS_LOCAL, 5374 bytes)
17/01/29 08:51:36,987 INFO CoarseGrainedSchedulerBackend$DriverEndpoint: Launching task 98 on executor id: 7 hostname: 10.1.2.26.
17/01/29 08:51:36,988 INFO TaskSetManager: Finished task 9.0 in stage 2.0 (TID 70) in 143 ms on 10.1.2.26 (7/59)
17/01/29 08:51:36,989 INFO TaskSetManager: Finished task 25.0 in stage 2.0 (TID 86) in 123 ms on 10.1.2.26 (8/59)
17/01/29 08:51:36,991 INFO TaskSetManager: Starting task 49.0 in stage 2.0 (TID 99, 10.1.2.26, partition 49, PROCESS_LOCAL, 5374 bytes)
17/01/29 08:51:36,993 INFO CoarseGrainedSchedulerBackend$DriverEndpoint: Launching task 99 on executor id: 7 hostname: 10.1.2.26.
17/01/29 08:51:36,996 INFO TaskSetManager: Finished task 23.0 in stage 2.0 (TID 77) in 141 ms on 10.1.2.131 (9/59)
17/01/29 08:51:36,997 INFO TaskSetManager: Starting task 57.0 in stage 2.0 (TID 100, 10.1.2.131, partition 57, PROCESS_LOCAL, 5374 bytes)
17/01/29 08:51:36,998 INFO CoarseGrainedSchedulerBackend$DriverEndpoint: Launching task 100 on executor id: 1 hostname: 10.1.2.131.
17/01/29 08:51:37,000 INFO TaskSetManager: Starting task 51.0 in stage 2.0 (TID 101, 10.1.2.26, partition 51, PROCESS_LOCAL, 5374 bytes)
17/01/29 08:51:37,000 INFO CoarseGrainedSchedulerBackend$DriverEndpoint: Launching task 101 on executor id: 7 hostname: 10.1.2.26.
17/01/29 08:51:37,001 INFO TaskSetManager: Finished task 1.0 in stage 2.0 (TID 62) in 164 ms on 10.1.2.26 (10/59)
17/01/29 08:51:37,003 INFO TaskSetManager: Finished task 6.0 in stage 2.0 (TID 63) in 166 ms on 10.1.2.122 (11/59)
17/01/29 08:51:37,004 INFO TaskSetManager: Starting task 41.0 in stage 2.0 (TID 102, 10.1.2.122, partition 41, PROCESS_LOCAL, 5374 bytes)
17/01/29 08:51:37,005 INFO CoarseGrainedSchedulerBackend$DriverEndpoint: Launching task 102 on executor id: 2 hostname: 10.1.2.122.
17/01/29 08:51:37,005 INFO TaskSetManager: Finished task 15.0 in stage 2.0 (TID 69) in 160 ms on 10.1.2.131 (12/59)
17/01/29 08:51:37,006 INFO TaskSetManager: Finished task 4.0 in stage 2.0 (TID 65) in 166 ms on 10.1.2.111 (13/59)
17/01/29 08:51:37,007 INFO TaskSetManager: Starting task 42.0 in stage 2.0 (TID 103, 10.1.2.111, partition 42, PROCESS_LOCAL, 5374 bytes)
17/01/29 08:51:37,008 INFO CoarseGrainedSchedulerBackend$DriverEndpoint: Launching task 103 on executor id: 6 hostname: 10.1.2.111.
17/01/29 08:51:37,009 INFO TaskSetManager: Starting task 54.0 in stage 2.0 (TID 104, 10.1.2.27, partition 54, PROCESS_LOCAL, 5374 bytes)
17/01/29 08:51:37,009 INFO CoarseGrainedSchedulerBackend$DriverEndpoint: Launching task 104 on executor id: 4 hostname: 10.1.2.27.
17/01/29 08:51:37,010 INFO TaskSetManager: Finished task 52.0 in stage 2.0 (TID 92) in 36 ms on 10.1.2.27 (14/59)
17/01/29 08:51:37,011 INFO BlockManagerInfo: Added broadcast_3_piece0 in memory on 10.1.2.29:40162 (size: 2.2 KB, free: 1768.1 MB)
17/01/29 08:51:37,011 INFO TaskSetManager: Finished task 37.0 in stage 2.0 (TID 93) in 36 ms on 10.1.2.122 (15/59)
17/01/29 08:51:37,013 INFO TaskSetManager: Finished task 38.0 in stage 2.0 (TID 94) in 36 ms on 10.1.2.122 (16/59)
17/01/29 08:51:37,014 INFO TaskSetManager: Starting task 40.0 in stage 2.0 (TID 105, 10.1.2.194, partition 40, PROCESS_LOCAL, 5374 bytes)
17/01/29 08:51:37,015 INFO TaskSetManager: Finished task 36.0 in stage 2.0 (TID 96) in 32 ms on 10.1.2.194 (17/59)
17/01/29 08:51:37,015 INFO CoarseGrainedSchedulerBackend$DriverEndpoint: Launching task 105 on executor id: 5 hostname: 10.1.2.194.
17/01/29 08:51:37,017 INFO TaskSetManager: Finished task 39.0 in stage 2.0 (TID 95) in 36 ms on 10.1.2.122 (18/59)
17/01/29 08:51:37,017 INFO TaskSetManager: Finished task 31.0 in stage 2.0 (TID 85) in 152 ms on 10.1.2.131 (19/59)
17/01/29 08:51:37,019 INFO TaskSetManager: Starting task 55.0 in stage 2.0 (TID 106, 10.1.2.27, partition 55, PROCESS_LOCAL, 5374 bytes)
17/01/29 08:51:37,019 INFO CoarseGrainedSchedulerBackend$DriverEndpoint: Launching task 106 on executor id: 4 hostname: 10.1.2.27.
17/01/29 08:51:37,020 INFO TaskSetManager: Finished task 53.0 in stage 2.0 (TID 97) in 34 ms on 10.1.2.27 (20/59)
17/01/29 08:51:37,021 INFO TaskSetManager: Starting task 56.0 in stage 2.0 (TID 107, 10.1.2.26, partition 56, PROCESS_LOCAL, 5374 bytes)
17/01/29 08:51:37,022 INFO CoarseGrainedSchedulerBackend$DriverEndpoint: Launching task 107 on executor id: 7 hostname: 10.1.2.26.
17/01/29 08:51:37,022 INFO TaskSetManager: Finished task 49.0 in stage 2.0 (TID 99) in 31 ms on 10.1.2.26 (21/59)
17/01/29 08:51:37,027 INFO TaskSetManager: Finished task 51.0 in stage 2.0 (TID 101) in 28 ms on 10.1.2.26 (22/59)
17/01/29 08:51:37,028 INFO TaskSetManager: Finished task 19.0 in stage 2.0 (TID 83) in 166 ms on 10.1.2.27 (23/59)
17/01/29 08:51:37,032 INFO TaskSetManager: Starting task 44.0 in stage 2.0 (TID 108, 10.1.2.194, partition 44, PROCESS_LOCAL, 5374 bytes)
17/01/29 08:51:37,032 INFO CoarseGrainedSchedulerBackend$DriverEndpoint: Launching task 108 on executor id: 5 hostname: 10.1.2.194.
17/01/29 08:51:37,032 INFO TaskSetManager: Finished task 5.0 in stage 2.0 (TID 64) in 194 ms on 10.1.2.194 (24/59)
17/01/29 08:51:37,034 INFO TaskSetManager: Finished task 7.0 in stage 2.0 (TID 61) in 198 ms on 10.1.2.131 (25/59)
17/01/29 08:51:37,034 INFO TaskSetManager: Finished task 41.0 in stage 2.0 (TID 102) in 30 ms on 10.1.2.122 (26/59)
17/01/29 08:51:37,035 INFO TaskSetManager: Finished task 54.0 in stage 2.0 (TID 104) in 27 ms on 10.1.2.27 (27/59)
17/01/29 08:51:37,036 INFO TaskSetManager: Finished task 57.0 in stage 2.0 (TID 100) in 39 ms on 10.1.2.131 (28/59)
17/01/29 08:51:37,037 INFO TaskSetManager: Finished task 46.0 in stage 2.0 (TID 98) in 51 ms on 10.1.2.26 (29/59)
17/01/29 08:51:37,040 INFO TaskSetManager: Starting task 47.0 in stage 2.0 (TID 109, 10.1.2.111, partition 47, PROCESS_LOCAL, 5374 bytes)
17/01/29 08:51:37,040 INFO CoarseGrainedSchedulerBackend$DriverEndpoint: Launching task 109 on executor id: 6 hostname: 10.1.2.111.
17/01/29 08:51:37,041 INFO TaskSetManager: Finished task 42.0 in stage 2.0 (TID 103) in 34 ms on 10.1.2.111 (30/59)
17/01/29 08:51:37,042 INFO TaskSetManager: Starting task 48.0 in stage 2.0 (TID 110, 10.1.2.111, partition 48, PROCESS_LOCAL, 5374 bytes)
17/01/29 08:51:37,042 INFO CoarseGrainedSchedulerBackend$DriverEndpoint: Launching task 110 on executor id: 6 hostname: 10.1.2.111.
17/01/29 08:51:37,042 INFO TaskSetManager: Finished task 12.0 in stage 2.0 (TID 73) in 193 ms on 10.1.2.111 (31/59)
17/01/29 08:51:37,045 INFO TaskSetManager: Finished task 55.0 in stage 2.0 (TID 106) in 26 ms on 10.1.2.27 (32/59)
17/01/29 08:51:37,046 INFO TaskSetManager: Starting task 45.0 in stage 2.0 (TID 111, 10.1.2.194, partition 45, PROCESS_LOCAL, 5374 bytes)
17/01/29 08:51:37,046 INFO CoarseGrainedSchedulerBackend$DriverEndpoint: Launching task 111 on executor id: 5 hostname: 10.1.2.194.
17/01/29 08:51:37,046 INFO TaskSetManager: Finished task 40.0 in stage 2.0 (TID 105) in 33 ms on 10.1.2.194 (33/59)
17/01/29 08:51:37,047 INFO TaskSetManager: Finished task 11.0 in stage 2.0 (TID 75) in 195 ms on 10.1.2.27 (34/59)
17/01/29 08:51:37,052 INFO TaskSetManager: Starting task 58.0 in stage 2.0 (TID 112, 10.1.2.29, partition 58, PROCESS_LOCAL, 5374 bytes)
17/01/29 08:51:37,052 INFO TaskSetManager: Finished task 56.0 in stage 2.0 (TID 107) in 31 ms on 10.1.2.26 (35/59)
17/01/29 08:51:37,052 INFO TaskSetManager: Finished task 16.0 in stage 2.0 (TID 74) in 202 ms on 10.1.2.29 (36/59)
17/01/29 08:51:37,053 INFO CoarseGrainedSchedulerBackend$DriverEndpoint: Launching task 112 on executor id: 0 hostname: 10.1.2.29.
17/01/29 08:51:37,054 INFO TaskSetManager: Starting task 26.0 in stage 2.0 (TID 113, 10.1.2.182, partition 26, PROCESS_LOCAL, 5374 bytes)
17/01/29 08:51:37,055 INFO CoarseGrainedSchedulerBackend$DriverEndpoint: Launching task 113 on executor id: 3 hostname: 10.1.2.182.
17/01/29 08:51:37,055 INFO TaskSetManager: Finished task 0.0 in stage 2.0 (TID 60) in 221 ms on 10.1.2.182 (37/59)
17/01/29 08:51:37,056 INFO TaskSetManager: Finished task 43.0 in stage 2.0 (TID 90) in 185 ms on 10.1.2.29 (38/59)
17/01/29 08:51:37,059 INFO TaskSetManager: Starting task 32.0 in stage 2.0 (TID 114, 10.1.2.182, partition 32, PROCESS_LOCAL, 5374 bytes)
17/01/29 08:51:37,059 INFO CoarseGrainedSchedulerBackend$DriverEndpoint: Launching task 114 on executor id: 3 hostname: 10.1.2.182.
17/01/29 08:51:37,059 INFO TaskSetManager: Finished task 10.0 in stage 2.0 (TID 76) in 206 ms on 10.1.2.182 (39/59)
17/01/29 08:51:37,062 INFO TaskSetManager: Starting task 33.0 in stage 2.0 (TID 115, 10.1.2.182, partition 33, PROCESS_LOCAL, 5374 bytes)
17/01/29 08:51:37,062 INFO CoarseGrainedSchedulerBackend$DriverEndpoint: Launching task 115 on executor id: 3 hostname: 10.1.2.182.
17/01/29 08:51:37,062 INFO TaskSetManager: Finished task 18.0 in stage 2.0 (TID 84) in 199 ms on 10.1.2.182 (40/59)
17/01/29 08:51:37,064 INFO TaskSetManager: Finished task 44.0 in stage 2.0 (TID 108) in 33 ms on 10.1.2.194 (41/59)
17/01/29 08:51:37,065 INFO TaskSetManager: Starting task 34.0 in stage 2.0 (TID 116, 10.1.2.182, partition 34, PROCESS_LOCAL, 5374 bytes)
17/01/29 08:51:37,066 INFO CoarseGrainedSchedulerBackend$DriverEndpoint: Launching task 116 on executor id: 3 hostname: 10.1.2.182.
17/01/29 08:51:37,066 INFO TaskSetManager: Finished task 2.0 in stage 2.0 (TID 68) in 223 ms on 10.1.2.182 (42/59)
17/01/29 08:51:37,071 INFO TaskSetManager: Starting task 50.0 in stage 2.0 (TID 117, 10.1.2.111, partition 50, PROCESS_LOCAL, 5374 bytes)
17/01/29 08:51:37,071 INFO CoarseGrainedSchedulerBackend$DriverEndpoint: Launching task 117 on executor id: 6 hostname: 10.1.2.111.
17/01/29 08:51:37,071 INFO TaskSetManager: Finished task 47.0 in stage 2.0 (TID 109) in 31 ms on 10.1.2.111 (43/59)
17/01/29 08:51:37,073 INFO TaskSetManager: Finished task 45.0 in stage 2.0 (TID 111) in 28 ms on 10.1.2.194 (44/59)
17/01/29 08:51:37,074 INFO TaskSetManager: Finished task 8.0 in stage 2.0 (TID 66) in 233 ms on 10.1.2.29 (45/59)
17/01/29 08:51:37,076 INFO TaskSetManager: Finished task 48.0 in stage 2.0 (TID 110) in 35 ms on 10.1.2.111 (46/59)
17/01/29 08:51:37,088 INFO TaskSetManager: Finished task 58.0 in stage 2.0 (TID 112) in 37 ms on 10.1.2.29 (47/59)
17/01/29 08:51:37,094 INFO TaskSetManager: Starting task 35.0 in stage 2.0 (TID 118, 10.1.2.182, partition 35, PROCESS_LOCAL, 5374 bytes)
17/01/29 08:51:37,094 INFO CoarseGrainedSchedulerBackend$DriverEndpoint: Launching task 118 on executor id: 3 hostname: 10.1.2.182.
17/01/29 08:51:37,094 INFO TaskSetManager: Finished task 26.0 in stage 2.0 (TID 113) in 41 ms on 10.1.2.182 (48/59)
17/01/29 08:51:37,096 INFO TaskSetManager: Finished task 33.0 in stage 2.0 (TID 115) in 35 ms on 10.1.2.182 (49/59)
17/01/29 08:51:37,097 INFO TaskSetManager: Finished task 50.0 in stage 2.0 (TID 117) in 26 ms on 10.1.2.111 (50/59)
17/01/29 08:51:37,098 INFO TaskSetManager: Finished task 34.0 in stage 2.0 (TID 116) in 32 ms on 10.1.2.182 (51/59)
17/01/29 08:51:37,100 INFO TaskSetManager: Finished task 32.0 in stage 2.0 (TID 114) in 42 ms on 10.1.2.182 (52/59)
17/01/29 08:51:37,107 INFO TaskSetManager: Finished task 20.0 in stage 2.0 (TID 81) in 248 ms on 10.1.2.111 (53/59)
17/01/29 08:51:37,122 INFO TaskSetManager: Finished task 35.0 in stage 2.0 (TID 118) in 29 ms on 10.1.2.182 (54/59)
17/01/29 08:51:37,156 INFO TaskSetManager: Finished task 29.0 in stage 2.0 (TID 88) in 287 ms on 10.1.2.194 (55/59)
17/01/29 08:51:37,166 INFO TaskSetManager: Finished task 24.0 in stage 2.0 (TID 82) in 304 ms on 10.1.2.29 (56/59)
17/01/29 08:51:37,204 INFO TaskSetManager: Finished task 17.0 in stage 2.0 (TID 78) in 348 ms on 10.1.2.26 (57/59)
17/01/29 08:51:37,266 INFO TaskSetManager: Finished task 28.0 in stage 2.0 (TID 89) in 396 ms on 10.1.2.111 (58/59)
17/01/29 08:51:37,268 INFO TaskSetManager: Finished task 13.0 in stage 2.0 (TID 72) in 420 ms on 10.1.2.194 (59/59)
17/01/29 08:51:37,268 INFO TaskSchedulerImpl: Removed TaskSet 2.0, whose tasks have all completed, from pool 
17/01/29 08:51:37,268 INFO DAGScheduler: ResultStage 2 (count at GradientDescent.scala:209) finished in 0.434 s
17/01/29 08:51:37,269 INFO DAGScheduler: Job 2 finished: count at GradientDescent.scala:209, took 0.451403 s
17/01/29 08:51:37,501 WARN BLAS: Failed to load implementation from: com.github.fommil.netlib.NativeSystemBLAS
17/01/29 08:51:37,501 WARN BLAS: Failed to load implementation from: com.github.fommil.netlib.NativeRefBLAS
17/01/29 08:51:37,524 INFO MemoryStore: Block broadcast_4 stored as values in memory (estimated size 280.0 B, free 2.1 GB)
17/01/29 08:51:37,527 INFO MemoryStore: Block broadcast_4_piece0 stored as bytes in memory (estimated size 153.0 B, free 2.1 GB)
17/01/29 08:51:37,530 INFO BlockManagerInfo: Added broadcast_4_piece0 in memory on 10.1.2.241:44852 (size: 153.0 B, free: 2.1 GB)
17/01/29 08:51:37,530 INFO SparkContext: Created broadcast 4 from broadcast at GradientDescent.scala:235
17/01/29 08:51:37,592 INFO SparkContext: Starting job: treeAggregate at GradientDescent.scala:239
17/01/29 08:51:37,598 INFO DAGScheduler: Registering RDD 11 (treeAggregate at GradientDescent.scala:239)
17/01/29 08:51:37,599 INFO DAGScheduler: Got job 3 (treeAggregate at GradientDescent.scala:239) with 7 output partitions
17/01/29 08:51:37,599 INFO DAGScheduler: Final stage: ResultStage 4 (treeAggregate at GradientDescent.scala:239)
17/01/29 08:51:37,599 INFO DAGScheduler: Parents of final stage: List(ShuffleMapStage 3)
17/01/29 08:51:37,599 INFO DAGScheduler: Missing parents: List(ShuffleMapStage 3)
17/01/29 08:51:37,602 INFO DAGScheduler: Submitting ShuffleMapStage 3 (MapPartitionsRDD[11] at treeAggregate at GradientDescent.scala:239), which has no missing parents
17/01/29 08:51:37,619 INFO MemoryStore: Block broadcast_5 stored as values in memory (estimated size 7.2 KB, free 2.1 GB)
17/01/29 08:51:37,623 INFO MemoryStore: Block broadcast_5_piece0 stored as bytes in memory (estimated size 3.7 KB, free 2.1 GB)
17/01/29 08:51:37,624 INFO BlockManagerInfo: Added broadcast_5_piece0 in memory on 10.1.2.241:44852 (size: 3.7 KB, free: 2.1 GB)
17/01/29 08:51:37,624 INFO SparkContext: Created broadcast 5 from broadcast at DAGScheduler.scala:1012
17/01/29 08:51:37,626 INFO DAGScheduler: Submitting 59 missing tasks from ShuffleMapStage 3 (MapPartitionsRDD[11] at treeAggregate at GradientDescent.scala:239)
17/01/29 08:51:37,627 INFO TaskSchedulerImpl: Adding task set 3.0 with 59 tasks
17/01/29 08:51:37,630 INFO TaskSetManager: Starting task 6.0 in stage 3.0 (TID 119, 10.1.2.122, partition 6, PROCESS_LOCAL, 5563 bytes)
17/01/29 08:51:37,631 INFO TaskSetManager: Starting task 4.0 in stage 3.0 (TID 120, 10.1.2.111, partition 4, PROCESS_LOCAL, 5563 bytes)
17/01/29 08:51:37,631 INFO TaskSetManager: Starting task 7.0 in stage 3.0 (TID 121, 10.1.2.131, partition 7, PROCESS_LOCAL, 5563 bytes)
17/01/29 08:51:37,632 INFO TaskSetManager: Starting task 3.0 in stage 3.0 (TID 122, 10.1.2.27, partition 3, PROCESS_LOCAL, 5563 bytes)
17/01/29 08:51:37,632 INFO TaskSetManager: Starting task 8.0 in stage 3.0 (TID 123, 10.1.2.29, partition 8, PROCESS_LOCAL, 5563 bytes)
17/01/29 08:51:37,633 INFO TaskSetManager: Starting task 0.0 in stage 3.0 (TID 124, 10.1.2.182, partition 0, PROCESS_LOCAL, 5563 bytes)
17/01/29 08:51:37,633 INFO TaskSetManager: Starting task 1.0 in stage 3.0 (TID 125, 10.1.2.26, partition 1, PROCESS_LOCAL, 5563 bytes)
17/01/29 08:51:37,634 INFO TaskSetManager: Starting task 5.0 in stage 3.0 (TID 126, 10.1.2.194, partition 5, PROCESS_LOCAL, 5563 bytes)
17/01/29 08:51:37,634 INFO TaskSetManager: Starting task 14.0 in stage 3.0 (TID 127, 10.1.2.122, partition 14, PROCESS_LOCAL, 5563 bytes)
17/01/29 08:51:37,635 INFO TaskSetManager: Starting task 12.0 in stage 3.0 (TID 128, 10.1.2.111, partition 12, PROCESS_LOCAL, 5563 bytes)
17/01/29 08:51:37,635 INFO TaskSetManager: Starting task 15.0 in stage 3.0 (TID 129, 10.1.2.131, partition 15, PROCESS_LOCAL, 5563 bytes)
17/01/29 08:51:37,636 INFO TaskSetManager: Starting task 11.0 in stage 3.0 (TID 130, 10.1.2.27, partition 11, PROCESS_LOCAL, 5563 bytes)
17/01/29 08:51:37,636 INFO TaskSetManager: Starting task 16.0 in stage 3.0 (TID 131, 10.1.2.29, partition 16, PROCESS_LOCAL, 5563 bytes)
17/01/29 08:51:37,637 INFO TaskSetManager: Starting task 2.0 in stage 3.0 (TID 132, 10.1.2.182, partition 2, PROCESS_LOCAL, 5563 bytes)
17/01/29 08:51:37,637 INFO TaskSetManager: Starting task 9.0 in stage 3.0 (TID 133, 10.1.2.26, partition 9, PROCESS_LOCAL, 5563 bytes)
17/01/29 08:51:37,637 INFO TaskSetManager: Starting task 13.0 in stage 3.0 (TID 134, 10.1.2.194, partition 13, PROCESS_LOCAL, 5563 bytes)
17/01/29 08:51:37,638 INFO TaskSetManager: Starting task 22.0 in stage 3.0 (TID 135, 10.1.2.122, partition 22, PROCESS_LOCAL, 5563 bytes)
17/01/29 08:51:37,638 INFO TaskSetManager: Starting task 20.0 in stage 3.0 (TID 136, 10.1.2.111, partition 20, PROCESS_LOCAL, 5563 bytes)
17/01/29 08:51:37,640 INFO TaskSetManager: Starting task 23.0 in stage 3.0 (TID 137, 10.1.2.131, partition 23, PROCESS_LOCAL, 5563 bytes)
17/01/29 08:51:37,640 INFO TaskSetManager: Starting task 19.0 in stage 3.0 (TID 138, 10.1.2.27, partition 19, PROCESS_LOCAL, 5563 bytes)
17/01/29 08:51:37,641 INFO TaskSetManager: Starting task 24.0 in stage 3.0 (TID 139, 10.1.2.29, partition 24, PROCESS_LOCAL, 5563 bytes)
17/01/29 08:51:37,641 INFO TaskSetManager: Starting task 10.0 in stage 3.0 (TID 140, 10.1.2.182, partition 10, PROCESS_LOCAL, 5563 bytes)
17/01/29 08:51:37,642 INFO TaskSetManager: Starting task 17.0 in stage 3.0 (TID 141, 10.1.2.26, partition 17, PROCESS_LOCAL, 5563 bytes)
17/01/29 08:51:37,642 INFO TaskSetManager: Starting task 21.0 in stage 3.0 (TID 142, 10.1.2.194, partition 21, PROCESS_LOCAL, 5563 bytes)
17/01/29 08:51:37,645 INFO TaskSetManager: Starting task 30.0 in stage 3.0 (TID 143, 10.1.2.122, partition 30, PROCESS_LOCAL, 5563 bytes)
17/01/29 08:51:37,645 INFO TaskSetManager: Starting task 28.0 in stage 3.0 (TID 144, 10.1.2.111, partition 28, PROCESS_LOCAL, 5563 bytes)
17/01/29 08:51:37,646 INFO TaskSetManager: Starting task 31.0 in stage 3.0 (TID 145, 10.1.2.131, partition 31, PROCESS_LOCAL, 5563 bytes)
17/01/29 08:51:37,646 INFO TaskSetManager: Starting task 27.0 in stage 3.0 (TID 146, 10.1.2.27, partition 27, PROCESS_LOCAL, 5563 bytes)
17/01/29 08:51:37,647 INFO TaskSetManager: Starting task 43.0 in stage 3.0 (TID 147, 10.1.2.29, partition 43, PROCESS_LOCAL, 5563 bytes)
17/01/29 08:51:37,647 INFO TaskSetManager: Starting task 18.0 in stage 3.0 (TID 148, 10.1.2.182, partition 18, PROCESS_LOCAL, 5563 bytes)
17/01/29 08:51:37,647 INFO TaskSetManager: Starting task 25.0 in stage 3.0 (TID 149, 10.1.2.26, partition 25, PROCESS_LOCAL, 5563 bytes)
17/01/29 08:51:37,648 INFO TaskSetManager: Starting task 29.0 in stage 3.0 (TID 150, 10.1.2.194, partition 29, PROCESS_LOCAL, 5563 bytes)
17/01/29 08:51:37,648 INFO CoarseGrainedSchedulerBackend$DriverEndpoint: Launching task 119 on executor id: 2 hostname: 10.1.2.122.
17/01/29 08:51:37,649 INFO CoarseGrainedSchedulerBackend$DriverEndpoint: Launching task 127 on executor id: 2 hostname: 10.1.2.122.
17/01/29 08:51:37,649 INFO CoarseGrainedSchedulerBackend$DriverEndpoint: Launching task 135 on executor id: 2 hostname: 10.1.2.122.
17/01/29 08:51:37,649 INFO CoarseGrainedSchedulerBackend$DriverEndpoint: Launching task 143 on executor id: 2 hostname: 10.1.2.122.
17/01/29 08:51:37,649 INFO CoarseGrainedSchedulerBackend$DriverEndpoint: Launching task 120 on executor id: 6 hostname: 10.1.2.111.
17/01/29 08:51:37,650 INFO CoarseGrainedSchedulerBackend$DriverEndpoint: Launching task 128 on executor id: 6 hostname: 10.1.2.111.
17/01/29 08:51:37,650 INFO CoarseGrainedSchedulerBackend$DriverEndpoint: Launching task 136 on executor id: 6 hostname: 10.1.2.111.
17/01/29 08:51:37,650 INFO CoarseGrainedSchedulerBackend$DriverEndpoint: Launching task 144 on executor id: 6 hostname: 10.1.2.111.
17/01/29 08:51:37,650 INFO CoarseGrainedSchedulerBackend$DriverEndpoint: Launching task 121 on executor id: 1 hostname: 10.1.2.131.
17/01/29 08:51:37,651 INFO CoarseGrainedSchedulerBackend$DriverEndpoint: Launching task 129 on executor id: 1 hostname: 10.1.2.131.
17/01/29 08:51:37,652 INFO CoarseGrainedSchedulerBackend$DriverEndpoint: Launching task 137 on executor id: 1 hostname: 10.1.2.131.
17/01/29 08:51:37,652 INFO CoarseGrainedSchedulerBackend$DriverEndpoint: Launching task 145 on executor id: 1 hostname: 10.1.2.131.
17/01/29 08:51:37,653 INFO CoarseGrainedSchedulerBackend$DriverEndpoint: Launching task 122 on executor id: 4 hostname: 10.1.2.27.
17/01/29 08:51:37,653 INFO CoarseGrainedSchedulerBackend$DriverEndpoint: Launching task 130 on executor id: 4 hostname: 10.1.2.27.
17/01/29 08:51:37,653 INFO CoarseGrainedSchedulerBackend$DriverEndpoint: Launching task 138 on executor id: 4 hostname: 10.1.2.27.
17/01/29 08:51:37,654 INFO CoarseGrainedSchedulerBackend$DriverEndpoint: Launching task 146 on executor id: 4 hostname: 10.1.2.27.
17/01/29 08:51:37,654 INFO CoarseGrainedSchedulerBackend$DriverEndpoint: Launching task 123 on executor id: 0 hostname: 10.1.2.29.
17/01/29 08:51:37,654 INFO CoarseGrainedSchedulerBackend$DriverEndpoint: Launching task 131 on executor id: 0 hostname: 10.1.2.29.
17/01/29 08:51:37,656 INFO CoarseGrainedSchedulerBackend$DriverEndpoint: Launching task 139 on executor id: 0 hostname: 10.1.2.29.
17/01/29 08:51:37,656 INFO CoarseGrainedSchedulerBackend$DriverEndpoint: Launching task 147 on executor id: 0 hostname: 10.1.2.29.
17/01/29 08:51:37,656 INFO CoarseGrainedSchedulerBackend$DriverEndpoint: Launching task 124 on executor id: 3 hostname: 10.1.2.182.
17/01/29 08:51:37,656 INFO CoarseGrainedSchedulerBackend$DriverEndpoint: Launching task 132 on executor id: 3 hostname: 10.1.2.182.
17/01/29 08:51:37,657 INFO CoarseGrainedSchedulerBackend$DriverEndpoint: Launching task 140 on executor id: 3 hostname: 10.1.2.182.
17/01/29 08:51:37,657 INFO CoarseGrainedSchedulerBackend$DriverEndpoint: Launching task 148 on executor id: 3 hostname: 10.1.2.182.
17/01/29 08:51:37,657 INFO CoarseGrainedSchedulerBackend$DriverEndpoint: Launching task 125 on executor id: 7 hostname: 10.1.2.26.
17/01/29 08:51:37,657 INFO CoarseGrainedSchedulerBackend$DriverEndpoint: Launching task 133 on executor id: 7 hostname: 10.1.2.26.
17/01/29 08:51:37,658 INFO CoarseGrainedSchedulerBackend$DriverEndpoint: Launching task 141 on executor id: 7 hostname: 10.1.2.26.
17/01/29 08:51:37,658 INFO CoarseGrainedSchedulerBackend$DriverEndpoint: Launching task 149 on executor id: 7 hostname: 10.1.2.26.
17/01/29 08:51:37,658 INFO CoarseGrainedSchedulerBackend$DriverEndpoint: Launching task 126 on executor id: 5 hostname: 10.1.2.194.
17/01/29 08:51:37,659 INFO CoarseGrainedSchedulerBackend$DriverEndpoint: Launching task 134 on executor id: 5 hostname: 10.1.2.194.
17/01/29 08:51:37,659 INFO CoarseGrainedSchedulerBackend$DriverEndpoint: Launching task 142 on executor id: 5 hostname: 10.1.2.194.
17/01/29 08:51:37,660 INFO CoarseGrainedSchedulerBackend$DriverEndpoint: Launching task 150 on executor id: 5 hostname: 10.1.2.194.
17/01/29 08:51:37,677 INFO BlockManagerInfo: Added broadcast_5_piece0 in memory on 10.1.2.122:34160 (size: 3.7 KB, free: 1560.9 MB)
17/01/29 08:51:37,679 INFO BlockManagerInfo: Added broadcast_5_piece0 in memory on 10.1.2.29:40162 (size: 3.7 KB, free: 1768.1 MB)
17/01/29 08:51:37,685 INFO BlockManagerInfo: Added broadcast_5_piece0 in memory on 10.1.2.111:33151 (size: 3.7 KB, free: 1561.1 MB)
17/01/29 08:51:37,687 INFO BlockManagerInfo: Added broadcast_5_piece0 in memory on 10.1.2.27:36131 (size: 3.7 KB, free: 1561.0 MB)
17/01/29 08:51:37,688 INFO BlockManagerInfo: Added broadcast_5_piece0 in memory on 10.1.2.131:37424 (size: 3.7 KB, free: 1770.8 MB)
17/01/29 08:51:37,692 INFO BlockManagerInfo: Added broadcast_5_piece0 in memory on 10.1.2.194:35157 (size: 3.7 KB, free: 1560.7 MB)
17/01/29 08:51:37,706 INFO BlockManagerInfo: Added broadcast_5_piece0 in memory on 10.1.2.182:45671 (size: 3.7 KB, free: 1490.8 MB)
17/01/29 08:51:37,706 INFO BlockManagerInfo: Added broadcast_5_piece0 in memory on 10.1.2.26:36963 (size: 3.7 KB, free: 1561.1 MB)
17/01/29 08:51:37,972 INFO BlockManagerInfo: Added broadcast_4_piece0 in memory on 10.1.2.131:37424 (size: 153.0 B, free: 1770.8 MB)
17/01/29 08:51:37,977 INFO BlockManagerInfo: Added broadcast_4_piece0 in memory on 10.1.2.27:36131 (size: 153.0 B, free: 1561.0 MB)
17/01/29 08:51:37,978 INFO BlockManagerInfo: Added broadcast_4_piece0 in memory on 10.1.2.194:35157 (size: 153.0 B, free: 1560.7 MB)
17/01/29 08:51:37,995 INFO BlockManagerInfo: Added broadcast_4_piece0 in memory on 10.1.2.122:34160 (size: 153.0 B, free: 1560.9 MB)
17/01/29 08:51:37,999 INFO BlockManagerInfo: Added broadcast_4_piece0 in memory on 10.1.2.29:40162 (size: 153.0 B, free: 1768.1 MB)
17/01/29 08:51:38,003 INFO BlockManagerInfo: Added broadcast_4_piece0 in memory on 10.1.2.111:33151 (size: 153.0 B, free: 1561.1 MB)
17/01/29 08:51:38,025 INFO BlockManagerInfo: Added broadcast_4_piece0 in memory on 10.1.2.182:45671 (size: 153.0 B, free: 1490.8 MB)
17/01/29 08:51:38,037 INFO BlockManagerInfo: Added broadcast_4_piece0 in memory on 10.1.2.26:36963 (size: 153.0 B, free: 1561.1 MB)
17/01/29 08:51:38,173 INFO TaskSetManager: Starting task 37.0 in stage 3.0 (TID 151, 10.1.2.122, partition 37, PROCESS_LOCAL, 5563 bytes)
17/01/29 08:51:38,174 INFO CoarseGrainedSchedulerBackend$DriverEndpoint: Launching task 151 on executor id: 2 hostname: 10.1.2.122.
17/01/29 08:51:38,175 INFO TaskSetManager: Starting task 38.0 in stage 3.0 (TID 152, 10.1.2.122, partition 38, PROCESS_LOCAL, 5563 bytes)
17/01/29 08:51:38,175 INFO CoarseGrainedSchedulerBackend$DriverEndpoint: Launching task 152 on executor id: 2 hostname: 10.1.2.122.
17/01/29 08:51:38,176 INFO TaskSetManager: Starting task 39.0 in stage 3.0 (TID 153, 10.1.2.122, partition 39, PROCESS_LOCAL, 5563 bytes)
17/01/29 08:51:38,177 INFO CoarseGrainedSchedulerBackend$DriverEndpoint: Launching task 153 on executor id: 2 hostname: 10.1.2.122.
17/01/29 08:51:38,177 INFO TaskSetManager: Starting task 41.0 in stage 3.0 (TID 154, 10.1.2.122, partition 41, PROCESS_LOCAL, 5563 bytes)
17/01/29 08:51:38,177 INFO CoarseGrainedSchedulerBackend$DriverEndpoint: Launching task 154 on executor id: 2 hostname: 10.1.2.122.
17/01/29 08:51:38,178 INFO TaskSetManager: Finished task 14.0 in stage 3.0 (TID 127) in 544 ms on 10.1.2.122 (1/59)
17/01/29 08:51:38,180 INFO TaskSetManager: Finished task 6.0 in stage 3.0 (TID 119) in 551 ms on 10.1.2.122 (2/59)
17/01/29 08:51:38,181 INFO TaskSetManager: Finished task 22.0 in stage 3.0 (TID 135) in 543 ms on 10.1.2.122 (3/59)
17/01/29 08:51:38,181 INFO TaskSetManager: Finished task 30.0 in stage 3.0 (TID 143) in 539 ms on 10.1.2.122 (4/59)
17/01/29 08:51:38,182 INFO TaskSetManager: Starting task 57.0 in stage 3.0 (TID 155, 10.1.2.131, partition 57, PROCESS_LOCAL, 5563 bytes)
17/01/29 08:51:38,182 INFO CoarseGrainedSchedulerBackend$DriverEndpoint: Launching task 155 on executor id: 1 hostname: 10.1.2.131.
17/01/29 08:51:38,182 INFO TaskSetManager: Finished task 31.0 in stage 3.0 (TID 145) in 537 ms on 10.1.2.131 (5/59)
17/01/29 08:51:38,183 INFO TaskSetManager: Starting task 42.0 in stage 3.0 (TID 156, 10.1.2.111, partition 42, PROCESS_LOCAL, 5563 bytes)
17/01/29 08:51:38,183 INFO CoarseGrainedSchedulerBackend$DriverEndpoint: Launching task 156 on executor id: 6 hostname: 10.1.2.111.
17/01/29 08:51:38,183 INFO TaskSetManager: Finished task 28.0 in stage 3.0 (TID 144) in 538 ms on 10.1.2.111 (6/59)
17/01/29 08:51:38,185 INFO TaskSetManager: Starting task 47.0 in stage 3.0 (TID 157, 10.1.2.111, partition 47, PROCESS_LOCAL, 5563 bytes)
17/01/29 08:51:38,185 INFO CoarseGrainedSchedulerBackend$DriverEndpoint: Launching task 157 on executor id: 6 hostname: 10.1.2.111.
17/01/29 08:51:38,185 INFO TaskSetManager: Finished task 20.0 in stage 3.0 (TID 136) in 547 ms on 10.1.2.111 (7/59)
17/01/29 08:51:38,188 INFO TaskSetManager: Starting task 48.0 in stage 3.0 (TID 158, 10.1.2.111, partition 48, PROCESS_LOCAL, 5563 bytes)
17/01/29 08:51:38,188 INFO CoarseGrainedSchedulerBackend$DriverEndpoint: Launching task 158 on executor id: 6 hostname: 10.1.2.111.
17/01/29 08:51:38,188 INFO TaskSetManager: Finished task 4.0 in stage 3.0 (TID 120) in 558 ms on 10.1.2.111 (8/59)
17/01/29 08:51:38,189 INFO TaskSetManager: Finished task 15.0 in stage 3.0 (TID 129) in 554 ms on 10.1.2.131 (9/59)
17/01/29 08:51:38,190 INFO TaskSetManager: Starting task 50.0 in stage 3.0 (TID 159, 10.1.2.111, partition 50, PROCESS_LOCAL, 5563 bytes)
17/01/29 08:51:38,190 INFO CoarseGrainedSchedulerBackend$DriverEndpoint: Launching task 159 on executor id: 6 hostname: 10.1.2.111.
17/01/29 08:51:38,191 INFO TaskSetManager: Finished task 23.0 in stage 3.0 (TID 137) in 552 ms on 10.1.2.131 (10/59)
17/01/29 08:51:38,191 INFO TaskSetManager: Finished task 12.0 in stage 3.0 (TID 128) in 557 ms on 10.1.2.111 (11/59)
17/01/29 08:51:38,192 INFO TaskSetManager: Finished task 7.0 in stage 3.0 (TID 121) in 561 ms on 10.1.2.131 (12/59)
17/01/29 08:51:38,193 INFO TaskSetManager: Finished task 19.0 in stage 3.0 (TID 138) in 553 ms on 10.1.2.27 (13/59)
17/01/29 08:51:38,194 INFO TaskSetManager: Starting task 52.0 in stage 3.0 (TID 160, 10.1.2.27, partition 52, PROCESS_LOCAL, 5563 bytes)
17/01/29 08:51:38,194 INFO CoarseGrainedSchedulerBackend$DriverEndpoint: Launching task 160 on executor id: 4 hostname: 10.1.2.27.
17/01/29 08:51:38,195 INFO TaskSetManager: Starting task 53.0 in stage 3.0 (TID 161, 10.1.2.27, partition 53, PROCESS_LOCAL, 5563 bytes)
17/01/29 08:51:38,195 INFO CoarseGrainedSchedulerBackend$DriverEndpoint: Launching task 161 on executor id: 4 hostname: 10.1.2.27.
17/01/29 08:51:38,196 INFO TaskSetManager: Finished task 27.0 in stage 3.0 (TID 146) in 549 ms on 10.1.2.27 (14/59)
17/01/29 08:51:38,197 INFO TaskSetManager: Starting task 54.0 in stage 3.0 (TID 162, 10.1.2.27, partition 54, PROCESS_LOCAL, 5563 bytes)
17/01/29 08:51:38,197 INFO CoarseGrainedSchedulerBackend$DriverEndpoint: Launching task 162 on executor id: 4 hostname: 10.1.2.27.
17/01/29 08:51:38,197 INFO TaskSetManager: Finished task 3.0 in stage 3.0 (TID 122) in 566 ms on 10.1.2.27 (15/59)
17/01/29 08:51:38,199 INFO TaskSetManager: Starting task 55.0 in stage 3.0 (TID 163, 10.1.2.27, partition 55, PROCESS_LOCAL, 5563 bytes)
17/01/29 08:51:38,199 INFO CoarseGrainedSchedulerBackend$DriverEndpoint: Launching task 163 on executor id: 4 hostname: 10.1.2.27.
17/01/29 08:51:38,203 INFO TaskSetManager: Finished task 11.0 in stage 3.0 (TID 130) in 568 ms on 10.1.2.27 (16/59)
17/01/29 08:51:38,204 INFO TaskSetManager: Starting task 36.0 in stage 3.0 (TID 164, 10.1.2.194, partition 36, PROCESS_LOCAL, 5563 bytes)
17/01/29 08:51:38,204 INFO CoarseGrainedSchedulerBackend$DriverEndpoint: Launching task 164 on executor id: 5 hostname: 10.1.2.194.
17/01/29 08:51:38,204 INFO TaskSetManager: Finished task 5.0 in stage 3.0 (TID 126) in 571 ms on 10.1.2.194 (17/59)
17/01/29 08:51:38,205 INFO TaskSetManager: Starting task 40.0 in stage 3.0 (TID 165, 10.1.2.194, partition 40, PROCESS_LOCAL, 5563 bytes)
17/01/29 08:51:38,205 INFO CoarseGrainedSchedulerBackend$DriverEndpoint: Launching task 165 on executor id: 5 hostname: 10.1.2.194.
17/01/29 08:51:38,205 INFO TaskSetManager: Finished task 13.0 in stage 3.0 (TID 134) in 568 ms on 10.1.2.194 (18/59)
17/01/29 08:51:38,206 INFO TaskSetManager: Finished task 29.0 in stage 3.0 (TID 150) in 558 ms on 10.1.2.194 (19/59)
17/01/29 08:51:38,207 INFO TaskSetManager: Starting task 44.0 in stage 3.0 (TID 166, 10.1.2.194, partition 44, PROCESS_LOCAL, 5563 bytes)
17/01/29 08:51:38,208 INFO CoarseGrainedSchedulerBackend$DriverEndpoint: Launching task 166 on executor id: 5 hostname: 10.1.2.194.
17/01/29 08:51:38,209 INFO TaskSetManager: Finished task 21.0 in stage 3.0 (TID 142) in 566 ms on 10.1.2.194 (20/59)
17/01/29 08:51:38,210 INFO TaskSetManager: Starting task 45.0 in stage 3.0 (TID 167, 10.1.2.194, partition 45, PROCESS_LOCAL, 5563 bytes)
17/01/29 08:51:38,210 INFO CoarseGrainedSchedulerBackend$DriverEndpoint: Launching task 167 on executor id: 5 hostname: 10.1.2.194.
17/01/29 08:51:38,211 INFO TaskSetManager: Starting task 58.0 in stage 3.0 (TID 168, 10.1.2.29, partition 58, PROCESS_LOCAL, 5563 bytes)
17/01/29 08:51:38,212 INFO CoarseGrainedSchedulerBackend$DriverEndpoint: Launching task 168 on executor id: 0 hostname: 10.1.2.29.
17/01/29 08:51:38,212 INFO TaskSetManager: Finished task 8.0 in stage 3.0 (TID 123) in 580 ms on 10.1.2.29 (21/59)
17/01/29 08:51:38,213 INFO TaskSetManager: Finished task 24.0 in stage 3.0 (TID 139) in 573 ms on 10.1.2.29 (22/59)
17/01/29 08:51:38,214 INFO TaskSetManager: Finished task 43.0 in stage 3.0 (TID 147) in 568 ms on 10.1.2.29 (23/59)
17/01/29 08:51:38,215 INFO TaskSetManager: Finished task 16.0 in stage 3.0 (TID 131) in 579 ms on 10.1.2.29 (24/59)
17/01/29 08:51:38,216 INFO TaskSetManager: Starting task 26.0 in stage 3.0 (TID 169, 10.1.2.182, partition 26, PROCESS_LOCAL, 5563 bytes)
17/01/29 08:51:38,216 INFO CoarseGrainedSchedulerBackend$DriverEndpoint: Launching task 169 on executor id: 3 hostname: 10.1.2.182.
17/01/29 08:51:38,217 INFO TaskSetManager: Starting task 32.0 in stage 3.0 (TID 170, 10.1.2.182, partition 32, PROCESS_LOCAL, 5563 bytes)
17/01/29 08:51:38,217 INFO CoarseGrainedSchedulerBackend$DriverEndpoint: Launching task 170 on executor id: 3 hostname: 10.1.2.182.
17/01/29 08:51:38,217 INFO TaskSetManager: Finished task 18.0 in stage 3.0 (TID 148) in 570 ms on 10.1.2.182 (25/59)
17/01/29 08:51:38,218 INFO TaskSetManager: Finished task 0.0 in stage 3.0 (TID 124) in 585 ms on 10.1.2.182 (26/59)
17/01/29 08:51:38,221 INFO TaskSetManager: Starting task 33.0 in stage 3.0 (TID 171, 10.1.2.182, partition 33, PROCESS_LOCAL, 5563 bytes)
17/01/29 08:51:38,221 INFO CoarseGrainedSchedulerBackend$DriverEndpoint: Launching task 171 on executor id: 3 hostname: 10.1.2.182.
17/01/29 08:51:38,221 INFO TaskSetManager: Finished task 10.0 in stage 3.0 (TID 140) in 580 ms on 10.1.2.182 (27/59)
17/01/29 08:51:38,223 INFO TaskSetManager: Starting task 34.0 in stage 3.0 (TID 172, 10.1.2.182, partition 34, PROCESS_LOCAL, 5563 bytes)
17/01/29 08:51:38,223 INFO CoarseGrainedSchedulerBackend$DriverEndpoint: Launching task 172 on executor id: 3 hostname: 10.1.2.182.
17/01/29 08:51:38,223 INFO TaskSetManager: Finished task 2.0 in stage 3.0 (TID 132) in 587 ms on 10.1.2.182 (28/59)
17/01/29 08:51:38,225 INFO TaskSetManager: Finished task 17.0 in stage 3.0 (TID 141) in 584 ms on 10.1.2.26 (29/59)
17/01/29 08:51:38,226 INFO TaskSetManager: Starting task 46.0 in stage 3.0 (TID 173, 10.1.2.26, partition 46, PROCESS_LOCAL, 5563 bytes)
17/01/29 08:51:38,226 INFO CoarseGrainedSchedulerBackend$DriverEndpoint: Launching task 173 on executor id: 7 hostname: 10.1.2.26.
17/01/29 08:51:38,227 INFO TaskSetManager: Starting task 49.0 in stage 3.0 (TID 174, 10.1.2.26, partition 49, PROCESS_LOCAL, 5563 bytes)
17/01/29 08:51:38,227 INFO CoarseGrainedSchedulerBackend$DriverEndpoint: Launching task 174 on executor id: 7 hostname: 10.1.2.26.
17/01/29 08:51:38,227 INFO TaskSetManager: Finished task 9.0 in stage 3.0 (TID 133) in 590 ms on 10.1.2.26 (30/59)
17/01/29 08:51:38,228 INFO TaskSetManager: Starting task 51.0 in stage 3.0 (TID 175, 10.1.2.26, partition 51, PROCESS_LOCAL, 5563 bytes)
17/01/29 08:51:38,229 INFO CoarseGrainedSchedulerBackend$DriverEndpoint: Launching task 175 on executor id: 7 hostname: 10.1.2.26.
17/01/29 08:51:38,229 INFO TaskSetManager: Finished task 25.0 in stage 3.0 (TID 149) in 582 ms on 10.1.2.26 (31/59)
17/01/29 08:51:38,230 INFO TaskSetManager: Starting task 56.0 in stage 3.0 (TID 176, 10.1.2.26, partition 56, PROCESS_LOCAL, 5563 bytes)
17/01/29 08:51:38,231 INFO CoarseGrainedSchedulerBackend$DriverEndpoint: Launching task 176 on executor id: 7 hostname: 10.1.2.26.
17/01/29 08:51:38,231 INFO TaskSetManager: Finished task 1.0 in stage 3.0 (TID 125) in 598 ms on 10.1.2.26 (32/59)
17/01/29 08:51:38,257 INFO TaskSetManager: Finished task 57.0 in stage 3.0 (TID 155) in 76 ms on 10.1.2.131 (33/59)
17/01/29 08:51:38,264 INFO TaskSetManager: Finished task 37.0 in stage 3.0 (TID 151) in 92 ms on 10.1.2.122 (34/59)
17/01/29 08:51:38,268 INFO TaskSetManager: Finished task 42.0 in stage 3.0 (TID 156) in 86 ms on 10.1.2.111 (35/59)
17/01/29 08:51:38,269 INFO TaskSetManager: Finished task 38.0 in stage 3.0 (TID 152) in 95 ms on 10.1.2.122 (36/59)
17/01/29 08:51:38,270 INFO TaskSetManager: Finished task 47.0 in stage 3.0 (TID 157) in 86 ms on 10.1.2.111 (37/59)
17/01/29 08:51:38,271 INFO TaskSetManager: Finished task 50.0 in stage 3.0 (TID 159) in 81 ms on 10.1.2.111 (38/59)
17/01/29 08:51:38,276 INFO TaskSetManager: Finished task 41.0 in stage 3.0 (TID 154) in 98 ms on 10.1.2.122 (39/59)
17/01/29 08:51:38,280 INFO TaskSetManager: Finished task 48.0 in stage 3.0 (TID 158) in 92 ms on 10.1.2.111 (40/59)
17/01/29 08:51:38,284 INFO TaskSetManager: Finished task 39.0 in stage 3.0 (TID 153) in 108 ms on 10.1.2.122 (41/59)
17/01/29 08:51:38,290 INFO TaskSetManager: Finished task 55.0 in stage 3.0 (TID 163) in 91 ms on 10.1.2.27 (42/59)
17/01/29 08:51:38,292 INFO TaskSetManager: Finished task 58.0 in stage 3.0 (TID 168) in 81 ms on 10.1.2.29 (43/59)
17/01/29 08:51:38,292 INFO TaskSetManager: Finished task 40.0 in stage 3.0 (TID 165) in 88 ms on 10.1.2.194 (44/59)
17/01/29 08:51:38,293 INFO TaskSetManager: Finished task 36.0 in stage 3.0 (TID 164) in 90 ms on 10.1.2.194 (45/59)
17/01/29 08:51:38,295 INFO TaskSetManager: Finished task 53.0 in stage 3.0 (TID 161) in 101 ms on 10.1.2.27 (46/59)
17/01/29 08:51:38,298 INFO TaskSetManager: Finished task 52.0 in stage 3.0 (TID 160) in 105 ms on 10.1.2.27 (47/59)
17/01/29 08:51:38,304 INFO TaskSetManager: Finished task 44.0 in stage 3.0 (TID 166) in 97 ms on 10.1.2.194 (48/59)
17/01/29 08:51:38,306 INFO TaskSetManager: Finished task 45.0 in stage 3.0 (TID 167) in 95 ms on 10.1.2.194 (49/59)
17/01/29 08:51:38,309 INFO TaskSetManager: Finished task 54.0 in stage 3.0 (TID 162) in 113 ms on 10.1.2.27 (50/59)
