Using properties file: /home/ubuntu/spark-2.0.0/conf/spark-defaults.conf
Adding default property: spark.executor.extraJavaOptions=-XX:+PrintGCDetails -XX:+PrintGCTimeStamps -Xms11500m -Dlog4j.configuration=file:///home/ubuntu/spark-2.0.0/conf/log4j.properties
Adding default property: spark.driver.extraJavaOptions=-XX:+PrintGCDetails -XX:+PrintGCTimeStamps -Xms11500m -Dlog4j.configuration=file:///home/ubuntu/spark-2.0.0/conf/log4j.properties
Parsed arguments:
  master                  spark://euca-10-1-2-238:7077
  deployMode              client
  executorMemory          11500m
  executorCores           null
  totalExecutorCores      null
  propertiesFile          /home/ubuntu/spark-2.0.0/conf/spark-defaults.conf
  driverMemory            11500m
  driverCores             null
  driverExtraClassPath    null
  driverExtraLibraryPath  null
  driverExtraJavaOptions  -XX:+PrintGCDetails -XX:+PrintGCTimeStamps -Xms11500m -Dlog4j.configuration=file:///home/ubuntu/spark-2.0.0/conf/log4j.properties
  supervise               false
  queue                   null
  numExecutors            16
  files                   null
  pyFiles                 null
  archives                null
  mainClass               LogRegExplicitParallelism
  primaryResource         file:///home/ubuntu/jars/log-reg-explicit-parallelism_2.11-1.0.jar
  name                    LogRegExplicitParallelism
  childArgs               [cluster 3231961 euca-10-1-2-238 9000 url_combined_0_exp 5 64]
  jars                    null
  packages                null
  packagesExclusions      null
  repositories            null
  verbose                 true

Spark properties used, including those specified through
 --conf and those from the properties file /home/ubuntu/spark-2.0.0/conf/spark-defaults.conf:
  spark.default.parallelism -> 64
  spark.driver.memory -> 11500m
  spark.executor.extraJavaOptions -> -XX:+PrintGCDetails -XX:+PrintGCTimeStamps -Xms11500m -Dlog4j.configuration=file:///home/ubuntu/spark-2.0.0/conf/log4j.properties
  spark.driver.extraJavaOptions -> -XX:+PrintGCDetails -XX:+PrintGCTimeStamps -Xms11500m -Dlog4j.configuration=file:///home/ubuntu/spark-2.0.0/conf/log4j.properties
  spark.shuffle.spill -> false
  spark.driver.maxResultSize -> 5g

    
Main class:
LogRegExplicitParallelism
Arguments:
cluster
3231961
euca-10-1-2-238
9000
url_combined_0_exp
5
64
System properties:
spark.default.parallelism -> 64
spark.executor.memory -> 11500m
spark.driver.memory -> 11500m
SPARK_SUBMIT -> true
spark.executor.extraJavaOptions -> -XX:+PrintGCDetails -XX:+PrintGCTimeStamps -Xms11500m -Dlog4j.configuration=file:///home/ubuntu/spark-2.0.0/conf/log4j.properties
spark.app.name -> LogRegExplicitParallelism
spark.shuffle.spill -> false
spark.driver.extraJavaOptions -> -XX:+PrintGCDetails -XX:+PrintGCTimeStamps -Xms11500m -Dlog4j.configuration=file:///home/ubuntu/spark-2.0.0/conf/log4j.properties
spark.jars -> file:///home/ubuntu/jars/log-reg-explicit-parallelism_2.11-1.0.jar
spark.submit.deployMode -> client
spark.driver.maxResultSize -> 5g
spark.master -> spark://euca-10-1-2-238:7077
Classpath elements:
file:///home/ubuntu/jars/log-reg-explicit-parallelism_2.11-1.0.jar


17/02/09 09:48:10,973 INFO SparkContext: Running Spark version 2.0.0
17/02/09 09:48:11,302 WARN NativeCodeLoader: Unable to load native-hadoop library for your platform... using builtin-java classes where applicable
17/02/09 09:48:11,456 INFO SecurityManager: Changing view acls to: ubuntu
17/02/09 09:48:11,457 INFO SecurityManager: Changing modify acls to: ubuntu
17/02/09 09:48:11,457 INFO SecurityManager: Changing view acls groups to: 
17/02/09 09:48:11,458 INFO SecurityManager: Changing modify acls groups to: 
17/02/09 09:48:11,459 INFO SecurityManager: SecurityManager: authentication disabled; ui acls disabled; users  with view permissions: Set(ubuntu); groups with view permissions: Set(); users  with modify permissions: Set(ubuntu); groups with modify permissions: Set()
17/02/09 09:48:11,764 INFO Utils: Successfully started service 'sparkDriver' on port 44587.
17/02/09 09:48:11,782 INFO SparkEnv: Registering MapOutputTracker
17/02/09 09:48:11,787 WARN SortShuffleManager: spark.shuffle.spill was set to false, but this configuration is ignored as of Spark 1.6+. Shuffle will continue to spill to disk when necessary.
17/02/09 09:48:11,798 INFO SparkEnv: Registering BlockManagerMaster
17/02/09 09:48:11,811 INFO DiskBlockManager: Created local directory at /tmp/blockmgr-676bea50-81a9-4b16-8d97-46582d3e03c8
17/02/09 09:48:11,829 INFO MemoryStore: MemoryStore started with capacity 6.3 GB
17/02/09 09:48:11,881 INFO SparkEnv: Registering OutputCommitCoordinator
17/02/09 09:48:12,073 INFO Utils: Successfully started service 'SparkUI' on port 4040.
17/02/09 09:48:12,075 INFO SparkUI: Bound SparkUI to 10.1.2.238, and started at http://10.1.2.238:4040
17/02/09 09:48:12,106 INFO SparkContext: Added JAR file:///home/ubuntu/jars/log-reg-explicit-parallelism_2.11-1.0.jar at spark://10.1.2.238:44587/jars/log-reg-explicit-parallelism_2.11-1.0.jar with timestamp 1486633692106
17/02/09 09:48:12,181 INFO StandaloneAppClient$ClientEndpoint: Connecting to master spark://euca-10-1-2-238:7077...
17/02/09 09:48:12,241 INFO TransportClientFactory: Successfully created connection to euca-10-1-2-238/10.1.2.238:7077 after 22 ms (0 ms spent in bootstraps)
17/02/09 09:48:12,329 INFO StandaloneSchedulerBackend: Connected to Spark cluster with app ID app-20170209094812-0000
17/02/09 09:48:12,334 INFO Utils: Successfully started service 'org.apache.spark.network.netty.NettyBlockTransferService' on port 40539.
17/02/09 09:48:12,335 INFO NettyBlockTransferService: Server created on 10.1.2.238:40539
17/02/09 09:48:12,336 INFO BlockManagerMaster: Registering BlockManager BlockManagerId(driver, 10.1.2.238, 40539)
17/02/09 09:48:12,351 INFO StandaloneAppClient$ClientEndpoint: Executor added: app-20170209094812-0000/0 on worker-20170209094734-10.1.2.157-41117 (10.1.2.157:41117) with 4 cores
17/02/09 09:48:12,351 INFO StandaloneSchedulerBackend: Granted executor ID app-20170209094812-0000/0 on hostPort 10.1.2.157:41117 with 4 cores, 11.2 GB RAM
17/02/09 09:48:12,352 INFO BlockManagerMasterEndpoint: Registering block manager 10.1.2.238:40539 with 6.3 GB RAM, BlockManagerId(driver, 10.1.2.238, 40539)
17/02/09 09:48:12,352 INFO StandaloneAppClient$ClientEndpoint: Executor added: app-20170209094812-0000/1 on worker-20170209094735-10.1.2.95-39134 (10.1.2.95:39134) with 4 cores
17/02/09 09:48:12,352 INFO StandaloneSchedulerBackend: Granted executor ID app-20170209094812-0000/1 on hostPort 10.1.2.95:39134 with 4 cores, 11.2 GB RAM
17/02/09 09:48:12,353 INFO StandaloneAppClient$ClientEndpoint: Executor added: app-20170209094812-0000/2 on worker-20170209094735-10.1.2.146-37385 (10.1.2.146:37385) with 4 cores
17/02/09 09:48:12,354 INFO StandaloneSchedulerBackend: Granted executor ID app-20170209094812-0000/2 on hostPort 10.1.2.146:37385 with 4 cores, 11.2 GB RAM
17/02/09 09:48:12,355 INFO StandaloneAppClient$ClientEndpoint: Executor added: app-20170209094812-0000/3 on worker-20170209094735-10.1.2.191-35787 (10.1.2.191:35787) with 4 cores
17/02/09 09:48:12,355 INFO StandaloneSchedulerBackend: Granted executor ID app-20170209094812-0000/3 on hostPort 10.1.2.191:35787 with 4 cores, 11.2 GB RAM
17/02/09 09:48:12,356 INFO BlockManagerMaster: Registered BlockManager BlockManagerId(driver, 10.1.2.238, 40539)
17/02/09 09:48:12,357 INFO StandaloneAppClient$ClientEndpoint: Executor added: app-20170209094812-0000/4 on worker-20170209094735-10.1.2.181-46192 (10.1.2.181:46192) with 4 cores
17/02/09 09:48:12,358 INFO StandaloneSchedulerBackend: Granted executor ID app-20170209094812-0000/4 on hostPort 10.1.2.181:46192 with 4 cores, 11.2 GB RAM
17/02/09 09:48:12,360 INFO StandaloneAppClient$ClientEndpoint: Executor added: app-20170209094812-0000/5 on worker-20170209094734-10.1.2.129-34390 (10.1.2.129:34390) with 4 cores
17/02/09 09:48:12,360 INFO StandaloneSchedulerBackend: Granted executor ID app-20170209094812-0000/5 on hostPort 10.1.2.129:34390 with 4 cores, 11.2 GB RAM
17/02/09 09:48:12,363 INFO StandaloneAppClient$ClientEndpoint: Executor added: app-20170209094812-0000/6 on worker-20170209094735-10.1.2.124-36096 (10.1.2.124:36096) with 4 cores
17/02/09 09:48:12,364 INFO StandaloneSchedulerBackend: Granted executor ID app-20170209094812-0000/6 on hostPort 10.1.2.124:36096 with 4 cores, 11.2 GB RAM
17/02/09 09:48:12,365 INFO StandaloneAppClient$ClientEndpoint: Executor added: app-20170209094812-0000/7 on worker-20170209094735-10.1.2.85-38408 (10.1.2.85:38408) with 4 cores
17/02/09 09:48:12,365 INFO StandaloneSchedulerBackend: Granted executor ID app-20170209094812-0000/7 on hostPort 10.1.2.85:38408 with 4 cores, 11.2 GB RAM
17/02/09 09:48:12,366 INFO StandaloneAppClient$ClientEndpoint: Executor added: app-20170209094812-0000/8 on worker-20170209094735-10.1.2.248-46383 (10.1.2.248:46383) with 4 cores
17/02/09 09:48:12,368 INFO StandaloneSchedulerBackend: Granted executor ID app-20170209094812-0000/8 on hostPort 10.1.2.248:46383 with 4 cores, 11.2 GB RAM
17/02/09 09:48:12,368 INFO StandaloneAppClient$ClientEndpoint: Executor added: app-20170209094812-0000/9 on worker-20170209094735-10.1.2.174-46231 (10.1.2.174:46231) with 4 cores
17/02/09 09:48:12,369 INFO StandaloneSchedulerBackend: Granted executor ID app-20170209094812-0000/9 on hostPort 10.1.2.174:46231 with 4 cores, 11.2 GB RAM
17/02/09 09:48:12,369 INFO StandaloneAppClient$ClientEndpoint: Executor added: app-20170209094812-0000/10 on worker-20170209094735-10.1.2.122-41079 (10.1.2.122:41079) with 4 cores
17/02/09 09:48:12,369 INFO StandaloneSchedulerBackend: Granted executor ID app-20170209094812-0000/10 on hostPort 10.1.2.122:41079 with 4 cores, 11.2 GB RAM
17/02/09 09:48:12,370 INFO StandaloneAppClient$ClientEndpoint: Executor added: app-20170209094812-0000/11 on worker-20170209094734-10.1.2.138-43338 (10.1.2.138:43338) with 4 cores
17/02/09 09:48:12,370 INFO StandaloneSchedulerBackend: Granted executor ID app-20170209094812-0000/11 on hostPort 10.1.2.138:43338 with 4 cores, 11.2 GB RAM
17/02/09 09:48:12,375 INFO StandaloneAppClient$ClientEndpoint: Executor added: app-20170209094812-0000/12 on worker-20170209094735-10.1.2.219-41098 (10.1.2.219:41098) with 4 cores
17/02/09 09:48:12,375 INFO StandaloneSchedulerBackend: Granted executor ID app-20170209094812-0000/12 on hostPort 10.1.2.219:41098 with 4 cores, 11.2 GB RAM
17/02/09 09:48:12,376 INFO StandaloneAppClient$ClientEndpoint: Executor added: app-20170209094812-0000/13 on worker-20170209094735-10.1.2.69-46361 (10.1.2.69:46361) with 4 cores
17/02/09 09:48:12,376 INFO StandaloneSchedulerBackend: Granted executor ID app-20170209094812-0000/13 on hostPort 10.1.2.69:46361 with 4 cores, 11.2 GB RAM
17/02/09 09:48:12,376 INFO StandaloneAppClient$ClientEndpoint: Executor added: app-20170209094812-0000/14 on worker-20170209094735-10.1.2.63-37916 (10.1.2.63:37916) with 4 cores
17/02/09 09:48:12,376 INFO StandaloneSchedulerBackend: Granted executor ID app-20170209094812-0000/14 on hostPort 10.1.2.63:37916 with 4 cores, 11.2 GB RAM
17/02/09 09:48:12,377 INFO StandaloneAppClient$ClientEndpoint: Executor added: app-20170209094812-0000/15 on worker-20170209094735-10.1.2.25-46253 (10.1.2.25:46253) with 4 cores
17/02/09 09:48:12,377 INFO StandaloneSchedulerBackend: Granted executor ID app-20170209094812-0000/15 on hostPort 10.1.2.25:46253 with 4 cores, 11.2 GB RAM
17/02/09 09:48:12,416 INFO StandaloneAppClient$ClientEndpoint: Executor updated: app-20170209094812-0000/3 is now RUNNING
17/02/09 09:48:12,421 INFO StandaloneAppClient$ClientEndpoint: Executor updated: app-20170209094812-0000/6 is now RUNNING
17/02/09 09:48:12,425 INFO StandaloneAppClient$ClientEndpoint: Executor updated: app-20170209094812-0000/4 is now RUNNING
17/02/09 09:48:12,428 INFO StandaloneAppClient$ClientEndpoint: Executor updated: app-20170209094812-0000/7 is now RUNNING
17/02/09 09:48:12,431 INFO StandaloneAppClient$ClientEndpoint: Executor updated: app-20170209094812-0000/1 is now RUNNING
17/02/09 09:48:12,434 INFO StandaloneAppClient$ClientEndpoint: Executor updated: app-20170209094812-0000/0 is now RUNNING
17/02/09 09:48:12,437 INFO StandaloneAppClient$ClientEndpoint: Executor updated: app-20170209094812-0000/11 is now RUNNING
17/02/09 09:48:12,441 INFO StandaloneAppClient$ClientEndpoint: Executor updated: app-20170209094812-0000/10 is now RUNNING
17/02/09 09:48:12,444 INFO StandaloneAppClient$ClientEndpoint: Executor updated: app-20170209094812-0000/2 is now RUNNING
17/02/09 09:48:12,450 INFO StandaloneAppClient$ClientEndpoint: Executor updated: app-20170209094812-0000/9 is now RUNNING
17/02/09 09:48:12,454 INFO StandaloneAppClient$ClientEndpoint: Executor updated: app-20170209094812-0000/8 is now RUNNING
17/02/09 09:48:12,456 INFO StandaloneAppClient$ClientEndpoint: Executor updated: app-20170209094812-0000/12 is now RUNNING
17/02/09 09:48:12,459 INFO StandaloneAppClient$ClientEndpoint: Executor updated: app-20170209094812-0000/5 is now RUNNING
17/02/09 09:48:12,461 INFO StandaloneAppClient$ClientEndpoint: Executor updated: app-20170209094812-0000/14 is now RUNNING
17/02/09 09:48:12,463 INFO StandaloneAppClient$ClientEndpoint: Executor updated: app-20170209094812-0000/15 is now RUNNING
17/02/09 09:48:12,465 INFO StandaloneAppClient$ClientEndpoint: Executor updated: app-20170209094812-0000/13 is now RUNNING
17/02/09 09:48:12,566 INFO StandaloneSchedulerBackend: SchedulerBackend is ready for scheduling beginning after reached minRegisteredResourcesRatio: 0.0
17/02/09 09:48:12,980 INFO MemoryStore: Block broadcast_0 stored as values in memory (estimated size 130.8 KB, free 6.3 GB)
17/02/09 09:48:13,048 INFO MemoryStore: Block broadcast_0_piece0 stored as bytes in memory (estimated size 16.5 KB, free 6.3 GB)
17/02/09 09:48:13,050 INFO BlockManagerInfo: Added broadcast_0_piece0 in memory on 10.1.2.238:40539 (size: 16.5 KB, free: 6.3 GB)
17/02/09 09:48:13,057 INFO SparkContext: Created broadcast 0 from textFile at MLUtils.scala:99
17/02/09 09:48:13,752 INFO FileInputFormat: Total input paths to process : 1
17/02/09 09:48:13,790 INFO NetworkTopology: Adding a new node: /default-rack/10.1.2.63:50010
17/02/09 09:48:13,790 INFO NetworkTopology: Adding a new node: /default-rack/10.1.2.181:50010
17/02/09 09:48:13,791 INFO NetworkTopology: Adding a new node: /default-rack/10.1.2.124:50010
17/02/09 09:48:13,791 INFO NetworkTopology: Adding a new node: /default-rack/10.1.2.191:50010
17/02/09 09:48:13,791 INFO NetworkTopology: Adding a new node: /default-rack/10.1.2.146:50010
17/02/09 09:48:13,792 INFO NetworkTopology: Adding a new node: /default-rack/10.1.2.122:50010
17/02/09 09:48:13,792 INFO NetworkTopology: Adding a new node: /default-rack/10.1.2.174:50010
17/02/09 09:48:13,792 INFO NetworkTopology: Adding a new node: /default-rack/10.1.2.25:50010
17/02/09 09:48:13,793 INFO NetworkTopology: Adding a new node: /default-rack/10.1.2.219:50010
17/02/09 09:48:13,793 INFO NetworkTopology: Adding a new node: /default-rack/10.1.2.138:50010
17/02/09 09:48:13,793 INFO NetworkTopology: Adding a new node: /default-rack/10.1.2.248:50010
17/02/09 09:48:13,793 INFO NetworkTopology: Adding a new node: /default-rack/10.1.2.157:50010
17/02/09 09:48:13,793 INFO NetworkTopology: Adding a new node: /default-rack/10.1.2.69:50010
17/02/09 09:48:13,794 INFO NetworkTopology: Adding a new node: /default-rack/10.1.2.129:50010
17/02/09 09:48:13,794 INFO NetworkTopology: Adding a new node: /default-rack/10.1.2.95:50010
17/02/09 09:48:13,840 INFO SparkContext: Starting job: first at GeneralizedLinearAlgorithm.scala:246
17/02/09 09:48:13,852 INFO DAGScheduler: Got job 0 (first at GeneralizedLinearAlgorithm.scala:246) with 1 output partitions
17/02/09 09:48:13,853 INFO DAGScheduler: Final stage: ResultStage 0 (first at GeneralizedLinearAlgorithm.scala:246)
17/02/09 09:48:13,853 INFO DAGScheduler: Parents of final stage: List()
17/02/09 09:48:13,861 INFO DAGScheduler: Missing parents: List()
17/02/09 09:48:13,875 INFO DAGScheduler: Submitting ResultStage 0 (MapPartitionsRDD[6] at map at GeneralizedLinearAlgorithm.scala:246), which has no missing parents
17/02/09 09:48:13,900 INFO MemoryStore: Block broadcast_1 stored as values in memory (estimated size 4.2 KB, free 6.3 GB)
17/02/09 09:48:13,903 INFO MemoryStore: Block broadcast_1_piece0 stored as bytes in memory (estimated size 2.4 KB, free 6.3 GB)
17/02/09 09:48:13,904 INFO BlockManagerInfo: Added broadcast_1_piece0 in memory on 10.1.2.238:40539 (size: 2.4 KB, free: 6.3 GB)
17/02/09 09:48:13,905 INFO SparkContext: Created broadcast 1 from broadcast at DAGScheduler.scala:1012
17/02/09 09:48:13,908 INFO DAGScheduler: Submitting 1 missing tasks from ResultStage 0 (MapPartitionsRDD[6] at map at GeneralizedLinearAlgorithm.scala:246)
17/02/09 09:48:13,910 INFO TaskSchedulerImpl: Adding task set 0.0 with 1 tasks
17/02/09 09:48:17,298 INFO CoarseGrainedSchedulerBackend$DriverEndpoint: Registered executor NettyRpcEndpointRef(null) (10.1.2.25:36066) with ID 15
17/02/09 09:48:17,330 INFO TaskSetManager: Starting task 0.0 in stage 0.0 (TID 0, 10.1.2.25, partition 0, ANY, 5463 bytes)
17/02/09 09:48:17,337 INFO CoarseGrainedSchedulerBackend$DriverEndpoint: Launching task 0 on executor id: 15 hostname: 10.1.2.25.
17/02/09 09:48:17,339 INFO CoarseGrainedSchedulerBackend$DriverEndpoint: Registered executor NettyRpcEndpointRef(null) (10.1.2.124:44446) with ID 6
17/02/09 09:48:17,351 INFO BlockManagerMasterEndpoint: Registering block manager 10.1.2.25:39678 with 6.3 GB RAM, BlockManagerId(15, 10.1.2.25, 39678)
17/02/09 09:48:17,393 INFO CoarseGrainedSchedulerBackend$DriverEndpoint: Registered executor NettyRpcEndpointRef(null) (10.1.2.181:58304) with ID 4
17/02/09 09:48:17,399 INFO BlockManagerMasterEndpoint: Registering block manager 10.1.2.124:34192 with 6.3 GB RAM, BlockManagerId(6, 10.1.2.124, 34192)
17/02/09 09:48:17,418 INFO CoarseGrainedSchedulerBackend$DriverEndpoint: Registered executor NettyRpcEndpointRef(null) (10.1.2.174:41762) with ID 9
17/02/09 09:48:17,429 INFO CoarseGrainedSchedulerBackend$DriverEndpoint: Registered executor NettyRpcEndpointRef(null) (10.1.2.191:36020) with ID 3
17/02/09 09:48:17,431 INFO CoarseGrainedSchedulerBackend$DriverEndpoint: Registered executor NettyRpcEndpointRef(null) (10.1.2.95:59410) with ID 1
17/02/09 09:48:17,433 INFO CoarseGrainedSchedulerBackend$DriverEndpoint: Registered executor NettyRpcEndpointRef(null) (10.1.2.146:48570) with ID 2
17/02/09 09:48:17,452 INFO BlockManagerMasterEndpoint: Registering block manager 10.1.2.181:33148 with 6.3 GB RAM, BlockManagerId(4, 10.1.2.181, 33148)
17/02/09 09:48:17,473 INFO CoarseGrainedSchedulerBackend$DriverEndpoint: Registered executor NettyRpcEndpointRef(null) (10.1.2.219:46540) with ID 12
17/02/09 09:48:17,479 INFO CoarseGrainedSchedulerBackend$DriverEndpoint: Registered executor NettyRpcEndpointRef(null) (10.1.2.138:48422) with ID 11
17/02/09 09:48:17,483 INFO CoarseGrainedSchedulerBackend$DriverEndpoint: Registered executor NettyRpcEndpointRef(null) (10.1.2.157:49826) with ID 0
17/02/09 09:48:17,484 INFO BlockManagerMasterEndpoint: Registering block manager 10.1.2.191:39598 with 6.3 GB RAM, BlockManagerId(3, 10.1.2.191, 39598)
17/02/09 09:48:17,484 INFO BlockManagerMasterEndpoint: Registering block manager 10.1.2.95:38307 with 6.3 GB RAM, BlockManagerId(1, 10.1.2.95, 38307)
17/02/09 09:48:17,486 INFO CoarseGrainedSchedulerBackend$DriverEndpoint: Registered executor NettyRpcEndpointRef(null) (10.1.2.248:49156) with ID 8
17/02/09 09:48:17,488 INFO BlockManagerMasterEndpoint: Registering block manager 10.1.2.146:36356 with 6.3 GB RAM, BlockManagerId(2, 10.1.2.146, 36356)
17/02/09 09:48:17,493 INFO BlockManagerMasterEndpoint: Registering block manager 10.1.2.174:36744 with 6.3 GB RAM, BlockManagerId(9, 10.1.2.174, 36744)
17/02/09 09:48:17,499 INFO CoarseGrainedSchedulerBackend$DriverEndpoint: Registered executor NettyRpcEndpointRef(null) (10.1.2.122:60656) with ID 10
17/02/09 09:48:17,504 INFO CoarseGrainedSchedulerBackend$DriverEndpoint: Registered executor NettyRpcEndpointRef(null) (10.1.2.85:48466) with ID 7
17/02/09 09:48:17,512 INFO CoarseGrainedSchedulerBackend$DriverEndpoint: Registered executor NettyRpcEndpointRef(null) (10.1.2.129:60966) with ID 5
17/02/09 09:48:17,523 INFO CoarseGrainedSchedulerBackend$DriverEndpoint: Registered executor NettyRpcEndpointRef(null) (10.1.2.69:55418) with ID 13
17/02/09 09:48:17,531 INFO BlockManagerMasterEndpoint: Registering block manager 10.1.2.219:38976 with 6.3 GB RAM, BlockManagerId(12, 10.1.2.219, 38976)
17/02/09 09:48:17,533 INFO BlockManagerMasterEndpoint: Registering block manager 10.1.2.157:44819 with 6.3 GB RAM, BlockManagerId(0, 10.1.2.157, 44819)
17/02/09 09:48:17,535 INFO BlockManagerMasterEndpoint: Registering block manager 10.1.2.138:43390 with 6.3 GB RAM, BlockManagerId(11, 10.1.2.138, 43390)
17/02/09 09:48:17,541 INFO BlockManagerMasterEndpoint: Registering block manager 10.1.2.248:44197 with 6.3 GB RAM, BlockManagerId(8, 10.1.2.248, 44197)
17/02/09 09:48:17,555 INFO BlockManagerMasterEndpoint: Registering block manager 10.1.2.122:42510 with 6.3 GB RAM, BlockManagerId(10, 10.1.2.122, 42510)
17/02/09 09:48:17,557 INFO CoarseGrainedSchedulerBackend$DriverEndpoint: Registered executor NettyRpcEndpointRef(null) (10.1.2.63:53708) with ID 14
17/02/09 09:48:17,566 INFO BlockManagerMasterEndpoint: Registering block manager 10.1.2.129:35547 with 6.3 GB RAM, BlockManagerId(5, 10.1.2.129, 35547)
17/02/09 09:48:17,573 INFO BlockManagerMasterEndpoint: Registering block manager 10.1.2.85:35336 with 6.3 GB RAM, BlockManagerId(7, 10.1.2.85, 35336)
17/02/09 09:48:17,578 INFO BlockManagerMasterEndpoint: Registering block manager 10.1.2.69:43318 with 6.3 GB RAM, BlockManagerId(13, 10.1.2.69, 43318)
17/02/09 09:48:17,613 INFO BlockManagerMasterEndpoint: Registering block manager 10.1.2.63:45802 with 6.3 GB RAM, BlockManagerId(14, 10.1.2.63, 45802)
17/02/09 09:48:17,642 INFO BlockManagerInfo: Added broadcast_1_piece0 in memory on 10.1.2.25:39678 (size: 2.4 KB, free: 6.3 GB)
17/02/09 09:48:17,790 INFO BlockManagerInfo: Added broadcast_0_piece0 in memory on 10.1.2.25:39678 (size: 16.5 KB, free: 6.3 GB)
17/02/09 09:48:20,719 INFO BlockManagerInfo: Added rdd_5_0 in memory on 10.1.2.25:39678 (size: 52.2 MB, free: 6.2 GB)
17/02/09 09:48:20,767 INFO TaskSetManager: Finished task 0.0 in stage 0.0 (TID 0) in 3462 ms on 10.1.2.25 (1/1)
17/02/09 09:48:20,768 INFO TaskSchedulerImpl: Removed TaskSet 0.0, whose tasks have all completed, from pool 
17/02/09 09:48:20,771 INFO DAGScheduler: ResultStage 0 (first at GeneralizedLinearAlgorithm.scala:246) finished in 6.850 s
17/02/09 09:48:20,775 INFO DAGScheduler: Job 0 finished: first at GeneralizedLinearAlgorithm.scala:246, took 6.934823 s
17/02/09 09:48:20,785 INFO SparkContext: Starting job: count at DataValidators.scala:40
17/02/09 09:48:20,786 INFO DAGScheduler: Got job 1 (count at DataValidators.scala:40) with 64 output partitions
17/02/09 09:48:20,786 INFO DAGScheduler: Final stage: ResultStage 1 (count at DataValidators.scala:40)
17/02/09 09:48:20,786 INFO DAGScheduler: Parents of final stage: List()
17/02/09 09:48:20,789 INFO DAGScheduler: Missing parents: List()
17/02/09 09:48:20,790 INFO DAGScheduler: Submitting ResultStage 1 (MapPartitionsRDD[7] at filter at DataValidators.scala:40), which has no missing parents
17/02/09 09:48:20,812 INFO MemoryStore: Block broadcast_2 stored as values in memory (estimated size 3.9 KB, free 6.3 GB)
17/02/09 09:48:20,814 INFO MemoryStore: Block broadcast_2_piece0 stored as bytes in memory (estimated size 2.2 KB, free 6.3 GB)
17/02/09 09:48:20,815 INFO BlockManagerInfo: Added broadcast_2_piece0 in memory on 10.1.2.238:40539 (size: 2.2 KB, free: 6.3 GB)
17/02/09 09:48:20,816 INFO SparkContext: Created broadcast 2 from broadcast at DAGScheduler.scala:1012
17/02/09 09:48:20,818 INFO DAGScheduler: Submitting 64 missing tasks from ResultStage 1 (MapPartitionsRDD[7] at filter at DataValidators.scala:40)
17/02/09 09:48:20,819 INFO TaskSchedulerImpl: Adding task set 1.0 with 64 tasks
17/02/09 09:48:20,825 INFO TaskSetManager: Starting task 0.0 in stage 1.0 (TID 1, 10.1.2.25, partition 0, PROCESS_LOCAL, 5381 bytes)
17/02/09 09:48:20,829 INFO TaskSetManager: Starting task 35.0 in stage 1.0 (TID 2, 10.1.2.95, partition 35, NODE_LOCAL, 5381 bytes)
17/02/09 09:48:20,830 INFO TaskSetManager: Starting task 15.0 in stage 1.0 (TID 3, 10.1.2.25, partition 15, NODE_LOCAL, 5381 bytes)
17/02/09 09:48:20,832 INFO TaskSetManager: Starting task 3.0 in stage 1.0 (TID 4, 10.1.2.63, partition 3, NODE_LOCAL, 5381 bytes)
17/02/09 09:48:20,834 INFO TaskSetManager: Starting task 23.0 in stage 1.0 (TID 5, 10.1.2.138, partition 23, NODE_LOCAL, 5381 bytes)
17/02/09 09:48:20,835 INFO TaskSetManager: Starting task 27.0 in stage 1.0 (TID 6, 10.1.2.157, partition 27, NODE_LOCAL, 5381 bytes)
17/02/09 09:48:20,837 INFO TaskSetManager: Starting task 31.0 in stage 1.0 (TID 7, 10.1.2.129, partition 31, NODE_LOCAL, 5381 bytes)
17/02/09 09:48:20,839 INFO TaskSetManager: Starting task 7.0 in stage 1.0 (TID 8, 10.1.2.146, partition 7, NODE_LOCAL, 5381 bytes)
17/02/09 09:48:20,841 INFO TaskSetManager: Starting task 62.0 in stage 1.0 (TID 9, 10.1.2.191, partition 62, NODE_LOCAL, 5381 bytes)
17/02/09 09:48:20,842 INFO TaskSetManager: Starting task 19.0 in stage 1.0 (TID 10, 10.1.2.69, partition 19, NODE_LOCAL, 5381 bytes)
17/02/09 09:48:20,845 INFO TaskSetManager: Starting task 54.0 in stage 1.0 (TID 11, 10.1.2.219, partition 54, NODE_LOCAL, 5381 bytes)
17/02/09 09:48:20,846 INFO TaskSetManager: Starting task 11.0 in stage 1.0 (TID 12, 10.1.2.174, partition 11, NODE_LOCAL, 5381 bytes)
17/02/09 09:48:20,848 INFO TaskSetManager: Starting task 42.0 in stage 1.0 (TID 13, 10.1.2.124, partition 42, NODE_LOCAL, 5381 bytes)
17/02/09 09:48:20,850 INFO TaskSetManager: Starting task 50.0 in stage 1.0 (TID 14, 10.1.2.181, partition 50, NODE_LOCAL, 5381 bytes)
17/02/09 09:48:20,852 INFO TaskSetManager: Starting task 38.0 in stage 1.0 (TID 15, 10.1.2.248, partition 38, NODE_LOCAL, 5381 bytes)
17/02/09 09:48:20,854 INFO TaskSetManager: Starting task 58.0 in stage 1.0 (TID 16, 10.1.2.25, partition 58, NODE_LOCAL, 5381 bytes)
17/02/09 09:48:20,856 INFO TaskSetManager: Starting task 46.0 in stage 1.0 (TID 17, 10.1.2.129, partition 46, NODE_LOCAL, 5381 bytes)
17/02/09 09:48:20,859 INFO CoarseGrainedSchedulerBackend$DriverEndpoint: Launching task 2 on executor id: 1 hostname: 10.1.2.95.
17/02/09 09:48:20,860 INFO CoarseGrainedSchedulerBackend$DriverEndpoint: Launching task 1 on executor id: 15 hostname: 10.1.2.25.
17/02/09 09:48:20,862 INFO CoarseGrainedSchedulerBackend$DriverEndpoint: Launching task 3 on executor id: 15 hostname: 10.1.2.25.
17/02/09 09:48:20,862 INFO CoarseGrainedSchedulerBackend$DriverEndpoint: Launching task 16 on executor id: 15 hostname: 10.1.2.25.
17/02/09 09:48:20,863 INFO CoarseGrainedSchedulerBackend$DriverEndpoint: Launching task 4 on executor id: 14 hostname: 10.1.2.63.
17/02/09 09:48:20,866 INFO CoarseGrainedSchedulerBackend$DriverEndpoint: Launching task 5 on executor id: 11 hostname: 10.1.2.138.
17/02/09 09:48:20,868 INFO CoarseGrainedSchedulerBackend$DriverEndpoint: Launching task 6 on executor id: 0 hostname: 10.1.2.157.
17/02/09 09:48:20,869 INFO CoarseGrainedSchedulerBackend$DriverEndpoint: Launching task 7 on executor id: 5 hostname: 10.1.2.129.
17/02/09 09:48:20,870 INFO CoarseGrainedSchedulerBackend$DriverEndpoint: Launching task 17 on executor id: 5 hostname: 10.1.2.129.
17/02/09 09:48:20,871 INFO CoarseGrainedSchedulerBackend$DriverEndpoint: Launching task 8 on executor id: 2 hostname: 10.1.2.146.
17/02/09 09:48:20,872 INFO CoarseGrainedSchedulerBackend$DriverEndpoint: Launching task 9 on executor id: 3 hostname: 10.1.2.191.
17/02/09 09:48:20,872 INFO CoarseGrainedSchedulerBackend$DriverEndpoint: Launching task 10 on executor id: 13 hostname: 10.1.2.69.
17/02/09 09:48:20,875 INFO CoarseGrainedSchedulerBackend$DriverEndpoint: Launching task 11 on executor id: 12 hostname: 10.1.2.219.
17/02/09 09:48:20,876 INFO CoarseGrainedSchedulerBackend$DriverEndpoint: Launching task 12 on executor id: 9 hostname: 10.1.2.174.
17/02/09 09:48:20,877 INFO CoarseGrainedSchedulerBackend$DriverEndpoint: Launching task 13 on executor id: 6 hostname: 10.1.2.124.
17/02/09 09:48:20,877 INFO CoarseGrainedSchedulerBackend$DriverEndpoint: Launching task 14 on executor id: 4 hostname: 10.1.2.181.
17/02/09 09:48:20,878 INFO CoarseGrainedSchedulerBackend$DriverEndpoint: Launching task 15 on executor id: 8 hostname: 10.1.2.248.
17/02/09 09:48:20,890 INFO BlockManagerInfo: Added broadcast_2_piece0 in memory on 10.1.2.25:39678 (size: 2.2 KB, free: 6.2 GB)
17/02/09 09:48:20,952 INFO TaskSetManager: Finished task 0.0 in stage 1.0 (TID 1) in 129 ms on 10.1.2.25 (1/64)
17/02/09 09:48:21,148 INFO BlockManagerInfo: Added broadcast_2_piece0 in memory on 10.1.2.124:34192 (size: 2.2 KB, free: 6.3 GB)
17/02/09 09:48:21,154 INFO BlockManagerInfo: Added broadcast_2_piece0 in memory on 10.1.2.63:45802 (size: 2.2 KB, free: 6.3 GB)
17/02/09 09:48:21,155 INFO BlockManagerInfo: Added broadcast_2_piece0 in memory on 10.1.2.146:36356 (size: 2.2 KB, free: 6.3 GB)
17/02/09 09:48:21,162 INFO BlockManagerInfo: Added broadcast_2_piece0 in memory on 10.1.2.95:38307 (size: 2.2 KB, free: 6.3 GB)
17/02/09 09:48:21,178 INFO BlockManagerInfo: Added broadcast_2_piece0 in memory on 10.1.2.129:35547 (size: 2.2 KB, free: 6.3 GB)
17/02/09 09:48:21,179 INFO BlockManagerInfo: Added broadcast_2_piece0 in memory on 10.1.2.181:33148 (size: 2.2 KB, free: 6.3 GB)
17/02/09 09:48:21,180 INFO BlockManagerInfo: Added broadcast_2_piece0 in memory on 10.1.2.191:39598 (size: 2.2 KB, free: 6.3 GB)
17/02/09 09:48:21,181 INFO BlockManagerInfo: Added broadcast_2_piece0 in memory on 10.1.2.248:44197 (size: 2.2 KB, free: 6.3 GB)
17/02/09 09:48:21,206 INFO BlockManagerInfo: Added broadcast_2_piece0 in memory on 10.1.2.174:36744 (size: 2.2 KB, free: 6.3 GB)
17/02/09 09:48:21,214 INFO BlockManagerInfo: Added broadcast_2_piece0 in memory on 10.1.2.219:38976 (size: 2.2 KB, free: 6.3 GB)
17/02/09 09:48:21,215 INFO BlockManagerInfo: Added broadcast_2_piece0 in memory on 10.1.2.69:43318 (size: 2.2 KB, free: 6.3 GB)
17/02/09 09:48:21,218 INFO BlockManagerInfo: Added broadcast_2_piece0 in memory on 10.1.2.138:43390 (size: 2.2 KB, free: 6.3 GB)
17/02/09 09:48:21,220 INFO BlockManagerInfo: Added broadcast_2_piece0 in memory on 10.1.2.157:44819 (size: 2.2 KB, free: 6.3 GB)
17/02/09 09:48:21,300 INFO BlockManagerInfo: Added broadcast_0_piece0 in memory on 10.1.2.124:34192 (size: 16.5 KB, free: 6.3 GB)
17/02/09 09:48:21,319 INFO BlockManagerInfo: Added broadcast_0_piece0 in memory on 10.1.2.63:45802 (size: 16.5 KB, free: 6.3 GB)
17/02/09 09:48:21,341 INFO BlockManagerInfo: Added broadcast_0_piece0 in memory on 10.1.2.95:38307 (size: 16.5 KB, free: 6.3 GB)
17/02/09 09:48:21,348 INFO BlockManagerInfo: Added broadcast_0_piece0 in memory on 10.1.2.248:44197 (size: 16.5 KB, free: 6.3 GB)
17/02/09 09:48:21,361 INFO BlockManagerInfo: Added broadcast_0_piece0 in memory on 10.1.2.146:36356 (size: 16.5 KB, free: 6.3 GB)
17/02/09 09:48:21,376 INFO BlockManagerInfo: Added broadcast_0_piece0 in memory on 10.1.2.191:39598 (size: 16.5 KB, free: 6.3 GB)
17/02/09 09:48:21,386 INFO BlockManagerInfo: Added broadcast_0_piece0 in memory on 10.1.2.138:43390 (size: 16.5 KB, free: 6.3 GB)
17/02/09 09:48:21,390 INFO BlockManagerInfo: Added broadcast_0_piece0 in memory on 10.1.2.157:44819 (size: 16.5 KB, free: 6.3 GB)
17/02/09 09:48:21,419 INFO BlockManagerInfo: Added broadcast_0_piece0 in memory on 10.1.2.174:36744 (size: 16.5 KB, free: 6.3 GB)
17/02/09 09:48:21,420 INFO BlockManagerInfo: Added broadcast_0_piece0 in memory on 10.1.2.181:33148 (size: 16.5 KB, free: 6.3 GB)
17/02/09 09:48:21,420 INFO BlockManagerInfo: Added broadcast_0_piece0 in memory on 10.1.2.129:35547 (size: 16.5 KB, free: 6.3 GB)
17/02/09 09:48:21,424 INFO BlockManagerInfo: Added broadcast_0_piece0 in memory on 10.1.2.69:43318 (size: 16.5 KB, free: 6.3 GB)
17/02/09 09:48:21,430 INFO BlockManagerInfo: Added broadcast_0_piece0 in memory on 10.1.2.219:38976 (size: 16.5 KB, free: 6.3 GB)
17/02/09 09:48:22,573 INFO BlockManagerInfo: Added rdd_5_15 in memory on 10.1.2.25:39678 (size: 52.9 MB, free: 6.2 GB)
17/02/09 09:48:22,585 INFO BlockManagerInfo: Added rdd_5_58 in memory on 10.1.2.25:39678 (size: 51.7 MB, free: 6.1 GB)
17/02/09 09:48:22,595 INFO TaskSetManager: Finished task 15.0 in stage 1.0 (TID 3) in 1766 ms on 10.1.2.25 (2/64)
17/02/09 09:48:22,601 INFO TaskSetManager: Finished task 58.0 in stage 1.0 (TID 16) in 1747 ms on 10.1.2.25 (3/64)
17/02/09 09:48:24,174 INFO TaskSetManager: Starting task 1.0 in stage 1.0 (TID 18, 10.1.2.63, partition 1, ANY, 5381 bytes)
17/02/09 09:48:24,175 INFO TaskSetManager: Starting task 2.0 in stage 1.0 (TID 19, 10.1.2.138, partition 2, ANY, 5381 bytes)
17/02/09 09:48:24,177 INFO TaskSetManager: Starting task 4.0 in stage 1.0 (TID 20, 10.1.2.174, partition 4, ANY, 5381 bytes)
17/02/09 09:48:24,179 INFO TaskSetManager: Starting task 5.0 in stage 1.0 (TID 21, 10.1.2.25, partition 5, ANY, 5381 bytes)
17/02/09 09:48:24,180 INFO TaskSetManager: Starting task 6.0 in stage 1.0 (TID 22, 10.1.2.124, partition 6, ANY, 5381 bytes)
17/02/09 09:48:24,182 INFO TaskSetManager: Starting task 8.0 in stage 1.0 (TID 23, 10.1.2.219, partition 8, ANY, 5381 bytes)
17/02/09 09:48:24,184 INFO TaskSetManager: Starting task 9.0 in stage 1.0 (TID 24, 10.1.2.85, partition 9, ANY, 5381 bytes)
17/02/09 09:48:24,186 INFO TaskSetManager: Starting task 10.0 in stage 1.0 (TID 25, 10.1.2.191, partition 10, ANY, 5381 bytes)
17/02/09 09:48:24,188 INFO TaskSetManager: Starting task 12.0 in stage 1.0 (TID 26, 10.1.2.69, partition 12, ANY, 5381 bytes)
17/02/09 09:48:24,190 INFO TaskSetManager: Starting task 13.0 in stage 1.0 (TID 27, 10.1.2.181, partition 13, ANY, 5381 bytes)
17/02/09 09:48:24,191 INFO TaskSetManager: Starting task 14.0 in stage 1.0 (TID 28, 10.1.2.95, partition 14, ANY, 5381 bytes)
17/02/09 09:48:24,193 INFO TaskSetManager: Starting task 16.0 in stage 1.0 (TID 29, 10.1.2.157, partition 16, ANY, 5381 bytes)
17/02/09 09:48:24,195 INFO TaskSetManager: Starting task 17.0 in stage 1.0 (TID 30, 10.1.2.146, partition 17, ANY, 5381 bytes)
17/02/09 09:48:24,196 INFO TaskSetManager: Starting task 18.0 in stage 1.0 (TID 31, 10.1.2.122, partition 18, ANY, 5381 bytes)
17/02/09 09:48:24,198 INFO TaskSetManager: Starting task 20.0 in stage 1.0 (TID 32, 10.1.2.129, partition 20, ANY, 5381 bytes)
17/02/09 09:48:24,200 INFO TaskSetManager: Starting task 21.0 in stage 1.0 (TID 33, 10.1.2.248, partition 21, ANY, 5381 bytes)
17/02/09 09:48:24,201 INFO TaskSetManager: Starting task 22.0 in stage 1.0 (TID 34, 10.1.2.63, partition 22, ANY, 5381 bytes)
17/02/09 09:48:24,203 INFO TaskSetManager: Starting task 24.0 in stage 1.0 (TID 35, 10.1.2.138, partition 24, ANY, 5381 bytes)
17/02/09 09:48:24,205 INFO TaskSetManager: Starting task 25.0 in stage 1.0 (TID 36, 10.1.2.174, partition 25, ANY, 5381 bytes)
17/02/09 09:48:24,207 INFO TaskSetManager: Starting task 26.0 in stage 1.0 (TID 37, 10.1.2.25, partition 26, ANY, 5381 bytes)
17/02/09 09:48:24,209 INFO TaskSetManager: Starting task 28.0 in stage 1.0 (TID 38, 10.1.2.124, partition 28, ANY, 5381 bytes)
17/02/09 09:48:24,211 INFO TaskSetManager: Starting task 29.0 in stage 1.0 (TID 39, 10.1.2.219, partition 29, ANY, 5381 bytes)
17/02/09 09:48:24,213 INFO TaskSetManager: Starting task 30.0 in stage 1.0 (TID 40, 10.1.2.85, partition 30, ANY, 5381 bytes)
17/02/09 09:48:24,215 INFO TaskSetManager: Starting task 32.0 in stage 1.0 (TID 41, 10.1.2.191, partition 32, ANY, 5381 bytes)
17/02/09 09:48:24,217 INFO TaskSetManager: Starting task 33.0 in stage 1.0 (TID 42, 10.1.2.69, partition 33, ANY, 5381 bytes)
17/02/09 09:48:24,219 INFO TaskSetManager: Starting task 34.0 in stage 1.0 (TID 43, 10.1.2.181, partition 34, ANY, 5381 bytes)
17/02/09 09:48:24,221 INFO TaskSetManager: Starting task 36.0 in stage 1.0 (TID 44, 10.1.2.95, partition 36, ANY, 5381 bytes)
17/02/09 09:48:24,222 INFO TaskSetManager: Starting task 37.0 in stage 1.0 (TID 45, 10.1.2.157, partition 37, ANY, 5381 bytes)
17/02/09 09:48:24,224 INFO TaskSetManager: Starting task 39.0 in stage 1.0 (TID 46, 10.1.2.146, partition 39, ANY, 5381 bytes)
17/02/09 09:48:24,226 INFO TaskSetManager: Starting task 40.0 in stage 1.0 (TID 47, 10.1.2.122, partition 40, ANY, 5381 bytes)
17/02/09 09:48:24,228 INFO TaskSetManager: Starting task 41.0 in stage 1.0 (TID 48, 10.1.2.129, partition 41, ANY, 5381 bytes)
17/02/09 09:48:24,229 INFO TaskSetManager: Starting task 43.0 in stage 1.0 (TID 49, 10.1.2.248, partition 43, ANY, 5381 bytes)
17/02/09 09:48:24,231 INFO TaskSetManager: Starting task 44.0 in stage 1.0 (TID 50, 10.1.2.63, partition 44, ANY, 5381 bytes)
17/02/09 09:48:24,233 INFO TaskSetManager: Starting task 45.0 in stage 1.0 (TID 51, 10.1.2.138, partition 45, ANY, 5381 bytes)
17/02/09 09:48:24,235 INFO TaskSetManager: Starting task 47.0 in stage 1.0 (TID 52, 10.1.2.174, partition 47, ANY, 5381 bytes)
17/02/09 09:48:24,237 INFO TaskSetManager: Starting task 48.0 in stage 1.0 (TID 53, 10.1.2.25, partition 48, ANY, 5381 bytes)
17/02/09 09:48:24,239 INFO TaskSetManager: Starting task 49.0 in stage 1.0 (TID 54, 10.1.2.124, partition 49, ANY, 5381 bytes)
17/02/09 09:48:24,241 INFO TaskSetManager: Starting task 51.0 in stage 1.0 (TID 55, 10.1.2.219, partition 51, ANY, 5381 bytes)
17/02/09 09:48:24,242 INFO TaskSetManager: Starting task 52.0 in stage 1.0 (TID 56, 10.1.2.85, partition 52, ANY, 5381 bytes)
17/02/09 09:48:24,244 INFO TaskSetManager: Starting task 53.0 in stage 1.0 (TID 57, 10.1.2.191, partition 53, ANY, 5381 bytes)
17/02/09 09:48:24,245 INFO TaskSetManager: Starting task 55.0 in stage 1.0 (TID 58, 10.1.2.69, partition 55, ANY, 5381 bytes)
17/02/09 09:48:24,246 INFO TaskSetManager: Starting task 56.0 in stage 1.0 (TID 59, 10.1.2.181, partition 56, ANY, 5381 bytes)
17/02/09 09:48:24,248 INFO TaskSetManager: Starting task 57.0 in stage 1.0 (TID 60, 10.1.2.95, partition 57, ANY, 5381 bytes)
17/02/09 09:48:24,249 INFO TaskSetManager: Starting task 59.0 in stage 1.0 (TID 61, 10.1.2.157, partition 59, ANY, 5381 bytes)
17/02/09 09:48:24,251 INFO TaskSetManager: Starting task 60.0 in stage 1.0 (TID 62, 10.1.2.146, partition 60, ANY, 5381 bytes)
17/02/09 09:48:24,252 INFO TaskSetManager: Starting task 61.0 in stage 1.0 (TID 63, 10.1.2.122, partition 61, ANY, 5381 bytes)
17/02/09 09:48:24,254 INFO TaskSetManager: Starting task 63.0 in stage 1.0 (TID 64, 10.1.2.248, partition 63, ANY, 5381 bytes)
17/02/09 09:48:24,254 INFO CoarseGrainedSchedulerBackend$DriverEndpoint: Launching task 18 on executor id: 14 hostname: 10.1.2.63.
17/02/09 09:48:24,255 INFO CoarseGrainedSchedulerBackend$DriverEndpoint: Launching task 34 on executor id: 14 hostname: 10.1.2.63.
17/02/09 09:48:24,256 INFO CoarseGrainedSchedulerBackend$DriverEndpoint: Launching task 50 on executor id: 14 hostname: 10.1.2.63.
17/02/09 09:48:24,257 INFO CoarseGrainedSchedulerBackend$DriverEndpoint: Launching task 19 on executor id: 11 hostname: 10.1.2.138.
17/02/09 09:48:24,257 INFO CoarseGrainedSchedulerBackend$DriverEndpoint: Launching task 35 on executor id: 11 hostname: 10.1.2.138.
17/02/09 09:48:24,258 INFO CoarseGrainedSchedulerBackend$DriverEndpoint: Launching task 51 on executor id: 11 hostname: 10.1.2.138.
17/02/09 09:48:24,258 INFO CoarseGrainedSchedulerBackend$DriverEndpoint: Launching task 20 on executor id: 9 hostname: 10.1.2.174.
17/02/09 09:48:24,259 INFO CoarseGrainedSchedulerBackend$DriverEndpoint: Launching task 36 on executor id: 9 hostname: 10.1.2.174.
17/02/09 09:48:24,260 INFO CoarseGrainedSchedulerBackend$DriverEndpoint: Launching task 52 on executor id: 9 hostname: 10.1.2.174.
17/02/09 09:48:24,260 INFO CoarseGrainedSchedulerBackend$DriverEndpoint: Launching task 21 on executor id: 15 hostname: 10.1.2.25.
17/02/09 09:48:24,261 INFO CoarseGrainedSchedulerBackend$DriverEndpoint: Launching task 37 on executor id: 15 hostname: 10.1.2.25.
17/02/09 09:48:24,262 INFO CoarseGrainedSchedulerBackend$DriverEndpoint: Launching task 53 on executor id: 15 hostname: 10.1.2.25.
17/02/09 09:48:24,262 INFO CoarseGrainedSchedulerBackend$DriverEndpoint: Launching task 22 on executor id: 6 hostname: 10.1.2.124.
17/02/09 09:48:24,263 INFO CoarseGrainedSchedulerBackend$DriverEndpoint: Launching task 38 on executor id: 6 hostname: 10.1.2.124.
17/02/09 09:48:24,263 INFO CoarseGrainedSchedulerBackend$DriverEndpoint: Launching task 54 on executor id: 6 hostname: 10.1.2.124.
17/02/09 09:48:24,264 INFO CoarseGrainedSchedulerBackend$DriverEndpoint: Launching task 23 on executor id: 12 hostname: 10.1.2.219.
17/02/09 09:48:24,265 INFO CoarseGrainedSchedulerBackend$DriverEndpoint: Launching task 39 on executor id: 12 hostname: 10.1.2.219.
17/02/09 09:48:24,265 INFO CoarseGrainedSchedulerBackend$DriverEndpoint: Launching task 55 on executor id: 12 hostname: 10.1.2.219.
17/02/09 09:48:24,269 INFO CoarseGrainedSchedulerBackend$DriverEndpoint: Launching task 24 on executor id: 7 hostname: 10.1.2.85.
17/02/09 09:48:24,270 INFO CoarseGrainedSchedulerBackend$DriverEndpoint: Launching task 40 on executor id: 7 hostname: 10.1.2.85.
17/02/09 09:48:24,271 INFO CoarseGrainedSchedulerBackend$DriverEndpoint: Launching task 56 on executor id: 7 hostname: 10.1.2.85.
17/02/09 09:48:24,271 INFO CoarseGrainedSchedulerBackend$DriverEndpoint: Launching task 25 on executor id: 3 hostname: 10.1.2.191.
17/02/09 09:48:24,272 INFO CoarseGrainedSchedulerBackend$DriverEndpoint: Launching task 41 on executor id: 3 hostname: 10.1.2.191.
17/02/09 09:48:24,273 INFO CoarseGrainedSchedulerBackend$DriverEndpoint: Launching task 57 on executor id: 3 hostname: 10.1.2.191.
17/02/09 09:48:24,277 INFO CoarseGrainedSchedulerBackend$DriverEndpoint: Launching task 26 on executor id: 13 hostname: 10.1.2.69.
17/02/09 09:48:24,278 INFO CoarseGrainedSchedulerBackend$DriverEndpoint: Launching task 42 on executor id: 13 hostname: 10.1.2.69.
17/02/09 09:48:24,278 INFO CoarseGrainedSchedulerBackend$DriverEndpoint: Launching task 58 on executor id: 13 hostname: 10.1.2.69.
17/02/09 09:48:24,279 INFO CoarseGrainedSchedulerBackend$DriverEndpoint: Launching task 27 on executor id: 4 hostname: 10.1.2.181.
17/02/09 09:48:24,279 INFO CoarseGrainedSchedulerBackend$DriverEndpoint: Launching task 43 on executor id: 4 hostname: 10.1.2.181.
17/02/09 09:48:24,279 INFO CoarseGrainedSchedulerBackend$DriverEndpoint: Launching task 59 on executor id: 4 hostname: 10.1.2.181.
17/02/09 09:48:24,280 INFO CoarseGrainedSchedulerBackend$DriverEndpoint: Launching task 28 on executor id: 1 hostname: 10.1.2.95.
17/02/09 09:48:24,281 INFO CoarseGrainedSchedulerBackend$DriverEndpoint: Launching task 44 on executor id: 1 hostname: 10.1.2.95.
17/02/09 09:48:24,281 INFO CoarseGrainedSchedulerBackend$DriverEndpoint: Launching task 60 on executor id: 1 hostname: 10.1.2.95.
17/02/09 09:48:24,282 INFO CoarseGrainedSchedulerBackend$DriverEndpoint: Launching task 29 on executor id: 0 hostname: 10.1.2.157.
17/02/09 09:48:24,282 INFO CoarseGrainedSchedulerBackend$DriverEndpoint: Launching task 45 on executor id: 0 hostname: 10.1.2.157.
17/02/09 09:48:24,283 INFO CoarseGrainedSchedulerBackend$DriverEndpoint: Launching task 61 on executor id: 0 hostname: 10.1.2.157.
17/02/09 09:48:24,283 INFO CoarseGrainedSchedulerBackend$DriverEndpoint: Launching task 30 on executor id: 2 hostname: 10.1.2.146.
17/02/09 09:48:24,284 INFO CoarseGrainedSchedulerBackend$DriverEndpoint: Launching task 46 on executor id: 2 hostname: 10.1.2.146.
17/02/09 09:48:24,284 INFO CoarseGrainedSchedulerBackend$DriverEndpoint: Launching task 62 on executor id: 2 hostname: 10.1.2.146.
17/02/09 09:48:24,284 INFO CoarseGrainedSchedulerBackend$DriverEndpoint: Launching task 31 on executor id: 10 hostname: 10.1.2.122.
17/02/09 09:48:24,285 INFO CoarseGrainedSchedulerBackend$DriverEndpoint: Launching task 47 on executor id: 10 hostname: 10.1.2.122.
17/02/09 09:48:24,285 INFO CoarseGrainedSchedulerBackend$DriverEndpoint: Launching task 63 on executor id: 10 hostname: 10.1.2.122.
17/02/09 09:48:24,286 INFO CoarseGrainedSchedulerBackend$DriverEndpoint: Launching task 32 on executor id: 5 hostname: 10.1.2.129.
17/02/09 09:48:24,286 INFO CoarseGrainedSchedulerBackend$DriverEndpoint: Launching task 48 on executor id: 5 hostname: 10.1.2.129.
17/02/09 09:48:24,286 INFO CoarseGrainedSchedulerBackend$DriverEndpoint: Launching task 33 on executor id: 8 hostname: 10.1.2.248.
17/02/09 09:48:24,287 INFO CoarseGrainedSchedulerBackend$DriverEndpoint: Launching task 49 on executor id: 8 hostname: 10.1.2.248.
17/02/09 09:48:24,288 INFO CoarseGrainedSchedulerBackend$DriverEndpoint: Launching task 64 on executor id: 8 hostname: 10.1.2.248.
17/02/09 09:48:24,495 INFO BlockManagerInfo: Added rdd_5_42 in memory on 10.1.2.124:34192 (size: 50.3 MB, free: 6.2 GB)
17/02/09 09:48:24,555 INFO BlockManagerInfo: Added rdd_5_46 in memory on 10.1.2.129:35547 (size: 52.4 MB, free: 6.2 GB)
17/02/09 09:48:24,603 INFO TaskSetManager: Finished task 42.0 in stage 1.0 (TID 13) in 3757 ms on 10.1.2.124 (4/64)
17/02/09 09:48:24,626 INFO TaskSetManager: Finished task 46.0 in stage 1.0 (TID 17) in 3771 ms on 10.1.2.129 (5/64)
17/02/09 09:48:24,648 INFO BlockManagerInfo: Added broadcast_2_piece0 in memory on 10.1.2.122:42510 (size: 2.2 KB, free: 6.3 GB)
17/02/09 09:48:24,666 INFO BlockManagerInfo: Added broadcast_2_piece0 in memory on 10.1.2.85:35336 (size: 2.2 KB, free: 6.3 GB)
17/02/09 09:48:24,685 INFO BlockManagerInfo: Added rdd_5_31 in memory on 10.1.2.129:35547 (size: 52.5 MB, free: 6.2 GB)
17/02/09 09:48:24,703 INFO TaskSetManager: Finished task 31.0 in stage 1.0 (TID 7) in 3866 ms on 10.1.2.129 (6/64)
17/02/09 09:48:24,779 INFO BlockManagerInfo: Added rdd_5_3 in memory on 10.1.2.63:45802 (size: 51.3 MB, free: 6.2 GB)
17/02/09 09:48:24,784 INFO BlockManagerInfo: Added rdd_5_54 in memory on 10.1.2.219:38976 (size: 51.8 MB, free: 6.2 GB)
17/02/09 09:48:24,793 INFO BlockManagerInfo: Added rdd_5_23 in memory on 10.1.2.138:43390 (size: 52.6 MB, free: 6.2 GB)
17/02/09 09:48:24,807 INFO BlockManagerInfo: Added rdd_5_7 in memory on 10.1.2.146:36356 (size: 51.3 MB, free: 6.2 GB)
17/02/09 09:48:24,808 INFO BlockManagerInfo: Added rdd_5_38 in memory on 10.1.2.248:44197 (size: 52.1 MB, free: 6.2 GB)
17/02/09 09:48:24,819 INFO BlockManagerInfo: Added rdd_5_11 in memory on 10.1.2.174:36744 (size: 51.2 MB, free: 6.2 GB)
17/02/09 09:48:24,856 INFO BlockManagerInfo: Added rdd_5_50 in memory on 10.1.2.181:33148 (size: 52.9 MB, free: 6.2 GB)
17/02/09 09:48:24,865 INFO BlockManagerInfo: Added rdd_5_62 in memory on 10.1.2.191:39598 (size: 52.2 MB, free: 6.2 GB)
17/02/09 09:48:24,867 INFO TaskSetManager: Finished task 23.0 in stage 1.0 (TID 5) in 4034 ms on 10.1.2.138 (7/64)
17/02/09 09:48:24,868 INFO TaskSetManager: Finished task 54.0 in stage 1.0 (TID 11) in 4025 ms on 10.1.2.219 (8/64)
17/02/09 09:48:24,874 INFO TaskSetManager: Finished task 38.0 in stage 1.0 (TID 15) in 4023 ms on 10.1.2.248 (9/64)
17/02/09 09:48:24,877 INFO TaskSetManager: Finished task 7.0 in stage 1.0 (TID 8) in 4040 ms on 10.1.2.146 (10/64)
17/02/09 09:48:24,881 INFO TaskSetManager: Finished task 3.0 in stage 1.0 (TID 4) in 4051 ms on 10.1.2.63 (11/64)
17/02/09 09:48:24,891 INFO TaskSetManager: Finished task 11.0 in stage 1.0 (TID 12) in 4046 ms on 10.1.2.174 (12/64)
17/02/09 09:48:24,922 INFO BlockManagerInfo: Added broadcast_0_piece0 in memory on 10.1.2.122:42510 (size: 16.5 KB, free: 6.3 GB)
17/02/09 09:48:24,942 INFO TaskSetManager: Finished task 62.0 in stage 1.0 (TID 9) in 4102 ms on 10.1.2.191 (13/64)
17/02/09 09:48:24,966 INFO TaskSetManager: Finished task 50.0 in stage 1.0 (TID 14) in 4118 ms on 10.1.2.181 (14/64)
17/02/09 09:48:24,967 INFO BlockManagerInfo: Added broadcast_0_piece0 in memory on 10.1.2.85:35336 (size: 16.5 KB, free: 6.3 GB)
17/02/09 09:48:24,993 INFO BlockManagerInfo: Added rdd_5_19 in memory on 10.1.2.69:43318 (size: 52.8 MB, free: 6.2 GB)
17/02/09 09:48:25,125 INFO BlockManagerInfo: Added rdd_5_35 in memory on 10.1.2.95:38307 (size: 52.8 MB, free: 6.2 GB)
17/02/09 09:48:25,194 INFO TaskSetManager: Finished task 19.0 in stage 1.0 (TID 10) in 4353 ms on 10.1.2.69 (15/64)
17/02/09 09:48:25,194 INFO TaskSetManager: Finished task 35.0 in stage 1.0 (TID 2) in 4367 ms on 10.1.2.95 (16/64)
17/02/09 09:48:25,331 INFO BlockManagerInfo: Added rdd_5_27 in memory on 10.1.2.157:44819 (size: 52.7 MB, free: 6.2 GB)
17/02/09 09:48:25,411 INFO TaskSetManager: Finished task 27.0 in stage 1.0 (TID 6) in 4577 ms on 10.1.2.157 (17/64)
17/02/09 09:48:26,155 INFO BlockManagerInfo: Added rdd_5_20 in memory on 10.1.2.129:35547 (size: 51.3 MB, free: 6.1 GB)
17/02/09 09:48:26,176 INFO TaskSetManager: Finished task 20.0 in stage 1.0 (TID 32) in 1978 ms on 10.1.2.129 (18/64)
17/02/09 09:48:26,188 INFO BlockManagerInfo: Added rdd_5_26 in memory on 10.1.2.25:39678 (size: 51.2 MB, free: 6.1 GB)
17/02/09 09:48:26,191 INFO BlockManagerInfo: Added rdd_5_41 in memory on 10.1.2.129:35547 (size: 52.3 MB, free: 6.1 GB)
17/02/09 09:48:26,202 INFO TaskSetManager: Finished task 26.0 in stage 1.0 (TID 37) in 1996 ms on 10.1.2.25 (19/64)
17/02/09 09:48:26,203 INFO TaskSetManager: Finished task 41.0 in stage 1.0 (TID 48) in 1977 ms on 10.1.2.129 (20/64)
17/02/09 09:48:26,224 INFO BlockManagerInfo: Added rdd_5_5 in memory on 10.1.2.25:39678 (size: 51.9 MB, free: 6.0 GB)
17/02/09 09:48:26,237 INFO TaskSetManager: Finished task 5.0 in stage 1.0 (TID 21) in 2060 ms on 10.1.2.25 (21/64)
17/02/09 09:48:26,239 INFO BlockManagerInfo: Added rdd_5_28 in memory on 10.1.2.124:34192 (size: 50.9 MB, free: 6.2 GB)
17/02/09 09:48:26,249 INFO TaskSetManager: Finished task 28.0 in stage 1.0 (TID 38) in 2042 ms on 10.1.2.124 (22/64)
17/02/09 09:48:26,275 INFO BlockManagerInfo: Added rdd_5_49 in memory on 10.1.2.124:34192 (size: 52.7 MB, free: 6.1 GB)
17/02/09 09:48:26,277 INFO BlockManagerInfo: Added rdd_5_6 in memory on 10.1.2.124:34192 (size: 52.3 MB, free: 6.1 GB)
17/02/09 09:48:26,298 INFO TaskSetManager: Finished task 6.0 in stage 1.0 (TID 22) in 2119 ms on 10.1.2.124 (23/64)
17/02/09 09:48:26,301 INFO BlockManagerInfo: Added rdd_5_8 in memory on 10.1.2.219:38976 (size: 53.9 MB, free: 6.2 GB)
17/02/09 09:48:26,302 INFO TaskSetManager: Finished task 49.0 in stage 1.0 (TID 54) in 2065 ms on 10.1.2.124 (24/64)
17/02/09 09:48:26,312 INFO TaskSetManager: Finished task 8.0 in stage 1.0 (TID 23) in 2132 ms on 10.1.2.219 (25/64)
17/02/09 09:48:26,314 INFO BlockManagerInfo: Added rdd_5_10 in memory on 10.1.2.191:39598 (size: 52.4 MB, free: 6.2 GB)
17/02/09 09:48:26,323 INFO BlockManagerInfo: Added rdd_5_29 in memory on 10.1.2.219:38976 (size: 51.8 MB, free: 6.1 GB)
17/02/09 09:48:26,324 INFO BlockManagerInfo: Added rdd_5_36 in memory on 10.1.2.95:38307 (size: 51.5 MB, free: 6.2 GB)
17/02/09 09:48:26,327 INFO TaskSetManager: Finished task 10.0 in stage 1.0 (TID 25) in 2143 ms on 10.1.2.191 (26/64)
17/02/09 09:48:26,328 INFO BlockManagerInfo: Added rdd_5_17 in memory on 10.1.2.146:36356 (size: 52.1 MB, free: 6.2 GB)
17/02/09 09:48:26,331 INFO BlockManagerInfo: Added rdd_5_39 in memory on 10.1.2.146:36356 (size: 52.4 MB, free: 6.1 GB)
17/02/09 09:48:26,337 INFO BlockManagerInfo: Added rdd_5_14 in memory on 10.1.2.95:38307 (size: 51.9 MB, free: 6.1 GB)
17/02/09 09:48:26,341 INFO BlockManagerInfo: Added rdd_5_60 in memory on 10.1.2.146:36356 (size: 51.7 MB, free: 6.1 GB)
17/02/09 09:48:26,341 INFO TaskSetManager: Finished task 17.0 in stage 1.0 (TID 30) in 2148 ms on 10.1.2.146 (27/64)
17/02/09 09:48:26,344 INFO TaskSetManager: Finished task 39.0 in stage 1.0 (TID 46) in 2121 ms on 10.1.2.146 (28/64)
17/02/09 09:48:26,346 INFO TaskSetManager: Finished task 29.0 in stage 1.0 (TID 39) in 2137 ms on 10.1.2.219 (29/64)
17/02/09 09:48:26,354 INFO BlockManagerInfo: Added rdd_5_59 in memory on 10.1.2.157:44819 (size: 52.2 MB, free: 6.2 GB)
17/02/09 09:48:26,355 INFO BlockManagerInfo: Added rdd_5_44 in memory on 10.1.2.63:45802 (size: 51.6 MB, free: 6.2 GB)
17/02/09 09:48:26,360 INFO BlockManagerInfo: Added rdd_5_48 in memory on 10.1.2.25:39678 (size: 52.1 MB, free: 6.0 GB)
17/02/09 09:48:26,361 INFO TaskSetManager: Finished task 60.0 in stage 1.0 (TID 62) in 2111 ms on 10.1.2.146 (30/64)
17/02/09 09:48:26,361 INFO TaskSetManager: Finished task 36.0 in stage 1.0 (TID 44) in 2142 ms on 10.1.2.95 (31/64)
17/02/09 09:48:26,361 INFO BlockManagerInfo: Added rdd_5_24 in memory on 10.1.2.138:43390 (size: 51.2 MB, free: 6.2 GB)
17/02/09 09:48:26,364 INFO TaskSetManager: Finished task 14.0 in stage 1.0 (TID 28) in 2174 ms on 10.1.2.95 (32/64)
17/02/09 09:48:26,366 INFO TaskSetManager: Finished task 59.0 in stage 1.0 (TID 61) in 2118 ms on 10.1.2.157 (33/64)
17/02/09 09:48:26,369 INFO BlockManagerInfo: Added rdd_5_53 in memory on 10.1.2.191:39598 (size: 51.5 MB, free: 6.1 GB)
17/02/09 09:48:26,371 INFO TaskSetManager: Finished task 48.0 in stage 1.0 (TID 53) in 2135 ms on 10.1.2.25 (34/64)
17/02/09 09:48:26,371 INFO BlockManagerInfo: Added rdd_5_4 in memory on 10.1.2.174:36744 (size: 51.8 MB, free: 6.2 GB)
17/02/09 09:48:26,372 INFO BlockManagerInfo: Added rdd_5_45 in memory on 10.1.2.138:43390 (size: 52.5 MB, free: 6.1 GB)
17/02/09 09:48:26,373 INFO BlockManagerInfo: Added rdd_5_1 in memory on 10.1.2.63:45802 (size: 51.7 MB, free: 6.1 GB)
17/02/09 09:48:26,378 INFO TaskSetManager: Finished task 24.0 in stage 1.0 (TID 35) in 2177 ms on 10.1.2.138 (35/64)
17/02/09 09:48:26,378 INFO BlockManagerInfo: Added rdd_5_16 in memory on 10.1.2.157:44819 (size: 52.5 MB, free: 6.1 GB)
17/02/09 09:48:26,380 INFO TaskSetManager: Finished task 44.0 in stage 1.0 (TID 50) in 2151 ms on 10.1.2.63 (36/64)
17/02/09 09:48:26,381 INFO TaskSetManager: Finished task 53.0 in stage 1.0 (TID 57) in 2137 ms on 10.1.2.191 (37/64)
17/02/09 09:48:26,384 INFO BlockManagerInfo: Added rdd_5_57 in memory on 10.1.2.95:38307 (size: 51.2 MB, free: 6.1 GB)
17/02/09 09:48:26,385 INFO TaskSetManager: Finished task 4.0 in stage 1.0 (TID 20) in 2209 ms on 10.1.2.174 (38/64)
17/02/09 09:48:26,394 INFO TaskSetManager: Finished task 57.0 in stage 1.0 (TID 60) in 2146 ms on 10.1.2.95 (39/64)
17/02/09 09:48:26,394 INFO BlockManagerInfo: Added rdd_5_43 in memory on 10.1.2.248:44197 (size: 53.5 MB, free: 6.2 GB)
17/02/09 09:48:26,395 INFO TaskSetManager: Finished task 1.0 in stage 1.0 (TID 18) in 2223 ms on 10.1.2.63 (40/64)
17/02/09 09:48:26,395 INFO TaskSetManager: Finished task 16.0 in stage 1.0 (TID 29) in 2203 ms on 10.1.2.157 (41/64)
17/02/09 09:48:26,402 INFO TaskSetManager: Finished task 45.0 in stage 1.0 (TID 51) in 2171 ms on 10.1.2.138 (42/64)
17/02/09 09:48:26,403 INFO TaskSetManager: Finished task 43.0 in stage 1.0 (TID 49) in 2175 ms on 10.1.2.248 (43/64)
17/02/09 09:48:26,405 INFO BlockManagerInfo: Added rdd_5_2 in memory on 10.1.2.138:43390 (size: 50.8 MB, free: 6.1 GB)
17/02/09 09:48:26,405 INFO BlockManagerInfo: Added rdd_5_55 in memory on 10.1.2.69:43318 (size: 52.3 MB, free: 6.2 GB)
17/02/09 09:48:26,415 INFO TaskSetManager: Finished task 2.0 in stage 1.0 (TID 19) in 2241 ms on 10.1.2.138 (44/64)
17/02/09 09:48:26,417 INFO TaskSetManager: Finished task 55.0 in stage 1.0 (TID 58) in 2173 ms on 10.1.2.69 (45/64)
17/02/09 09:48:26,422 INFO BlockManagerInfo: Added rdd_5_34 in memory on 10.1.2.181:33148 (size: 52.5 MB, free: 6.2 GB)
17/02/09 09:48:26,435 INFO TaskSetManager: Finished task 34.0 in stage 1.0 (TID 43) in 2217 ms on 10.1.2.181 (46/64)
17/02/09 09:48:26,443 INFO BlockManagerInfo: Added rdd_5_22 in memory on 10.1.2.63:45802 (size: 52.3 MB, free: 6.1 GB)
17/02/09 09:48:26,454 INFO TaskSetManager: Finished task 22.0 in stage 1.0 (TID 34) in 2253 ms on 10.1.2.63 (47/64)
17/02/09 09:48:26,454 INFO BlockManagerInfo: Added rdd_5_32 in memory on 10.1.2.191:39598 (size: 51.5 MB, free: 6.1 GB)
17/02/09 09:48:26,460 INFO BlockManagerInfo: Added rdd_5_37 in memory on 10.1.2.157:44819 (size: 52.8 MB, free: 6.1 GB)
17/02/09 09:48:26,464 INFO TaskSetManager: Finished task 32.0 in stage 1.0 (TID 41) in 2251 ms on 10.1.2.191 (48/64)
17/02/09 09:48:26,468 INFO BlockManagerInfo: Added rdd_5_63 in memory on 10.1.2.248:44197 (size: 52.2 MB, free: 6.1 GB)
17/02/09 09:48:26,471 INFO BlockManagerInfo: Added rdd_5_47 in memory on 10.1.2.174:36744 (size: 51.8 MB, free: 6.1 GB)
17/02/09 09:48:26,473 INFO TaskSetManager: Finished task 37.0 in stage 1.0 (TID 45) in 2252 ms on 10.1.2.157 (49/64)
17/02/09 09:48:26,477 INFO BlockManagerInfo: Added rdd_5_25 in memory on 10.1.2.174:36744 (size: 52.2 MB, free: 6.1 GB)
17/02/09 09:48:26,478 INFO BlockManagerInfo: Added rdd_5_56 in memory on 10.1.2.181:33148 (size: 52.6 MB, free: 6.1 GB)
17/02/09 09:48:26,479 INFO BlockManagerInfo: Added rdd_5_12 in memory on 10.1.2.69:43318 (size: 52.3 MB, free: 6.1 GB)
17/02/09 09:48:26,482 INFO TaskSetManager: Finished task 47.0 in stage 1.0 (TID 52) in 2249 ms on 10.1.2.174 (50/64)
17/02/09 09:48:26,488 INFO TaskSetManager: Finished task 56.0 in stage 1.0 (TID 59) in 2243 ms on 10.1.2.181 (51/64)
17/02/09 09:48:26,493 INFO TaskSetManager: Finished task 12.0 in stage 1.0 (TID 26) in 2307 ms on 10.1.2.69 (52/64)
17/02/09 09:48:26,495 INFO TaskSetManager: Finished task 63.0 in stage 1.0 (TID 64) in 2243 ms on 10.1.2.248 (53/64)
17/02/09 09:48:26,496 INFO TaskSetManager: Finished task 25.0 in stage 1.0 (TID 36) in 2293 ms on 10.1.2.174 (54/64)
17/02/09 09:48:26,502 INFO BlockManagerInfo: Added rdd_5_13 in memory on 10.1.2.181:33148 (size: 52.9 MB, free: 6.1 GB)
17/02/09 09:48:26,512 INFO TaskSetManager: Finished task 13.0 in stage 1.0 (TID 27) in 2324 ms on 10.1.2.181 (55/64)
17/02/09 09:48:26,526 INFO BlockManagerInfo: Added rdd_5_21 in memory on 10.1.2.248:44197 (size: 51.8 MB, free: 6.1 GB)
17/02/09 09:48:26,527 INFO BlockManagerInfo: Added rdd_5_33 in memory on 10.1.2.69:43318 (size: 51.2 MB, free: 6.1 GB)
17/02/09 09:48:26,535 INFO TaskSetManager: Finished task 21.0 in stage 1.0 (TID 33) in 2337 ms on 10.1.2.248 (56/64)
17/02/09 09:48:26,537 INFO BlockManagerInfo: Added rdd_5_51 in memory on 10.1.2.219:38976 (size: 51.1 MB, free: 6.1 GB)
17/02/09 09:48:26,541 INFO TaskSetManager: Finished task 33.0 in stage 1.0 (TID 42) in 2325 ms on 10.1.2.69 (57/64)
17/02/09 09:48:26,546 INFO TaskSetManager: Finished task 51.0 in stage 1.0 (TID 55) in 2306 ms on 10.1.2.219 (58/64)
17/02/09 09:48:28,110 INFO BlockManagerInfo: Added rdd_5_40 in memory on 10.1.2.122:42510 (size: 51.5 MB, free: 6.2 GB)
17/02/09 09:48:28,140 INFO BlockManagerInfo: Added rdd_5_52 in memory on 10.1.2.85:35336 (size: 51.9 MB, free: 6.2 GB)
17/02/09 09:48:28,161 INFO BlockManagerInfo: Added rdd_5_30 in memory on 10.1.2.85:35336 (size: 51.9 MB, free: 6.2 GB)
17/02/09 09:48:28,164 INFO TaskSetManager: Finished task 40.0 in stage 1.0 (TID 47) in 3940 ms on 10.1.2.122 (59/64)
17/02/09 09:48:28,185 INFO BlockManagerInfo: Added rdd_5_61 in memory on 10.1.2.122:42510 (size: 51.5 MB, free: 6.2 GB)
17/02/09 09:48:28,197 INFO TaskSetManager: Finished task 61.0 in stage 1.0 (TID 63) in 3945 ms on 10.1.2.122 (60/64)
17/02/09 09:48:28,211 INFO BlockManagerInfo: Added rdd_5_18 in memory on 10.1.2.122:42510 (size: 52.5 MB, free: 6.1 GB)
17/02/09 09:48:28,221 INFO TaskSetManager: Finished task 18.0 in stage 1.0 (TID 31) in 4025 ms on 10.1.2.122 (61/64)
17/02/09 09:48:28,230 INFO TaskSetManager: Finished task 52.0 in stage 1.0 (TID 56) in 3989 ms on 10.1.2.85 (62/64)
17/02/09 09:48:28,232 INFO TaskSetManager: Finished task 30.0 in stage 1.0 (TID 40) in 4021 ms on 10.1.2.85 (63/64)
17/02/09 09:48:28,240 INFO BlockManagerInfo: Added rdd_5_9 in memory on 10.1.2.85:35336 (size: 51.5 MB, free: 6.1 GB)
17/02/09 09:48:28,249 INFO TaskSetManager: Finished task 9.0 in stage 1.0 (TID 24) in 4066 ms on 10.1.2.85 (64/64)
17/02/09 09:48:28,249 INFO TaskSchedulerImpl: Removed TaskSet 1.0, whose tasks have all completed, from pool 
17/02/09 09:48:28,249 INFO DAGScheduler: ResultStage 1 (count at DataValidators.scala:40) finished in 7.428 s
17/02/09 09:48:28,250 INFO DAGScheduler: Job 1 finished: count at DataValidators.scala:40, took 7.464855 s
17/02/09 09:48:28,259 INFO SparkContext: Starting job: count at GradientDescent.scala:209
17/02/09 09:48:28,261 INFO DAGScheduler: Got job 2 (count at GradientDescent.scala:209) with 64 output partitions
17/02/09 09:48:28,261 INFO DAGScheduler: Final stage: ResultStage 2 (count at GradientDescent.scala:209)
17/02/09 09:48:28,261 INFO DAGScheduler: Parents of final stage: List()
17/02/09 09:48:28,263 INFO DAGScheduler: Missing parents: List()
17/02/09 09:48:28,264 INFO DAGScheduler: Submitting ResultStage 2 (MapPartitionsRDD[8] at map at GeneralizedLinearAlgorithm.scala:297), which has no missing parents
17/02/09 09:48:28,270 INFO MemoryStore: Block broadcast_3 stored as values in memory (estimated size 3.9 KB, free 6.3 GB)
17/02/09 09:48:28,272 INFO MemoryStore: Block broadcast_3_piece0 stored as bytes in memory (estimated size 2.2 KB, free 6.3 GB)
17/02/09 09:48:28,272 INFO BlockManagerInfo: Added broadcast_3_piece0 in memory on 10.1.2.238:40539 (size: 2.2 KB, free: 6.3 GB)
17/02/09 09:48:28,273 INFO SparkContext: Created broadcast 3 from broadcast at DAGScheduler.scala:1012
17/02/09 09:48:28,274 INFO DAGScheduler: Submitting 64 missing tasks from ResultStage 2 (MapPartitionsRDD[8] at map at GeneralizedLinearAlgorithm.scala:297)
17/02/09 09:48:28,275 INFO TaskSchedulerImpl: Adding task set 2.0 with 64 tasks
17/02/09 09:48:28,278 INFO TaskSetManager: Starting task 21.0 in stage 2.0 (TID 65, 10.1.2.248, partition 21, PROCESS_LOCAL, 5381 bytes)
17/02/09 09:48:28,279 INFO TaskSetManager: Starting task 14.0 in stage 2.0 (TID 66, 10.1.2.95, partition 14, PROCESS_LOCAL, 5381 bytes)
17/02/09 09:48:28,280 INFO TaskSetManager: Starting task 10.0 in stage 2.0 (TID 67, 10.1.2.191, partition 10, PROCESS_LOCAL, 5381 bytes)
17/02/09 09:48:28,280 INFO TaskSetManager: Starting task 7.0 in stage 2.0 (TID 68, 10.1.2.146, partition 7, PROCESS_LOCAL, 5381 bytes)
17/02/09 09:48:28,281 INFO TaskSetManager: Starting task 4.0 in stage 2.0 (TID 69, 10.1.2.174, partition 4, PROCESS_LOCAL, 5381 bytes)
17/02/09 09:48:28,282 INFO TaskSetManager: Starting task 1.0 in stage 2.0 (TID 70, 10.1.2.63, partition 1, PROCESS_LOCAL, 5381 bytes)
17/02/09 09:48:28,282 INFO TaskSetManager: Starting task 20.0 in stage 2.0 (TID 71, 10.1.2.129, partition 20, PROCESS_LOCAL, 5381 bytes)
17/02/09 09:48:28,283 INFO TaskSetManager: Starting task 2.0 in stage 2.0 (TID 72, 10.1.2.138, partition 2, PROCESS_LOCAL, 5381 bytes)
17/02/09 09:48:28,284 INFO TaskSetManager: Starting task 0.0 in stage 2.0 (TID 73, 10.1.2.25, partition 0, PROCESS_LOCAL, 5381 bytes)
17/02/09 09:48:28,284 INFO TaskSetManager: Starting task 18.0 in stage 2.0 (TID 74, 10.1.2.122, partition 18, PROCESS_LOCAL, 5381 bytes)
17/02/09 09:48:28,285 INFO TaskSetManager: Starting task 13.0 in stage 2.0 (TID 75, 10.1.2.181, partition 13, PROCESS_LOCAL, 5381 bytes)
17/02/09 09:48:28,286 INFO TaskSetManager: Starting task 6.0 in stage 2.0 (TID 76, 10.1.2.124, partition 6, PROCESS_LOCAL, 5381 bytes)
17/02/09 09:48:28,287 INFO TaskSetManager: Starting task 9.0 in stage 2.0 (TID 77, 10.1.2.85, partition 9, PROCESS_LOCAL, 5381 bytes)
17/02/09 09:48:28,287 INFO TaskSetManager: Starting task 8.0 in stage 2.0 (TID 78, 10.1.2.219, partition 8, PROCESS_LOCAL, 5381 bytes)
17/02/09 09:48:28,288 INFO TaskSetManager: Starting task 16.0 in stage 2.0 (TID 79, 10.1.2.157, partition 16, PROCESS_LOCAL, 5381 bytes)
17/02/09 09:48:28,289 INFO TaskSetManager: Starting task 12.0 in stage 2.0 (TID 80, 10.1.2.69, partition 12, PROCESS_LOCAL, 5381 bytes)
17/02/09 09:48:28,289 INFO TaskSetManager: Starting task 38.0 in stage 2.0 (TID 81, 10.1.2.248, partition 38, PROCESS_LOCAL, 5381 bytes)
17/02/09 09:48:28,290 INFO TaskSetManager: Starting task 35.0 in stage 2.0 (TID 82, 10.1.2.95, partition 35, PROCESS_LOCAL, 5381 bytes)
17/02/09 09:48:28,291 INFO TaskSetManager: Starting task 32.0 in stage 2.0 (TID 83, 10.1.2.191, partition 32, PROCESS_LOCAL, 5381 bytes)
17/02/09 09:48:28,291 INFO TaskSetManager: Starting task 17.0 in stage 2.0 (TID 84, 10.1.2.146, partition 17, PROCESS_LOCAL, 5381 bytes)
17/02/09 09:48:28,292 INFO TaskSetManager: Starting task 11.0 in stage 2.0 (TID 85, 10.1.2.174, partition 11, PROCESS_LOCAL, 5381 bytes)
17/02/09 09:48:28,293 INFO TaskSetManager: Starting task 3.0 in stage 2.0 (TID 86, 10.1.2.63, partition 3, PROCESS_LOCAL, 5381 bytes)
17/02/09 09:48:28,293 INFO TaskSetManager: Starting task 31.0 in stage 2.0 (TID 87, 10.1.2.129, partition 31, PROCESS_LOCAL, 5381 bytes)
17/02/09 09:48:28,294 INFO TaskSetManager: Starting task 23.0 in stage 2.0 (TID 88, 10.1.2.138, partition 23, PROCESS_LOCAL, 5381 bytes)
17/02/09 09:48:28,295 INFO TaskSetManager: Starting task 5.0 in stage 2.0 (TID 89, 10.1.2.25, partition 5, PROCESS_LOCAL, 5381 bytes)
17/02/09 09:48:28,295 INFO TaskSetManager: Starting task 40.0 in stage 2.0 (TID 90, 10.1.2.122, partition 40, PROCESS_LOCAL, 5381 bytes)
17/02/09 09:48:28,296 INFO TaskSetManager: Starting task 34.0 in stage 2.0 (TID 91, 10.1.2.181, partition 34, PROCESS_LOCAL, 5381 bytes)
17/02/09 09:48:28,297 INFO TaskSetManager: Starting task 28.0 in stage 2.0 (TID 92, 10.1.2.124, partition 28, PROCESS_LOCAL, 5381 bytes)
17/02/09 09:48:28,297 INFO TaskSetManager: Starting task 30.0 in stage 2.0 (TID 93, 10.1.2.85, partition 30, PROCESS_LOCAL, 5381 bytes)
17/02/09 09:48:28,298 INFO TaskSetManager: Starting task 29.0 in stage 2.0 (TID 94, 10.1.2.219, partition 29, PROCESS_LOCAL, 5381 bytes)
17/02/09 09:48:28,299 INFO TaskSetManager: Starting task 27.0 in stage 2.0 (TID 95, 10.1.2.157, partition 27, PROCESS_LOCAL, 5381 bytes)
17/02/09 09:48:28,299 INFO TaskSetManager: Starting task 19.0 in stage 2.0 (TID 96, 10.1.2.69, partition 19, PROCESS_LOCAL, 5381 bytes)
17/02/09 09:48:28,300 INFO TaskSetManager: Starting task 43.0 in stage 2.0 (TID 97, 10.1.2.248, partition 43, PROCESS_LOCAL, 5381 bytes)
17/02/09 09:48:28,301 INFO TaskSetManager: Starting task 36.0 in stage 2.0 (TID 98, 10.1.2.95, partition 36, PROCESS_LOCAL, 5381 bytes)
17/02/09 09:48:28,301 INFO TaskSetManager: Starting task 53.0 in stage 2.0 (TID 99, 10.1.2.191, partition 53, PROCESS_LOCAL, 5381 bytes)
17/02/09 09:48:28,302 INFO TaskSetManager: Starting task 39.0 in stage 2.0 (TID 100, 10.1.2.146, partition 39, PROCESS_LOCAL, 5381 bytes)
17/02/09 09:48:28,303 INFO TaskSetManager: Starting task 25.0 in stage 2.0 (TID 101, 10.1.2.174, partition 25, PROCESS_LOCAL, 5381 bytes)
17/02/09 09:48:28,303 INFO TaskSetManager: Starting task 22.0 in stage 2.0 (TID 102, 10.1.2.63, partition 22, PROCESS_LOCAL, 5381 bytes)
17/02/09 09:48:28,304 INFO TaskSetManager: Starting task 41.0 in stage 2.0 (TID 103, 10.1.2.129, partition 41, PROCESS_LOCAL, 5381 bytes)
17/02/09 09:48:28,304 INFO TaskSetManager: Starting task 24.0 in stage 2.0 (TID 104, 10.1.2.138, partition 24, PROCESS_LOCAL, 5381 bytes)
17/02/09 09:48:28,305 INFO TaskSetManager: Starting task 15.0 in stage 2.0 (TID 105, 10.1.2.25, partition 15, PROCESS_LOCAL, 5381 bytes)
17/02/09 09:48:28,306 INFO TaskSetManager: Starting task 61.0 in stage 2.0 (TID 106, 10.1.2.122, partition 61, PROCESS_LOCAL, 5381 bytes)
17/02/09 09:48:28,306 INFO TaskSetManager: Starting task 50.0 in stage 2.0 (TID 107, 10.1.2.181, partition 50, PROCESS_LOCAL, 5381 bytes)
17/02/09 09:48:28,307 INFO TaskSetManager: Starting task 42.0 in stage 2.0 (TID 108, 10.1.2.124, partition 42, PROCESS_LOCAL, 5381 bytes)
17/02/09 09:48:28,308 INFO TaskSetManager: Starting task 52.0 in stage 2.0 (TID 109, 10.1.2.85, partition 52, PROCESS_LOCAL, 5381 bytes)
17/02/09 09:48:28,308 INFO TaskSetManager: Starting task 51.0 in stage 2.0 (TID 110, 10.1.2.219, partition 51, PROCESS_LOCAL, 5381 bytes)
17/02/09 09:48:28,309 INFO TaskSetManager: Starting task 37.0 in stage 2.0 (TID 111, 10.1.2.157, partition 37, PROCESS_LOCAL, 5381 bytes)
17/02/09 09:48:28,309 INFO TaskSetManager: Starting task 33.0 in stage 2.0 (TID 112, 10.1.2.69, partition 33, PROCESS_LOCAL, 5381 bytes)
17/02/09 09:48:28,310 INFO TaskSetManager: Starting task 63.0 in stage 2.0 (TID 113, 10.1.2.248, partition 63, PROCESS_LOCAL, 5381 bytes)
17/02/09 09:48:28,311 INFO TaskSetManager: Starting task 57.0 in stage 2.0 (TID 114, 10.1.2.95, partition 57, PROCESS_LOCAL, 5381 bytes)
17/02/09 09:48:28,311 INFO TaskSetManager: Starting task 62.0 in stage 2.0 (TID 115, 10.1.2.191, partition 62, PROCESS_LOCAL, 5381 bytes)
17/02/09 09:48:28,312 INFO TaskSetManager: Starting task 60.0 in stage 2.0 (TID 116, 10.1.2.146, partition 60, PROCESS_LOCAL, 5381 bytes)
17/02/09 09:48:28,313 INFO TaskSetManager: Starting task 47.0 in stage 2.0 (TID 117, 10.1.2.174, partition 47, PROCESS_LOCAL, 5381 bytes)
17/02/09 09:48:28,313 INFO TaskSetManager: Starting task 44.0 in stage 2.0 (TID 118, 10.1.2.63, partition 44, PROCESS_LOCAL, 5381 bytes)
17/02/09 09:48:28,314 INFO TaskSetManager: Starting task 46.0 in stage 2.0 (TID 119, 10.1.2.129, partition 46, PROCESS_LOCAL, 5381 bytes)
17/02/09 09:48:28,314 INFO TaskSetManager: Starting task 45.0 in stage 2.0 (TID 120, 10.1.2.138, partition 45, PROCESS_LOCAL, 5381 bytes)
17/02/09 09:48:28,315 INFO TaskSetManager: Starting task 26.0 in stage 2.0 (TID 121, 10.1.2.25, partition 26, PROCESS_LOCAL, 5381 bytes)
17/02/09 09:48:28,316 INFO TaskSetManager: Starting task 56.0 in stage 2.0 (TID 122, 10.1.2.181, partition 56, PROCESS_LOCAL, 5381 bytes)
17/02/09 09:48:28,316 INFO TaskSetManager: Starting task 49.0 in stage 2.0 (TID 123, 10.1.2.124, partition 49, PROCESS_LOCAL, 5381 bytes)
17/02/09 09:48:28,317 INFO TaskSetManager: Starting task 54.0 in stage 2.0 (TID 124, 10.1.2.219, partition 54, PROCESS_LOCAL, 5381 bytes)
17/02/09 09:48:28,317 INFO TaskSetManager: Starting task 59.0 in stage 2.0 (TID 125, 10.1.2.157, partition 59, PROCESS_LOCAL, 5381 bytes)
17/02/09 09:48:28,318 INFO TaskSetManager: Starting task 55.0 in stage 2.0 (TID 126, 10.1.2.69, partition 55, PROCESS_LOCAL, 5381 bytes)
17/02/09 09:48:28,319 INFO CoarseGrainedSchedulerBackend$DriverEndpoint: Launching task 65 on executor id: 8 hostname: 10.1.2.248.
17/02/09 09:48:28,319 INFO CoarseGrainedSchedulerBackend$DriverEndpoint: Launching task 81 on executor id: 8 hostname: 10.1.2.248.
17/02/09 09:48:28,319 INFO CoarseGrainedSchedulerBackend$DriverEndpoint: Launching task 97 on executor id: 8 hostname: 10.1.2.248.
17/02/09 09:48:28,320 INFO CoarseGrainedSchedulerBackend$DriverEndpoint: Launching task 113 on executor id: 8 hostname: 10.1.2.248.
17/02/09 09:48:28,320 INFO CoarseGrainedSchedulerBackend$DriverEndpoint: Launching task 66 on executor id: 1 hostname: 10.1.2.95.
17/02/09 09:48:28,320 INFO CoarseGrainedSchedulerBackend$DriverEndpoint: Launching task 82 on executor id: 1 hostname: 10.1.2.95.
17/02/09 09:48:28,320 INFO CoarseGrainedSchedulerBackend$DriverEndpoint: Launching task 98 on executor id: 1 hostname: 10.1.2.95.
17/02/09 09:48:28,321 INFO CoarseGrainedSchedulerBackend$DriverEndpoint: Launching task 114 on executor id: 1 hostname: 10.1.2.95.
17/02/09 09:48:28,321 INFO CoarseGrainedSchedulerBackend$DriverEndpoint: Launching task 67 on executor id: 3 hostname: 10.1.2.191.
17/02/09 09:48:28,321 INFO CoarseGrainedSchedulerBackend$DriverEndpoint: Launching task 83 on executor id: 3 hostname: 10.1.2.191.
17/02/09 09:48:28,322 INFO CoarseGrainedSchedulerBackend$DriverEndpoint: Launching task 99 on executor id: 3 hostname: 10.1.2.191.
17/02/09 09:48:28,322 INFO CoarseGrainedSchedulerBackend$DriverEndpoint: Launching task 115 on executor id: 3 hostname: 10.1.2.191.
17/02/09 09:48:28,323 INFO CoarseGrainedSchedulerBackend$DriverEndpoint: Launching task 68 on executor id: 2 hostname: 10.1.2.146.
17/02/09 09:48:28,323 INFO CoarseGrainedSchedulerBackend$DriverEndpoint: Launching task 84 on executor id: 2 hostname: 10.1.2.146.
17/02/09 09:48:28,323 INFO CoarseGrainedSchedulerBackend$DriverEndpoint: Launching task 100 on executor id: 2 hostname: 10.1.2.146.
17/02/09 09:48:28,324 INFO CoarseGrainedSchedulerBackend$DriverEndpoint: Launching task 116 on executor id: 2 hostname: 10.1.2.146.
17/02/09 09:48:28,324 INFO CoarseGrainedSchedulerBackend$DriverEndpoint: Launching task 69 on executor id: 9 hostname: 10.1.2.174.
17/02/09 09:48:28,324 INFO CoarseGrainedSchedulerBackend$DriverEndpoint: Launching task 85 on executor id: 9 hostname: 10.1.2.174.
17/02/09 09:48:28,324 INFO CoarseGrainedSchedulerBackend$DriverEndpoint: Launching task 101 on executor id: 9 hostname: 10.1.2.174.
17/02/09 09:48:28,325 INFO CoarseGrainedSchedulerBackend$DriverEndpoint: Launching task 117 on executor id: 9 hostname: 10.1.2.174.
17/02/09 09:48:28,325 INFO CoarseGrainedSchedulerBackend$DriverEndpoint: Launching task 70 on executor id: 14 hostname: 10.1.2.63.
17/02/09 09:48:28,325 INFO CoarseGrainedSchedulerBackend$DriverEndpoint: Launching task 86 on executor id: 14 hostname: 10.1.2.63.
17/02/09 09:48:28,325 INFO CoarseGrainedSchedulerBackend$DriverEndpoint: Launching task 102 on executor id: 14 hostname: 10.1.2.63.
17/02/09 09:48:28,325 INFO CoarseGrainedSchedulerBackend$DriverEndpoint: Launching task 118 on executor id: 14 hostname: 10.1.2.63.
17/02/09 09:48:28,326 INFO CoarseGrainedSchedulerBackend$DriverEndpoint: Launching task 71 on executor id: 5 hostname: 10.1.2.129.
17/02/09 09:48:28,327 INFO CoarseGrainedSchedulerBackend$DriverEndpoint: Launching task 87 on executor id: 5 hostname: 10.1.2.129.
17/02/09 09:48:28,327 INFO CoarseGrainedSchedulerBackend$DriverEndpoint: Launching task 103 on executor id: 5 hostname: 10.1.2.129.
17/02/09 09:48:28,327 INFO CoarseGrainedSchedulerBackend$DriverEndpoint: Launching task 119 on executor id: 5 hostname: 10.1.2.129.
17/02/09 09:48:28,328 INFO CoarseGrainedSchedulerBackend$DriverEndpoint: Launching task 72 on executor id: 11 hostname: 10.1.2.138.
17/02/09 09:48:28,328 INFO CoarseGrainedSchedulerBackend$DriverEndpoint: Launching task 88 on executor id: 11 hostname: 10.1.2.138.
17/02/09 09:48:28,328 INFO CoarseGrainedSchedulerBackend$DriverEndpoint: Launching task 104 on executor id: 11 hostname: 10.1.2.138.
17/02/09 09:48:28,329 INFO CoarseGrainedSchedulerBackend$DriverEndpoint: Launching task 120 on executor id: 11 hostname: 10.1.2.138.
17/02/09 09:48:28,329 INFO CoarseGrainedSchedulerBackend$DriverEndpoint: Launching task 73 on executor id: 15 hostname: 10.1.2.25.
17/02/09 09:48:28,329 INFO CoarseGrainedSchedulerBackend$DriverEndpoint: Launching task 89 on executor id: 15 hostname: 10.1.2.25.
17/02/09 09:48:28,329 INFO CoarseGrainedSchedulerBackend$DriverEndpoint: Launching task 105 on executor id: 15 hostname: 10.1.2.25.
17/02/09 09:48:28,329 INFO CoarseGrainedSchedulerBackend$DriverEndpoint: Launching task 121 on executor id: 15 hostname: 10.1.2.25.
17/02/09 09:48:28,330 INFO CoarseGrainedSchedulerBackend$DriverEndpoint: Launching task 74 on executor id: 10 hostname: 10.1.2.122.
17/02/09 09:48:28,330 INFO CoarseGrainedSchedulerBackend$DriverEndpoint: Launching task 90 on executor id: 10 hostname: 10.1.2.122.
17/02/09 09:48:28,330 INFO CoarseGrainedSchedulerBackend$DriverEndpoint: Launching task 106 on executor id: 10 hostname: 10.1.2.122.
17/02/09 09:48:28,330 INFO CoarseGrainedSchedulerBackend$DriverEndpoint: Launching task 75 on executor id: 4 hostname: 10.1.2.181.
17/02/09 09:48:28,330 INFO CoarseGrainedSchedulerBackend$DriverEndpoint: Launching task 91 on executor id: 4 hostname: 10.1.2.181.
17/02/09 09:48:28,331 INFO CoarseGrainedSchedulerBackend$DriverEndpoint: Launching task 107 on executor id: 4 hostname: 10.1.2.181.
17/02/09 09:48:28,331 INFO CoarseGrainedSchedulerBackend$DriverEndpoint: Launching task 122 on executor id: 4 hostname: 10.1.2.181.
17/02/09 09:48:28,331 INFO CoarseGrainedSchedulerBackend$DriverEndpoint: Launching task 76 on executor id: 6 hostname: 10.1.2.124.
17/02/09 09:48:28,331 INFO CoarseGrainedSchedulerBackend$DriverEndpoint: Launching task 92 on executor id: 6 hostname: 10.1.2.124.
17/02/09 09:48:28,332 INFO CoarseGrainedSchedulerBackend$DriverEndpoint: Launching task 108 on executor id: 6 hostname: 10.1.2.124.
17/02/09 09:48:28,332 INFO CoarseGrainedSchedulerBackend$DriverEndpoint: Launching task 123 on executor id: 6 hostname: 10.1.2.124.
17/02/09 09:48:28,333 INFO CoarseGrainedSchedulerBackend$DriverEndpoint: Launching task 77 on executor id: 7 hostname: 10.1.2.85.
17/02/09 09:48:28,333 INFO CoarseGrainedSchedulerBackend$DriverEndpoint: Launching task 93 on executor id: 7 hostname: 10.1.2.85.
17/02/09 09:48:28,333 INFO CoarseGrainedSchedulerBackend$DriverEndpoint: Launching task 109 on executor id: 7 hostname: 10.1.2.85.
17/02/09 09:48:28,333 INFO CoarseGrainedSchedulerBackend$DriverEndpoint: Launching task 78 on executor id: 12 hostname: 10.1.2.219.
17/02/09 09:48:28,334 INFO CoarseGrainedSchedulerBackend$DriverEndpoint: Launching task 94 on executor id: 12 hostname: 10.1.2.219.
17/02/09 09:48:28,334 INFO CoarseGrainedSchedulerBackend$DriverEndpoint: Launching task 110 on executor id: 12 hostname: 10.1.2.219.
17/02/09 09:48:28,335 INFO CoarseGrainedSchedulerBackend$DriverEndpoint: Launching task 124 on executor id: 12 hostname: 10.1.2.219.
17/02/09 09:48:28,335 INFO CoarseGrainedSchedulerBackend$DriverEndpoint: Launching task 79 on executor id: 0 hostname: 10.1.2.157.
17/02/09 09:48:28,336 INFO CoarseGrainedSchedulerBackend$DriverEndpoint: Launching task 95 on executor id: 0 hostname: 10.1.2.157.
17/02/09 09:48:28,336 INFO CoarseGrainedSchedulerBackend$DriverEndpoint: Launching task 111 on executor id: 0 hostname: 10.1.2.157.
17/02/09 09:48:28,336 INFO CoarseGrainedSchedulerBackend$DriverEndpoint: Launching task 125 on executor id: 0 hostname: 10.1.2.157.
17/02/09 09:48:28,336 INFO CoarseGrainedSchedulerBackend$DriverEndpoint: Launching task 80 on executor id: 13 hostname: 10.1.2.69.
17/02/09 09:48:28,337 INFO CoarseGrainedSchedulerBackend$DriverEndpoint: Launching task 96 on executor id: 13 hostname: 10.1.2.69.
17/02/09 09:48:28,337 INFO CoarseGrainedSchedulerBackend$DriverEndpoint: Launching task 112 on executor id: 13 hostname: 10.1.2.69.
17/02/09 09:48:28,337 INFO CoarseGrainedSchedulerBackend$DriverEndpoint: Launching task 126 on executor id: 13 hostname: 10.1.2.69.
17/02/09 09:48:28,357 INFO BlockManagerInfo: Added broadcast_3_piece0 in memory on 10.1.2.248:44197 (size: 2.2 KB, free: 6.1 GB)
17/02/09 09:48:28,359 INFO BlockManagerInfo: Added broadcast_3_piece0 in memory on 10.1.2.146:36356 (size: 2.2 KB, free: 6.1 GB)
17/02/09 09:48:28,360 INFO BlockManagerInfo: Added broadcast_3_piece0 in memory on 10.1.2.191:39598 (size: 2.2 KB, free: 6.1 GB)
17/02/09 09:48:28,367 INFO BlockManagerInfo: Added broadcast_3_piece0 in memory on 10.1.2.129:35547 (size: 2.2 KB, free: 6.1 GB)
17/02/09 09:48:28,368 INFO BlockManagerInfo: Added broadcast_3_piece0 in memory on 10.1.2.25:39678 (size: 2.2 KB, free: 6.0 GB)
17/02/09 09:48:28,369 INFO BlockManagerInfo: Added broadcast_3_piece0 in memory on 10.1.2.95:38307 (size: 2.2 KB, free: 6.1 GB)
17/02/09 09:48:28,370 INFO BlockManagerInfo: Added broadcast_3_piece0 in memory on 10.1.2.181:33148 (size: 2.2 KB, free: 6.1 GB)
17/02/09 09:48:28,375 INFO BlockManagerInfo: Added broadcast_3_piece0 in memory on 10.1.2.174:36744 (size: 2.2 KB, free: 6.1 GB)
17/02/09 09:48:28,376 INFO BlockManagerInfo: Added broadcast_3_piece0 in memory on 10.1.2.138:43390 (size: 2.2 KB, free: 6.1 GB)
17/02/09 09:48:28,384 INFO BlockManagerInfo: Added broadcast_3_piece0 in memory on 10.1.2.69:43318 (size: 2.2 KB, free: 6.1 GB)
17/02/09 09:48:28,386 INFO BlockManagerInfo: Added broadcast_3_piece0 in memory on 10.1.2.219:38976 (size: 2.2 KB, free: 6.1 GB)
17/02/09 09:48:28,392 INFO TaskSetManager: Starting task 48.0 in stage 2.0 (TID 127, 10.1.2.25, partition 48, PROCESS_LOCAL, 5381 bytes)
17/02/09 09:48:28,393 INFO CoarseGrainedSchedulerBackend$DriverEndpoint: Launching task 127 on executor id: 15 hostname: 10.1.2.25.
17/02/09 09:48:28,393 INFO TaskSetManager: Finished task 26.0 in stage 2.0 (TID 121) in 79 ms on 10.1.2.25 (1/64)
17/02/09 09:48:28,394 INFO TaskSetManager: Starting task 58.0 in stage 2.0 (TID 128, 10.1.2.25, partition 58, PROCESS_LOCAL, 5381 bytes)
17/02/09 09:48:28,395 INFO CoarseGrainedSchedulerBackend$DriverEndpoint: Launching task 128 on executor id: 15 hostname: 10.1.2.25.
17/02/09 09:48:28,395 INFO TaskSetManager: Finished task 0.0 in stage 2.0 (TID 73) in 112 ms on 10.1.2.25 (2/64)
17/02/09 09:48:28,397 INFO TaskSetManager: Finished task 5.0 in stage 2.0 (TID 89) in 103 ms on 10.1.2.25 (3/64)
17/02/09 09:48:28,398 INFO TaskSetManager: Finished task 15.0 in stage 2.0 (TID 105) in 93 ms on 10.1.2.25 (4/64)
17/02/09 09:48:28,402 INFO TaskSetManager: Finished task 31.0 in stage 2.0 (TID 87) in 109 ms on 10.1.2.129 (5/64)
17/02/09 09:48:28,405 INFO TaskSetManager: Finished task 20.0 in stage 2.0 (TID 71) in 123 ms on 10.1.2.129 (6/64)
17/02/09 09:48:28,407 INFO TaskSetManager: Finished task 41.0 in stage 2.0 (TID 103) in 103 ms on 10.1.2.129 (7/64)
17/02/09 09:48:28,408 INFO TaskSetManager: Finished task 23.0 in stage 2.0 (TID 88) in 115 ms on 10.1.2.138 (8/64)
17/02/09 09:48:28,410 INFO TaskSetManager: Finished task 46.0 in stage 2.0 (TID 119) in 97 ms on 10.1.2.129 (9/64)
17/02/09 09:48:28,411 INFO TaskSetManager: Finished task 24.0 in stage 2.0 (TID 104) in 107 ms on 10.1.2.138 (10/64)
17/02/09 09:48:28,412 INFO TaskSetManager: Finished task 48.0 in stage 2.0 (TID 127) in 21 ms on 10.1.2.25 (11/64)
17/02/09 09:48:28,412 INFO TaskSetManager: Finished task 45.0 in stage 2.0 (TID 120) in 98 ms on 10.1.2.138 (12/64)
17/02/09 09:48:28,413 INFO TaskSetManager: Finished task 2.0 in stage 2.0 (TID 72) in 130 ms on 10.1.2.138 (13/64)
17/02/09 09:48:28,415 INFO TaskSetManager: Finished task 10.0 in stage 2.0 (TID 67) in 136 ms on 10.1.2.191 (14/64)
17/02/09 09:48:28,416 INFO TaskSetManager: Finished task 50.0 in stage 2.0 (TID 107) in 110 ms on 10.1.2.181 (15/64)
17/02/09 09:48:28,418 INFO BlockManagerInfo: Added broadcast_3_piece0 in memory on 10.1.2.63:45802 (size: 2.2 KB, free: 6.1 GB)
17/02/09 09:48:28,419 INFO TaskSetManager: Finished task 56.0 in stage 2.0 (TID 122) in 104 ms on 10.1.2.181 (16/64)
17/02/09 09:48:28,419 INFO TaskSetManager: Finished task 58.0 in stage 2.0 (TID 128) in 25 ms on 10.1.2.25 (17/64)
17/02/09 09:48:28,420 INFO TaskSetManager: Finished task 34.0 in stage 2.0 (TID 91) in 125 ms on 10.1.2.181 (18/64)
17/02/09 09:48:28,421 INFO TaskSetManager: Finished task 13.0 in stage 2.0 (TID 75) in 137 ms on 10.1.2.181 (19/64)
17/02/09 09:48:28,421 INFO TaskSetManager: Finished task 39.0 in stage 2.0 (TID 100) in 120 ms on 10.1.2.146 (20/64)
17/02/09 09:48:28,422 INFO TaskSetManager: Finished task 19.0 in stage 2.0 (TID 96) in 123 ms on 10.1.2.69 (21/64)
17/02/09 09:48:28,422 INFO TaskSetManager: Finished task 12.0 in stage 2.0 (TID 80) in 134 ms on 10.1.2.69 (22/64)
17/02/09 09:48:28,424 INFO TaskSetManager: Finished task 63.0 in stage 2.0 (TID 113) in 115 ms on 10.1.2.248 (23/64)
17/02/09 09:48:28,424 INFO TaskSetManager: Finished task 21.0 in stage 2.0 (TID 65) in 147 ms on 10.1.2.248 (24/64)
17/02/09 09:48:28,425 INFO TaskSetManager: Finished task 33.0 in stage 2.0 (TID 112) in 116 ms on 10.1.2.69 (25/64)
17/02/09 09:48:28,425 INFO TaskSetManager: Finished task 38.0 in stage 2.0 (TID 81) in 136 ms on 10.1.2.248 (26/64)
17/02/09 09:48:28,426 INFO TaskSetManager: Finished task 43.0 in stage 2.0 (TID 97) in 125 ms on 10.1.2.248 (27/64)
17/02/09 09:48:28,426 INFO TaskSetManager: Finished task 55.0 in stage 2.0 (TID 126) in 108 ms on 10.1.2.69 (28/64)
17/02/09 09:48:28,427 INFO TaskSetManager: Finished task 53.0 in stage 2.0 (TID 99) in 125 ms on 10.1.2.191 (29/64)
17/02/09 09:48:28,427 INFO TaskSetManager: Finished task 62.0 in stage 2.0 (TID 115) in 116 ms on 10.1.2.191 (30/64)
17/02/09 09:48:28,429 INFO TaskSetManager: Finished task 25.0 in stage 2.0 (TID 101) in 127 ms on 10.1.2.174 (31/64)
17/02/09 09:48:28,429 INFO TaskSetManager: Finished task 35.0 in stage 2.0 (TID 82) in 140 ms on 10.1.2.95 (32/64)
17/02/09 09:48:28,430 INFO TaskSetManager: Finished task 17.0 in stage 2.0 (TID 84) in 139 ms on 10.1.2.146 (33/64)
17/02/09 09:48:28,430 INFO TaskSetManager: Finished task 14.0 in stage 2.0 (TID 66) in 152 ms on 10.1.2.95 (34/64)
17/02/09 09:48:28,431 INFO TaskSetManager: Finished task 4.0 in stage 2.0 (TID 69) in 151 ms on 10.1.2.174 (35/64)
17/02/09 09:48:28,431 INFO TaskSetManager: Finished task 32.0 in stage 2.0 (TID 83) in 141 ms on 10.1.2.191 (36/64)
17/02/09 09:48:28,431 INFO TaskSetManager: Finished task 47.0 in stage 2.0 (TID 117) in 119 ms on 10.1.2.174 (37/64)
17/02/09 09:48:28,432 INFO TaskSetManager: Finished task 36.0 in stage 2.0 (TID 98) in 131 ms on 10.1.2.95 (38/64)
17/02/09 09:48:28,432 INFO BlockManagerInfo: Added broadcast_3_piece0 in memory on 10.1.2.124:34192 (size: 2.2 KB, free: 6.1 GB)
17/02/09 09:48:28,432 INFO TaskSetManager: Finished task 57.0 in stage 2.0 (TID 114) in 122 ms on 10.1.2.95 (39/64)
17/02/09 09:48:28,434 INFO TaskSetManager: Finished task 54.0 in stage 2.0 (TID 124) in 118 ms on 10.1.2.219 (40/64)
17/02/09 09:48:28,434 INFO TaskSetManager: Finished task 11.0 in stage 2.0 (TID 85) in 143 ms on 10.1.2.174 (41/64)
17/02/09 09:48:28,435 INFO TaskSetManager: Finished task 7.0 in stage 2.0 (TID 68) in 155 ms on 10.1.2.146 (42/64)
17/02/09 09:48:28,435 INFO BlockManagerInfo: Added broadcast_3_piece0 in memory on 10.1.2.157:44819 (size: 2.2 KB, free: 6.1 GB)
17/02/09 09:48:28,436 INFO TaskSetManager: Finished task 8.0 in stage 2.0 (TID 78) in 149 ms on 10.1.2.219 (43/64)
17/02/09 09:48:28,439 INFO BlockManagerInfo: Added broadcast_3_piece0 in memory on 10.1.2.122:42510 (size: 2.2 KB, free: 6.1 GB)
17/02/09 09:48:28,442 INFO TaskSetManager: Finished task 29.0 in stage 2.0 (TID 94) in 144 ms on 10.1.2.219 (44/64)
17/02/09 09:48:28,443 INFO TaskSetManager: Finished task 51.0 in stage 2.0 (TID 110) in 135 ms on 10.1.2.219 (45/64)
17/02/09 09:48:28,451 INFO TaskSetManager: Finished task 1.0 in stage 2.0 (TID 70) in 170 ms on 10.1.2.63 (46/64)
17/02/09 09:48:28,452 INFO TaskSetManager: Finished task 44.0 in stage 2.0 (TID 118) in 139 ms on 10.1.2.63 (47/64)
17/02/09 09:48:28,452 INFO BlockManagerInfo: Added broadcast_3_piece0 in memory on 10.1.2.85:35336 (size: 2.2 KB, free: 6.1 GB)
17/02/09 09:48:28,454 INFO TaskSetManager: Finished task 22.0 in stage 2.0 (TID 102) in 151 ms on 10.1.2.63 (48/64)
17/02/09 09:48:28,454 INFO TaskSetManager: Finished task 3.0 in stage 2.0 (TID 86) in 162 ms on 10.1.2.63 (49/64)
17/02/09 09:48:28,465 INFO TaskSetManager: Finished task 59.0 in stage 2.0 (TID 125) in 147 ms on 10.1.2.157 (50/64)
17/02/09 09:48:28,467 INFO TaskSetManager: Finished task 37.0 in stage 2.0 (TID 111) in 159 ms on 10.1.2.157 (51/64)
17/02/09 09:48:28,468 INFO TaskSetManager: Finished task 16.0 in stage 2.0 (TID 79) in 181 ms on 10.1.2.157 (52/64)
17/02/09 09:48:28,470 INFO TaskSetManager: Finished task 27.0 in stage 2.0 (TID 95) in 171 ms on 10.1.2.157 (53/64)
17/02/09 09:48:28,478 INFO TaskSetManager: Finished task 6.0 in stage 2.0 (TID 76) in 193 ms on 10.1.2.124 (54/64)
17/02/09 09:48:28,480 INFO TaskSetManager: Finished task 60.0 in stage 2.0 (TID 116) in 169 ms on 10.1.2.146 (55/64)
17/02/09 09:48:28,483 INFO TaskSetManager: Finished task 28.0 in stage 2.0 (TID 92) in 187 ms on 10.1.2.124 (56/64)
17/02/09 09:48:28,484 INFO TaskSetManager: Finished task 42.0 in stage 2.0 (TID 108) in 177 ms on 10.1.2.124 (57/64)
17/02/09 09:48:28,485 INFO TaskSetManager: Finished task 49.0 in stage 2.0 (TID 123) in 169 ms on 10.1.2.124 (58/64)
17/02/09 09:48:28,489 INFO TaskSetManager: Finished task 30.0 in stage 2.0 (TID 93) in 191 ms on 10.1.2.85 (59/64)
17/02/09 09:48:28,490 INFO TaskSetManager: Finished task 9.0 in stage 2.0 (TID 77) in 204 ms on 10.1.2.85 (60/64)
17/02/09 09:48:28,492 INFO TaskSetManager: Finished task 52.0 in stage 2.0 (TID 109) in 185 ms on 10.1.2.85 (61/64)
17/02/09 09:48:28,503 INFO TaskSetManager: Finished task 40.0 in stage 2.0 (TID 90) in 207 ms on 10.1.2.122 (62/64)
17/02/09 09:48:28,503 INFO TaskSetManager: Finished task 18.0 in stage 2.0 (TID 74) in 219 ms on 10.1.2.122 (63/64)
17/02/09 09:48:28,504 INFO TaskSetManager: Finished task 61.0 in stage 2.0 (TID 106) in 199 ms on 10.1.2.122 (64/64)
17/02/09 09:48:28,504 INFO TaskSchedulerImpl: Removed TaskSet 2.0, whose tasks have all completed, from pool 
17/02/09 09:48:28,505 INFO DAGScheduler: ResultStage 2 (count at GradientDescent.scala:209) finished in 0.227 s
17/02/09 09:48:28,505 INFO DAGScheduler: Job 2 finished: count at GradientDescent.scala:209, took 0.245886 s
17/02/09 09:48:28,752 WARN BLAS: Failed to load implementation from: com.github.fommil.netlib.NativeSystemBLAS
17/02/09 09:48:28,753 WARN BLAS: Failed to load implementation from: com.github.fommil.netlib.NativeRefBLAS
17/02/09 09:48:28,908 INFO MemoryStore: Block broadcast_4 stored as values in memory (estimated size 24.7 MB, free 6.3 GB)
17/02/09 09:48:28,959 INFO MemoryStore: Block broadcast_4_piece0 stored as bytes in memory (estimated size 123.4 KB, free 6.3 GB)
17/02/09 09:48:28,959 INFO BlockManagerInfo: Added broadcast_4_piece0 in memory on 10.1.2.238:40539 (size: 123.4 KB, free: 6.3 GB)
17/02/09 09:48:28,960 INFO SparkContext: Created broadcast 4 from broadcast at GradientDescent.scala:235
17/02/09 09:48:29,059 INFO SparkContext: Starting job: treeAggregate at GradientDescent.scala:239
17/02/09 09:48:29,065 INFO DAGScheduler: Registering RDD 11 (treeAggregate at GradientDescent.scala:239)
17/02/09 09:48:29,066 INFO DAGScheduler: Got job 3 (treeAggregate at GradientDescent.scala:239) with 8 output partitions
17/02/09 09:48:29,066 INFO DAGScheduler: Final stage: ResultStage 4 (treeAggregate at GradientDescent.scala:239)
17/02/09 09:48:29,066 INFO DAGScheduler: Parents of final stage: List(ShuffleMapStage 3)
17/02/09 09:48:29,066 INFO DAGScheduler: Missing parents: List(ShuffleMapStage 3)
17/02/09 09:48:29,070 INFO DAGScheduler: Submitting ShuffleMapStage 3 (MapPartitionsRDD[11] at treeAggregate at GradientDescent.scala:239), which has no missing parents
17/02/09 09:48:29,141 INFO MemoryStore: Block broadcast_5 stored as values in memory (estimated size 24.7 MB, free 6.2 GB)
17/02/09 09:48:29,159 INFO MemoryStore: Block broadcast_5_piece0 stored as bytes in memory (estimated size 127.2 KB, free 6.2 GB)
17/02/09 09:48:29,160 INFO BlockManagerInfo: Added broadcast_5_piece0 in memory on 10.1.2.238:40539 (size: 127.2 KB, free: 6.3 GB)
17/02/09 09:48:29,161 INFO SparkContext: Created broadcast 5 from broadcast at DAGScheduler.scala:1012
17/02/09 09:48:29,164 INFO DAGScheduler: Submitting 64 missing tasks from ShuffleMapStage 3 (MapPartitionsRDD[11] at treeAggregate at GradientDescent.scala:239)
17/02/09 09:48:29,164 INFO TaskSchedulerImpl: Adding task set 3.0 with 64 tasks
17/02/09 09:48:29,169 INFO TaskSetManager: Starting task 4.0 in stage 3.0 (TID 129, 10.1.2.174, partition 4, PROCESS_LOCAL, 5570 bytes)
17/02/09 09:48:29,169 INFO TaskSetManager: Starting task 12.0 in stage 3.0 (TID 130, 10.1.2.69, partition 12, PROCESS_LOCAL, 5570 bytes)
17/02/09 09:48:29,170 INFO TaskSetManager: Starting task 13.0 in stage 3.0 (TID 131, 10.1.2.181, partition 13, PROCESS_LOCAL, 5570 bytes)
17/02/09 09:48:29,171 INFO TaskSetManager: Starting task 21.0 in stage 3.0 (TID 132, 10.1.2.248, partition 21, PROCESS_LOCAL, 5570 bytes)
17/02/09 09:48:29,171 INFO TaskSetManager: Starting task 10.0 in stage 3.0 (TID 133, 10.1.2.191, partition 10, PROCESS_LOCAL, 5570 bytes)
17/02/09 09:48:29,172 INFO TaskSetManager: Starting task 8.0 in stage 3.0 (TID 134, 10.1.2.219, partition 8, PROCESS_LOCAL, 5570 bytes)
17/02/09 09:48:29,173 INFO TaskSetManager: Starting task 2.0 in stage 3.0 (TID 135, 10.1.2.138, partition 2, PROCESS_LOCAL, 5570 bytes)
17/02/09 09:48:29,173 INFO TaskSetManager: Starting task 6.0 in stage 3.0 (TID 136, 10.1.2.124, partition 6, PROCESS_LOCAL, 5570 bytes)
17/02/09 09:48:29,174 INFO TaskSetManager: Starting task 0.0 in stage 3.0 (TID 137, 10.1.2.25, partition 0, PROCESS_LOCAL, 5570 bytes)
17/02/09 09:48:29,175 INFO TaskSetManager: Starting task 9.0 in stage 3.0 (TID 138, 10.1.2.85, partition 9, PROCESS_LOCAL, 5570 bytes)
17/02/09 09:48:29,175 INFO TaskSetManager: Starting task 18.0 in stage 3.0 (TID 139, 10.1.2.122, partition 18, PROCESS_LOCAL, 5570 bytes)
17/02/09 09:48:29,176 INFO TaskSetManager: Starting task 20.0 in stage 3.0 (TID 140, 10.1.2.129, partition 20, PROCESS_LOCAL, 5570 bytes)
17/02/09 09:48:29,176 INFO TaskSetManager: Starting task 16.0 in stage 3.0 (TID 141, 10.1.2.157, partition 16, PROCESS_LOCAL, 5570 bytes)
17/02/09 09:48:29,177 INFO TaskSetManager: Starting task 7.0 in stage 3.0 (TID 142, 10.1.2.146, partition 7, PROCESS_LOCAL, 5570 bytes)
17/02/09 09:48:29,178 INFO TaskSetManager: Starting task 14.0 in stage 3.0 (TID 143, 10.1.2.95, partition 14, PROCESS_LOCAL, 5570 bytes)
17/02/09 09:48:29,178 INFO TaskSetManager: Starting task 1.0 in stage 3.0 (TID 144, 10.1.2.63, partition 1, PROCESS_LOCAL, 5570 bytes)
17/02/09 09:48:29,179 INFO TaskSetManager: Starting task 11.0 in stage 3.0 (TID 145, 10.1.2.174, partition 11, PROCESS_LOCAL, 5570 bytes)
17/02/09 09:48:29,179 INFO TaskSetManager: Starting task 19.0 in stage 3.0 (TID 146, 10.1.2.69, partition 19, PROCESS_LOCAL, 5570 bytes)
17/02/09 09:48:29,180 INFO TaskSetManager: Starting task 34.0 in stage 3.0 (TID 147, 10.1.2.181, partition 34, PROCESS_LOCAL, 5570 bytes)
17/02/09 09:48:29,181 INFO TaskSetManager: Starting task 38.0 in stage 3.0 (TID 148, 10.1.2.248, partition 38, PROCESS_LOCAL, 5570 bytes)
17/02/09 09:48:29,181 INFO TaskSetManager: Starting task 32.0 in stage 3.0 (TID 149, 10.1.2.191, partition 32, PROCESS_LOCAL, 5570 bytes)
17/02/09 09:48:29,182 INFO TaskSetManager: Starting task 29.0 in stage 3.0 (TID 150, 10.1.2.219, partition 29, PROCESS_LOCAL, 5570 bytes)
17/02/09 09:48:29,182 INFO TaskSetManager: Starting task 23.0 in stage 3.0 (TID 151, 10.1.2.138, partition 23, PROCESS_LOCAL, 5570 bytes)
17/02/09 09:48:29,183 INFO TaskSetManager: Starting task 28.0 in stage 3.0 (TID 152, 10.1.2.124, partition 28, PROCESS_LOCAL, 5570 bytes)
17/02/09 09:48:29,183 INFO TaskSetManager: Starting task 5.0 in stage 3.0 (TID 153, 10.1.2.25, partition 5, PROCESS_LOCAL, 5570 bytes)
17/02/09 09:48:29,184 INFO TaskSetManager: Starting task 30.0 in stage 3.0 (TID 154, 10.1.2.85, partition 30, PROCESS_LOCAL, 5570 bytes)
17/02/09 09:48:29,185 INFO TaskSetManager: Starting task 40.0 in stage 3.0 (TID 155, 10.1.2.122, partition 40, PROCESS_LOCAL, 5570 bytes)
17/02/09 09:48:29,185 INFO TaskSetManager: Starting task 31.0 in stage 3.0 (TID 156, 10.1.2.129, partition 31, PROCESS_LOCAL, 5570 bytes)
17/02/09 09:48:29,186 INFO TaskSetManager: Starting task 27.0 in stage 3.0 (TID 157, 10.1.2.157, partition 27, PROCESS_LOCAL, 5570 bytes)
17/02/09 09:48:29,186 INFO TaskSetManager: Starting task 17.0 in stage 3.0 (TID 158, 10.1.2.146, partition 17, PROCESS_LOCAL, 5570 bytes)
17/02/09 09:48:29,187 INFO TaskSetManager: Starting task 35.0 in stage 3.0 (TID 159, 10.1.2.95, partition 35, PROCESS_LOCAL, 5570 bytes)
17/02/09 09:48:29,188 INFO TaskSetManager: Starting task 3.0 in stage 3.0 (TID 160, 10.1.2.63, partition 3, PROCESS_LOCAL, 5570 bytes)
17/02/09 09:48:29,188 INFO TaskSetManager: Starting task 25.0 in stage 3.0 (TID 161, 10.1.2.174, partition 25, PROCESS_LOCAL, 5570 bytes)
17/02/09 09:48:29,189 INFO TaskSetManager: Starting task 33.0 in stage 3.0 (TID 162, 10.1.2.69, partition 33, PROCESS_LOCAL, 5570 bytes)
17/02/09 09:48:29,190 INFO TaskSetManager: Starting task 50.0 in stage 3.0 (TID 163, 10.1.2.181, partition 50, PROCESS_LOCAL, 5570 bytes)
17/02/09 09:48:29,190 INFO TaskSetManager: Starting task 43.0 in stage 3.0 (TID 164, 10.1.2.248, partition 43, PROCESS_LOCAL, 5570 bytes)
17/02/09 09:48:29,191 INFO TaskSetManager: Starting task 53.0 in stage 3.0 (TID 165, 10.1.2.191, partition 53, PROCESS_LOCAL, 5570 bytes)
17/02/09 09:48:29,191 INFO TaskSetManager: Starting task 51.0 in stage 3.0 (TID 166, 10.1.2.219, partition 51, PROCESS_LOCAL, 5570 bytes)
17/02/09 09:48:29,192 INFO TaskSetManager: Starting task 24.0 in stage 3.0 (TID 167, 10.1.2.138, partition 24, PROCESS_LOCAL, 5570 bytes)
17/02/09 09:48:29,193 INFO TaskSetManager: Starting task 42.0 in stage 3.0 (TID 168, 10.1.2.124, partition 42, PROCESS_LOCAL, 5570 bytes)
17/02/09 09:48:29,193 INFO TaskSetManager: Starting task 15.0 in stage 3.0 (TID 169, 10.1.2.25, partition 15, PROCESS_LOCAL, 5570 bytes)
17/02/09 09:48:29,194 INFO TaskSetManager: Starting task 52.0 in stage 3.0 (TID 170, 10.1.2.85, partition 52, PROCESS_LOCAL, 5570 bytes)
17/02/09 09:48:29,195 INFO TaskSetManager: Starting task 61.0 in stage 3.0 (TID 171, 10.1.2.122, partition 61, PROCESS_LOCAL, 5570 bytes)
17/02/09 09:48:29,195 INFO TaskSetManager: Starting task 41.0 in stage 3.0 (TID 172, 10.1.2.129, partition 41, PROCESS_LOCAL, 5570 bytes)
17/02/09 09:48:29,196 INFO TaskSetManager: Starting task 37.0 in stage 3.0 (TID 173, 10.1.2.157, partition 37, PROCESS_LOCAL, 5570 bytes)
17/02/09 09:48:29,196 INFO TaskSetManager: Starting task 39.0 in stage 3.0 (TID 174, 10.1.2.146, partition 39, PROCESS_LOCAL, 5570 bytes)
17/02/09 09:48:29,197 INFO TaskSetManager: Starting task 36.0 in stage 3.0 (TID 175, 10.1.2.95, partition 36, PROCESS_LOCAL, 5570 bytes)
17/02/09 09:48:29,198 INFO TaskSetManager: Starting task 22.0 in stage 3.0 (TID 176, 10.1.2.63, partition 22, PROCESS_LOCAL, 5570 bytes)
17/02/09 09:48:29,198 INFO TaskSetManager: Starting task 47.0 in stage 3.0 (TID 177, 10.1.2.174, partition 47, PROCESS_LOCAL, 5570 bytes)
17/02/09 09:48:29,199 INFO TaskSetManager: Starting task 55.0 in stage 3.0 (TID 178, 10.1.2.69, partition 55, PROCESS_LOCAL, 5570 bytes)
17/02/09 09:48:29,199 INFO TaskSetManager: Starting task 56.0 in stage 3.0 (TID 179, 10.1.2.181, partition 56, PROCESS_LOCAL, 5570 bytes)
17/02/09 09:48:29,200 INFO TaskSetManager: Starting task 63.0 in stage 3.0 (TID 180, 10.1.2.248, partition 63, PROCESS_LOCAL, 5570 bytes)
17/02/09 09:48:29,201 INFO TaskSetManager: Starting task 62.0 in stage 3.0 (TID 181, 10.1.2.191, partition 62, PROCESS_LOCAL, 5570 bytes)
17/02/09 09:48:29,201 INFO TaskSetManager: Starting task 54.0 in stage 3.0 (TID 182, 10.1.2.219, partition 54, PROCESS_LOCAL, 5570 bytes)
17/02/09 09:48:29,202 INFO TaskSetManager: Starting task 45.0 in stage 3.0 (TID 183, 10.1.2.138, partition 45, PROCESS_LOCAL, 5570 bytes)
17/02/09 09:48:29,202 INFO TaskSetManager: Starting task 49.0 in stage 3.0 (TID 184, 10.1.2.124, partition 49, PROCESS_LOCAL, 5570 bytes)
17/02/09 09:48:29,203 INFO TaskSetManager: Starting task 26.0 in stage 3.0 (TID 185, 10.1.2.25, partition 26, PROCESS_LOCAL, 5570 bytes)
17/02/09 09:48:29,204 INFO TaskSetManager: Starting task 46.0 in stage 3.0 (TID 186, 10.1.2.129, partition 46, PROCESS_LOCAL, 5570 bytes)
17/02/09 09:48:29,204 INFO TaskSetManager: Starting task 59.0 in stage 3.0 (TID 187, 10.1.2.157, partition 59, PROCESS_LOCAL, 5570 bytes)
17/02/09 09:48:29,205 INFO TaskSetManager: Starting task 60.0 in stage 3.0 (TID 188, 10.1.2.146, partition 60, PROCESS_LOCAL, 5570 bytes)
17/02/09 09:48:29,206 INFO TaskSetManager: Starting task 57.0 in stage 3.0 (TID 189, 10.1.2.95, partition 57, PROCESS_LOCAL, 5570 bytes)
17/02/09 09:48:29,206 INFO TaskSetManager: Starting task 44.0 in stage 3.0 (TID 190, 10.1.2.63, partition 44, PROCESS_LOCAL, 5570 bytes)
17/02/09 09:48:29,207 INFO CoarseGrainedSchedulerBackend$DriverEndpoint: Launching task 129 on executor id: 9 hostname: 10.1.2.174.
17/02/09 09:48:29,207 INFO CoarseGrainedSchedulerBackend$DriverEndpoint: Launching task 145 on executor id: 9 hostname: 10.1.2.174.
17/02/09 09:48:29,208 INFO CoarseGrainedSchedulerBackend$DriverEndpoint: Launching task 161 on executor id: 9 hostname: 10.1.2.174.
17/02/09 09:48:29,209 INFO CoarseGrainedSchedulerBackend$DriverEndpoint: Launching task 177 on executor id: 9 hostname: 10.1.2.174.
17/02/09 09:48:29,209 INFO CoarseGrainedSchedulerBackend$DriverEndpoint: Launching task 130 on executor id: 13 hostname: 10.1.2.69.
17/02/09 09:48:29,209 INFO CoarseGrainedSchedulerBackend$DriverEndpoint: Launching task 146 on executor id: 13 hostname: 10.1.2.69.
17/02/09 09:48:29,209 INFO CoarseGrainedSchedulerBackend$DriverEndpoint: Launching task 162 on executor id: 13 hostname: 10.1.2.69.
