Using properties file: /home/ubuntu/spark-2.0.0/conf/spark-defaults.conf
Adding default property: spark.driver.extraJavaOptions=-XX:+PrintGCDetails -XX:+PrintGCTimeStamps -Xms4000m -Dlog4j.configuration=file:///home/ubuntu/spark-2.0.0/conf/log4j.properties
Adding default property: spark.executor.extraJavaOptions=-XX:+PrintGCDetails -XX:+PrintGCTimeStamps -Xms4000m -Dlog4j.configuration=file:///home/ubuntu/spark-2.0.0/conf/log4j.properties
Parsed arguments:
  master                  spark://euca-10-1-2-115:7077
  deployMode              client
  executorMemory          4000m
  executorCores           null
  totalExecutorCores      null
  propertiesFile          /home/ubuntu/spark-2.0.0/conf/spark-defaults.conf
  driverMemory            4000m
  driverCores             null
  driverExtraClassPath    null
  driverExtraLibraryPath  null
  driverExtraJavaOptions  -XX:+PrintGCDetails -XX:+PrintGCTimeStamps -Xms4000m -Dlog4j.configuration=file:///home/ubuntu/spark-2.0.0/conf/log4j.properties
  supervise               false
  queue                   null
  numExecutors            16
  files                   null
  pyFiles                 null
  archives                null
  mainClass               LogRegExplicitParallelism
  primaryResource         file:///home/ubuntu/jars/log-reg-explicit-parallelism_2.11-1.0.jar
  name                    LogRegExplicitParallelism
  childArgs               [cluster 18 euca-10-1-2-115 9000 susy_0_exp 5 64]
  jars                    null
  packages                null
  packagesExclusions      null
  repositories            null
  verbose                 true

Spark properties used, including those specified through
 --conf and those from the properties file /home/ubuntu/spark-2.0.0/conf/spark-defaults.conf:
  spark.default.parallelism -> 64
  spark.driver.memory -> 4000m
  spark.executor.extraJavaOptions -> -XX:+PrintGCDetails -XX:+PrintGCTimeStamps -Xms4000m -Dlog4j.configuration=file:///home/ubuntu/spark-2.0.0/conf/log4j.properties
  spark.driver.extraJavaOptions -> -XX:+PrintGCDetails -XX:+PrintGCTimeStamps -Xms4000m -Dlog4j.configuration=file:///home/ubuntu/spark-2.0.0/conf/log4j.properties
  spark.shuffle.spill -> false

    
Main class:
LogRegExplicitParallelism
Arguments:
cluster
18
euca-10-1-2-115
9000
susy_0_exp
5
64
System properties:
spark.default.parallelism -> 64
spark.executor.memory -> 4000m
spark.driver.memory -> 4000m
SPARK_SUBMIT -> true
spark.executor.extraJavaOptions -> -XX:+PrintGCDetails -XX:+PrintGCTimeStamps -Xms4000m -Dlog4j.configuration=file:///home/ubuntu/spark-2.0.0/conf/log4j.properties
spark.app.name -> LogRegExplicitParallelism
spark.shuffle.spill -> false
spark.driver.extraJavaOptions -> -XX:+PrintGCDetails -XX:+PrintGCTimeStamps -Xms4000m -Dlog4j.configuration=file:///home/ubuntu/spark-2.0.0/conf/log4j.properties
spark.jars -> file:///home/ubuntu/jars/log-reg-explicit-parallelism_2.11-1.0.jar
spark.submit.deployMode -> client
spark.master -> spark://euca-10-1-2-115:7077
Classpath elements:
file:///home/ubuntu/jars/log-reg-explicit-parallelism_2.11-1.0.jar


17/01/29 16:17:42,029 INFO SparkContext: Running Spark version 2.0.0
17/01/29 16:17:42,374 WARN NativeCodeLoader: Unable to load native-hadoop library for your platform... using builtin-java classes where applicable
17/01/29 16:17:42,541 INFO SecurityManager: Changing view acls to: ubuntu
17/01/29 16:17:42,541 INFO SecurityManager: Changing modify acls to: ubuntu
17/01/29 16:17:42,542 INFO SecurityManager: Changing view acls groups to: 
17/01/29 16:17:42,542 INFO SecurityManager: Changing modify acls groups to: 
17/01/29 16:17:42,543 INFO SecurityManager: SecurityManager: authentication disabled; ui acls disabled; users  with view permissions: Set(ubuntu); groups with view permissions: Set(); users  with modify permissions: Set(ubuntu); groups with modify permissions: Set()
17/01/29 16:17:42,851 INFO Utils: Successfully started service 'sparkDriver' on port 39312.
17/01/29 16:17:42,869 INFO SparkEnv: Registering MapOutputTracker
17/01/29 16:17:42,875 WARN SortShuffleManager: spark.shuffle.spill was set to false, but this configuration is ignored as of Spark 1.6+. Shuffle will continue to spill to disk when necessary.
17/01/29 16:17:42,886 INFO SparkEnv: Registering BlockManagerMaster
17/01/29 16:17:42,898 INFO DiskBlockManager: Created local directory at /tmp/blockmgr-bf97b1bf-7ede-4928-a9e0-6168f5d11af5
17/01/29 16:17:42,915 INFO MemoryStore: MemoryStore started with capacity 2.1 GB
17/01/29 16:17:42,968 INFO SparkEnv: Registering OutputCommitCoordinator
17/01/29 16:17:43,167 INFO Utils: Successfully started service 'SparkUI' on port 4040.
17/01/29 16:17:43,168 INFO SparkUI: Bound SparkUI to 10.1.2.115, and started at http://10.1.2.115:4040
17/01/29 16:17:43,203 INFO SparkContext: Added JAR file:///home/ubuntu/jars/log-reg-explicit-parallelism_2.11-1.0.jar at spark://10.1.2.115:39312/jars/log-reg-explicit-parallelism_2.11-1.0.jar with timestamp 1485706663202
17/01/29 16:17:43,278 INFO StandaloneAppClient$ClientEndpoint: Connecting to master spark://euca-10-1-2-115:7077...
17/01/29 16:17:43,326 INFO TransportClientFactory: Successfully created connection to euca-10-1-2-115/10.1.2.115:7077 after 23 ms (0 ms spent in bootstraps)
17/01/29 16:17:43,418 INFO StandaloneSchedulerBackend: Connected to Spark cluster with app ID app-20170129161743-0000
17/01/29 16:17:43,423 INFO Utils: Successfully started service 'org.apache.spark.network.netty.NettyBlockTransferService' on port 42399.
17/01/29 16:17:43,424 INFO NettyBlockTransferService: Server created on 10.1.2.115:42399
17/01/29 16:17:43,426 INFO BlockManagerMaster: Registering BlockManager BlockManagerId(driver, 10.1.2.115, 42399)
17/01/29 16:17:43,432 INFO BlockManagerMasterEndpoint: Registering block manager 10.1.2.115:42399 with 2.1 GB RAM, BlockManagerId(driver, 10.1.2.115, 42399)
17/01/29 16:17:43,434 INFO BlockManagerMaster: Registered BlockManager BlockManagerId(driver, 10.1.2.115, 42399)
17/01/29 16:17:43,435 INFO StandaloneAppClient$ClientEndpoint: Executor added: app-20170129161743-0000/0 on worker-20170129161651-10.1.2.163-37229 (10.1.2.163:37229) with 4 cores
17/01/29 16:17:43,436 INFO StandaloneSchedulerBackend: Granted executor ID app-20170129161743-0000/0 on hostPort 10.1.2.163:37229 with 4 cores, 3.9 GB RAM
17/01/29 16:17:43,440 INFO StandaloneAppClient$ClientEndpoint: Executor added: app-20170129161743-0000/1 on worker-20170129161651-10.1.2.47-37698 (10.1.2.47:37698) with 4 cores
17/01/29 16:17:43,441 INFO StandaloneSchedulerBackend: Granted executor ID app-20170129161743-0000/1 on hostPort 10.1.2.47:37698 with 4 cores, 3.9 GB RAM
17/01/29 16:17:43,441 INFO StandaloneAppClient$ClientEndpoint: Executor added: app-20170129161743-0000/2 on worker-20170129161651-10.1.2.13-43189 (10.1.2.13:43189) with 4 cores
17/01/29 16:17:43,441 INFO StandaloneSchedulerBackend: Granted executor ID app-20170129161743-0000/2 on hostPort 10.1.2.13:43189 with 4 cores, 3.9 GB RAM
17/01/29 16:17:43,442 INFO StandaloneAppClient$ClientEndpoint: Executor added: app-20170129161743-0000/3 on worker-20170129161651-10.1.2.190-39549 (10.1.2.190:39549) with 4 cores
17/01/29 16:17:43,442 INFO StandaloneSchedulerBackend: Granted executor ID app-20170129161743-0000/3 on hostPort 10.1.2.190:39549 with 4 cores, 3.9 GB RAM
17/01/29 16:17:43,446 INFO StandaloneAppClient$ClientEndpoint: Executor added: app-20170129161743-0000/4 on worker-20170129161651-10.1.2.135-35520 (10.1.2.135:35520) with 4 cores
17/01/29 16:17:43,447 INFO StandaloneSchedulerBackend: Granted executor ID app-20170129161743-0000/4 on hostPort 10.1.2.135:35520 with 4 cores, 3.9 GB RAM
17/01/29 16:17:43,447 INFO StandaloneAppClient$ClientEndpoint: Executor added: app-20170129161743-0000/5 on worker-20170129161650-10.1.2.53-34287 (10.1.2.53:34287) with 4 cores
17/01/29 16:17:43,447 INFO StandaloneSchedulerBackend: Granted executor ID app-20170129161743-0000/5 on hostPort 10.1.2.53:34287 with 4 cores, 3.9 GB RAM
17/01/29 16:17:43,447 INFO StandaloneAppClient$ClientEndpoint: Executor added: app-20170129161743-0000/6 on worker-20170129161651-10.1.2.114-41033 (10.1.2.114:41033) with 4 cores
17/01/29 16:17:43,448 INFO StandaloneSchedulerBackend: Granted executor ID app-20170129161743-0000/6 on hostPort 10.1.2.114:41033 with 4 cores, 3.9 GB RAM
17/01/29 16:17:43,448 INFO StandaloneAppClient$ClientEndpoint: Executor added: app-20170129161743-0000/7 on worker-20170129161650-10.1.2.108-36373 (10.1.2.108:36373) with 4 cores
17/01/29 16:17:43,448 INFO StandaloneSchedulerBackend: Granted executor ID app-20170129161743-0000/7 on hostPort 10.1.2.108:36373 with 4 cores, 3.9 GB RAM
17/01/29 16:17:43,460 INFO StandaloneAppClient$ClientEndpoint: Executor added: app-20170129161743-0000/8 on worker-20170129161650-10.1.2.195-33268 (10.1.2.195:33268) with 4 cores
17/01/29 16:17:43,461 INFO StandaloneSchedulerBackend: Granted executor ID app-20170129161743-0000/8 on hostPort 10.1.2.195:33268 with 4 cores, 3.9 GB RAM
17/01/29 16:17:43,461 INFO StandaloneAppClient$ClientEndpoint: Executor added: app-20170129161743-0000/9 on worker-20170129161651-10.1.2.146-45623 (10.1.2.146:45623) with 4 cores
17/01/29 16:17:43,462 INFO StandaloneSchedulerBackend: Granted executor ID app-20170129161743-0000/9 on hostPort 10.1.2.146:45623 with 4 cores, 3.9 GB RAM
17/01/29 16:17:43,463 INFO StandaloneAppClient$ClientEndpoint: Executor added: app-20170129161743-0000/10 on worker-20170129161650-10.1.2.64-35893 (10.1.2.64:35893) with 4 cores
17/01/29 16:17:43,463 INFO StandaloneSchedulerBackend: Granted executor ID app-20170129161743-0000/10 on hostPort 10.1.2.64:35893 with 4 cores, 3.9 GB RAM
17/01/29 16:17:43,464 INFO StandaloneAppClient$ClientEndpoint: Executor added: app-20170129161743-0000/11 on worker-20170129161651-10.1.2.113-33265 (10.1.2.113:33265) with 4 cores
17/01/29 16:17:43,464 INFO StandaloneSchedulerBackend: Granted executor ID app-20170129161743-0000/11 on hostPort 10.1.2.113:33265 with 4 cores, 3.9 GB RAM
17/01/29 16:17:43,465 INFO StandaloneAppClient$ClientEndpoint: Executor added: app-20170129161743-0000/12 on worker-20170129161650-10.1.2.179-37811 (10.1.2.179:37811) with 4 cores
17/01/29 16:17:43,465 INFO StandaloneSchedulerBackend: Granted executor ID app-20170129161743-0000/12 on hostPort 10.1.2.179:37811 with 4 cores, 3.9 GB RAM
17/01/29 16:17:43,466 INFO StandaloneAppClient$ClientEndpoint: Executor added: app-20170129161743-0000/13 on worker-20170129161654-10.1.2.162-42410 (10.1.2.162:42410) with 4 cores
17/01/29 16:17:43,467 INFO StandaloneSchedulerBackend: Granted executor ID app-20170129161743-0000/13 on hostPort 10.1.2.162:42410 with 4 cores, 3.9 GB RAM
17/01/29 16:17:43,468 INFO StandaloneAppClient$ClientEndpoint: Executor added: app-20170129161743-0000/14 on worker-20170129161653-10.1.2.222-45022 (10.1.2.222:45022) with 4 cores
17/01/29 16:17:43,469 INFO StandaloneSchedulerBackend: Granted executor ID app-20170129161743-0000/14 on hostPort 10.1.2.222:45022 with 4 cores, 3.9 GB RAM
17/01/29 16:17:43,469 INFO StandaloneAppClient$ClientEndpoint: Executor added: app-20170129161743-0000/15 on worker-20170129161654-10.1.2.89-32947 (10.1.2.89:32947) with 4 cores
17/01/29 16:17:43,469 INFO StandaloneSchedulerBackend: Granted executor ID app-20170129161743-0000/15 on hostPort 10.1.2.89:32947 with 4 cores, 3.9 GB RAM
17/01/29 16:17:43,503 INFO StandaloneAppClient$ClientEndpoint: Executor updated: app-20170129161743-0000/5 is now RUNNING
17/01/29 16:17:43,507 INFO StandaloneAppClient$ClientEndpoint: Executor updated: app-20170129161743-0000/4 is now RUNNING
17/01/29 16:17:43,507 INFO StandaloneAppClient$ClientEndpoint: Executor updated: app-20170129161743-0000/3 is now RUNNING
17/01/29 16:17:43,513 INFO StandaloneAppClient$ClientEndpoint: Executor updated: app-20170129161743-0000/9 is now RUNNING
17/01/29 16:17:43,514 INFO StandaloneAppClient$ClientEndpoint: Executor updated: app-20170129161743-0000/7 is now RUNNING
17/01/29 16:17:43,516 INFO StandaloneAppClient$ClientEndpoint: Executor updated: app-20170129161743-0000/12 is now RUNNING
17/01/29 16:17:43,518 INFO StandaloneAppClient$ClientEndpoint: Executor updated: app-20170129161743-0000/1 is now RUNNING
17/01/29 16:17:43,523 INFO StandaloneAppClient$ClientEndpoint: Executor updated: app-20170129161743-0000/0 is now RUNNING
17/01/29 16:17:43,526 INFO StandaloneAppClient$ClientEndpoint: Executor updated: app-20170129161743-0000/6 is now RUNNING
17/01/29 16:17:43,528 INFO StandaloneAppClient$ClientEndpoint: Executor updated: app-20170129161743-0000/2 is now RUNNING
17/01/29 16:17:43,536 INFO StandaloneAppClient$ClientEndpoint: Executor updated: app-20170129161743-0000/8 is now RUNNING
17/01/29 16:17:43,538 INFO StandaloneAppClient$ClientEndpoint: Executor updated: app-20170129161743-0000/15 is now RUNNING
17/01/29 16:17:43,540 INFO StandaloneAppClient$ClientEndpoint: Executor updated: app-20170129161743-0000/13 is now RUNNING
17/01/29 16:17:43,542 INFO StandaloneAppClient$ClientEndpoint: Executor updated: app-20170129161743-0000/14 is now RUNNING
17/01/29 16:17:43,545 INFO StandaloneAppClient$ClientEndpoint: Executor updated: app-20170129161743-0000/10 is now RUNNING
17/01/29 16:17:43,547 INFO StandaloneAppClient$ClientEndpoint: Executor updated: app-20170129161743-0000/11 is now RUNNING
17/01/29 16:17:43,632 INFO StandaloneSchedulerBackend: SchedulerBackend is ready for scheduling beginning after reached minRegisteredResourcesRatio: 0.0
17/01/29 16:17:44,048 INFO MemoryStore: Block broadcast_0 stored as values in memory (estimated size 130.8 KB, free 2.1 GB)
17/01/29 16:17:44,117 INFO MemoryStore: Block broadcast_0_piece0 stored as bytes in memory (estimated size 16.5 KB, free 2.1 GB)
17/01/29 16:17:44,119 INFO BlockManagerInfo: Added broadcast_0_piece0 in memory on 10.1.2.115:42399 (size: 16.5 KB, free: 2.1 GB)
17/01/29 16:17:44,127 INFO SparkContext: Created broadcast 0 from textFile at MLUtils.scala:99
17/01/29 16:17:44,759 INFO FileInputFormat: Total input paths to process : 1
17/01/29 16:17:44,797 INFO NetworkTopology: Adding a new node: /default-rack/10.1.2.135:50010
17/01/29 16:17:44,798 INFO NetworkTopology: Adding a new node: /default-rack/10.1.2.47:50010
17/01/29 16:17:44,798 INFO NetworkTopology: Adding a new node: /default-rack/10.1.2.179:50010
17/01/29 16:17:44,798 INFO NetworkTopology: Adding a new node: /default-rack/10.1.2.108:50010
17/01/29 16:17:44,798 INFO NetworkTopology: Adding a new node: /default-rack/10.1.2.163:50010
17/01/29 16:17:44,798 INFO NetworkTopology: Adding a new node: /default-rack/10.1.2.195:50010
17/01/29 16:17:44,799 INFO NetworkTopology: Adding a new node: /default-rack/10.1.2.114:50010
17/01/29 16:17:44,799 INFO NetworkTopology: Adding a new node: /default-rack/10.1.2.190:50010
17/01/29 16:17:44,800 INFO NetworkTopology: Adding a new node: /default-rack/10.1.2.13:50010
17/01/29 16:17:44,800 INFO NetworkTopology: Adding a new node: /default-rack/10.1.2.53:50010
17/01/29 16:17:44,800 INFO NetworkTopology: Adding a new node: /default-rack/10.1.2.113:50010
17/01/29 16:17:44,800 INFO NetworkTopology: Adding a new node: /default-rack/10.1.2.146:50010
17/01/29 16:17:44,801 INFO NetworkTopology: Adding a new node: /default-rack/10.1.2.89:50010
17/01/29 16:17:44,801 INFO NetworkTopology: Adding a new node: /default-rack/10.1.2.222:50010
17/01/29 16:17:44,802 INFO NetworkTopology: Adding a new node: /default-rack/10.1.2.64:50010
17/01/29 16:17:44,841 INFO SparkContext: Starting job: first at GeneralizedLinearAlgorithm.scala:246
17/01/29 16:17:44,852 INFO DAGScheduler: Got job 0 (first at GeneralizedLinearAlgorithm.scala:246) with 1 output partitions
17/01/29 16:17:44,853 INFO DAGScheduler: Final stage: ResultStage 0 (first at GeneralizedLinearAlgorithm.scala:246)
17/01/29 16:17:44,853 INFO DAGScheduler: Parents of final stage: List()
17/01/29 16:17:44,859 INFO DAGScheduler: Missing parents: List()
17/01/29 16:17:44,866 INFO DAGScheduler: Submitting ResultStage 0 (MapPartitionsRDD[6] at map at GeneralizedLinearAlgorithm.scala:246), which has no missing parents
17/01/29 16:17:44,887 INFO MemoryStore: Block broadcast_1 stored as values in memory (estimated size 4.2 KB, free 2.1 GB)
17/01/29 16:17:44,889 INFO MemoryStore: Block broadcast_1_piece0 stored as bytes in memory (estimated size 2.4 KB, free 2.1 GB)
17/01/29 16:17:44,890 INFO BlockManagerInfo: Added broadcast_1_piece0 in memory on 10.1.2.115:42399 (size: 2.4 KB, free: 2.1 GB)
17/01/29 16:17:44,891 INFO SparkContext: Created broadcast 1 from broadcast at DAGScheduler.scala:1012
17/01/29 16:17:44,894 INFO DAGScheduler: Submitting 1 missing tasks from ResultStage 0 (MapPartitionsRDD[6] at map at GeneralizedLinearAlgorithm.scala:246)
17/01/29 16:17:44,895 INFO TaskSchedulerImpl: Adding task set 0.0 with 1 tasks
17/01/29 16:17:45,353 INFO CoarseGrainedSchedulerBackend$DriverEndpoint: Registered executor NettyRpcEndpointRef(null) (10.1.2.195:40434) with ID 8
17/01/29 16:17:45,383 INFO TaskSetManager: Starting task 0.0 in stage 0.0 (TID 0, 10.1.2.195, partition 0, ANY, 5455 bytes)
17/01/29 16:17:45,389 INFO CoarseGrainedSchedulerBackend$DriverEndpoint: Launching task 0 on executor id: 8 hostname: 10.1.2.195.
17/01/29 16:17:45,391 INFO CoarseGrainedSchedulerBackend$DriverEndpoint: Registered executor NettyRpcEndpointRef(null) (10.1.2.179:41518) with ID 12
17/01/29 16:17:45,406 INFO BlockManagerMasterEndpoint: Registering block manager 10.1.2.195:41309 with 2.1 GB RAM, BlockManagerId(8, 10.1.2.195, 41309)
17/01/29 16:17:45,432 INFO BlockManagerMasterEndpoint: Registering block manager 10.1.2.179:42798 with 2.1 GB RAM, BlockManagerId(12, 10.1.2.179, 42798)
17/01/29 16:17:45,449 INFO CoarseGrainedSchedulerBackend$DriverEndpoint: Registered executor NettyRpcEndpointRef(null) (10.1.2.114:36560) with ID 6
17/01/29 16:17:45,484 INFO CoarseGrainedSchedulerBackend$DriverEndpoint: Registered executor NettyRpcEndpointRef(null) (10.1.2.53:35300) with ID 5
17/01/29 16:17:45,490 INFO CoarseGrainedSchedulerBackend$DriverEndpoint: Registered executor NettyRpcEndpointRef(null) (10.1.2.190:55170) with ID 3
17/01/29 16:17:45,503 INFO BlockManagerMasterEndpoint: Registering block manager 10.1.2.114:42068 with 2.1 GB RAM, BlockManagerId(6, 10.1.2.114, 42068)
17/01/29 16:17:45,529 INFO BlockManagerMasterEndpoint: Registering block manager 10.1.2.53:42975 with 2.1 GB RAM, BlockManagerId(5, 10.1.2.53, 42975)
17/01/29 16:17:45,533 INFO BlockManagerMasterEndpoint: Registering block manager 10.1.2.190:42016 with 2.1 GB RAM, BlockManagerId(3, 10.1.2.190, 42016)
17/01/29 16:17:45,536 INFO CoarseGrainedSchedulerBackend$DriverEndpoint: Registered executor NettyRpcEndpointRef(null) (10.1.2.47:53456) with ID 1
17/01/29 16:17:45,581 INFO CoarseGrainedSchedulerBackend$DriverEndpoint: Registered executor NettyRpcEndpointRef(null) (10.1.2.108:46956) with ID 7
17/01/29 16:17:45,594 INFO BlockManagerMasterEndpoint: Registering block manager 10.1.2.47:34662 with 2.1 GB RAM, BlockManagerId(1, 10.1.2.47, 34662)
17/01/29 16:17:45,633 INFO BlockManagerMasterEndpoint: Registering block manager 10.1.2.108:42762 with 2.1 GB RAM, BlockManagerId(7, 10.1.2.108, 42762)
17/01/29 16:17:45,652 INFO CoarseGrainedSchedulerBackend$DriverEndpoint: Registered executor NettyRpcEndpointRef(null) (10.1.2.113:51070) with ID 11
17/01/29 16:17:45,671 INFO CoarseGrainedSchedulerBackend$DriverEndpoint: Registered executor NettyRpcEndpointRef(null) (10.1.2.146:40796) with ID 9
17/01/29 16:17:45,681 INFO BlockManagerInfo: Added broadcast_1_piece0 in memory on 10.1.2.195:41309 (size: 2.4 KB, free: 2.1 GB)
17/01/29 16:17:45,711 INFO BlockManagerMasterEndpoint: Registering block manager 10.1.2.113:46670 with 2.1 GB RAM, BlockManagerId(11, 10.1.2.113, 46670)
17/01/29 16:17:45,719 INFO BlockManagerMasterEndpoint: Registering block manager 10.1.2.146:43656 with 2.1 GB RAM, BlockManagerId(9, 10.1.2.146, 43656)
17/01/29 16:17:45,739 INFO CoarseGrainedSchedulerBackend$DriverEndpoint: Registered executor NettyRpcEndpointRef(null) (10.1.2.13:59498) with ID 2
17/01/29 16:17:45,784 INFO BlockManagerMasterEndpoint: Registering block manager 10.1.2.13:42626 with 2.1 GB RAM, BlockManagerId(2, 10.1.2.13, 42626)
17/01/29 16:17:45,830 INFO BlockManagerInfo: Added broadcast_0_piece0 in memory on 10.1.2.195:41309 (size: 16.5 KB, free: 2.1 GB)
17/01/29 16:17:48,422 INFO CoarseGrainedSchedulerBackend$DriverEndpoint: Registered executor NettyRpcEndpointRef(null) (10.1.2.162:43146) with ID 13
17/01/29 16:17:48,479 INFO BlockManagerMasterEndpoint: Registering block manager 10.1.2.162:46602 with 2.1 GB RAM, BlockManagerId(13, 10.1.2.162, 46602)
17/01/29 16:17:48,519 INFO CoarseGrainedSchedulerBackend$DriverEndpoint: Registered executor NettyRpcEndpointRef(null) (10.1.2.135:39708) with ID 4
17/01/29 16:17:48,524 INFO CoarseGrainedSchedulerBackend$DriverEndpoint: Registered executor NettyRpcEndpointRef(null) (10.1.2.163:49006) with ID 0
17/01/29 16:17:48,530 INFO CoarseGrainedSchedulerBackend$DriverEndpoint: Registered executor NettyRpcEndpointRef(null) (10.1.2.89:60586) with ID 15
17/01/29 16:17:48,554 INFO CoarseGrainedSchedulerBackend$DriverEndpoint: Registered executor NettyRpcEndpointRef(null) (10.1.2.222:44258) with ID 14
17/01/29 16:17:48,577 INFO BlockManagerMasterEndpoint: Registering block manager 10.1.2.89:37684 with 2.1 GB RAM, BlockManagerId(15, 10.1.2.89, 37684)
17/01/29 16:17:48,586 INFO BlockManagerMasterEndpoint: Registering block manager 10.1.2.135:35121 with 2.1 GB RAM, BlockManagerId(4, 10.1.2.135, 35121)
17/01/29 16:17:48,587 INFO CoarseGrainedSchedulerBackend$DriverEndpoint: Registered executor NettyRpcEndpointRef(null) (10.1.2.64:59544) with ID 10
17/01/29 16:17:48,593 INFO BlockManagerMasterEndpoint: Registering block manager 10.1.2.163:45416 with 2.1 GB RAM, BlockManagerId(0, 10.1.2.163, 45416)
17/01/29 16:17:48,612 INFO BlockManagerMasterEndpoint: Registering block manager 10.1.2.222:43894 with 2.1 GB RAM, BlockManagerId(14, 10.1.2.222, 43894)
17/01/29 16:17:48,636 INFO BlockManagerMasterEndpoint: Registering block manager 10.1.2.64:36604 with 2.1 GB RAM, BlockManagerId(10, 10.1.2.64, 36604)
17/01/29 16:17:48,899 INFO BlockManagerInfo: Added rdd_5_0 in memory on 10.1.2.195:41309 (size: 22.2 MB, free: 2.0 GB)
17/01/29 16:17:48,949 INFO TaskSetManager: Finished task 0.0 in stage 0.0 (TID 0) in 3588 ms on 10.1.2.195 (1/1)
17/01/29 16:17:48,950 INFO TaskSchedulerImpl: Removed TaskSet 0.0, whose tasks have all completed, from pool 
17/01/29 16:17:48,954 INFO DAGScheduler: ResultStage 0 (first at GeneralizedLinearAlgorithm.scala:246) finished in 4.046 s
17/01/29 16:17:48,958 INFO DAGScheduler: Job 0 finished: first at GeneralizedLinearAlgorithm.scala:246, took 4.117177 s
17/01/29 16:17:48,972 INFO SparkContext: Starting job: count at DataValidators.scala:40
17/01/29 16:17:48,974 INFO DAGScheduler: Got job 1 (count at DataValidators.scala:40) with 64 output partitions
17/01/29 16:17:48,974 INFO DAGScheduler: Final stage: ResultStage 1 (count at DataValidators.scala:40)
17/01/29 16:17:48,974 INFO DAGScheduler: Parents of final stage: List()
17/01/29 16:17:48,977 INFO DAGScheduler: Missing parents: List()
17/01/29 16:17:48,978 INFO DAGScheduler: Submitting ResultStage 1 (MapPartitionsRDD[7] at filter at DataValidators.scala:40), which has no missing parents
17/01/29 16:17:49,003 INFO MemoryStore: Block broadcast_2 stored as values in memory (estimated size 3.9 KB, free 2.1 GB)
17/01/29 16:17:49,005 INFO MemoryStore: Block broadcast_2_piece0 stored as bytes in memory (estimated size 2.2 KB, free 2.1 GB)
17/01/29 16:17:49,006 INFO BlockManagerInfo: Added broadcast_2_piece0 in memory on 10.1.2.115:42399 (size: 2.2 KB, free: 2.1 GB)
17/01/29 16:17:49,007 INFO SparkContext: Created broadcast 2 from broadcast at DAGScheduler.scala:1012
17/01/29 16:17:49,009 INFO DAGScheduler: Submitting 64 missing tasks from ResultStage 1 (MapPartitionsRDD[7] at filter at DataValidators.scala:40)
17/01/29 16:17:49,010 INFO TaskSchedulerImpl: Adding task set 1.0 with 64 tasks
17/01/29 16:17:49,018 INFO TaskSetManager: Starting task 0.0 in stage 1.0 (TID 1, 10.1.2.195, partition 0, PROCESS_LOCAL, 5373 bytes)
17/01/29 16:17:49,021 INFO TaskSetManager: Starting task 17.0 in stage 1.0 (TID 2, 10.1.2.53, partition 17, NODE_LOCAL, 5373 bytes)
17/01/29 16:17:49,024 INFO TaskSetManager: Starting task 52.0 in stage 1.0 (TID 3, 10.1.2.64, partition 52, NODE_LOCAL, 5373 bytes)
17/01/29 16:17:49,025 INFO TaskSetManager: Starting task 20.0 in stage 1.0 (TID 4, 10.1.2.113, partition 20, NODE_LOCAL, 5373 bytes)
17/01/29 16:17:49,028 INFO TaskSetManager: Starting task 59.0 in stage 1.0 (TID 5, 10.1.2.47, partition 59, NODE_LOCAL, 5373 bytes)
17/01/29 16:17:49,029 INFO TaskSetManager: Starting task 3.0 in stage 1.0 (TID 6, 10.1.2.108, partition 3, NODE_LOCAL, 5373 bytes)
17/01/29 16:17:49,031 INFO TaskSetManager: Starting task 6.0 in stage 1.0 (TID 7, 10.1.2.163, partition 6, NODE_LOCAL, 5373 bytes)
17/01/29 16:17:49,033 INFO TaskSetManager: Starting task 38.0 in stage 1.0 (TID 8, 10.1.2.222, partition 38, NODE_LOCAL, 5373 bytes)
17/01/29 16:17:49,035 INFO TaskSetManager: Starting task 31.0 in stage 1.0 (TID 9, 10.1.2.179, partition 31, NODE_LOCAL, 5373 bytes)
17/01/29 16:17:49,036 INFO TaskSetManager: Starting task 10.0 in stage 1.0 (TID 10, 10.1.2.114, partition 10, NODE_LOCAL, 5373 bytes)
17/01/29 16:17:49,039 INFO TaskSetManager: Starting task 62.0 in stage 1.0 (TID 11, 10.1.2.146, partition 62, NODE_LOCAL, 5373 bytes)
17/01/29 16:17:49,041 INFO TaskSetManager: Starting task 24.0 in stage 1.0 (TID 12, 10.1.2.190, partition 24, NODE_LOCAL, 5373 bytes)
17/01/29 16:17:49,042 INFO TaskSetManager: Starting task 13.0 in stage 1.0 (TID 13, 10.1.2.13, partition 13, NODE_LOCAL, 5373 bytes)
17/01/29 16:17:49,044 INFO TaskSetManager: Starting task 34.0 in stage 1.0 (TID 14, 10.1.2.195, partition 34, NODE_LOCAL, 5373 bytes)
17/01/29 16:17:49,046 INFO TaskSetManager: Starting task 27.0 in stage 1.0 (TID 15, 10.1.2.89, partition 27, NODE_LOCAL, 5373 bytes)
17/01/29 16:17:49,048 INFO TaskSetManager: Starting task 55.0 in stage 1.0 (TID 16, 10.1.2.53, partition 55, NODE_LOCAL, 5373 bytes)
17/01/29 16:17:49,050 INFO TaskSetManager: Starting task 45.0 in stage 1.0 (TID 17, 10.1.2.113, partition 45, NODE_LOCAL, 5373 bytes)
17/01/29 16:17:49,051 INFO TaskSetManager: Starting task 41.0 in stage 1.0 (TID 18, 10.1.2.108, partition 41, NODE_LOCAL, 5373 bytes)
17/01/29 16:17:49,053 INFO TaskSetManager: Starting task 48.0 in stage 1.0 (TID 19, 10.1.2.114, partition 48, NODE_LOCAL, 5373 bytes)
17/01/29 16:17:49,055 INFO CoarseGrainedSchedulerBackend$DriverEndpoint: Launching task 2 on executor id: 5 hostname: 10.1.2.53.
17/01/29 16:17:49,056 INFO CoarseGrainedSchedulerBackend$DriverEndpoint: Launching task 16 on executor id: 5 hostname: 10.1.2.53.
17/01/29 16:17:49,057 INFO CoarseGrainedSchedulerBackend$DriverEndpoint: Launching task 3 on executor id: 10 hostname: 10.1.2.64.
17/01/29 16:17:49,057 INFO CoarseGrainedSchedulerBackend$DriverEndpoint: Launching task 4 on executor id: 11 hostname: 10.1.2.113.
17/01/29 16:17:49,058 INFO CoarseGrainedSchedulerBackend$DriverEndpoint: Launching task 17 on executor id: 11 hostname: 10.1.2.113.
17/01/29 16:17:49,059 INFO CoarseGrainedSchedulerBackend$DriverEndpoint: Launching task 5 on executor id: 1 hostname: 10.1.2.47.
17/01/29 16:17:49,060 INFO CoarseGrainedSchedulerBackend$DriverEndpoint: Launching task 6 on executor id: 7 hostname: 10.1.2.108.
17/01/29 16:17:49,060 INFO CoarseGrainedSchedulerBackend$DriverEndpoint: Launching task 18 on executor id: 7 hostname: 10.1.2.108.
17/01/29 16:17:49,061 INFO CoarseGrainedSchedulerBackend$DriverEndpoint: Launching task 7 on executor id: 0 hostname: 10.1.2.163.
17/01/29 16:17:49,062 INFO CoarseGrainedSchedulerBackend$DriverEndpoint: Launching task 8 on executor id: 14 hostname: 10.1.2.222.
17/01/29 16:17:49,063 INFO CoarseGrainedSchedulerBackend$DriverEndpoint: Launching task 9 on executor id: 12 hostname: 10.1.2.179.
17/01/29 16:17:49,064 INFO CoarseGrainedSchedulerBackend$DriverEndpoint: Launching task 10 on executor id: 6 hostname: 10.1.2.114.
17/01/29 16:17:49,064 INFO CoarseGrainedSchedulerBackend$DriverEndpoint: Launching task 19 on executor id: 6 hostname: 10.1.2.114.
17/01/29 16:17:49,065 INFO CoarseGrainedSchedulerBackend$DriverEndpoint: Launching task 11 on executor id: 9 hostname: 10.1.2.146.
17/01/29 16:17:49,066 INFO CoarseGrainedSchedulerBackend$DriverEndpoint: Launching task 12 on executor id: 3 hostname: 10.1.2.190.
17/01/29 16:17:49,066 INFO CoarseGrainedSchedulerBackend$DriverEndpoint: Launching task 13 on executor id: 2 hostname: 10.1.2.13.
17/01/29 16:17:49,067 INFO CoarseGrainedSchedulerBackend$DriverEndpoint: Launching task 1 on executor id: 8 hostname: 10.1.2.195.
17/01/29 16:17:49,068 INFO CoarseGrainedSchedulerBackend$DriverEndpoint: Launching task 14 on executor id: 8 hostname: 10.1.2.195.
17/01/29 16:17:49,068 INFO CoarseGrainedSchedulerBackend$DriverEndpoint: Launching task 15 on executor id: 15 hostname: 10.1.2.89.
17/01/29 16:17:49,088 INFO BlockManagerInfo: Added broadcast_2_piece0 in memory on 10.1.2.195:41309 (size: 2.2 KB, free: 2.0 GB)
17/01/29 16:17:49,140 INFO TaskSetManager: Finished task 0.0 in stage 1.0 (TID 1) in 125 ms on 10.1.2.195 (1/64)
7.881: [GC [PSYoungGen: 1024512K->140464K(1195008K)] 1024512K->140536K(3926016K), 0.0588880 secs] [Times: user=0.12 sys=0.03, real=0.06 secs] 
17/01/29 16:17:49,348 INFO BlockManagerInfo: Added broadcast_2_piece0 in memory on 10.1.2.64:36604 (size: 2.2 KB, free: 2.1 GB)
17/01/29 16:17:49,416 INFO BlockManagerInfo: Added broadcast_2_piece0 in memory on 10.1.2.179:42798 (size: 2.2 KB, free: 2.1 GB)
17/01/29 16:17:49,417 INFO BlockManagerInfo: Added broadcast_2_piece0 in memory on 10.1.2.190:42016 (size: 2.2 KB, free: 2.1 GB)
17/01/29 16:17:49,417 INFO BlockManagerInfo: Added broadcast_2_piece0 in memory on 10.1.2.89:37684 (size: 2.2 KB, free: 2.1 GB)
17/01/29 16:17:49,420 INFO BlockManagerInfo: Added broadcast_2_piece0 in memory on 10.1.2.47:34662 (size: 2.2 KB, free: 2.1 GB)
17/01/29 16:17:49,421 INFO BlockManagerInfo: Added broadcast_2_piece0 in memory on 10.1.2.146:43656 (size: 2.2 KB, free: 2.1 GB)
17/01/29 16:17:49,422 INFO BlockManagerInfo: Added broadcast_2_piece0 in memory on 10.1.2.13:42626 (size: 2.2 KB, free: 2.1 GB)
17/01/29 16:17:49,430 INFO BlockManagerInfo: Removed broadcast_1_piece0 on 10.1.2.115:42399 in memory (size: 2.4 KB, free: 2.1 GB)
17/01/29 16:17:49,432 INFO BlockManagerInfo: Added broadcast_2_piece0 in memory on 10.1.2.53:42975 (size: 2.2 KB, free: 2.1 GB)
17/01/29 16:17:49,435 INFO BlockManagerInfo: Removed broadcast_1_piece0 on 10.1.2.195:41309 in memory (size: 2.4 KB, free: 2.0 GB)
17/01/29 16:17:49,437 INFO BlockManagerInfo: Added broadcast_2_piece0 in memory on 10.1.2.114:42068 (size: 2.2 KB, free: 2.1 GB)
17/01/29 16:17:49,438 INFO BlockManagerInfo: Added broadcast_2_piece0 in memory on 10.1.2.108:42762 (size: 2.2 KB, free: 2.1 GB)
17/01/29 16:17:49,441 INFO BlockManagerInfo: Added broadcast_2_piece0 in memory on 10.1.2.163:45416 (size: 2.2 KB, free: 2.1 GB)
17/01/29 16:17:49,447 INFO BlockManagerInfo: Added broadcast_2_piece0 in memory on 10.1.2.113:46670 (size: 2.2 KB, free: 2.1 GB)
17/01/29 16:17:49,464 INFO BlockManagerInfo: Added broadcast_2_piece0 in memory on 10.1.2.222:43894 (size: 2.2 KB, free: 2.1 GB)
17/01/29 16:17:49,517 INFO BlockManagerInfo: Added broadcast_0_piece0 in memory on 10.1.2.64:36604 (size: 16.5 KB, free: 2.1 GB)
17/01/29 16:17:49,572 INFO BlockManagerInfo: Added broadcast_0_piece0 in memory on 10.1.2.179:42798 (size: 16.5 KB, free: 2.1 GB)
17/01/29 16:17:49,580 INFO BlockManagerInfo: Added broadcast_0_piece0 in memory on 10.1.2.190:42016 (size: 16.5 KB, free: 2.1 GB)
17/01/29 16:17:49,593 INFO BlockManagerInfo: Added broadcast_0_piece0 in memory on 10.1.2.114:42068 (size: 16.5 KB, free: 2.1 GB)
17/01/29 16:17:49,620 INFO BlockManagerInfo: Added broadcast_0_piece0 in memory on 10.1.2.108:42762 (size: 16.5 KB, free: 2.1 GB)
17/01/29 16:17:49,621 INFO BlockManagerInfo: Added broadcast_0_piece0 in memory on 10.1.2.53:42975 (size: 16.5 KB, free: 2.1 GB)
17/01/29 16:17:49,632 INFO BlockManagerInfo: Added broadcast_0_piece0 in memory on 10.1.2.13:42626 (size: 16.5 KB, free: 2.1 GB)
17/01/29 16:17:49,637 INFO BlockManagerInfo: Added broadcast_0_piece0 in memory on 10.1.2.89:37684 (size: 16.5 KB, free: 2.1 GB)
17/01/29 16:17:49,638 INFO BlockManagerInfo: Added broadcast_0_piece0 in memory on 10.1.2.163:45416 (size: 16.5 KB, free: 2.1 GB)
17/01/29 16:17:49,641 INFO BlockManagerInfo: Added broadcast_0_piece0 in memory on 10.1.2.47:34662 (size: 16.5 KB, free: 2.1 GB)
17/01/29 16:17:49,641 INFO BlockManagerInfo: Added broadcast_0_piece0 in memory on 10.1.2.146:43656 (size: 16.5 KB, free: 2.1 GB)
17/01/29 16:17:49,648 INFO BlockManagerInfo: Added broadcast_0_piece0 in memory on 10.1.2.113:46670 (size: 16.5 KB, free: 2.1 GB)
17/01/29 16:17:49,657 INFO BlockManagerInfo: Added broadcast_0_piece0 in memory on 10.1.2.222:43894 (size: 16.5 KB, free: 2.1 GB)
17/01/29 16:17:51,096 INFO BlockManagerInfo: Added rdd_5_34 in memory on 10.1.2.195:41309 (size: 22.2 MB, free: 2.0 GB)
17/01/29 16:17:51,121 INFO TaskSetManager: Finished task 34.0 in stage 1.0 (TID 14) in 2078 ms on 10.1.2.195 (2/64)
17/01/29 16:17:52,271 INFO TaskSetManager: Starting task 1.0 in stage 1.0 (TID 20, 10.1.2.114, partition 1, ANY, 5373 bytes)
17/01/29 16:17:52,273 INFO TaskSetManager: Starting task 2.0 in stage 1.0 (TID 21, 10.1.2.13, partition 2, ANY, 5373 bytes)
17/01/29 16:17:52,274 INFO TaskSetManager: Starting task 4.0 in stage 1.0 (TID 22, 10.1.2.163, partition 4, ANY, 5373 bytes)
17/01/29 16:17:52,276 INFO TaskSetManager: Starting task 5.0 in stage 1.0 (TID 23, 10.1.2.64, partition 5, ANY, 5373 bytes)
17/01/29 16:17:52,277 INFO TaskSetManager: Starting task 7.0 in stage 1.0 (TID 24, 10.1.2.108, partition 7, ANY, 5373 bytes)
17/01/29 16:17:52,279 INFO TaskSetManager: Starting task 8.0 in stage 1.0 (TID 25, 10.1.2.146, partition 8, ANY, 5373 bytes)
17/01/29 16:17:52,281 INFO TaskSetManager: Starting task 9.0 in stage 1.0 (TID 26, 10.1.2.135, partition 9, ANY, 5373 bytes)
17/01/29 16:17:52,282 INFO TaskSetManager: Starting task 11.0 in stage 1.0 (TID 27, 10.1.2.89, partition 11, ANY, 5373 bytes)
17/01/29 16:17:52,284 INFO TaskSetManager: Starting task 12.0 in stage 1.0 (TID 28, 10.1.2.53, partition 12, ANY, 5373 bytes)
17/01/29 16:17:52,285 INFO TaskSetManager: Starting task 14.0 in stage 1.0 (TID 29, 10.1.2.113, partition 14, ANY, 5373 bytes)
17/01/29 16:17:52,287 INFO TaskSetManager: Starting task 15.0 in stage 1.0 (TID 30, 10.1.2.162, partition 15, ANY, 5373 bytes)
17/01/29 16:17:52,289 INFO TaskSetManager: Starting task 16.0 in stage 1.0 (TID 31, 10.1.2.179, partition 16, ANY, 5373 bytes)
17/01/29 16:17:52,290 INFO TaskSetManager: Starting task 18.0 in stage 1.0 (TID 32, 10.1.2.195, partition 18, ANY, 5373 bytes)
17/01/29 16:17:52,292 INFO TaskSetManager: Starting task 19.0 in stage 1.0 (TID 33, 10.1.2.222, partition 19, ANY, 5373 bytes)
17/01/29 16:17:52,294 INFO TaskSetManager: Starting task 21.0 in stage 1.0 (TID 34, 10.1.2.47, partition 21, ANY, 5373 bytes)
17/01/29 16:17:52,296 INFO TaskSetManager: Starting task 22.0 in stage 1.0 (TID 35, 10.1.2.190, partition 22, ANY, 5373 bytes)
17/01/29 16:17:52,298 INFO TaskSetManager: Starting task 23.0 in stage 1.0 (TID 36, 10.1.2.114, partition 23, ANY, 5373 bytes)
17/01/29 16:17:52,299 INFO TaskSetManager: Starting task 25.0 in stage 1.0 (TID 37, 10.1.2.13, partition 25, ANY, 5373 bytes)
17/01/29 16:17:52,301 INFO TaskSetManager: Starting task 26.0 in stage 1.0 (TID 38, 10.1.2.163, partition 26, ANY, 5373 bytes)
17/01/29 16:17:52,303 INFO TaskSetManager: Starting task 28.0 in stage 1.0 (TID 39, 10.1.2.64, partition 28, ANY, 5373 bytes)
17/01/29 16:17:52,305 INFO TaskSetManager: Starting task 29.0 in stage 1.0 (TID 40, 10.1.2.108, partition 29, ANY, 5373 bytes)
17/01/29 16:17:52,306 INFO TaskSetManager: Starting task 30.0 in stage 1.0 (TID 41, 10.1.2.146, partition 30, ANY, 5373 bytes)
17/01/29 16:17:52,308 INFO TaskSetManager: Starting task 32.0 in stage 1.0 (TID 42, 10.1.2.135, partition 32, ANY, 5373 bytes)
17/01/29 16:17:52,310 INFO TaskSetManager: Starting task 33.0 in stage 1.0 (TID 43, 10.1.2.89, partition 33, ANY, 5373 bytes)
17/01/29 16:17:52,311 INFO TaskSetManager: Starting task 35.0 in stage 1.0 (TID 44, 10.1.2.53, partition 35, ANY, 5373 bytes)
17/01/29 16:17:52,313 INFO TaskSetManager: Starting task 36.0 in stage 1.0 (TID 45, 10.1.2.113, partition 36, ANY, 5373 bytes)
17/01/29 16:17:52,314 INFO TaskSetManager: Starting task 37.0 in stage 1.0 (TID 46, 10.1.2.162, partition 37, ANY, 5373 bytes)
17/01/29 16:17:52,316 INFO TaskSetManager: Starting task 39.0 in stage 1.0 (TID 47, 10.1.2.179, partition 39, ANY, 5373 bytes)
17/01/29 16:17:52,318 INFO TaskSetManager: Starting task 40.0 in stage 1.0 (TID 48, 10.1.2.195, partition 40, ANY, 5373 bytes)
17/01/29 16:17:52,320 INFO TaskSetManager: Starting task 42.0 in stage 1.0 (TID 49, 10.1.2.222, partition 42, ANY, 5373 bytes)
17/01/29 16:17:52,321 INFO TaskSetManager: Starting task 43.0 in stage 1.0 (TID 50, 10.1.2.47, partition 43, ANY, 5373 bytes)
17/01/29 16:17:52,323 INFO TaskSetManager: Starting task 44.0 in stage 1.0 (TID 51, 10.1.2.190, partition 44, ANY, 5373 bytes)
17/01/29 16:17:52,325 INFO TaskSetManager: Starting task 46.0 in stage 1.0 (TID 52, 10.1.2.13, partition 46, ANY, 5373 bytes)
17/01/29 16:17:52,327 INFO TaskSetManager: Starting task 47.0 in stage 1.0 (TID 53, 10.1.2.163, partition 47, ANY, 5373 bytes)
17/01/29 16:17:52,328 INFO TaskSetManager: Starting task 49.0 in stage 1.0 (TID 54, 10.1.2.64, partition 49, ANY, 5373 bytes)
17/01/29 16:17:52,330 INFO TaskSetManager: Starting task 50.0 in stage 1.0 (TID 55, 10.1.2.146, partition 50, ANY, 5373 bytes)
17/01/29 16:17:52,331 INFO TaskSetManager: Starting task 51.0 in stage 1.0 (TID 56, 10.1.2.135, partition 51, ANY, 5373 bytes)
17/01/29 16:17:52,332 INFO TaskSetManager: Starting task 53.0 in stage 1.0 (TID 57, 10.1.2.89, partition 53, ANY, 5373 bytes)
17/01/29 16:17:52,334 INFO TaskSetManager: Starting task 54.0 in stage 1.0 (TID 58, 10.1.2.162, partition 54, ANY, 5373 bytes)
17/01/29 16:17:52,335 INFO TaskSetManager: Starting task 56.0 in stage 1.0 (TID 59, 10.1.2.179, partition 56, ANY, 5373 bytes)
17/01/29 16:17:52,336 INFO TaskSetManager: Starting task 57.0 in stage 1.0 (TID 60, 10.1.2.195, partition 57, ANY, 5373 bytes)
17/01/29 16:17:52,338 INFO TaskSetManager: Starting task 58.0 in stage 1.0 (TID 61, 10.1.2.222, partition 58, ANY, 5373 bytes)
17/01/29 16:17:52,339 INFO TaskSetManager: Starting task 60.0 in stage 1.0 (TID 62, 10.1.2.47, partition 60, ANY, 5373 bytes)
17/01/29 16:17:52,341 INFO TaskSetManager: Starting task 61.0 in stage 1.0 (TID 63, 10.1.2.190, partition 61, ANY, 5373 bytes)
17/01/29 16:17:52,342 INFO TaskSetManager: Starting task 63.0 in stage 1.0 (TID 64, 10.1.2.135, partition 63, ANY, 5373 bytes)
17/01/29 16:17:52,343 INFO CoarseGrainedSchedulerBackend$DriverEndpoint: Launching task 20 on executor id: 6 hostname: 10.1.2.114.
17/01/29 16:17:52,343 INFO CoarseGrainedSchedulerBackend$DriverEndpoint: Launching task 36 on executor id: 6 hostname: 10.1.2.114.
17/01/29 16:17:52,344 INFO CoarseGrainedSchedulerBackend$DriverEndpoint: Launching task 21 on executor id: 2 hostname: 10.1.2.13.
17/01/29 16:17:52,344 INFO CoarseGrainedSchedulerBackend$DriverEndpoint: Launching task 37 on executor id: 2 hostname: 10.1.2.13.
17/01/29 16:17:52,344 INFO CoarseGrainedSchedulerBackend$DriverEndpoint: Launching task 52 on executor id: 2 hostname: 10.1.2.13.
17/01/29 16:17:52,345 INFO CoarseGrainedSchedulerBackend$DriverEndpoint: Launching task 22 on executor id: 0 hostname: 10.1.2.163.
17/01/29 16:17:52,345 INFO CoarseGrainedSchedulerBackend$DriverEndpoint: Launching task 38 on executor id: 0 hostname: 10.1.2.163.
17/01/29 16:17:52,346 INFO CoarseGrainedSchedulerBackend$DriverEndpoint: Launching task 53 on executor id: 0 hostname: 10.1.2.163.
17/01/29 16:17:52,346 INFO CoarseGrainedSchedulerBackend$DriverEndpoint: Launching task 23 on executor id: 10 hostname: 10.1.2.64.
17/01/29 16:17:52,347 INFO CoarseGrainedSchedulerBackend$DriverEndpoint: Launching task 39 on executor id: 10 hostname: 10.1.2.64.
17/01/29 16:17:52,347 INFO CoarseGrainedSchedulerBackend$DriverEndpoint: Launching task 54 on executor id: 10 hostname: 10.1.2.64.
17/01/29 16:17:52,348 INFO CoarseGrainedSchedulerBackend$DriverEndpoint: Launching task 24 on executor id: 7 hostname: 10.1.2.108.
17/01/29 16:17:52,348 INFO CoarseGrainedSchedulerBackend$DriverEndpoint: Launching task 40 on executor id: 7 hostname: 10.1.2.108.
17/01/29 16:17:52,348 INFO CoarseGrainedSchedulerBackend$DriverEndpoint: Launching task 25 on executor id: 9 hostname: 10.1.2.146.
17/01/29 16:17:52,349 INFO CoarseGrainedSchedulerBackend$DriverEndpoint: Launching task 41 on executor id: 9 hostname: 10.1.2.146.
17/01/29 16:17:52,349 INFO CoarseGrainedSchedulerBackend$DriverEndpoint: Launching task 55 on executor id: 9 hostname: 10.1.2.146.
17/01/29 16:17:52,350 INFO CoarseGrainedSchedulerBackend$DriverEndpoint: Launching task 26 on executor id: 4 hostname: 10.1.2.135.
17/01/29 16:17:52,350 INFO CoarseGrainedSchedulerBackend$DriverEndpoint: Launching task 42 on executor id: 4 hostname: 10.1.2.135.
17/01/29 16:17:52,350 INFO CoarseGrainedSchedulerBackend$DriverEndpoint: Launching task 56 on executor id: 4 hostname: 10.1.2.135.
17/01/29 16:17:52,351 INFO CoarseGrainedSchedulerBackend$DriverEndpoint: Launching task 64 on executor id: 4 hostname: 10.1.2.135.
17/01/29 16:17:52,351 INFO CoarseGrainedSchedulerBackend$DriverEndpoint: Launching task 27 on executor id: 15 hostname: 10.1.2.89.
17/01/29 16:17:52,352 INFO CoarseGrainedSchedulerBackend$DriverEndpoint: Launching task 43 on executor id: 15 hostname: 10.1.2.89.
17/01/29 16:17:52,352 INFO CoarseGrainedSchedulerBackend$DriverEndpoint: Launching task 57 on executor id: 15 hostname: 10.1.2.89.
17/01/29 16:17:52,353 INFO CoarseGrainedSchedulerBackend$DriverEndpoint: Launching task 28 on executor id: 5 hostname: 10.1.2.53.
17/01/29 16:17:52,353 INFO CoarseGrainedSchedulerBackend$DriverEndpoint: Launching task 44 on executor id: 5 hostname: 10.1.2.53.
17/01/29 16:17:52,353 INFO CoarseGrainedSchedulerBackend$DriverEndpoint: Launching task 29 on executor id: 11 hostname: 10.1.2.113.
17/01/29 16:17:52,354 INFO CoarseGrainedSchedulerBackend$DriverEndpoint: Launching task 45 on executor id: 11 hostname: 10.1.2.113.
17/01/29 16:17:52,354 INFO CoarseGrainedSchedulerBackend$DriverEndpoint: Launching task 30 on executor id: 13 hostname: 10.1.2.162.
17/01/29 16:17:52,355 INFO CoarseGrainedSchedulerBackend$DriverEndpoint: Launching task 46 on executor id: 13 hostname: 10.1.2.162.
17/01/29 16:17:52,355 INFO CoarseGrainedSchedulerBackend$DriverEndpoint: Launching task 58 on executor id: 13 hostname: 10.1.2.162.
17/01/29 16:17:52,356 INFO CoarseGrainedSchedulerBackend$DriverEndpoint: Launching task 31 on executor id: 12 hostname: 10.1.2.179.
17/01/29 16:17:52,356 INFO CoarseGrainedSchedulerBackend$DriverEndpoint: Launching task 47 on executor id: 12 hostname: 10.1.2.179.
17/01/29 16:17:52,357 INFO CoarseGrainedSchedulerBackend$DriverEndpoint: Launching task 59 on executor id: 12 hostname: 10.1.2.179.
17/01/29 16:17:52,357 INFO CoarseGrainedSchedulerBackend$DriverEndpoint: Launching task 32 on executor id: 8 hostname: 10.1.2.195.
17/01/29 16:17:52,358 INFO CoarseGrainedSchedulerBackend$DriverEndpoint: Launching task 48 on executor id: 8 hostname: 10.1.2.195.
17/01/29 16:17:52,358 INFO CoarseGrainedSchedulerBackend$DriverEndpoint: Launching task 60 on executor id: 8 hostname: 10.1.2.195.
17/01/29 16:17:52,358 INFO CoarseGrainedSchedulerBackend$DriverEndpoint: Launching task 33 on executor id: 14 hostname: 10.1.2.222.
17/01/29 16:17:52,359 INFO CoarseGrainedSchedulerBackend$DriverEndpoint: Launching task 49 on executor id: 14 hostname: 10.1.2.222.
17/01/29 16:17:52,359 INFO CoarseGrainedSchedulerBackend$DriverEndpoint: Launching task 61 on executor id: 14 hostname: 10.1.2.222.
17/01/29 16:17:52,359 INFO CoarseGrainedSchedulerBackend$DriverEndpoint: Launching task 34 on executor id: 1 hostname: 10.1.2.47.
17/01/29 16:17:52,360 INFO CoarseGrainedSchedulerBackend$DriverEndpoint: Launching task 50 on executor id: 1 hostname: 10.1.2.47.
17/01/29 16:17:52,360 INFO CoarseGrainedSchedulerBackend$DriverEndpoint: Launching task 62 on executor id: 1 hostname: 10.1.2.47.
17/01/29 16:17:52,361 INFO CoarseGrainedSchedulerBackend$DriverEndpoint: Launching task 35 on executor id: 3 hostname: 10.1.2.190.
17/01/29 16:17:52,362 INFO CoarseGrainedSchedulerBackend$DriverEndpoint: Launching task 51 on executor id: 3 hostname: 10.1.2.190.
17/01/29 16:17:52,362 INFO CoarseGrainedSchedulerBackend$DriverEndpoint: Launching task 63 on executor id: 3 hostname: 10.1.2.190.
17/01/29 16:17:52,749 INFO BlockManagerInfo: Added broadcast_2_piece0 in memory on 10.1.2.135:35121 (size: 2.2 KB, free: 2.1 GB)
17/01/29 16:17:52,775 INFO BlockManagerInfo: Added broadcast_2_piece0 in memory on 10.1.2.162:46602 (size: 2.2 KB, free: 2.1 GB)
17/01/29 16:17:52,971 INFO BlockManagerInfo: Added broadcast_0_piece0 in memory on 10.1.2.135:35121 (size: 16.5 KB, free: 2.1 GB)
17/01/29 16:17:53,021 INFO BlockManagerInfo: Added broadcast_0_piece0 in memory on 10.1.2.162:46602 (size: 16.5 KB, free: 2.1 GB)
17/01/29 16:17:53,647 INFO BlockManagerInfo: Added rdd_5_31 in memory on 10.1.2.179:42798 (size: 22.2 MB, free: 2.0 GB)
17/01/29 16:17:53,755 INFO TaskSetManager: Finished task 31.0 in stage 1.0 (TID 9) in 4721 ms on 10.1.2.179 (3/64)
17/01/29 16:17:54,153 INFO BlockManagerInfo: Added rdd_5_52 in memory on 10.1.2.64:36604 (size: 22.2 MB, free: 2.0 GB)
17/01/29 16:17:54,211 INFO BlockManagerInfo: Added rdd_5_24 in memory on 10.1.2.190:42016 (size: 22.2 MB, free: 2.0 GB)
17/01/29 16:17:54,289 INFO TaskSetManager: Finished task 52.0 in stage 1.0 (TID 3) in 5268 ms on 10.1.2.64 (4/64)
17/01/29 16:17:54,302 INFO TaskSetManager: Finished task 24.0 in stage 1.0 (TID 12) in 5263 ms on 10.1.2.190 (5/64)
17/01/29 16:17:54,386 INFO BlockManagerInfo: Added rdd_5_6 in memory on 10.1.2.163:45416 (size: 22.2 MB, free: 2.0 GB)
17/01/29 16:17:54,518 INFO TaskSetManager: Finished task 6.0 in stage 1.0 (TID 7) in 5488 ms on 10.1.2.163 (6/64)
17/01/29 16:17:54,981 INFO BlockManagerInfo: Added rdd_5_59 in memory on 10.1.2.47:34662 (size: 22.2 MB, free: 2.0 GB)
17/01/29 16:17:55,059 INFO TaskSetManager: Finished task 59.0 in stage 1.0 (TID 5) in 6032 ms on 10.1.2.47 (7/64)
17/01/29 16:17:55,119 INFO BlockManagerInfo: Added rdd_5_38 in memory on 10.1.2.222:43894 (size: 22.2 MB, free: 2.0 GB)
17/01/29 16:17:55,177 INFO BlockManagerInfo: Added rdd_5_62 in memory on 10.1.2.146:43656 (size: 22.2 MB, free: 2.0 GB)
17/01/29 16:17:55,220 INFO BlockManagerInfo: Added rdd_5_27 in memory on 10.1.2.89:37684 (size: 22.1 MB, free: 2.0 GB)
17/01/29 16:17:55,223 INFO TaskSetManager: Finished task 38.0 in stage 1.0 (TID 8) in 6192 ms on 10.1.2.222 (8/64)
17/01/29 16:17:55,264 INFO TaskSetManager: Finished task 62.0 in stage 1.0 (TID 11) in 6227 ms on 10.1.2.146 (9/64)
17/01/29 16:17:55,318 INFO TaskSetManager: Finished task 27.0 in stage 1.0 (TID 15) in 6273 ms on 10.1.2.89 (10/64)
17/01/29 16:17:55,408 INFO BlockManagerInfo: Added rdd_5_41 in memory on 10.1.2.108:42762 (size: 22.2 MB, free: 2.0 GB)
17/01/29 16:17:55,481 INFO TaskSetManager: Finished task 41.0 in stage 1.0 (TID 18) in 6431 ms on 10.1.2.108 (11/64)
17/01/29 16:17:55,589 INFO BlockManagerInfo: Added rdd_5_3 in memory on 10.1.2.108:42762 (size: 22.2 MB, free: 2.0 GB)
17/01/29 16:17:55,604 INFO TaskSetManager: Finished task 3.0 in stage 1.0 (TID 6) in 6575 ms on 10.1.2.108 (12/64)
17/01/29 16:17:55,634 INFO BlockManagerInfo: Added rdd_5_13 in memory on 10.1.2.13:42626 (size: 22.2 MB, free: 2.0 GB)
17/01/29 16:17:55,723 INFO TaskSetManager: Finished task 13.0 in stage 1.0 (TID 13) in 6681 ms on 10.1.2.13 (13/64)
17/01/29 16:17:55,950 INFO BlockManagerInfo: Added rdd_5_20 in memory on 10.1.2.113:46670 (size: 22.2 MB, free: 2.0 GB)
17/01/29 16:17:56,032 INFO TaskSetManager: Finished task 20.0 in stage 1.0 (TID 4) in 7007 ms on 10.1.2.113 (14/64)
17/01/29 16:17:56,119 INFO BlockManagerInfo: Added rdd_5_48 in memory on 10.1.2.114:42068 (size: 22.1 MB, free: 2.0 GB)
17/01/29 16:17:56,142 INFO BlockManagerInfo: Added rdd_5_10 in memory on 10.1.2.114:42068 (size: 22.2 MB, free: 2.0 GB)
17/01/29 16:17:56,227 INFO TaskSetManager: Finished task 48.0 in stage 1.0 (TID 19) in 7173 ms on 10.1.2.114 (15/64)
17/01/29 16:17:56,228 INFO TaskSetManager: Finished task 10.0 in stage 1.0 (TID 10) in 7193 ms on 10.1.2.114 (16/64)
17/01/29 16:17:56,357 INFO BlockManagerInfo: Added rdd_5_45 in memory on 10.1.2.113:46670 (size: 22.2 MB, free: 2.0 GB)
17/01/29 16:17:56,370 INFO TaskSetManager: Finished task 45.0 in stage 1.0 (TID 17) in 7322 ms on 10.1.2.113 (17/64)
17/01/29 16:17:56,503 INFO BlockManagerInfo: Added rdd_5_5 in memory on 10.1.2.64:36604 (size: 22.2 MB, free: 2.0 GB)
17/01/29 16:17:56,521 INFO TaskSetManager: Finished task 5.0 in stage 1.0 (TID 23) in 4247 ms on 10.1.2.64 (18/64)
17/01/29 16:17:56,590 INFO BlockManagerInfo: Added rdd_5_49 in memory on 10.1.2.64:36604 (size: 22.2 MB, free: 2.0 GB)
17/01/29 16:17:56,635 INFO TaskSetManager: Finished task 49.0 in stage 1.0 (TID 54) in 4308 ms on 10.1.2.64 (19/64)
17/01/29 16:17:56,681 INFO BlockManagerInfo: Added rdd_5_17 in memory on 10.1.2.53:42975 (size: 22.2 MB, free: 2.0 GB)
17/01/29 16:17:56,732 INFO BlockManagerInfo: Added rdd_5_55 in memory on 10.1.2.53:42975 (size: 22.2 MB, free: 2.0 GB)
17/01/29 16:17:56,744 INFO BlockManagerInfo: Added rdd_5_28 in memory on 10.1.2.64:36604 (size: 22.2 MB, free: 2031.6 MB)
17/01/29 16:17:56,758 INFO BlockManagerInfo: Added rdd_5_56 in memory on 10.1.2.179:42798 (size: 22.2 MB, free: 2.0 GB)
17/01/29 16:17:56,759 INFO TaskSetManager: Finished task 28.0 in stage 1.0 (TID 39) in 4458 ms on 10.1.2.64 (20/64)
17/01/29 16:17:56,776 INFO TaskSetManager: Finished task 55.0 in stage 1.0 (TID 16) in 7730 ms on 10.1.2.53 (21/64)
17/01/29 16:17:56,778 INFO TaskSetManager: Finished task 17.0 in stage 1.0 (TID 2) in 7758 ms on 10.1.2.53 (22/64)
17/01/29 16:17:56,779 INFO TaskSetManager: Finished task 56.0 in stage 1.0 (TID 59) in 4445 ms on 10.1.2.179 (23/64)
17/01/29 16:17:56,806 INFO BlockManagerInfo: Added rdd_5_22 in memory on 10.1.2.190:42016 (size: 22.2 MB, free: 2.0 GB)
17/01/29 16:17:56,823 INFO BlockManagerInfo: Added rdd_5_61 in memory on 10.1.2.190:42016 (size: 22.2 MB, free: 2.0 GB)
17/01/29 16:17:56,831 INFO TaskSetManager: Finished task 22.0 in stage 1.0 (TID 35) in 4537 ms on 10.1.2.190 (24/64)
17/01/29 16:17:56,833 INFO BlockManagerInfo: Added rdd_5_47 in memory on 10.1.2.163:45416 (size: 22.2 MB, free: 2.0 GB)
17/01/29 16:17:56,849 INFO TaskSetManager: Finished task 47.0 in stage 1.0 (TID 53) in 4523 ms on 10.1.2.163 (25/64)
17/01/29 16:17:56,861 INFO TaskSetManager: Finished task 61.0 in stage 1.0 (TID 63) in 4520 ms on 10.1.2.190 (26/64)
17/01/29 16:17:56,863 INFO BlockManagerInfo: Added rdd_5_39 in memory on 10.1.2.179:42798 (size: 22.1 MB, free: 2.0 GB)
17/01/29 16:17:56,864 INFO BlockManagerInfo: Added rdd_5_16 in memory on 10.1.2.179:42798 (size: 22.1 MB, free: 2031.7 MB)
17/01/29 16:17:56,868 INFO BlockManagerInfo: Added rdd_5_26 in memory on 10.1.2.163:45416 (size: 22.2 MB, free: 2.0 GB)
17/01/29 16:17:56,890 INFO TaskSetManager: Finished task 26.0 in stage 1.0 (TID 38) in 4590 ms on 10.1.2.163 (27/64)
17/01/29 16:17:56,892 INFO TaskSetManager: Finished task 39.0 in stage 1.0 (TID 47) in 4577 ms on 10.1.2.179 (28/64)
17/01/29 16:17:56,895 INFO TaskSetManager: Finished task 16.0 in stage 1.0 (TID 31) in 4607 ms on 10.1.2.179 (29/64)
17/01/29 16:17:56,917 INFO BlockManagerInfo: Added rdd_5_44 in memory on 10.1.2.190:42016 (size: 22.2 MB, free: 2031.6 MB)
17/01/29 16:17:56,936 INFO TaskSetManager: Finished task 44.0 in stage 1.0 (TID 51) in 4614 ms on 10.1.2.190 (30/64)
17/01/29 16:17:57,022 INFO BlockManagerInfo: Added rdd_5_30 in memory on 10.1.2.146:43656 (size: 22.2 MB, free: 2.0 GB)
17/01/29 16:17:57,029 INFO BlockManagerInfo: Added rdd_5_4 in memory on 10.1.2.163:45416 (size: 22.2 MB, free: 2031.6 MB)
17/01/29 16:17:57,039 INFO TaskSetManager: Finished task 30.0 in stage 1.0 (TID 41) in 4733 ms on 10.1.2.146 (31/64)
17/01/29 16:17:57,041 INFO TaskSetManager: Finished task 4.0 in stage 1.0 (TID 22) in 4768 ms on 10.1.2.163 (32/64)
17/01/29 16:17:57,108 INFO BlockManagerInfo: Added rdd_5_29 in memory on 10.1.2.108:42762 (size: 22.2 MB, free: 2.0 GB)
17/01/29 16:17:57,123 INFO TaskSetManager: Finished task 29.0 in stage 1.0 (TID 40) in 4820 ms on 10.1.2.108 (33/64)
17/01/29 16:17:57,134 INFO BlockManagerInfo: Added rdd_5_21 in memory on 10.1.2.47:34662 (size: 22.2 MB, free: 2.0 GB)
17/01/29 16:17:57,145 INFO TaskSetManager: Finished task 21.0 in stage 1.0 (TID 34) in 4853 ms on 10.1.2.47 (34/64)
17/01/29 16:17:57,191 INFO BlockManagerInfo: Added rdd_5_42 in memory on 10.1.2.222:43894 (size: 22.2 MB, free: 2.0 GB)
17/01/29 16:17:57,206 INFO TaskSetManager: Finished task 42.0 in stage 1.0 (TID 49) in 4888 ms on 10.1.2.222 (35/64)
17/01/29 16:17:57,208 INFO BlockManagerInfo: Added rdd_5_60 in memory on 10.1.2.47:34662 (size: 22.1 MB, free: 2.0 GB)
17/01/29 16:17:57,211 INFO BlockManagerInfo: Added rdd_5_50 in memory on 10.1.2.146:43656 (size: 22.1 MB, free: 2.0 GB)
17/01/29 16:17:57,230 INFO TaskSetManager: Finished task 60.0 in stage 1.0 (TID 62) in 4891 ms on 10.1.2.47 (36/64)
17/01/29 16:17:57,230 INFO BlockManagerInfo: Added rdd_5_1 in memory on 10.1.2.114:42068 (size: 22.2 MB, free: 2.0 GB)
17/01/29 16:17:57,245 INFO TaskSetManager: Finished task 1.0 in stage 1.0 (TID 20) in 4976 ms on 10.1.2.114 (37/64)
17/01/29 16:17:57,250 INFO TaskSetManager: Finished task 50.0 in stage 1.0 (TID 55) in 4921 ms on 10.1.2.146 (38/64)
17/01/29 16:17:57,286 INFO BlockManagerInfo: Added rdd_5_7 in memory on 10.1.2.108:42762 (size: 22.2 MB, free: 2031.6 MB)
17/01/29 16:17:57,294 INFO BlockManagerInfo: Added rdd_5_43 in memory on 10.1.2.47:34662 (size: 22.2 MB, free: 2031.7 MB)
17/01/29 16:17:57,298 INFO BlockManagerInfo: Added rdd_5_8 in memory on 10.1.2.146:43656 (size: 22.2 MB, free: 2031.7 MB)
17/01/29 16:17:57,299 INFO TaskSetManager: Finished task 7.0 in stage 1.0 (TID 24) in 5023 ms on 10.1.2.108 (39/64)
17/01/29 16:17:57,306 INFO TaskSetManager: Finished task 43.0 in stage 1.0 (TID 50) in 4985 ms on 10.1.2.47 (40/64)
17/01/29 16:17:57,313 INFO TaskSetManager: Finished task 8.0 in stage 1.0 (TID 25) in 5034 ms on 10.1.2.146 (41/64)
17/01/29 16:17:57,341 INFO BlockManagerInfo: Added rdd_5_19 in memory on 10.1.2.222:43894 (size: 22.2 MB, free: 2.0 GB)
17/01/29 16:17:57,344 INFO BlockManagerInfo: Added rdd_5_58 in memory on 10.1.2.222:43894 (size: 22.2 MB, free: 2031.6 MB)
17/01/29 16:17:57,355 INFO TaskSetManager: Finished task 19.0 in stage 1.0 (TID 33) in 5065 ms on 10.1.2.222 (42/64)
17/01/29 16:17:57,359 INFO TaskSetManager: Finished task 58.0 in stage 1.0 (TID 61) in 5022 ms on 10.1.2.222 (43/64)
17/01/29 16:17:57,388 INFO BlockManagerInfo: Added rdd_5_23 in memory on 10.1.2.114:42068 (size: 22.2 MB, free: 2031.7 MB)
17/01/29 16:17:57,399 INFO TaskSetManager: Finished task 23.0 in stage 1.0 (TID 36) in 5103 ms on 10.1.2.114 (44/64)
17/01/29 16:17:57,651 INFO BlockManagerInfo: Added rdd_5_33 in memory on 10.1.2.89:37684 (size: 22.2 MB, free: 2.0 GB)
17/01/29 16:17:57,667 INFO TaskSetManager: Finished task 33.0 in stage 1.0 (TID 43) in 5359 ms on 10.1.2.89 (45/64)
17/01/29 16:17:57,679 INFO BlockManagerInfo: Added rdd_5_11 in memory on 10.1.2.89:37684 (size: 22.2 MB, free: 2.0 GB)
17/01/29 16:17:57,687 INFO BlockManagerInfo: Added rdd_5_18 in memory on 10.1.2.195:41309 (size: 22.2 MB, free: 2.0 GB)
17/01/29 16:17:57,702 INFO TaskSetManager: Finished task 18.0 in stage 1.0 (TID 32) in 5413 ms on 10.1.2.195 (46/64)
17/01/29 16:17:57,706 INFO TaskSetManager: Finished task 11.0 in stage 1.0 (TID 27) in 5425 ms on 10.1.2.89 (47/64)
17/01/29 16:17:57,746 INFO BlockManagerInfo: Added rdd_5_53 in memory on 10.1.2.89:37684 (size: 22.2 MB, free: 2031.7 MB)
17/01/29 16:17:57,759 INFO TaskSetManager: Finished task 53.0 in stage 1.0 (TID 57) in 5427 ms on 10.1.2.89 (48/64)
17/01/29 16:17:57,789 INFO BlockManagerInfo: Added rdd_5_57 in memory on 10.1.2.195:41309 (size: 22.2 MB, free: 2031.7 MB)
17/01/29 16:17:57,803 INFO TaskSetManager: Finished task 57.0 in stage 1.0 (TID 60) in 5467 ms on 10.1.2.195 (49/64)
17/01/29 16:17:57,834 INFO BlockManagerInfo: Added rdd_5_40 in memory on 10.1.2.195:41309 (size: 22.2 MB, free: 2009.5 MB)
17/01/29 16:17:57,846 INFO TaskSetManager: Finished task 40.0 in stage 1.0 (TID 48) in 5530 ms on 10.1.2.195 (50/64)
17/01/29 16:17:57,955 INFO BlockManagerInfo: Added rdd_5_36 in memory on 10.1.2.113:46670 (size: 22.2 MB, free: 2.0 GB)
17/01/29 16:17:57,972 INFO TaskSetManager: Finished task 36.0 in stage 1.0 (TID 45) in 5661 ms on 10.1.2.113 (51/64)
17/01/29 16:17:58,025 INFO BlockManagerInfo: Added rdd_5_14 in memory on 10.1.2.113:46670 (size: 22.2 MB, free: 2031.6 MB)
17/01/29 16:17:58,038 INFO TaskSetManager: Finished task 14.0 in stage 1.0 (TID 29) in 5754 ms on 10.1.2.113 (52/64)
17/01/29 16:17:58,056 INFO BlockManagerInfo: Added rdd_5_35 in memory on 10.1.2.53:42975 (size: 22.1 MB, free: 2.0 GB)
17/01/29 16:17:58,072 INFO TaskSetManager: Finished task 35.0 in stage 1.0 (TID 44) in 5762 ms on 10.1.2.53 (53/64)
17/01/29 16:17:58,261 INFO BlockManagerInfo: Added rdd_5_12 in memory on 10.1.2.53:42975 (size: 22.2 MB, free: 2031.7 MB)
17/01/29 16:17:58,274 INFO TaskSetManager: Finished task 12.0 in stage 1.0 (TID 28) in 5992 ms on 10.1.2.53 (54/64)
17/01/29 16:17:58,517 INFO BlockManagerInfo: Added rdd_5_25 in memory on 10.1.2.13:42626 (size: 22.2 MB, free: 2.0 GB)
17/01/29 16:17:58,530 INFO TaskSetManager: Finished task 25.0 in stage 1.0 (TID 37) in 6232 ms on 10.1.2.13 (55/64)
17/01/29 16:17:58,550 INFO BlockManagerInfo: Added rdd_5_37 in memory on 10.1.2.162:46602 (size: 22.2 MB, free: 2.0 GB)
17/01/29 16:17:58,635 INFO BlockManagerInfo: Added rdd_5_15 in memory on 10.1.2.162:46602 (size: 22.1 MB, free: 2.0 GB)
17/01/29 16:17:58,688 INFO TaskSetManager: Finished task 37.0 in stage 1.0 (TID 46) in 6375 ms on 10.1.2.162 (56/64)
17/01/29 16:17:58,689 INFO TaskSetManager: Finished task 15.0 in stage 1.0 (TID 30) in 6403 ms on 10.1.2.162 (57/64)
17/01/29 16:17:58,732 INFO BlockManagerInfo: Added rdd_5_2 in memory on 10.1.2.13:42626 (size: 22.1 MB, free: 2.0 GB)
17/01/29 16:17:58,733 INFO BlockManagerInfo: Added rdd_5_54 in memory on 10.1.2.162:46602 (size: 22.2 MB, free: 2.0 GB)
17/01/29 16:17:58,747 INFO TaskSetManager: Finished task 2.0 in stage 1.0 (TID 21) in 6475 ms on 10.1.2.13 (58/64)
17/01/29 16:17:58,748 INFO TaskSetManager: Finished task 54.0 in stage 1.0 (TID 58) in 6414 ms on 10.1.2.162 (59/64)
17/01/29 16:17:59,099 INFO BlockManagerInfo: Added rdd_5_46 in memory on 10.1.2.13:42626 (size: 22.1 MB, free: 2031.7 MB)
17/01/29 16:17:59,110 INFO TaskSetManager: Finished task 46.0 in stage 1.0 (TID 52) in 6786 ms on 10.1.2.13 (60/64)
17/01/29 16:17:59,626 INFO BlockManagerInfo: Added rdd_5_63 in memory on 10.1.2.135:35121 (size: 22.2 MB, free: 2.0 GB)
17/01/29 16:17:59,704 INFO TaskSetManager: Finished task 63.0 in stage 1.0 (TID 64) in 7363 ms on 10.1.2.135 (61/64)
17/01/29 16:17:59,909 INFO BlockManagerInfo: Added rdd_5_32 in memory on 10.1.2.135:35121 (size: 22.2 MB, free: 2.0 GB)
17/01/29 16:17:59,932 INFO BlockManagerInfo: Added rdd_5_9 in memory on 10.1.2.135:35121 (size: 22.2 MB, free: 2.0 GB)
17/01/29 16:17:59,946 INFO BlockManagerInfo: Added rdd_5_51 in memory on 10.1.2.135:35121 (size: 22.2 MB, free: 2031.6 MB)
17/01/29 16:17:59,951 INFO TaskSetManager: Finished task 9.0 in stage 1.0 (TID 26) in 7671 ms on 10.1.2.135 (62/64)
17/01/29 16:17:59,954 INFO TaskSetManager: Finished task 32.0 in stage 1.0 (TID 42) in 7648 ms on 10.1.2.135 (63/64)
17/01/29 16:17:59,973 INFO TaskSetManager: Finished task 51.0 in stage 1.0 (TID 56) in 7643 ms on 10.1.2.135 (64/64)
17/01/29 16:17:59,973 INFO TaskSchedulerImpl: Removed TaskSet 1.0, whose tasks have all completed, from pool 
17/01/29 16:17:59,974 INFO DAGScheduler: ResultStage 1 (count at DataValidators.scala:40) finished in 10.961 s
17/01/29 16:17:59,975 INFO DAGScheduler: Job 1 finished: count at DataValidators.scala:40, took 11.001866 s
17/01/29 16:17:59,985 INFO SparkContext: Starting job: count at GradientDescent.scala:209
17/01/29 16:17:59,986 INFO DAGScheduler: Got job 2 (count at GradientDescent.scala:209) with 64 output partitions
17/01/29 16:17:59,987 INFO DAGScheduler: Final stage: ResultStage 2 (count at GradientDescent.scala:209)
17/01/29 16:17:59,987 INFO DAGScheduler: Parents of final stage: List()
17/01/29 16:17:59,989 INFO DAGScheduler: Missing parents: List()
17/01/29 16:17:59,991 INFO DAGScheduler: Submitting ResultStage 2 (MapPartitionsRDD[8] at map at GeneralizedLinearAlgorithm.scala:297), which has no missing parents
17/01/29 16:17:59,996 INFO MemoryStore: Block broadcast_3 stored as values in memory (estimated size 3.9 KB, free 2.1 GB)
17/01/29 16:17:59,998 INFO MemoryStore: Block broadcast_3_piece0 stored as bytes in memory (estimated size 2.2 KB, free 2.1 GB)
17/01/29 16:17:59,999 INFO BlockManagerInfo: Added broadcast_3_piece0 in memory on 10.1.2.115:42399 (size: 2.2 KB, free: 2.1 GB)
17/01/29 16:18:00,002 INFO SparkContext: Created broadcast 3 from broadcast at DAGScheduler.scala:1012
17/01/29 16:18:00,003 INFO DAGScheduler: Submitting 64 missing tasks from ResultStage 2 (MapPartitionsRDD[8] at map at GeneralizedLinearAlgorithm.scala:297)
17/01/29 16:18:00,004 INFO TaskSchedulerImpl: Adding task set 2.0 with 64 tasks
17/01/29 16:18:00,008 INFO TaskSetManager: Starting task 12.0 in stage 2.0 (TID 65, 10.1.2.53, partition 12, PROCESS_LOCAL, 5373 bytes)
17/01/29 16:18:00,008 INFO TaskSetManager: Starting task 3.0 in stage 2.0 (TID 66, 10.1.2.108, partition 3, PROCESS_LOCAL, 5373 bytes)
17/01/29 16:18:00,009 INFO TaskSetManager: Starting task 1.0 in stage 2.0 (TID 67, 10.1.2.114, partition 1, PROCESS_LOCAL, 5373 bytes)
17/01/29 16:18:00,010 INFO TaskSetManager: Starting task 2.0 in stage 2.0 (TID 68, 10.1.2.13, partition 2, PROCESS_LOCAL, 5373 bytes)
17/01/29 16:18:00,010 INFO TaskSetManager: Starting task 22.0 in stage 2.0 (TID 69, 10.1.2.190, partition 22, PROCESS_LOCAL, 5373 bytes)
17/01/29 16:18:00,011 INFO TaskSetManager: Starting task 19.0 in stage 2.0 (TID 70, 10.1.2.222, partition 19, PROCESS_LOCAL, 5373 bytes)
17/01/29 16:18:00,012 INFO TaskSetManager: Starting task 14.0 in stage 2.0 (TID 71, 10.1.2.113, partition 14, PROCESS_LOCAL, 5373 bytes)
17/01/29 16:18:00,012 INFO TaskSetManager: Starting task 16.0 in stage 2.0 (TID 72, 10.1.2.179, partition 16, PROCESS_LOCAL, 5373 bytes)
17/01/29 16:18:00,013 INFO TaskSetManager: Starting task 0.0 in stage 2.0 (TID 73, 10.1.2.195, partition 0, PROCESS_LOCAL, 5373 bytes)
17/01/29 16:18:00,014 INFO TaskSetManager: Starting task 9.0 in stage 2.0 (TID 74, 10.1.2.135, partition 9, PROCESS_LOCAL, 5373 bytes)
17/01/29 16:18:00,014 INFO TaskSetManager: Starting task 21.0 in stage 2.0 (TID 75, 10.1.2.47, partition 21, PROCESS_LOCAL, 5373 bytes)
17/01/29 16:18:00,015 INFO TaskSetManager: Starting task 5.0 in stage 2.0 (TID 76, 10.1.2.64, partition 5, PROCESS_LOCAL, 5373 bytes)
17/01/29 16:18:00,016 INFO TaskSetManager: Starting task 15.0 in stage 2.0 (TID 77, 10.1.2.162, partition 15, PROCESS_LOCAL, 5373 bytes)
17/01/29 16:18:00,016 INFO TaskSetManager: Starting task 8.0 in stage 2.0 (TID 78, 10.1.2.146, partition 8, PROCESS_LOCAL, 5373 bytes)
17/01/29 16:18:00,017 INFO TaskSetManager: Starting task 4.0 in stage 2.0 (TID 79, 10.1.2.163, partition 4, PROCESS_LOCAL, 5373 bytes)
17/01/29 16:18:00,018 INFO TaskSetManager: Starting task 11.0 in stage 2.0 (TID 80, 10.1.2.89, partition 11, PROCESS_LOCAL, 5373 bytes)
17/01/29 16:18:00,018 INFO TaskSetManager: Starting task 17.0 in stage 2.0 (TID 81, 10.1.2.53, partition 17, PROCESS_LOCAL, 5373 bytes)
17/01/29 16:18:00,019 INFO TaskSetManager: Starting task 7.0 in stage 2.0 (TID 82, 10.1.2.108, partition 7, PROCESS_LOCAL, 5373 bytes)
17/01/29 16:18:00,020 INFO TaskSetManager: Starting task 10.0 in stage 2.0 (TID 83, 10.1.2.114, partition 10, PROCESS_LOCAL, 5373 bytes)
17/01/29 16:18:00,020 INFO TaskSetManager: Starting task 13.0 in stage 2.0 (TID 84, 10.1.2.13, partition 13, PROCESS_LOCAL, 5373 bytes)
17/01/29 16:18:00,021 INFO TaskSetManager: Starting task 24.0 in stage 2.0 (TID 85, 10.1.2.190, partition 24, PROCESS_LOCAL, 5373 bytes)
17/01/29 16:18:00,022 INFO TaskSetManager: Starting task 38.0 in stage 2.0 (TID 86, 10.1.2.222, partition 38, PROCESS_LOCAL, 5373 bytes)
17/01/29 16:18:00,022 INFO TaskSetManager: Starting task 20.0 in stage 2.0 (TID 87, 10.1.2.113, partition 20, PROCESS_LOCAL, 5373 bytes)
17/01/29 16:18:00,023 INFO TaskSetManager: Starting task 31.0 in stage 2.0 (TID 88, 10.1.2.179, partition 31, PROCESS_LOCAL, 5373 bytes)
17/01/29 16:18:00,024 INFO TaskSetManager: Starting task 18.0 in stage 2.0 (TID 89, 10.1.2.195, partition 18, PROCESS_LOCAL, 5373 bytes)
17/01/29 16:18:00,024 INFO TaskSetManager: Starting task 32.0 in stage 2.0 (TID 90, 10.1.2.135, partition 32, PROCESS_LOCAL, 5373 bytes)
17/01/29 16:18:00,025 INFO TaskSetManager: Starting task 43.0 in stage 2.0 (TID 91, 10.1.2.47, partition 43, PROCESS_LOCAL, 5373 bytes)
17/01/29 16:18:00,026 INFO TaskSetManager: Starting task 28.0 in stage 2.0 (TID 92, 10.1.2.64, partition 28, PROCESS_LOCAL, 5373 bytes)
17/01/29 16:18:00,026 INFO TaskSetManager: Starting task 37.0 in stage 2.0 (TID 93, 10.1.2.162, partition 37, PROCESS_LOCAL, 5373 bytes)
17/01/29 16:18:00,027 INFO TaskSetManager: Starting task 30.0 in stage 2.0 (TID 94, 10.1.2.146, partition 30, PROCESS_LOCAL, 5373 bytes)
17/01/29 16:18:00,028 INFO TaskSetManager: Starting task 6.0 in stage 2.0 (TID 95, 10.1.2.163, partition 6, PROCESS_LOCAL, 5373 bytes)
17/01/29 16:18:00,028 INFO TaskSetManager: Starting task 27.0 in stage 2.0 (TID 96, 10.1.2.89, partition 27, PROCESS_LOCAL, 5373 bytes)
17/01/29 16:18:00,029 INFO TaskSetManager: Starting task 35.0 in stage 2.0 (TID 97, 10.1.2.53, partition 35, PROCESS_LOCAL, 5373 bytes)
17/01/29 16:18:00,030 INFO TaskSetManager: Starting task 29.0 in stage 2.0 (TID 98, 10.1.2.108, partition 29, PROCESS_LOCAL, 5373 bytes)
17/01/29 16:18:00,030 INFO TaskSetManager: Starting task 23.0 in stage 2.0 (TID 99, 10.1.2.114, partition 23, PROCESS_LOCAL, 5373 bytes)
17/01/29 16:18:00,031 INFO TaskSetManager: Starting task 25.0 in stage 2.0 (TID 100, 10.1.2.13, partition 25, PROCESS_LOCAL, 5373 bytes)
17/01/29 16:18:00,032 INFO TaskSetManager: Starting task 44.0 in stage 2.0 (TID 101, 10.1.2.190, partition 44, PROCESS_LOCAL, 5373 bytes)
17/01/29 16:18:00,032 INFO TaskSetManager: Starting task 42.0 in stage 2.0 (TID 102, 10.1.2.222, partition 42, PROCESS_LOCAL, 5373 bytes)
17/01/29 16:18:00,033 INFO TaskSetManager: Starting task 36.0 in stage 2.0 (TID 103, 10.1.2.113, partition 36, PROCESS_LOCAL, 5373 bytes)
17/01/29 16:18:00,034 INFO TaskSetManager: Starting task 39.0 in stage 2.0 (TID 104, 10.1.2.179, partition 39, PROCESS_LOCAL, 5373 bytes)
17/01/29 16:18:00,034 INFO TaskSetManager: Starting task 34.0 in stage 2.0 (TID 105, 10.1.2.195, partition 34, PROCESS_LOCAL, 5373 bytes)
17/01/29 16:18:00,035 INFO TaskSetManager: Starting task 51.0 in stage 2.0 (TID 106, 10.1.2.135, partition 51, PROCESS_LOCAL, 5373 bytes)
17/01/29 16:18:00,036 INFO TaskSetManager: Starting task 59.0 in stage 2.0 (TID 107, 10.1.2.47, partition 59, PROCESS_LOCAL, 5373 bytes)
17/01/29 16:18:00,036 INFO TaskSetManager: Starting task 49.0 in stage 2.0 (TID 108, 10.1.2.64, partition 49, PROCESS_LOCAL, 5373 bytes)
17/01/29 16:18:00,037 INFO TaskSetManager: Starting task 54.0 in stage 2.0 (TID 109, 10.1.2.162, partition 54, PROCESS_LOCAL, 5373 bytes)
17/01/29 16:18:00,037 INFO TaskSetManager: Starting task 50.0 in stage 2.0 (TID 110, 10.1.2.146, partition 50, PROCESS_LOCAL, 5373 bytes)
17/01/29 16:18:00,038 INFO TaskSetManager: Starting task 26.0 in stage 2.0 (TID 111, 10.1.2.163, partition 26, PROCESS_LOCAL, 5373 bytes)
17/01/29 16:18:00,039 INFO TaskSetManager: Starting task 33.0 in stage 2.0 (TID 112, 10.1.2.89, partition 33, PROCESS_LOCAL, 5373 bytes)
17/01/29 16:18:00,039 INFO TaskSetManager: Starting task 55.0 in stage 2.0 (TID 113, 10.1.2.53, partition 55, PROCESS_LOCAL, 5373 bytes)
17/01/29 16:18:00,040 INFO TaskSetManager: Starting task 41.0 in stage 2.0 (TID 114, 10.1.2.108, partition 41, PROCESS_LOCAL, 5373 bytes)
17/01/29 16:18:00,041 INFO TaskSetManager: Starting task 48.0 in stage 2.0 (TID 115, 10.1.2.114, partition 48, PROCESS_LOCAL, 5373 bytes)
17/01/29 16:18:00,041 INFO TaskSetManager: Starting task 46.0 in stage 2.0 (TID 116, 10.1.2.13, partition 46, PROCESS_LOCAL, 5373 bytes)
17/01/29 16:18:00,042 INFO TaskSetManager: Starting task 61.0 in stage 2.0 (TID 117, 10.1.2.190, partition 61, PROCESS_LOCAL, 5373 bytes)
17/01/29 16:18:00,042 INFO TaskSetManager: Starting task 58.0 in stage 2.0 (TID 118, 10.1.2.222, partition 58, PROCESS_LOCAL, 5373 bytes)
17/01/29 16:18:00,043 INFO TaskSetManager: Starting task 45.0 in stage 2.0 (TID 119, 10.1.2.113, partition 45, PROCESS_LOCAL, 5373 bytes)
17/01/29 16:18:00,044 INFO TaskSetManager: Starting task 56.0 in stage 2.0 (TID 120, 10.1.2.179, partition 56, PROCESS_LOCAL, 5373 bytes)
17/01/29 16:18:00,045 INFO TaskSetManager: Starting task 40.0 in stage 2.0 (TID 121, 10.1.2.195, partition 40, PROCESS_LOCAL, 5373 bytes)
17/01/29 16:18:00,045 INFO TaskSetManager: Starting task 63.0 in stage 2.0 (TID 122, 10.1.2.135, partition 63, PROCESS_LOCAL, 5373 bytes)
17/01/29 16:18:00,046 INFO TaskSetManager: Starting task 60.0 in stage 2.0 (TID 123, 10.1.2.47, partition 60, PROCESS_LOCAL, 5373 bytes)
17/01/29 16:18:00,046 INFO TaskSetManager: Starting task 52.0 in stage 2.0 (TID 124, 10.1.2.64, partition 52, PROCESS_LOCAL, 5373 bytes)
17/01/29 16:18:00,047 INFO TaskSetManager: Starting task 62.0 in stage 2.0 (TID 125, 10.1.2.146, partition 62, PROCESS_LOCAL, 5373 bytes)
17/01/29 16:18:00,048 INFO TaskSetManager: Starting task 47.0 in stage 2.0 (TID 126, 10.1.2.163, partition 47, PROCESS_LOCAL, 5373 bytes)
17/01/29 16:18:00,048 INFO TaskSetManager: Starting task 53.0 in stage 2.0 (TID 127, 10.1.2.89, partition 53, PROCESS_LOCAL, 5373 bytes)
17/01/29 16:18:00,049 INFO CoarseGrainedSchedulerBackend$DriverEndpoint: Launching task 65 on executor id: 5 hostname: 10.1.2.53.
17/01/29 16:18:00,049 INFO CoarseGrainedSchedulerBackend$DriverEndpoint: Launching task 81 on executor id: 5 hostname: 10.1.2.53.
17/01/29 16:18:00,050 INFO CoarseGrainedSchedulerBackend$DriverEndpoint: Launching task 97 on executor id: 5 hostname: 10.1.2.53.
17/01/29 16:18:00,050 INFO CoarseGrainedSchedulerBackend$DriverEndpoint: Launching task 113 on executor id: 5 hostname: 10.1.2.53.
17/01/29 16:18:00,050 INFO CoarseGrainedSchedulerBackend$DriverEndpoint: Launching task 66 on executor id: 7 hostname: 10.1.2.108.
17/01/29 16:18:00,051 INFO CoarseGrainedSchedulerBackend$DriverEndpoint: Launching task 82 on executor id: 7 hostname: 10.1.2.108.
17/01/29 16:18:00,052 INFO CoarseGrainedSchedulerBackend$DriverEndpoint: Launching task 98 on executor id: 7 hostname: 10.1.2.108.
17/01/29 16:18:00,052 INFO CoarseGrainedSchedulerBackend$DriverEndpoint: Launching task 114 on executor id: 7 hostname: 10.1.2.108.
17/01/29 16:18:00,053 INFO CoarseGrainedSchedulerBackend$DriverEndpoint: Launching task 67 on executor id: 6 hostname: 10.1.2.114.
17/01/29 16:18:00,053 INFO CoarseGrainedSchedulerBackend$DriverEndpoint: Launching task 83 on executor id: 6 hostname: 10.1.2.114.
17/01/29 16:18:00,054 INFO CoarseGrainedSchedulerBackend$DriverEndpoint: Launching task 99 on executor id: 6 hostname: 10.1.2.114.
17/01/29 16:18:00,054 INFO CoarseGrainedSchedulerBackend$DriverEndpoint: Launching task 115 on executor id: 6 hostname: 10.1.2.114.
17/01/29 16:18:00,054 INFO CoarseGrainedSchedulerBackend$DriverEndpoint: Launching task 68 on executor id: 2 hostname: 10.1.2.13.
17/01/29 16:18:00,054 INFO CoarseGrainedSchedulerBackend$DriverEndpoint: Launching task 84 on executor id: 2 hostname: 10.1.2.13.
17/01/29 16:18:00,055 INFO CoarseGrainedSchedulerBackend$DriverEndpoint: Launching task 100 on executor id: 2 hostname: 10.1.2.13.
17/01/29 16:18:00,055 INFO CoarseGrainedSchedulerBackend$DriverEndpoint: Launching task 116 on executor id: 2 hostname: 10.1.2.13.
17/01/29 16:18:00,055 INFO CoarseGrainedSchedulerBackend$DriverEndpoint: Launching task 69 on executor id: 3 hostname: 10.1.2.190.
17/01/29 16:18:00,055 INFO CoarseGrainedSchedulerBackend$DriverEndpoint: Launching task 85 on executor id: 3 hostname: 10.1.2.190.
17/01/29 16:18:00,056 INFO CoarseGrainedSchedulerBackend$DriverEndpoint: Launching task 101 on executor id: 3 hostname: 10.1.2.190.
17/01/29 16:18:00,056 INFO CoarseGrainedSchedulerBackend$DriverEndpoint: Launching task 117 on executor id: 3 hostname: 10.1.2.190.
17/01/29 16:18:00,056 INFO CoarseGrainedSchedulerBackend$DriverEndpoint: Launching task 70 on executor id: 14 hostname: 10.1.2.222.
17/01/29 16:18:00,056 INFO CoarseGrainedSchedulerBackend$DriverEndpoint: Launching task 86 on executor id: 14 hostname: 10.1.2.222.
17/01/29 16:18:00,057 INFO CoarseGrainedSchedulerBackend$DriverEndpoint: Launching task 102 on executor id: 14 hostname: 10.1.2.222.
17/01/29 16:18:00,057 INFO CoarseGrainedSchedulerBackend$DriverEndpoint: Launching task 118 on executor id: 14 hostname: 10.1.2.222.
17/01/29 16:18:00,057 INFO CoarseGrainedSchedulerBackend$DriverEndpoint: Launching task 71 on executor id: 11 hostname: 10.1.2.113.
17/01/29 16:18:00,057 INFO CoarseGrainedSchedulerBackend$DriverEndpoint: Launching task 87 on executor id: 11 hostname: 10.1.2.113.
17/01/29 16:18:00,058 INFO CoarseGrainedSchedulerBackend$DriverEndpoint: Launching task 103 on executor id: 11 hostname: 10.1.2.113.
17/01/29 16:18:00,058 INFO CoarseGrainedSchedulerBackend$DriverEndpoint: Launching task 119 on executor id: 11 hostname: 10.1.2.113.
17/01/29 16:18:00,058 INFO CoarseGrainedSchedulerBackend$DriverEndpoint: Launching task 72 on executor id: 12 hostname: 10.1.2.179.
17/01/29 16:18:00,059 INFO CoarseGrainedSchedulerBackend$DriverEndpoint: Launching task 88 on executor id: 12 hostname: 10.1.2.179.
17/01/29 16:18:00,059 INFO CoarseGrainedSchedulerBackend$DriverEndpoint: Launching task 104 on executor id: 12 hostname: 10.1.2.179.
17/01/29 16:18:00,059 INFO CoarseGrainedSchedulerBackend$DriverEndpoint: Launching task 120 on executor id: 12 hostname: 10.1.2.179.
17/01/29 16:18:00,059 INFO CoarseGrainedSchedulerBackend$DriverEndpoint: Launching task 73 on executor id: 8 hostname: 10.1.2.195.
17/01/29 16:18:00,060 INFO CoarseGrainedSchedulerBackend$DriverEndpoint: Launching task 89 on executor id: 8 hostname: 10.1.2.195.
17/01/29 16:18:00,060 INFO CoarseGrainedSchedulerBackend$DriverEndpoint: Launching task 105 on executor id: 8 hostname: 10.1.2.195.
17/01/29 16:18:00,060 INFO CoarseGrainedSchedulerBackend$DriverEndpoint: Launching task 121 on executor id: 8 hostname: 10.1.2.195.
17/01/29 16:18:00,060 INFO CoarseGrainedSchedulerBackend$DriverEndpoint: Launching task 74 on executor id: 4 hostname: 10.1.2.135.
17/01/29 16:18:00,061 INFO CoarseGrainedSchedulerBackend$DriverEndpoint: Launching task 90 on executor id: 4 hostname: 10.1.2.135.
17/01/29 16:18:00,061 INFO CoarseGrainedSchedulerBackend$DriverEndpoint: Launching task 106 on executor id: 4 hostname: 10.1.2.135.
17/01/29 16:18:00,062 INFO CoarseGrainedSchedulerBackend$DriverEndpoint: Launching task 122 on executor id: 4 hostname: 10.1.2.135.
17/01/29 16:18:00,062 INFO CoarseGrainedSchedulerBackend$DriverEndpoint: Launching task 75 on executor id: 1 hostname: 10.1.2.47.
17/01/29 16:18:00,063 INFO CoarseGrainedSchedulerBackend$DriverEndpoint: Launching task 91 on executor id: 1 hostname: 10.1.2.47.
17/01/29 16:18:00,063 INFO CoarseGrainedSchedulerBackend$DriverEndpoint: Launching task 107 on executor id: 1 hostname: 10.1.2.47.
17/01/29 16:18:00,063 INFO CoarseGrainedSchedulerBackend$DriverEndpoint: Launching task 123 on executor id: 1 hostname: 10.1.2.47.
17/01/29 16:18:00,063 INFO CoarseGrainedSchedulerBackend$DriverEndpoint: Launching task 76 on executor id: 10 hostname: 10.1.2.64.
17/01/29 16:18:00,064 INFO CoarseGrainedSchedulerBackend$DriverEndpoint: Launching task 92 on executor id: 10 hostname: 10.1.2.64.
17/01/29 16:18:00,064 INFO CoarseGrainedSchedulerBackend$DriverEndpoint: Launching task 108 on executor id: 10 hostname: 10.1.2.64.
17/01/29 16:18:00,065 INFO CoarseGrainedSchedulerBackend$DriverEndpoint: Launching task 124 on executor id: 10 hostname: 10.1.2.64.
17/01/29 16:18:00,065 INFO CoarseGrainedSchedulerBackend$DriverEndpoint: Launching task 77 on executor id: 13 hostname: 10.1.2.162.
17/01/29 16:18:00,066 INFO CoarseGrainedSchedulerBackend$DriverEndpoint: Launching task 93 on executor id: 13 hostname: 10.1.2.162.
17/01/29 16:18:00,066 INFO CoarseGrainedSchedulerBackend$DriverEndpoint: Launching task 109 on executor id: 13 hostname: 10.1.2.162.
17/01/29 16:18:00,066 INFO CoarseGrainedSchedulerBackend$DriverEndpoint: Launching task 78 on executor id: 9 hostname: 10.1.2.146.
17/01/29 16:18:00,066 INFO CoarseGrainedSchedulerBackend$DriverEndpoint: Launching task 94 on executor id: 9 hostname: 10.1.2.146.
17/01/29 16:18:00,067 INFO CoarseGrainedSchedulerBackend$DriverEndpoint: Launching task 110 on executor id: 9 hostname: 10.1.2.146.
17/01/29 16:18:00,067 INFO CoarseGrainedSchedulerBackend$DriverEndpoint: Launching task 125 on executor id: 9 hostname: 10.1.2.146.
17/01/29 16:18:00,067 INFO CoarseGrainedSchedulerBackend$DriverEndpoint: Launching task 79 on executor id: 0 hostname: 10.1.2.163.
17/01/29 16:18:00,067 INFO CoarseGrainedSchedulerBackend$DriverEndpoint: Launching task 95 on executor id: 0 hostname: 10.1.2.163.
17/01/29 16:18:00,068 INFO CoarseGrainedSchedulerBackend$DriverEndpoint: Launching task 111 on executor id: 0 hostname: 10.1.2.163.
17/01/29 16:18:00,068 INFO CoarseGrainedSchedulerBackend$DriverEndpoint: Launching task 126 on executor id: 0 hostname: 10.1.2.163.
17/01/29 16:18:00,068 INFO CoarseGrainedSchedulerBackend$DriverEndpoint: Launching task 80 on executor id: 15 hostname: 10.1.2.89.
17/01/29 16:18:00,068 INFO CoarseGrainedSchedulerBackend$DriverEndpoint: Launching task 96 on executor id: 15 hostname: 10.1.2.89.
17/01/29 16:18:00,069 INFO CoarseGrainedSchedulerBackend$DriverEndpoint: Launching task 112 on executor id: 15 hostname: 10.1.2.89.
17/01/29 16:18:00,069 INFO CoarseGrainedSchedulerBackend$DriverEndpoint: Launching task 127 on executor id: 15 hostname: 10.1.2.89.
17/01/29 16:18:00,084 INFO BlockManagerInfo: Added broadcast_3_piece0 in memory on 10.1.2.114:42068 (size: 2.2 KB, free: 2031.7 MB)
17/01/29 16:18:00,092 INFO BlockManagerInfo: Added broadcast_3_piece0 in memory on 10.1.2.179:42798 (size: 2.2 KB, free: 2031.7 MB)
17/01/29 16:18:00,099 INFO BlockManagerInfo: Added broadcast_3_piece0 in memory on 10.1.2.190:42016 (size: 2.2 KB, free: 2031.6 MB)
17/01/29 16:18:00,099 INFO BlockManagerInfo: Added broadcast_3_piece0 in memory on 10.1.2.135:35121 (size: 2.2 KB, free: 2031.6 MB)
17/01/29 16:18:00,100 INFO BlockManagerInfo: Added broadcast_3_piece0 in memory on 10.1.2.53:42975 (size: 2.2 KB, free: 2031.7 MB)
17/01/29 16:18:00,107 INFO BlockManagerInfo: Added broadcast_3_piece0 in memory on 10.1.2.222:43894 (size: 2.2 KB, free: 2031.6 MB)
17/01/29 16:18:00,107 INFO BlockManagerInfo: Added broadcast_3_piece0 in memory on 10.1.2.64:36604 (size: 2.2 KB, free: 2031.6 MB)
17/01/29 16:18:00,109 INFO BlockManagerInfo: Added broadcast_3_piece0 in memory on 10.1.2.162:46602 (size: 2.2 KB, free: 2.0 GB)
17/01/29 16:18:00,111 INFO BlockManagerInfo: Added broadcast_3_piece0 in memory on 10.1.2.13:42626 (size: 2.2 KB, free: 2031.7 MB)
17/01/29 16:18:00,112 INFO BlockManagerInfo: Added broadcast_3_piece0 in memory on 10.1.2.163:45416 (size: 2.2 KB, free: 2031.6 MB)
17/01/29 16:18:00,133 INFO TaskSetManager: Finished task 9.0 in stage 2.0 (TID 74) in 120 ms on 10.1.2.135 (1/64)
17/01/29 16:18:00,137 INFO TaskSetManager: Finished task 22.0 in stage 2.0 (TID 69) in 126 ms on 10.1.2.190 (2/64)
17/01/29 16:18:00,138 INFO TaskSetManager: Finished task 44.0 in stage 2.0 (TID 101) in 107 ms on 10.1.2.190 (3/64)
17/01/29 16:18:00,138 INFO TaskSetManager: Finished task 61.0 in stage 2.0 (TID 117) in 97 ms on 10.1.2.190 (4/64)
17/01/29 16:18:00,140 INFO TaskSetManager: Finished task 24.0 in stage 2.0 (TID 85) in 118 ms on 10.1.2.190 (5/64)
17/01/29 16:18:00,140 INFO TaskSetManager: Finished task 51.0 in stage 2.0 (TID 106) in 106 ms on 10.1.2.135 (6/64)
17/01/29 16:18:00,141 INFO TaskSetManager: Finished task 31.0 in stage 2.0 (TID 88) in 119 ms on 10.1.2.179 (7/64)
17/01/29 16:18:00,143 INFO TaskSetManager: Finished task 63.0 in stage 2.0 (TID 122) in 97 ms on 10.1.2.135 (8/64)
17/01/29 16:18:00,144 INFO TaskSetManager: Finished task 32.0 in stage 2.0 (TID 90) in 120 ms on 10.1.2.135 (9/64)
17/01/29 16:18:00,145 INFO TaskSetManager: Finished task 54.0 in stage 2.0 (TID 109) in 109 ms on 10.1.2.162 (10/64)
17/01/29 16:18:00,150 INFO TaskSetManager: Finished task 37.0 in stage 2.0 (TID 93) in 124 ms on 10.1.2.162 (11/64)
17/01/29 16:18:00,151 INFO TaskSetManager: Finished task 39.0 in stage 2.0 (TID 104) in 118 ms on 10.1.2.179 (12/64)
17/01/29 16:18:00,152 INFO TaskSetManager: Finished task 12.0 in stage 2.0 (TID 65) in 145 ms on 10.1.2.53 (13/64)
17/01/29 16:18:00,154 INFO TaskSetManager: Finished task 15.0 in stage 2.0 (TID 77) in 139 ms on 10.1.2.162 (14/64)
17/01/29 16:18:00,155 INFO TaskSetManager: Finished task 56.0 in stage 2.0 (TID 120) in 112 ms on 10.1.2.179 (15/64)
17/01/29 16:18:00,156 INFO TaskSetManager: Finished task 35.0 in stage 2.0 (TID 97) in 127 ms on 10.1.2.53 (16/64)
17/01/29 16:18:00,157 INFO TaskSetManager: Finished task 58.0 in stage 2.0 (TID 118) in 115 ms on 10.1.2.222 (17/64)
17/01/29 16:18:00,158 INFO TaskSetManager: Finished task 46.0 in stage 2.0 (TID 116) in 117 ms on 10.1.2.13 (18/64)
17/01/29 16:18:00,159 INFO TaskSetManager: Finished task 19.0 in stage 2.0 (TID 70) in 148 ms on 10.1.2.222 (19/64)
17/01/29 16:18:00,161 INFO TaskSetManager: Finished task 38.0 in stage 2.0 (TID 86) in 139 ms on 10.1.2.222 (20/64)
17/01/29 16:18:00,161 INFO TaskSetManager: Finished task 25.0 in stage 2.0 (TID 100) in 130 ms on 10.1.2.13 (21/64)
17/01/29 16:18:00,162 INFO TaskSetManager: Finished task 2.0 in stage 2.0 (TID 68) in 153 ms on 10.1.2.13 (22/64)
17/01/29 16:18:00,164 INFO TaskSetManager: Finished task 13.0 in stage 2.0 (TID 84) in 143 ms on 10.1.2.13 (23/64)
17/01/29 16:18:00,166 INFO TaskSetManager: Finished task 42.0 in stage 2.0 (TID 102) in 134 ms on 10.1.2.222 (24/64)
17/01/29 16:18:00,171 INFO TaskSetManager: Finished task 49.0 in stage 2.0 (TID 108) in 135 ms on 10.1.2.64 (25/64)
17/01/29 16:18:00,174 INFO TaskSetManager: Finished task 55.0 in stage 2.0 (TID 113) in 134 ms on 10.1.2.53 (26/64)
17/01/29 16:18:00,176 INFO TaskSetManager: Finished task 6.0 in stage 2.0 (TID 95) in 148 ms on 10.1.2.163 (27/64)
17/01/29 16:18:00,180 INFO TaskSetManager: Finished task 23.0 in stage 2.0 (TID 99) in 149 ms on 10.1.2.114 (28/64)
17/01/29 16:18:00,182 INFO TaskSetManager: Finished task 26.0 in stage 2.0 (TID 111) in 143 ms on 10.1.2.163 (29/64)
17/01/29 16:18:00,183 INFO BlockManagerInfo: Added broadcast_3_piece0 in memory on 10.1.2.113:46670 (size: 2.2 KB, free: 2031.6 MB)
17/01/29 16:18:00,183 INFO TaskSetManager: Finished task 28.0 in stage 2.0 (TID 92) in 158 ms on 10.1.2.64 (30/64)
17/01/29 16:18:00,185 INFO TaskSetManager: Finished task 4.0 in stage 2.0 (TID 79) in 167 ms on 10.1.2.163 (31/64)
17/01/29 16:18:00,185 INFO BlockManagerInfo: Added broadcast_3_piece0 in memory on 10.1.2.195:41309 (size: 2.2 KB, free: 2009.5 MB)
17/01/29 16:18:00,188 INFO TaskSetManager: Finished task 10.0 in stage 2.0 (TID 83) in 168 ms on 10.1.2.114 (32/64)
17/01/29 16:18:00,188 INFO BlockManagerInfo: Added broadcast_3_piece0 in memory on 10.1.2.47:34662 (size: 2.2 KB, free: 2031.7 MB)
17/01/29 16:18:00,188 INFO TaskSetManager: Finished task 48.0 in stage 2.0 (TID 115) in 148 ms on 10.1.2.114 (33/64)
17/01/29 16:18:00,190 INFO BlockManagerInfo: Added broadcast_3_piece0 in memory on 10.1.2.108:42762 (size: 2.2 KB, free: 2031.6 MB)
17/01/29 16:18:00,191 INFO TaskSetManager: Finished task 1.0 in stage 2.0 (TID 67) in 182 ms on 10.1.2.114 (34/64)
17/01/29 16:18:00,193 INFO BlockManagerInfo: Added broadcast_3_piece0 in memory on 10.1.2.146:43656 (size: 2.2 KB, free: 2031.7 MB)
17/01/29 16:18:00,194 INFO BlockManagerInfo: Added broadcast_3_piece0 in memory on 10.1.2.89:37684 (size: 2.2 KB, free: 2031.7 MB)
17/01/29 16:18:00,202 INFO TaskSetManager: Finished task 16.0 in stage 2.0 (TID 72) in 190 ms on 10.1.2.179 (35/64)
17/01/29 16:18:00,212 INFO TaskSetManager: Finished task 17.0 in stage 2.0 (TID 81) in 194 ms on 10.1.2.53 (36/64)
17/01/29 16:18:00,217 INFO TaskSetManager: Finished task 5.0 in stage 2.0 (TID 76) in 201 ms on 10.1.2.64 (37/64)
17/01/29 16:18:00,221 INFO TaskSetManager: Finished task 52.0 in stage 2.0 (TID 124) in 174 ms on 10.1.2.64 (38/64)
17/01/29 16:18:00,224 INFO TaskSetManager: Starting task 57.0 in stage 2.0 (TID 128, 10.1.2.195, partition 57, PROCESS_LOCAL, 5373 bytes)
17/01/29 16:18:00,224 INFO CoarseGrainedSchedulerBackend$DriverEndpoint: Launching task 128 on executor id: 8 hostname: 10.1.2.195.
17/01/29 16:18:00,225 INFO TaskSetManager: Finished task 18.0 in stage 2.0 (TID 89) in 201 ms on 10.1.2.195 (39/64)
17/01/29 16:18:00,230 INFO TaskSetManager: Finished task 43.0 in stage 2.0 (TID 91) in 206 ms on 10.1.2.47 (40/64)
17/01/29 16:18:00,230 INFO TaskSetManager: Finished task 60.0 in stage 2.0 (TID 123) in 185 ms on 10.1.2.47 (41/64)
17/01/29 16:18:00,231 INFO TaskSetManager: Finished task 0.0 in stage 2.0 (TID 73) in 218 ms on 10.1.2.195 (42/64)
17/01/29 16:18:00,231 INFO TaskSetManager: Finished task 21.0 in stage 2.0 (TID 75) in 217 ms on 10.1.2.47 (43/64)
17/01/29 16:18:00,232 INFO TaskSetManager: Finished task 34.0 in stage 2.0 (TID 105) in 198 ms on 10.1.2.195 (44/64)
17/01/29 16:18:00,234 INFO TaskSetManager: Finished task 11.0 in stage 2.0 (TID 80) in 216 ms on 10.1.2.89 (45/64)
17/01/29 16:18:00,235 INFO TaskSetManager: Finished task 40.0 in stage 2.0 (TID 121) in 191 ms on 10.1.2.195 (46/64)
17/01/29 16:18:00,236 INFO TaskSetManager: Finished task 59.0 in stage 2.0 (TID 107) in 201 ms on 10.1.2.47 (47/64)
17/01/29 16:18:00,242 INFO TaskSetManager: Finished task 30.0 in stage 2.0 (TID 94) in 215 ms on 10.1.2.146 (48/64)
17/01/29 16:18:00,248 INFO TaskSetManager: Finished task 33.0 in stage 2.0 (TID 112) in 209 ms on 10.1.2.89 (49/64)
17/01/29 16:18:00,251 INFO TaskSetManager: Finished task 57.0 in stage 2.0 (TID 128) in 28 ms on 10.1.2.195 (50/64)
17/01/29 16:18:00,251 INFO TaskSetManager: Finished task 29.0 in stage 2.0 (TID 98) in 222 ms on 10.1.2.108 (51/64)
17/01/29 16:18:00,257 INFO TaskSetManager: Finished task 41.0 in stage 2.0 (TID 114) in 218 ms on 10.1.2.108 (52/64)
17/01/29 16:18:00,259 INFO TaskSetManager: Finished task 7.0 in stage 2.0 (TID 82) in 240 ms on 10.1.2.108 (53/64)
17/01/29 16:18:00,263 INFO TaskSetManager: Finished task 62.0 in stage 2.0 (TID 125) in 216 ms on 10.1.2.146 (54/64)
17/01/29 16:18:00,264 INFO TaskSetManager: Finished task 14.0 in stage 2.0 (TID 71) in 253 ms on 10.1.2.113 (55/64)
17/01/29 16:18:00,265 INFO TaskSetManager: Finished task 36.0 in stage 2.0 (TID 103) in 233 ms on 10.1.2.113 (56/64)
17/01/29 16:18:00,269 INFO TaskSetManager: Finished task 47.0 in stage 2.0 (TID 126) in 222 ms on 10.1.2.163 (57/64)
17/01/29 16:18:00,275 INFO TaskSetManager: Finished task 45.0 in stage 2.0 (TID 119) in 232 ms on 10.1.2.113 (58/64)
17/01/29 16:18:00,286 INFO TaskSetManager: Finished task 3.0 in stage 2.0 (TID 66) in 278 ms on 10.1.2.108 (59/64)
17/01/29 16:18:00,288 INFO TaskSetManager: Finished task 20.0 in stage 2.0 (TID 87) in 265 ms on 10.1.2.113 (60/64)
17/01/29 16:18:00,326 INFO TaskSetManager: Finished task 27.0 in stage 2.0 (TID 96) in 297 ms on 10.1.2.89 (61/64)
17/01/29 16:18:00,347 INFO TaskSetManager: Finished task 8.0 in stage 2.0 (TID 78) in 331 ms on 10.1.2.146 (62/64)
17/01/29 16:18:00,348 INFO TaskSetManager: Finished task 53.0 in stage 2.0 (TID 127) in 300 ms on 10.1.2.89 (63/64)
17/01/29 16:18:00,350 INFO TaskSetManager: Finished task 50.0 in stage 2.0 (TID 110) in 313 ms on 10.1.2.146 (64/64)
17/01/29 16:18:00,351 INFO TaskSchedulerImpl: Removed TaskSet 2.0, whose tasks have all completed, from pool 
17/01/29 16:18:00,351 INFO DAGScheduler: ResultStage 2 (count at GradientDescent.scala:209) finished in 0.345 s
17/01/29 16:18:00,351 INFO DAGScheduler: Job 2 finished: count at GradientDescent.scala:209, took 0.366110 s
17/01/29 16:18:00,581 WARN BLAS: Failed to load implementation from: com.github.fommil.netlib.NativeSystemBLAS
17/01/29 16:18:00,581 WARN BLAS: Failed to load implementation from: com.github.fommil.netlib.NativeRefBLAS
17/01/29 16:18:00,603 INFO MemoryStore: Block broadcast_4 stored as values in memory (estimated size 200.0 B, free 2.1 GB)
17/01/29 16:18:00,606 INFO MemoryStore: Block broadcast_4_piece0 stored as bytes in memory (estimated size 153.0 B, free 2.1 GB)
17/01/29 16:18:00,606 INFO BlockManagerInfo: Added broadcast_4_piece0 in memory on 10.1.2.115:42399 (size: 153.0 B, free: 2.1 GB)
17/01/29 16:18:00,607 INFO SparkContext: Created broadcast 4 from broadcast at GradientDescent.scala:235
17/01/29 16:18:00,654 INFO SparkContext: Starting job: treeAggregate at GradientDescent.scala:239
17/01/29 16:18:00,660 INFO DAGScheduler: Registering RDD 11 (treeAggregate at GradientDescent.scala:239)
17/01/29 16:18:00,660 INFO DAGScheduler: Got job 3 (treeAggregate at GradientDescent.scala:239) with 8 output partitions
17/01/29 16:18:00,661 INFO DAGScheduler: Final stage: ResultStage 4 (treeAggregate at GradientDescent.scala:239)
17/01/29 16:18:00,661 INFO DAGScheduler: Parents of final stage: List(ShuffleMapStage 3)
17/01/29 16:18:00,661 INFO DAGScheduler: Missing parents: List(ShuffleMapStage 3)
17/01/29 16:18:00,664 INFO DAGScheduler: Submitting ShuffleMapStage 3 (MapPartitionsRDD[11] at treeAggregate at GradientDescent.scala:239), which has no missing parents
17/01/29 16:18:00,680 INFO MemoryStore: Block broadcast_5 stored as values in memory (estimated size 7.1 KB, free 2.1 GB)
17/01/29 16:18:00,681 INFO MemoryStore: Block broadcast_5_piece0 stored as bytes in memory (estimated size 3.7 KB, free 2.1 GB)
17/01/29 16:18:00,682 INFO BlockManagerInfo: Added broadcast_5_piece0 in memory on 10.1.2.115:42399 (size: 3.7 KB, free: 2.1 GB)
17/01/29 16:18:00,682 INFO SparkContext: Created broadcast 5 from broadcast at DAGScheduler.scala:1012
17/01/29 16:18:00,684 INFO DAGScheduler: Submitting 64 missing tasks from ShuffleMapStage 3 (MapPartitionsRDD[11] at treeAggregate at GradientDescent.scala:239)
17/01/29 16:18:00,685 INFO TaskSchedulerImpl: Adding task set 3.0 with 64 tasks
17/01/29 16:18:00,689 INFO TaskSetManager: Starting task 5.0 in stage 3.0 (TID 129, 10.1.2.64, partition 5, PROCESS_LOCAL, 5562 bytes)
17/01/29 16:18:00,690 INFO TaskSetManager: Starting task 12.0 in stage 3.0 (TID 130, 10.1.2.53, partition 12, PROCESS_LOCAL, 5562 bytes)
17/01/29 16:18:00,690 INFO TaskSetManager: Starting task 2.0 in stage 3.0 (TID 131, 10.1.2.13, partition 2, PROCESS_LOCAL, 5562 bytes)
17/01/29 16:18:00,691 INFO TaskSetManager: Starting task 1.0 in stage 3.0 (TID 132, 10.1.2.114, partition 1, PROCESS_LOCAL, 5562 bytes)
17/01/29 16:18:00,692 INFO TaskSetManager: Starting task 15.0 in stage 3.0 (TID 133, 10.1.2.162, partition 15, PROCESS_LOCAL, 5562 bytes)
17/01/29 16:18:00,692 INFO TaskSetManager: Starting task 14.0 in stage 3.0 (TID 134, 10.1.2.113, partition 14, PROCESS_LOCAL, 5562 bytes)
17/01/29 16:18:00,693 INFO TaskSetManager: Starting task 4.0 in stage 3.0 (TID 135, 10.1.2.163, partition 4, PROCESS_LOCAL, 5562 bytes)
17/01/29 16:18:00,693 INFO TaskSetManager: Starting task 21.0 in stage 3.0 (TID 136, 10.1.2.47, partition 21, PROCESS_LOCAL, 5562 bytes)
17/01/29 16:18:00,694 INFO TaskSetManager: Starting task 16.0 in stage 3.0 (TID 137, 10.1.2.179, partition 16, PROCESS_LOCAL, 5562 bytes)
17/01/29 16:18:00,695 INFO TaskSetManager: Starting task 19.0 in stage 3.0 (TID 138, 10.1.2.222, partition 19, PROCESS_LOCAL, 5562 bytes)
17/01/29 16:18:00,695 INFO TaskSetManager: Starting task 22.0 in stage 3.0 (TID 139, 10.1.2.190, partition 22, PROCESS_LOCAL, 5562 bytes)
17/01/29 16:18:00,696 INFO TaskSetManager: Starting task 11.0 in stage 3.0 (TID 140, 10.1.2.89, partition 11, PROCESS_LOCAL, 5562 bytes)
17/01/29 16:18:00,697 INFO TaskSetManager: Starting task 0.0 in stage 3.0 (TID 141, 10.1.2.195, partition 0, PROCESS_LOCAL, 5562 bytes)
17/01/29 16:18:00,697 INFO TaskSetManager: Starting task 3.0 in stage 3.0 (TID 142, 10.1.2.108, partition 3, PROCESS_LOCAL, 5562 bytes)
17/01/29 16:18:00,698 INFO TaskSetManager: Starting task 9.0 in stage 3.0 (TID 143, 10.1.2.135, partition 9, PROCESS_LOCAL, 5562 bytes)
17/01/29 16:18:00,699 INFO TaskSetManager: Starting task 8.0 in stage 3.0 (TID 144, 10.1.2.146, partition 8, PROCESS_LOCAL, 5562 bytes)
17/01/29 16:18:00,699 INFO TaskSetManager: Starting task 28.0 in stage 3.0 (TID 145, 10.1.2.64, partition 28, PROCESS_LOCAL, 5562 bytes)
17/01/29 16:18:00,701 INFO TaskSetManager: Starting task 17.0 in stage 3.0 (TID 146, 10.1.2.53, partition 17, PROCESS_LOCAL, 5562 bytes)
17/01/29 16:18:00,702 INFO TaskSetManager: Starting task 13.0 in stage 3.0 (TID 147, 10.1.2.13, partition 13, PROCESS_LOCAL, 5562 bytes)
17/01/29 16:18:00,703 INFO TaskSetManager: Starting task 10.0 in stage 3.0 (TID 148, 10.1.2.114, partition 10, PROCESS_LOCAL, 5562 bytes)
17/01/29 16:18:00,704 INFO TaskSetManager: Starting task 37.0 in stage 3.0 (TID 149, 10.1.2.162, partition 37, PROCESS_LOCAL, 5562 bytes)
17/01/29 16:18:00,705 INFO TaskSetManager: Starting task 20.0 in stage 3.0 (TID 150, 10.1.2.113, partition 20, PROCESS_LOCAL, 5562 bytes)
17/01/29 16:18:00,706 INFO TaskSetManager: Starting task 6.0 in stage 3.0 (TID 151, 10.1.2.163, partition 6, PROCESS_LOCAL, 5562 bytes)
17/01/29 16:18:00,707 INFO TaskSetManager: Starting task 43.0 in stage 3.0 (TID 152, 10.1.2.47, partition 43, PROCESS_LOCAL, 5562 bytes)
17/01/29 16:18:00,708 INFO TaskSetManager: Starting task 31.0 in stage 3.0 (TID 153, 10.1.2.179, partition 31, PROCESS_LOCAL, 5562 bytes)
17/01/29 16:18:00,709 INFO TaskSetManager: Starting task 38.0 in stage 3.0 (TID 154, 10.1.2.222, partition 38, PROCESS_LOCAL, 5562 bytes)
17/01/29 16:18:00,710 INFO TaskSetManager: Starting task 24.0 in stage 3.0 (TID 155, 10.1.2.190, partition 24, PROCESS_LOCAL, 5562 bytes)
17/01/29 16:18:00,711 INFO TaskSetManager: Starting task 27.0 in stage 3.0 (TID 156, 10.1.2.89, partition 27, PROCESS_LOCAL, 5562 bytes)
17/01/29 16:18:00,712 INFO TaskSetManager: Starting task 18.0 in stage 3.0 (TID 157, 10.1.2.195, partition 18, PROCESS_LOCAL, 5562 bytes)
17/01/29 16:18:00,713 INFO TaskSetManager: Starting task 7.0 in stage 3.0 (TID 158, 10.1.2.108, partition 7, PROCESS_LOCAL, 5562 bytes)
17/01/29 16:18:00,714 INFO TaskSetManager: Starting task 32.0 in stage 3.0 (TID 159, 10.1.2.135, partition 32, PROCESS_LOCAL, 5562 bytes)
17/01/29 16:18:00,715 INFO TaskSetManager: Starting task 30.0 in stage 3.0 (TID 160, 10.1.2.146, partition 30, PROCESS_LOCAL, 5562 bytes)
17/01/29 16:18:00,716 INFO TaskSetManager: Starting task 49.0 in stage 3.0 (TID 161, 10.1.2.64, partition 49, PROCESS_LOCAL, 5562 bytes)
17/01/29 16:18:00,717 INFO TaskSetManager: Starting task 35.0 in stage 3.0 (TID 162, 10.1.2.53, partition 35, PROCESS_LOCAL, 5562 bytes)
17/01/29 16:18:00,718 INFO TaskSetManager: Starting task 25.0 in stage 3.0 (TID 163, 10.1.2.13, partition 25, PROCESS_LOCAL, 5562 bytes)
17/01/29 16:18:00,719 INFO TaskSetManager: Starting task 23.0 in stage 3.0 (TID 164, 10.1.2.114, partition 23, PROCESS_LOCAL, 5562 bytes)
17/01/29 16:18:00,720 INFO TaskSetManager: Starting task 54.0 in stage 3.0 (TID 165, 10.1.2.162, partition 54, PROCESS_LOCAL, 5562 bytes)
17/01/29 16:18:00,721 INFO TaskSetManager: Starting task 36.0 in stage 3.0 (TID 166, 10.1.2.113, partition 36, PROCESS_LOCAL, 5562 bytes)
17/01/29 16:18:00,722 INFO TaskSetManager: Starting task 26.0 in stage 3.0 (TID 167, 10.1.2.163, partition 26, PROCESS_LOCAL, 5562 bytes)
17/01/29 16:18:00,723 INFO TaskSetManager: Starting task 59.0 in stage 3.0 (TID 168, 10.1.2.47, partition 59, PROCESS_LOCAL, 5562 bytes)
17/01/29 16:18:00,724 INFO TaskSetManager: Starting task 39.0 in stage 3.0 (TID 169, 10.1.2.179, partition 39, PROCESS_LOCAL, 5562 bytes)
17/01/29 16:18:00,725 INFO TaskSetManager: Starting task 42.0 in stage 3.0 (TID 170, 10.1.2.222, partition 42, PROCESS_LOCAL, 5562 bytes)
17/01/29 16:18:00,726 INFO TaskSetManager: Starting task 44.0 in stage 3.0 (TID 171, 10.1.2.190, partition 44, PROCESS_LOCAL, 5562 bytes)
17/01/29 16:18:00,727 INFO TaskSetManager: Starting task 33.0 in stage 3.0 (TID 172, 10.1.2.89, partition 33, PROCESS_LOCAL, 5562 bytes)
17/01/29 16:18:00,728 INFO TaskSetManager: Starting task 34.0 in stage 3.0 (TID 173, 10.1.2.195, partition 34, PROCESS_LOCAL, 5562 bytes)
17/01/29 16:18:00,729 INFO TaskSetManager: Starting task 29.0 in stage 3.0 (TID 174, 10.1.2.108, partition 29, PROCESS_LOCAL, 5562 bytes)
17/01/29 16:18:00,731 INFO TaskSetManager: Starting task 51.0 in stage 3.0 (TID 175, 10.1.2.135, partition 51, PROCESS_LOCAL, 5562 bytes)
17/01/29 16:18:00,732 INFO TaskSetManager: Starting task 50.0 in stage 3.0 (TID 176, 10.1.2.146, partition 50, PROCESS_LOCAL, 5562 bytes)
17/01/29 16:18:00,732 INFO TaskSetManager: Starting task 52.0 in stage 3.0 (TID 177, 10.1.2.64, partition 52, PROCESS_LOCAL, 5562 bytes)
17/01/29 16:18:00,733 INFO TaskSetManager: Starting task 55.0 in stage 3.0 (TID 178, 10.1.2.53, partition 55, PROCESS_LOCAL, 5562 bytes)
17/01/29 16:18:00,734 INFO TaskSetManager: Starting task 46.0 in stage 3.0 (TID 179, 10.1.2.13, partition 46, PROCESS_LOCAL, 5562 bytes)
17/01/29 16:18:00,735 INFO TaskSetManager: Starting task 48.0 in stage 3.0 (TID 180, 10.1.2.114, partition 48, PROCESS_LOCAL, 5562 bytes)
17/01/29 16:18:00,736 INFO TaskSetManager: Starting task 45.0 in stage 3.0 (TID 181, 10.1.2.113, partition 45, PROCESS_LOCAL, 5562 bytes)
17/01/29 16:18:00,737 INFO TaskSetManager: Starting task 47.0 in stage 3.0 (TID 182, 10.1.2.163, partition 47, PROCESS_LOCAL, 5562 bytes)
17/01/29 16:18:00,737 INFO TaskSetManager: Starting task 60.0 in stage 3.0 (TID 183, 10.1.2.47, partition 60, PROCESS_LOCAL, 5562 bytes)
17/01/29 16:18:00,738 INFO TaskSetManager: Starting task 56.0 in stage 3.0 (TID 184, 10.1.2.179, partition 56, PROCESS_LOCAL, 5562 bytes)
17/01/29 16:18:00,739 INFO TaskSetManager: Starting task 58.0 in stage 3.0 (TID 185, 10.1.2.222, partition 58, PROCESS_LOCAL, 5562 bytes)
17/01/29 16:18:00,740 INFO TaskSetManager: Starting task 61.0 in stage 3.0 (TID 186, 10.1.2.190, partition 61, PROCESS_LOCAL, 5562 bytes)
17/01/29 16:18:00,741 INFO TaskSetManager: Starting task 53.0 in stage 3.0 (TID 187, 10.1.2.89, partition 53, PROCESS_LOCAL, 5562 bytes)
17/01/29 16:18:00,742 INFO TaskSetManager: Starting task 40.0 in stage 3.0 (TID 188, 10.1.2.195, partition 40, PROCESS_LOCAL, 5562 bytes)
17/01/29 16:18:00,742 INFO TaskSetManager: Starting task 41.0 in stage 3.0 (TID 189, 10.1.2.108, partition 41, PROCESS_LOCAL, 5562 bytes)
17/01/29 16:18:00,743 INFO TaskSetManager: Starting task 63.0 in stage 3.0 (TID 190, 10.1.2.135, partition 63, PROCESS_LOCAL, 5562 bytes)
17/01/29 16:18:00,744 INFO TaskSetManager: Starting task 62.0 in stage 3.0 (TID 191, 10.1.2.146, partition 62, PROCESS_LOCAL, 5562 bytes)
17/01/29 16:18:00,745 INFO CoarseGrainedSchedulerBackend$DriverEndpoint: Launching task 129 on executor id: 10 hostname: 10.1.2.64.
17/01/29 16:18:00,746 INFO CoarseGrainedSchedulerBackend$DriverEndpoint: Launching task 145 on executor id: 10 hostname: 10.1.2.64.
17/01/29 16:18:00,746 INFO CoarseGrainedSchedulerBackend$DriverEndpoint: Launching task 161 on executor id: 10 hostname: 10.1.2.64.
