Using properties file: /home/ubuntu/spark-2.0.0/conf/spark-defaults.conf
Adding default property: spark.driver.extraJavaOptions=-XX:+PrintGCDetails -XX:+PrintGCTimeStamps -Xms4000m -Dlog4j.configuration=file:///home/ubuntu/spark-2.0.0/conf/log4j.properties
Adding default property: spark.executor.extraJavaOptions=-XX:+PrintGCDetails -XX:+PrintGCTimeStamps -Xms4000m -Dlog4j.configuration=file:///home/ubuntu/spark-2.0.0/conf/log4j.properties
Parsed arguments:
  master                  spark://euca-10-1-2-115:7077
  deployMode              client
  executorMemory          4000m
  executorCores           null
  totalExecutorCores      null
  propertiesFile          /home/ubuntu/spark-2.0.0/conf/spark-defaults.conf
  driverMemory            4000m
  driverCores             null
  driverExtraClassPath    null
  driverExtraLibraryPath  null
  driverExtraJavaOptions  -XX:+PrintGCDetails -XX:+PrintGCTimeStamps -Xms4000m -Dlog4j.configuration=file:///home/ubuntu/spark-2.0.0/conf/log4j.properties
  supervise               false
  queue                   null
  numExecutors            16
  files                   null
  pyFiles                 null
  archives                null
  mainClass               LogRegExplicitParallelism
  primaryResource         file:///home/ubuntu/jars/log-reg-explicit-parallelism_2.11-1.0.jar
  name                    LogRegExplicitParallelism
  childArgs               [cluster 18 euca-10-1-2-115 9000 susy_0_exp 5 64]
  jars                    null
  packages                null
  packagesExclusions      null
  repositories            null
  verbose                 true

Spark properties used, including those specified through
 --conf and those from the properties file /home/ubuntu/spark-2.0.0/conf/spark-defaults.conf:
  spark.default.parallelism -> 64
  spark.driver.memory -> 4000m
  spark.executor.extraJavaOptions -> -XX:+PrintGCDetails -XX:+PrintGCTimeStamps -Xms4000m -Dlog4j.configuration=file:///home/ubuntu/spark-2.0.0/conf/log4j.properties
  spark.driver.extraJavaOptions -> -XX:+PrintGCDetails -XX:+PrintGCTimeStamps -Xms4000m -Dlog4j.configuration=file:///home/ubuntu/spark-2.0.0/conf/log4j.properties
  spark.shuffle.spill -> false

    
Main class:
LogRegExplicitParallelism
Arguments:
cluster
18
euca-10-1-2-115
9000
susy_0_exp
5
64
System properties:
spark.default.parallelism -> 64
spark.executor.memory -> 4000m
spark.driver.memory -> 4000m
SPARK_SUBMIT -> true
spark.executor.extraJavaOptions -> -XX:+PrintGCDetails -XX:+PrintGCTimeStamps -Xms4000m -Dlog4j.configuration=file:///home/ubuntu/spark-2.0.0/conf/log4j.properties
spark.app.name -> LogRegExplicitParallelism
spark.shuffle.spill -> false
spark.driver.extraJavaOptions -> -XX:+PrintGCDetails -XX:+PrintGCTimeStamps -Xms4000m -Dlog4j.configuration=file:///home/ubuntu/spark-2.0.0/conf/log4j.properties
spark.jars -> file:///home/ubuntu/jars/log-reg-explicit-parallelism_2.11-1.0.jar
spark.submit.deployMode -> client
spark.master -> spark://euca-10-1-2-115:7077
Classpath elements:
file:///home/ubuntu/jars/log-reg-explicit-parallelism_2.11-1.0.jar


17/01/29 17:04:23,402 INFO SparkContext: Running Spark version 2.0.0
17/01/29 17:04:23,733 WARN NativeCodeLoader: Unable to load native-hadoop library for your platform... using builtin-java classes where applicable
17/01/29 17:04:23,890 INFO SecurityManager: Changing view acls to: ubuntu
17/01/29 17:04:23,890 INFO SecurityManager: Changing modify acls to: ubuntu
17/01/29 17:04:23,891 INFO SecurityManager: Changing view acls groups to: 
17/01/29 17:04:23,891 INFO SecurityManager: Changing modify acls groups to: 
17/01/29 17:04:23,891 INFO SecurityManager: SecurityManager: authentication disabled; ui acls disabled; users  with view permissions: Set(ubuntu); groups with view permissions: Set(); users  with modify permissions: Set(ubuntu); groups with modify permissions: Set()
17/01/29 17:04:27,150 WARN ThreadLocalRandom: Failed to generate a seed from SecureRandom within 3 seconds. Not enough entrophy?
17/01/29 17:04:27,197 INFO Utils: Successfully started service 'sparkDriver' on port 34487.
17/01/29 17:04:27,215 INFO SparkEnv: Registering MapOutputTracker
17/01/29 17:04:27,221 WARN SortShuffleManager: spark.shuffle.spill was set to false, but this configuration is ignored as of Spark 1.6+. Shuffle will continue to spill to disk when necessary.
17/01/29 17:04:27,232 INFO SparkEnv: Registering BlockManagerMaster
17/01/29 17:04:27,244 INFO DiskBlockManager: Created local directory at /tmp/blockmgr-46b219a3-264b-4258-9ff1-29a364459e67
17/01/29 17:04:27,264 INFO MemoryStore: MemoryStore started with capacity 2.1 GB
17/01/29 17:04:27,316 INFO SparkEnv: Registering OutputCommitCoordinator
17/01/29 17:04:27,507 INFO Utils: Successfully started service 'SparkUI' on port 4040.
17/01/29 17:04:27,509 INFO SparkUI: Bound SparkUI to 10.1.2.115, and started at http://10.1.2.115:4040
17/01/29 17:04:27,545 INFO SparkContext: Added JAR file:///home/ubuntu/jars/log-reg-explicit-parallelism_2.11-1.0.jar at spark://10.1.2.115:34487/jars/log-reg-explicit-parallelism_2.11-1.0.jar with timestamp 1485709467544
17/01/29 17:04:27,627 INFO StandaloneAppClient$ClientEndpoint: Connecting to master spark://euca-10-1-2-115:7077...
17/01/29 17:04:27,684 INFO TransportClientFactory: Successfully created connection to euca-10-1-2-115/10.1.2.115:7077 after 26 ms (0 ms spent in bootstraps)
17/01/29 17:04:27,784 INFO StandaloneSchedulerBackend: Connected to Spark cluster with app ID app-20170129170427-0000
17/01/29 17:04:27,794 INFO Utils: Successfully started service 'org.apache.spark.network.netty.NettyBlockTransferService' on port 42089.
17/01/29 17:04:27,795 INFO NettyBlockTransferService: Server created on 10.1.2.115:42089
17/01/29 17:04:27,797 INFO BlockManagerMaster: Registering BlockManager BlockManagerId(driver, 10.1.2.115, 42089)
17/01/29 17:04:27,799 INFO BlockManagerMasterEndpoint: Registering block manager 10.1.2.115:42089 with 2.1 GB RAM, BlockManagerId(driver, 10.1.2.115, 42089)
17/01/29 17:04:27,802 INFO BlockManagerMaster: Registered BlockManager BlockManagerId(driver, 10.1.2.115, 42089)
17/01/29 17:04:27,807 INFO StandaloneAppClient$ClientEndpoint: Executor added: app-20170129170427-0000/0 on worker-20170129170340-10.1.2.146-41798 (10.1.2.146:41798) with 4 cores
17/01/29 17:04:27,814 INFO StandaloneSchedulerBackend: Granted executor ID app-20170129170427-0000/0 on hostPort 10.1.2.146:41798 with 4 cores, 3.9 GB RAM
17/01/29 17:04:27,815 INFO StandaloneAppClient$ClientEndpoint: Executor added: app-20170129170427-0000/1 on worker-20170129170340-10.1.2.13-43174 (10.1.2.13:43174) with 4 cores
17/01/29 17:04:27,816 INFO StandaloneSchedulerBackend: Granted executor ID app-20170129170427-0000/1 on hostPort 10.1.2.13:43174 with 4 cores, 3.9 GB RAM
17/01/29 17:04:27,817 INFO StandaloneAppClient$ClientEndpoint: Executor added: app-20170129170427-0000/2 on worker-20170129170340-10.1.2.190-38498 (10.1.2.190:38498) with 4 cores
17/01/29 17:04:27,817 INFO StandaloneSchedulerBackend: Granted executor ID app-20170129170427-0000/2 on hostPort 10.1.2.190:38498 with 4 cores, 3.9 GB RAM
17/01/29 17:04:27,826 INFO StandaloneAppClient$ClientEndpoint: Executor added: app-20170129170427-0000/3 on worker-20170129170340-10.1.2.179-44436 (10.1.2.179:44436) with 4 cores
17/01/29 17:04:27,826 INFO StandaloneSchedulerBackend: Granted executor ID app-20170129170427-0000/3 on hostPort 10.1.2.179:44436 with 4 cores, 3.9 GB RAM
17/01/29 17:04:27,827 INFO StandaloneAppClient$ClientEndpoint: Executor added: app-20170129170427-0000/4 on worker-20170129170340-10.1.2.195-46503 (10.1.2.195:46503) with 4 cores
17/01/29 17:04:27,827 INFO StandaloneSchedulerBackend: Granted executor ID app-20170129170427-0000/4 on hostPort 10.1.2.195:46503 with 4 cores, 3.9 GB RAM
17/01/29 17:04:27,829 INFO StandaloneAppClient$ClientEndpoint: Executor added: app-20170129170427-0000/5 on worker-20170129170340-10.1.2.162-39622 (10.1.2.162:39622) with 4 cores
17/01/29 17:04:27,829 INFO StandaloneSchedulerBackend: Granted executor ID app-20170129170427-0000/5 on hostPort 10.1.2.162:39622 with 4 cores, 3.9 GB RAM
17/01/29 17:04:27,830 INFO StandaloneAppClient$ClientEndpoint: Executor added: app-20170129170427-0000/6 on worker-20170129170340-10.1.2.222-39780 (10.1.2.222:39780) with 4 cores
17/01/29 17:04:27,830 INFO StandaloneSchedulerBackend: Granted executor ID app-20170129170427-0000/6 on hostPort 10.1.2.222:39780 with 4 cores, 3.9 GB RAM
17/01/29 17:04:27,831 INFO StandaloneAppClient$ClientEndpoint: Executor added: app-20170129170427-0000/7 on worker-20170129170340-10.1.2.47-45039 (10.1.2.47:45039) with 4 cores
17/01/29 17:04:27,832 INFO StandaloneSchedulerBackend: Granted executor ID app-20170129170427-0000/7 on hostPort 10.1.2.47:45039 with 4 cores, 3.9 GB RAM
17/01/29 17:04:27,833 INFO StandaloneAppClient$ClientEndpoint: Executor added: app-20170129170427-0000/8 on worker-20170129170340-10.1.2.114-45033 (10.1.2.114:45033) with 4 cores
17/01/29 17:04:27,833 INFO StandaloneSchedulerBackend: Granted executor ID app-20170129170427-0000/8 on hostPort 10.1.2.114:45033 with 4 cores, 3.9 GB RAM
17/01/29 17:04:27,834 INFO StandaloneAppClient$ClientEndpoint: Executor added: app-20170129170427-0000/9 on worker-20170129170340-10.1.2.135-38477 (10.1.2.135:38477) with 4 cores
17/01/29 17:04:27,835 INFO StandaloneSchedulerBackend: Granted executor ID app-20170129170427-0000/9 on hostPort 10.1.2.135:38477 with 4 cores, 3.9 GB RAM
17/01/29 17:04:27,836 INFO StandaloneAppClient$ClientEndpoint: Executor added: app-20170129170427-0000/10 on worker-20170129170340-10.1.2.89-32790 (10.1.2.89:32790) with 4 cores
17/01/29 17:04:27,836 INFO StandaloneSchedulerBackend: Granted executor ID app-20170129170427-0000/10 on hostPort 10.1.2.89:32790 with 4 cores, 3.9 GB RAM
17/01/29 17:04:27,837 INFO StandaloneAppClient$ClientEndpoint: Executor added: app-20170129170427-0000/11 on worker-20170129170340-10.1.2.64-38246 (10.1.2.64:38246) with 4 cores
17/01/29 17:04:27,837 INFO StandaloneSchedulerBackend: Granted executor ID app-20170129170427-0000/11 on hostPort 10.1.2.64:38246 with 4 cores, 3.9 GB RAM
17/01/29 17:04:27,839 INFO StandaloneAppClient$ClientEndpoint: Executor added: app-20170129170427-0000/12 on worker-20170129170340-10.1.2.108-45328 (10.1.2.108:45328) with 4 cores
17/01/29 17:04:27,839 INFO StandaloneSchedulerBackend: Granted executor ID app-20170129170427-0000/12 on hostPort 10.1.2.108:45328 with 4 cores, 3.9 GB RAM
17/01/29 17:04:27,840 INFO StandaloneAppClient$ClientEndpoint: Executor added: app-20170129170427-0000/13 on worker-20170129170340-10.1.2.53-46337 (10.1.2.53:46337) with 4 cores
17/01/29 17:04:27,841 INFO StandaloneSchedulerBackend: Granted executor ID app-20170129170427-0000/13 on hostPort 10.1.2.53:46337 with 4 cores, 3.9 GB RAM
17/01/29 17:04:27,842 INFO StandaloneAppClient$ClientEndpoint: Executor added: app-20170129170427-0000/14 on worker-20170129170340-10.1.2.113-42417 (10.1.2.113:42417) with 4 cores
17/01/29 17:04:27,842 INFO StandaloneSchedulerBackend: Granted executor ID app-20170129170427-0000/14 on hostPort 10.1.2.113:42417 with 4 cores, 3.9 GB RAM
17/01/29 17:04:27,843 INFO StandaloneAppClient$ClientEndpoint: Executor added: app-20170129170427-0000/15 on worker-20170129170340-10.1.2.163-36216 (10.1.2.163:36216) with 4 cores
17/01/29 17:04:27,844 INFO StandaloneSchedulerBackend: Granted executor ID app-20170129170427-0000/15 on hostPort 10.1.2.163:36216 with 4 cores, 3.9 GB RAM
17/01/29 17:04:27,905 INFO StandaloneAppClient$ClientEndpoint: Executor updated: app-20170129170427-0000/3 is now RUNNING
17/01/29 17:04:27,906 INFO StandaloneAppClient$ClientEndpoint: Executor updated: app-20170129170427-0000/5 is now RUNNING
17/01/29 17:04:27,909 INFO StandaloneAppClient$ClientEndpoint: Executor updated: app-20170129170427-0000/9 is now RUNNING
17/01/29 17:04:27,911 INFO StandaloneAppClient$ClientEndpoint: Executor updated: app-20170129170427-0000/14 is now RUNNING
17/01/29 17:04:27,914 INFO StandaloneAppClient$ClientEndpoint: Executor updated: app-20170129170427-0000/12 is now RUNNING
17/01/29 17:04:27,917 INFO StandaloneAppClient$ClientEndpoint: Executor updated: app-20170129170427-0000/7 is now RUNNING
17/01/29 17:04:27,919 INFO StandaloneAppClient$ClientEndpoint: Executor updated: app-20170129170427-0000/1 is now RUNNING
17/01/29 17:04:27,922 INFO StandaloneAppClient$ClientEndpoint: Executor updated: app-20170129170427-0000/11 is now RUNNING
17/01/29 17:04:27,925 INFO StandaloneAppClient$ClientEndpoint: Executor updated: app-20170129170427-0000/4 is now RUNNING
17/01/29 17:04:27,927 INFO StandaloneAppClient$ClientEndpoint: Executor updated: app-20170129170427-0000/13 is now RUNNING
17/01/29 17:04:27,929 INFO StandaloneAppClient$ClientEndpoint: Executor updated: app-20170129170427-0000/15 is now RUNNING
17/01/29 17:04:27,931 INFO StandaloneAppClient$ClientEndpoint: Executor updated: app-20170129170427-0000/8 is now RUNNING
17/01/29 17:04:27,934 INFO StandaloneAppClient$ClientEndpoint: Executor updated: app-20170129170427-0000/0 is now RUNNING
17/01/29 17:04:27,935 INFO StandaloneAppClient$ClientEndpoint: Executor updated: app-20170129170427-0000/10 is now RUNNING
17/01/29 17:04:27,937 INFO StandaloneAppClient$ClientEndpoint: Executor updated: app-20170129170427-0000/6 is now RUNNING
17/01/29 17:04:27,940 INFO StandaloneAppClient$ClientEndpoint: Executor updated: app-20170129170427-0000/2 is now RUNNING
17/01/29 17:04:28,031 INFO StandaloneSchedulerBackend: SchedulerBackend is ready for scheduling beginning after reached minRegisteredResourcesRatio: 0.0
17/01/29 17:04:28,448 INFO MemoryStore: Block broadcast_0 stored as values in memory (estimated size 130.8 KB, free 2.1 GB)
17/01/29 17:04:28,516 INFO MemoryStore: Block broadcast_0_piece0 stored as bytes in memory (estimated size 16.5 KB, free 2.1 GB)
17/01/29 17:04:28,519 INFO BlockManagerInfo: Added broadcast_0_piece0 in memory on 10.1.2.115:42089 (size: 16.5 KB, free: 2.1 GB)
17/01/29 17:04:28,526 INFO SparkContext: Created broadcast 0 from textFile at MLUtils.scala:99
17/01/29 17:04:29,191 INFO FileInputFormat: Total input paths to process : 1
17/01/29 17:04:29,230 INFO NetworkTopology: Adding a new node: /default-rack/10.1.2.47:50010
17/01/29 17:04:29,231 INFO NetworkTopology: Adding a new node: /default-rack/10.1.2.135:50010
17/01/29 17:04:29,231 INFO NetworkTopology: Adding a new node: /default-rack/10.1.2.179:50010
17/01/29 17:04:29,231 INFO NetworkTopology: Adding a new node: /default-rack/10.1.2.195:50010
17/01/29 17:04:29,232 INFO NetworkTopology: Adding a new node: /default-rack/10.1.2.163:50010
17/01/29 17:04:29,232 INFO NetworkTopology: Adding a new node: /default-rack/10.1.2.108:50010
17/01/29 17:04:29,233 INFO NetworkTopology: Adding a new node: /default-rack/10.1.2.190:50010
17/01/29 17:04:29,233 INFO NetworkTopology: Adding a new node: /default-rack/10.1.2.114:50010
17/01/29 17:04:29,233 INFO NetworkTopology: Adding a new node: /default-rack/10.1.2.13:50010
17/01/29 17:04:29,234 INFO NetworkTopology: Adding a new node: /default-rack/10.1.2.53:50010
17/01/29 17:04:29,234 INFO NetworkTopology: Adding a new node: /default-rack/10.1.2.113:50010
17/01/29 17:04:29,234 INFO NetworkTopology: Adding a new node: /default-rack/10.1.2.146:50010
17/01/29 17:04:29,235 INFO NetworkTopology: Adding a new node: /default-rack/10.1.2.89:50010
17/01/29 17:04:29,236 INFO NetworkTopology: Adding a new node: /default-rack/10.1.2.222:50010
17/01/29 17:04:29,237 INFO NetworkTopology: Adding a new node: /default-rack/10.1.2.64:50010
17/01/29 17:04:29,279 INFO SparkContext: Starting job: first at GeneralizedLinearAlgorithm.scala:246
17/01/29 17:04:29,293 INFO DAGScheduler: Got job 0 (first at GeneralizedLinearAlgorithm.scala:246) with 1 output partitions
17/01/29 17:04:29,293 INFO DAGScheduler: Final stage: ResultStage 0 (first at GeneralizedLinearAlgorithm.scala:246)
17/01/29 17:04:29,294 INFO DAGScheduler: Parents of final stage: List()
17/01/29 17:04:29,301 INFO DAGScheduler: Missing parents: List()
17/01/29 17:04:29,310 INFO DAGScheduler: Submitting ResultStage 0 (MapPartitionsRDD[6] at map at GeneralizedLinearAlgorithm.scala:246), which has no missing parents
17/01/29 17:04:29,335 INFO MemoryStore: Block broadcast_1 stored as values in memory (estimated size 4.2 KB, free 2.1 GB)
17/01/29 17:04:29,338 INFO MemoryStore: Block broadcast_1_piece0 stored as bytes in memory (estimated size 2.4 KB, free 2.1 GB)
17/01/29 17:04:29,339 INFO BlockManagerInfo: Added broadcast_1_piece0 in memory on 10.1.2.115:42089 (size: 2.4 KB, free: 2.1 GB)
17/01/29 17:04:29,340 INFO SparkContext: Created broadcast 1 from broadcast at DAGScheduler.scala:1012
17/01/29 17:04:29,344 INFO DAGScheduler: Submitting 1 missing tasks from ResultStage 0 (MapPartitionsRDD[6] at map at GeneralizedLinearAlgorithm.scala:246)
17/01/29 17:04:29,345 INFO TaskSchedulerImpl: Adding task set 0.0 with 1 tasks
17/01/29 17:04:32,694 INFO CoarseGrainedSchedulerBackend$DriverEndpoint: Registered executor NettyRpcEndpointRef(null) (10.1.2.47:47726) with ID 7
17/01/29 17:04:32,726 INFO TaskSetManager: Starting task 0.0 in stage 0.0 (TID 0, 10.1.2.47, partition 0, ANY, 5455 bytes)
17/01/29 17:04:32,732 INFO CoarseGrainedSchedulerBackend$DriverEndpoint: Launching task 0 on executor id: 7 hostname: 10.1.2.47.
17/01/29 17:04:32,752 INFO BlockManagerMasterEndpoint: Registering block manager 10.1.2.47:43177 with 2.1 GB RAM, BlockManagerId(7, 10.1.2.47, 43177)
17/01/29 17:04:32,853 INFO CoarseGrainedSchedulerBackend$DriverEndpoint: Registered executor NettyRpcEndpointRef(null) (10.1.2.64:51800) with ID 11
17/01/29 17:04:32,862 INFO CoarseGrainedSchedulerBackend$DriverEndpoint: Registered executor NettyRpcEndpointRef(null) (10.1.2.89:37056) with ID 10
17/01/29 17:04:32,888 INFO CoarseGrainedSchedulerBackend$DriverEndpoint: Registered executor NettyRpcEndpointRef(null) (10.1.2.179:59862) with ID 3
17/01/29 17:04:32,891 INFO CoarseGrainedSchedulerBackend$DriverEndpoint: Registered executor NettyRpcEndpointRef(null) (10.1.2.108:36548) with ID 12
17/01/29 17:04:32,911 INFO CoarseGrainedSchedulerBackend$DriverEndpoint: Registered executor NettyRpcEndpointRef(null) (10.1.2.135:36804) with ID 9
17/01/29 17:04:32,913 INFO BlockManagerMasterEndpoint: Registering block manager 10.1.2.89:39575 with 2.1 GB RAM, BlockManagerId(10, 10.1.2.89, 39575)
17/01/29 17:04:32,913 INFO CoarseGrainedSchedulerBackend$DriverEndpoint: Registered executor NettyRpcEndpointRef(null) (10.1.2.190:43264) with ID 2
17/01/29 17:04:32,923 INFO BlockManagerMasterEndpoint: Registering block manager 10.1.2.64:37605 with 2.1 GB RAM, BlockManagerId(11, 10.1.2.64, 37605)
17/01/29 17:04:32,940 INFO CoarseGrainedSchedulerBackend$DriverEndpoint: Registered executor NettyRpcEndpointRef(null) (10.1.2.162:57240) with ID 5
17/01/29 17:04:32,946 INFO BlockManagerMasterEndpoint: Registering block manager 10.1.2.179:41020 with 2.1 GB RAM, BlockManagerId(3, 10.1.2.179, 41020)
17/01/29 17:04:32,951 INFO CoarseGrainedSchedulerBackend$DriverEndpoint: Registered executor NettyRpcEndpointRef(null) (10.1.2.163:42088) with ID 15
17/01/29 17:04:32,952 INFO BlockManagerMasterEndpoint: Registering block manager 10.1.2.108:41185 with 2.1 GB RAM, BlockManagerId(12, 10.1.2.108, 41185)
17/01/29 17:04:32,957 INFO CoarseGrainedSchedulerBackend$DriverEndpoint: Registered executor NettyRpcEndpointRef(null) (10.1.2.222:58838) with ID 6
17/01/29 17:04:32,967 INFO BlockManagerMasterEndpoint: Registering block manager 10.1.2.135:37284 with 2.1 GB RAM, BlockManagerId(9, 10.1.2.135, 37284)
17/01/29 17:04:32,970 INFO BlockManagerMasterEndpoint: Registering block manager 10.1.2.190:37862 with 2.1 GB RAM, BlockManagerId(2, 10.1.2.190, 37862)
17/01/29 17:04:32,987 INFO CoarseGrainedSchedulerBackend$DriverEndpoint: Registered executor NettyRpcEndpointRef(null) (10.1.2.53:34056) with ID 13
17/01/29 17:04:32,990 INFO CoarseGrainedSchedulerBackend$DriverEndpoint: Registered executor NettyRpcEndpointRef(null) (10.1.2.114:51738) with ID 8
17/01/29 17:04:32,997 INFO BlockManagerMasterEndpoint: Registering block manager 10.1.2.162:45664 with 2.1 GB RAM, BlockManagerId(5, 10.1.2.162, 45664)
17/01/29 17:04:33,000 INFO BlockManagerMasterEndpoint: Registering block manager 10.1.2.163:38469 with 2.1 GB RAM, BlockManagerId(15, 10.1.2.163, 38469)
17/01/29 17:04:33,020 INFO BlockManagerMasterEndpoint: Registering block manager 10.1.2.222:36021 with 2.1 GB RAM, BlockManagerId(6, 10.1.2.222, 36021)
17/01/29 17:04:33,021 INFO CoarseGrainedSchedulerBackend$DriverEndpoint: Registered executor NettyRpcEndpointRef(null) (10.1.2.195:59956) with ID 4
17/01/29 17:04:33,045 INFO BlockManagerMasterEndpoint: Registering block manager 10.1.2.53:37053 with 2.1 GB RAM, BlockManagerId(13, 10.1.2.53, 37053)
17/01/29 17:04:33,048 INFO BlockManagerMasterEndpoint: Registering block manager 10.1.2.114:44486 with 2.1 GB RAM, BlockManagerId(8, 10.1.2.114, 44486)
17/01/29 17:04:33,068 INFO BlockManagerMasterEndpoint: Registering block manager 10.1.2.195:41578 with 2.1 GB RAM, BlockManagerId(4, 10.1.2.195, 41578)
17/01/29 17:04:33,085 INFO BlockManagerInfo: Added broadcast_1_piece0 in memory on 10.1.2.47:43177 (size: 2.4 KB, free: 2.1 GB)
17/01/29 17:04:33,105 INFO CoarseGrainedSchedulerBackend$DriverEndpoint: Registered executor NettyRpcEndpointRef(null) (10.1.2.13:56414) with ID 1
17/01/29 17:04:33,173 INFO BlockManagerMasterEndpoint: Registering block manager 10.1.2.13:42861 with 2.1 GB RAM, BlockManagerId(1, 10.1.2.13, 42861)
17/01/29 17:04:33,207 INFO CoarseGrainedSchedulerBackend$DriverEndpoint: Registered executor NettyRpcEndpointRef(null) (10.1.2.146:38658) with ID 0
17/01/29 17:04:33,218 INFO CoarseGrainedSchedulerBackend$DriverEndpoint: Registered executor NettyRpcEndpointRef(null) (10.1.2.113:42520) with ID 14
17/01/29 17:04:33,258 INFO BlockManagerMasterEndpoint: Registering block manager 10.1.2.146:37857 with 2.1 GB RAM, BlockManagerId(0, 10.1.2.146, 37857)
17/01/29 17:04:33,260 INFO BlockManagerInfo: Added broadcast_0_piece0 in memory on 10.1.2.47:43177 (size: 16.5 KB, free: 2.1 GB)
17/01/29 17:04:33,268 INFO BlockManagerMasterEndpoint: Registering block manager 10.1.2.113:35066 with 2.1 GB RAM, BlockManagerId(14, 10.1.2.113, 35066)
17/01/29 17:04:36,345 INFO BlockManagerInfo: Added rdd_5_0 in memory on 10.1.2.47:43177 (size: 22.2 MB, free: 2.0 GB)
17/01/29 17:04:36,393 INFO DAGScheduler: ResultStage 0 (first at GeneralizedLinearAlgorithm.scala:246) finished in 7.032 s
17/01/29 17:04:36,389 INFO TaskSetManager: Finished task 0.0 in stage 0.0 (TID 0) in 3687 ms on 10.1.2.47 (1/1)
17/01/29 17:04:36,394 INFO TaskSchedulerImpl: Removed TaskSet 0.0, whose tasks have all completed, from pool 
17/01/29 17:04:36,398 INFO DAGScheduler: Job 0 finished: first at GeneralizedLinearAlgorithm.scala:246, took 7.118225 s
17/01/29 17:04:36,408 INFO SparkContext: Starting job: count at DataValidators.scala:40
17/01/29 17:04:36,410 INFO DAGScheduler: Got job 1 (count at DataValidators.scala:40) with 64 output partitions
17/01/29 17:04:36,410 INFO DAGScheduler: Final stage: ResultStage 1 (count at DataValidators.scala:40)
17/01/29 17:04:36,411 INFO DAGScheduler: Parents of final stage: List()
17/01/29 17:04:36,413 INFO DAGScheduler: Missing parents: List()
17/01/29 17:04:36,414 INFO DAGScheduler: Submitting ResultStage 1 (MapPartitionsRDD[7] at filter at DataValidators.scala:40), which has no missing parents
17/01/29 17:04:36,436 INFO MemoryStore: Block broadcast_2 stored as values in memory (estimated size 3.9 KB, free 2.1 GB)
17/01/29 17:04:36,438 INFO MemoryStore: Block broadcast_2_piece0 stored as bytes in memory (estimated size 2.2 KB, free 2.1 GB)
17/01/29 17:04:36,438 INFO BlockManagerInfo: Added broadcast_2_piece0 in memory on 10.1.2.115:42089 (size: 2.2 KB, free: 2.1 GB)
17/01/29 17:04:36,439 INFO SparkContext: Created broadcast 2 from broadcast at DAGScheduler.scala:1012
17/01/29 17:04:36,441 INFO DAGScheduler: Submitting 64 missing tasks from ResultStage 1 (MapPartitionsRDD[7] at filter at DataValidators.scala:40)
17/01/29 17:04:36,442 INFO TaskSchedulerImpl: Adding task set 1.0 with 64 tasks
17/01/29 17:04:36,449 INFO TaskSetManager: Starting task 0.0 in stage 1.0 (TID 1, 10.1.2.47, partition 0, PROCESS_LOCAL, 5373 bytes)
17/01/29 17:04:36,451 INFO TaskSetManager: Starting task 59.0 in stage 1.0 (TID 2, 10.1.2.135, partition 59, NODE_LOCAL, 5373 bytes)
17/01/29 17:04:36,453 INFO TaskSetManager: Starting task 31.0 in stage 1.0 (TID 3, 10.1.2.179, partition 31, NODE_LOCAL, 5373 bytes)
17/01/29 17:04:36,455 INFO TaskSetManager: Starting task 24.0 in stage 1.0 (TID 4, 10.1.2.190, partition 24, NODE_LOCAL, 5373 bytes)
17/01/29 17:04:36,457 INFO TaskSetManager: Starting task 10.0 in stage 1.0 (TID 5, 10.1.2.114, partition 10, NODE_LOCAL, 5373 bytes)
17/01/29 17:04:36,459 INFO TaskSetManager: Starting task 38.0 in stage 1.0 (TID 6, 10.1.2.222, partition 38, NODE_LOCAL, 5373 bytes)
17/01/29 17:04:36,461 INFO TaskSetManager: Starting task 17.0 in stage 1.0 (TID 7, 10.1.2.53, partition 17, NODE_LOCAL, 5373 bytes)
17/01/29 17:04:36,462 INFO TaskSetManager: Starting task 13.0 in stage 1.0 (TID 8, 10.1.2.13, partition 13, NODE_LOCAL, 5373 bytes)
17/01/29 17:04:36,464 INFO TaskSetManager: Starting task 20.0 in stage 1.0 (TID 9, 10.1.2.113, partition 20, NODE_LOCAL, 5373 bytes)
17/01/29 17:04:36,466 INFO TaskSetManager: Starting task 3.0 in stage 1.0 (TID 10, 10.1.2.163, partition 3, NODE_LOCAL, 5373 bytes)
17/01/29 17:04:36,468 INFO TaskSetManager: Starting task 62.0 in stage 1.0 (TID 11, 10.1.2.146, partition 62, NODE_LOCAL, 5373 bytes)
17/01/29 17:04:36,470 INFO TaskSetManager: Starting task 6.0 in stage 1.0 (TID 12, 10.1.2.108, partition 6, NODE_LOCAL, 5373 bytes)
17/01/29 17:04:36,471 INFO TaskSetManager: Starting task 27.0 in stage 1.0 (TID 13, 10.1.2.89, partition 27, NODE_LOCAL, 5373 bytes)
17/01/29 17:04:36,473 INFO TaskSetManager: Starting task 34.0 in stage 1.0 (TID 14, 10.1.2.195, partition 34, NODE_LOCAL, 5373 bytes)
17/01/29 17:04:36,475 INFO TaskSetManager: Starting task 52.0 in stage 1.0 (TID 15, 10.1.2.64, partition 52, NODE_LOCAL, 5373 bytes)
17/01/29 17:04:36,477 INFO TaskSetManager: Starting task 45.0 in stage 1.0 (TID 16, 10.1.2.190, partition 45, NODE_LOCAL, 5373 bytes)
17/01/29 17:04:36,479 INFO TaskSetManager: Starting task 48.0 in stage 1.0 (TID 17, 10.1.2.114, partition 48, NODE_LOCAL, 5373 bytes)
17/01/29 17:04:36,480 INFO TaskSetManager: Starting task 41.0 in stage 1.0 (TID 18, 10.1.2.222, partition 41, NODE_LOCAL, 5373 bytes)
17/01/29 17:04:36,482 INFO TaskSetManager: Starting task 55.0 in stage 1.0 (TID 19, 10.1.2.53, partition 55, NODE_LOCAL, 5373 bytes)
17/01/29 17:04:36,484 INFO CoarseGrainedSchedulerBackend$DriverEndpoint: Launching task 2 on executor id: 9 hostname: 10.1.2.135.
17/01/29 17:04:36,486 INFO CoarseGrainedSchedulerBackend$DriverEndpoint: Launching task 3 on executor id: 3 hostname: 10.1.2.179.
17/01/29 17:04:36,487 INFO CoarseGrainedSchedulerBackend$DriverEndpoint: Launching task 4 on executor id: 2 hostname: 10.1.2.190.
17/01/29 17:04:36,487 INFO CoarseGrainedSchedulerBackend$DriverEndpoint: Launching task 16 on executor id: 2 hostname: 10.1.2.190.
17/01/29 17:04:36,488 INFO CoarseGrainedSchedulerBackend$DriverEndpoint: Launching task 5 on executor id: 8 hostname: 10.1.2.114.
17/01/29 17:04:36,489 INFO CoarseGrainedSchedulerBackend$DriverEndpoint: Launching task 17 on executor id: 8 hostname: 10.1.2.114.
17/01/29 17:04:36,490 INFO CoarseGrainedSchedulerBackend$DriverEndpoint: Launching task 6 on executor id: 6 hostname: 10.1.2.222.
17/01/29 17:04:36,491 INFO CoarseGrainedSchedulerBackend$DriverEndpoint: Launching task 18 on executor id: 6 hostname: 10.1.2.222.
17/01/29 17:04:36,491 INFO CoarseGrainedSchedulerBackend$DriverEndpoint: Launching task 7 on executor id: 13 hostname: 10.1.2.53.
17/01/29 17:04:36,492 INFO CoarseGrainedSchedulerBackend$DriverEndpoint: Launching task 19 on executor id: 13 hostname: 10.1.2.53.
17/01/29 17:04:36,493 INFO CoarseGrainedSchedulerBackend$DriverEndpoint: Launching task 8 on executor id: 1 hostname: 10.1.2.13.
17/01/29 17:04:36,494 INFO CoarseGrainedSchedulerBackend$DriverEndpoint: Launching task 9 on executor id: 14 hostname: 10.1.2.113.
17/01/29 17:04:36,495 INFO CoarseGrainedSchedulerBackend$DriverEndpoint: Launching task 10 on executor id: 15 hostname: 10.1.2.163.
17/01/29 17:04:36,495 INFO CoarseGrainedSchedulerBackend$DriverEndpoint: Launching task 11 on executor id: 0 hostname: 10.1.2.146.
17/01/29 17:04:36,496 INFO CoarseGrainedSchedulerBackend$DriverEndpoint: Launching task 12 on executor id: 12 hostname: 10.1.2.108.
17/01/29 17:04:36,497 INFO CoarseGrainedSchedulerBackend$DriverEndpoint: Launching task 13 on executor id: 10 hostname: 10.1.2.89.
17/01/29 17:04:36,497 INFO CoarseGrainedSchedulerBackend$DriverEndpoint: Launching task 14 on executor id: 4 hostname: 10.1.2.195.
17/01/29 17:04:36,498 INFO CoarseGrainedSchedulerBackend$DriverEndpoint: Launching task 15 on executor id: 11 hostname: 10.1.2.64.
17/01/29 17:04:36,499 INFO CoarseGrainedSchedulerBackend$DriverEndpoint: Launching task 1 on executor id: 7 hostname: 10.1.2.47.
17/01/29 17:04:36,523 INFO BlockManagerInfo: Added broadcast_2_piece0 in memory on 10.1.2.47:43177 (size: 2.2 KB, free: 2.0 GB)
17/01/29 17:04:36,578 INFO TaskSetManager: Finished task 0.0 in stage 1.0 (TID 1) in 131 ms on 10.1.2.47 (1/64)
13.928: [GC [PSYoungGen: 1024512K->140454K(1195008K)] 1024512K->140526K(3926016K), 0.0702350 secs] [Times: user=0.12 sys=0.04, real=0.07 secs] 
17/01/29 17:04:36,801 INFO BlockManagerInfo: Added broadcast_2_piece0 in memory on 10.1.2.114:44486 (size: 2.2 KB, free: 2.1 GB)
17/01/29 17:04:36,841 INFO BlockManagerInfo: Added broadcast_2_piece0 in memory on 10.1.2.108:41185 (size: 2.2 KB, free: 2.1 GB)
17/01/29 17:04:36,871 INFO BlockManagerInfo: Added broadcast_2_piece0 in memory on 10.1.2.195:41578 (size: 2.2 KB, free: 2.1 GB)
17/01/29 17:04:36,872 INFO BlockManagerInfo: Added broadcast_2_piece0 in memory on 10.1.2.113:35066 (size: 2.2 KB, free: 2.1 GB)
17/01/29 17:04:36,873 INFO BlockManagerInfo: Added broadcast_2_piece0 in memory on 10.1.2.163:38469 (size: 2.2 KB, free: 2.1 GB)
17/01/29 17:04:36,874 INFO BlockManagerInfo: Added broadcast_2_piece0 in memory on 10.1.2.64:37605 (size: 2.2 KB, free: 2.1 GB)
17/01/29 17:04:36,874 INFO BlockManagerInfo: Added broadcast_2_piece0 in memory on 10.1.2.89:39575 (size: 2.2 KB, free: 2.1 GB)
17/01/29 17:04:36,875 INFO BlockManagerInfo: Added broadcast_2_piece0 in memory on 10.1.2.146:37857 (size: 2.2 KB, free: 2.1 GB)
17/01/29 17:04:36,875 INFO BlockManagerInfo: Added broadcast_2_piece0 in memory on 10.1.2.179:41020 (size: 2.2 KB, free: 2.1 GB)
17/01/29 17:04:36,877 INFO BlockManagerInfo: Removed broadcast_1_piece0 on 10.1.2.115:42089 in memory (size: 2.4 KB, free: 2.1 GB)
17/01/29 17:04:36,880 INFO BlockManagerInfo: Added broadcast_2_piece0 in memory on 10.1.2.13:42861 (size: 2.2 KB, free: 2.1 GB)
17/01/29 17:04:36,885 INFO BlockManagerInfo: Removed broadcast_1_piece0 on 10.1.2.47:43177 in memory (size: 2.4 KB, free: 2.0 GB)
17/01/29 17:04:36,887 INFO BlockManagerInfo: Added broadcast_2_piece0 in memory on 10.1.2.135:37284 (size: 2.2 KB, free: 2.1 GB)
17/01/29 17:04:36,889 INFO BlockManagerInfo: Added broadcast_2_piece0 in memory on 10.1.2.53:37053 (size: 2.2 KB, free: 2.1 GB)
17/01/29 17:04:36,897 INFO BlockManagerInfo: Added broadcast_2_piece0 in memory on 10.1.2.222:36021 (size: 2.2 KB, free: 2.1 GB)
17/01/29 17:04:36,908 INFO BlockManagerInfo: Added broadcast_2_piece0 in memory on 10.1.2.190:37862 (size: 2.2 KB, free: 2.1 GB)
17/01/29 17:04:37,009 INFO BlockManagerInfo: Added broadcast_0_piece0 in memory on 10.1.2.108:41185 (size: 16.5 KB, free: 2.1 GB)
17/01/29 17:04:37,020 INFO BlockManagerInfo: Added broadcast_0_piece0 in memory on 10.1.2.114:44486 (size: 16.5 KB, free: 2.1 GB)
17/01/29 17:04:37,034 INFO BlockManagerInfo: Added broadcast_0_piece0 in memory on 10.1.2.146:37857 (size: 16.5 KB, free: 2.1 GB)
17/01/29 17:04:37,035 INFO BlockManagerInfo: Added broadcast_0_piece0 in memory on 10.1.2.113:35066 (size: 16.5 KB, free: 2.1 GB)
17/01/29 17:04:37,040 INFO BlockManagerInfo: Added broadcast_0_piece0 in memory on 10.1.2.163:38469 (size: 16.5 KB, free: 2.1 GB)
17/01/29 17:04:37,050 INFO BlockManagerInfo: Added broadcast_0_piece0 in memory on 10.1.2.179:41020 (size: 16.5 KB, free: 2.1 GB)
17/01/29 17:04:37,057 INFO BlockManagerInfo: Added broadcast_0_piece0 in memory on 10.1.2.135:37284 (size: 16.5 KB, free: 2.1 GB)
17/01/29 17:04:37,073 INFO BlockManagerInfo: Added broadcast_0_piece0 in memory on 10.1.2.89:39575 (size: 16.5 KB, free: 2.1 GB)
17/01/29 17:04:37,073 INFO BlockManagerInfo: Added broadcast_0_piece0 in memory on 10.1.2.195:41578 (size: 16.5 KB, free: 2.1 GB)
17/01/29 17:04:37,077 INFO BlockManagerInfo: Added broadcast_0_piece0 in memory on 10.1.2.64:37605 (size: 16.5 KB, free: 2.1 GB)
17/01/29 17:04:37,092 INFO BlockManagerInfo: Added broadcast_0_piece0 in memory on 10.1.2.190:37862 (size: 16.5 KB, free: 2.1 GB)
17/01/29 17:04:37,093 INFO BlockManagerInfo: Added broadcast_0_piece0 in memory on 10.1.2.13:42861 (size: 16.5 KB, free: 2.1 GB)
17/01/29 17:04:37,094 INFO BlockManagerInfo: Added broadcast_0_piece0 in memory on 10.1.2.53:37053 (size: 16.5 KB, free: 2.1 GB)
17/01/29 17:04:37,102 INFO BlockManagerInfo: Added broadcast_0_piece0 in memory on 10.1.2.222:36021 (size: 16.5 KB, free: 2.1 GB)
17/01/29 17:04:39,618 INFO TaskSetManager: Starting task 1.0 in stage 1.0 (TID 20, 10.1.2.190, partition 1, ANY, 5373 bytes)
17/01/29 17:04:39,619 INFO TaskSetManager: Starting task 2.0 in stage 1.0 (TID 21, 10.1.2.146, partition 2, ANY, 5373 bytes)
17/01/29 17:04:39,621 INFO TaskSetManager: Starting task 4.0 in stage 1.0 (TID 22, 10.1.2.162, partition 4, ANY, 5373 bytes)
17/01/29 17:04:39,623 INFO TaskSetManager: Starting task 5.0 in stage 1.0 (TID 23, 10.1.2.163, partition 5, ANY, 5373 bytes)
17/01/29 17:04:39,625 INFO TaskSetManager: Starting task 7.0 in stage 1.0 (TID 24, 10.1.2.108, partition 7, ANY, 5373 bytes)
17/01/29 17:04:39,628 INFO TaskSetManager: Starting task 8.0 in stage 1.0 (TID 25, 10.1.2.89, partition 8, ANY, 5373 bytes)
17/01/29 17:04:39,632 INFO TaskSetManager: Starting task 9.0 in stage 1.0 (TID 26, 10.1.2.13, partition 9, ANY, 5373 bytes)
17/01/29 17:04:39,636 INFO TaskSetManager: Starting task 11.0 in stage 1.0 (TID 27, 10.1.2.195, partition 11, ANY, 5373 bytes)
17/01/29 17:04:39,638 INFO TaskSetManager: Starting task 12.0 in stage 1.0 (TID 28, 10.1.2.222, partition 12, ANY, 5373 bytes)
17/01/29 17:04:39,642 INFO TaskSetManager: Starting task 14.0 in stage 1.0 (TID 29, 10.1.2.114, partition 14, ANY, 5373 bytes)
17/01/29 17:04:39,644 INFO TaskSetManager: Starting task 15.0 in stage 1.0 (TID 30, 10.1.2.47, partition 15, ANY, 5373 bytes)
17/01/29 17:04:39,647 INFO TaskSetManager: Starting task 16.0 in stage 1.0 (TID 31, 10.1.2.113, partition 16, ANY, 5373 bytes)
17/01/29 17:04:39,651 INFO TaskSetManager: Starting task 18.0 in stage 1.0 (TID 32, 10.1.2.135, partition 18, ANY, 5373 bytes)
17/01/29 17:04:39,654 INFO TaskSetManager: Starting task 19.0 in stage 1.0 (TID 33, 10.1.2.53, partition 19, ANY, 5373 bytes)
17/01/29 17:04:39,666 INFO TaskSetManager: Starting task 21.0 in stage 1.0 (TID 34, 10.1.2.64, partition 21, ANY, 5373 bytes)
17/01/29 17:04:39,668 INFO TaskSetManager: Starting task 22.0 in stage 1.0 (TID 35, 10.1.2.179, partition 22, ANY, 5373 bytes)
17/01/29 17:04:39,671 INFO TaskSetManager: Starting task 23.0 in stage 1.0 (TID 36, 10.1.2.190, partition 23, ANY, 5373 bytes)
17/01/29 17:04:39,674 INFO TaskSetManager: Starting task 25.0 in stage 1.0 (TID 37, 10.1.2.146, partition 25, ANY, 5373 bytes)
17/01/29 17:04:39,676 INFO TaskSetManager: Starting task 26.0 in stage 1.0 (TID 38, 10.1.2.162, partition 26, ANY, 5373 bytes)
17/01/29 17:04:39,679 INFO TaskSetManager: Starting task 28.0 in stage 1.0 (TID 39, 10.1.2.163, partition 28, ANY, 5373 bytes)
17/01/29 17:04:39,681 INFO TaskSetManager: Starting task 29.0 in stage 1.0 (TID 40, 10.1.2.108, partition 29, ANY, 5373 bytes)
17/01/29 17:04:39,682 INFO TaskSetManager: Starting task 30.0 in stage 1.0 (TID 41, 10.1.2.89, partition 30, ANY, 5373 bytes)
17/01/29 17:04:39,683 INFO TaskSetManager: Starting task 32.0 in stage 1.0 (TID 42, 10.1.2.13, partition 32, ANY, 5373 bytes)
17/01/29 17:04:39,685 INFO TaskSetManager: Starting task 33.0 in stage 1.0 (TID 43, 10.1.2.195, partition 33, ANY, 5373 bytes)
17/01/29 17:04:39,686 INFO TaskSetManager: Starting task 35.0 in stage 1.0 (TID 44, 10.1.2.222, partition 35, ANY, 5373 bytes)
17/01/29 17:04:39,688 INFO TaskSetManager: Starting task 36.0 in stage 1.0 (TID 45, 10.1.2.114, partition 36, ANY, 5373 bytes)
17/01/29 17:04:39,689 INFO TaskSetManager: Starting task 37.0 in stage 1.0 (TID 46, 10.1.2.47, partition 37, ANY, 5373 bytes)
17/01/29 17:04:39,691 INFO TaskSetManager: Starting task 39.0 in stage 1.0 (TID 47, 10.1.2.113, partition 39, ANY, 5373 bytes)
17/01/29 17:04:39,692 INFO TaskSetManager: Starting task 40.0 in stage 1.0 (TID 48, 10.1.2.135, partition 40, ANY, 5373 bytes)
17/01/29 17:04:39,694 INFO TaskSetManager: Starting task 42.0 in stage 1.0 (TID 49, 10.1.2.53, partition 42, ANY, 5373 bytes)
17/01/29 17:04:39,695 INFO TaskSetManager: Starting task 43.0 in stage 1.0 (TID 50, 10.1.2.64, partition 43, ANY, 5373 bytes)
17/01/29 17:04:39,697 INFO TaskSetManager: Starting task 44.0 in stage 1.0 (TID 51, 10.1.2.179, partition 44, ANY, 5373 bytes)
17/01/29 17:04:39,699 INFO TaskSetManager: Starting task 46.0 in stage 1.0 (TID 52, 10.1.2.146, partition 46, ANY, 5373 bytes)
17/01/29 17:04:39,701 INFO TaskSetManager: Starting task 47.0 in stage 1.0 (TID 53, 10.1.2.162, partition 47, ANY, 5373 bytes)
17/01/29 17:04:39,702 INFO TaskSetManager: Starting task 49.0 in stage 1.0 (TID 54, 10.1.2.163, partition 49, ANY, 5373 bytes)
17/01/29 17:04:39,705 INFO TaskSetManager: Starting task 50.0 in stage 1.0 (TID 55, 10.1.2.108, partition 50, ANY, 5373 bytes)
17/01/29 17:04:39,707 INFO TaskSetManager: Starting task 51.0 in stage 1.0 (TID 56, 10.1.2.89, partition 51, ANY, 5373 bytes)
17/01/29 17:04:39,709 INFO TaskSetManager: Starting task 53.0 in stage 1.0 (TID 57, 10.1.2.13, partition 53, ANY, 5373 bytes)
17/01/29 17:04:39,711 INFO TaskSetManager: Starting task 54.0 in stage 1.0 (TID 58, 10.1.2.195, partition 54, ANY, 5373 bytes)
17/01/29 17:04:39,713 INFO TaskSetManager: Starting task 56.0 in stage 1.0 (TID 59, 10.1.2.47, partition 56, ANY, 5373 bytes)
17/01/29 17:04:39,715 INFO TaskSetManager: Starting task 57.0 in stage 1.0 (TID 60, 10.1.2.113, partition 57, ANY, 5373 bytes)
17/01/29 17:04:39,717 INFO TaskSetManager: Starting task 58.0 in stage 1.0 (TID 61, 10.1.2.135, partition 58, ANY, 5373 bytes)
17/01/29 17:04:39,719 INFO TaskSetManager: Starting task 60.0 in stage 1.0 (TID 62, 10.1.2.64, partition 60, ANY, 5373 bytes)
17/01/29 17:04:39,721 INFO TaskSetManager: Starting task 61.0 in stage 1.0 (TID 63, 10.1.2.179, partition 61, ANY, 5373 bytes)
17/01/29 17:04:39,723 INFO TaskSetManager: Starting task 63.0 in stage 1.0 (TID 64, 10.1.2.162, partition 63, ANY, 5373 bytes)
17/01/29 17:04:39,724 INFO CoarseGrainedSchedulerBackend$DriverEndpoint: Launching task 20 on executor id: 2 hostname: 10.1.2.190.
17/01/29 17:04:39,725 INFO CoarseGrainedSchedulerBackend$DriverEndpoint: Launching task 36 on executor id: 2 hostname: 10.1.2.190.
17/01/29 17:04:39,725 INFO CoarseGrainedSchedulerBackend$DriverEndpoint: Launching task 21 on executor id: 0 hostname: 10.1.2.146.
17/01/29 17:04:39,726 INFO CoarseGrainedSchedulerBackend$DriverEndpoint: Launching task 37 on executor id: 0 hostname: 10.1.2.146.
17/01/29 17:04:39,726 INFO CoarseGrainedSchedulerBackend$DriverEndpoint: Launching task 52 on executor id: 0 hostname: 10.1.2.146.
17/01/29 17:04:39,727 INFO CoarseGrainedSchedulerBackend$DriverEndpoint: Launching task 22 on executor id: 5 hostname: 10.1.2.162.
17/01/29 17:04:39,727 INFO CoarseGrainedSchedulerBackend$DriverEndpoint: Launching task 38 on executor id: 5 hostname: 10.1.2.162.
17/01/29 17:04:39,728 INFO CoarseGrainedSchedulerBackend$DriverEndpoint: Launching task 53 on executor id: 5 hostname: 10.1.2.162.
17/01/29 17:04:39,729 INFO CoarseGrainedSchedulerBackend$DriverEndpoint: Launching task 64 on executor id: 5 hostname: 10.1.2.162.
17/01/29 17:04:39,729 INFO CoarseGrainedSchedulerBackend$DriverEndpoint: Launching task 23 on executor id: 15 hostname: 10.1.2.163.
17/01/29 17:04:39,730 INFO CoarseGrainedSchedulerBackend$DriverEndpoint: Launching task 39 on executor id: 15 hostname: 10.1.2.163.
17/01/29 17:04:39,730 INFO CoarseGrainedSchedulerBackend$DriverEndpoint: Launching task 54 on executor id: 15 hostname: 10.1.2.163.
17/01/29 17:04:39,731 INFO CoarseGrainedSchedulerBackend$DriverEndpoint: Launching task 24 on executor id: 12 hostname: 10.1.2.108.
17/01/29 17:04:39,731 INFO CoarseGrainedSchedulerBackend$DriverEndpoint: Launching task 40 on executor id: 12 hostname: 10.1.2.108.
17/01/29 17:04:39,732 INFO CoarseGrainedSchedulerBackend$DriverEndpoint: Launching task 55 on executor id: 12 hostname: 10.1.2.108.
17/01/29 17:04:39,732 INFO CoarseGrainedSchedulerBackend$DriverEndpoint: Launching task 25 on executor id: 10 hostname: 10.1.2.89.
17/01/29 17:04:39,733 INFO CoarseGrainedSchedulerBackend$DriverEndpoint: Launching task 41 on executor id: 10 hostname: 10.1.2.89.
17/01/29 17:04:39,733 INFO CoarseGrainedSchedulerBackend$DriverEndpoint: Launching task 56 on executor id: 10 hostname: 10.1.2.89.
17/01/29 17:04:39,734 INFO CoarseGrainedSchedulerBackend$DriverEndpoint: Launching task 26 on executor id: 1 hostname: 10.1.2.13.
17/01/29 17:04:39,734 INFO CoarseGrainedSchedulerBackend$DriverEndpoint: Launching task 42 on executor id: 1 hostname: 10.1.2.13.
17/01/29 17:04:39,735 INFO CoarseGrainedSchedulerBackend$DriverEndpoint: Launching task 57 on executor id: 1 hostname: 10.1.2.13.
17/01/29 17:04:39,736 INFO CoarseGrainedSchedulerBackend$DriverEndpoint: Launching task 27 on executor id: 4 hostname: 10.1.2.195.
17/01/29 17:04:39,736 INFO CoarseGrainedSchedulerBackend$DriverEndpoint: Launching task 43 on executor id: 4 hostname: 10.1.2.195.
17/01/29 17:04:39,737 INFO CoarseGrainedSchedulerBackend$DriverEndpoint: Launching task 58 on executor id: 4 hostname: 10.1.2.195.
17/01/29 17:04:39,737 INFO CoarseGrainedSchedulerBackend$DriverEndpoint: Launching task 28 on executor id: 6 hostname: 10.1.2.222.
17/01/29 17:04:39,738 INFO CoarseGrainedSchedulerBackend$DriverEndpoint: Launching task 44 on executor id: 6 hostname: 10.1.2.222.
17/01/29 17:04:39,738 INFO CoarseGrainedSchedulerBackend$DriverEndpoint: Launching task 29 on executor id: 8 hostname: 10.1.2.114.
17/01/29 17:04:39,738 INFO CoarseGrainedSchedulerBackend$DriverEndpoint: Launching task 45 on executor id: 8 hostname: 10.1.2.114.
17/01/29 17:04:39,739 INFO CoarseGrainedSchedulerBackend$DriverEndpoint: Launching task 30 on executor id: 7 hostname: 10.1.2.47.
17/01/29 17:04:39,739 INFO CoarseGrainedSchedulerBackend$DriverEndpoint: Launching task 46 on executor id: 7 hostname: 10.1.2.47.
17/01/29 17:04:39,740 INFO CoarseGrainedSchedulerBackend$DriverEndpoint: Launching task 59 on executor id: 7 hostname: 10.1.2.47.
17/01/29 17:04:39,740 INFO CoarseGrainedSchedulerBackend$DriverEndpoint: Launching task 31 on executor id: 14 hostname: 10.1.2.113.
17/01/29 17:04:39,740 INFO CoarseGrainedSchedulerBackend$DriverEndpoint: Launching task 47 on executor id: 14 hostname: 10.1.2.113.
17/01/29 17:04:39,741 INFO CoarseGrainedSchedulerBackend$DriverEndpoint: Launching task 60 on executor id: 14 hostname: 10.1.2.113.
17/01/29 17:04:39,741 INFO CoarseGrainedSchedulerBackend$DriverEndpoint: Launching task 32 on executor id: 9 hostname: 10.1.2.135.
17/01/29 17:04:39,742 INFO CoarseGrainedSchedulerBackend$DriverEndpoint: Launching task 48 on executor id: 9 hostname: 10.1.2.135.
17/01/29 17:04:39,742 INFO CoarseGrainedSchedulerBackend$DriverEndpoint: Launching task 61 on executor id: 9 hostname: 10.1.2.135.
17/01/29 17:04:39,743 INFO CoarseGrainedSchedulerBackend$DriverEndpoint: Launching task 33 on executor id: 13 hostname: 10.1.2.53.
17/01/29 17:04:39,743 INFO CoarseGrainedSchedulerBackend$DriverEndpoint: Launching task 49 on executor id: 13 hostname: 10.1.2.53.
17/01/29 17:04:39,744 INFO CoarseGrainedSchedulerBackend$DriverEndpoint: Launching task 34 on executor id: 11 hostname: 10.1.2.64.
17/01/29 17:04:39,744 INFO CoarseGrainedSchedulerBackend$DriverEndpoint: Launching task 50 on executor id: 11 hostname: 10.1.2.64.
17/01/29 17:04:39,744 INFO CoarseGrainedSchedulerBackend$DriverEndpoint: Launching task 62 on executor id: 11 hostname: 10.1.2.64.
17/01/29 17:04:39,745 INFO CoarseGrainedSchedulerBackend$DriverEndpoint: Launching task 35 on executor id: 3 hostname: 10.1.2.179.
17/01/29 17:04:39,745 INFO CoarseGrainedSchedulerBackend$DriverEndpoint: Launching task 51 on executor id: 3 hostname: 10.1.2.179.
17/01/29 17:04:39,745 INFO CoarseGrainedSchedulerBackend$DriverEndpoint: Launching task 63 on executor id: 3 hostname: 10.1.2.179.
17/01/29 17:04:40,071 INFO BlockManagerInfo: Added broadcast_2_piece0 in memory on 10.1.2.162:45664 (size: 2.2 KB, free: 2.1 GB)
17/01/29 17:04:40,314 INFO BlockManagerInfo: Added broadcast_0_piece0 in memory on 10.1.2.162:45664 (size: 16.5 KB, free: 2.1 GB)
17/01/29 17:04:41,129 INFO BlockManagerInfo: Added rdd_5_20 in memory on 10.1.2.113:35066 (size: 22.2 MB, free: 2.0 GB)
17/01/29 17:04:41,227 INFO TaskSetManager: Finished task 20.0 in stage 1.0 (TID 9) in 4764 ms on 10.1.2.113 (2/64)
17/01/29 17:04:41,260 INFO BlockManagerInfo: Added rdd_5_27 in memory on 10.1.2.89:39575 (size: 22.1 MB, free: 2.0 GB)
17/01/29 17:04:41,361 INFO TaskSetManager: Finished task 27.0 in stage 1.0 (TID 13) in 4891 ms on 10.1.2.89 (3/64)
17/01/29 17:04:42,036 INFO BlockManagerInfo: Added rdd_5_31 in memory on 10.1.2.179:41020 (size: 22.2 MB, free: 2.0 GB)
17/01/29 17:04:42,054 INFO BlockManagerInfo: Added rdd_5_13 in memory on 10.1.2.13:42861 (size: 22.2 MB, free: 2.0 GB)
17/01/29 17:04:42,070 INFO BlockManagerInfo: Added rdd_5_62 in memory on 10.1.2.146:37857 (size: 22.2 MB, free: 2.0 GB)
17/01/29 17:04:42,078 INFO BlockManagerInfo: Added rdd_5_34 in memory on 10.1.2.195:41578 (size: 22.2 MB, free: 2.0 GB)
17/01/29 17:04:42,115 INFO TaskSetManager: Finished task 31.0 in stage 1.0 (TID 3) in 5663 ms on 10.1.2.179 (4/64)
17/01/29 17:04:42,133 INFO TaskSetManager: Finished task 13.0 in stage 1.0 (TID 8) in 5672 ms on 10.1.2.13 (5/64)
17/01/29 17:04:42,143 INFO BlockManagerInfo: Added rdd_5_59 in memory on 10.1.2.135:37284 (size: 22.2 MB, free: 2.0 GB)
17/01/29 17:04:42,144 INFO TaskSetManager: Finished task 62.0 in stage 1.0 (TID 11) in 5678 ms on 10.1.2.146 (6/64)
17/01/29 17:04:42,185 INFO BlockManagerInfo: Added rdd_5_52 in memory on 10.1.2.64:37605 (size: 22.2 MB, free: 2.0 GB)
17/01/29 17:04:42,217 INFO TaskSetManager: Finished task 59.0 in stage 1.0 (TID 2) in 5766 ms on 10.1.2.135 (7/64)
17/01/29 17:04:42,237 INFO TaskSetManager: Finished task 34.0 in stage 1.0 (TID 14) in 5765 ms on 10.1.2.195 (8/64)
17/01/29 17:04:42,260 INFO TaskSetManager: Finished task 52.0 in stage 1.0 (TID 15) in 5786 ms on 10.1.2.64 (9/64)
17/01/29 17:04:42,386 INFO BlockManagerInfo: Added rdd_5_48 in memory on 10.1.2.114:44486 (size: 22.1 MB, free: 2.0 GB)
17/01/29 17:04:42,462 INFO TaskSetManager: Finished task 48.0 in stage 1.0 (TID 17) in 5984 ms on 10.1.2.114 (10/64)
17/01/29 17:04:42,477 INFO BlockManagerInfo: Added rdd_5_45 in memory on 10.1.2.190:37862 (size: 22.2 MB, free: 2.0 GB)
17/01/29 17:04:42,531 INFO BlockManagerInfo: Added rdd_5_24 in memory on 10.1.2.190:37862 (size: 22.2 MB, free: 2.0 GB)
17/01/29 17:04:42,544 INFO BlockManagerInfo: Added rdd_5_6 in memory on 10.1.2.108:41185 (size: 22.2 MB, free: 2.0 GB)
17/01/29 17:04:42,547 INFO TaskSetManager: Finished task 45.0 in stage 1.0 (TID 16) in 6071 ms on 10.1.2.190 (11/64)
17/01/29 17:04:42,562 INFO TaskSetManager: Finished task 24.0 in stage 1.0 (TID 4) in 6109 ms on 10.1.2.190 (12/64)
17/01/29 17:04:42,608 INFO TaskSetManager: Finished task 6.0 in stage 1.0 (TID 12) in 6140 ms on 10.1.2.108 (13/64)
17/01/29 17:04:42,622 INFO BlockManagerInfo: Added rdd_5_3 in memory on 10.1.2.163:38469 (size: 22.2 MB, free: 2.0 GB)
17/01/29 17:04:42,626 INFO BlockManagerInfo: Added rdd_5_10 in memory on 10.1.2.114:44486 (size: 22.2 MB, free: 2.0 GB)
17/01/29 17:04:42,642 INFO TaskSetManager: Finished task 10.0 in stage 1.0 (TID 5) in 6186 ms on 10.1.2.114 (14/64)
17/01/29 17:04:42,723 INFO TaskSetManager: Finished task 3.0 in stage 1.0 (TID 10) in 6259 ms on 10.1.2.163 (15/64)
17/01/29 17:04:43,214 INFO BlockManagerInfo: Added rdd_5_41 in memory on 10.1.2.222:36021 (size: 22.2 MB, free: 2.0 GB)
17/01/29 17:04:43,304 INFO TaskSetManager: Finished task 41.0 in stage 1.0 (TID 18) in 6825 ms on 10.1.2.222 (16/64)
17/01/29 17:04:43,809 INFO BlockManagerInfo: Added rdd_5_38 in memory on 10.1.2.222:36021 (size: 22.2 MB, free: 2.0 GB)
17/01/29 17:04:43,827 INFO TaskSetManager: Finished task 38.0 in stage 1.0 (TID 6) in 7370 ms on 10.1.2.222 (17/64)
17/01/29 17:04:43,968 INFO BlockManagerInfo: Added rdd_5_36 in memory on 10.1.2.114:44486 (size: 22.2 MB, free: 2.0 GB)
17/01/29 17:04:43,991 INFO TaskSetManager: Finished task 36.0 in stage 1.0 (TID 45) in 4303 ms on 10.1.2.114 (18/64)
17/01/29 17:04:44,005 INFO BlockManagerInfo: Added rdd_5_14 in memory on 10.1.2.114:44486 (size: 22.2 MB, free: 2031.7 MB)
17/01/29 17:04:44,017 INFO BlockManagerInfo: Added rdd_5_46 in memory on 10.1.2.146:37857 (size: 22.1 MB, free: 2.0 GB)
17/01/29 17:04:44,019 INFO TaskSetManager: Finished task 14.0 in stage 1.0 (TID 29) in 4380 ms on 10.1.2.114 (19/64)
17/01/29 17:04:44,066 INFO BlockManagerInfo: Added rdd_5_30 in memory on 10.1.2.89:39575 (size: 22.2 MB, free: 2.0 GB)
17/01/29 17:04:44,066 INFO BlockManagerInfo: Added rdd_5_8 in memory on 10.1.2.89:39575 (size: 22.2 MB, free: 2.0 GB)
17/01/29 17:04:44,068 INFO BlockManagerInfo: Added rdd_5_17 in memory on 10.1.2.53:37053 (size: 22.2 MB, free: 2.0 GB)
17/01/29 17:04:44,076 INFO BlockManagerInfo: Added rdd_5_51 in memory on 10.1.2.89:39575 (size: 22.2 MB, free: 2031.7 MB)
17/01/29 17:04:44,079 INFO TaskSetManager: Finished task 46.0 in stage 1.0 (TID 52) in 4382 ms on 10.1.2.146 (20/64)
17/01/29 17:04:44,083 INFO TaskSetManager: Finished task 8.0 in stage 1.0 (TID 25) in 4458 ms on 10.1.2.89 (21/64)
17/01/29 17:04:44,083 INFO TaskSetManager: Finished task 30.0 in stage 1.0 (TID 41) in 4402 ms on 10.1.2.89 (22/64)
17/01/29 17:04:44,109 INFO TaskSetManager: Finished task 51.0 in stage 1.0 (TID 56) in 4404 ms on 10.1.2.89 (23/64)
17/01/29 17:04:44,122 INFO BlockManagerInfo: Added rdd_5_55 in memory on 10.1.2.53:37053 (size: 22.2 MB, free: 2.0 GB)
17/01/29 17:04:44,140 INFO TaskSetManager: Finished task 17.0 in stage 1.0 (TID 7) in 7681 ms on 10.1.2.53 (24/64)
17/01/29 17:04:44,141 INFO TaskSetManager: Finished task 55.0 in stage 1.0 (TID 19) in 7661 ms on 10.1.2.53 (25/64)
17/01/29 17:04:44,148 INFO BlockManagerInfo: Added rdd_5_57 in memory on 10.1.2.113:35066 (size: 22.2 MB, free: 2.0 GB)
17/01/29 17:04:44,148 INFO BlockManagerInfo: Added rdd_5_58 in memory on 10.1.2.135:37284 (size: 22.2 MB, free: 2.0 GB)
17/01/29 17:04:44,155 INFO BlockManagerInfo: Added rdd_5_39 in memory on 10.1.2.113:35066 (size: 22.1 MB, free: 2.0 GB)
17/01/29 17:04:44,164 INFO BlockManagerInfo: Added rdd_5_2 in memory on 10.1.2.146:37857 (size: 22.1 MB, free: 2.0 GB)
17/01/29 17:04:44,165 INFO BlockManagerInfo: Added rdd_5_25 in memory on 10.1.2.146:37857 (size: 22.2 MB, free: 2031.7 MB)
17/01/29 17:04:44,167 INFO TaskSetManager: Finished task 58.0 in stage 1.0 (TID 61) in 4450 ms on 10.1.2.135 (26/64)
17/01/29 17:04:44,169 INFO TaskSetManager: Finished task 57.0 in stage 1.0 (TID 60) in 4455 ms on 10.1.2.113 (27/64)
17/01/29 17:04:44,170 INFO TaskSetManager: Finished task 39.0 in stage 1.0 (TID 47) in 4481 ms on 10.1.2.113 (28/64)
17/01/29 17:04:44,186 INFO BlockManagerInfo: Added rdd_5_18 in memory on 10.1.2.135:37284 (size: 22.2 MB, free: 2.0 GB)
17/01/29 17:04:44,189 INFO TaskSetManager: Finished task 2.0 in stage 1.0 (TID 21) in 4571 ms on 10.1.2.146 (29/64)
17/01/29 17:04:44,191 INFO TaskSetManager: Finished task 25.0 in stage 1.0 (TID 37) in 4520 ms on 10.1.2.146 (30/64)
17/01/29 17:04:44,200 INFO TaskSetManager: Finished task 18.0 in stage 1.0 (TID 32) in 4551 ms on 10.1.2.135 (31/64)
17/01/29 17:04:44,200 INFO BlockManagerInfo: Added rdd_5_16 in memory on 10.1.2.113:35066 (size: 22.1 MB, free: 2031.7 MB)
17/01/29 17:04:44,206 INFO BlockManagerInfo: Added rdd_5_1 in memory on 10.1.2.190:37862 (size: 22.2 MB, free: 2.0 GB)
17/01/29 17:04:44,219 INFO TaskSetManager: Finished task 1.0 in stage 1.0 (TID 20) in 4602 ms on 10.1.2.190 (32/64)
17/01/29 17:04:44,225 INFO TaskSetManager: Finished task 16.0 in stage 1.0 (TID 31) in 4579 ms on 10.1.2.113 (33/64)
17/01/29 17:04:44,233 INFO BlockManagerInfo: Added rdd_5_40 in memory on 10.1.2.135:37284 (size: 22.2 MB, free: 2031.6 MB)
17/01/29 17:04:44,247 INFO TaskSetManager: Finished task 40.0 in stage 1.0 (TID 48) in 4555 ms on 10.1.2.135 (34/64)
17/01/29 17:04:44,266 INFO BlockManagerInfo: Added rdd_5_23 in memory on 10.1.2.190:37862 (size: 22.2 MB, free: 2031.6 MB)
17/01/29 17:04:44,279 INFO TaskSetManager: Finished task 23.0 in stage 1.0 (TID 36) in 4609 ms on 10.1.2.190 (35/64)
17/01/29 17:04:44,378 INFO BlockManagerInfo: Added rdd_5_60 in memory on 10.1.2.64:37605 (size: 22.1 MB, free: 2.0 GB)
17/01/29 17:04:44,398 INFO TaskSetManager: Finished task 60.0 in stage 1.0 (TID 62) in 4679 ms on 10.1.2.64 (36/64)
17/01/29 17:04:44,403 INFO BlockManagerInfo: Added rdd_5_22 in memory on 10.1.2.179:41020 (size: 22.2 MB, free: 2.0 GB)
17/01/29 17:04:44,427 INFO TaskSetManager: Finished task 22.0 in stage 1.0 (TID 35) in 4761 ms on 10.1.2.179 (37/64)
17/01/29 17:04:44,440 INFO BlockManagerInfo: Added rdd_5_61 in memory on 10.1.2.179:41020 (size: 22.2 MB, free: 2.0 GB)
17/01/29 17:04:44,466 INFO TaskSetManager: Finished task 61.0 in stage 1.0 (TID 63) in 4745 ms on 10.1.2.179 (38/64)
17/01/29 17:04:44,466 INFO BlockManagerInfo: Added rdd_5_33 in memory on 10.1.2.195:41578 (size: 22.2 MB, free: 2.0 GB)
17/01/29 17:04:44,478 INFO BlockManagerInfo: Added rdd_5_44 in memory on 10.1.2.179:41020 (size: 22.2 MB, free: 2031.6 MB)
17/01/29 17:04:44,481 INFO TaskSetManager: Finished task 33.0 in stage 1.0 (TID 43) in 4797 ms on 10.1.2.195 (39/64)
17/01/29 17:04:44,491 INFO TaskSetManager: Finished task 44.0 in stage 1.0 (TID 51) in 4794 ms on 10.1.2.179 (40/64)
17/01/29 17:04:44,512 INFO BlockManagerInfo: Added rdd_5_11 in memory on 10.1.2.195:41578 (size: 22.2 MB, free: 2.0 GB)
17/01/29 17:04:44,535 INFO TaskSetManager: Finished task 11.0 in stage 1.0 (TID 27) in 4902 ms on 10.1.2.195 (41/64)
17/01/29 17:04:44,540 INFO BlockManagerInfo: Added rdd_5_54 in memory on 10.1.2.195:41578 (size: 22.2 MB, free: 2031.6 MB)
17/01/29 17:04:44,555 INFO TaskSetManager: Finished task 54.0 in stage 1.0 (TID 58) in 4845 ms on 10.1.2.195 (42/64)
17/01/29 17:04:44,556 INFO BlockManagerInfo: Added rdd_5_53 in memory on 10.1.2.13:42861 (size: 22.2 MB, free: 2.0 GB)
17/01/29 17:04:44,556 INFO BlockManagerInfo: Added rdd_5_9 in memory on 10.1.2.13:42861 (size: 22.2 MB, free: 2.0 GB)
17/01/29 17:04:44,575 INFO TaskSetManager: Finished task 53.0 in stage 1.0 (TID 57) in 4868 ms on 10.1.2.13 (43/64)
17/01/29 17:04:44,576 INFO TaskSetManager: Finished task 9.0 in stage 1.0 (TID 26) in 4948 ms on 10.1.2.13 (44/64)
17/01/29 17:04:44,594 INFO BlockManagerInfo: Added rdd_5_43 in memory on 10.1.2.64:37605 (size: 22.2 MB, free: 2.0 GB)
17/01/29 17:04:44,606 INFO TaskSetManager: Finished task 43.0 in stage 1.0 (TID 50) in 4912 ms on 10.1.2.64 (45/64)
17/01/29 17:04:44,632 INFO BlockManagerInfo: Added rdd_5_32 in memory on 10.1.2.13:42861 (size: 22.2 MB, free: 2031.6 MB)
17/01/29 17:04:44,650 INFO BlockManagerInfo: Added rdd_5_21 in memory on 10.1.2.64:37605 (size: 22.2 MB, free: 2031.7 MB)
17/01/29 17:04:44,656 INFO TaskSetManager: Finished task 32.0 in stage 1.0 (TID 42) in 4974 ms on 10.1.2.13 (46/64)
17/01/29 17:04:44,662 INFO TaskSetManager: Finished task 21.0 in stage 1.0 (TID 34) in 5008 ms on 10.1.2.64 (47/64)
17/01/29 17:04:44,711 INFO BlockManagerInfo: Added rdd_5_35 in memory on 10.1.2.222:36021 (size: 22.1 MB, free: 2.0 GB)
17/01/29 17:04:44,737 INFO TaskSetManager: Finished task 35.0 in stage 1.0 (TID 44) in 5052 ms on 10.1.2.222 (48/64)
17/01/29 17:04:44,837 INFO BlockManagerInfo: Added rdd_5_28 in memory on 10.1.2.163:38469 (size: 22.2 MB, free: 2.0 GB)
17/01/29 17:04:44,852 INFO TaskSetManager: Finished task 28.0 in stage 1.0 (TID 39) in 5175 ms on 10.1.2.163 (49/64)
17/01/29 17:04:44,859 INFO BlockManagerInfo: Added rdd_5_12 in memory on 10.1.2.222:36021 (size: 22.2 MB, free: 2031.6 MB)
17/01/29 17:04:44,872 INFO TaskSetManager: Finished task 12.0 in stage 1.0 (TID 28) in 5236 ms on 10.1.2.222 (50/64)
17/01/29 17:04:44,890 INFO BlockManagerInfo: Added rdd_5_49 in memory on 10.1.2.163:38469 (size: 22.2 MB, free: 2.0 GB)
17/01/29 17:04:44,915 INFO TaskSetManager: Finished task 49.0 in stage 1.0 (TID 54) in 5214 ms on 10.1.2.163 (51/64)
17/01/29 17:04:45,010 INFO BlockManagerInfo: Added rdd_5_5 in memory on 10.1.2.163:38469 (size: 22.2 MB, free: 2031.6 MB)
17/01/29 17:04:45,023 INFO TaskSetManager: Finished task 5.0 in stage 1.0 (TID 23) in 5402 ms on 10.1.2.163 (52/64)
17/01/29 17:04:45,135 INFO BlockManagerInfo: Added rdd_5_15 in memory on 10.1.2.47:43177 (size: 22.1 MB, free: 2.0 GB)
17/01/29 17:04:45,154 INFO TaskSetManager: Finished task 15.0 in stage 1.0 (TID 30) in 5511 ms on 10.1.2.47 (53/64)
17/01/29 17:04:45,174 INFO BlockManagerInfo: Added rdd_5_42 in memory on 10.1.2.53:37053 (size: 22.2 MB, free: 2.0 GB)
17/01/29 17:04:45,188 INFO TaskSetManager: Finished task 42.0 in stage 1.0 (TID 49) in 5495 ms on 10.1.2.53 (54/64)
17/01/29 17:04:45,284 INFO BlockManagerInfo: Added rdd_5_37 in memory on 10.1.2.47:43177 (size: 22.2 MB, free: 2.0 GB)
17/01/29 17:04:45,298 INFO TaskSetManager: Finished task 37.0 in stage 1.0 (TID 46) in 5609 ms on 10.1.2.47 (55/64)
17/01/29 17:04:45,374 INFO BlockManagerInfo: Added rdd_5_56 in memory on 10.1.2.47:43177 (size: 22.2 MB, free: 2031.7 MB)
17/01/29 17:04:45,387 INFO TaskSetManager: Finished task 56.0 in stage 1.0 (TID 59) in 5676 ms on 10.1.2.47 (56/64)
17/01/29 17:04:45,437 INFO BlockManagerInfo: Added rdd_5_19 in memory on 10.1.2.53:37053 (size: 22.2 MB, free: 2031.6 MB)
17/01/29 17:04:45,449 INFO TaskSetManager: Finished task 19.0 in stage 1.0 (TID 33) in 5798 ms on 10.1.2.53 (57/64)
17/01/29 17:04:45,580 INFO BlockManagerInfo: Added rdd_5_7 in memory on 10.1.2.108:41185 (size: 22.2 MB, free: 2.0 GB)
17/01/29 17:04:45,600 INFO TaskSetManager: Finished task 7.0 in stage 1.0 (TID 24) in 5977 ms on 10.1.2.108 (58/64)
17/01/29 17:04:45,674 INFO BlockManagerInfo: Added rdd_5_29 in memory on 10.1.2.108:41185 (size: 22.2 MB, free: 2.0 GB)
17/01/29 17:04:45,694 INFO TaskSetManager: Finished task 29.0 in stage 1.0 (TID 40) in 6015 ms on 10.1.2.108 (59/64)
17/01/29 17:04:45,769 INFO BlockManagerInfo: Added rdd_5_50 in memory on 10.1.2.108:41185 (size: 22.1 MB, free: 2031.7 MB)
17/01/29 17:04:45,780 INFO TaskSetManager: Finished task 50.0 in stage 1.0 (TID 55) in 6077 ms on 10.1.2.108 (60/64)
17/01/29 17:04:46,811 INFO BlockManagerInfo: Added rdd_5_63 in memory on 10.1.2.162:45664 (size: 22.2 MB, free: 2.0 GB)
17/01/29 17:04:46,873 INFO TaskSetManager: Finished task 63.0 in stage 1.0 (TID 64) in 7150 ms on 10.1.2.162 (61/64)
17/01/29 17:04:47,001 INFO BlockManagerInfo: Added rdd_5_47 in memory on 10.1.2.162:45664 (size: 22.2 MB, free: 2.0 GB)
17/01/29 17:04:47,015 INFO TaskSetManager: Finished task 47.0 in stage 1.0 (TID 53) in 7316 ms on 10.1.2.162 (62/64)
17/01/29 17:04:47,057 INFO BlockManagerInfo: Added rdd_5_4 in memory on 10.1.2.162:45664 (size: 22.2 MB, free: 2.0 GB)
17/01/29 17:04:47,068 INFO TaskSetManager: Finished task 4.0 in stage 1.0 (TID 22) in 7447 ms on 10.1.2.162 (63/64)
17/01/29 17:04:47,120 INFO BlockManagerInfo: Added rdd_5_26 in memory on 10.1.2.162:45664 (size: 22.2 MB, free: 2031.6 MB)
17/01/29 17:04:47,132 INFO TaskSetManager: Finished task 26.0 in stage 1.0 (TID 38) in 7457 ms on 10.1.2.162 (64/64)
17/01/29 17:04:47,132 INFO TaskSchedulerImpl: Removed TaskSet 1.0, whose tasks have all completed, from pool 
17/01/29 17:04:47,132 INFO DAGScheduler: ResultStage 1 (count at DataValidators.scala:40) finished in 10.686 s
17/01/29 17:04:47,133 INFO DAGScheduler: Job 1 finished: count at DataValidators.scala:40, took 10.723888 s
17/01/29 17:04:47,142 INFO SparkContext: Starting job: count at GradientDescent.scala:209
17/01/29 17:04:47,144 INFO DAGScheduler: Got job 2 (count at GradientDescent.scala:209) with 64 output partitions
17/01/29 17:04:47,144 INFO DAGScheduler: Final stage: ResultStage 2 (count at GradientDescent.scala:209)
17/01/29 17:04:47,144 INFO DAGScheduler: Parents of final stage: List()
17/01/29 17:04:47,147 INFO DAGScheduler: Missing parents: List()
17/01/29 17:04:47,147 INFO DAGScheduler: Submitting ResultStage 2 (MapPartitionsRDD[8] at map at GeneralizedLinearAlgorithm.scala:297), which has no missing parents
17/01/29 17:04:47,153 INFO MemoryStore: Block broadcast_3 stored as values in memory (estimated size 3.9 KB, free 2.1 GB)
17/01/29 17:04:47,154 INFO MemoryStore: Block broadcast_3_piece0 stored as bytes in memory (estimated size 2.2 KB, free 2.1 GB)
17/01/29 17:04:47,155 INFO BlockManagerInfo: Added broadcast_3_piece0 in memory on 10.1.2.115:42089 (size: 2.2 KB, free: 2.1 GB)
17/01/29 17:04:47,156 INFO SparkContext: Created broadcast 3 from broadcast at DAGScheduler.scala:1012
17/01/29 17:04:47,157 INFO DAGScheduler: Submitting 64 missing tasks from ResultStage 2 (MapPartitionsRDD[8] at map at GeneralizedLinearAlgorithm.scala:297)
17/01/29 17:04:47,158 INFO TaskSchedulerImpl: Adding task set 2.0 with 64 tasks
17/01/29 17:04:47,161 INFO TaskSetManager: Starting task 11.0 in stage 2.0 (TID 65, 10.1.2.195, partition 11, PROCESS_LOCAL, 5373 bytes)
17/01/29 17:04:47,162 INFO TaskSetManager: Starting task 17.0 in stage 2.0 (TID 66, 10.1.2.53, partition 17, PROCESS_LOCAL, 5373 bytes)
17/01/29 17:04:47,163 INFO TaskSetManager: Starting task 8.0 in stage 2.0 (TID 67, 10.1.2.89, partition 8, PROCESS_LOCAL, 5373 bytes)
17/01/29 17:04:47,163 INFO TaskSetManager: Starting task 16.0 in stage 2.0 (TID 68, 10.1.2.113, partition 16, PROCESS_LOCAL, 5373 bytes)
17/01/29 17:04:47,164 INFO TaskSetManager: Starting task 4.0 in stage 2.0 (TID 69, 10.1.2.162, partition 4, PROCESS_LOCAL, 5373 bytes)
17/01/29 17:04:47,164 INFO TaskSetManager: Starting task 0.0 in stage 2.0 (TID 70, 10.1.2.47, partition 0, PROCESS_LOCAL, 5373 bytes)
17/01/29 17:04:47,165 INFO TaskSetManager: Starting task 6.0 in stage 2.0 (TID 71, 10.1.2.108, partition 6, PROCESS_LOCAL, 5373 bytes)
17/01/29 17:04:47,166 INFO TaskSetManager: Starting task 22.0 in stage 2.0 (TID 72, 10.1.2.179, partition 22, PROCESS_LOCAL, 5373 bytes)
17/01/29 17:04:47,166 INFO TaskSetManager: Starting task 12.0 in stage 2.0 (TID 73, 10.1.2.222, partition 12, PROCESS_LOCAL, 5373 bytes)
17/01/29 17:04:47,167 INFO TaskSetManager: Starting task 1.0 in stage 2.0 (TID 74, 10.1.2.190, partition 1, PROCESS_LOCAL, 5373 bytes)
17/01/29 17:04:47,168 INFO TaskSetManager: Starting task 9.0 in stage 2.0 (TID 75, 10.1.2.13, partition 9, PROCESS_LOCAL, 5373 bytes)
17/01/29 17:04:47,168 INFO TaskSetManager: Starting task 2.0 in stage 2.0 (TID 76, 10.1.2.146, partition 2, PROCESS_LOCAL, 5373 bytes)
17/01/29 17:04:47,169 INFO TaskSetManager: Starting task 10.0 in stage 2.0 (TID 77, 10.1.2.114, partition 10, PROCESS_LOCAL, 5373 bytes)
17/01/29 17:04:47,170 INFO TaskSetManager: Starting task 3.0 in stage 2.0 (TID 78, 10.1.2.163, partition 3, PROCESS_LOCAL, 5373 bytes)
17/01/29 17:04:47,170 INFO TaskSetManager: Starting task 18.0 in stage 2.0 (TID 79, 10.1.2.135, partition 18, PROCESS_LOCAL, 5373 bytes)
17/01/29 17:04:47,171 INFO TaskSetManager: Starting task 21.0 in stage 2.0 (TID 80, 10.1.2.64, partition 21, PROCESS_LOCAL, 5373 bytes)
17/01/29 17:04:47,172 INFO TaskSetManager: Starting task 33.0 in stage 2.0 (TID 81, 10.1.2.195, partition 33, PROCESS_LOCAL, 5373 bytes)
17/01/29 17:04:47,172 INFO TaskSetManager: Starting task 19.0 in stage 2.0 (TID 82, 10.1.2.53, partition 19, PROCESS_LOCAL, 5373 bytes)
17/01/29 17:04:47,173 INFO TaskSetManager: Starting task 27.0 in stage 2.0 (TID 83, 10.1.2.89, partition 27, PROCESS_LOCAL, 5373 bytes)
17/01/29 17:04:47,174 INFO TaskSetManager: Starting task 20.0 in stage 2.0 (TID 84, 10.1.2.113, partition 20, PROCESS_LOCAL, 5373 bytes)
17/01/29 17:04:47,174 INFO TaskSetManager: Starting task 26.0 in stage 2.0 (TID 85, 10.1.2.162, partition 26, PROCESS_LOCAL, 5373 bytes)
17/01/29 17:04:47,175 INFO TaskSetManager: Starting task 15.0 in stage 2.0 (TID 86, 10.1.2.47, partition 15, PROCESS_LOCAL, 5373 bytes)
17/01/29 17:04:47,176 INFO TaskSetManager: Starting task 7.0 in stage 2.0 (TID 87, 10.1.2.108, partition 7, PROCESS_LOCAL, 5373 bytes)
17/01/29 17:04:47,176 INFO TaskSetManager: Starting task 31.0 in stage 2.0 (TID 88, 10.1.2.179, partition 31, PROCESS_LOCAL, 5373 bytes)
17/01/29 17:04:47,177 INFO TaskSetManager: Starting task 35.0 in stage 2.0 (TID 89, 10.1.2.222, partition 35, PROCESS_LOCAL, 5373 bytes)
17/01/29 17:04:47,178 INFO TaskSetManager: Starting task 23.0 in stage 2.0 (TID 90, 10.1.2.190, partition 23, PROCESS_LOCAL, 5373 bytes)
17/01/29 17:04:47,178 INFO TaskSetManager: Starting task 13.0 in stage 2.0 (TID 91, 10.1.2.13, partition 13, PROCESS_LOCAL, 5373 bytes)
17/01/29 17:04:47,179 INFO TaskSetManager: Starting task 25.0 in stage 2.0 (TID 92, 10.1.2.146, partition 25, PROCESS_LOCAL, 5373 bytes)
17/01/29 17:04:47,180 INFO TaskSetManager: Starting task 14.0 in stage 2.0 (TID 93, 10.1.2.114, partition 14, PROCESS_LOCAL, 5373 bytes)
17/01/29 17:04:47,181 INFO TaskSetManager: Starting task 5.0 in stage 2.0 (TID 94, 10.1.2.163, partition 5, PROCESS_LOCAL, 5373 bytes)
17/01/29 17:04:47,182 INFO TaskSetManager: Starting task 40.0 in stage 2.0 (TID 95, 10.1.2.135, partition 40, PROCESS_LOCAL, 5373 bytes)
17/01/29 17:04:47,182 INFO TaskSetManager: Starting task 43.0 in stage 2.0 (TID 96, 10.1.2.64, partition 43, PROCESS_LOCAL, 5373 bytes)
17/01/29 17:04:47,183 INFO TaskSetManager: Starting task 34.0 in stage 2.0 (TID 97, 10.1.2.195, partition 34, PROCESS_LOCAL, 5373 bytes)
17/01/29 17:04:47,184 INFO TaskSetManager: Starting task 42.0 in stage 2.0 (TID 98, 10.1.2.53, partition 42, PROCESS_LOCAL, 5373 bytes)
17/01/29 17:04:47,184 INFO TaskSetManager: Starting task 30.0 in stage 2.0 (TID 99, 10.1.2.89, partition 30, PROCESS_LOCAL, 5373 bytes)
17/01/29 17:04:47,185 INFO TaskSetManager: Starting task 39.0 in stage 2.0 (TID 100, 10.1.2.113, partition 39, PROCESS_LOCAL, 5373 bytes)
17/01/29 17:04:47,188 INFO TaskSetManager: Starting task 47.0 in stage 2.0 (TID 101, 10.1.2.162, partition 47, PROCESS_LOCAL, 5373 bytes)
17/01/29 17:04:47,189 INFO TaskSetManager: Starting task 37.0 in stage 2.0 (TID 102, 10.1.2.47, partition 37, PROCESS_LOCAL, 5373 bytes)
17/01/29 17:04:47,190 INFO TaskSetManager: Starting task 29.0 in stage 2.0 (TID 103, 10.1.2.108, partition 29, PROCESS_LOCAL, 5373 bytes)
17/01/29 17:04:47,191 INFO TaskSetManager: Starting task 44.0 in stage 2.0 (TID 104, 10.1.2.179, partition 44, PROCESS_LOCAL, 5373 bytes)
17/01/29 17:04:47,192 INFO TaskSetManager: Starting task 38.0 in stage 2.0 (TID 105, 10.1.2.222, partition 38, PROCESS_LOCAL, 5373 bytes)
17/01/29 17:04:47,193 INFO TaskSetManager: Starting task 24.0 in stage 2.0 (TID 106, 10.1.2.190, partition 24, PROCESS_LOCAL, 5373 bytes)
17/01/29 17:04:47,193 INFO TaskSetManager: Starting task 32.0 in stage 2.0 (TID 107, 10.1.2.13, partition 32, PROCESS_LOCAL, 5373 bytes)
17/01/29 17:04:47,194 INFO TaskSetManager: Starting task 46.0 in stage 2.0 (TID 108, 10.1.2.146, partition 46, PROCESS_LOCAL, 5373 bytes)
17/01/29 17:04:47,195 INFO TaskSetManager: Starting task 36.0 in stage 2.0 (TID 109, 10.1.2.114, partition 36, PROCESS_LOCAL, 5373 bytes)
17/01/29 17:04:47,196 INFO TaskSetManager: Starting task 28.0 in stage 2.0 (TID 110, 10.1.2.163, partition 28, PROCESS_LOCAL, 5373 bytes)
17/01/29 17:04:47,197 INFO TaskSetManager: Starting task 58.0 in stage 2.0 (TID 111, 10.1.2.135, partition 58, PROCESS_LOCAL, 5373 bytes)
17/01/29 17:04:47,198 INFO TaskSetManager: Starting task 52.0 in stage 2.0 (TID 112, 10.1.2.64, partition 52, PROCESS_LOCAL, 5373 bytes)
17/01/29 17:04:47,199 INFO TaskSetManager: Starting task 54.0 in stage 2.0 (TID 113, 10.1.2.195, partition 54, PROCESS_LOCAL, 5373 bytes)
17/01/29 17:04:47,199 INFO TaskSetManager: Starting task 55.0 in stage 2.0 (TID 114, 10.1.2.53, partition 55, PROCESS_LOCAL, 5373 bytes)
17/01/29 17:04:47,200 INFO TaskSetManager: Starting task 51.0 in stage 2.0 (TID 115, 10.1.2.89, partition 51, PROCESS_LOCAL, 5373 bytes)
17/01/29 17:04:47,201 INFO TaskSetManager: Starting task 57.0 in stage 2.0 (TID 116, 10.1.2.113, partition 57, PROCESS_LOCAL, 5373 bytes)
17/01/29 17:04:47,202 INFO TaskSetManager: Starting task 63.0 in stage 2.0 (TID 117, 10.1.2.162, partition 63, PROCESS_LOCAL, 5373 bytes)
17/01/29 17:04:47,203 INFO TaskSetManager: Starting task 56.0 in stage 2.0 (TID 118, 10.1.2.47, partition 56, PROCESS_LOCAL, 5373 bytes)
17/01/29 17:04:47,203 INFO TaskSetManager: Starting task 50.0 in stage 2.0 (TID 119, 10.1.2.108, partition 50, PROCESS_LOCAL, 5373 bytes)
17/01/29 17:04:47,204 INFO TaskSetManager: Starting task 61.0 in stage 2.0 (TID 120, 10.1.2.179, partition 61, PROCESS_LOCAL, 5373 bytes)
17/01/29 17:04:47,205 INFO TaskSetManager: Starting task 41.0 in stage 2.0 (TID 121, 10.1.2.222, partition 41, PROCESS_LOCAL, 5373 bytes)
17/01/29 17:04:47,206 INFO TaskSetManager: Starting task 45.0 in stage 2.0 (TID 122, 10.1.2.190, partition 45, PROCESS_LOCAL, 5373 bytes)
17/01/29 17:04:47,207 INFO TaskSetManager: Starting task 53.0 in stage 2.0 (TID 123, 10.1.2.13, partition 53, PROCESS_LOCAL, 5373 bytes)
17/01/29 17:04:47,208 INFO TaskSetManager: Starting task 62.0 in stage 2.0 (TID 124, 10.1.2.146, partition 62, PROCESS_LOCAL, 5373 bytes)
17/01/29 17:04:47,208 INFO TaskSetManager: Starting task 48.0 in stage 2.0 (TID 125, 10.1.2.114, partition 48, PROCESS_LOCAL, 5373 bytes)
17/01/29 17:04:47,209 INFO TaskSetManager: Starting task 49.0 in stage 2.0 (TID 126, 10.1.2.163, partition 49, PROCESS_LOCAL, 5373 bytes)
17/01/29 17:04:47,210 INFO TaskSetManager: Starting task 59.0 in stage 2.0 (TID 127, 10.1.2.135, partition 59, PROCESS_LOCAL, 5373 bytes)
17/01/29 17:04:47,211 INFO TaskSetManager: Starting task 60.0 in stage 2.0 (TID 128, 10.1.2.64, partition 60, PROCESS_LOCAL, 5373 bytes)
17/01/29 17:04:47,212 INFO CoarseGrainedSchedulerBackend$DriverEndpoint: Launching task 65 on executor id: 4 hostname: 10.1.2.195.
17/01/29 17:04:47,212 INFO CoarseGrainedSchedulerBackend$DriverEndpoint: Launching task 81 on executor id: 4 hostname: 10.1.2.195.
17/01/29 17:04:47,212 INFO CoarseGrainedSchedulerBackend$DriverEndpoint: Launching task 97 on executor id: 4 hostname: 10.1.2.195.
17/01/29 17:04:47,212 INFO CoarseGrainedSchedulerBackend$DriverEndpoint: Launching task 113 on executor id: 4 hostname: 10.1.2.195.
17/01/29 17:04:47,213 INFO CoarseGrainedSchedulerBackend$DriverEndpoint: Launching task 66 on executor id: 13 hostname: 10.1.2.53.
17/01/29 17:04:47,213 INFO CoarseGrainedSchedulerBackend$DriverEndpoint: Launching task 82 on executor id: 13 hostname: 10.1.2.53.
17/01/29 17:04:47,214 INFO CoarseGrainedSchedulerBackend$DriverEndpoint: Launching task 98 on executor id: 13 hostname: 10.1.2.53.
17/01/29 17:04:47,215 INFO CoarseGrainedSchedulerBackend$DriverEndpoint: Launching task 114 on executor id: 13 hostname: 10.1.2.53.
17/01/29 17:04:47,216 INFO CoarseGrainedSchedulerBackend$DriverEndpoint: Launching task 67 on executor id: 10 hostname: 10.1.2.89.
17/01/29 17:04:47,216 INFO CoarseGrainedSchedulerBackend$DriverEndpoint: Launching task 83 on executor id: 10 hostname: 10.1.2.89.
17/01/29 17:04:47,217 INFO CoarseGrainedSchedulerBackend$DriverEndpoint: Launching task 99 on executor id: 10 hostname: 10.1.2.89.
17/01/29 17:04:47,217 INFO CoarseGrainedSchedulerBackend$DriverEndpoint: Launching task 115 on executor id: 10 hostname: 10.1.2.89.
17/01/29 17:04:47,218 INFO CoarseGrainedSchedulerBackend$DriverEndpoint: Launching task 68 on executor id: 14 hostname: 10.1.2.113.
17/01/29 17:04:47,218 INFO CoarseGrainedSchedulerBackend$DriverEndpoint: Launching task 84 on executor id: 14 hostname: 10.1.2.113.
17/01/29 17:04:47,219 INFO CoarseGrainedSchedulerBackend$DriverEndpoint: Launching task 100 on executor id: 14 hostname: 10.1.2.113.
17/01/29 17:04:47,219 INFO CoarseGrainedSchedulerBackend$DriverEndpoint: Launching task 116 on executor id: 14 hostname: 10.1.2.113.
17/01/29 17:04:47,220 INFO CoarseGrainedSchedulerBackend$DriverEndpoint: Launching task 69 on executor id: 5 hostname: 10.1.2.162.
17/01/29 17:04:47,221 INFO CoarseGrainedSchedulerBackend$DriverEndpoint: Launching task 85 on executor id: 5 hostname: 10.1.2.162.
17/01/29 17:04:47,222 INFO CoarseGrainedSchedulerBackend$DriverEndpoint: Launching task 101 on executor id: 5 hostname: 10.1.2.162.
17/01/29 17:04:47,222 INFO CoarseGrainedSchedulerBackend$DriverEndpoint: Launching task 117 on executor id: 5 hostname: 10.1.2.162.
17/01/29 17:04:47,223 INFO CoarseGrainedSchedulerBackend$DriverEndpoint: Launching task 70 on executor id: 7 hostname: 10.1.2.47.
17/01/29 17:04:47,223 INFO CoarseGrainedSchedulerBackend$DriverEndpoint: Launching task 86 on executor id: 7 hostname: 10.1.2.47.
17/01/29 17:04:47,224 INFO CoarseGrainedSchedulerBackend$DriverEndpoint: Launching task 102 on executor id: 7 hostname: 10.1.2.47.
17/01/29 17:04:47,224 INFO CoarseGrainedSchedulerBackend$DriverEndpoint: Launching task 118 on executor id: 7 hostname: 10.1.2.47.
17/01/29 17:04:47,225 INFO CoarseGrainedSchedulerBackend$DriverEndpoint: Launching task 71 on executor id: 12 hostname: 10.1.2.108.
17/01/29 17:04:47,229 INFO CoarseGrainedSchedulerBackend$DriverEndpoint: Launching task 87 on executor id: 12 hostname: 10.1.2.108.
17/01/29 17:04:47,229 INFO CoarseGrainedSchedulerBackend$DriverEndpoint: Launching task 103 on executor id: 12 hostname: 10.1.2.108.
17/01/29 17:04:47,230 INFO CoarseGrainedSchedulerBackend$DriverEndpoint: Launching task 119 on executor id: 12 hostname: 10.1.2.108.
17/01/29 17:04:47,230 INFO CoarseGrainedSchedulerBackend$DriverEndpoint: Launching task 72 on executor id: 3 hostname: 10.1.2.179.
17/01/29 17:04:47,231 INFO CoarseGrainedSchedulerBackend$DriverEndpoint: Launching task 88 on executor id: 3 hostname: 10.1.2.179.
17/01/29 17:04:47,232 INFO CoarseGrainedSchedulerBackend$DriverEndpoint: Launching task 104 on executor id: 3 hostname: 10.1.2.179.
17/01/29 17:04:47,232 INFO CoarseGrainedSchedulerBackend$DriverEndpoint: Launching task 120 on executor id: 3 hostname: 10.1.2.179.
17/01/29 17:04:47,233 INFO CoarseGrainedSchedulerBackend$DriverEndpoint: Launching task 73 on executor id: 6 hostname: 10.1.2.222.
17/01/29 17:04:47,233 INFO CoarseGrainedSchedulerBackend$DriverEndpoint: Launching task 89 on executor id: 6 hostname: 10.1.2.222.
17/01/29 17:04:47,233 INFO CoarseGrainedSchedulerBackend$DriverEndpoint: Launching task 105 on executor id: 6 hostname: 10.1.2.222.
17/01/29 17:04:47,233 INFO CoarseGrainedSchedulerBackend$DriverEndpoint: Launching task 121 on executor id: 6 hostname: 10.1.2.222.
17/01/29 17:04:47,234 INFO CoarseGrainedSchedulerBackend$DriverEndpoint: Launching task 74 on executor id: 2 hostname: 10.1.2.190.
17/01/29 17:04:47,234 INFO CoarseGrainedSchedulerBackend$DriverEndpoint: Launching task 90 on executor id: 2 hostname: 10.1.2.190.
17/01/29 17:04:47,234 INFO CoarseGrainedSchedulerBackend$DriverEndpoint: Launching task 106 on executor id: 2 hostname: 10.1.2.190.
17/01/29 17:04:47,235 INFO CoarseGrainedSchedulerBackend$DriverEndpoint: Launching task 122 on executor id: 2 hostname: 10.1.2.190.
17/01/29 17:04:47,235 INFO CoarseGrainedSchedulerBackend$DriverEndpoint: Launching task 75 on executor id: 1 hostname: 10.1.2.13.
17/01/29 17:04:47,235 INFO CoarseGrainedSchedulerBackend$DriverEndpoint: Launching task 91 on executor id: 1 hostname: 10.1.2.13.
17/01/29 17:04:47,235 INFO CoarseGrainedSchedulerBackend$DriverEndpoint: Launching task 107 on executor id: 1 hostname: 10.1.2.13.
17/01/29 17:04:47,236 INFO CoarseGrainedSchedulerBackend$DriverEndpoint: Launching task 123 on executor id: 1 hostname: 10.1.2.13.
17/01/29 17:04:47,238 INFO CoarseGrainedSchedulerBackend$DriverEndpoint: Launching task 76 on executor id: 0 hostname: 10.1.2.146.
17/01/29 17:04:47,238 INFO CoarseGrainedSchedulerBackend$DriverEndpoint: Launching task 92 on executor id: 0 hostname: 10.1.2.146.
17/01/29 17:04:47,238 INFO CoarseGrainedSchedulerBackend$DriverEndpoint: Launching task 108 on executor id: 0 hostname: 10.1.2.146.
17/01/29 17:04:47,239 INFO CoarseGrainedSchedulerBackend$DriverEndpoint: Launching task 124 on executor id: 0 hostname: 10.1.2.146.
17/01/29 17:04:47,239 INFO CoarseGrainedSchedulerBackend$DriverEndpoint: Launching task 77 on executor id: 8 hostname: 10.1.2.114.
17/01/29 17:04:47,239 INFO CoarseGrainedSchedulerBackend$DriverEndpoint: Launching task 93 on executor id: 8 hostname: 10.1.2.114.
17/01/29 17:04:47,241 INFO CoarseGrainedSchedulerBackend$DriverEndpoint: Launching task 109 on executor id: 8 hostname: 10.1.2.114.
17/01/29 17:04:47,242 INFO CoarseGrainedSchedulerBackend$DriverEndpoint: Launching task 125 on executor id: 8 hostname: 10.1.2.114.
17/01/29 17:04:47,242 INFO CoarseGrainedSchedulerBackend$DriverEndpoint: Launching task 78 on executor id: 15 hostname: 10.1.2.163.
17/01/29 17:04:47,242 INFO CoarseGrainedSchedulerBackend$DriverEndpoint: Launching task 94 on executor id: 15 hostname: 10.1.2.163.
17/01/29 17:04:47,243 INFO CoarseGrainedSchedulerBackend$DriverEndpoint: Launching task 110 on executor id: 15 hostname: 10.1.2.163.
17/01/29 17:04:47,244 INFO CoarseGrainedSchedulerBackend$DriverEndpoint: Launching task 126 on executor id: 15 hostname: 10.1.2.163.
17/01/29 17:04:47,245 INFO CoarseGrainedSchedulerBackend$DriverEndpoint: Launching task 79 on executor id: 9 hostname: 10.1.2.135.
17/01/29 17:04:47,245 INFO CoarseGrainedSchedulerBackend$DriverEndpoint: Launching task 95 on executor id: 9 hostname: 10.1.2.135.
17/01/29 17:04:47,245 INFO CoarseGrainedSchedulerBackend$DriverEndpoint: Launching task 111 on executor id: 9 hostname: 10.1.2.135.
17/01/29 17:04:47,245 INFO CoarseGrainedSchedulerBackend$DriverEndpoint: Launching task 127 on executor id: 9 hostname: 10.1.2.135.
17/01/29 17:04:47,246 INFO CoarseGrainedSchedulerBackend$DriverEndpoint: Launching task 80 on executor id: 11 hostname: 10.1.2.64.
17/01/29 17:04:47,246 INFO CoarseGrainedSchedulerBackend$DriverEndpoint: Launching task 96 on executor id: 11 hostname: 10.1.2.64.
17/01/29 17:04:47,246 INFO CoarseGrainedSchedulerBackend$DriverEndpoint: Launching task 112 on executor id: 11 hostname: 10.1.2.64.
17/01/29 17:04:47,247 INFO CoarseGrainedSchedulerBackend$DriverEndpoint: Launching task 128 on executor id: 11 hostname: 10.1.2.64.
17/01/29 17:04:47,249 INFO BlockManagerInfo: Added broadcast_3_piece0 in memory on 10.1.2.47:43177 (size: 2.2 KB, free: 2031.7 MB)
17/01/29 17:04:47,254 INFO BlockManagerInfo: Added broadcast_3_piece0 in memory on 10.1.2.89:39575 (size: 2.2 KB, free: 2031.7 MB)
17/01/29 17:04:47,261 INFO BlockManagerInfo: Added broadcast_3_piece0 in memory on 10.1.2.162:45664 (size: 2.2 KB, free: 2031.6 MB)
17/01/29 17:04:47,264 INFO BlockManagerInfo: Added broadcast_3_piece0 in memory on 10.1.2.179:41020 (size: 2.2 KB, free: 2031.6 MB)
17/01/29 17:04:47,264 INFO BlockManagerInfo: Added broadcast_3_piece0 in memory on 10.1.2.113:35066 (size: 2.2 KB, free: 2031.7 MB)
17/01/29 17:04:47,265 INFO BlockManagerInfo: Added broadcast_3_piece0 in memory on 10.1.2.53:37053 (size: 2.2 KB, free: 2031.6 MB)
17/01/29 17:04:47,266 INFO BlockManagerInfo: Added broadcast_3_piece0 in memory on 10.1.2.195:41578 (size: 2.2 KB, free: 2031.6 MB)
17/01/29 17:04:47,270 INFO BlockManagerInfo: Added broadcast_3_piece0 in memory on 10.1.2.108:41185 (size: 2.2 KB, free: 2031.7 MB)
17/01/29 17:04:47,271 INFO BlockManagerInfo: Added broadcast_3_piece0 in memory on 10.1.2.222:36021 (size: 2.2 KB, free: 2031.6 MB)
17/01/29 17:04:47,274 INFO BlockManagerInfo: Added broadcast_3_piece0 in memory on 10.1.2.190:37862 (size: 2.2 KB, free: 2031.6 MB)
17/01/29 17:04:47,276 INFO BlockManagerInfo: Added broadcast_3_piece0 in memory on 10.1.2.114:44486 (size: 2.2 KB, free: 2031.7 MB)
17/01/29 17:04:47,287 INFO TaskSetManager: Finished task 37.0 in stage 2.0 (TID 102) in 99 ms on 10.1.2.47 (1/64)
17/01/29 17:04:47,289 INFO BlockManagerInfo: Added broadcast_3_piece0 in memory on 10.1.2.13:42861 (size: 2.2 KB, free: 2031.6 MB)
17/01/29 17:04:47,290 INFO TaskSetManager: Finished task 0.0 in stage 2.0 (TID 70) in 126 ms on 10.1.2.47 (2/64)
17/01/29 17:04:47,292 INFO TaskSetManager: Finished task 15.0 in stage 2.0 (TID 86) in 117 ms on 10.1.2.47 (3/64)
17/01/29 17:04:47,293 INFO TaskSetManager: Finished task 56.0 in stage 2.0 (TID 118) in 91 ms on 10.1.2.47 (4/64)
17/01/29 17:04:47,295 INFO TaskSetManager: Finished task 8.0 in stage 2.0 (TID 67) in 133 ms on 10.1.2.89 (5/64)
17/01/29 17:04:47,305 INFO TaskSetManager: Finished task 41.0 in stage 2.0 (TID 121) in 101 ms on 10.1.2.222 (6/64)
17/01/29 17:04:47,305 INFO TaskSetManager: Finished task 30.0 in stage 2.0 (TID 99) in 121 ms on 10.1.2.89 (7/64)
17/01/29 17:04:47,311 INFO TaskSetManager: Finished task 51.0 in stage 2.0 (TID 115) in 111 ms on 10.1.2.89 (8/64)
17/01/29 17:04:47,317 INFO TaskSetManager: Finished task 47.0 in stage 2.0 (TID 101) in 131 ms on 10.1.2.162 (9/64)
17/01/29 17:04:47,318 INFO TaskSetManager: Finished task 55.0 in stage 2.0 (TID 114) in 118 ms on 10.1.2.53 (10/64)
17/01/29 17:04:47,318 INFO TaskSetManager: Finished task 42.0 in stage 2.0 (TID 98) in 135 ms on 10.1.2.53 (11/64)
17/01/29 17:04:47,319 INFO TaskSetManager: Finished task 14.0 in stage 2.0 (TID 93) in 139 ms on 10.1.2.114 (12/64)
17/01/29 17:04:47,322 INFO TaskSetManager: Finished task 1.0 in stage 2.0 (TID 74) in 156 ms on 10.1.2.190 (13/64)
17/01/29 17:04:47,323 INFO TaskSetManager: Finished task 4.0 in stage 2.0 (TID 69) in 159 ms on 10.1.2.162 (14/64)
17/01/29 17:04:47,323 INFO TaskSetManager: Finished task 23.0 in stage 2.0 (TID 90) in 146 ms on 10.1.2.190 (15/64)
17/01/29 17:04:47,324 INFO TaskSetManager: Finished task 45.0 in stage 2.0 (TID 122) in 119 ms on 10.1.2.190 (16/64)
17/01/29 17:04:47,327 INFO BlockManagerInfo: Added broadcast_3_piece0 in memory on 10.1.2.163:38469 (size: 2.2 KB, free: 2031.6 MB)
17/01/29 17:04:47,329 INFO TaskSetManager: Finished task 19.0 in stage 2.0 (TID 82) in 157 ms on 10.1.2.53 (17/64)
17/01/29 17:04:47,329 INFO TaskSetManager: Finished task 36.0 in stage 2.0 (TID 109) in 135 ms on 10.1.2.114 (18/64)
17/01/29 17:04:47,330 INFO TaskSetManager: Finished task 44.0 in stage 2.0 (TID 104) in 140 ms on 10.1.2.179 (19/64)
17/01/29 17:04:47,331 INFO BlockManagerInfo: Added broadcast_3_piece0 in memory on 10.1.2.146:37857 (size: 2.2 KB, free: 2031.7 MB)
17/01/29 17:04:47,331 INFO TaskSetManager: Finished task 10.0 in stage 2.0 (TID 77) in 163 ms on 10.1.2.114 (20/64)
17/01/29 17:04:47,331 INFO TaskSetManager: Finished task 61.0 in stage 2.0 (TID 120) in 128 ms on 10.1.2.179 (21/64)
17/01/29 17:04:47,332 INFO TaskSetManager: Finished task 17.0 in stage 2.0 (TID 66) in 171 ms on 10.1.2.53 (22/64)
17/01/29 17:04:47,333 INFO TaskSetManager: Finished task 63.0 in stage 2.0 (TID 117) in 132 ms on 10.1.2.162 (23/64)
17/01/29 17:04:47,334 INFO TaskSetManager: Finished task 6.0 in stage 2.0 (TID 71) in 168 ms on 10.1.2.108 (24/64)
17/01/29 17:04:47,334 INFO TaskSetManager: Finished task 22.0 in stage 2.0 (TID 72) in 169 ms on 10.1.2.179 (25/64)
17/01/29 17:04:47,335 INFO TaskSetManager: Finished task 39.0 in stage 2.0 (TID 100) in 151 ms on 10.1.2.113 (26/64)
17/01/29 17:04:47,335 INFO TaskSetManager: Finished task 7.0 in stage 2.0 (TID 87) in 160 ms on 10.1.2.108 (27/64)
17/01/29 17:04:47,336 INFO TaskSetManager: Finished task 57.0 in stage 2.0 (TID 116) in 136 ms on 10.1.2.113 (28/64)
17/01/29 17:04:47,337 INFO TaskSetManager: Finished task 31.0 in stage 2.0 (TID 88) in 161 ms on 10.1.2.179 (29/64)
17/01/29 17:04:47,337 INFO TaskSetManager: Finished task 12.0 in stage 2.0 (TID 73) in 171 ms on 10.1.2.222 (30/64)
17/01/29 17:04:47,338 INFO TaskSetManager: Finished task 29.0 in stage 2.0 (TID 103) in 149 ms on 10.1.2.108 (31/64)
17/01/29 17:04:47,338 INFO TaskSetManager: Finished task 26.0 in stage 2.0 (TID 85) in 164 ms on 10.1.2.162 (32/64)
17/01/29 17:04:47,339 INFO BlockManagerInfo: Added broadcast_3_piece0 in memory on 10.1.2.64:37605 (size: 2.2 KB, free: 2031.7 MB)
17/01/29 17:04:47,340 INFO TaskSetManager: Finished task 24.0 in stage 2.0 (TID 106) in 148 ms on 10.1.2.190 (33/64)
17/01/29 17:04:47,341 INFO TaskSetManager: Finished task 48.0 in stage 2.0 (TID 125) in 133 ms on 10.1.2.114 (34/64)
17/01/29 17:04:47,342 INFO TaskSetManager: Finished task 53.0 in stage 2.0 (TID 123) in 136 ms on 10.1.2.13 (35/64)
17/01/29 17:04:47,344 INFO TaskSetManager: Finished task 9.0 in stage 2.0 (TID 75) in 176 ms on 10.1.2.13 (36/64)
17/01/29 17:04:47,344 INFO TaskSetManager: Finished task 20.0 in stage 2.0 (TID 84) in 171 ms on 10.1.2.113 (37/64)
17/01/29 17:04:47,344 INFO TaskSetManager: Finished task 32.0 in stage 2.0 (TID 107) in 151 ms on 10.1.2.13 (38/64)
17/01/29 17:04:47,346 INFO TaskSetManager: Finished task 13.0 in stage 2.0 (TID 91) in 168 ms on 10.1.2.13 (39/64)
17/01/29 17:04:47,347 INFO TaskSetManager: Finished task 27.0 in stage 2.0 (TID 83) in 175 ms on 10.1.2.89 (40/64)
17/01/29 17:04:47,348 INFO TaskSetManager: Finished task 34.0 in stage 2.0 (TID 97) in 166 ms on 10.1.2.195 (41/64)
17/01/29 17:04:47,354 INFO TaskSetManager: Finished task 33.0 in stage 2.0 (TID 81) in 182 ms on 10.1.2.195 (42/64)
17/01/29 17:04:47,361 INFO TaskSetManager: Finished task 16.0 in stage 2.0 (TID 68) in 198 ms on 10.1.2.113 (43/64)
17/01/29 17:04:47,366 INFO BlockManagerInfo: Added broadcast_3_piece0 in memory on 10.1.2.135:37284 (size: 2.2 KB, free: 2031.6 MB)
17/01/29 17:04:47,368 INFO TaskSetManager: Finished task 50.0 in stage 2.0 (TID 119) in 165 ms on 10.1.2.108 (44/64)
17/01/29 17:04:47,370 INFO TaskSetManager: Finished task 5.0 in stage 2.0 (TID 94) in 190 ms on 10.1.2.163 (45/64)
17/01/29 17:04:47,373 INFO TaskSetManager: Finished task 3.0 in stage 2.0 (TID 78) in 204 ms on 10.1.2.163 (46/64)
17/01/29 17:04:47,374 INFO TaskSetManager: Finished task 49.0 in stage 2.0 (TID 126) in 165 ms on 10.1.2.163 (47/64)
17/01/29 17:04:47,378 INFO TaskSetManager: Finished task 28.0 in stage 2.0 (TID 110) in 182 ms on 10.1.2.163 (48/64)
17/01/29 17:04:47,388 INFO TaskSetManager: Finished task 2.0 in stage 2.0 (TID 76) in 220 ms on 10.1.2.146 (49/64)
17/01/29 17:04:47,389 INFO TaskSetManager: Finished task 52.0 in stage 2.0 (TID 112) in 192 ms on 10.1.2.64 (50/64)
17/01/29 17:04:47,390 INFO TaskSetManager: Finished task 21.0 in stage 2.0 (TID 80) in 219 ms on 10.1.2.64 (51/64)
17/01/29 17:04:47,391 INFO TaskSetManager: Finished task 60.0 in stage 2.0 (TID 128) in 181 ms on 10.1.2.64 (52/64)
17/01/29 17:04:47,391 INFO TaskSetManager: Finished task 43.0 in stage 2.0 (TID 96) in 209 ms on 10.1.2.64 (53/64)
17/01/29 17:04:47,392 INFO TaskSetManager: Finished task 38.0 in stage 2.0 (TID 105) in 201 ms on 10.1.2.222 (54/64)
17/01/29 17:04:47,393 INFO TaskSetManager: Finished task 62.0 in stage 2.0 (TID 124) in 186 ms on 10.1.2.146 (55/64)
17/01/29 17:04:47,403 INFO TaskSetManager: Finished task 11.0 in stage 2.0 (TID 65) in 243 ms on 10.1.2.195 (56/64)
17/01/29 17:04:47,409 INFO TaskSetManager: Finished task 35.0 in stage 2.0 (TID 89) in 233 ms on 10.1.2.222 (57/64)
17/01/29 17:04:47,420 INFO TaskSetManager: Finished task 54.0 in stage 2.0 (TID 113) in 222 ms on 10.1.2.195 (58/64)
17/01/29 17:04:47,425 INFO TaskSetManager: Finished task 58.0 in stage 2.0 (TID 111) in 229 ms on 10.1.2.135 (59/64)
17/01/29 17:04:47,430 INFO TaskSetManager: Finished task 18.0 in stage 2.0 (TID 79) in 259 ms on 10.1.2.135 (60/64)
17/01/29 17:04:47,430 INFO TaskSetManager: Finished task 40.0 in stage 2.0 (TID 95) in 249 ms on 10.1.2.135 (61/64)
17/01/29 17:04:47,433 INFO TaskSetManager: Finished task 59.0 in stage 2.0 (TID 127) in 223 ms on 10.1.2.135 (62/64)
17/01/29 17:04:47,446 INFO TaskSetManager: Finished task 46.0 in stage 2.0 (TID 108) in 252 ms on 10.1.2.146 (63/64)
17/01/29 17:04:47,469 INFO TaskSetManager: Finished task 25.0 in stage 2.0 (TID 92) in 290 ms on 10.1.2.146 (64/64)
17/01/29 17:04:47,469 INFO TaskSchedulerImpl: Removed TaskSet 2.0, whose tasks have all completed, from pool 
17/01/29 17:04:47,470 INFO DAGScheduler: ResultStage 2 (count at GradientDescent.scala:209) finished in 0.311 s
17/01/29 17:04:47,470 INFO DAGScheduler: Job 2 finished: count at GradientDescent.scala:209, took 0.327940 s
17/01/29 17:04:47,703 WARN BLAS: Failed to load implementation from: com.github.fommil.netlib.NativeSystemBLAS
17/01/29 17:04:47,703 WARN BLAS: Failed to load implementation from: com.github.fommil.netlib.NativeRefBLAS
17/01/29 17:04:47,726 INFO MemoryStore: Block broadcast_4 stored as values in memory (estimated size 200.0 B, free 2.1 GB)
17/01/29 17:04:47,729 INFO MemoryStore: Block broadcast_4_piece0 stored as bytes in memory (estimated size 153.0 B, free 2.1 GB)
17/01/29 17:04:47,730 INFO BlockManagerInfo: Added broadcast_4_piece0 in memory on 10.1.2.115:42089 (size: 153.0 B, free: 2.1 GB)
17/01/29 17:04:47,731 INFO SparkContext: Created broadcast 4 from broadcast at GradientDescent.scala:235
17/01/29 17:04:47,784 INFO SparkContext: Starting job: treeAggregate at GradientDescent.scala:239
17/01/29 17:04:47,789 INFO DAGScheduler: Registering RDD 11 (treeAggregate at GradientDescent.scala:239)
17/01/29 17:04:47,790 INFO DAGScheduler: Got job 3 (treeAggregate at GradientDescent.scala:239) with 8 output partitions
17/01/29 17:04:47,790 INFO DAGScheduler: Final stage: ResultStage 4 (treeAggregate at GradientDescent.scala:239)
17/01/29 17:04:47,791 INFO DAGScheduler: Parents of final stage: List(ShuffleMapStage 3)
17/01/29 17:04:47,791 INFO DAGScheduler: Missing parents: List(ShuffleMapStage 3)
17/01/29 17:04:47,794 INFO DAGScheduler: Submitting ShuffleMapStage 3 (MapPartitionsRDD[11] at treeAggregate at GradientDescent.scala:239), which has no missing parents
17/01/29 17:04:47,811 INFO MemoryStore: Block broadcast_5 stored as values in memory (estimated size 7.1 KB, free 2.1 GB)
17/01/29 17:04:47,813 INFO MemoryStore: Block broadcast_5_piece0 stored as bytes in memory (estimated size 3.7 KB, free 2.1 GB)
17/01/29 17:04:47,814 INFO BlockManagerInfo: Added broadcast_5_piece0 in memory on 10.1.2.115:42089 (size: 3.7 KB, free: 2.1 GB)
17/01/29 17:04:47,814 INFO SparkContext: Created broadcast 5 from broadcast at DAGScheduler.scala:1012
17/01/29 17:04:47,817 INFO DAGScheduler: Submitting 64 missing tasks from ShuffleMapStage 3 (MapPartitionsRDD[11] at treeAggregate at GradientDescent.scala:239)
17/01/29 17:04:47,817 INFO TaskSchedulerImpl: Adding task set 3.0 with 64 tasks
17/01/29 17:04:47,821 INFO TaskSetManager: Starting task 11.0 in stage 3.0 (TID 129, 10.1.2.195, partition 11, PROCESS_LOCAL, 5562 bytes)
17/01/29 17:04:47,822 INFO TaskSetManager: Starting task 12.0 in stage 3.0 (TID 130, 10.1.2.222, partition 12, PROCESS_LOCAL, 5562 bytes)
17/01/29 17:04:47,832 INFO TaskSetManager: Starting task 22.0 in stage 3.0 (TID 131, 10.1.2.179, partition 22, PROCESS_LOCAL, 5562 bytes)
17/01/29 17:04:47,833 INFO TaskSetManager: Starting task 8.0 in stage 3.0 (TID 132, 10.1.2.89, partition 8, PROCESS_LOCAL, 5562 bytes)
17/01/29 17:04:47,833 INFO TaskSetManager: Starting task 16.0 in stage 3.0 (TID 133, 10.1.2.113, partition 16, PROCESS_LOCAL, 5562 bytes)
17/01/29 17:04:47,834 INFO TaskSetManager: Starting task 2.0 in stage 3.0 (TID 134, 10.1.2.146, partition 2, PROCESS_LOCAL, 5562 bytes)
17/01/29 17:04:47,835 INFO TaskSetManager: Starting task 3.0 in stage 3.0 (TID 135, 10.1.2.163, partition 3, PROCESS_LOCAL, 5562 bytes)
17/01/29 17:04:47,835 INFO TaskSetManager: Starting task 6.0 in stage 3.0 (TID 136, 10.1.2.108, partition 6, PROCESS_LOCAL, 5562 bytes)
17/01/29 17:04:47,836 INFO TaskSetManager: Starting task 10.0 in stage 3.0 (TID 137, 10.1.2.114, partition 10, PROCESS_LOCAL, 5562 bytes)
17/01/29 17:04:47,837 INFO TaskSetManager: Starting task 21.0 in stage 3.0 (TID 138, 10.1.2.64, partition 21, PROCESS_LOCAL, 5562 bytes)
17/01/29 17:04:47,838 INFO TaskSetManager: Starting task 17.0 in stage 3.0 (TID 139, 10.1.2.53, partition 17, PROCESS_LOCAL, 5562 bytes)
17/01/29 17:04:47,838 INFO TaskSetManager: Starting task 4.0 in stage 3.0 (TID 140, 10.1.2.162, partition 4, PROCESS_LOCAL, 5562 bytes)
17/01/29 17:04:47,839 INFO TaskSetManager: Starting task 1.0 in stage 3.0 (TID 141, 10.1.2.190, partition 1, PROCESS_LOCAL, 5562 bytes)
17/01/29 17:04:47,840 INFO TaskSetManager: Starting task 18.0 in stage 3.0 (TID 142, 10.1.2.135, partition 18, PROCESS_LOCAL, 5562 bytes)
17/01/29 17:04:47,841 INFO TaskSetManager: Starting task 9.0 in stage 3.0 (TID 143, 10.1.2.13, partition 9, PROCESS_LOCAL, 5562 bytes)
17/01/29 17:04:47,841 INFO TaskSetManager: Starting task 0.0 in stage 3.0 (TID 144, 10.1.2.47, partition 0, PROCESS_LOCAL, 5562 bytes)
17/01/29 17:04:47,842 INFO TaskSetManager: Starting task 33.0 in stage 3.0 (TID 145, 10.1.2.195, partition 33, PROCESS_LOCAL, 5562 bytes)
17/01/29 17:04:47,843 INFO TaskSetManager: Starting task 35.0 in stage 3.0 (TID 146, 10.1.2.222, partition 35, PROCESS_LOCAL, 5562 bytes)
17/01/29 17:04:47,845 INFO TaskSetManager: Starting task 31.0 in stage 3.0 (TID 147, 10.1.2.179, partition 31, PROCESS_LOCAL, 5562 bytes)
17/01/29 17:04:47,846 INFO TaskSetManager: Starting task 27.0 in stage 3.0 (TID 148, 10.1.2.89, partition 27, PROCESS_LOCAL, 5562 bytes)
17/01/29 17:04:47,846 INFO TaskSetManager: Starting task 20.0 in stage 3.0 (TID 149, 10.1.2.113, partition 20, PROCESS_LOCAL, 5562 bytes)
17/01/29 17:04:47,847 INFO TaskSetManager: Starting task 25.0 in stage 3.0 (TID 150, 10.1.2.146, partition 25, PROCESS_LOCAL, 5562 bytes)
17/01/29 17:04:47,848 INFO TaskSetManager: Starting task 5.0 in stage 3.0 (TID 151, 10.1.2.163, partition 5, PROCESS_LOCAL, 5562 bytes)
17/01/29 17:04:47,849 INFO TaskSetManager: Starting task 7.0 in stage 3.0 (TID 152, 10.1.2.108, partition 7, PROCESS_LOCAL, 5562 bytes)
17/01/29 17:04:47,850 INFO TaskSetManager: Starting task 14.0 in stage 3.0 (TID 153, 10.1.2.114, partition 14, PROCESS_LOCAL, 5562 bytes)
17/01/29 17:04:47,851 INFO TaskSetManager: Starting task 43.0 in stage 3.0 (TID 154, 10.1.2.64, partition 43, PROCESS_LOCAL, 5562 bytes)
17/01/29 17:04:47,852 INFO TaskSetManager: Starting task 19.0 in stage 3.0 (TID 155, 10.1.2.53, partition 19, PROCESS_LOCAL, 5562 bytes)
17/01/29 17:04:47,853 INFO TaskSetManager: Starting task 26.0 in stage 3.0 (TID 156, 10.1.2.162, partition 26, PROCESS_LOCAL, 5562 bytes)
17/01/29 17:04:47,854 INFO TaskSetManager: Starting task 23.0 in stage 3.0 (TID 157, 10.1.2.190, partition 23, PROCESS_LOCAL, 5562 bytes)
17/01/29 17:04:47,855 INFO TaskSetManager: Starting task 40.0 in stage 3.0 (TID 158, 10.1.2.135, partition 40, PROCESS_LOCAL, 5562 bytes)
17/01/29 17:04:47,856 INFO TaskSetManager: Starting task 13.0 in stage 3.0 (TID 159, 10.1.2.13, partition 13, PROCESS_LOCAL, 5562 bytes)
17/01/29 17:04:47,857 INFO TaskSetManager: Starting task 15.0 in stage 3.0 (TID 160, 10.1.2.47, partition 15, PROCESS_LOCAL, 5562 bytes)
17/01/29 17:04:47,858 INFO TaskSetManager: Starting task 34.0 in stage 3.0 (TID 161, 10.1.2.195, partition 34, PROCESS_LOCAL, 5562 bytes)
17/01/29 17:04:47,859 INFO TaskSetManager: Starting task 38.0 in stage 3.0 (TID 162, 10.1.2.222, partition 38, PROCESS_LOCAL, 5562 bytes)
17/01/29 17:04:47,859 INFO TaskSetManager: Starting task 44.0 in stage 3.0 (TID 163, 10.1.2.179, partition 44, PROCESS_LOCAL, 5562 bytes)
17/01/29 17:04:47,860 INFO TaskSetManager: Starting task 30.0 in stage 3.0 (TID 164, 10.1.2.89, partition 30, PROCESS_LOCAL, 5562 bytes)
17/01/29 17:04:47,861 INFO TaskSetManager: Starting task 39.0 in stage 3.0 (TID 165, 10.1.2.113, partition 39, PROCESS_LOCAL, 5562 bytes)
17/01/29 17:04:47,862 INFO TaskSetManager: Starting task 46.0 in stage 3.0 (TID 166, 10.1.2.146, partition 46, PROCESS_LOCAL, 5562 bytes)
17/01/29 17:04:47,863 INFO TaskSetManager: Starting task 28.0 in stage 3.0 (TID 167, 10.1.2.163, partition 28, PROCESS_LOCAL, 5562 bytes)
17/01/29 17:04:47,864 INFO TaskSetManager: Starting task 29.0 in stage 3.0 (TID 168, 10.1.2.108, partition 29, PROCESS_LOCAL, 5562 bytes)
17/01/29 17:04:47,865 INFO TaskSetManager: Starting task 36.0 in stage 3.0 (TID 169, 10.1.2.114, partition 36, PROCESS_LOCAL, 5562 bytes)
17/01/29 17:04:47,866 INFO TaskSetManager: Starting task 52.0 in stage 3.0 (TID 170, 10.1.2.64, partition 52, PROCESS_LOCAL, 5562 bytes)
17/01/29 17:04:47,866 INFO TaskSetManager: Starting task 42.0 in stage 3.0 (TID 171, 10.1.2.53, partition 42, PROCESS_LOCAL, 5562 bytes)
17/01/29 17:04:47,867 INFO TaskSetManager: Starting task 47.0 in stage 3.0 (TID 172, 10.1.2.162, partition 47, PROCESS_LOCAL, 5562 bytes)
17/01/29 17:04:47,868 INFO TaskSetManager: Starting task 24.0 in stage 3.0 (TID 173, 10.1.2.190, partition 24, PROCESS_LOCAL, 5562 bytes)
17/01/29 17:04:47,869 INFO TaskSetManager: Starting task 58.0 in stage 3.0 (TID 174, 10.1.2.135, partition 58, PROCESS_LOCAL, 5562 bytes)
17/01/29 17:04:47,869 INFO TaskSetManager: Starting task 32.0 in stage 3.0 (TID 175, 10.1.2.13, partition 32, PROCESS_LOCAL, 5562 bytes)
17/01/29 17:04:47,870 INFO TaskSetManager: Starting task 37.0 in stage 3.0 (TID 176, 10.1.2.47, partition 37, PROCESS_LOCAL, 5562 bytes)
17/01/29 17:04:47,871 INFO TaskSetManager: Starting task 54.0 in stage 3.0 (TID 177, 10.1.2.195, partition 54, PROCESS_LOCAL, 5562 bytes)
17/01/29 17:04:47,872 INFO TaskSetManager: Starting task 41.0 in stage 3.0 (TID 178, 10.1.2.222, partition 41, PROCESS_LOCAL, 5562 bytes)
17/01/29 17:04:47,873 INFO TaskSetManager: Starting task 61.0 in stage 3.0 (TID 179, 10.1.2.179, partition 61, PROCESS_LOCAL, 5562 bytes)
17/01/29 17:04:47,873 INFO TaskSetManager: Starting task 51.0 in stage 3.0 (TID 180, 10.1.2.89, partition 51, PROCESS_LOCAL, 5562 bytes)
17/01/29 17:04:47,874 INFO TaskSetManager: Starting task 57.0 in stage 3.0 (TID 181, 10.1.2.113, partition 57, PROCESS_LOCAL, 5562 bytes)
17/01/29 17:04:47,875 INFO TaskSetManager: Starting task 62.0 in stage 3.0 (TID 182, 10.1.2.146, partition 62, PROCESS_LOCAL, 5562 bytes)
17/01/29 17:04:47,875 INFO TaskSetManager: Starting task 49.0 in stage 3.0 (TID 183, 10.1.2.163, partition 49, PROCESS_LOCAL, 5562 bytes)
17/01/29 17:04:47,876 INFO TaskSetManager: Starting task 50.0 in stage 3.0 (TID 184, 10.1.2.108, partition 50, PROCESS_LOCAL, 5562 bytes)
17/01/29 17:04:47,877 INFO TaskSetManager: Starting task 48.0 in stage 3.0 (TID 185, 10.1.2.114, partition 48, PROCESS_LOCAL, 5562 bytes)
17/01/29 17:04:47,878 INFO TaskSetManager: Starting task 60.0 in stage 3.0 (TID 186, 10.1.2.64, partition 60, PROCESS_LOCAL, 5562 bytes)
17/01/29 17:04:47,879 INFO TaskSetManager: Starting task 55.0 in stage 3.0 (TID 187, 10.1.2.53, partition 55, PROCESS_LOCAL, 5562 bytes)
17/01/29 17:04:47,879 INFO TaskSetManager: Starting task 63.0 in stage 3.0 (TID 188, 10.1.2.162, partition 63, PROCESS_LOCAL, 5562 bytes)
17/01/29 17:04:47,880 INFO TaskSetManager: Starting task 45.0 in stage 3.0 (TID 189, 10.1.2.190, partition 45, PROCESS_LOCAL, 5562 bytes)
17/01/29 17:04:47,881 INFO TaskSetManager: Starting task 59.0 in stage 3.0 (TID 190, 10.1.2.135, partition 59, PROCESS_LOCAL, 5562 bytes)
17/01/29 17:04:47,882 INFO TaskSetManager: Starting task 53.0 in stage 3.0 (TID 191, 10.1.2.13, partition 53, PROCESS_LOCAL, 5562 bytes)
17/01/29 17:04:47,882 INFO TaskSetManager: Starting task 56.0 in stage 3.0 (TID 192, 10.1.2.47, partition 56, PROCESS_LOCAL, 5562 bytes)
17/01/29 17:04:47,883 INFO CoarseGrainedSchedulerBackend$DriverEndpoint: Launching task 129 on executor id: 4 hostname: 10.1.2.195.
