Using properties file: /home/ubuntu/spark-2.0.0/conf/spark-defaults.conf
Adding default property: spark.driver.extraJavaOptions=-XX:+PrintGCDetails -XX:+PrintGCTimeStamps -Xms4000m -Dlog4j.configuration=file:///home/ubuntu/spark-2.0.0/conf/log4j.properties
Adding default property: spark.executor.extraJavaOptions=-XX:+PrintGCDetails -XX:+PrintGCTimeStamps -Xms4000m -Dlog4j.configuration=file:///home/ubuntu/spark-2.0.0/conf/log4j.properties
Parsed arguments:
  master                  spark://euca-10-1-2-253:7077
  deployMode              client
  executorMemory          4000m
  executorCores           null
  totalExecutorCores      null
  propertiesFile          /home/ubuntu/spark-2.0.0/conf/spark-defaults.conf
  driverMemory            4000m
  driverCores             null
  driverExtraClassPath    null
  driverExtraLibraryPath  null
  driverExtraJavaOptions  -XX:+PrintGCDetails -XX:+PrintGCTimeStamps -Xms4000m -Dlog4j.configuration=file:///home/ubuntu/spark-2.0.0/conf/log4j.properties
  supervise               false
  queue                   null
  numExecutors            16
  files                   null
  pyFiles                 null
  archives                null
  mainClass               LogRegExplicitParallelism
  primaryResource         file:///home/ubuntu/jars/log-reg-explicit-parallelism_2.11-1.0.jar
  name                    LogRegExplicitParallelism
  childArgs               [cluster 28 euca-10-1-2-253 9000 higgs_0_exp 5 64]
  jars                    null
  packages                null
  packagesExclusions      null
  repositories            null
  verbose                 true

Spark properties used, including those specified through
 --conf and those from the properties file /home/ubuntu/spark-2.0.0/conf/spark-defaults.conf:
  spark.default.parallelism -> 64
  spark.driver.memory -> 4000m
  spark.executor.extraJavaOptions -> -XX:+PrintGCDetails -XX:+PrintGCTimeStamps -Xms4000m -Dlog4j.configuration=file:///home/ubuntu/spark-2.0.0/conf/log4j.properties
  spark.driver.extraJavaOptions -> -XX:+PrintGCDetails -XX:+PrintGCTimeStamps -Xms4000m -Dlog4j.configuration=file:///home/ubuntu/spark-2.0.0/conf/log4j.properties
  spark.shuffle.spill -> false

    
Main class:
LogRegExplicitParallelism
Arguments:
cluster
28
euca-10-1-2-253
9000
higgs_0_exp
5
64
System properties:
spark.default.parallelism -> 64
spark.executor.memory -> 4000m
spark.driver.memory -> 4000m
SPARK_SUBMIT -> true
spark.executor.extraJavaOptions -> -XX:+PrintGCDetails -XX:+PrintGCTimeStamps -Xms4000m -Dlog4j.configuration=file:///home/ubuntu/spark-2.0.0/conf/log4j.properties
spark.app.name -> LogRegExplicitParallelism
spark.shuffle.spill -> false
spark.driver.extraJavaOptions -> -XX:+PrintGCDetails -XX:+PrintGCTimeStamps -Xms4000m -Dlog4j.configuration=file:///home/ubuntu/spark-2.0.0/conf/log4j.properties
spark.jars -> file:///home/ubuntu/jars/log-reg-explicit-parallelism_2.11-1.0.jar
spark.submit.deployMode -> client
spark.master -> spark://euca-10-1-2-253:7077
Classpath elements:
file:///home/ubuntu/jars/log-reg-explicit-parallelism_2.11-1.0.jar


17/01/29 10:33:24,815 INFO SparkContext: Running Spark version 2.0.0
17/01/29 10:33:25,142 WARN NativeCodeLoader: Unable to load native-hadoop library for your platform... using builtin-java classes where applicable
17/01/29 10:33:25,297 INFO SecurityManager: Changing view acls to: ubuntu
17/01/29 10:33:25,297 INFO SecurityManager: Changing modify acls to: ubuntu
17/01/29 10:33:25,298 INFO SecurityManager: Changing view acls groups to: 
17/01/29 10:33:25,298 INFO SecurityManager: Changing modify acls groups to: 
17/01/29 10:33:25,299 INFO SecurityManager: SecurityManager: authentication disabled; ui acls disabled; users  with view permissions: Set(ubuntu); groups with view permissions: Set(); users  with modify permissions: Set(ubuntu); groups with modify permissions: Set()
17/01/29 10:33:28,563 WARN ThreadLocalRandom: Failed to generate a seed from SecureRandom within 3 seconds. Not enough entrophy?
17/01/29 10:33:28,616 INFO Utils: Successfully started service 'sparkDriver' on port 38692.
17/01/29 10:33:28,633 INFO SparkEnv: Registering MapOutputTracker
17/01/29 10:33:28,639 WARN SortShuffleManager: spark.shuffle.spill was set to false, but this configuration is ignored as of Spark 1.6+. Shuffle will continue to spill to disk when necessary.
17/01/29 10:33:28,650 INFO SparkEnv: Registering BlockManagerMaster
17/01/29 10:33:28,662 INFO DiskBlockManager: Created local directory at /tmp/blockmgr-bd7c53ce-6b5f-4a1d-a738-468f59e9db3b
17/01/29 10:33:28,680 INFO MemoryStore: MemoryStore started with capacity 2.1 GB
17/01/29 10:33:28,732 INFO SparkEnv: Registering OutputCommitCoordinator
17/01/29 10:33:28,933 INFO Utils: Successfully started service 'SparkUI' on port 4040.
17/01/29 10:33:28,936 INFO SparkUI: Bound SparkUI to 10.1.2.253, and started at http://10.1.2.253:4040
17/01/29 10:33:28,970 INFO SparkContext: Added JAR file:///home/ubuntu/jars/log-reg-explicit-parallelism_2.11-1.0.jar at spark://10.1.2.253:38692/jars/log-reg-explicit-parallelism_2.11-1.0.jar with timestamp 1485686008970
17/01/29 10:33:29,045 INFO StandaloneAppClient$ClientEndpoint: Connecting to master spark://euca-10-1-2-253:7077...
17/01/29 10:33:29,094 INFO TransportClientFactory: Successfully created connection to euca-10-1-2-253/10.1.2.253:7077 after 24 ms (0 ms spent in bootstraps)
17/01/29 10:33:29,186 INFO StandaloneSchedulerBackend: Connected to Spark cluster with app ID app-20170129103329-0000
17/01/29 10:33:29,191 INFO Utils: Successfully started service 'org.apache.spark.network.netty.NettyBlockTransferService' on port 34451.
17/01/29 10:33:29,192 INFO NettyBlockTransferService: Server created on 10.1.2.253:34451
17/01/29 10:33:29,194 INFO BlockManagerMaster: Registering BlockManager BlockManagerId(driver, 10.1.2.253, 34451)
17/01/29 10:33:29,196 INFO BlockManagerMasterEndpoint: Registering block manager 10.1.2.253:34451 with 2.1 GB RAM, BlockManagerId(driver, 10.1.2.253, 34451)
17/01/29 10:33:29,199 INFO BlockManagerMaster: Registered BlockManager BlockManagerId(driver, 10.1.2.253, 34451)
17/01/29 10:33:29,210 INFO StandaloneAppClient$ClientEndpoint: Executor added: app-20170129103329-0000/0 on worker-20170129103245-10.1.2.31-43816 (10.1.2.31:43816) with 4 cores
17/01/29 10:33:29,212 INFO StandaloneSchedulerBackend: Granted executor ID app-20170129103329-0000/0 on hostPort 10.1.2.31:43816 with 4 cores, 3.9 GB RAM
17/01/29 10:33:29,214 INFO StandaloneAppClient$ClientEndpoint: Executor added: app-20170129103329-0000/1 on worker-20170129103245-10.1.2.243-37445 (10.1.2.243:37445) with 4 cores
17/01/29 10:33:29,214 INFO StandaloneSchedulerBackend: Granted executor ID app-20170129103329-0000/1 on hostPort 10.1.2.243:37445 with 4 cores, 3.9 GB RAM
17/01/29 10:33:29,217 INFO StandaloneAppClient$ClientEndpoint: Executor added: app-20170129103329-0000/2 on worker-20170129103245-10.1.2.247-33527 (10.1.2.247:33527) with 4 cores
17/01/29 10:33:29,218 INFO StandaloneSchedulerBackend: Granted executor ID app-20170129103329-0000/2 on hostPort 10.1.2.247:33527 with 4 cores, 3.9 GB RAM
17/01/29 10:33:29,220 INFO StandaloneAppClient$ClientEndpoint: Executor added: app-20170129103329-0000/3 on worker-20170129103245-10.1.2.168-34273 (10.1.2.168:34273) with 4 cores
17/01/29 10:33:29,220 INFO StandaloneSchedulerBackend: Granted executor ID app-20170129103329-0000/3 on hostPort 10.1.2.168:34273 with 4 cores, 3.9 GB RAM
17/01/29 10:33:29,222 INFO StandaloneAppClient$ClientEndpoint: Executor added: app-20170129103329-0000/4 on worker-20170129103245-10.1.2.214-38316 (10.1.2.214:38316) with 4 cores
17/01/29 10:33:29,222 INFO StandaloneSchedulerBackend: Granted executor ID app-20170129103329-0000/4 on hostPort 10.1.2.214:38316 with 4 cores, 3.9 GB RAM
17/01/29 10:33:29,225 INFO StandaloneAppClient$ClientEndpoint: Executor added: app-20170129103329-0000/5 on worker-20170129103245-10.1.2.193-45683 (10.1.2.193:45683) with 4 cores
17/01/29 10:33:29,226 INFO StandaloneSchedulerBackend: Granted executor ID app-20170129103329-0000/5 on hostPort 10.1.2.193:45683 with 4 cores, 3.9 GB RAM
17/01/29 10:33:29,228 INFO StandaloneAppClient$ClientEndpoint: Executor added: app-20170129103329-0000/6 on worker-20170129103245-10.1.2.191-35759 (10.1.2.191:35759) with 4 cores
17/01/29 10:33:29,229 INFO StandaloneSchedulerBackend: Granted executor ID app-20170129103329-0000/6 on hostPort 10.1.2.191:35759 with 4 cores, 3.9 GB RAM
17/01/29 10:33:29,231 INFO StandaloneAppClient$ClientEndpoint: Executor added: app-20170129103329-0000/7 on worker-20170129103245-10.1.2.32-41042 (10.1.2.32:41042) with 4 cores
17/01/29 10:33:29,231 INFO StandaloneSchedulerBackend: Granted executor ID app-20170129103329-0000/7 on hostPort 10.1.2.32:41042 with 4 cores, 3.9 GB RAM
17/01/29 10:33:29,233 INFO StandaloneAppClient$ClientEndpoint: Executor added: app-20170129103329-0000/8 on worker-20170129103242-10.1.2.112-35215 (10.1.2.112:35215) with 4 cores
17/01/29 10:33:29,234 INFO StandaloneSchedulerBackend: Granted executor ID app-20170129103329-0000/8 on hostPort 10.1.2.112:35215 with 4 cores, 3.9 GB RAM
17/01/29 10:33:29,236 INFO StandaloneAppClient$ClientEndpoint: Executor added: app-20170129103329-0000/9 on worker-20170129103245-10.1.2.159-38858 (10.1.2.159:38858) with 4 cores
17/01/29 10:33:29,237 INFO StandaloneSchedulerBackend: Granted executor ID app-20170129103329-0000/9 on hostPort 10.1.2.159:38858 with 4 cores, 3.9 GB RAM
17/01/29 10:33:29,239 INFO StandaloneAppClient$ClientEndpoint: Executor added: app-20170129103329-0000/10 on worker-20170129103242-10.1.2.233-46468 (10.1.2.233:46468) with 4 cores
17/01/29 10:33:29,240 INFO StandaloneSchedulerBackend: Granted executor ID app-20170129103329-0000/10 on hostPort 10.1.2.233:46468 with 4 cores, 3.9 GB RAM
17/01/29 10:33:29,241 INFO StandaloneAppClient$ClientEndpoint: Executor added: app-20170129103329-0000/11 on worker-20170129103245-10.1.2.201-42747 (10.1.2.201:42747) with 4 cores
17/01/29 10:33:29,242 INFO StandaloneSchedulerBackend: Granted executor ID app-20170129103329-0000/11 on hostPort 10.1.2.201:42747 with 4 cores, 3.9 GB RAM
17/01/29 10:33:29,243 INFO StandaloneAppClient$ClientEndpoint: Executor added: app-20170129103329-0000/12 on worker-20170129103245-10.1.2.101-38418 (10.1.2.101:38418) with 4 cores
17/01/29 10:33:29,244 INFO StandaloneSchedulerBackend: Granted executor ID app-20170129103329-0000/12 on hostPort 10.1.2.101:38418 with 4 cores, 3.9 GB RAM
17/01/29 10:33:29,247 INFO StandaloneAppClient$ClientEndpoint: Executor added: app-20170129103329-0000/13 on worker-20170129103242-10.1.2.88-38710 (10.1.2.88:38710) with 4 cores
17/01/29 10:33:29,247 INFO StandaloneSchedulerBackend: Granted executor ID app-20170129103329-0000/13 on hostPort 10.1.2.88:38710 with 4 cores, 3.9 GB RAM
17/01/29 10:33:29,249 INFO StandaloneAppClient$ClientEndpoint: Executor added: app-20170129103329-0000/14 on worker-20170129103245-10.1.2.138-41091 (10.1.2.138:41091) with 4 cores
17/01/29 10:33:29,249 INFO StandaloneSchedulerBackend: Granted executor ID app-20170129103329-0000/14 on hostPort 10.1.2.138:41091 with 4 cores, 3.9 GB RAM
17/01/29 10:33:29,250 INFO StandaloneAppClient$ClientEndpoint: Executor added: app-20170129103329-0000/15 on worker-20170129103245-10.1.2.188-44920 (10.1.2.188:44920) with 4 cores
17/01/29 10:33:29,251 INFO StandaloneSchedulerBackend: Granted executor ID app-20170129103329-0000/15 on hostPort 10.1.2.188:44920 with 4 cores, 3.9 GB RAM
17/01/29 10:33:29,308 INFO StandaloneAppClient$ClientEndpoint: Executor updated: app-20170129103329-0000/7 is now RUNNING
17/01/29 10:33:29,313 INFO StandaloneAppClient$ClientEndpoint: Executor updated: app-20170129103329-0000/2 is now RUNNING
17/01/29 10:33:29,316 INFO StandaloneAppClient$ClientEndpoint: Executor updated: app-20170129103329-0000/0 is now RUNNING
17/01/29 10:33:29,319 INFO StandaloneAppClient$ClientEndpoint: Executor updated: app-20170129103329-0000/3 is now RUNNING
17/01/29 10:33:29,321 INFO StandaloneAppClient$ClientEndpoint: Executor updated: app-20170129103329-0000/6 is now RUNNING
17/01/29 10:33:29,324 INFO StandaloneAppClient$ClientEndpoint: Executor updated: app-20170129103329-0000/4 is now RUNNING
17/01/29 10:33:29,327 INFO StandaloneAppClient$ClientEndpoint: Executor updated: app-20170129103329-0000/1 is now RUNNING
17/01/29 10:33:29,330 INFO StandaloneAppClient$ClientEndpoint: Executor updated: app-20170129103329-0000/13 is now RUNNING
17/01/29 10:33:29,333 INFO StandaloneAppClient$ClientEndpoint: Executor updated: app-20170129103329-0000/15 is now RUNNING
17/01/29 10:33:29,335 INFO StandaloneAppClient$ClientEndpoint: Executor updated: app-20170129103329-0000/10 is now RUNNING
17/01/29 10:33:29,338 INFO StandaloneAppClient$ClientEndpoint: Executor updated: app-20170129103329-0000/5 is now RUNNING
17/01/29 10:33:29,341 INFO StandaloneAppClient$ClientEndpoint: Executor updated: app-20170129103329-0000/9 is now RUNNING
17/01/29 10:33:29,343 INFO StandaloneAppClient$ClientEndpoint: Executor updated: app-20170129103329-0000/11 is now RUNNING
17/01/29 10:33:29,346 INFO StandaloneAppClient$ClientEndpoint: Executor updated: app-20170129103329-0000/12 is now RUNNING
17/01/29 10:33:29,349 INFO StandaloneAppClient$ClientEndpoint: Executor updated: app-20170129103329-0000/8 is now RUNNING
17/01/29 10:33:29,352 INFO StandaloneAppClient$ClientEndpoint: Executor updated: app-20170129103329-0000/14 is now RUNNING
17/01/29 10:33:29,449 INFO StandaloneSchedulerBackend: SchedulerBackend is ready for scheduling beginning after reached minRegisteredResourcesRatio: 0.0
17/01/29 10:33:29,883 INFO MemoryStore: Block broadcast_0 stored as values in memory (estimated size 130.8 KB, free 2.1 GB)
17/01/29 10:33:29,952 INFO MemoryStore: Block broadcast_0_piece0 stored as bytes in memory (estimated size 16.5 KB, free 2.1 GB)
17/01/29 10:33:29,955 INFO BlockManagerInfo: Added broadcast_0_piece0 in memory on 10.1.2.253:34451 (size: 16.5 KB, free: 2.1 GB)
17/01/29 10:33:29,963 INFO SparkContext: Created broadcast 0 from textFile at MLUtils.scala:99
17/01/29 10:33:30,694 INFO FileInputFormat: Total input paths to process : 1
17/01/29 10:33:30,755 INFO NetworkTopology: Adding a new node: /default-rack/10.1.2.112:50010
17/01/29 10:33:30,756 INFO NetworkTopology: Adding a new node: /default-rack/10.1.2.32:50010
17/01/29 10:33:30,756 INFO NetworkTopology: Adding a new node: /default-rack/10.1.2.243:50010
17/01/29 10:33:30,756 INFO NetworkTopology: Adding a new node: /default-rack/10.1.2.101:50010
17/01/29 10:33:30,756 INFO NetworkTopology: Adding a new node: /default-rack/10.1.2.247:50010
17/01/29 10:33:30,756 INFO NetworkTopology: Adding a new node: /default-rack/10.1.2.159:50010
17/01/29 10:33:30,758 INFO NetworkTopology: Adding a new node: /default-rack/10.1.2.188:50010
17/01/29 10:33:30,758 INFO NetworkTopology: Adding a new node: /default-rack/10.1.2.88:50010
17/01/29 10:33:30,758 INFO NetworkTopology: Adding a new node: /default-rack/10.1.2.168:50010
17/01/29 10:33:30,759 INFO NetworkTopology: Adding a new node: /default-rack/10.1.2.191:50010
17/01/29 10:33:30,759 INFO NetworkTopology: Adding a new node: /default-rack/10.1.2.138:50010
17/01/29 10:33:30,759 INFO NetworkTopology: Adding a new node: /default-rack/10.1.2.214:50010
17/01/29 10:33:30,760 INFO NetworkTopology: Adding a new node: /default-rack/10.1.2.233:50010
17/01/29 10:33:30,760 INFO NetworkTopology: Adding a new node: /default-rack/10.1.2.201:50010
17/01/29 10:33:30,761 INFO NetworkTopology: Adding a new node: /default-rack/10.1.2.31:50010
17/01/29 10:33:30,761 INFO NetworkTopology: Adding a new node: /default-rack/10.1.2.193:50010
17/01/29 10:33:30,819 INFO SparkContext: Starting job: first at GeneralizedLinearAlgorithm.scala:246
17/01/29 10:33:30,833 INFO DAGScheduler: Got job 0 (first at GeneralizedLinearAlgorithm.scala:246) with 1 output partitions
17/01/29 10:33:30,834 INFO DAGScheduler: Final stage: ResultStage 0 (first at GeneralizedLinearAlgorithm.scala:246)
17/01/29 10:33:30,834 INFO DAGScheduler: Parents of final stage: List()
17/01/29 10:33:30,840 INFO DAGScheduler: Missing parents: List()
17/01/29 10:33:30,854 INFO DAGScheduler: Submitting ResultStage 0 (MapPartitionsRDD[6] at map at GeneralizedLinearAlgorithm.scala:246), which has no missing parents
17/01/29 10:33:30,877 INFO MemoryStore: Block broadcast_1 stored as values in memory (estimated size 4.2 KB, free 2.1 GB)
17/01/29 10:33:30,880 INFO MemoryStore: Block broadcast_1_piece0 stored as bytes in memory (estimated size 2.4 KB, free 2.1 GB)
17/01/29 10:33:30,881 INFO BlockManagerInfo: Added broadcast_1_piece0 in memory on 10.1.2.253:34451 (size: 2.4 KB, free: 2.1 GB)
17/01/29 10:33:30,883 INFO SparkContext: Created broadcast 1 from broadcast at DAGScheduler.scala:1012
17/01/29 10:33:30,886 INFO DAGScheduler: Submitting 1 missing tasks from ResultStage 0 (MapPartitionsRDD[6] at map at GeneralizedLinearAlgorithm.scala:246)
17/01/29 10:33:30,887 INFO TaskSchedulerImpl: Adding task set 0.0 with 1 tasks
17/01/29 10:33:34,113 INFO CoarseGrainedSchedulerBackend$DriverEndpoint: Registered executor NettyRpcEndpointRef(null) (10.1.2.112:56248) with ID 8
17/01/29 10:33:34,147 INFO TaskSetManager: Starting task 0.0 in stage 0.0 (TID 0, 10.1.2.112, partition 0, ANY, 5456 bytes)
17/01/29 10:33:34,153 INFO CoarseGrainedSchedulerBackend$DriverEndpoint: Launching task 0 on executor id: 8 hostname: 10.1.2.112.
17/01/29 10:33:34,155 INFO CoarseGrainedSchedulerBackend$DriverEndpoint: Registered executor NettyRpcEndpointRef(null) (10.1.2.201:44634) with ID 11
17/01/29 10:33:34,177 INFO BlockManagerMasterEndpoint: Registering block manager 10.1.2.112:35569 with 2.1 GB RAM, BlockManagerId(8, 10.1.2.112, 35569)
17/01/29 10:33:34,213 INFO BlockManagerMasterEndpoint: Registering block manager 10.1.2.201:36512 with 2.1 GB RAM, BlockManagerId(11, 10.1.2.201, 36512)
17/01/29 10:33:34,272 INFO CoarseGrainedSchedulerBackend$DriverEndpoint: Registered executor NettyRpcEndpointRef(null) (10.1.2.32:44778) with ID 7
17/01/29 10:33:34,276 INFO CoarseGrainedSchedulerBackend$DriverEndpoint: Registered executor NettyRpcEndpointRef(null) (10.1.2.247:56192) with ID 2
17/01/29 10:33:34,284 INFO CoarseGrainedSchedulerBackend$DriverEndpoint: Registered executor NettyRpcEndpointRef(null) (10.1.2.191:34054) with ID 6
17/01/29 10:33:34,289 INFO CoarseGrainedSchedulerBackend$DriverEndpoint: Registered executor NettyRpcEndpointRef(null) (10.1.2.101:60258) with ID 12
17/01/29 10:33:34,291 INFO CoarseGrainedSchedulerBackend$DriverEndpoint: Registered executor NettyRpcEndpointRef(null) (10.1.2.159:37170) with ID 9
17/01/29 10:33:34,301 INFO CoarseGrainedSchedulerBackend$DriverEndpoint: Registered executor NettyRpcEndpointRef(null) (10.1.2.168:42316) with ID 3
17/01/29 10:33:34,310 INFO CoarseGrainedSchedulerBackend$DriverEndpoint: Registered executor NettyRpcEndpointRef(null) (10.1.2.188:58538) with ID 15
17/01/29 10:33:34,319 INFO CoarseGrainedSchedulerBackend$DriverEndpoint: Registered executor NettyRpcEndpointRef(null) (10.1.2.193:38572) with ID 5
17/01/29 10:33:34,330 INFO BlockManagerMasterEndpoint: Registering block manager 10.1.2.32:37531 with 2.1 GB RAM, BlockManagerId(7, 10.1.2.32, 37531)
17/01/29 10:33:34,333 INFO BlockManagerMasterEndpoint: Registering block manager 10.1.2.247:46539 with 2.1 GB RAM, BlockManagerId(2, 10.1.2.247, 46539)
17/01/29 10:33:34,337 INFO CoarseGrainedSchedulerBackend$DriverEndpoint: Registered executor NettyRpcEndpointRef(null) (10.1.2.214:49708) with ID 4
17/01/29 10:33:34,340 INFO BlockManagerMasterEndpoint: Registering block manager 10.1.2.191:39424 with 2.1 GB RAM, BlockManagerId(6, 10.1.2.191, 39424)
17/01/29 10:33:34,342 INFO BlockManagerMasterEndpoint: Registering block manager 10.1.2.101:43794 with 2.1 GB RAM, BlockManagerId(12, 10.1.2.101, 43794)
17/01/29 10:33:34,343 INFO BlockManagerMasterEndpoint: Registering block manager 10.1.2.159:36325 with 2.1 GB RAM, BlockManagerId(9, 10.1.2.159, 36325)
17/01/29 10:33:34,345 INFO CoarseGrainedSchedulerBackend$DriverEndpoint: Registered executor NettyRpcEndpointRef(null) (10.1.2.88:36506) with ID 13
17/01/29 10:33:34,360 INFO BlockManagerMasterEndpoint: Registering block manager 10.1.2.188:35389 with 2.1 GB RAM, BlockManagerId(15, 10.1.2.188, 35389)
17/01/29 10:33:34,365 INFO BlockManagerMasterEndpoint: Registering block manager 10.1.2.168:45304 with 2.1 GB RAM, BlockManagerId(3, 10.1.2.168, 45304)
17/01/29 10:33:34,378 INFO BlockManagerMasterEndpoint: Registering block manager 10.1.2.193:34183 with 2.1 GB RAM, BlockManagerId(5, 10.1.2.193, 34183)
17/01/29 10:33:34,391 INFO BlockManagerMasterEndpoint: Registering block manager 10.1.2.214:40179 with 2.1 GB RAM, BlockManagerId(4, 10.1.2.214, 40179)
17/01/29 10:33:34,401 INFO CoarseGrainedSchedulerBackend$DriverEndpoint: Registered executor NettyRpcEndpointRef(null) (10.1.2.31:46138) with ID 0
17/01/29 10:33:34,415 INFO BlockManagerMasterEndpoint: Registering block manager 10.1.2.88:34574 with 2.1 GB RAM, BlockManagerId(13, 10.1.2.88, 34574)
17/01/29 10:33:34,417 INFO CoarseGrainedSchedulerBackend$DriverEndpoint: Registered executor NettyRpcEndpointRef(null) (10.1.2.138:56378) with ID 14
17/01/29 10:33:34,423 INFO CoarseGrainedSchedulerBackend$DriverEndpoint: Registered executor NettyRpcEndpointRef(null) (10.1.2.243:57002) with ID 1
17/01/29 10:33:34,461 INFO BlockManagerMasterEndpoint: Registering block manager 10.1.2.31:46549 with 2.1 GB RAM, BlockManagerId(0, 10.1.2.31, 46549)
17/01/29 10:33:34,468 INFO CoarseGrainedSchedulerBackend$DriverEndpoint: Registered executor NettyRpcEndpointRef(null) (10.1.2.233:46612) with ID 10
17/01/29 10:33:34,472 INFO BlockManagerInfo: Added broadcast_1_piece0 in memory on 10.1.2.112:35569 (size: 2.4 KB, free: 2.1 GB)
17/01/29 10:33:34,478 INFO BlockManagerMasterEndpoint: Registering block manager 10.1.2.138:39427 with 2.1 GB RAM, BlockManagerId(14, 10.1.2.138, 39427)
17/01/29 10:33:34,487 INFO BlockManagerMasterEndpoint: Registering block manager 10.1.2.243:44321 with 2.1 GB RAM, BlockManagerId(1, 10.1.2.243, 44321)
17/01/29 10:33:34,518 INFO BlockManagerMasterEndpoint: Registering block manager 10.1.2.233:43780 with 2.1 GB RAM, BlockManagerId(10, 10.1.2.233, 43780)
17/01/29 10:33:34,615 INFO BlockManagerInfo: Added broadcast_0_piece0 in memory on 10.1.2.112:35569 (size: 16.5 KB, free: 2.1 GB)
17/01/29 10:33:41,392 INFO BlockManagerInfo: Added rdd_5_0 in memory on 10.1.2.112:35569 (size: 64.6 MB, free: 2.0 GB)
17/01/29 10:33:41,445 INFO DAGScheduler: ResultStage 0 (first at GeneralizedLinearAlgorithm.scala:246) finished in 10.546 s
17/01/29 10:33:41,443 INFO TaskSetManager: Finished task 0.0 in stage 0.0 (TID 0) in 7318 ms on 10.1.2.112 (1/1)
17/01/29 10:33:41,449 INFO TaskSchedulerImpl: Removed TaskSet 0.0, whose tasks have all completed, from pool 
17/01/29 10:33:41,451 INFO DAGScheduler: Job 0 finished: first at GeneralizedLinearAlgorithm.scala:246, took 10.631545 s
17/01/29 10:33:41,462 INFO SparkContext: Starting job: count at DataValidators.scala:40
17/01/29 10:33:41,464 INFO DAGScheduler: Got job 1 (count at DataValidators.scala:40) with 64 output partitions
17/01/29 10:33:41,464 INFO DAGScheduler: Final stage: ResultStage 1 (count at DataValidators.scala:40)
17/01/29 10:33:41,464 INFO DAGScheduler: Parents of final stage: List()
17/01/29 10:33:41,468 INFO DAGScheduler: Missing parents: List()
17/01/29 10:33:41,468 INFO DAGScheduler: Submitting ResultStage 1 (MapPartitionsRDD[7] at filter at DataValidators.scala:40), which has no missing parents
17/01/29 10:33:41,492 INFO MemoryStore: Block broadcast_2 stored as values in memory (estimated size 3.9 KB, free 2.1 GB)
17/01/29 10:33:41,496 INFO MemoryStore: Block broadcast_2_piece0 stored as bytes in memory (estimated size 2.2 KB, free 2.1 GB)
17/01/29 10:33:41,497 INFO BlockManagerInfo: Added broadcast_2_piece0 in memory on 10.1.2.253:34451 (size: 2.2 KB, free: 2.1 GB)
17/01/29 10:33:41,498 INFO SparkContext: Created broadcast 2 from broadcast at DAGScheduler.scala:1012
17/01/29 10:33:41,500 INFO DAGScheduler: Submitting 64 missing tasks from ResultStage 1 (MapPartitionsRDD[7] at filter at DataValidators.scala:40)
17/01/29 10:33:41,500 INFO TaskSchedulerImpl: Adding task set 1.0 with 64 tasks
17/01/29 10:33:41,508 INFO TaskSetManager: Starting task 0.0 in stage 1.0 (TID 1, 10.1.2.112, partition 0, PROCESS_LOCAL, 5374 bytes)
17/01/29 10:33:41,511 INFO TaskSetManager: Starting task 8.0 in stage 1.0 (TID 2, 10.1.2.214, partition 8, NODE_LOCAL, 5374 bytes)
17/01/29 10:33:41,513 INFO TaskSetManager: Starting task 7.0 in stage 1.0 (TID 3, 10.1.2.138, partition 7, NODE_LOCAL, 5374 bytes)
17/01/29 10:33:41,515 INFO TaskSetManager: Starting task 13.0 in stage 1.0 (TID 4, 10.1.2.243, partition 13, NODE_LOCAL, 5374 bytes)
17/01/29 10:33:41,517 INFO TaskSetManager: Starting task 1.0 in stage 1.0 (TID 5, 10.1.2.247, partition 1, NODE_LOCAL, 5374 bytes)
17/01/29 10:33:41,519 INFO TaskSetManager: Starting task 14.0 in stage 1.0 (TID 6, 10.1.2.31, partition 14, NODE_LOCAL, 5374 bytes)
17/01/29 10:33:41,521 INFO TaskSetManager: Starting task 3.0 in stage 1.0 (TID 7, 10.1.2.88, partition 3, NODE_LOCAL, 5374 bytes)
17/01/29 10:33:41,523 INFO TaskSetManager: Starting task 2.0 in stage 1.0 (TID 8, 10.1.2.101, partition 2, NODE_LOCAL, 5374 bytes)
17/01/29 10:33:41,525 INFO TaskSetManager: Starting task 20.0 in stage 1.0 (TID 9, 10.1.2.32, partition 20, NODE_LOCAL, 5374 bytes)
17/01/29 10:33:41,527 INFO TaskSetManager: Starting task 10.0 in stage 1.0 (TID 10, 10.1.2.201, partition 10, NODE_LOCAL, 5374 bytes)
17/01/29 10:33:41,529 INFO TaskSetManager: Starting task 9.0 in stage 1.0 (TID 11, 10.1.2.233, partition 9, NODE_LOCAL, 5374 bytes)
17/01/29 10:33:41,531 INFO TaskSetManager: Starting task 5.0 in stage 1.0 (TID 12, 10.1.2.188, partition 5, NODE_LOCAL, 5374 bytes)
17/01/29 10:33:41,534 INFO TaskSetManager: Starting task 17.0 in stage 1.0 (TID 13, 10.1.2.159, partition 17, NODE_LOCAL, 5374 bytes)
17/01/29 10:33:41,536 INFO TaskSetManager: Starting task 6.0 in stage 1.0 (TID 14, 10.1.2.112, partition 6, NODE_LOCAL, 5374 bytes)
17/01/29 10:33:41,538 INFO TaskSetManager: Starting task 16.0 in stage 1.0 (TID 15, 10.1.2.191, partition 16, NODE_LOCAL, 5374 bytes)
17/01/29 10:33:41,540 INFO TaskSetManager: Starting task 18.0 in stage 1.0 (TID 16, 10.1.2.168, partition 18, NODE_LOCAL, 5374 bytes)
17/01/29 10:33:41,542 INFO TaskSetManager: Starting task 15.0 in stage 1.0 (TID 17, 10.1.2.193, partition 15, NODE_LOCAL, 5374 bytes)
17/01/29 10:33:41,544 INFO TaskSetManager: Starting task 21.0 in stage 1.0 (TID 18, 10.1.2.214, partition 21, NODE_LOCAL, 5374 bytes)
17/01/29 10:33:41,546 INFO TaskSetManager: Starting task 19.0 in stage 1.0 (TID 19, 10.1.2.138, partition 19, NODE_LOCAL, 5374 bytes)
17/01/29 10:33:41,548 INFO TaskSetManager: Starting task 27.0 in stage 1.0 (TID 20, 10.1.2.243, partition 27, NODE_LOCAL, 5374 bytes)
17/01/29 10:33:41,549 INFO TaskSetManager: Starting task 4.0 in stage 1.0 (TID 21, 10.1.2.247, partition 4, NODE_LOCAL, 5374 bytes)
17/01/29 10:33:41,551 INFO TaskSetManager: Starting task 24.0 in stage 1.0 (TID 22, 10.1.2.31, partition 24, NODE_LOCAL, 5374 bytes)
17/01/29 10:33:41,553 INFO TaskSetManager: Starting task 29.0 in stage 1.0 (TID 23, 10.1.2.88, partition 29, NODE_LOCAL, 5374 bytes)
17/01/29 10:33:41,554 INFO TaskSetManager: Starting task 39.0 in stage 1.0 (TID 24, 10.1.2.101, partition 39, NODE_LOCAL, 5374 bytes)
17/01/29 10:33:41,556 INFO TaskSetManager: Starting task 23.0 in stage 1.0 (TID 25, 10.1.2.32, partition 23, NODE_LOCAL, 5374 bytes)
17/01/29 10:33:41,558 INFO TaskSetManager: Starting task 11.0 in stage 1.0 (TID 26, 10.1.2.201, partition 11, NODE_LOCAL, 5374 bytes)
17/01/29 10:33:41,559 INFO TaskSetManager: Starting task 26.0 in stage 1.0 (TID 27, 10.1.2.233, partition 26, NODE_LOCAL, 5374 bytes)
17/01/29 10:33:41,561 INFO TaskSetManager: Starting task 28.0 in stage 1.0 (TID 28, 10.1.2.188, partition 28, NODE_LOCAL, 5374 bytes)
17/01/29 10:33:41,563 INFO TaskSetManager: Starting task 22.0 in stage 1.0 (TID 29, 10.1.2.159, partition 22, NODE_LOCAL, 5374 bytes)
17/01/29 10:33:41,565 INFO TaskSetManager: Starting task 43.0 in stage 1.0 (TID 30, 10.1.2.112, partition 43, NODE_LOCAL, 5374 bytes)
17/01/29 10:33:41,566 INFO TaskSetManager: Starting task 37.0 in stage 1.0 (TID 31, 10.1.2.191, partition 37, NODE_LOCAL, 5374 bytes)
17/01/29 10:33:41,568 INFO TaskSetManager: Starting task 47.0 in stage 1.0 (TID 32, 10.1.2.168, partition 47, NODE_LOCAL, 5374 bytes)
17/01/29 10:33:41,569 INFO TaskSetManager: Starting task 33.0 in stage 1.0 (TID 33, 10.1.2.193, partition 33, NODE_LOCAL, 5374 bytes)
17/01/29 10:33:41,571 INFO TaskSetManager: Starting task 36.0 in stage 1.0 (TID 34, 10.1.2.214, partition 36, NODE_LOCAL, 5374 bytes)
17/01/29 10:33:41,573 INFO TaskSetManager: Starting task 41.0 in stage 1.0 (TID 35, 10.1.2.138, partition 41, NODE_LOCAL, 5374 bytes)
17/01/29 10:33:41,575 INFO TaskSetManager: Starting task 48.0 in stage 1.0 (TID 36, 10.1.2.243, partition 48, NODE_LOCAL, 5374 bytes)
17/01/29 10:33:41,577 INFO TaskSetManager: Starting task 34.0 in stage 1.0 (TID 37, 10.1.2.247, partition 34, NODE_LOCAL, 5374 bytes)
17/01/29 10:33:41,579 INFO TaskSetManager: Starting task 31.0 in stage 1.0 (TID 38, 10.1.2.31, partition 31, NODE_LOCAL, 5374 bytes)
17/01/29 10:33:41,581 INFO TaskSetManager: Starting task 32.0 in stage 1.0 (TID 39, 10.1.2.88, partition 32, NODE_LOCAL, 5374 bytes)
17/01/29 10:33:41,583 INFO TaskSetManager: Starting task 52.0 in stage 1.0 (TID 40, 10.1.2.101, partition 52, NODE_LOCAL, 5374 bytes)
17/01/29 10:33:41,585 INFO TaskSetManager: Starting task 30.0 in stage 1.0 (TID 41, 10.1.2.32, partition 30, NODE_LOCAL, 5374 bytes)
17/01/29 10:33:41,587 INFO TaskSetManager: Starting task 35.0 in stage 1.0 (TID 42, 10.1.2.201, partition 35, NODE_LOCAL, 5374 bytes)
17/01/29 10:33:41,589 INFO TaskSetManager: Starting task 54.0 in stage 1.0 (TID 43, 10.1.2.233, partition 54, NODE_LOCAL, 5374 bytes)
17/01/29 10:33:41,590 INFO TaskSetManager: Starting task 50.0 in stage 1.0 (TID 44, 10.1.2.188, partition 50, NODE_LOCAL, 5374 bytes)
17/01/29 10:33:41,592 INFO TaskSetManager: Starting task 55.0 in stage 1.0 (TID 45, 10.1.2.159, partition 55, NODE_LOCAL, 5374 bytes)
17/01/29 10:33:41,594 INFO TaskSetManager: Starting task 59.0 in stage 1.0 (TID 46, 10.1.2.112, partition 59, NODE_LOCAL, 5374 bytes)
17/01/29 10:33:41,595 INFO TaskSetManager: Starting task 40.0 in stage 1.0 (TID 47, 10.1.2.191, partition 40, NODE_LOCAL, 5374 bytes)
17/01/29 10:33:41,597 INFO TaskSetManager: Starting task 60.0 in stage 1.0 (TID 48, 10.1.2.168, partition 60, NODE_LOCAL, 5374 bytes)
17/01/29 10:33:41,598 INFO TaskSetManager: Starting task 44.0 in stage 1.0 (TID 49, 10.1.2.193, partition 44, NODE_LOCAL, 5374 bytes)
17/01/29 10:33:41,600 INFO TaskSetManager: Starting task 45.0 in stage 1.0 (TID 50, 10.1.2.214, partition 45, NODE_LOCAL, 5374 bytes)
17/01/29 10:33:41,601 INFO TaskSetManager: Starting task 42.0 in stage 1.0 (TID 51, 10.1.2.138, partition 42, NODE_LOCAL, 5374 bytes)
17/01/29 10:33:41,602 INFO TaskSetManager: Starting task 53.0 in stage 1.0 (TID 52, 10.1.2.243, partition 53, NODE_LOCAL, 5374 bytes)
17/01/29 10:33:41,604 INFO TaskSetManager: Starting task 49.0 in stage 1.0 (TID 53, 10.1.2.247, partition 49, NODE_LOCAL, 5374 bytes)
17/01/29 10:33:41,605 INFO TaskSetManager: Starting task 46.0 in stage 1.0 (TID 54, 10.1.2.88, partition 46, NODE_LOCAL, 5374 bytes)
17/01/29 10:33:41,607 INFO TaskSetManager: Starting task 56.0 in stage 1.0 (TID 55, 10.1.2.101, partition 56, NODE_LOCAL, 5374 bytes)
17/01/29 10:33:41,609 INFO TaskSetManager: Starting task 57.0 in stage 1.0 (TID 56, 10.1.2.32, partition 57, NODE_LOCAL, 5374 bytes)
17/01/29 10:33:41,610 INFO TaskSetManager: Starting task 61.0 in stage 1.0 (TID 57, 10.1.2.201, partition 61, NODE_LOCAL, 5374 bytes)
17/01/29 10:33:41,612 INFO TaskSetManager: Starting task 63.0 in stage 1.0 (TID 58, 10.1.2.233, partition 63, NODE_LOCAL, 5374 bytes)
17/01/29 10:33:41,613 INFO TaskSetManager: Starting task 62.0 in stage 1.0 (TID 59, 10.1.2.159, partition 62, NODE_LOCAL, 5374 bytes)
17/01/29 10:33:41,615 INFO TaskSetManager: Starting task 58.0 in stage 1.0 (TID 60, 10.1.2.193, partition 58, NODE_LOCAL, 5374 bytes)
17/01/29 10:33:41,616 INFO CoarseGrainedSchedulerBackend$DriverEndpoint: Launching task 2 on executor id: 4 hostname: 10.1.2.214.
17/01/29 10:33:41,617 INFO CoarseGrainedSchedulerBackend$DriverEndpoint: Launching task 18 on executor id: 4 hostname: 10.1.2.214.
17/01/29 10:33:41,618 INFO CoarseGrainedSchedulerBackend$DriverEndpoint: Launching task 34 on executor id: 4 hostname: 10.1.2.214.
17/01/29 10:33:41,619 INFO CoarseGrainedSchedulerBackend$DriverEndpoint: Launching task 50 on executor id: 4 hostname: 10.1.2.214.
17/01/29 10:33:41,619 INFO CoarseGrainedSchedulerBackend$DriverEndpoint: Launching task 3 on executor id: 14 hostname: 10.1.2.138.
17/01/29 10:33:41,620 INFO CoarseGrainedSchedulerBackend$DriverEndpoint: Launching task 19 on executor id: 14 hostname: 10.1.2.138.
17/01/29 10:33:41,621 INFO CoarseGrainedSchedulerBackend$DriverEndpoint: Launching task 35 on executor id: 14 hostname: 10.1.2.138.
17/01/29 10:33:41,621 INFO CoarseGrainedSchedulerBackend$DriverEndpoint: Launching task 51 on executor id: 14 hostname: 10.1.2.138.
17/01/29 10:33:41,622 INFO CoarseGrainedSchedulerBackend$DriverEndpoint: Launching task 4 on executor id: 1 hostname: 10.1.2.243.
17/01/29 10:33:41,623 INFO CoarseGrainedSchedulerBackend$DriverEndpoint: Launching task 20 on executor id: 1 hostname: 10.1.2.243.
17/01/29 10:33:41,623 INFO CoarseGrainedSchedulerBackend$DriverEndpoint: Launching task 36 on executor id: 1 hostname: 10.1.2.243.
17/01/29 10:33:41,623 INFO CoarseGrainedSchedulerBackend$DriverEndpoint: Launching task 52 on executor id: 1 hostname: 10.1.2.243.
17/01/29 10:33:41,624 INFO CoarseGrainedSchedulerBackend$DriverEndpoint: Launching task 5 on executor id: 2 hostname: 10.1.2.247.
17/01/29 10:33:41,624 INFO CoarseGrainedSchedulerBackend$DriverEndpoint: Launching task 21 on executor id: 2 hostname: 10.1.2.247.
17/01/29 10:33:41,625 INFO CoarseGrainedSchedulerBackend$DriverEndpoint: Launching task 37 on executor id: 2 hostname: 10.1.2.247.
17/01/29 10:33:41,625 INFO CoarseGrainedSchedulerBackend$DriverEndpoint: Launching task 53 on executor id: 2 hostname: 10.1.2.247.
17/01/29 10:33:41,626 INFO CoarseGrainedSchedulerBackend$DriverEndpoint: Launching task 6 on executor id: 0 hostname: 10.1.2.31.
17/01/29 10:33:41,626 INFO CoarseGrainedSchedulerBackend$DriverEndpoint: Launching task 22 on executor id: 0 hostname: 10.1.2.31.
17/01/29 10:33:41,627 INFO CoarseGrainedSchedulerBackend$DriverEndpoint: Launching task 38 on executor id: 0 hostname: 10.1.2.31.
17/01/29 10:33:41,627 INFO CoarseGrainedSchedulerBackend$DriverEndpoint: Launching task 7 on executor id: 13 hostname: 10.1.2.88.
17/01/29 10:33:41,628 INFO CoarseGrainedSchedulerBackend$DriverEndpoint: Launching task 23 on executor id: 13 hostname: 10.1.2.88.
17/01/29 10:33:41,629 INFO CoarseGrainedSchedulerBackend$DriverEndpoint: Launching task 39 on executor id: 13 hostname: 10.1.2.88.
17/01/29 10:33:41,629 INFO CoarseGrainedSchedulerBackend$DriverEndpoint: Launching task 54 on executor id: 13 hostname: 10.1.2.88.
17/01/29 10:33:41,629 INFO CoarseGrainedSchedulerBackend$DriverEndpoint: Launching task 8 on executor id: 12 hostname: 10.1.2.101.
17/01/29 10:33:41,630 INFO CoarseGrainedSchedulerBackend$DriverEndpoint: Launching task 24 on executor id: 12 hostname: 10.1.2.101.
17/01/29 10:33:41,630 INFO CoarseGrainedSchedulerBackend$DriverEndpoint: Launching task 40 on executor id: 12 hostname: 10.1.2.101.
17/01/29 10:33:41,631 INFO CoarseGrainedSchedulerBackend$DriverEndpoint: Launching task 55 on executor id: 12 hostname: 10.1.2.101.
17/01/29 10:33:41,632 INFO CoarseGrainedSchedulerBackend$DriverEndpoint: Launching task 9 on executor id: 7 hostname: 10.1.2.32.
17/01/29 10:33:41,633 INFO CoarseGrainedSchedulerBackend$DriverEndpoint: Launching task 25 on executor id: 7 hostname: 10.1.2.32.
17/01/29 10:33:41,633 INFO CoarseGrainedSchedulerBackend$DriverEndpoint: Launching task 41 on executor id: 7 hostname: 10.1.2.32.
17/01/29 10:33:41,634 INFO CoarseGrainedSchedulerBackend$DriverEndpoint: Launching task 56 on executor id: 7 hostname: 10.1.2.32.
17/01/29 10:33:41,634 INFO CoarseGrainedSchedulerBackend$DriverEndpoint: Launching task 10 on executor id: 11 hostname: 10.1.2.201.
17/01/29 10:33:41,634 INFO CoarseGrainedSchedulerBackend$DriverEndpoint: Launching task 26 on executor id: 11 hostname: 10.1.2.201.
17/01/29 10:33:41,635 INFO CoarseGrainedSchedulerBackend$DriverEndpoint: Launching task 42 on executor id: 11 hostname: 10.1.2.201.
17/01/29 10:33:41,635 INFO CoarseGrainedSchedulerBackend$DriverEndpoint: Launching task 57 on executor id: 11 hostname: 10.1.2.201.
17/01/29 10:33:41,636 INFO CoarseGrainedSchedulerBackend$DriverEndpoint: Launching task 11 on executor id: 10 hostname: 10.1.2.233.
17/01/29 10:33:41,637 INFO CoarseGrainedSchedulerBackend$DriverEndpoint: Launching task 27 on executor id: 10 hostname: 10.1.2.233.
17/01/29 10:33:41,637 INFO CoarseGrainedSchedulerBackend$DriverEndpoint: Launching task 43 on executor id: 10 hostname: 10.1.2.233.
17/01/29 10:33:41,638 INFO CoarseGrainedSchedulerBackend$DriverEndpoint: Launching task 58 on executor id: 10 hostname: 10.1.2.233.
17/01/29 10:33:41,639 INFO CoarseGrainedSchedulerBackend$DriverEndpoint: Launching task 12 on executor id: 15 hostname: 10.1.2.188.
17/01/29 10:33:41,639 INFO CoarseGrainedSchedulerBackend$DriverEndpoint: Launching task 28 on executor id: 15 hostname: 10.1.2.188.
17/01/29 10:33:41,640 INFO CoarseGrainedSchedulerBackend$DriverEndpoint: Launching task 44 on executor id: 15 hostname: 10.1.2.188.
17/01/29 10:33:41,640 INFO CoarseGrainedSchedulerBackend$DriverEndpoint: Launching task 13 on executor id: 9 hostname: 10.1.2.159.
17/01/29 10:33:41,641 INFO CoarseGrainedSchedulerBackend$DriverEndpoint: Launching task 29 on executor id: 9 hostname: 10.1.2.159.
17/01/29 10:33:41,642 INFO CoarseGrainedSchedulerBackend$DriverEndpoint: Launching task 45 on executor id: 9 hostname: 10.1.2.159.
17/01/29 10:33:41,642 INFO CoarseGrainedSchedulerBackend$DriverEndpoint: Launching task 59 on executor id: 9 hostname: 10.1.2.159.
17/01/29 10:33:41,643 INFO CoarseGrainedSchedulerBackend$DriverEndpoint: Launching task 1 on executor id: 8 hostname: 10.1.2.112.
17/01/29 10:33:41,643 INFO CoarseGrainedSchedulerBackend$DriverEndpoint: Launching task 14 on executor id: 8 hostname: 10.1.2.112.
17/01/29 10:33:41,644 INFO CoarseGrainedSchedulerBackend$DriverEndpoint: Launching task 30 on executor id: 8 hostname: 10.1.2.112.
17/01/29 10:33:41,644 INFO CoarseGrainedSchedulerBackend$DriverEndpoint: Launching task 46 on executor id: 8 hostname: 10.1.2.112.
17/01/29 10:33:41,645 INFO CoarseGrainedSchedulerBackend$DriverEndpoint: Launching task 15 on executor id: 6 hostname: 10.1.2.191.
17/01/29 10:33:41,645 INFO CoarseGrainedSchedulerBackend$DriverEndpoint: Launching task 31 on executor id: 6 hostname: 10.1.2.191.
17/01/29 10:33:41,646 INFO CoarseGrainedSchedulerBackend$DriverEndpoint: Launching task 47 on executor id: 6 hostname: 10.1.2.191.
17/01/29 10:33:41,646 INFO CoarseGrainedSchedulerBackend$DriverEndpoint: Launching task 16 on executor id: 3 hostname: 10.1.2.168.
17/01/29 10:33:41,647 INFO CoarseGrainedSchedulerBackend$DriverEndpoint: Launching task 32 on executor id: 3 hostname: 10.1.2.168.
17/01/29 10:33:41,647 INFO CoarseGrainedSchedulerBackend$DriverEndpoint: Launching task 48 on executor id: 3 hostname: 10.1.2.168.
17/01/29 10:33:41,648 INFO CoarseGrainedSchedulerBackend$DriverEndpoint: Launching task 17 on executor id: 5 hostname: 10.1.2.193.
17/01/29 10:33:41,648 INFO CoarseGrainedSchedulerBackend$DriverEndpoint: Launching task 33 on executor id: 5 hostname: 10.1.2.193.
17/01/29 10:33:41,650 INFO CoarseGrainedSchedulerBackend$DriverEndpoint: Launching task 49 on executor id: 5 hostname: 10.1.2.193.
17/01/29 10:33:41,650 INFO CoarseGrainedSchedulerBackend$DriverEndpoint: Launching task 60 on executor id: 5 hostname: 10.1.2.193.
17/01/29 10:33:41,700 INFO BlockManagerInfo: Added broadcast_2_piece0 in memory on 10.1.2.112:35569 (size: 2.2 KB, free: 2.0 GB)
17.664: [GC [PSYoungGen: 1024512K->140523K(1195008K)] 1024512K->140595K(3926016K), 0.0866490 secs] [Times: user=0.11 sys=0.10, real=0.09 secs] 
17/01/29 10:33:41,929 INFO TaskSetManager: Finished task 0.0 in stage 1.0 (TID 1) in 424 ms on 10.1.2.112 (1/64)
17/01/29 10:33:42,030 INFO BlockManagerInfo: Added broadcast_2_piece0 in memory on 10.1.2.31:46549 (size: 2.2 KB, free: 2.1 GB)
17/01/29 10:33:42,032 INFO BlockManagerInfo: Removed broadcast_1_piece0 on 10.1.2.253:34451 in memory (size: 2.4 KB, free: 2.1 GB)
17/01/29 10:33:42,038 INFO BlockManagerInfo: Removed broadcast_1_piece0 on 10.1.2.112:35569 in memory (size: 2.4 KB, free: 2.0 GB)
17/01/29 10:33:42,042 INFO BlockManagerInfo: Added broadcast_2_piece0 in memory on 10.1.2.201:36512 (size: 2.2 KB, free: 2.1 GB)
17/01/29 10:33:42,046 INFO BlockManagerInfo: Added broadcast_2_piece0 in memory on 10.1.2.214:40179 (size: 2.2 KB, free: 2.1 GB)
17/01/29 10:33:42,048 INFO BlockManagerInfo: Added broadcast_2_piece0 in memory on 10.1.2.188:35389 (size: 2.2 KB, free: 2.1 GB)
17/01/29 10:33:42,052 INFO BlockManagerInfo: Added broadcast_2_piece0 in memory on 10.1.2.32:37531 (size: 2.2 KB, free: 2.1 GB)
17/01/29 10:33:42,052 INFO BlockManagerInfo: Added broadcast_2_piece0 in memory on 10.1.2.191:39424 (size: 2.2 KB, free: 2.1 GB)
17/01/29 10:33:42,054 INFO BlockManagerInfo: Added broadcast_2_piece0 in memory on 10.1.2.247:46539 (size: 2.2 KB, free: 2.1 GB)
17/01/29 10:33:42,054 INFO BlockManagerInfo: Added broadcast_2_piece0 in memory on 10.1.2.138:39427 (size: 2.2 KB, free: 2.1 GB)
17/01/29 10:33:42,056 INFO BlockManagerInfo: Added broadcast_2_piece0 in memory on 10.1.2.101:43794 (size: 2.2 KB, free: 2.1 GB)
17/01/29 10:33:42,058 INFO BlockManagerInfo: Added broadcast_2_piece0 in memory on 10.1.2.159:36325 (size: 2.2 KB, free: 2.1 GB)
17/01/29 10:33:42,061 INFO BlockManagerInfo: Added broadcast_2_piece0 in memory on 10.1.2.168:45304 (size: 2.2 KB, free: 2.1 GB)
17/01/29 10:33:42,063 INFO BlockManagerInfo: Added broadcast_2_piece0 in memory on 10.1.2.88:34574 (size: 2.2 KB, free: 2.1 GB)
17/01/29 10:33:42,065 INFO BlockManagerInfo: Added broadcast_2_piece0 in memory on 10.1.2.233:43780 (size: 2.2 KB, free: 2.1 GB)
17/01/29 10:33:42,069 INFO BlockManagerInfo: Added broadcast_2_piece0 in memory on 10.1.2.243:44321 (size: 2.2 KB, free: 2.1 GB)
17/01/29 10:33:42,085 INFO BlockManagerInfo: Added broadcast_2_piece0 in memory on 10.1.2.193:34183 (size: 2.2 KB, free: 2.1 GB)
17/01/29 10:33:42,220 INFO BlockManagerInfo: Added broadcast_0_piece0 in memory on 10.1.2.201:36512 (size: 16.5 KB, free: 2.1 GB)
17/01/29 10:33:42,237 INFO BlockManagerInfo: Added broadcast_0_piece0 in memory on 10.1.2.214:40179 (size: 16.5 KB, free: 2.1 GB)
17/01/29 10:33:42,241 INFO BlockManagerInfo: Added broadcast_0_piece0 in memory on 10.1.2.101:43794 (size: 16.5 KB, free: 2.1 GB)
17/01/29 10:33:42,245 INFO BlockManagerInfo: Added broadcast_0_piece0 in memory on 10.1.2.233:43780 (size: 16.5 KB, free: 2.1 GB)
17/01/29 10:33:42,253 INFO BlockManagerInfo: Added broadcast_0_piece0 in memory on 10.1.2.159:36325 (size: 16.5 KB, free: 2.1 GB)
17/01/29 10:33:42,253 INFO BlockManagerInfo: Added broadcast_0_piece0 in memory on 10.1.2.191:39424 (size: 16.5 KB, free: 2.1 GB)
17/01/29 10:33:42,261 INFO BlockManagerInfo: Added broadcast_0_piece0 in memory on 10.1.2.188:35389 (size: 16.5 KB, free: 2.1 GB)
17/01/29 10:33:42,263 INFO BlockManagerInfo: Added broadcast_0_piece0 in memory on 10.1.2.243:44321 (size: 16.5 KB, free: 2.1 GB)
17/01/29 10:33:42,265 INFO BlockManagerInfo: Added broadcast_0_piece0 in memory on 10.1.2.31:46549 (size: 16.5 KB, free: 2.1 GB)
17/01/29 10:33:42,272 INFO BlockManagerInfo: Added broadcast_0_piece0 in memory on 10.1.2.32:37531 (size: 16.5 KB, free: 2.1 GB)
17/01/29 10:33:42,273 INFO BlockManagerInfo: Added broadcast_0_piece0 in memory on 10.1.2.247:46539 (size: 16.5 KB, free: 2.1 GB)
17/01/29 10:33:42,274 INFO BlockManagerInfo: Added broadcast_0_piece0 in memory on 10.1.2.138:39427 (size: 16.5 KB, free: 2.1 GB)
17/01/29 10:33:42,300 INFO BlockManagerInfo: Added broadcast_0_piece0 in memory on 10.1.2.88:34574 (size: 16.5 KB, free: 2.1 GB)
17/01/29 10:33:42,300 INFO BlockManagerInfo: Added broadcast_0_piece0 in memory on 10.1.2.168:45304 (size: 16.5 KB, free: 2.1 GB)
17/01/29 10:33:42,311 INFO BlockManagerInfo: Added broadcast_0_piece0 in memory on 10.1.2.193:34183 (size: 16.5 KB, free: 2.1 GB)
17/01/29 10:33:45,037 INFO TaskSetManager: Starting task 12.0 in stage 1.0 (TID 61, 10.1.2.191, partition 12, ANY, 5374 bytes)
17/01/29 10:33:45,038 INFO TaskSetManager: Starting task 25.0 in stage 1.0 (TID 62, 10.1.2.188, partition 25, ANY, 5374 bytes)
17/01/29 10:33:45,040 INFO TaskSetManager: Starting task 38.0 in stage 1.0 (TID 63, 10.1.2.168, partition 38, ANY, 5374 bytes)
17/01/29 10:33:45,043 INFO TaskSetManager: Starting task 51.0 in stage 1.0 (TID 64, 10.1.2.112, partition 51, ANY, 5374 bytes)
17/01/29 10:33:45,044 INFO CoarseGrainedSchedulerBackend$DriverEndpoint: Launching task 61 on executor id: 6 hostname: 10.1.2.191.
17/01/29 10:33:45,044 INFO CoarseGrainedSchedulerBackend$DriverEndpoint: Launching task 62 on executor id: 15 hostname: 10.1.2.188.
17/01/29 10:33:45,045 INFO CoarseGrainedSchedulerBackend$DriverEndpoint: Launching task 63 on executor id: 3 hostname: 10.1.2.168.
17/01/29 10:33:45,045 INFO CoarseGrainedSchedulerBackend$DriverEndpoint: Launching task 64 on executor id: 8 hostname: 10.1.2.112.
17/01/29 10:33:56,230 INFO BlockManagerInfo: Added rdd_5_24 in memory on 10.1.2.31:46549 (size: 64.4 MB, free: 2.0 GB)
17/01/29 10:33:56,310 INFO TaskSetManager: Finished task 24.0 in stage 1.0 (TID 22) in 14761 ms on 10.1.2.31 (2/64)
17/01/29 10:33:56,311 INFO BlockManagerInfo: Added rdd_5_14 in memory on 10.1.2.31:46549 (size: 64.6 MB, free: 1991.4 MB)
17/01/29 10:33:56,343 INFO TaskSetManager: Finished task 14.0 in stage 1.0 (TID 6) in 14826 ms on 10.1.2.31 (3/64)
17/01/29 10:33:56,519 INFO BlockManagerInfo: Added rdd_5_31 in memory on 10.1.2.31:46549 (size: 64.6 MB, free: 1926.7 MB)
17/01/29 10:33:56,548 INFO TaskSetManager: Finished task 31.0 in stage 1.0 (TID 38) in 14970 ms on 10.1.2.31 (4/64)
17/01/29 10:33:59,143 INFO BlockManagerInfo: Added rdd_5_6 in memory on 10.1.2.112:35569 (size: 64.5 MB, free: 1991.3 MB)
17/01/29 10:33:59,177 INFO TaskSetManager: Finished task 6.0 in stage 1.0 (TID 14) in 17641 ms on 10.1.2.112 (5/64)
17/01/29 10:33:59,974 INFO BlockManagerInfo: Added rdd_5_9 in memory on 10.1.2.233:43780 (size: 64.5 MB, free: 2.0 GB)
17/01/29 10:34:00,034 INFO TaskSetManager: Finished task 9.0 in stage 1.0 (TID 11) in 18507 ms on 10.1.2.233 (6/64)
17/01/29 10:34:00,100 INFO BlockManagerInfo: Added rdd_5_43 in memory on 10.1.2.112:35569 (size: 64.6 MB, free: 1926.7 MB)
17/01/29 10:34:00,122 INFO TaskSetManager: Finished task 43.0 in stage 1.0 (TID 30) in 18559 ms on 10.1.2.112 (7/64)
17/01/29 10:34:00,195 INFO BlockManagerInfo: Added rdd_5_59 in memory on 10.1.2.112:35569 (size: 64.5 MB, free: 1862.2 MB)
17/01/29 10:34:00,216 INFO TaskSetManager: Finished task 59.0 in stage 1.0 (TID 46) in 18623 ms on 10.1.2.112 (8/64)
17/01/29 10:34:00,392 INFO BlockManagerInfo: Added rdd_5_10 in memory on 10.1.2.201:36512 (size: 64.5 MB, free: 2.0 GB)
17/01/29 10:34:00,458 INFO TaskSetManager: Finished task 10.0 in stage 1.0 (TID 10) in 18933 ms on 10.1.2.201 (9/64)
17/01/29 10:34:00,506 INFO BlockManagerInfo: Added rdd_5_61 in memory on 10.1.2.201:36512 (size: 64.6 MB, free: 1991.4 MB)
17/01/29 10:34:00,526 INFO TaskSetManager: Finished task 61.0 in stage 1.0 (TID 57) in 18917 ms on 10.1.2.201 (10/64)
17/01/29 10:34:00,528 INFO BlockManagerInfo: Added rdd_5_35 in memory on 10.1.2.201:36512 (size: 64.5 MB, free: 1926.9 MB)
17/01/29 10:34:00,559 INFO TaskSetManager: Finished task 35.0 in stage 1.0 (TID 42) in 18973 ms on 10.1.2.201 (11/64)
17/01/29 10:34:00,673 INFO BlockManagerInfo: Added rdd_5_11 in memory on 10.1.2.201:36512 (size: 64.6 MB, free: 1862.3 MB)
17/01/29 10:34:00,692 INFO TaskSetManager: Finished task 11.0 in stage 1.0 (TID 26) in 19136 ms on 10.1.2.201 (12/64)
17/01/29 10:34:00,973 INFO BlockManagerInfo: Added rdd_5_40 in memory on 10.1.2.191:39424 (size: 64.5 MB, free: 2.0 GB)
17/01/29 10:34:01,030 INFO BlockManagerInfo: Added rdd_5_47 in memory on 10.1.2.168:45304 (size: 64.5 MB, free: 2.0 GB)
17/01/29 10:34:01,051 INFO TaskSetManager: Finished task 40.0 in stage 1.0 (TID 47) in 19457 ms on 10.1.2.191 (13/64)
17/01/29 10:34:01,085 INFO BlockManagerInfo: Added rdd_5_30 in memory on 10.1.2.32:37531 (size: 64.5 MB, free: 2.0 GB)
17/01/29 10:34:01,090 INFO BlockManagerInfo: Added rdd_5_16 in memory on 10.1.2.191:39424 (size: 64.6 MB, free: 1991.2 MB)
17/01/29 10:34:01,108 INFO TaskSetManager: Finished task 47.0 in stage 1.0 (TID 32) in 19540 ms on 10.1.2.168 (14/64)
17/01/29 10:34:01,115 INFO TaskSetManager: Finished task 16.0 in stage 1.0 (TID 15) in 19576 ms on 10.1.2.191 (15/64)
17/01/29 10:34:01,174 INFO TaskSetManager: Finished task 30.0 in stage 1.0 (TID 41) in 19590 ms on 10.1.2.32 (16/64)
17/01/29 10:34:01,250 INFO BlockManagerInfo: Added rdd_5_22 in memory on 10.1.2.159:36325 (size: 64.5 MB, free: 2.0 GB)
17/01/29 10:34:01,265 INFO BlockManagerInfo: Added rdd_5_44 in memory on 10.1.2.193:34183 (size: 64.4 MB, free: 2.0 GB)
17/01/29 10:34:01,272 INFO BlockManagerInfo: Added rdd_5_37 in memory on 10.1.2.191:39424 (size: 64.5 MB, free: 1926.7 MB)
17/01/29 10:34:01,284 INFO BlockManagerInfo: Added rdd_5_54 in memory on 10.1.2.233:43780 (size: 64.5 MB, free: 1991.4 MB)
17/01/29 10:34:01,301 INFO TaskSetManager: Finished task 37.0 in stage 1.0 (TID 31) in 19736 ms on 10.1.2.191 (17/64)
17/01/29 10:34:01,304 INFO TaskSetManager: Finished task 54.0 in stage 1.0 (TID 43) in 19717 ms on 10.1.2.233 (18/64)
17/01/29 10:34:01,347 INFO TaskSetManager: Finished task 22.0 in stage 1.0 (TID 29) in 19786 ms on 10.1.2.159 (19/64)
17/01/29 10:34:01,382 INFO TaskSetManager: Finished task 44.0 in stage 1.0 (TID 49) in 19784 ms on 10.1.2.193 (20/64)
17/01/29 10:34:01,458 INFO BlockManagerInfo: Added rdd_5_51 in memory on 10.1.2.112:35569 (size: 64.6 MB, free: 1797.6 MB)
17/01/29 10:34:01,480 INFO TaskSetManager: Finished task 51.0 in stage 1.0 (TID 64) in 16440 ms on 10.1.2.112 (21/64)
17/01/29 10:34:01,487 INFO BlockManagerInfo: Added rdd_5_17 in memory on 10.1.2.159:36325 (size: 64.5 MB, free: 1991.4 MB)
17/01/29 10:34:01,510 INFO TaskSetManager: Finished task 17.0 in stage 1.0 (TID 13) in 19979 ms on 10.1.2.159 (22/64)
17/01/29 10:34:01,532 INFO BlockManagerInfo: Added rdd_5_21 in memory on 10.1.2.214:40179 (size: 64.5 MB, free: 2.0 GB)
17/01/29 10:34:01,549 INFO BlockManagerInfo: Added rdd_5_36 in memory on 10.1.2.214:40179 (size: 64.6 MB, free: 1991.2 MB)
17/01/29 10:34:01,622 INFO BlockManagerInfo: Added rdd_5_62 in memory on 10.1.2.159:36325 (size: 64.5 MB, free: 1926.9 MB)
17/01/29 10:34:01,626 INFO BlockManagerInfo: Added rdd_5_55 in memory on 10.1.2.159:36325 (size: 64.5 MB, free: 1862.5 MB)
17/01/29 10:34:01,632 INFO BlockManagerInfo: Added rdd_5_63 in memory on 10.1.2.233:43780 (size: 64.5 MB, free: 1926.9 MB)
17/01/29 10:34:01,647 INFO TaskSetManager: Finished task 63.0 in stage 1.0 (TID 58) in 20036 ms on 10.1.2.233 (23/64)
17/01/29 10:34:01,649 INFO BlockManagerInfo: Added rdd_5_48 in memory on 10.1.2.243:44321 (size: 64.5 MB, free: 2.0 GB)
17/01/29 10:34:01,657 INFO TaskSetManager: Finished task 55.0 in stage 1.0 (TID 45) in 20066 ms on 10.1.2.159 (24/64)
17/01/29 10:34:01,660 INFO TaskSetManager: Finished task 62.0 in stage 1.0 (TID 59) in 20047 ms on 10.1.2.159 (25/64)
17/01/29 10:34:01,673 INFO BlockManagerInfo: Added rdd_5_12 in memory on 10.1.2.191:39424 (size: 64.6 MB, free: 1862.1 MB)
17/01/29 10:34:01,679 INFO TaskSetManager: Finished task 21.0 in stage 1.0 (TID 18) in 20135 ms on 10.1.2.214 (26/64)
17/01/29 10:34:01,680 INFO BlockManagerInfo: Added rdd_5_45 in memory on 10.1.2.214:40179 (size: 64.4 MB, free: 1926.8 MB)
17/01/29 10:34:01,688 INFO TaskSetManager: Finished task 36.0 in stage 1.0 (TID 34) in 20118 ms on 10.1.2.214 (27/64)
17/01/29 10:34:01,690 INFO TaskSetManager: Finished task 12.0 in stage 1.0 (TID 61) in 16653 ms on 10.1.2.191 (28/64)
17/01/29 10:34:01,692 INFO BlockManagerInfo: Added rdd_5_32 in memory on 10.1.2.88:34574 (size: 64.6 MB, free: 2.0 GB)
17/01/29 10:34:01,706 INFO BlockManagerInfo: Added rdd_5_28 in memory on 10.1.2.188:35389 (size: 64.4 MB, free: 2.0 GB)
17/01/29 10:34:01,706 INFO TaskSetManager: Finished task 45.0 in stage 1.0 (TID 50) in 20107 ms on 10.1.2.214 (29/64)
17/01/29 10:34:01,716 INFO TaskSetManager: Finished task 48.0 in stage 1.0 (TID 36) in 20142 ms on 10.1.2.243 (30/64)
17/01/29 10:34:01,748 INFO BlockManagerInfo: Added rdd_5_26 in memory on 10.1.2.233:43780 (size: 64.4 MB, free: 1862.5 MB)
17/01/29 10:34:01,756 INFO BlockManagerInfo: Added rdd_5_33 in memory on 10.1.2.193:34183 (size: 64.4 MB, free: 1991.5 MB)
17/01/29 10:34:01,764 INFO TaskSetManager: Finished task 26.0 in stage 1.0 (TID 27) in 20206 ms on 10.1.2.233 (31/64)
17/01/29 10:34:01,775 INFO TaskSetManager: Finished task 32.0 in stage 1.0 (TID 39) in 20196 ms on 10.1.2.88 (32/64)
17/01/29 10:34:01,777 INFO TaskSetManager: Finished task 28.0 in stage 1.0 (TID 28) in 20217 ms on 10.1.2.188 (33/64)
17/01/29 10:34:01,784 INFO TaskSetManager: Finished task 33.0 in stage 1.0 (TID 33) in 20216 ms on 10.1.2.193 (34/64)
17/01/29 10:34:01,816 INFO BlockManagerInfo: Added rdd_5_15 in memory on 10.1.2.193:34183 (size: 64.5 MB, free: 1927.1 MB)
17/01/29 10:34:01,830 INFO BlockManagerInfo: Added rdd_5_20 in memory on 10.1.2.32:37531 (size: 64.5 MB, free: 1991.3 MB)
17/01/29 10:34:01,837 INFO BlockManagerInfo: Added rdd_5_23 in memory on 10.1.2.32:37531 (size: 64.5 MB, free: 1926.8 MB)
17/01/29 10:34:01,848 INFO TaskSetManager: Finished task 15.0 in stage 1.0 (TID 17) in 20306 ms on 10.1.2.193 (35/64)
17/01/29 10:34:01,850 INFO BlockManagerInfo: Added rdd_5_8 in memory on 10.1.2.214:40179 (size: 64.6 MB, free: 1862.3 MB)
17/01/29 10:34:01,853 INFO TaskSetManager: Finished task 20.0 in stage 1.0 (TID 9) in 20328 ms on 10.1.2.32 (36/64)
17/01/29 10:34:01,855 INFO TaskSetManager: Finished task 23.0 in stage 1.0 (TID 25) in 20300 ms on 10.1.2.32 (37/64)
17/01/29 10:34:01,864 INFO BlockManagerInfo: Added rdd_5_58 in memory on 10.1.2.193:34183 (size: 64.6 MB, free: 1862.5 MB)
17/01/29 10:34:01,869 INFO TaskSetManager: Finished task 8.0 in stage 1.0 (TID 2) in 20360 ms on 10.1.2.214 (38/64)
17/01/29 10:34:01,869 INFO BlockManagerInfo: Added rdd_5_13 in memory on 10.1.2.243:44321 (size: 64.6 MB, free: 1991.2 MB)
17/01/29 10:34:01,872 INFO BlockManagerInfo: Added rdd_5_57 in memory on 10.1.2.32:37531 (size: 64.6 MB, free: 1862.2 MB)
17/01/29 10:34:01,883 INFO TaskSetManager: Finished task 58.0 in stage 1.0 (TID 60) in 20269 ms on 10.1.2.193 (39/64)
17/01/29 10:34:01,888 INFO TaskSetManager: Finished task 13.0 in stage 1.0 (TID 4) in 20375 ms on 10.1.2.243 (40/64)
17/01/29 10:34:01,903 INFO TaskSetManager: Finished task 57.0 in stage 1.0 (TID 56) in 20295 ms on 10.1.2.32 (41/64)
17/01/29 10:34:01,904 INFO BlockManagerInfo: Added rdd_5_3 in memory on 10.1.2.88:34574 (size: 64.5 MB, free: 1991.3 MB)
17/01/29 10:34:01,919 INFO TaskSetManager: Finished task 3.0 in stage 1.0 (TID 7) in 20400 ms on 10.1.2.88 (42/64)
17/01/29 10:34:01,921 INFO BlockManagerInfo: Added rdd_5_46 in memory on 10.1.2.88:34574 (size: 64.5 MB, free: 1926.8 MB)
17/01/29 10:34:01,932 INFO BlockManagerInfo: Added rdd_5_60 in memory on 10.1.2.168:45304 (size: 64.5 MB, free: 1991.4 MB)
17/01/29 10:34:01,951 INFO BlockManagerInfo: Added rdd_5_53 in memory on 10.1.2.243:44321 (size: 64.6 MB, free: 1926.6 MB)
17/01/29 10:34:01,957 INFO TaskSetManager: Finished task 60.0 in stage 1.0 (TID 48) in 20362 ms on 10.1.2.168 (43/64)
17/01/29 10:34:01,965 INFO TaskSetManager: Finished task 46.0 in stage 1.0 (TID 54) in 20360 ms on 10.1.2.88 (44/64)
17/01/29 10:34:01,984 INFO TaskSetManager: Finished task 53.0 in stage 1.0 (TID 52) in 20383 ms on 10.1.2.243 (45/64)
17/01/29 10:34:02,035 INFO BlockManagerInfo: Added rdd_5_5 in memory on 10.1.2.188:35389 (size: 64.5 MB, free: 1991.5 MB)
17/01/29 10:34:02,074 INFO TaskSetManager: Finished task 5.0 in stage 1.0 (TID 12) in 20544 ms on 10.1.2.188 (46/64)
17/01/29 10:34:02,101 INFO BlockManagerInfo: Added rdd_5_27 in memory on 10.1.2.243:44321 (size: 64.5 MB, free: 1862.1 MB)
17/01/29 10:34:02,117 INFO TaskSetManager: Finished task 27.0 in stage 1.0 (TID 20) in 20571 ms on 10.1.2.243 (47/64)
17/01/29 10:34:02,120 INFO BlockManagerInfo: Added rdd_5_29 in memory on 10.1.2.88:34574 (size: 64.5 MB, free: 1862.3 MB)
17/01/29 10:34:02,139 INFO TaskSetManager: Finished task 29.0 in stage 1.0 (TID 23) in 20587 ms on 10.1.2.88 (48/64)
17/01/29 10:34:02,146 INFO BlockManagerInfo: Added rdd_5_1 in memory on 10.1.2.247:46539 (size: 64.5 MB, free: 2.0 GB)
17/01/29 10:34:02,178 INFO BlockManagerInfo: Added rdd_5_18 in memory on 10.1.2.168:45304 (size: 64.6 MB, free: 1926.8 MB)
17/01/29 10:34:02,206 INFO TaskSetManager: Finished task 18.0 in stage 1.0 (TID 16) in 20667 ms on 10.1.2.168 (49/64)
17/01/29 10:34:02,219 INFO BlockManagerInfo: Added rdd_5_49 in memory on 10.1.2.247:46539 (size: 64.5 MB, free: 1991.4 MB)
17/01/29 10:34:02,222 INFO TaskSetManager: Finished task 1.0 in stage 1.0 (TID 5) in 20707 ms on 10.1.2.247 (50/64)
17/01/29 10:34:02,235 INFO TaskSetManager: Finished task 49.0 in stage 1.0 (TID 53) in 20633 ms on 10.1.2.247 (51/64)
17/01/29 10:34:02,406 INFO BlockManagerInfo: Added rdd_5_38 in memory on 10.1.2.168:45304 (size: 64.4 MB, free: 1862.5 MB)
17/01/29 10:34:02,419 INFO BlockManagerInfo: Added rdd_5_4 in memory on 10.1.2.247:46539 (size: 64.6 MB, free: 1926.8 MB)
17/01/29 10:34:02,423 INFO TaskSetManager: Finished task 38.0 in stage 1.0 (TID 63) in 17384 ms on 10.1.2.168 (52/64)
17/01/29 10:34:02,445 INFO TaskSetManager: Finished task 4.0 in stage 1.0 (TID 21) in 20897 ms on 10.1.2.247 (53/64)
17/01/29 10:34:02,478 INFO BlockManagerInfo: Added rdd_5_50 in memory on 10.1.2.188:35389 (size: 64.3 MB, free: 1927.2 MB)
17/01/29 10:34:02,493 INFO TaskSetManager: Finished task 50.0 in stage 1.0 (TID 44) in 20904 ms on 10.1.2.188 (54/64)
17/01/29 10:34:02,622 INFO BlockManagerInfo: Added rdd_5_41 in memory on 10.1.2.138:39427 (size: 64.5 MB, free: 2.0 GB)
17/01/29 10:34:02,666 INFO BlockManagerInfo: Added rdd_5_42 in memory on 10.1.2.138:39427 (size: 64.5 MB, free: 1991.4 MB)
17/01/29 10:34:02,693 INFO TaskSetManager: Finished task 42.0 in stage 1.0 (TID 51) in 21093 ms on 10.1.2.138 (55/64)
17/01/29 10:34:02,695 INFO TaskSetManager: Finished task 41.0 in stage 1.0 (TID 35) in 21123 ms on 10.1.2.138 (56/64)
17/01/29 10:34:02,722 INFO BlockManagerInfo: Added rdd_5_34 in memory on 10.1.2.247:46539 (size: 64.6 MB, free: 1862.2 MB)
17/01/29 10:34:02,737 INFO TaskSetManager: Finished task 34.0 in stage 1.0 (TID 37) in 21162 ms on 10.1.2.247 (57/64)
17/01/29 10:34:02,894 INFO BlockManagerInfo: Added rdd_5_25 in memory on 10.1.2.188:35389 (size: 64.5 MB, free: 1862.7 MB)
17/01/29 10:34:02,911 INFO TaskSetManager: Finished task 25.0 in stage 1.0 (TID 62) in 17874 ms on 10.1.2.188 (58/64)
17/01/29 10:34:03,456 INFO BlockManagerInfo: Added rdd_5_7 in memory on 10.1.2.138:39427 (size: 64.5 MB, free: 1926.9 MB)
17/01/29 10:34:03,484 INFO TaskSetManager: Finished task 7.0 in stage 1.0 (TID 3) in 21973 ms on 10.1.2.138 (59/64)
17/01/29 10:34:03,562 INFO BlockManagerInfo: Added rdd_5_19 in memory on 10.1.2.138:39427 (size: 64.5 MB, free: 1862.4 MB)
17/01/29 10:34:03,578 INFO TaskSetManager: Finished task 19.0 in stage 1.0 (TID 19) in 22033 ms on 10.1.2.138 (60/64)
17/01/29 10:34:04,981 INFO BlockManagerInfo: Added rdd_5_2 in memory on 10.1.2.101:43794 (size: 64.6 MB, free: 2.0 GB)
17/01/29 10:34:05,043 INFO TaskSetManager: Finished task 2.0 in stage 1.0 (TID 8) in 23522 ms on 10.1.2.101 (61/64)
17/01/29 10:34:05,044 INFO BlockManagerInfo: Added rdd_5_39 in memory on 10.1.2.101:43794 (size: 64.5 MB, free: 1991.3 MB)
17/01/29 10:34:05,057 INFO TaskSetManager: Finished task 39.0 in stage 1.0 (TID 24) in 23504 ms on 10.1.2.101 (62/64)
17/01/29 10:34:05,087 INFO BlockManagerInfo: Added rdd_5_52 in memory on 10.1.2.101:43794 (size: 64.5 MB, free: 1926.7 MB)
17/01/29 10:34:05,107 INFO TaskSetManager: Finished task 52.0 in stage 1.0 (TID 40) in 23525 ms on 10.1.2.101 (63/64)
17/01/29 10:34:05,247 INFO BlockManagerInfo: Added rdd_5_56 in memory on 10.1.2.101:43794 (size: 64.7 MB, free: 1862.1 MB)
17/01/29 10:34:05,258 INFO TaskSetManager: Finished task 56.0 in stage 1.0 (TID 55) in 23653 ms on 10.1.2.101 (64/64)
17/01/29 10:34:05,259 INFO TaskSchedulerImpl: Removed TaskSet 1.0, whose tasks have all completed, from pool 
17/01/29 10:34:05,259 INFO DAGScheduler: ResultStage 1 (count at DataValidators.scala:40) finished in 23.753 s
17/01/29 10:34:05,260 INFO DAGScheduler: Job 1 finished: count at DataValidators.scala:40, took 23.797184 s
17/01/29 10:34:05,268 INFO SparkContext: Starting job: count at GradientDescent.scala:209
17/01/29 10:34:05,270 INFO DAGScheduler: Got job 2 (count at GradientDescent.scala:209) with 64 output partitions
17/01/29 10:34:05,270 INFO DAGScheduler: Final stage: ResultStage 2 (count at GradientDescent.scala:209)
17/01/29 10:34:05,270 INFO DAGScheduler: Parents of final stage: List()
17/01/29 10:34:05,274 INFO DAGScheduler: Missing parents: List()
17/01/29 10:34:05,274 INFO DAGScheduler: Submitting ResultStage 2 (MapPartitionsRDD[8] at map at GeneralizedLinearAlgorithm.scala:297), which has no missing parents
17/01/29 10:34:05,280 INFO MemoryStore: Block broadcast_3 stored as values in memory (estimated size 3.9 KB, free 2.1 GB)
17/01/29 10:34:05,282 INFO MemoryStore: Block broadcast_3_piece0 stored as bytes in memory (estimated size 2.2 KB, free 2.1 GB)
17/01/29 10:34:05,282 INFO BlockManagerInfo: Added broadcast_3_piece0 in memory on 10.1.2.253:34451 (size: 2.2 KB, free: 2.1 GB)
17/01/29 10:34:05,283 INFO SparkContext: Created broadcast 3 from broadcast at DAGScheduler.scala:1012
17/01/29 10:34:05,284 INFO DAGScheduler: Submitting 64 missing tasks from ResultStage 2 (MapPartitionsRDD[8] at map at GeneralizedLinearAlgorithm.scala:297)
17/01/29 10:34:05,285 INFO TaskSchedulerImpl: Adding task set 2.0 with 64 tasks
17/01/29 10:34:05,288 INFO TaskSetManager: Starting task 9.0 in stage 2.0 (TID 65, 10.1.2.233, partition 9, PROCESS_LOCAL, 5374 bytes)
17/01/29 10:34:05,289 INFO TaskSetManager: Starting task 3.0 in stage 2.0 (TID 66, 10.1.2.88, partition 3, PROCESS_LOCAL, 5374 bytes)
17/01/29 10:34:05,290 INFO TaskSetManager: Starting task 12.0 in stage 2.0 (TID 67, 10.1.2.191, partition 12, PROCESS_LOCAL, 5374 bytes)
17/01/29 10:34:05,291 INFO TaskSetManager: Starting task 1.0 in stage 2.0 (TID 68, 10.1.2.247, partition 1, PROCESS_LOCAL, 5374 bytes)
17/01/29 10:34:05,292 INFO TaskSetManager: Starting task 7.0 in stage 2.0 (TID 69, 10.1.2.138, partition 7, PROCESS_LOCAL, 5374 bytes)
17/01/29 10:34:05,292 INFO TaskSetManager: Starting task 8.0 in stage 2.0 (TID 70, 10.1.2.214, partition 8, PROCESS_LOCAL, 5374 bytes)
17/01/29 10:34:05,293 INFO TaskSetManager: Starting task 14.0 in stage 2.0 (TID 71, 10.1.2.31, partition 14, PROCESS_LOCAL, 5374 bytes)
17/01/29 10:34:05,294 INFO TaskSetManager: Starting task 18.0 in stage 2.0 (TID 72, 10.1.2.168, partition 18, PROCESS_LOCAL, 5374 bytes)
17/01/29 10:34:05,295 INFO TaskSetManager: Starting task 5.0 in stage 2.0 (TID 73, 10.1.2.188, partition 5, PROCESS_LOCAL, 5374 bytes)
17/01/29 10:34:05,296 INFO TaskSetManager: Starting task 20.0 in stage 2.0 (TID 74, 10.1.2.32, partition 20, PROCESS_LOCAL, 5374 bytes)
17/01/29 10:34:05,297 INFO TaskSetManager: Starting task 17.0 in stage 2.0 (TID 75, 10.1.2.159, partition 17, PROCESS_LOCAL, 5374 bytes)
17/01/29 10:34:05,298 INFO TaskSetManager: Starting task 2.0 in stage 2.0 (TID 76, 10.1.2.101, partition 2, PROCESS_LOCAL, 5374 bytes)
17/01/29 10:34:05,298 INFO TaskSetManager: Starting task 0.0 in stage 2.0 (TID 77, 10.1.2.112, partition 0, PROCESS_LOCAL, 5374 bytes)
17/01/29 10:34:05,299 INFO TaskSetManager: Starting task 15.0 in stage 2.0 (TID 78, 10.1.2.193, partition 15, PROCESS_LOCAL, 5374 bytes)
17/01/29 10:34:05,300 INFO TaskSetManager: Starting task 13.0 in stage 2.0 (TID 79, 10.1.2.243, partition 13, PROCESS_LOCAL, 5374 bytes)
17/01/29 10:34:05,301 INFO TaskSetManager: Starting task 10.0 in stage 2.0 (TID 80, 10.1.2.201, partition 10, PROCESS_LOCAL, 5374 bytes)
17/01/29 10:34:05,302 INFO TaskSetManager: Starting task 26.0 in stage 2.0 (TID 81, 10.1.2.233, partition 26, PROCESS_LOCAL, 5374 bytes)
17/01/29 10:34:05,303 INFO TaskSetManager: Starting task 29.0 in stage 2.0 (TID 82, 10.1.2.88, partition 29, PROCESS_LOCAL, 5374 bytes)
17/01/29 10:34:05,304 INFO TaskSetManager: Starting task 16.0 in stage 2.0 (TID 83, 10.1.2.191, partition 16, PROCESS_LOCAL, 5374 bytes)
17/01/29 10:34:05,305 INFO TaskSetManager: Starting task 4.0 in stage 2.0 (TID 84, 10.1.2.247, partition 4, PROCESS_LOCAL, 5374 bytes)
17/01/29 10:34:05,305 INFO TaskSetManager: Starting task 19.0 in stage 2.0 (TID 85, 10.1.2.138, partition 19, PROCESS_LOCAL, 5374 bytes)
17/01/29 10:34:05,306 INFO TaskSetManager: Starting task 21.0 in stage 2.0 (TID 86, 10.1.2.214, partition 21, PROCESS_LOCAL, 5374 bytes)
17/01/29 10:34:05,307 INFO TaskSetManager: Starting task 24.0 in stage 2.0 (TID 87, 10.1.2.31, partition 24, PROCESS_LOCAL, 5374 bytes)
17/01/29 10:34:05,308 INFO TaskSetManager: Starting task 38.0 in stage 2.0 (TID 88, 10.1.2.168, partition 38, PROCESS_LOCAL, 5374 bytes)
17/01/29 10:34:05,309 INFO TaskSetManager: Starting task 25.0 in stage 2.0 (TID 89, 10.1.2.188, partition 25, PROCESS_LOCAL, 5374 bytes)
17/01/29 10:34:05,311 INFO TaskSetManager: Starting task 23.0 in stage 2.0 (TID 90, 10.1.2.32, partition 23, PROCESS_LOCAL, 5374 bytes)
17/01/29 10:34:05,312 INFO TaskSetManager: Starting task 22.0 in stage 2.0 (TID 91, 10.1.2.159, partition 22, PROCESS_LOCAL, 5374 bytes)
17/01/29 10:34:05,313 INFO TaskSetManager: Starting task 39.0 in stage 2.0 (TID 92, 10.1.2.101, partition 39, PROCESS_LOCAL, 5374 bytes)
17/01/29 10:34:05,314 INFO TaskSetManager: Starting task 6.0 in stage 2.0 (TID 93, 10.1.2.112, partition 6, PROCESS_LOCAL, 5374 bytes)
17/01/29 10:34:05,316 INFO TaskSetManager: Starting task 33.0 in stage 2.0 (TID 94, 10.1.2.193, partition 33, PROCESS_LOCAL, 5374 bytes)
17/01/29 10:34:05,317 INFO TaskSetManager: Starting task 27.0 in stage 2.0 (TID 95, 10.1.2.243, partition 27, PROCESS_LOCAL, 5374 bytes)
17/01/29 10:34:05,319 INFO TaskSetManager: Starting task 11.0 in stage 2.0 (TID 96, 10.1.2.201, partition 11, PROCESS_LOCAL, 5374 bytes)
17/01/29 10:34:05,320 INFO TaskSetManager: Starting task 54.0 in stage 2.0 (TID 97, 10.1.2.233, partition 54, PROCESS_LOCAL, 5374 bytes)
17/01/29 10:34:05,321 INFO TaskSetManager: Starting task 32.0 in stage 2.0 (TID 98, 10.1.2.88, partition 32, PROCESS_LOCAL, 5374 bytes)
17/01/29 10:34:05,323 INFO TaskSetManager: Starting task 37.0 in stage 2.0 (TID 99, 10.1.2.191, partition 37, PROCESS_LOCAL, 5374 bytes)
17/01/29 10:34:05,324 INFO TaskSetManager: Starting task 34.0 in stage 2.0 (TID 100, 10.1.2.247, partition 34, PROCESS_LOCAL, 5374 bytes)
17/01/29 10:34:05,326 INFO TaskSetManager: Starting task 41.0 in stage 2.0 (TID 101, 10.1.2.138, partition 41, PROCESS_LOCAL, 5374 bytes)
17/01/29 10:34:05,327 INFO TaskSetManager: Starting task 36.0 in stage 2.0 (TID 102, 10.1.2.214, partition 36, PROCESS_LOCAL, 5374 bytes)
17/01/29 10:34:05,328 INFO TaskSetManager: Starting task 31.0 in stage 2.0 (TID 103, 10.1.2.31, partition 31, PROCESS_LOCAL, 5374 bytes)
17/01/29 10:34:05,329 INFO TaskSetManager: Starting task 47.0 in stage 2.0 (TID 104, 10.1.2.168, partition 47, PROCESS_LOCAL, 5374 bytes)
17/01/29 10:34:05,330 INFO TaskSetManager: Starting task 28.0 in stage 2.0 (TID 105, 10.1.2.188, partition 28, PROCESS_LOCAL, 5374 bytes)
17/01/29 10:34:05,331 INFO TaskSetManager: Starting task 30.0 in stage 2.0 (TID 106, 10.1.2.32, partition 30, PROCESS_LOCAL, 5374 bytes)
17/01/29 10:34:05,332 INFO TaskSetManager: Starting task 55.0 in stage 2.0 (TID 107, 10.1.2.159, partition 55, PROCESS_LOCAL, 5374 bytes)
17/01/29 10:34:05,333 INFO TaskSetManager: Starting task 52.0 in stage 2.0 (TID 108, 10.1.2.101, partition 52, PROCESS_LOCAL, 5374 bytes)
17/01/29 10:34:05,334 INFO TaskSetManager: Starting task 43.0 in stage 2.0 (TID 109, 10.1.2.112, partition 43, PROCESS_LOCAL, 5374 bytes)
17/01/29 10:34:05,335 INFO TaskSetManager: Starting task 44.0 in stage 2.0 (TID 110, 10.1.2.193, partition 44, PROCESS_LOCAL, 5374 bytes)
17/01/29 10:34:05,336 INFO TaskSetManager: Starting task 48.0 in stage 2.0 (TID 111, 10.1.2.243, partition 48, PROCESS_LOCAL, 5374 bytes)
17/01/29 10:34:05,337 INFO TaskSetManager: Starting task 35.0 in stage 2.0 (TID 112, 10.1.2.201, partition 35, PROCESS_LOCAL, 5374 bytes)
17/01/29 10:34:05,338 INFO TaskSetManager: Starting task 63.0 in stage 2.0 (TID 113, 10.1.2.233, partition 63, PROCESS_LOCAL, 5374 bytes)
17/01/29 10:34:05,339 INFO TaskSetManager: Starting task 46.0 in stage 2.0 (TID 114, 10.1.2.88, partition 46, PROCESS_LOCAL, 5374 bytes)
17/01/29 10:34:05,340 INFO TaskSetManager: Starting task 40.0 in stage 2.0 (TID 115, 10.1.2.191, partition 40, PROCESS_LOCAL, 5374 bytes)
17/01/29 10:34:05,341 INFO TaskSetManager: Starting task 49.0 in stage 2.0 (TID 116, 10.1.2.247, partition 49, PROCESS_LOCAL, 5374 bytes)
17/01/29 10:34:05,342 INFO TaskSetManager: Starting task 42.0 in stage 2.0 (TID 117, 10.1.2.138, partition 42, PROCESS_LOCAL, 5374 bytes)
17/01/29 10:34:05,343 INFO TaskSetManager: Starting task 45.0 in stage 2.0 (TID 118, 10.1.2.214, partition 45, PROCESS_LOCAL, 5374 bytes)
17/01/29 10:34:05,344 INFO TaskSetManager: Starting task 60.0 in stage 2.0 (TID 119, 10.1.2.168, partition 60, PROCESS_LOCAL, 5374 bytes)
17/01/29 10:34:05,344 INFO TaskSetManager: Starting task 50.0 in stage 2.0 (TID 120, 10.1.2.188, partition 50, PROCESS_LOCAL, 5374 bytes)
17/01/29 10:34:05,345 INFO TaskSetManager: Starting task 57.0 in stage 2.0 (TID 121, 10.1.2.32, partition 57, PROCESS_LOCAL, 5374 bytes)
17/01/29 10:34:05,346 INFO TaskSetManager: Starting task 62.0 in stage 2.0 (TID 122, 10.1.2.159, partition 62, PROCESS_LOCAL, 5374 bytes)
17/01/29 10:34:05,346 INFO TaskSetManager: Starting task 56.0 in stage 2.0 (TID 123, 10.1.2.101, partition 56, PROCESS_LOCAL, 5374 bytes)
17/01/29 10:34:05,347 INFO TaskSetManager: Starting task 51.0 in stage 2.0 (TID 124, 10.1.2.112, partition 51, PROCESS_LOCAL, 5374 bytes)
17/01/29 10:34:05,348 INFO TaskSetManager: Starting task 58.0 in stage 2.0 (TID 125, 10.1.2.193, partition 58, PROCESS_LOCAL, 5374 bytes)
17/01/29 10:34:05,349 INFO TaskSetManager: Starting task 53.0 in stage 2.0 (TID 126, 10.1.2.243, partition 53, PROCESS_LOCAL, 5374 bytes)
17/01/29 10:34:05,349 INFO TaskSetManager: Starting task 61.0 in stage 2.0 (TID 127, 10.1.2.201, partition 61, PROCESS_LOCAL, 5374 bytes)
17/01/29 10:34:05,350 INFO CoarseGrainedSchedulerBackend$DriverEndpoint: Launching task 65 on executor id: 10 hostname: 10.1.2.233.
17/01/29 10:34:05,351 INFO CoarseGrainedSchedulerBackend$DriverEndpoint: Launching task 81 on executor id: 10 hostname: 10.1.2.233.
17/01/29 10:34:05,351 INFO CoarseGrainedSchedulerBackend$DriverEndpoint: Launching task 97 on executor id: 10 hostname: 10.1.2.233.
17/01/29 10:34:05,352 INFO CoarseGrainedSchedulerBackend$DriverEndpoint: Launching task 113 on executor id: 10 hostname: 10.1.2.233.
17/01/29 10:34:05,353 INFO CoarseGrainedSchedulerBackend$DriverEndpoint: Launching task 66 on executor id: 13 hostname: 10.1.2.88.
17/01/29 10:34:05,353 INFO CoarseGrainedSchedulerBackend$DriverEndpoint: Launching task 82 on executor id: 13 hostname: 10.1.2.88.
17/01/29 10:34:05,354 INFO CoarseGrainedSchedulerBackend$DriverEndpoint: Launching task 98 on executor id: 13 hostname: 10.1.2.88.
17/01/29 10:34:05,354 INFO CoarseGrainedSchedulerBackend$DriverEndpoint: Launching task 114 on executor id: 13 hostname: 10.1.2.88.
17/01/29 10:34:05,355 INFO CoarseGrainedSchedulerBackend$DriverEndpoint: Launching task 67 on executor id: 6 hostname: 10.1.2.191.
17/01/29 10:34:05,356 INFO CoarseGrainedSchedulerBackend$DriverEndpoint: Launching task 83 on executor id: 6 hostname: 10.1.2.191.
17/01/29 10:34:05,356 INFO CoarseGrainedSchedulerBackend$DriverEndpoint: Launching task 99 on executor id: 6 hostname: 10.1.2.191.
17/01/29 10:34:05,358 INFO CoarseGrainedSchedulerBackend$DriverEndpoint: Launching task 115 on executor id: 6 hostname: 10.1.2.191.
17/01/29 10:34:05,358 INFO CoarseGrainedSchedulerBackend$DriverEndpoint: Launching task 68 on executor id: 2 hostname: 10.1.2.247.
17/01/29 10:34:05,361 INFO CoarseGrainedSchedulerBackend$DriverEndpoint: Launching task 84 on executor id: 2 hostname: 10.1.2.247.
17/01/29 10:34:05,361 INFO CoarseGrainedSchedulerBackend$DriverEndpoint: Launching task 100 on executor id: 2 hostname: 10.1.2.247.
17/01/29 10:34:05,362 INFO CoarseGrainedSchedulerBackend$DriverEndpoint: Launching task 116 on executor id: 2 hostname: 10.1.2.247.
17/01/29 10:34:05,363 INFO CoarseGrainedSchedulerBackend$DriverEndpoint: Launching task 69 on executor id: 14 hostname: 10.1.2.138.
17/01/29 10:34:05,363 INFO CoarseGrainedSchedulerBackend$DriverEndpoint: Launching task 85 on executor id: 14 hostname: 10.1.2.138.
17/01/29 10:34:05,363 INFO CoarseGrainedSchedulerBackend$DriverEndpoint: Launching task 101 on executor id: 14 hostname: 10.1.2.138.
17/01/29 10:34:05,364 INFO CoarseGrainedSchedulerBackend$DriverEndpoint: Launching task 117 on executor id: 14 hostname: 10.1.2.138.
17/01/29 10:34:05,364 INFO CoarseGrainedSchedulerBackend$DriverEndpoint: Launching task 70 on executor id: 4 hostname: 10.1.2.214.
17/01/29 10:34:05,364 INFO CoarseGrainedSchedulerBackend$DriverEndpoint: Launching task 86 on executor id: 4 hostname: 10.1.2.214.
17/01/29 10:34:05,365 INFO CoarseGrainedSchedulerBackend$DriverEndpoint: Launching task 102 on executor id: 4 hostname: 10.1.2.214.
17/01/29 10:34:05,365 INFO CoarseGrainedSchedulerBackend$DriverEndpoint: Launching task 118 on executor id: 4 hostname: 10.1.2.214.
17/01/29 10:34:05,365 INFO CoarseGrainedSchedulerBackend$DriverEndpoint: Launching task 71 on executor id: 0 hostname: 10.1.2.31.
17/01/29 10:34:05,366 INFO CoarseGrainedSchedulerBackend$DriverEndpoint: Launching task 87 on executor id: 0 hostname: 10.1.2.31.
17/01/29 10:34:05,367 INFO CoarseGrainedSchedulerBackend$DriverEndpoint: Launching task 103 on executor id: 0 hostname: 10.1.2.31.
17/01/29 10:34:05,368 INFO CoarseGrainedSchedulerBackend$DriverEndpoint: Launching task 72 on executor id: 3 hostname: 10.1.2.168.
17/01/29 10:34:05,368 INFO CoarseGrainedSchedulerBackend$DriverEndpoint: Launching task 88 on executor id: 3 hostname: 10.1.2.168.
17/01/29 10:34:05,369 INFO CoarseGrainedSchedulerBackend$DriverEndpoint: Launching task 104 on executor id: 3 hostname: 10.1.2.168.
17/01/29 10:34:05,370 INFO CoarseGrainedSchedulerBackend$DriverEndpoint: Launching task 119 on executor id: 3 hostname: 10.1.2.168.
17/01/29 10:34:05,371 INFO CoarseGrainedSchedulerBackend$DriverEndpoint: Launching task 73 on executor id: 15 hostname: 10.1.2.188.
17/01/29 10:34:05,372 INFO CoarseGrainedSchedulerBackend$DriverEndpoint: Launching task 89 on executor id: 15 hostname: 10.1.2.188.
17/01/29 10:34:05,372 INFO CoarseGrainedSchedulerBackend$DriverEndpoint: Launching task 105 on executor id: 15 hostname: 10.1.2.188.
17/01/29 10:34:05,373 INFO CoarseGrainedSchedulerBackend$DriverEndpoint: Launching task 120 on executor id: 15 hostname: 10.1.2.188.
17/01/29 10:34:05,373 INFO CoarseGrainedSchedulerBackend$DriverEndpoint: Launching task 74 on executor id: 7 hostname: 10.1.2.32.
17/01/29 10:34:05,374 INFO CoarseGrainedSchedulerBackend$DriverEndpoint: Launching task 90 on executor id: 7 hostname: 10.1.2.32.
17/01/29 10:34:05,374 INFO CoarseGrainedSchedulerBackend$DriverEndpoint: Launching task 106 on executor id: 7 hostname: 10.1.2.32.
17/01/29 10:34:05,375 INFO CoarseGrainedSchedulerBackend$DriverEndpoint: Launching task 121 on executor id: 7 hostname: 10.1.2.32.
17/01/29 10:34:05,375 INFO CoarseGrainedSchedulerBackend$DriverEndpoint: Launching task 75 on executor id: 9 hostname: 10.1.2.159.
17/01/29 10:34:05,376 INFO CoarseGrainedSchedulerBackend$DriverEndpoint: Launching task 91 on executor id: 9 hostname: 10.1.2.159.
17/01/29 10:34:05,376 INFO CoarseGrainedSchedulerBackend$DriverEndpoint: Launching task 107 on executor id: 9 hostname: 10.1.2.159.
17/01/29 10:34:05,376 INFO CoarseGrainedSchedulerBackend$DriverEndpoint: Launching task 122 on executor id: 9 hostname: 10.1.2.159.
17/01/29 10:34:05,378 INFO CoarseGrainedSchedulerBackend$DriverEndpoint: Launching task 76 on executor id: 12 hostname: 10.1.2.101.
17/01/29 10:34:05,378 INFO CoarseGrainedSchedulerBackend$DriverEndpoint: Launching task 92 on executor id: 12 hostname: 10.1.2.101.
17/01/29 10:34:05,378 INFO CoarseGrainedSchedulerBackend$DriverEndpoint: Launching task 108 on executor id: 12 hostname: 10.1.2.101.
17/01/29 10:34:05,379 INFO CoarseGrainedSchedulerBackend$DriverEndpoint: Launching task 123 on executor id: 12 hostname: 10.1.2.101.
17/01/29 10:34:05,379 INFO CoarseGrainedSchedulerBackend$DriverEndpoint: Launching task 77 on executor id: 8 hostname: 10.1.2.112.
17/01/29 10:34:05,379 INFO CoarseGrainedSchedulerBackend$DriverEndpoint: Launching task 93 on executor id: 8 hostname: 10.1.2.112.
17/01/29 10:34:05,379 INFO BlockManagerInfo: Added broadcast_3_piece0 in memory on 10.1.2.88:34574 (size: 2.2 KB, free: 1862.3 MB)
17/01/29 10:34:05,381 INFO CoarseGrainedSchedulerBackend$DriverEndpoint: Launching task 109 on executor id: 8 hostname: 10.1.2.112.
17/01/29 10:34:05,381 INFO CoarseGrainedSchedulerBackend$DriverEndpoint: Launching task 124 on executor id: 8 hostname: 10.1.2.112.
17/01/29 10:34:05,381 INFO CoarseGrainedSchedulerBackend$DriverEndpoint: Launching task 78 on executor id: 5 hostname: 10.1.2.193.
17/01/29 10:34:05,382 INFO CoarseGrainedSchedulerBackend$DriverEndpoint: Launching task 94 on executor id: 5 hostname: 10.1.2.193.
17/01/29 10:34:05,382 INFO CoarseGrainedSchedulerBackend$DriverEndpoint: Launching task 110 on executor id: 5 hostname: 10.1.2.193.
17/01/29 10:34:05,384 INFO CoarseGrainedSchedulerBackend$DriverEndpoint: Launching task 125 on executor id: 5 hostname: 10.1.2.193.
17/01/29 10:34:05,384 INFO CoarseGrainedSchedulerBackend$DriverEndpoint: Launching task 79 on executor id: 1 hostname: 10.1.2.243.
17/01/29 10:34:05,384 INFO CoarseGrainedSchedulerBackend$DriverEndpoint: Launching task 95 on executor id: 1 hostname: 10.1.2.243.
17/01/29 10:34:05,385 INFO CoarseGrainedSchedulerBackend$DriverEndpoint: Launching task 111 on executor id: 1 hostname: 10.1.2.243.
17/01/29 10:34:05,385 INFO CoarseGrainedSchedulerBackend$DriverEndpoint: Launching task 126 on executor id: 1 hostname: 10.1.2.243.
17/01/29 10:34:05,385 INFO CoarseGrainedSchedulerBackend$DriverEndpoint: Launching task 80 on executor id: 11 hostname: 10.1.2.201.
17/01/29 10:34:05,386 INFO CoarseGrainedSchedulerBackend$DriverEndpoint: Launching task 96 on executor id: 11 hostname: 10.1.2.201.
17/01/29 10:34:05,387 INFO CoarseGrainedSchedulerBackend$DriverEndpoint: Launching task 112 on executor id: 11 hostname: 10.1.2.201.
17/01/29 10:34:05,387 INFO CoarseGrainedSchedulerBackend$DriverEndpoint: Launching task 127 on executor id: 11 hostname: 10.1.2.201.
17/01/29 10:34:05,393 INFO BlockManagerInfo: Added broadcast_3_piece0 in memory on 10.1.2.233:43780 (size: 2.2 KB, free: 1862.5 MB)
17/01/29 10:34:05,399 INFO BlockManagerInfo: Added broadcast_3_piece0 in memory on 10.1.2.31:46549 (size: 2.2 KB, free: 1926.7 MB)
17/01/29 10:34:05,401 INFO BlockManagerInfo: Added broadcast_3_piece0 in memory on 10.1.2.247:46539 (size: 2.2 KB, free: 1862.2 MB)
17/01/29 10:34:05,405 INFO BlockManagerInfo: Added broadcast_3_piece0 in memory on 10.1.2.214:40179 (size: 2.2 KB, free: 1862.3 MB)
17/01/29 10:34:05,421 INFO BlockManagerInfo: Added broadcast_3_piece0 in memory on 10.1.2.138:39427 (size: 2.2 KB, free: 1862.4 MB)
17/01/29 10:34:05,439 INFO TaskSetManager: Finished task 32.0 in stage 2.0 (TID 98) in 119 ms on 10.1.2.88 (1/64)
17/01/29 10:34:05,445 INFO TaskSetManager: Finished task 26.0 in stage 2.0 (TID 81) in 144 ms on 10.1.2.233 (2/64)
17/01/29 10:34:05,445 INFO BlockManagerInfo: Added broadcast_3_piece0 in memory on 10.1.2.101:43794 (size: 2.2 KB, free: 1862.1 MB)
17/01/29 10:34:05,452 INFO BlockManagerInfo: Added broadcast_3_piece0 in memory on 10.1.2.191:39424 (size: 2.2 KB, free: 1862.1 MB)
17/01/29 10:34:05,453 INFO BlockManagerInfo: Added broadcast_3_piece0 in memory on 10.1.2.188:35389 (size: 2.2 KB, free: 1862.7 MB)
17/01/29 10:34:05,456 INFO TaskSetManager: Finished task 45.0 in stage 2.0 (TID 118) in 114 ms on 10.1.2.214 (3/64)
17/01/29 10:34:05,458 INFO TaskSetManager: Finished task 1.0 in stage 2.0 (TID 68) in 168 ms on 10.1.2.247 (4/64)
17/01/29 10:34:05,460 INFO TaskSetManager: Finished task 8.0 in stage 2.0 (TID 70) in 168 ms on 10.1.2.214 (5/64)
17/01/29 10:34:05,461 INFO TaskSetManager: Finished task 46.0 in stage 2.0 (TID 114) in 123 ms on 10.1.2.88 (6/64)
17/01/29 10:34:05,461 INFO TaskSetManager: Finished task 36.0 in stage 2.0 (TID 102) in 135 ms on 10.1.2.214 (7/64)
17/01/29 10:34:05,464 INFO TaskSetManager: Finished task 29.0 in stage 2.0 (TID 82) in 161 ms on 10.1.2.88 (8/64)
17/01/29 10:34:05,467 INFO TaskSetManager: Finished task 21.0 in stage 2.0 (TID 86) in 161 ms on 10.1.2.214 (9/64)
17/01/29 10:34:05,474 INFO TaskSetManager: Finished task 41.0 in stage 2.0 (TID 101) in 150 ms on 10.1.2.138 (10/64)
17/01/29 10:34:05,479 INFO TaskSetManager: Finished task 54.0 in stage 2.0 (TID 97) in 160 ms on 10.1.2.233 (11/64)
17/01/29 10:34:05,482 INFO BlockManagerInfo: Added broadcast_3_piece0 in memory on 10.1.2.168:45304 (size: 2.2 KB, free: 1862.5 MB)
17/01/29 10:34:05,483 INFO BlockManagerInfo: Added broadcast_3_piece0 in memory on 10.1.2.243:44321 (size: 2.2 KB, free: 1862.1 MB)
17/01/29 10:34:05,484 INFO TaskSetManager: Finished task 49.0 in stage 2.0 (TID 116) in 144 ms on 10.1.2.247 (12/64)
17/01/29 10:34:05,485 INFO BlockManagerInfo: Added broadcast_3_piece0 in memory on 10.1.2.201:36512 (size: 2.2 KB, free: 1862.3 MB)
17/01/29 10:34:05,486 INFO BlockManagerInfo: Added broadcast_3_piece0 in memory on 10.1.2.159:36325 (size: 2.2 KB, free: 1862.5 MB)
17/01/29 10:34:05,487 INFO BlockManagerInfo: Added broadcast_3_piece0 in memory on 10.1.2.112:35569 (size: 2.2 KB, free: 1797.6 MB)
17/01/29 10:34:05,489 INFO BlockManagerInfo: Added broadcast_3_piece0 in memory on 10.1.2.32:37531 (size: 2.2 KB, free: 1862.2 MB)
17/01/29 10:34:05,489 INFO TaskSetManager: Finished task 42.0 in stage 2.0 (TID 117) in 147 ms on 10.1.2.138 (13/64)
17/01/29 10:34:05,496 INFO TaskSetManager: Finished task 2.0 in stage 2.0 (TID 76) in 198 ms on 10.1.2.101 (14/64)
17/01/29 10:34:05,497 INFO TaskSetManager: Finished task 40.0 in stage 2.0 (TID 115) in 158 ms on 10.1.2.191 (15/64)
17/01/29 10:34:05,498 INFO TaskSetManager: Finished task 52.0 in stage 2.0 (TID 108) in 165 ms on 10.1.2.101 (16/64)
17/01/29 10:34:05,499 INFO TaskSetManager: Finished task 56.0 in stage 2.0 (TID 123) in 152 ms on 10.1.2.101 (17/64)
17/01/29 10:34:05,501 INFO TaskSetManager: Finished task 14.0 in stage 2.0 (TID 71) in 207 ms on 10.1.2.31 (18/64)
17/01/29 10:34:05,501 INFO TaskSetManager: Finished task 19.0 in stage 2.0 (TID 85) in 196 ms on 10.1.2.138 (19/64)
17/01/29 10:34:05,502 INFO TaskSetManager: Finished task 28.0 in stage 2.0 (TID 105) in 173 ms on 10.1.2.188 (20/64)
17/01/29 10:34:05,508 INFO TaskSetManager: Finished task 63.0 in stage 2.0 (TID 113) in 171 ms on 10.1.2.233 (21/64)
17/01/29 10:34:05,510 INFO TaskSetManager: Finished task 39.0 in stage 2.0 (TID 92) in 198 ms on 10.1.2.101 (22/64)
17/01/29 10:34:05,513 INFO BlockManagerInfo: Added broadcast_3_piece0 in memory on 10.1.2.193:34183 (size: 2.2 KB, free: 1862.5 MB)
17/01/29 10:34:05,515 INFO TaskSetManager: Finished task 16.0 in stage 2.0 (TID 83) in 211 ms on 10.1.2.191 (23/64)
17/01/29 10:34:05,516 INFO TaskSetManager: Finished task 25.0 in stage 2.0 (TID 89) in 208 ms on 10.1.2.188 (24/64)
17/01/29 10:34:05,519 INFO TaskSetManager: Finished task 9.0 in stage 2.0 (TID 65) in 233 ms on 10.1.2.233 (25/64)
17/01/29 10:34:05,526 INFO TaskSetManager: Finished task 17.0 in stage 2.0 (TID 75) in 229 ms on 10.1.2.159 (26/64)
17/01/29 10:34:05,529 INFO TaskSetManager: Finished task 18.0 in stage 2.0 (TID 72) in 235 ms on 10.1.2.168 (27/64)
17/01/29 10:34:05,530 INFO TaskSetManager: Finished task 3.0 in stage 2.0 (TID 66) in 242 ms on 10.1.2.88 (28/64)
17/01/29 10:34:05,532 INFO TaskSetManager: Finished task 23.0 in stage 2.0 (TID 90) in 222 ms on 10.1.2.32 (29/64)
17/01/29 10:34:05,534 INFO TaskSetManager: Starting task 59.0 in stage 2.0 (TID 128, 10.1.2.112, partition 59, PROCESS_LOCAL, 5374 bytes)
17/01/29 10:34:05,535 INFO CoarseGrainedSchedulerBackend$DriverEndpoint: Launching task 128 on executor id: 8 hostname: 10.1.2.112.
17/01/29 10:34:05,535 INFO TaskSetManager: Finished task 51.0 in stage 2.0 (TID 124) in 188 ms on 10.1.2.112 (30/64)
17/01/29 10:34:05,536 INFO TaskSetManager: Finished task 0.0 in stage 2.0 (TID 77) in 238 ms on 10.1.2.112 (31/64)
17/01/29 10:34:05,537 INFO TaskSetManager: Finished task 43.0 in stage 2.0 (TID 109) in 204 ms on 10.1.2.112 (32/64)
17/01/29 10:34:05,537 INFO TaskSetManager: Finished task 38.0 in stage 2.0 (TID 88) in 230 ms on 10.1.2.168 (33/64)
17/01/29 10:34:05,538 INFO TaskSetManager: Finished task 20.0 in stage 2.0 (TID 74) in 243 ms on 10.1.2.32 (34/64)
17/01/29 10:34:05,539 INFO TaskSetManager: Finished task 22.0 in stage 2.0 (TID 91) in 228 ms on 10.1.2.159 (35/64)
17/01/29 10:34:05,540 INFO TaskSetManager: Finished task 6.0 in stage 2.0 (TID 93) in 227 ms on 10.1.2.112 (36/64)
17/01/29 10:34:05,541 INFO TaskSetManager: Finished task 10.0 in stage 2.0 (TID 80) in 240 ms on 10.1.2.201 (37/64)
17/01/29 10:34:05,544 INFO TaskSetManager: Finished task 27.0 in stage 2.0 (TID 95) in 227 ms on 10.1.2.243 (38/64)
17/01/29 10:34:05,547 INFO TaskSetManager: Finished task 62.0 in stage 2.0 (TID 122) in 202 ms on 10.1.2.159 (39/64)
17/01/29 10:34:05,558 INFO TaskSetManager: Finished task 5.0 in stage 2.0 (TID 73) in 263 ms on 10.1.2.188 (40/64)
17/01/29 10:34:05,561 INFO TaskSetManager: Finished task 55.0 in stage 2.0 (TID 107) in 230 ms on 10.1.2.159 (41/64)
17/01/29 10:34:05,561 INFO TaskSetManager: Finished task 33.0 in stage 2.0 (TID 94) in 246 ms on 10.1.2.193 (42/64)
17/01/29 10:34:05,562 INFO TaskSetManager: Finished task 59.0 in stage 2.0 (TID 128) in 29 ms on 10.1.2.112 (43/64)
17/01/29 10:34:05,564 INFO TaskSetManager: Finished task 31.0 in stage 2.0 (TID 103) in 237 ms on 10.1.2.31 (44/64)
17/01/29 10:34:05,570 INFO TaskSetManager: Finished task 60.0 in stage 2.0 (TID 119) in 226 ms on 10.1.2.168 (45/64)
17/01/29 10:34:05,578 INFO TaskSetManager: Finished task 47.0 in stage 2.0 (TID 104) in 249 ms on 10.1.2.168 (46/64)
17/01/29 10:34:05,579 INFO TaskSetManager: Finished task 24.0 in stage 2.0 (TID 87) in 272 ms on 10.1.2.31 (47/64)
17/01/29 10:34:05,593 INFO TaskSetManager: Finished task 58.0 in stage 2.0 (TID 125) in 245 ms on 10.1.2.193 (48/64)
17/01/29 10:34:05,595 INFO TaskSetManager: Finished task 37.0 in stage 2.0 (TID 99) in 274 ms on 10.1.2.191 (49/64)
17/01/29 10:34:05,605 INFO TaskSetManager: Finished task 50.0 in stage 2.0 (TID 120) in 261 ms on 10.1.2.188 (50/64)
17/01/29 10:34:05,606 INFO TaskSetManager: Finished task 35.0 in stage 2.0 (TID 112) in 270 ms on 10.1.2.201 (51/64)
17/01/29 10:34:05,608 INFO TaskSetManager: Finished task 4.0 in stage 2.0 (TID 84) in 303 ms on 10.1.2.247 (52/64)
17/01/29 10:34:05,609 INFO TaskSetManager: Finished task 44.0 in stage 2.0 (TID 110) in 275 ms on 10.1.2.193 (53/64)
17/01/29 10:34:05,616 INFO TaskSetManager: Finished task 34.0 in stage 2.0 (TID 100) in 293 ms on 10.1.2.247 (54/64)
17/01/29 10:34:05,618 INFO TaskSetManager: Finished task 30.0 in stage 2.0 (TID 106) in 287 ms on 10.1.2.32 (55/64)
17/01/29 10:34:05,624 INFO TaskSetManager: Finished task 15.0 in stage 2.0 (TID 78) in 326 ms on 10.1.2.193 (56/64)
17/01/29 10:34:05,631 INFO TaskSetManager: Finished task 11.0 in stage 2.0 (TID 96) in 313 ms on 10.1.2.201 (57/64)
17/01/29 10:34:05,643 INFO TaskSetManager: Finished task 13.0 in stage 2.0 (TID 79) in 344 ms on 10.1.2.243 (58/64)
17/01/29 10:34:05,651 INFO TaskSetManager: Finished task 53.0 in stage 2.0 (TID 126) in 303 ms on 10.1.2.243 (59/64)
17/01/29 10:34:05,662 INFO TaskSetManager: Finished task 48.0 in stage 2.0 (TID 111) in 327 ms on 10.1.2.243 (60/64)
17/01/29 10:34:05,663 INFO TaskSetManager: Finished task 61.0 in stage 2.0 (TID 127) in 314 ms on 10.1.2.201 (61/64)
17/01/29 10:34:05,703 INFO TaskSetManager: Finished task 7.0 in stage 2.0 (TID 69) in 411 ms on 10.1.2.138 (62/64)
17/01/29 10:34:05,703 INFO TaskSetManager: Finished task 12.0 in stage 2.0 (TID 67) in 414 ms on 10.1.2.191 (63/64)
17/01/29 10:34:05,753 INFO TaskSetManager: Finished task 57.0 in stage 2.0 (TID 121) in 409 ms on 10.1.2.32 (64/64)
17/01/29 10:34:05,753 INFO TaskSchedulerImpl: Removed TaskSet 2.0, whose tasks have all completed, from pool 
17/01/29 10:34:05,754 INFO DAGScheduler: ResultStage 2 (count at GradientDescent.scala:209) finished in 0.468 s
17/01/29 10:34:05,754 INFO DAGScheduler: Job 2 finished: count at GradientDescent.scala:209, took 0.485841 s
17/01/29 10:34:05,983 WARN BLAS: Failed to load implementation from: com.github.fommil.netlib.NativeSystemBLAS
17/01/29 10:34:05,983 WARN BLAS: Failed to load implementation from: com.github.fommil.netlib.NativeRefBLAS
17/01/29 10:34:06,008 INFO MemoryStore: Block broadcast_4 stored as values in memory (estimated size 280.0 B, free 2.1 GB)
17/01/29 10:34:06,013 INFO MemoryStore: Block broadcast_4_piece0 stored as bytes in memory (estimated size 153.0 B, free 2.1 GB)
17/01/29 10:34:06,015 INFO BlockManagerInfo: Added broadcast_4_piece0 in memory on 10.1.2.253:34451 (size: 153.0 B, free: 2.1 GB)
17/01/29 10:34:06,016 INFO SparkContext: Created broadcast 4 from broadcast at GradientDescent.scala:235
17/01/29 10:34:06,071 INFO SparkContext: Starting job: treeAggregate at GradientDescent.scala:239
17/01/29 10:34:06,076 INFO DAGScheduler: Registering RDD 11 (treeAggregate at GradientDescent.scala:239)
17/01/29 10:34:06,077 INFO DAGScheduler: Got job 3 (treeAggregate at GradientDescent.scala:239) with 8 output partitions
17/01/29 10:34:06,077 INFO DAGScheduler: Final stage: ResultStage 4 (treeAggregate at GradientDescent.scala:239)
17/01/29 10:34:06,077 INFO DAGScheduler: Parents of final stage: List(ShuffleMapStage 3)
17/01/29 10:34:06,078 INFO DAGScheduler: Missing parents: List(ShuffleMapStage 3)
17/01/29 10:34:06,081 INFO DAGScheduler: Submitting ShuffleMapStage 3 (MapPartitionsRDD[11] at treeAggregate at GradientDescent.scala:239), which has no missing parents
17/01/29 10:34:06,098 INFO MemoryStore: Block broadcast_5 stored as values in memory (estimated size 7.2 KB, free 2.1 GB)
17/01/29 10:34:06,101 INFO MemoryStore: Block broadcast_5_piece0 stored as bytes in memory (estimated size 3.7 KB, free 2.1 GB)
17/01/29 10:34:06,102 INFO BlockManagerInfo: Added broadcast_5_piece0 in memory on 10.1.2.253:34451 (size: 3.7 KB, free: 2.1 GB)
17/01/29 10:34:06,103 INFO SparkContext: Created broadcast 5 from broadcast at DAGScheduler.scala:1012
17/01/29 10:34:06,105 INFO DAGScheduler: Submitting 64 missing tasks from ShuffleMapStage 3 (MapPartitionsRDD[11] at treeAggregate at GradientDescent.scala:239)
17/01/29 10:34:06,105 INFO TaskSchedulerImpl: Adding task set 3.0 with 64 tasks
17/01/29 10:34:06,109 INFO TaskSetManager: Starting task 7.0 in stage 3.0 (TID 129, 10.1.2.138, partition 7, PROCESS_LOCAL, 5563 bytes)
17/01/29 10:34:06,110 INFO TaskSetManager: Starting task 20.0 in stage 3.0 (TID 130, 10.1.2.32, partition 20, PROCESS_LOCAL, 5563 bytes)
17/01/29 10:34:06,110 INFO TaskSetManager: Starting task 17.0 in stage 3.0 (TID 131, 10.1.2.159, partition 17, PROCESS_LOCAL, 5563 bytes)
17/01/29 10:34:06,111 INFO TaskSetManager: Starting task 15.0 in stage 3.0 (TID 132, 10.1.2.193, partition 15, PROCESS_LOCAL, 5563 bytes)
17/01/29 10:34:06,111 INFO TaskSetManager: Starting task 5.0 in stage 3.0 (TID 133, 10.1.2.188, partition 5, PROCESS_LOCAL, 5563 bytes)
17/01/29 10:34:06,112 INFO TaskSetManager: Starting task 14.0 in stage 3.0 (TID 134, 10.1.2.31, partition 14, PROCESS_LOCAL, 5563 bytes)
17/01/29 10:34:06,112 INFO TaskSetManager: Starting task 9.0 in stage 3.0 (TID 135, 10.1.2.233, partition 9, PROCESS_LOCAL, 5563 bytes)
17/01/29 10:34:06,113 INFO TaskSetManager: Starting task 10.0 in stage 3.0 (TID 136, 10.1.2.201, partition 10, PROCESS_LOCAL, 5563 bytes)
17/01/29 10:34:06,113 INFO TaskSetManager: Starting task 13.0 in stage 3.0 (TID 137, 10.1.2.243, partition 13, PROCESS_LOCAL, 5563 bytes)
17/01/29 10:34:06,114 INFO TaskSetManager: Starting task 0.0 in stage 3.0 (TID 138, 10.1.2.112, partition 0, PROCESS_LOCAL, 5563 bytes)
17/01/29 10:34:06,114 INFO TaskSetManager: Starting task 3.0 in stage 3.0 (TID 139, 10.1.2.88, partition 3, PROCESS_LOCAL, 5563 bytes)
17/01/29 10:34:06,115 INFO TaskSetManager: Starting task 2.0 in stage 3.0 (TID 140, 10.1.2.101, partition 2, PROCESS_LOCAL, 5563 bytes)
17/01/29 10:34:06,116 INFO TaskSetManager: Starting task 1.0 in stage 3.0 (TID 141, 10.1.2.247, partition 1, PROCESS_LOCAL, 5563 bytes)
17/01/29 10:34:06,116 INFO TaskSetManager: Starting task 12.0 in stage 3.0 (TID 142, 10.1.2.191, partition 12, PROCESS_LOCAL, 5563 bytes)
17/01/29 10:34:06,117 INFO TaskSetManager: Starting task 8.0 in stage 3.0 (TID 143, 10.1.2.214, partition 8, PROCESS_LOCAL, 5563 bytes)
17/01/29 10:34:06,117 INFO TaskSetManager: Starting task 18.0 in stage 3.0 (TID 144, 10.1.2.168, partition 18, PROCESS_LOCAL, 5563 bytes)
17/01/29 10:34:06,118 INFO TaskSetManager: Starting task 19.0 in stage 3.0 (TID 145, 10.1.2.138, partition 19, PROCESS_LOCAL, 5563 bytes)
17/01/29 10:34:06,118 INFO TaskSetManager: Starting task 23.0 in stage 3.0 (TID 146, 10.1.2.32, partition 23, PROCESS_LOCAL, 5563 bytes)
17/01/29 10:34:06,119 INFO TaskSetManager: Starting task 22.0 in stage 3.0 (TID 147, 10.1.2.159, partition 22, PROCESS_LOCAL, 5563 bytes)
17/01/29 10:34:06,119 INFO TaskSetManager: Starting task 33.0 in stage 3.0 (TID 148, 10.1.2.193, partition 33, PROCESS_LOCAL, 5563 bytes)
17/01/29 10:34:06,120 INFO TaskSetManager: Starting task 25.0 in stage 3.0 (TID 149, 10.1.2.188, partition 25, PROCESS_LOCAL, 5563 bytes)
17/01/29 10:34:06,121 INFO TaskSetManager: Starting task 24.0 in stage 3.0 (TID 150, 10.1.2.31, partition 24, PROCESS_LOCAL, 5563 bytes)
17/01/29 10:34:06,121 INFO TaskSetManager: Starting task 26.0 in stage 3.0 (TID 151, 10.1.2.233, partition 26, PROCESS_LOCAL, 5563 bytes)
17/01/29 10:34:06,122 INFO TaskSetManager: Starting task 11.0 in stage 3.0 (TID 152, 10.1.2.201, partition 11, PROCESS_LOCAL, 5563 bytes)
17/01/29 10:34:06,122 INFO TaskSetManager: Starting task 27.0 in stage 3.0 (TID 153, 10.1.2.243, partition 27, PROCESS_LOCAL, 5563 bytes)
17/01/29 10:34:06,123 INFO TaskSetManager: Starting task 6.0 in stage 3.0 (TID 154, 10.1.2.112, partition 6, PROCESS_LOCAL, 5563 bytes)
17/01/29 10:34:06,123 INFO TaskSetManager: Starting task 29.0 in stage 3.0 (TID 155, 10.1.2.88, partition 29, PROCESS_LOCAL, 5563 bytes)
17/01/29 10:34:06,124 INFO TaskSetManager: Starting task 39.0 in stage 3.0 (TID 156, 10.1.2.101, partition 39, PROCESS_LOCAL, 5563 bytes)
17/01/29 10:34:06,125 INFO TaskSetManager: Starting task 4.0 in stage 3.0 (TID 157, 10.1.2.247, partition 4, PROCESS_LOCAL, 5563 bytes)
17/01/29 10:34:06,125 INFO TaskSetManager: Starting task 16.0 in stage 3.0 (TID 158, 10.1.2.191, partition 16, PROCESS_LOCAL, 5563 bytes)
17/01/29 10:34:06,126 INFO TaskSetManager: Starting task 21.0 in stage 3.0 (TID 159, 10.1.2.214, partition 21, PROCESS_LOCAL, 5563 bytes)
17/01/29 10:34:06,126 INFO TaskSetManager: Starting task 38.0 in stage 3.0 (TID 160, 10.1.2.168, partition 38, PROCESS_LOCAL, 5563 bytes)
17/01/29 10:34:06,127 INFO TaskSetManager: Starting task 41.0 in stage 3.0 (TID 161, 10.1.2.138, partition 41, PROCESS_LOCAL, 5563 bytes)
17/01/29 10:34:06,127 INFO TaskSetManager: Starting task 30.0 in stage 3.0 (TID 162, 10.1.2.32, partition 30, PROCESS_LOCAL, 5563 bytes)
17/01/29 10:34:06,128 INFO TaskSetManager: Starting task 55.0 in stage 3.0 (TID 163, 10.1.2.159, partition 55, PROCESS_LOCAL, 5563 bytes)
17/01/29 10:34:06,129 INFO TaskSetManager: Starting task 44.0 in stage 3.0 (TID 164, 10.1.2.193, partition 44, PROCESS_LOCAL, 5563 bytes)
17/01/29 10:34:06,129 INFO TaskSetManager: Starting task 28.0 in stage 3.0 (TID 165, 10.1.2.188, partition 28, PROCESS_LOCAL, 5563 bytes)
17/01/29 10:34:06,130 INFO TaskSetManager: Starting task 31.0 in stage 3.0 (TID 166, 10.1.2.31, partition 31, PROCESS_LOCAL, 5563 bytes)
17/01/29 10:34:06,130 INFO TaskSetManager: Starting task 54.0 in stage 3.0 (TID 167, 10.1.2.233, partition 54, PROCESS_LOCAL, 5563 bytes)
17/01/29 10:34:06,131 INFO TaskSetManager: Starting task 35.0 in stage 3.0 (TID 168, 10.1.2.201, partition 35, PROCESS_LOCAL, 5563 bytes)
17/01/29 10:34:06,131 INFO TaskSetManager: Starting task 48.0 in stage 3.0 (TID 169, 10.1.2.243, partition 48, PROCESS_LOCAL, 5563 bytes)
17/01/29 10:34:06,132 INFO TaskSetManager: Starting task 43.0 in stage 3.0 (TID 170, 10.1.2.112, partition 43, PROCESS_LOCAL, 5563 bytes)
17/01/29 10:34:06,133 INFO TaskSetManager: Starting task 32.0 in stage 3.0 (TID 171, 10.1.2.88, partition 32, PROCESS_LOCAL, 5563 bytes)
17/01/29 10:34:06,133 INFO TaskSetManager: Starting task 52.0 in stage 3.0 (TID 172, 10.1.2.101, partition 52, PROCESS_LOCAL, 5563 bytes)
17/01/29 10:34:06,134 INFO TaskSetManager: Starting task 34.0 in stage 3.0 (TID 173, 10.1.2.247, partition 34, PROCESS_LOCAL, 5563 bytes)
17/01/29 10:34:06,134 INFO TaskSetManager: Starting task 37.0 in stage 3.0 (TID 174, 10.1.2.191, partition 37, PROCESS_LOCAL, 5563 bytes)
17/01/29 10:34:06,135 INFO TaskSetManager: Starting task 36.0 in stage 3.0 (TID 175, 10.1.2.214, partition 36, PROCESS_LOCAL, 5563 bytes)
17/01/29 10:34:06,136 INFO TaskSetManager: Starting task 47.0 in stage 3.0 (TID 176, 10.1.2.168, partition 47, PROCESS_LOCAL, 5563 bytes)
17/01/29 10:34:06,136 INFO TaskSetManager: Starting task 42.0 in stage 3.0 (TID 177, 10.1.2.138, partition 42, PROCESS_LOCAL, 5563 bytes)
17/01/29 10:34:06,137 INFO TaskSetManager: Starting task 57.0 in stage 3.0 (TID 178, 10.1.2.32, partition 57, PROCESS_LOCAL, 5563 bytes)
17/01/29 10:34:06,137 INFO TaskSetManager: Starting task 62.0 in stage 3.0 (TID 179, 10.1.2.159, partition 62, PROCESS_LOCAL, 5563 bytes)
17/01/29 10:34:06,138 INFO TaskSetManager: Starting task 58.0 in stage 3.0 (TID 180, 10.1.2.193, partition 58, PROCESS_LOCAL, 5563 bytes)
17/01/29 10:34:06,138 INFO TaskSetManager: Starting task 50.0 in stage 3.0 (TID 181, 10.1.2.188, partition 50, PROCESS_LOCAL, 5563 bytes)
17/01/29 10:34:06,139 INFO TaskSetManager: Starting task 63.0 in stage 3.0 (TID 182, 10.1.2.233, partition 63, PROCESS_LOCAL, 5563 bytes)
17/01/29 10:34:06,140 INFO TaskSetManager: Starting task 61.0 in stage 3.0 (TID 183, 10.1.2.201, partition 61, PROCESS_LOCAL, 5563 bytes)
17/01/29 10:34:06,140 INFO TaskSetManager: Starting task 53.0 in stage 3.0 (TID 184, 10.1.2.243, partition 53, PROCESS_LOCAL, 5563 bytes)
17/01/29 10:34:06,141 INFO TaskSetManager: Starting task 51.0 in stage 3.0 (TID 185, 10.1.2.112, partition 51, PROCESS_LOCAL, 5563 bytes)
17/01/29 10:34:06,142 INFO TaskSetManager: Starting task 46.0 in stage 3.0 (TID 186, 10.1.2.88, partition 46, PROCESS_LOCAL, 5563 bytes)
17/01/29 10:34:06,142 INFO TaskSetManager: Starting task 56.0 in stage 3.0 (TID 187, 10.1.2.101, partition 56, PROCESS_LOCAL, 5563 bytes)
17/01/29 10:34:06,143 INFO TaskSetManager: Starting task 49.0 in stage 3.0 (TID 188, 10.1.2.247, partition 49, PROCESS_LOCAL, 5563 bytes)
17/01/29 10:34:06,143 INFO TaskSetManager: Starting task 40.0 in stage 3.0 (TID 189, 10.1.2.191, partition 40, PROCESS_LOCAL, 5563 bytes)
