Using properties file: /home/ubuntu/spark-2.0.0/conf/spark-defaults.conf
Adding default property: spark.driver.extraJavaOptions=-XX:+PrintGCDetails -XX:+PrintGCTimeStamps -Xms4000m -Dlog4j.configuration=file:///home/ubuntu/spark-2.0.0/conf/log4j.properties
Adding default property: spark.executor.extraJavaOptions=-XX:+PrintGCDetails -XX:+PrintGCTimeStamps -Xms4000m -Dlog4j.configuration=file:///home/ubuntu/spark-2.0.0/conf/log4j.properties
Parsed arguments:
  master                  spark://euca-10-1-2-60:7077
  deployMode              client
  executorMemory          4000m
  executorCores           null
  totalExecutorCores      null
  propertiesFile          /home/ubuntu/spark-2.0.0/conf/spark-defaults.conf
  driverMemory            4000m
  driverCores             null
  driverExtraClassPath    null
  driverExtraLibraryPath  null
  driverExtraJavaOptions  -XX:+PrintGCDetails -XX:+PrintGCTimeStamps -Xms4000m -Dlog4j.configuration=file:///home/ubuntu/spark-2.0.0/conf/log4j.properties
  supervise               false
  queue                   null
  numExecutors            1
  files                   null
  pyFiles                 null
  archives                null
  mainClass               LogRegExplicitParallelism
  primaryResource         file:///home/ubuntu/jars/log-reg-explicit-parallelism_2.11-1.0.jar
  name                    LogRegExplicitParallelism
  childArgs               [cluster 28 euca-10-1-2-60 9000 higgs_0_exp 5 4]
  jars                    null
  packages                null
  packagesExclusions      null
  repositories            null
  verbose                 true

Spark properties used, including those specified through
 --conf and those from the properties file /home/ubuntu/spark-2.0.0/conf/spark-defaults.conf:
  spark.default.parallelism -> 4
  spark.driver.memory -> 4000m
  spark.executor.extraJavaOptions -> -XX:+PrintGCDetails -XX:+PrintGCTimeStamps -Xms4000m -Dlog4j.configuration=file:///home/ubuntu/spark-2.0.0/conf/log4j.properties
  spark.driver.extraJavaOptions -> -XX:+PrintGCDetails -XX:+PrintGCTimeStamps -Xms4000m -Dlog4j.configuration=file:///home/ubuntu/spark-2.0.0/conf/log4j.properties
  spark.shuffle.spill -> false

    
Main class:
LogRegExplicitParallelism
Arguments:
cluster
28
euca-10-1-2-60
9000
higgs_0_exp
5
4
System properties:
spark.default.parallelism -> 4
spark.executor.memory -> 4000m
spark.driver.memory -> 4000m
SPARK_SUBMIT -> true
spark.executor.extraJavaOptions -> -XX:+PrintGCDetails -XX:+PrintGCTimeStamps -Xms4000m -Dlog4j.configuration=file:///home/ubuntu/spark-2.0.0/conf/log4j.properties
spark.app.name -> LogRegExplicitParallelism
spark.shuffle.spill -> false
spark.driver.extraJavaOptions -> -XX:+PrintGCDetails -XX:+PrintGCTimeStamps -Xms4000m -Dlog4j.configuration=file:///home/ubuntu/spark-2.0.0/conf/log4j.properties
spark.jars -> file:///home/ubuntu/jars/log-reg-explicit-parallelism_2.11-1.0.jar
spark.submit.deployMode -> client
spark.master -> spark://euca-10-1-2-60:7077
Classpath elements:
file:///home/ubuntu/jars/log-reg-explicit-parallelism_2.11-1.0.jar


17/01/28 20:39:00,873 INFO SparkContext: Running Spark version 2.0.0
17/01/28 20:39:01,204 WARN NativeCodeLoader: Unable to load native-hadoop library for your platform... using builtin-java classes where applicable
17/01/28 20:39:01,364 INFO SecurityManager: Changing view acls to: ubuntu
17/01/28 20:39:01,365 INFO SecurityManager: Changing modify acls to: ubuntu
17/01/28 20:39:01,365 INFO SecurityManager: Changing view acls groups to: 
17/01/28 20:39:01,366 INFO SecurityManager: Changing modify acls groups to: 
17/01/28 20:39:01,366 INFO SecurityManager: SecurityManager: authentication disabled; ui acls disabled; users  with view permissions: Set(ubuntu); groups with view permissions: Set(); users  with modify permissions: Set(ubuntu); groups with modify permissions: Set()
17/01/28 20:39:01,679 INFO Utils: Successfully started service 'sparkDriver' on port 35960.
17/01/28 20:39:01,697 INFO SparkEnv: Registering MapOutputTracker
17/01/28 20:39:01,703 WARN SortShuffleManager: spark.shuffle.spill was set to false, but this configuration is ignored as of Spark 1.6+. Shuffle will continue to spill to disk when necessary.
17/01/28 20:39:01,714 INFO SparkEnv: Registering BlockManagerMaster
17/01/28 20:39:01,726 INFO DiskBlockManager: Created local directory at /tmp/blockmgr-3e684b80-2b44-476d-b996-b3f4d8d12027
17/01/28 20:39:01,745 INFO MemoryStore: MemoryStore started with capacity 2.1 GB
17/01/28 20:39:01,802 INFO SparkEnv: Registering OutputCommitCoordinator
17/01/28 20:39:01,999 INFO Utils: Successfully started service 'SparkUI' on port 4040.
17/01/28 20:39:02,001 INFO SparkUI: Bound SparkUI to 10.1.2.60, and started at http://10.1.2.60:4040
17/01/28 20:39:02,034 INFO SparkContext: Added JAR file:///home/ubuntu/jars/log-reg-explicit-parallelism_2.11-1.0.jar at spark://10.1.2.60:35960/jars/log-reg-explicit-parallelism_2.11-1.0.jar with timestamp 1485635942034
17/01/28 20:39:02,110 INFO StandaloneAppClient$ClientEndpoint: Connecting to master spark://euca-10-1-2-60:7077...
17/01/28 20:39:02,159 INFO TransportClientFactory: Successfully created connection to euca-10-1-2-60/10.1.2.60:7077 after 24 ms (0 ms spent in bootstraps)
17/01/28 20:39:02,258 INFO StandaloneSchedulerBackend: Connected to Spark cluster with app ID app-20170128203902-0000
17/01/28 20:39:02,263 INFO Utils: Successfully started service 'org.apache.spark.network.netty.NettyBlockTransferService' on port 32932.
17/01/28 20:39:02,264 INFO NettyBlockTransferService: Server created on 10.1.2.60:32932
17/01/28 20:39:02,265 INFO BlockManagerMaster: Registering BlockManager BlockManagerId(driver, 10.1.2.60, 32932)
17/01/28 20:39:02,268 INFO BlockManagerMasterEndpoint: Registering block manager 10.1.2.60:32932 with 2.1 GB RAM, BlockManagerId(driver, 10.1.2.60, 32932)
17/01/28 20:39:02,270 INFO BlockManagerMaster: Registered BlockManager BlockManagerId(driver, 10.1.2.60, 32932)
17/01/28 20:39:02,285 INFO StandaloneAppClient$ClientEndpoint: Executor added: app-20170128203902-0000/0 on worker-20170128203851-10.1.2.97-44033 (10.1.2.97:44033) with 4 cores
17/01/28 20:39:02,285 INFO StandaloneSchedulerBackend: Granted executor ID app-20170128203902-0000/0 on hostPort 10.1.2.97:44033 with 4 cores, 3.9 GB RAM
17/01/28 20:39:02,346 INFO StandaloneAppClient$ClientEndpoint: Executor updated: app-20170128203902-0000/0 is now RUNNING
17/01/28 20:39:02,427 INFO StandaloneSchedulerBackend: SchedulerBackend is ready for scheduling beginning after reached minRegisteredResourcesRatio: 0.0
17/01/28 20:39:02,784 INFO MemoryStore: Block broadcast_0 stored as values in memory (estimated size 130.8 KB, free 2.1 GB)
17/01/28 20:39:02,855 INFO MemoryStore: Block broadcast_0_piece0 stored as bytes in memory (estimated size 16.5 KB, free 2.1 GB)
17/01/28 20:39:02,857 INFO BlockManagerInfo: Added broadcast_0_piece0 in memory on 10.1.2.60:32932 (size: 16.5 KB, free: 2.1 GB)
17/01/28 20:39:02,866 INFO SparkContext: Created broadcast 0 from textFile at MLUtils.scala:99
17/01/28 20:39:03,435 INFO FileInputFormat: Total input paths to process : 1
17/01/28 20:39:03,469 INFO NetworkTopology: Adding a new node: /default-rack/10.1.2.97:50010
17/01/28 20:39:03,506 INFO SparkContext: Starting job: first at GeneralizedLinearAlgorithm.scala:246
17/01/28 20:39:03,518 INFO DAGScheduler: Got job 0 (first at GeneralizedLinearAlgorithm.scala:246) with 1 output partitions
17/01/28 20:39:03,518 INFO DAGScheduler: Final stage: ResultStage 0 (first at GeneralizedLinearAlgorithm.scala:246)
17/01/28 20:39:03,519 INFO DAGScheduler: Parents of final stage: List()
17/01/28 20:39:03,524 INFO DAGScheduler: Missing parents: List()
17/01/28 20:39:03,531 INFO DAGScheduler: Submitting ResultStage 0 (MapPartitionsRDD[6] at map at GeneralizedLinearAlgorithm.scala:246), which has no missing parents
17/01/28 20:39:03,550 INFO MemoryStore: Block broadcast_1 stored as values in memory (estimated size 4.2 KB, free 2.1 GB)
17/01/28 20:39:03,552 INFO MemoryStore: Block broadcast_1_piece0 stored as bytes in memory (estimated size 2.4 KB, free 2.1 GB)
17/01/28 20:39:03,552 INFO BlockManagerInfo: Added broadcast_1_piece0 in memory on 10.1.2.60:32932 (size: 2.4 KB, free: 2.1 GB)
17/01/28 20:39:03,554 INFO SparkContext: Created broadcast 1 from broadcast at DAGScheduler.scala:1012
17/01/28 20:39:03,556 INFO DAGScheduler: Submitting 1 missing tasks from ResultStage 0 (MapPartitionsRDD[6] at map at GeneralizedLinearAlgorithm.scala:246)
17/01/28 20:39:03,557 INFO TaskSchedulerImpl: Adding task set 0.0 with 1 tasks
17/01/28 20:39:04,134 INFO CoarseGrainedSchedulerBackend$DriverEndpoint: Registered executor NettyRpcEndpointRef(null) (10.1.2.97:35938) with ID 0
17/01/28 20:39:04,167 INFO TaskSetManager: Starting task 0.0 in stage 0.0 (TID 0, 10.1.2.97, partition 0, ANY, 5454 bytes)
17/01/28 20:39:04,173 INFO CoarseGrainedSchedulerBackend$DriverEndpoint: Launching task 0 on executor id: 0 hostname: 10.1.2.97.
17/01/28 20:39:04,188 INFO BlockManagerMasterEndpoint: Registering block manager 10.1.2.97:46198 with 2.1 GB RAM, BlockManagerId(0, 10.1.2.97, 46198)
17/01/28 20:39:04,470 INFO BlockManagerInfo: Added broadcast_1_piece0 in memory on 10.1.2.97:46198 (size: 2.4 KB, free: 2.1 GB)
17/01/28 20:39:04,627 INFO BlockManagerInfo: Added broadcast_0_piece0 in memory on 10.1.2.97:46198 (size: 16.5 KB, free: 2.1 GB)
17/01/28 20:39:12,075 INFO BlockManagerInfo: Added rdd_5_0 in memory on 10.1.2.97:46198 (size: 70.0 MB, free: 2.0 GB)
17/01/28 20:39:12,131 INFO TaskSetManager: Finished task 0.0 in stage 0.0 (TID 0) in 7988 ms on 10.1.2.97 (1/1)
17/01/28 20:39:12,132 INFO TaskSchedulerImpl: Removed TaskSet 0.0, whose tasks have all completed, from pool 
17/01/28 20:39:12,136 INFO DAGScheduler: ResultStage 0 (first at GeneralizedLinearAlgorithm.scala:246) finished in 8.570 s
17/01/28 20:39:12,142 INFO DAGScheduler: Job 0 finished: first at GeneralizedLinearAlgorithm.scala:246, took 8.634998 s
17/01/28 20:39:12,153 INFO SparkContext: Starting job: count at DataValidators.scala:40
17/01/28 20:39:12,155 INFO DAGScheduler: Got job 1 (count at DataValidators.scala:40) with 59 output partitions
17/01/28 20:39:12,155 INFO DAGScheduler: Final stage: ResultStage 1 (count at DataValidators.scala:40)
17/01/28 20:39:12,155 INFO DAGScheduler: Parents of final stage: List()
17/01/28 20:39:12,158 INFO DAGScheduler: Missing parents: List()
17/01/28 20:39:12,158 INFO DAGScheduler: Submitting ResultStage 1 (MapPartitionsRDD[7] at filter at DataValidators.scala:40), which has no missing parents
17/01/28 20:39:12,180 INFO MemoryStore: Block broadcast_2 stored as values in memory (estimated size 3.9 KB, free 2.1 GB)
17/01/28 20:39:12,182 INFO MemoryStore: Block broadcast_2_piece0 stored as bytes in memory (estimated size 2.2 KB, free 2.1 GB)
17/01/28 20:39:12,182 INFO BlockManagerInfo: Added broadcast_2_piece0 in memory on 10.1.2.60:32932 (size: 2.2 KB, free: 2.1 GB)
17/01/28 20:39:12,183 INFO SparkContext: Created broadcast 2 from broadcast at DAGScheduler.scala:1012
17/01/28 20:39:12,185 INFO DAGScheduler: Submitting 59 missing tasks from ResultStage 1 (MapPartitionsRDD[7] at filter at DataValidators.scala:40)
17/01/28 20:39:12,186 INFO TaskSchedulerImpl: Adding task set 1.0 with 59 tasks
17/01/28 20:39:12,191 INFO TaskSetManager: Starting task 0.0 in stage 1.0 (TID 1, 10.1.2.97, partition 0, PROCESS_LOCAL, 5372 bytes)
17/01/28 20:39:12,193 INFO TaskSetManager: Starting task 58.0 in stage 1.0 (TID 2, 10.1.2.97, partition 58, NODE_LOCAL, 5372 bytes)
17/01/28 20:39:12,193 INFO CoarseGrainedSchedulerBackend$DriverEndpoint: Launching task 1 on executor id: 0 hostname: 10.1.2.97.
17/01/28 20:39:12,194 INFO CoarseGrainedSchedulerBackend$DriverEndpoint: Launching task 2 on executor id: 0 hostname: 10.1.2.97.
17/01/28 20:39:12,214 INFO BlockManagerInfo: Added broadcast_2_piece0 in memory on 10.1.2.97:46198 (size: 2.2 KB, free: 2.0 GB)
17/01/28 20:39:12,293 INFO TaskSetManager: Finished task 0.0 in stage 1.0 (TID 1) in 104 ms on 10.1.2.97 (1/59)
17/01/28 20:39:16,101 INFO TaskSetManager: Starting task 1.0 in stage 1.0 (TID 3, 10.1.2.97, partition 1, ANY, 5372 bytes)
17/01/28 20:39:16,104 INFO TaskSetManager: Starting task 2.0 in stage 1.0 (TID 4, 10.1.2.97, partition 2, ANY, 5372 bytes)
17/01/28 20:39:16,109 INFO TaskSetManager: Starting task 3.0 in stage 1.0 (TID 5, 10.1.2.97, partition 3, ANY, 5372 bytes)
17/01/28 20:39:16,110 INFO CoarseGrainedSchedulerBackend$DriverEndpoint: Launching task 3 on executor id: 0 hostname: 10.1.2.97.
17/01/28 20:39:16,110 INFO CoarseGrainedSchedulerBackend$DriverEndpoint: Launching task 4 on executor id: 0 hostname: 10.1.2.97.
17/01/28 20:39:16,111 INFO CoarseGrainedSchedulerBackend$DriverEndpoint: Launching task 5 on executor id: 0 hostname: 10.1.2.97.
22.86317/01/28 20:39:23,050 INFO BlockManagerInfo: Added rdd_5_58 in memory on 10.1.2.97:46198 (size: 72.8 MB, free: 1977.6 MB)
: [GC [PSYoungGen: 1024512K->123932K(1195008K)] 1024512K->123940K(3926016K), 0.0636420 secs] [Times: user=0.10 sys=0.02, real=0.06 secs] 
17/01/28 20:39:23,159 INFO TaskSetManager: Starting task 4.0 in stage 1.0 (TID 6, 10.1.2.97, partition 4, ANY, 5372 bytes)
17/01/28 20:39:23,159 INFO CoarseGrainedSchedulerBackend$DriverEndpoint: Launching task 6 on executor id: 0 hostname: 10.1.2.97.
17/01/28 20:39:23,162 INFO TaskSetManager: Finished task 58.0 in stage 1.0 (TID 2) in 10970 ms on 10.1.2.97 (2/59)
17/01/28 20:39:23,207 INFO BlockManagerInfo: Removed broadcast_1_piece0 on 10.1.2.60:32932 in memory (size: 2.4 KB, free: 2.1 GB)
17/01/28 20:39:23,222 INFO BlockManagerInfo: Removed broadcast_1_piece0 on 10.1.2.97:46198 in memory (size: 2.4 KB, free: 1977.6 MB)
17/01/28 20:39:35,936 INFO BlockManagerInfo: Added rdd_5_1 in memory on 10.1.2.97:46198 (size: 70.0 MB, free: 1907.7 MB)
17/01/28 20:39:35,959 INFO TaskSetManager: Starting task 5.0 in stage 1.0 (TID 7, 10.1.2.97, partition 5, ANY, 5372 bytes)
17/01/28 20:39:35,960 INFO CoarseGrainedSchedulerBackend$DriverEndpoint: Launching task 7 on executor id: 0 hostname: 10.1.2.97.
17/01/28 20:39:35,960 INFO TaskSetManager: Finished task 1.0 in stage 1.0 (TID 3) in 19860 ms on 10.1.2.97 (3/59)
17/01/28 20:39:37,475 INFO BlockManagerInfo: Added rdd_5_2 in memory on 10.1.2.97:46198 (size: 69.9 MB, free: 1837.8 MB)
17/01/28 20:39:37,495 INFO TaskSetManager: Starting task 6.0 in stage 1.0 (TID 8, 10.1.2.97, partition 6, ANY, 5372 bytes)
17/01/28 20:39:37,495 INFO CoarseGrainedSchedulerBackend$DriverEndpoint: Launching task 8 on executor id: 0 hostname: 10.1.2.97.
17/01/28 20:39:37,497 INFO TaskSetManager: Finished task 2.0 in stage 1.0 (TID 4) in 21395 ms on 10.1.2.97 (4/59)
17/01/28 20:39:37,573 INFO BlockManagerInfo: Added rdd_5_3 in memory on 10.1.2.97:46198 (size: 69.9 MB, free: 1767.8 MB)
17/01/28 20:39:37,596 INFO TaskSetManager: Starting task 7.0 in stage 1.0 (TID 9, 10.1.2.97, partition 7, ANY, 5372 bytes)
17/01/28 20:39:37,596 INFO CoarseGrainedSchedulerBackend$DriverEndpoint: Launching task 9 on executor id: 0 hostname: 10.1.2.97.
17/01/28 20:39:37,597 INFO TaskSetManager: Finished task 3.0 in stage 1.0 (TID 5) in 21492 ms on 10.1.2.97 (5/59)
17/01/28 20:39:43,538 INFO BlockManagerInfo: Added rdd_5_4 in memory on 10.1.2.97:46198 (size: 70.0 MB, free: 1697.9 MB)
17/01/28 20:39:43,562 INFO TaskSetManager: Starting task 8.0 in stage 1.0 (TID 10, 10.1.2.97, partition 8, ANY, 5372 bytes)
17/01/28 20:39:43,563 INFO CoarseGrainedSchedulerBackend$DriverEndpoint: Launching task 10 on executor id: 0 hostname: 10.1.2.97.
17/01/28 20:39:43,563 INFO TaskSetManager: Finished task 4.0 in stage 1.0 (TID 6) in 20406 ms on 10.1.2.97 (6/59)
17/01/28 20:39:54,347 INFO BlockManagerInfo: Added rdd_5_5 in memory on 10.1.2.97:46198 (size: 70.0 MB, free: 1627.9 MB)
17/01/28 20:39:54,372 INFO TaskSetManager: Starting task 9.0 in stage 1.0 (TID 11, 10.1.2.97, partition 9, ANY, 5372 bytes)
17/01/28 20:39:54,372 INFO CoarseGrainedSchedulerBackend$DriverEndpoint: Launching task 11 on executor id: 0 hostname: 10.1.2.97.
17/01/28 20:39:54,373 INFO TaskSetManager: Finished task 5.0 in stage 1.0 (TID 7) in 18416 ms on 10.1.2.97 (7/59)
17/01/28 20:39:54,729 INFO BlockManagerInfo: Added rdd_5_6 in memory on 10.1.2.97:46198 (size: 69.9 MB, free: 1557.9 MB)
17/01/28 20:39:54,751 INFO TaskSetManager: Starting task 10.0 in stage 1.0 (TID 12, 10.1.2.97, partition 10, ANY, 5372 bytes)
17/01/28 20:39:54,752 INFO CoarseGrainedSchedulerBackend$DriverEndpoint: Launching task 12 on executor id: 0 hostname: 10.1.2.97.
17/01/28 20:39:54,752 INFO TaskSetManager: Finished task 6.0 in stage 1.0 (TID 8) in 17258 ms on 10.1.2.97 (8/59)
17/01/28 20:39:57,705 INFO BlockManagerInfo: Added rdd_5_7 in memory on 10.1.2.97:46198 (size: 70.0 MB, free: 1488.0 MB)
17/01/28 20:39:57,727 INFO TaskSetManager: Starting task 11.0 in stage 1.0 (TID 13, 10.1.2.97, partition 11, ANY, 5372 bytes)
17/01/28 20:39:57,728 INFO CoarseGrainedSchedulerBackend$DriverEndpoint: Launching task 13 on executor id: 0 hostname: 10.1.2.97.
17/01/28 20:39:57,728 INFO TaskSetManager: Finished task 7.0 in stage 1.0 (TID 9) in 20135 ms on 10.1.2.97 (9/59)
17/01/28 20:40:02,178 INFO BlockManagerInfo: Added rdd_5_8 in memory on 10.1.2.97:46198 (size: 70.0 MB, free: 1418.0 MB)
17/01/28 20:40:02,198 INFO TaskSetManager: Starting task 12.0 in stage 1.0 (TID 14, 10.1.2.97, partition 12, ANY, 5372 bytes)
17/01/28 20:40:02,199 INFO CoarseGrainedSchedulerBackend$DriverEndpoint: Launching task 14 on executor id: 0 hostname: 10.1.2.97.
17/01/28 20:40:02,199 INFO TaskSetManager: Finished task 8.0 in stage 1.0 (TID 10) in 18639 ms on 10.1.2.97 (10/59)
17/01/28 20:40:14,082 INFO BlockManagerInfo: Added rdd_5_10 in memory on 10.1.2.97:46198 (size: 70.0 MB, free: 1348.0 MB)
17/01/28 20:40:14,102 INFO TaskSetManager: Starting task 13.0 in stage 1.0 (TID 15, 10.1.2.97, partition 13, ANY, 5372 bytes)
17/01/28 20:40:14,102 INFO CoarseGrainedSchedulerBackend$DriverEndpoint: Launching task 15 on executor id: 0 hostname: 10.1.2.97.
17/01/28 20:40:14,103 INFO TaskSetManager: Finished task 10.0 in stage 1.0 (TID 12) in 19352 ms on 10.1.2.97 (11/59)
17/01/28 20:40:14,932 INFO BlockManagerInfo: Added rdd_5_9 in memory on 10.1.2.97:46198 (size: 69.9 MB, free: 1278.1 MB)
17/01/28 20:40:14,953 INFO TaskSetManager: Starting task 14.0 in stage 1.0 (TID 16, 10.1.2.97, partition 14, ANY, 5372 bytes)
17/01/28 20:40:14,954 INFO TaskSetManager: Finished task 9.0 in stage 1.0 (TID 11) in 20583 ms on 10.1.2.97 (12/59)
17/01/28 20:40:14,954 INFO CoarseGrainedSchedulerBackend$DriverEndpoint: Launching task 16 on executor id: 0 hostname: 10.1.2.97.
17/01/28 20:40:18,510 INFO BlockManagerInfo: Added rdd_5_11 in memory on 10.1.2.97:46198 (size: 69.9 MB, free: 1208.2 MB)
17/01/28 20:40:18,533 INFO TaskSetManager: Starting task 15.0 in stage 1.0 (TID 17, 10.1.2.97, partition 15, ANY, 5372 bytes)
17/01/28 20:40:18,535 INFO CoarseGrainedSchedulerBackend$DriverEndpoint: Launching task 17 on executor id: 0 hostname: 10.1.2.97.
17/01/28 20:40:18,535 INFO TaskSetManager: Finished task 11.0 in stage 1.0 (TID 13) in 20811 ms on 10.1.2.97 (13/59)
17/01/28 20:40:22,519 INFO BlockManagerInfo: Added rdd_5_12 in memory on 10.1.2.97:46198 (size: 70.0 MB, free: 1138.3 MB)
17/01/28 20:40:22,539 INFO TaskSetManager: Starting task 16.0 in stage 1.0 (TID 18, 10.1.2.97, partition 16, ANY, 5372 bytes)
17/01/28 20:40:22,539 INFO CoarseGrainedSchedulerBackend$DriverEndpoint: Launching task 18 on executor id: 0 hostname: 10.1.2.97.
17/01/28 20:40:22,541 INFO TaskSetManager: Finished task 12.0 in stage 1.0 (TID 14) in 20344 ms on 10.1.2.97 (14/59)
17/01/28 20:40:33,647 INFO BlockManagerInfo: Added rdd_5_14 in memory on 10.1.2.97:46198 (size: 69.9 MB, free: 1068.3 MB)
17/01/28 20:40:33,668 INFO TaskSetManager: Starting task 17.0 in stage 1.0 (TID 19, 10.1.2.97, partition 17, ANY, 5372 bytes)
17/01/28 20:40:33,668 INFO CoarseGrainedSchedulerBackend$DriverEndpoint: Launching task 19 on executor id: 0 hostname: 10.1.2.97.
17/01/28 20:40:33,668 INFO TaskSetManager: Finished task 14.0 in stage 1.0 (TID 16) in 18717 ms on 10.1.2.97 (15/59)
17/01/28 20:40:34,501 INFO BlockManagerInfo: Added rdd_5_13 in memory on 10.1.2.97:46198 (size: 69.9 MB, free: 998.4 MB)
17/01/28 20:40:34,522 INFO TaskSetManager: Starting task 18.0 in stage 1.0 (TID 20, 10.1.2.97, partition 18, ANY, 5372 bytes)
17/01/28 20:40:34,523 INFO CoarseGrainedSchedulerBackend$DriverEndpoint: Launching task 20 on executor id: 0 hostname: 10.1.2.97.
17/01/28 20:40:34,524 INFO TaskSetManager: Finished task 13.0 in stage 1.0 (TID 15) in 20424 ms on 10.1.2.97 (16/59)
17/01/28 20:40:37,670 INFO BlockManagerInfo: Added rdd_5_15 in memory on 10.1.2.97:46198 (size: 69.9 MB, free: 928.5 MB)
17/01/28 20:40:37,689 INFO TaskSetManager: Finished task 15.0 in stage 1.0 (TID 17) in 19158 ms on 10.1.2.97 (17/59)
17/01/28 20:40:37,692 INFO TaskSetManager: Starting task 19.0 in stage 1.0 (TID 21, 10.1.2.97, partition 19, ANY, 5372 bytes)
17/01/28 20:40:37,693 INFO CoarseGrainedSchedulerBackend$DriverEndpoint: Launching task 21 on executor id: 0 hostname: 10.1.2.97.
17/01/28 20:40:40,781 INFO BlockManagerInfo: Added rdd_5_16 in memory on 10.1.2.97:46198 (size: 70.0 MB, free: 858.5 MB)
17/01/28 20:40:40,801 INFO TaskSetManager: Starting task 20.0 in stage 1.0 (TID 22, 10.1.2.97, partition 20, ANY, 5372 bytes)
17/01/28 20:40:40,801 INFO CoarseGrainedSchedulerBackend$DriverEndpoint: Launching task 22 on executor id: 0 hostname: 10.1.2.97.
17/01/28 20:40:40,803 INFO TaskSetManager: Finished task 16.0 in stage 1.0 (TID 18) in 18266 ms on 10.1.2.97 (18/59)
17/01/28 20:40:53,814 INFO BlockManagerInfo: Added rdd_5_17 in memory on 10.1.2.97:46198 (size: 69.9 MB, free: 788.6 MB)
17/01/28 20:40:53,833 INFO TaskSetManager: Starting task 21.0 in stage 1.0 (TID 23, 10.1.2.97, partition 21, ANY, 5372 bytes)
17/01/28 20:40:53,833 INFO CoarseGrainedSchedulerBackend$DriverEndpoint: Launching task 23 on executor id: 0 hostname: 10.1.2.97.
17/01/28 20:40:53,836 INFO TaskSetManager: Finished task 17.0 in stage 1.0 (TID 19) in 20169 ms on 10.1.2.97 (19/59)
17/01/28 20:40:56,017 INFO BlockManagerInfo: Added rdd_5_18 in memory on 10.1.2.97:46198 (size: 70.0 MB, free: 718.7 MB)
17/01/28 20:40:56,043 INFO TaskSetManager: Starting task 22.0 in stage 1.0 (TID 24, 10.1.2.97, partition 22, ANY, 5372 bytes)
17/01/28 20:40:56,044 INFO CoarseGrainedSchedulerBackend$DriverEndpoint: Launching task 24 on executor id: 0 hostname: 10.1.2.97.
17/01/28 20:40:56,045 INFO TaskSetManager: Finished task 18.0 in stage 1.0 (TID 20) in 21524 ms on 10.1.2.97 (20/59)
17/01/28 20:40:57,221 INFO BlockManagerInfo: Added rdd_5_19 in memory on 10.1.2.97:46198 (size: 70.0 MB, free: 648.7 MB)
17/01/28 20:40:57,242 INFO TaskSetManager: Starting task 23.0 in stage 1.0 (TID 25, 10.1.2.97, partition 23, ANY, 5372 bytes)
17/01/28 20:40:57,242 INFO CoarseGrainedSchedulerBackend$DriverEndpoint: Launching task 25 on executor id: 0 hostname: 10.1.2.97.
17/01/28 20:40:57,244 INFO TaskSetManager: Finished task 19.0 in stage 1.0 (TID 21) in 19554 ms on 10.1.2.97 (21/59)
17/01/28 20:41:00,993 INFO BlockManagerInfo: Added rdd_5_20 in memory on 10.1.2.97:46198 (size: 69.8 MB, free: 578.9 MB)
17/01/28 20:41:01,013 INFO TaskSetManager: Starting task 24.0 in stage 1.0 (TID 26, 10.1.2.97, partition 24, ANY, 5372 bytes)
17/01/28 20:41:01,014 INFO CoarseGrainedSchedulerBackend$DriverEndpoint: Launching task 26 on executor id: 0 hostname: 10.1.2.97.
17/01/28 20:41:01,015 INFO TaskSetManager: Finished task 20.0 in stage 1.0 (TID 22) in 20216 ms on 10.1.2.97 (22/59)
17/01/28 20:41:14,021 INFO BlockManagerInfo: Added rdd_5_21 in memory on 10.1.2.97:46198 (size: 69.9 MB, free: 508.9 MB)
17/01/28 20:41:14,041 INFO TaskSetManager: Starting task 25.0 in stage 1.0 (TID 27, 10.1.2.97, partition 25, ANY, 5372 bytes)
17/01/28 20:41:14,041 INFO CoarseGrainedSchedulerBackend$DriverEndpoint: Launching task 27 on executor id: 0 hostname: 10.1.2.97.
17/01/28 20:41:14,042 INFO TaskSetManager: Finished task 21.0 in stage 1.0 (TID 23) in 20210 ms on 10.1.2.97 (23/59)
17/01/28 20:41:17,461 INFO BlockManagerInfo: Added rdd_5_23 in memory on 10.1.2.97:46198 (size: 69.9 MB, free: 439.0 MB)
17/01/28 20:41:17,479 INFO TaskSetManager: Starting task 26.0 in stage 1.0 (TID 28, 10.1.2.97, partition 26, ANY, 5372 bytes)
17/01/28 20:41:17,479 INFO CoarseGrainedSchedulerBackend$DriverEndpoint: Launching task 28 on executor id: 0 hostname: 10.1.2.97.
17/01/28 20:41:17,480 INFO TaskSetManager: Finished task 23.0 in stage 1.0 (TID 25) in 20240 ms on 10.1.2.97 (24/59)
17/01/28 20:41:20,214 INFO BlockManagerInfo: Added rdd_5_22 in memory on 10.1.2.97:46198 (size: 69.8 MB, free: 369.2 MB)
17/01/28 20:41:20,234 INFO TaskSetManager: Starting task 27.0 in stage 1.0 (TID 29, 10.1.2.97, partition 27, ANY, 5372 bytes)
17/01/28 20:41:20,234 INFO CoarseGrainedSchedulerBackend$DriverEndpoint: Launching task 29 on executor id: 0 hostname: 10.1.2.97.
17/01/28 20:41:20,236 INFO TaskSetManager: Finished task 22.0 in stage 1.0 (TID 24) in 24194 ms on 10.1.2.97 (25/59)
17/01/28 20:41:21,969 INFO BlockManagerInfo: Added rdd_5_24 in memory on 10.1.2.97:46198 (size: 69.8 MB, free: 299.4 MB)
17/01/28 20:41:21,991 INFO TaskSetManager: Starting task 28.0 in stage 1.0 (TID 30, 10.1.2.97, partition 28, ANY, 5372 bytes)
17/01/28 20:41:21,991 INFO CoarseGrainedSchedulerBackend$DriverEndpoint: Launching task 30 on executor id: 0 hostname: 10.1.2.97.
17/01/28 20:41:21,992 INFO TaskSetManager: Finished task 24.0 in stage 1.0 (TID 26) in 20980 ms on 10.1.2.97 (26/59)
17/01/28 20:41:35,514 INFO BlockManagerInfo: Added rdd_5_25 in memory on 10.1.2.97:46198 (size: 70.0 MB, free: 229.5 MB)
17/01/28 20:41:35,533 INFO TaskSetManager: Starting task 29.0 in stage 1.0 (TID 31, 10.1.2.97, partition 29, ANY, 5372 bytes)
17/01/28 20:41:35,533 INFO CoarseGrainedSchedulerBackend$DriverEndpoint: Launching task 31 on executor id: 0 hostname: 10.1.2.97.
17/01/28 20:41:35,534 INFO TaskSetManager: Finished task 25.0 in stage 1.0 (TID 27) in 21495 ms on 10.1.2.97 (27/59)
17/01/28 20:41:38,626 INFO TaskSetManager: Starting task 30.0 in stage 1.0 (TID 32, 10.1.2.97, partition 30, ANY, 5372 bytes)
17/01/28 20:41:38,627 INFO CoarseGrainedSchedulerBackend$DriverEndpoint: Launching task 32 on executor id: 0 hostname: 10.1.2.97.
17/01/28 20:41:38,627 INFO TaskSetManager: Finished task 26.0 in stage 1.0 (TID 28) in 21149 ms on 10.1.2.97 (28/59)
17/01/28 20:41:39,485 INFO BlockManagerInfo: Added rdd_5_27 in memory on 10.1.2.97:46198 (size: 69.9 MB, free: 159.6 MB)
17/01/28 20:41:39,513 INFO TaskSetManager: Starting task 31.0 in stage 1.0 (TID 33, 10.1.2.97, partition 31, ANY, 5372 bytes)
17/01/28 20:41:39,514 INFO CoarseGrainedSchedulerBackend$DriverEndpoint: Launching task 33 on executor id: 0 hostname: 10.1.2.97.
17/01/28 20:41:39,514 INFO TaskSetManager: Finished task 27.0 in stage 1.0 (TID 29) in 19282 ms on 10.1.2.97 (29/59)
17/01/28 20:41:42,303 INFO BlockManagerInfo: Added rdd_5_28 in memory on 10.1.2.97:46198 (size: 70.0 MB, free: 89.6 MB)
17/01/28 20:41:42,328 INFO TaskSetManager: Starting task 32.0 in stage 1.0 (TID 34, 10.1.2.97, partition 32, ANY, 5372 bytes)
17/01/28 20:41:42,328 INFO CoarseGrainedSchedulerBackend$DriverEndpoint: Launching task 34 on executor id: 0 hostname: 10.1.2.97.
17/01/28 20:41:42,329 INFO TaskSetManager: Finished task 28.0 in stage 1.0 (TID 30) in 20339 ms on 10.1.2.97 (30/59)
17/01/28 20:41:53,760 INFO TaskSetManager: Starting task 33.0 in stage 1.0 (TID 35, 10.1.2.97, partition 33, ANY, 5372 bytes)
17/01/28 20:41:53,761 INFO CoarseGrainedSchedulerBackend$DriverEndpoint: Launching task 35 on executor id: 0 hostname: 10.1.2.97.
17/01/28 20:41:53,762 INFO TaskSetManager: Finished task 29.0 in stage 1.0 (TID 31) in 18230 ms on 10.1.2.97 (31/59)
17/01/28 20:41:55,479 INFO TaskSetManager: Starting task 34.0 in stage 1.0 (TID 36, 10.1.2.97, partition 34, ANY, 5372 bytes)
17/01/28 20:41:55,480 INFO CoarseGrainedSchedulerBackend$DriverEndpoint: Launching task 36 on executor id: 0 hostname: 10.1.2.97.
17/01/28 20:41:55,480 INFO TaskSetManager: Finished task 30.0 in stage 1.0 (TID 32) in 16855 ms on 10.1.2.97 (32/59)
17/01/28 20:41:55,723 INFO TaskSetManager: Starting task 35.0 in stage 1.0 (TID 37, 10.1.2.97, partition 35, ANY, 5372 bytes)
17/01/28 20:41:55,723 INFO CoarseGrainedSchedulerBackend$DriverEndpoint: Launching task 37 on executor id: 0 hostname: 10.1.2.97.
17/01/28 20:41:55,723 INFO TaskSetManager: Finished task 31.0 in stage 1.0 (TID 33) in 16211 ms on 10.1.2.97 (33/59)
17/01/28 20:42:00,062 INFO TaskSetManager: Starting task 36.0 in stage 1.0 (TID 38, 10.1.2.97, partition 36, ANY, 5372 bytes)
17/01/28 20:42:00,062 INFO CoarseGrainedSchedulerBackend$DriverEndpoint: Launching task 38 on executor id: 0 hostname: 10.1.2.97.
17/01/28 20:42:00,063 INFO TaskSetManager: Finished task 32.0 in stage 1.0 (TID 34) in 17736 ms on 10.1.2.97 (34/59)
17/01/28 20:42:14,723 INFO TaskSetManager: Starting task 37.0 in stage 1.0 (TID 39, 10.1.2.97, partition 37, ANY, 5372 bytes)
17/01/28 20:42:14,724 INFO CoarseGrainedSchedulerBackend$DriverEndpoint: Launching task 39 on executor id: 0 hostname: 10.1.2.97.
17/01/28 20:42:14,724 INFO TaskSetManager: Finished task 33.0 in stage 1.0 (TID 35) in 20965 ms on 10.1.2.97 (35/59)
17/01/28 20:42:16,851 INFO TaskSetManager: Starting task 38.0 in stage 1.0 (TID 40, 10.1.2.97, partition 38, ANY, 5372 bytes)
17/01/28 20:42:16,851 INFO CoarseGrainedSchedulerBackend$DriverEndpoint: Launching task 40 on executor id: 0 hostname: 10.1.2.97.
17/01/28 20:42:16,852 INFO TaskSetManager: Finished task 35.0 in stage 1.0 (TID 37) in 21130 ms on 10.1.2.97 (36/59)
17/01/28 20:42:17,421 INFO TaskSetManager: Starting task 39.0 in stage 1.0 (TID 41, 10.1.2.97, partition 39, ANY, 5372 bytes)
17/01/28 20:42:17,422 INFO CoarseGrainedSchedulerBackend$DriverEndpoint: Launching task 41 on executor id: 0 hostname: 10.1.2.97.
17/01/28 20:42:17,422 INFO TaskSetManager: Finished task 34.0 in stage 1.0 (TID 36) in 21943 ms on 10.1.2.97 (37/59)
17/01/28 20:42:21,250 INFO TaskSetManager: Starting task 40.0 in stage 1.0 (TID 42, 10.1.2.97, partition 40, ANY, 5372 bytes)
17/01/28 20:42:21,250 INFO CoarseGrainedSchedulerBackend$DriverEndpoint: Launching task 42 on executor id: 0 hostname: 10.1.2.97.
17/01/28 20:42:21,251 INFO TaskSetManager: Finished task 36.0 in stage 1.0 (TID 38) in 21191 ms on 10.1.2.97 (38/59)
17/01/28 20:42:35,886 INFO TaskSetManager: Starting task 41.0 in stage 1.0 (TID 43, 10.1.2.97, partition 41, ANY, 5372 bytes)
17/01/28 20:42:35,886 INFO CoarseGrainedSchedulerBackend$DriverEndpoint: Launching task 43 on executor id: 0 hostname: 10.1.2.97.
17/01/28 20:42:35,887 INFO TaskSetManager: Finished task 37.0 in stage 1.0 (TID 39) in 21165 ms on 10.1.2.97 (39/59)
17/01/28 20:42:37,669 INFO TaskSetManager: Starting task 42.0 in stage 1.0 (TID 44, 10.1.2.97, partition 42, ANY, 5372 bytes)
17/01/28 20:42:37,669 INFO CoarseGrainedSchedulerBackend$DriverEndpoint: Launching task 44 on executor id: 0 hostname: 10.1.2.97.
17/01/28 20:42:37,670 INFO TaskSetManager: Finished task 39.0 in stage 1.0 (TID 41) in 20250 ms on 10.1.2.97 (40/59)
17/01/28 20:42:38,024 INFO TaskSetManager: Starting task 43.0 in stage 1.0 (TID 45, 10.1.2.97, partition 43, ANY, 5372 bytes)
17/01/28 20:42:38,024 INFO CoarseGrainedSchedulerBackend$DriverEndpoint: Launching task 45 on executor id: 0 hostname: 10.1.2.97.
17/01/28 20:42:38,025 INFO TaskSetManager: Finished task 38.0 in stage 1.0 (TID 40) in 21175 ms on 10.1.2.97 (41/59)
17/01/28 20:42:41,038 INFO TaskSetManager: Starting task 44.0 in stage 1.0 (TID 46, 10.1.2.97, partition 44, ANY, 5372 bytes)
17/01/28 20:42:41,038 INFO CoarseGrainedSchedulerBackend$DriverEndpoint: Launching task 46 on executor id: 0 hostname: 10.1.2.97.
17/01/28 20:42:41,041 INFO TaskSetManager: Finished task 40.0 in stage 1.0 (TID 42) in 19790 ms on 10.1.2.97 (42/59)
17/01/28 20:42:55,654 INFO TaskSetManager: Starting task 45.0 in stage 1.0 (TID 47, 10.1.2.97, partition 45, ANY, 5372 bytes)
17/01/28 20:42:55,655 INFO CoarseGrainedSchedulerBackend$DriverEndpoint: Launching task 47 on executor id: 0 hostname: 10.1.2.97.
17/01/28 20:42:55,656 INFO TaskSetManager: Finished task 41.0 in stage 1.0 (TID 43) in 19771 ms on 10.1.2.97 (43/59)
17/01/28 20:42:57,795 INFO TaskSetManager: Starting task 46.0 in stage 1.0 (TID 48, 10.1.2.97, partition 46, ANY, 5372 bytes)
17/01/28 20:42:57,795 INFO CoarseGrainedSchedulerBackend$DriverEndpoint: Launching task 48 on executor id: 0 hostname: 10.1.2.97.
17/01/28 20:42:57,796 INFO TaskSetManager: Finished task 42.0 in stage 1.0 (TID 44) in 20128 ms on 10.1.2.97 (44/59)
17/01/28 20:42:58,296 INFO TaskSetManager: Starting task 47.0 in stage 1.0 (TID 49, 10.1.2.97, partition 47, ANY, 5372 bytes)
17/01/28 20:42:58,296 INFO CoarseGrainedSchedulerBackend$DriverEndpoint: Launching task 49 on executor id: 0 hostname: 10.1.2.97.
17/01/28 20:42:58,296 INFO TaskSetManager: Finished task 43.0 in stage 1.0 (TID 45) in 20273 ms on 10.1.2.97 (45/59)
17/01/28 20:43:01,987 INFO TaskSetManager: Starting task 48.0 in stage 1.0 (TID 50, 10.1.2.97, partition 48, ANY, 5372 bytes)
17/01/28 20:43:01,988 INFO TaskSetManager: Finished task 44.0 in stage 1.0 (TID 46) in 20951 ms on 10.1.2.97 (46/59)
17/01/28 20:43:01,989 INFO CoarseGrainedSchedulerBackend$DriverEndpoint: Launching task 50 on executor id: 0 hostname: 10.1.2.97.
17/01/28 20:43:17,320 INFO TaskSetManager: Starting task 49.0 in stage 1.0 (TID 51, 10.1.2.97, partition 49, ANY, 5372 bytes)
17/01/28 20:43:17,320 INFO CoarseGrainedSchedulerBackend$DriverEndpoint: Launching task 51 on executor id: 0 hostname: 10.1.2.97.
17/01/28 20:43:17,321 INFO TaskSetManager: Finished task 47.0 in stage 1.0 (TID 49) in 19026 ms on 10.1.2.97 (47/59)
17/01/28 20:43:21,887 INFO TaskSetManager: Starting task 50.0 in stage 1.0 (TID 52, 10.1.2.97, partition 50, ANY, 5372 bytes)
17/01/28 20:43:21,887 INFO CoarseGrainedSchedulerBackend$DriverEndpoint: Launching task 52 on executor id: 0 hostname: 10.1.2.97.
17/01/28 20:43:21,888 INFO TaskSetManager: Finished task 46.0 in stage 1.0 (TID 48) in 24094 ms on 10.1.2.97 (48/59)
17/01/28 20:43:22,228 INFO TaskSetManager: Starting task 51.0 in stage 1.0 (TID 53, 10.1.2.97, partition 51, ANY, 5372 bytes)
17/01/28 20:43:22,228 INFO CoarseGrainedSchedulerBackend$DriverEndpoint: Launching task 53 on executor id: 0 hostname: 10.1.2.97.
17/01/28 20:43:22,229 INFO TaskSetManager: Finished task 45.0 in stage 1.0 (TID 47) in 26576 ms on 10.1.2.97 (49/59)
17/01/28 20:43:25,229 INFO TaskSetManager: Starting task 52.0 in stage 1.0 (TID 54, 10.1.2.97, partition 52, ANY, 5372 bytes)
17/01/28 20:43:25,229 INFO CoarseGrainedSchedulerBackend$DriverEndpoint: Launching task 54 on executor id: 0 hostname: 10.1.2.97.
17/01/28 20:43:25,230 INFO TaskSetManager: Finished task 48.0 in stage 1.0 (TID 50) in 23243 ms on 10.1.2.97 (50/59)
17/01/28 20:43:36,999 INFO TaskSetManager: Starting task 53.0 in stage 1.0 (TID 55, 10.1.2.97, partition 53, ANY, 5372 bytes)
17/01/28 20:43:36,999 INFO CoarseGrainedSchedulerBackend$DriverEndpoint: Launching task 55 on executor id: 0 hostname: 10.1.2.97.
17/01/28 20:43:37,001 INFO TaskSetManager: Finished task 49.0 in stage 1.0 (TID 51) in 19681 ms on 10.1.2.97 (51/59)
17/01/28 20:43:43,978 INFO TaskSetManager: Starting task 54.0 in stage 1.0 (TID 56, 10.1.2.97, partition 54, ANY, 5372 bytes)
17/01/28 20:43:43,978 INFO CoarseGrainedSchedulerBackend$DriverEndpoint: Launching task 56 on executor id: 0 hostname: 10.1.2.97.
17/01/28 20:43:43,979 INFO TaskSetManager: Finished task 50.0 in stage 1.0 (TID 52) in 22093 ms on 10.1.2.97 (52/59)
17/01/28 20:43:45,136 INFO TaskSetManager: Starting task 55.0 in stage 1.0 (TID 57, 10.1.2.97, partition 55, ANY, 5372 bytes)
17/01/28 20:43:45,137 INFO CoarseGrainedSchedulerBackend$DriverEndpoint: Launching task 57 on executor id: 0 hostname: 10.1.2.97.
17/01/28 20:43:45,137 INFO TaskSetManager: Finished task 51.0 in stage 1.0 (TID 53) in 22910 ms on 10.1.2.97 (53/59)
17/01/28 20:43:46,684 INFO TaskSetManager: Starting task 56.0 in stage 1.0 (TID 58, 10.1.2.97, partition 56, ANY, 5372 bytes)
17/01/28 20:43:46,684 INFO CoarseGrainedSchedulerBackend$DriverEndpoint: Launching task 58 on executor id: 0 hostname: 10.1.2.97.
17/01/28 20:43:46,685 INFO TaskSetManager: Finished task 52.0 in stage 1.0 (TID 54) in 21457 ms on 10.1.2.97 (54/59)
17/01/28 20:44:04,619 INFO TaskSetManager: Starting task 57.0 in stage 1.0 (TID 59, 10.1.2.97, partition 57, ANY, 5372 bytes)
17/01/28 20:44:04,620 INFO CoarseGrainedSchedulerBackend$DriverEndpoint: Launching task 59 on executor id: 0 hostname: 10.1.2.97.
17/01/28 20:44:04,620 INFO TaskSetManager: Finished task 53.0 in stage 1.0 (TID 55) in 27622 ms on 10.1.2.97 (55/59)
17/01/28 20:44:06,713 INFO TaskSetManager: Finished task 56.0 in stage 1.0 (TID 58) in 20030 ms on 10.1.2.97 (56/59)
17/01/28 20:44:07,264 INFO TaskSetManager: Finished task 54.0 in stage 1.0 (TID 56) in 23287 ms on 10.1.2.97 (57/59)
17/01/28 20:44:07,522 INFO TaskSetManager: Finished task 55.0 in stage 1.0 (TID 57) in 22386 ms on 10.1.2.97 (58/59)
17/01/28 20:44:13,683 INFO TaskSetManager: Finished task 57.0 in stage 1.0 (TID 59) in 9064 ms on 10.1.2.97 (59/59)
17/01/28 20:44:13,683 INFO TaskSchedulerImpl: Removed TaskSet 1.0, whose tasks have all completed, from pool 
17/01/28 20:44:13,683 INFO DAGScheduler: ResultStage 1 (count at DataValidators.scala:40) finished in 301.495 s
17/01/28 20:44:13,685 INFO DAGScheduler: Job 1 finished: count at DataValidators.scala:40, took 301.531298 s
17/01/28 20:44:13,695 INFO SparkContext: Starting job: count at GradientDescent.scala:209
17/01/28 20:44:13,696 INFO DAGScheduler: Got job 2 (count at GradientDescent.scala:209) with 59 output partitions
17/01/28 20:44:13,696 INFO DAGScheduler: Final stage: ResultStage 2 (count at GradientDescent.scala:209)
17/01/28 20:44:13,696 INFO DAGScheduler: Parents of final stage: List()
17/01/28 20:44:13,699 INFO DAGScheduler: Missing parents: List()
17/01/28 20:44:13,700 INFO DAGScheduler: Submitting ResultStage 2 (MapPartitionsRDD[8] at map at GeneralizedLinearAlgorithm.scala:297), which has no missing parents
17/01/28 20:44:13,710 INFO MemoryStore: Block broadcast_3 stored as values in memory (estimated size 3.9 KB, free 2.1 GB)
17/01/28 20:44:13,713 INFO MemoryStore: Block broadcast_3_piece0 stored as bytes in memory (estimated size 2.2 KB, free 2.1 GB)
17/01/28 20:44:13,714 INFO BlockManagerInfo: Added broadcast_3_piece0 in memory on 10.1.2.60:32932 (size: 2.2 KB, free: 2.1 GB)
17/01/28 20:44:13,715 INFO SparkContext: Created broadcast 3 from broadcast at DAGScheduler.scala:1012
17/01/28 20:44:13,716 INFO DAGScheduler: Submitting 59 missing tasks from ResultStage 2 (MapPartitionsRDD[8] at map at GeneralizedLinearAlgorithm.scala:297)
17/01/28 20:44:13,717 INFO TaskSchedulerImpl: Adding task set 2.0 with 59 tasks
17/01/28 20:44:13,719 INFO TaskSetManager: Starting task 0.0 in stage 2.0 (TID 60, 10.1.2.97, partition 0, PROCESS_LOCAL, 5372 bytes)
17/01/28 20:44:13,720 INFO TaskSetManager: Starting task 1.0 in stage 2.0 (TID 61, 10.1.2.97, partition 1, PROCESS_LOCAL, 5372 bytes)
17/01/28 20:44:13,721 INFO TaskSetManager: Starting task 2.0 in stage 2.0 (TID 62, 10.1.2.97, partition 2, PROCESS_LOCAL, 5372 bytes)
17/01/28 20:44:13,722 INFO TaskSetManager: Starting task 3.0 in stage 2.0 (TID 63, 10.1.2.97, partition 3, PROCESS_LOCAL, 5372 bytes)
17/01/28 20:44:13,722 INFO CoarseGrainedSchedulerBackend$DriverEndpoint: Launching task 60 on executor id: 0 hostname: 10.1.2.97.
17/01/28 20:44:13,723 INFO CoarseGrainedSchedulerBackend$DriverEndpoint: Launching task 61 on executor id: 0 hostname: 10.1.2.97.
17/01/28 20:44:13,724 INFO CoarseGrainedSchedulerBackend$DriverEndpoint: Launching task 62 on executor id: 0 hostname: 10.1.2.97.
17/01/28 20:44:13,724 INFO CoarseGrainedSchedulerBackend$DriverEndpoint: Launching task 63 on executor id: 0 hostname: 10.1.2.97.
17/01/28 20:44:13,739 INFO BlockManagerInfo: Added broadcast_3_piece0 in memory on 10.1.2.97:46198 (size: 2.2 KB, free: 89.6 MB)
17/01/28 20:44:13,781 INFO TaskSetManager: Starting task 4.0 in stage 2.0 (TID 64, 10.1.2.97, partition 4, PROCESS_LOCAL, 5372 bytes)
17/01/28 20:44:13,781 INFO CoarseGrainedSchedulerBackend$DriverEndpoint: Launching task 64 on executor id: 0 hostname: 10.1.2.97.
17/01/28 20:44:13,782 INFO TaskSetManager: Finished task 2.0 in stage 2.0 (TID 62) in 62 ms on 10.1.2.97 (1/59)
17/01/28 20:44:13,787 INFO TaskSetManager: Starting task 5.0 in stage 2.0 (TID 65, 10.1.2.97, partition 5, PROCESS_LOCAL, 5372 bytes)
17/01/28 20:44:13,787 INFO CoarseGrainedSchedulerBackend$DriverEndpoint: Launching task 65 on executor id: 0 hostname: 10.1.2.97.
17/01/28 20:44:13,787 INFO TaskSetManager: Finished task 1.0 in stage 2.0 (TID 61) in 67 ms on 10.1.2.97 (2/59)
17/01/28 20:44:13,790 INFO TaskSetManager: Starting task 6.0 in stage 2.0 (TID 66, 10.1.2.97, partition 6, PROCESS_LOCAL, 5372 bytes)
17/01/28 20:44:13,791 INFO CoarseGrainedSchedulerBackend$DriverEndpoint: Launching task 66 on executor id: 0 hostname: 10.1.2.97.
17/01/28 20:44:13,791 INFO TaskSetManager: Finished task 0.0 in stage 2.0 (TID 60) in 73 ms on 10.1.2.97 (3/59)
17/01/28 20:44:13,804 INFO TaskSetManager: Starting task 7.0 in stage 2.0 (TID 67, 10.1.2.97, partition 7, PROCESS_LOCAL, 5372 bytes)
17/01/28 20:44:13,804 INFO CoarseGrainedSchedulerBackend$DriverEndpoint: Launching task 67 on executor id: 0 hostname: 10.1.2.97.
17/01/28 20:44:13,804 INFO TaskSetManager: Finished task 3.0 in stage 2.0 (TID 63) in 83 ms on 10.1.2.97 (4/59)
17/01/28 20:44:13,816 INFO TaskSetManager: Starting task 8.0 in stage 2.0 (TID 68, 10.1.2.97, partition 8, PROCESS_LOCAL, 5372 bytes)
17/01/28 20:44:13,816 INFO CoarseGrainedSchedulerBackend$DriverEndpoint: Launching task 68 on executor id: 0 hostname: 10.1.2.97.
17/01/28 20:44:13,817 INFO TaskSetManager: Finished task 4.0 in stage 2.0 (TID 64) in 37 ms on 10.1.2.97 (5/59)
17/01/28 20:44:13,829 INFO TaskSetManager: Starting task 9.0 in stage 2.0 (TID 69, 10.1.2.97, partition 9, PROCESS_LOCAL, 5372 bytes)
17/01/28 20:44:13,829 INFO CoarseGrainedSchedulerBackend$DriverEndpoint: Launching task 69 on executor id: 0 hostname: 10.1.2.97.
17/01/28 20:44:13,830 INFO TaskSetManager: Finished task 7.0 in stage 2.0 (TID 67) in 26 ms on 10.1.2.97 (6/59)
17/01/28 20:44:13,831 INFO TaskSetManager: Finished task 5.0 in stage 2.0 (TID 65) in 44 ms on 10.1.2.97 (7/59)
17/01/28 20:44:13,832 INFO TaskSetManager: Starting task 10.0 in stage 2.0 (TID 70, 10.1.2.97, partition 10, PROCESS_LOCAL, 5372 bytes)
17/01/28 20:44:13,832 INFO CoarseGrainedSchedulerBackend$DriverEndpoint: Launching task 70 on executor id: 0 hostname: 10.1.2.97.
17/01/28 20:44:13,833 INFO TaskSetManager: Starting task 11.0 in stage 2.0 (TID 71, 10.1.2.97, partition 11, PROCESS_LOCAL, 5372 bytes)
17/01/28 20:44:13,833 INFO CoarseGrainedSchedulerBackend$DriverEndpoint: Launching task 71 on executor id: 0 hostname: 10.1.2.97.
17/01/28 20:44:13,834 INFO TaskSetManager: Finished task 6.0 in stage 2.0 (TID 66) in 44 ms on 10.1.2.97 (8/59)
17/01/28 20:44:13,850 INFO TaskSetManager: Starting task 12.0 in stage 2.0 (TID 72, 10.1.2.97, partition 12, PROCESS_LOCAL, 5372 bytes)
17/01/28 20:44:13,851 INFO CoarseGrainedSchedulerBackend$DriverEndpoint: Launching task 72 on executor id: 0 hostname: 10.1.2.97.
17/01/28 20:44:13,851 INFO TaskSetManager: Finished task 8.0 in stage 2.0 (TID 68) in 36 ms on 10.1.2.97 (9/59)
17/01/28 20:44:13,859 INFO TaskSetManager: Starting task 13.0 in stage 2.0 (TID 73, 10.1.2.97, partition 13, PROCESS_LOCAL, 5372 bytes)
17/01/28 20:44:13,859 INFO CoarseGrainedSchedulerBackend$DriverEndpoint: Launching task 73 on executor id: 0 hostname: 10.1.2.97.
17/01/28 20:44:13,860 INFO TaskSetManager: Finished task 10.0 in stage 2.0 (TID 70) in 29 ms on 10.1.2.97 (10/59)
17/01/28 20:44:13,874 INFO TaskSetManager: Starting task 14.0 in stage 2.0 (TID 74, 10.1.2.97, partition 14, PROCESS_LOCAL, 5372 bytes)
17/01/28 20:44:13,875 INFO CoarseGrainedSchedulerBackend$DriverEndpoint: Launching task 74 on executor id: 0 hostname: 10.1.2.97.
17/01/28 20:44:13,875 INFO TaskSetManager: Finished task 11.0 in stage 2.0 (TID 71) in 43 ms on 10.1.2.97 (11/59)
17/01/28 20:44:13,880 INFO TaskSetManager: Starting task 15.0 in stage 2.0 (TID 75, 10.1.2.97, partition 15, PROCESS_LOCAL, 5372 bytes)
17/01/28 20:44:13,880 INFO CoarseGrainedSchedulerBackend$DriverEndpoint: Launching task 75 on executor id: 0 hostname: 10.1.2.97.
17/01/28 20:44:13,880 INFO TaskSetManager: Finished task 9.0 in stage 2.0 (TID 69) in 52 ms on 10.1.2.97 (12/59)
17/01/28 20:44:13,902 INFO TaskSetManager: Starting task 16.0 in stage 2.0 (TID 76, 10.1.2.97, partition 16, PROCESS_LOCAL, 5372 bytes)
17/01/28 20:44:13,902 INFO CoarseGrainedSchedulerBackend$DriverEndpoint: Launching task 76 on executor id: 0 hostname: 10.1.2.97.
17/01/28 20:44:13,903 INFO TaskSetManager: Finished task 13.0 in stage 2.0 (TID 73) in 44 ms on 10.1.2.97 (13/59)
17/01/28 20:44:13,905 INFO TaskSetManager: Starting task 17.0 in stage 2.0 (TID 77, 10.1.2.97, partition 17, PROCESS_LOCAL, 5372 bytes)
17/01/28 20:44:13,905 INFO CoarseGrainedSchedulerBackend$DriverEndpoint: Launching task 77 on executor id: 0 hostname: 10.1.2.97.
17/01/28 20:44:13,905 INFO TaskSetManager: Finished task 12.0 in stage 2.0 (TID 72) in 55 ms on 10.1.2.97 (14/59)
17/01/28 20:44:13,907 INFO TaskSetManager: Starting task 18.0 in stage 2.0 (TID 78, 10.1.2.97, partition 18, PROCESS_LOCAL, 5372 bytes)
17/01/28 20:44:13,907 INFO CoarseGrainedSchedulerBackend$DriverEndpoint: Launching task 78 on executor id: 0 hostname: 10.1.2.97.
17/01/28 20:44:13,908 INFO TaskSetManager: Finished task 14.0 in stage 2.0 (TID 74) in 34 ms on 10.1.2.97 (15/59)
17/01/28 20:44:13,918 INFO TaskSetManager: Starting task 19.0 in stage 2.0 (TID 79, 10.1.2.97, partition 19, PROCESS_LOCAL, 5372 bytes)
17/01/28 20:44:13,918 INFO CoarseGrainedSchedulerBackend$DriverEndpoint: Launching task 79 on executor id: 0 hostname: 10.1.2.97.
17/01/28 20:44:13,919 INFO TaskSetManager: Finished task 15.0 in stage 2.0 (TID 75) in 40 ms on 10.1.2.97 (16/59)
17/01/28 20:44:13,934 INFO TaskSetManager: Starting task 20.0 in stage 2.0 (TID 80, 10.1.2.97, partition 20, PROCESS_LOCAL, 5372 bytes)
17/01/28 20:44:13,934 INFO CoarseGrainedSchedulerBackend$DriverEndpoint: Launching task 80 on executor id: 0 hostname: 10.1.2.97.
17/01/28 20:44:13,935 INFO TaskSetManager: Finished task 16.0 in stage 2.0 (TID 76) in 34 ms on 10.1.2.97 (17/59)
17/01/28 20:44:13,940 INFO TaskSetManager: Starting task 21.0 in stage 2.0 (TID 81, 10.1.2.97, partition 21, PROCESS_LOCAL, 5372 bytes)
17/01/28 20:44:13,940 INFO CoarseGrainedSchedulerBackend$DriverEndpoint: Launching task 81 on executor id: 0 hostname: 10.1.2.97.
17/01/28 20:44:13,941 INFO TaskSetManager: Finished task 17.0 in stage 2.0 (TID 77) in 36 ms on 10.1.2.97 (18/59)
17/01/28 20:44:13,943 INFO TaskSetManager: Starting task 22.0 in stage 2.0 (TID 82, 10.1.2.97, partition 22, PROCESS_LOCAL, 5372 bytes)
17/01/28 20:44:13,944 INFO CoarseGrainedSchedulerBackend$DriverEndpoint: Launching task 82 on executor id: 0 hostname: 10.1.2.97.
17/01/28 20:44:13,944 INFO TaskSetManager: Finished task 18.0 in stage 2.0 (TID 78) in 38 ms on 10.1.2.97 (19/59)
17/01/28 20:44:13,957 INFO TaskSetManager: Starting task 23.0 in stage 2.0 (TID 83, 10.1.2.97, partition 23, PROCESS_LOCAL, 5372 bytes)
17/01/28 20:44:13,957 INFO CoarseGrainedSchedulerBackend$DriverEndpoint: Launching task 83 on executor id: 0 hostname: 10.1.2.97.
17/01/28 20:44:13,957 INFO TaskSetManager: Finished task 19.0 in stage 2.0 (TID 79) in 40 ms on 10.1.2.97 (20/59)
17/01/28 20:44:13,962 INFO TaskSetManager: Starting task 24.0 in stage 2.0 (TID 84, 10.1.2.97, partition 24, PROCESS_LOCAL, 5372 bytes)
17/01/28 20:44:13,962 INFO CoarseGrainedSchedulerBackend$DriverEndpoint: Launching task 84 on executor id: 0 hostname: 10.1.2.97.
17/01/28 20:44:13,962 INFO TaskSetManager: Finished task 20.0 in stage 2.0 (TID 80) in 29 ms on 10.1.2.97 (21/59)
17/01/28 20:44:13,975 INFO TaskSetManager: Starting task 25.0 in stage 2.0 (TID 85, 10.1.2.97, partition 25, PROCESS_LOCAL, 5372 bytes)
17/01/28 20:44:13,975 INFO CoarseGrainedSchedulerBackend$DriverEndpoint: Launching task 85 on executor id: 0 hostname: 10.1.2.97.
17/01/28 20:44:13,975 INFO TaskSetManager: Finished task 21.0 in stage 2.0 (TID 81) in 36 ms on 10.1.2.97 (22/59)
17/01/28 20:44:13,976 INFO TaskSetManager: Finished task 22.0 in stage 2.0 (TID 82) in 33 ms on 10.1.2.97 (23/59)
17/01/28 20:44:13,977 INFO TaskSetManager: Starting task 27.0 in stage 2.0 (TID 86, 10.1.2.97, partition 27, PROCESS_LOCAL, 5372 bytes)
17/01/28 20:44:13,978 INFO CoarseGrainedSchedulerBackend$DriverEndpoint: Launching task 86 on executor id: 0 hostname: 10.1.2.97.
17/01/28 20:44:13,993 INFO TaskSetManager: Starting task 28.0 in stage 2.0 (TID 87, 10.1.2.97, partition 28, PROCESS_LOCAL, 5372 bytes)
17/01/28 20:44:13,993 INFO CoarseGrainedSchedulerBackend$DriverEndpoint: Launching task 87 on executor id: 0 hostname: 10.1.2.97.
17/01/28 20:44:13,993 INFO TaskSetManager: Finished task 23.0 in stage 2.0 (TID 83) in 37 ms on 10.1.2.97 (24/59)
17/01/28 20:44:13,994 INFO TaskSetManager: Starting task 58.0 in stage 2.0 (TID 88, 10.1.2.97, partition 58, PROCESS_LOCAL, 5372 bytes)
17/01/28 20:44:13,995 INFO CoarseGrainedSchedulerBackend$DriverEndpoint: Launching task 88 on executor id: 0 hostname: 10.1.2.97.
17/01/28 20:44:13,995 INFO TaskSetManager: Finished task 24.0 in stage 2.0 (TID 84) in 34 ms on 10.1.2.97 (25/59)
17/01/28 20:44:14,004 INFO TaskSetManager: Finished task 25.0 in stage 2.0 (TID 85) in 30 ms on 10.1.2.97 (26/59)
17/01/28 20:44:14,016 INFO TaskSetManager: Finished task 27.0 in stage 2.0 (TID 86) in 38 ms on 10.1.2.97 (27/59)
17/01/28 20:44:14,022 INFO TaskSetManager: Finished task 28.0 in stage 2.0 (TID 87) in 30 ms on 10.1.2.97 (28/59)
17/01/28 20:44:14,024 INFO TaskSetManager: Finished task 58.0 in stage 2.0 (TID 88) in 30 ms on 10.1.2.97 (29/59)
17/01/28 20:44:17,099 INFO TaskSetManager: Starting task 26.0 in stage 2.0 (TID 89, 10.1.2.97, partition 26, ANY, 5372 bytes)
17/01/28 20:44:17,100 INFO TaskSetManager: Starting task 29.0 in stage 2.0 (TID 90, 10.1.2.97, partition 29, ANY, 5372 bytes)
17/01/28 20:44:17,100 INFO TaskSetManager: Starting task 30.0 in stage 2.0 (TID 91, 10.1.2.97, partition 30, ANY, 5372 bytes)
17/01/28 20:44:17,101 INFO TaskSetManager: Starting task 31.0 in stage 2.0 (TID 92, 10.1.2.97, partition 31, ANY, 5372 bytes)
17/01/28 20:44:17,101 INFO CoarseGrainedSchedulerBackend$DriverEndpoint: Launching task 89 on executor id: 0 hostname: 10.1.2.97.
17/01/28 20:44:17,101 INFO CoarseGrainedSchedulerBackend$DriverEndpoint: Launching task 90 on executor id: 0 hostname: 10.1.2.97.
17/01/28 20:44:17,102 INFO CoarseGrainedSchedulerBackend$DriverEndpoint: Launching task 91 on executor id: 0 hostname: 10.1.2.97.
17/01/28 20:44:17,102 INFO CoarseGrainedSchedulerBackend$DriverEndpoint: Launching task 92 on executor id: 0 hostname: 10.1.2.97.
17/01/28 20:44:35,199 INFO TaskSetManager: Starting task 32.0 in stage 2.0 (TID 93, 10.1.2.97, partition 32, ANY, 5372 bytes)
17/01/28 20:44:35,199 INFO CoarseGrainedSchedulerBackend$DriverEndpoint: Launching task 93 on executor id: 0 hostname: 10.1.2.97.
17/01/28 20:44:35,200 INFO TaskSetManager: Finished task 31.0 in stage 2.0 (TID 92) in 18099 ms on 10.1.2.97 (30/59)
17/01/28 20:44:36,099 INFO TaskSetManager: Starting task 33.0 in stage 2.0 (TID 94, 10.1.2.97, partition 33, ANY, 5372 bytes)
17/01/28 20:44:36,099 INFO CoarseGrainedSchedulerBackend$DriverEndpoint: Launching task 94 on executor id: 0 hostname: 10.1.2.97.
17/01/28 20:44:36,100 INFO TaskSetManager: Finished task 26.0 in stage 2.0 (TID 89) in 19002 ms on 10.1.2.97 (31/59)
17/01/28 20:44:38,666 INFO TaskSetManager: Starting task 34.0 in stage 2.0 (TID 95, 10.1.2.97, partition 34, ANY, 5372 bytes)
17/01/28 20:44:38,666 INFO CoarseGrainedSchedulerBackend$DriverEndpoint: Launching task 95 on executor id: 0 hostname: 10.1.2.97.
17/01/28 20:44:38,667 INFO TaskSetManager: Finished task 30.0 in stage 2.0 (TID 91) in 21566 ms on 10.1.2.97 (32/59)
17/01/28 20:44:44,051 INFO TaskSetManager: Starting task 35.0 in stage 2.0 (TID 96, 10.1.2.97, partition 35, ANY, 5372 bytes)
17/01/28 20:44:44,051 INFO CoarseGrainedSchedulerBackend$DriverEndpoint: Launching task 96 on executor id: 0 hostname: 10.1.2.97.
17/01/28 20:44:44,052 INFO TaskSetManager: Finished task 29.0 in stage 2.0 (TID 90) in 26953 ms on 10.1.2.97 (33/59)
17/01/28 20:44:53,799 INFO TaskSetManager: Starting task 36.0 in stage 2.0 (TID 97, 10.1.2.97, partition 36, ANY, 5372 bytes)
17/01/28 20:44:53,799 INFO CoarseGrainedSchedulerBackend$DriverEndpoint: Launching task 97 on executor id: 0 hostname: 10.1.2.97.
17/01/28 20:44:53,800 INFO TaskSetManager: Finished task 32.0 in stage 2.0 (TID 93) in 18602 ms on 10.1.2.97 (34/59)
17/01/28 20:44:55,605 INFO TaskSetManager: Starting task 37.0 in stage 2.0 (TID 98, 10.1.2.97, partition 37, ANY, 5372 bytes)
17/01/28 20:44:55,605 INFO CoarseGrainedSchedulerBackend$DriverEndpoint: Launching task 98 on executor id: 0 hostname: 10.1.2.97.
17/01/28 20:44:55,605 INFO TaskSetManager: Finished task 33.0 in stage 2.0 (TID 94) in 19507 ms on 10.1.2.97 (35/59)
17/01/28 20:45:01,917 INFO TaskSetManager: Starting task 38.0 in stage 2.0 (TID 99, 10.1.2.97, partition 38, ANY, 5372 bytes)
17/01/28 20:45:01,917 INFO CoarseGrainedSchedulerBackend$DriverEndpoint: Launching task 99 on executor id: 0 hostname: 10.1.2.97.
17/01/28 20:45:01,918 INFO TaskSetManager: Finished task 34.0 in stage 2.0 (TID 95) in 23253 ms on 10.1.2.97 (36/59)
17/01/28 20:45:06,993 INFO TaskSetManager: Starting task 39.0 in stage 2.0 (TID 100, 10.1.2.97, partition 39, ANY, 5372 bytes)
17/01/28 20:45:06,993 INFO CoarseGrainedSchedulerBackend$DriverEndpoint: Launching task 100 on executor id: 0 hostname: 10.1.2.97.
17/01/28 20:45:06,994 INFO TaskSetManager: Finished task 35.0 in stage 2.0 (TID 96) in 22944 ms on 10.1.2.97 (37/59)
17/01/28 20:45:14,927 INFO TaskSetManager: Starting task 40.0 in stage 2.0 (TID 101, 10.1.2.97, partition 40, ANY, 5372 bytes)
17/01/28 20:45:14,927 INFO CoarseGrainedSchedulerBackend$DriverEndpoint: Launching task 101 on executor id: 0 hostname: 10.1.2.97.
17/01/28 20:45:14,928 INFO TaskSetManager: Finished task 37.0 in stage 2.0 (TID 98) in 19324 ms on 10.1.2.97 (38/59)
17/01/28 20:45:15,909 INFO TaskSetManager: Starting task 41.0 in stage 2.0 (TID 102, 10.1.2.97, partition 41, ANY, 5372 bytes)
17/01/28 20:45:15,909 INFO CoarseGrainedSchedulerBackend$DriverEndpoint: Launching task 102 on executor id: 0 hostname: 10.1.2.97.
17/01/28 20:45:15,909 INFO TaskSetManager: Finished task 36.0 in stage 2.0 (TID 97) in 22111 ms on 10.1.2.97 (39/59)
17/01/28 20:45:20,781 INFO TaskSetManager: Starting task 42.0 in stage 2.0 (TID 103, 10.1.2.97, partition 42, ANY, 5372 bytes)
17/01/28 20:45:20,781 INFO CoarseGrainedSchedulerBackend$DriverEndpoint: Launching task 103 on executor id: 0 hostname: 10.1.2.97.
17/01/28 20:45:20,781 INFO TaskSetManager: Finished task 38.0 in stage 2.0 (TID 99) in 18865 ms on 10.1.2.97 (40/59)
17/01/28 20:45:27,162 INFO TaskSetManager: Starting task 43.0 in stage 2.0 (TID 104, 10.1.2.97, partition 43, ANY, 5372 bytes)
17/01/28 20:45:27,162 INFO CoarseGrainedSchedulerBackend$DriverEndpoint: Launching task 104 on executor id: 0 hostname: 10.1.2.97.
17/01/28 20:45:27,163 INFO TaskSetManager: Finished task 39.0 in stage 2.0 (TID 100) in 20171 ms on 10.1.2.97 (41/59)
17/01/28 20:45:33,601 INFO TaskSetManager: Starting task 44.0 in stage 2.0 (TID 105, 10.1.2.97, partition 44, ANY, 5372 bytes)
17/01/28 20:45:33,601 INFO CoarseGrainedSchedulerBackend$DriverEndpoint: Launching task 105 on executor id: 0 hostname: 10.1.2.97.
17/01/28 20:45:33,602 INFO TaskSetManager: Finished task 40.0 in stage 2.0 (TID 101) in 18675 ms on 10.1.2.97 (42/59)
17/01/28 20:45:37,987 INFO TaskSetManager: Starting task 45.0 in stage 2.0 (TID 106, 10.1.2.97, partition 45, ANY, 5372 bytes)
17/01/28 20:45:37,988 INFO CoarseGrainedSchedulerBackend$DriverEndpoint: Launching task 106 on executor id: 0 hostname: 10.1.2.97.
17/01/28 20:45:37,988 INFO TaskSetManager: Finished task 41.0 in stage 2.0 (TID 102) in 22080 ms on 10.1.2.97 (43/59)
17/01/28 20:45:39,702 INFO TaskSetManager: Starting task 46.0 in stage 2.0 (TID 107, 10.1.2.97, partition 46, ANY, 5372 bytes)
17/01/28 20:45:39,703 INFO CoarseGrainedSchedulerBackend$DriverEndpoint: Launching task 107 on executor id: 0 hostname: 10.1.2.97.
17/01/28 20:45:39,703 INFO TaskSetManager: Finished task 42.0 in stage 2.0 (TID 103) in 18923 ms on 10.1.2.97 (44/59)
17/01/28 20:45:51,140 INFO TaskSetManager: Starting task 47.0 in stage 2.0 (TID 108, 10.1.2.97, partition 47, ANY, 5372 bytes)
17/01/28 20:45:51,140 INFO CoarseGrainedSchedulerBackend$DriverEndpoint: Launching task 108 on executor id: 0 hostname: 10.1.2.97.
17/01/28 20:45:51,141 INFO TaskSetManager: Finished task 43.0 in stage 2.0 (TID 104) in 23979 ms on 10.1.2.97 (45/59)
17/01/28 20:45:52,124 INFO TaskSetManager: Starting task 48.0 in stage 2.0 (TID 109, 10.1.2.97, partition 48, ANY, 5372 bytes)
17/01/28 20:45:52,124 INFO CoarseGrainedSchedulerBackend$DriverEndpoint: Launching task 109 on executor id: 0 hostname: 10.1.2.97.
17/01/28 20:45:52,125 INFO TaskSetManager: Finished task 44.0 in stage 2.0 (TID 105) in 18525 ms on 10.1.2.97 (46/59)
17/01/28 20:45:59,790 INFO TaskSetManager: Starting task 49.0 in stage 2.0 (TID 110, 10.1.2.97, partition 49, ANY, 5372 bytes)
17/01/28 20:45:59,790 INFO CoarseGrainedSchedulerBackend$DriverEndpoint: Launching task 110 on executor id: 0 hostname: 10.1.2.97.
17/01/28 20:45:59,791 INFO TaskSetManager: Finished task 45.0 in stage 2.0 (TID 106) in 21804 ms on 10.1.2.97 (47/59)
17/01/28 20:46:01,007 INFO TaskSetManager: Starting task 50.0 in stage 2.0 (TID 111, 10.1.2.97, partition 50, ANY, 5372 bytes)
17/01/28 20:46:01,008 INFO CoarseGrainedSchedulerBackend$DriverEndpoint: Launching task 111 on executor id: 0 hostname: 10.1.2.97.
17/01/28 20:46:01,008 INFO TaskSetManager: Finished task 46.0 in stage 2.0 (TID 107) in 21306 ms on 10.1.2.97 (48/59)
17/01/28 20:46:12,228 INFO TaskSetManager: Starting task 51.0 in stage 2.0 (TID 112, 10.1.2.97, partition 51, ANY, 5372 bytes)
17/01/28 20:46:12,228 INFO CoarseGrainedSchedulerBackend$DriverEndpoint: Launching task 112 on executor id: 0 hostname: 10.1.2.97.
17/01/28 20:46:12,229 INFO TaskSetManager: Finished task 47.0 in stage 2.0 (TID 108) in 21089 ms on 10.1.2.97 (49/59)
17/01/28 20:46:14,516 INFO TaskSetManager: Starting task 52.0 in stage 2.0 (TID 113, 10.1.2.97, partition 52, ANY, 5372 bytes)
17/01/28 20:46:14,516 INFO CoarseGrainedSchedulerBackend$DriverEndpoint: Launching task 113 on executor id: 0 hostname: 10.1.2.97.
17/01/28 20:46:14,517 INFO TaskSetManager: Finished task 48.0 in stage 2.0 (TID 109) in 22392 ms on 10.1.2.97 (50/59)
17/01/28 20:46:21,640 INFO TaskSetManager: Starting task 53.0 in stage 2.0 (TID 114, 10.1.2.97, partition 53, ANY, 5372 bytes)
17/01/28 20:46:21,640 INFO CoarseGrainedSchedulerBackend$DriverEndpoint: Launching task 114 on executor id: 0 hostname: 10.1.2.97.
17/01/28 20:46:21,641 INFO TaskSetManager: Finished task 50.0 in stage 2.0 (TID 111) in 20634 ms on 10.1.2.97 (51/59)
17/01/28 20:46:21,747 INFO TaskSetManager: Starting task 54.0 in stage 2.0 (TID 115, 10.1.2.97, partition 54, ANY, 5372 bytes)
17/01/28 20:46:21,748 INFO CoarseGrainedSchedulerBackend$DriverEndpoint: Launching task 115 on executor id: 0 hostname: 10.1.2.97.
17/01/28 20:46:21,749 INFO TaskSetManager: Finished task 49.0 in stage 2.0 (TID 110) in 21959 ms on 10.1.2.97 (52/59)
17/01/28 20:46:32,063 INFO TaskSetManager: Starting task 55.0 in stage 2.0 (TID 116, 10.1.2.97, partition 55, ANY, 5372 bytes)
17/01/28 20:46:32,063 INFO CoarseGrainedSchedulerBackend$DriverEndpoint: Launching task 116 on executor id: 0 hostname: 10.1.2.97.
17/01/28 20:46:32,064 INFO TaskSetManager: Finished task 51.0 in stage 2.0 (TID 112) in 19836 ms on 10.1.2.97 (53/59)
17/01/28 20:46:36,050 INFO TaskSetManager: Starting task 56.0 in stage 2.0 (TID 117, 10.1.2.97, partition 56, ANY, 5372 bytes)
17/01/28 20:46:36,050 INFO CoarseGrainedSchedulerBackend$DriverEndpoint: Launching task 117 on executor id: 0 hostname: 10.1.2.97.
17/01/28 20:46:36,051 INFO TaskSetManager: Finished task 52.0 in stage 2.0 (TID 113) in 21535 ms on 10.1.2.97 (54/59)
17/01/28 20:46:38,987 INFO TaskSetManager: Starting task 57.0 in stage 2.0 (TID 118, 10.1.2.97, partition 57, ANY, 5372 bytes)
17/01/28 20:46:38,987 INFO CoarseGrainedSchedulerBackend$DriverEndpoint: Launching task 118 on executor id: 0 hostname: 10.1.2.97.
17/01/28 20:46:38,987 INFO TaskSetManager: Finished task 54.0 in stage 2.0 (TID 115) in 17240 ms on 10.1.2.97 (55/59)
17/01/28 20:46:41,178 INFO TaskSetManager: Finished task 53.0 in stage 2.0 (TID 114) in 19538 ms on 10.1.2.97 (56/59)
17/01/28 20:46:47,232 INFO TaskSetManager: Finished task 55.0 in stage 2.0 (TID 116) in 15170 ms on 10.1.2.97 (57/59)
17/01/28 20:46:49,331 INFO TaskSetManager: Finished task 56.0 in stage 2.0 (TID 117) in 13282 ms on 10.1.2.97 (58/59)
17/01/28 20:46:50,382 INFO TaskSetManager: Finished task 57.0 in stage 2.0 (TID 118) in 11396 ms on 10.1.2.97 (59/59)
17/01/28 20:46:50,382 INFO TaskSchedulerImpl: Removed TaskSet 2.0, whose tasks have all completed, from pool 
17/01/28 20:46:50,383 INFO DAGScheduler: ResultStage 2 (count at GradientDescent.scala:209) finished in 156.657 s
17/01/28 20:46:50,383 INFO DAGScheduler: Job 2 finished: count at GradientDescent.scala:209, took 156.688368 s
17/01/28 20:46:50,621 WARN BLAS: Failed to load implementation from: com.github.fommil.netlib.NativeSystemBLAS
17/01/28 20:46:50,621 WARN BLAS: Failed to load implementation from: com.github.fommil.netlib.NativeRefBLAS
17/01/28 20:46:50,645 INFO MemoryStore: Block broadcast_4 stored as values in memory (estimated size 280.0 B, free 2.1 GB)
17/01/28 20:46:50,650 INFO MemoryStore: Block broadcast_4_piece0 stored as bytes in memory (estimated size 153.0 B, free 2.1 GB)
17/01/28 20:46:50,651 INFO BlockManagerInfo: Added broadcast_4_piece0 in memory on 10.1.2.60:32932 (size: 153.0 B, free: 2.1 GB)
17/01/28 20:46:50,652 INFO SparkContext: Created broadcast 4 from broadcast at GradientDescent.scala:235
17/01/28 20:46:50,704 INFO SparkContext: Starting job: treeAggregate at GradientDescent.scala:239
17/01/28 20:46:50,710 INFO DAGScheduler: Registering RDD 11 (treeAggregate at GradientDescent.scala:239)
17/01/28 20:46:50,711 INFO DAGScheduler: Got job 3 (treeAggregate at GradientDescent.scala:239) with 7 output partitions
17/01/28 20:46:50,711 INFO DAGScheduler: Final stage: ResultStage 4 (treeAggregate at GradientDescent.scala:239)
17/01/28 20:46:50,711 INFO DAGScheduler: Parents of final stage: List(ShuffleMapStage 3)
17/01/28 20:46:50,711 INFO DAGScheduler: Missing parents: List(ShuffleMapStage 3)
17/01/28 20:46:50,716 INFO DAGScheduler: Submitting ShuffleMapStage 3 (MapPartitionsRDD[11] at treeAggregate at GradientDescent.scala:239), which has no missing parents
17/01/28 20:46:50,737 INFO MemoryStore: Block broadcast_5 stored as values in memory (estimated size 7.2 KB, free 2.1 GB)
17/01/28 20:46:50,741 INFO MemoryStore: Block broadcast_5_piece0 stored as bytes in memory (estimated size 3.7 KB, free 2.1 GB)
17/01/28 20:46:50,742 INFO BlockManagerInfo: Added broadcast_5_piece0 in memory on 10.1.2.60:32932 (size: 3.7 KB, free: 2.1 GB)
17/01/28 20:46:50,743 INFO SparkContext: Created broadcast 5 from broadcast at DAGScheduler.scala:1012
17/01/28 20:46:50,745 INFO DAGScheduler: Submitting 59 missing tasks from ShuffleMapStage 3 (MapPartitionsRDD[11] at treeAggregate at GradientDescent.scala:239)
17/01/28 20:46:50,746 INFO TaskSchedulerImpl: Adding task set 3.0 with 59 tasks
17/01/28 20:46:50,749 INFO TaskSetManager: Starting task 0.0 in stage 3.0 (TID 119, 10.1.2.97, partition 0, PROCESS_LOCAL, 5561 bytes)
17/01/28 20:46:50,750 INFO TaskSetManager: Starting task 1.0 in stage 3.0 (TID 120, 10.1.2.97, partition 1, PROCESS_LOCAL, 5561 bytes)
17/01/28 20:46:50,751 INFO TaskSetManager: Starting task 2.0 in stage 3.0 (TID 121, 10.1.2.97, partition 2, PROCESS_LOCAL, 5561 bytes)
17/01/28 20:46:50,751 INFO TaskSetManager: Starting task 3.0 in stage 3.0 (TID 122, 10.1.2.97, partition 3, PROCESS_LOCAL, 5561 bytes)
17/01/28 20:46:50,751 INFO CoarseGrainedSchedulerBackend$DriverEndpoint: Launching task 119 on executor id: 0 hostname: 10.1.2.97.
17/01/28 20:46:50,752 INFO CoarseGrainedSchedulerBackend$DriverEndpoint: Launching task 120 on executor id: 0 hostname: 10.1.2.97.
17/01/28 20:46:50,753 INFO CoarseGrainedSchedulerBackend$DriverEndpoint: Launching task 121 on executor id: 0 hostname: 10.1.2.97.
17/01/28 20:46:50,753 INFO CoarseGrainedSchedulerBackend$DriverEndpoint: Launching task 122 on executor id: 0 hostname: 10.1.2.97.
17/01/28 20:46:50,772 INFO BlockManagerInfo: Added broadcast_5_piece0 in memory on 10.1.2.97:46198 (size: 3.7 KB, free: 89.6 MB)
17/01/28 20:46:51,221 INFO BlockManagerInfo: Added broadcast_4_piece0 in memory on 10.1.2.97:46198 (size: 153.0 B, free: 89.6 MB)
17/01/28 20:46:51,392 INFO TaskSetManager: Starting task 4.0 in stage 3.0 (TID 123, 10.1.2.97, partition 4, PROCESS_LOCAL, 5561 bytes)
17/01/28 20:46:51,393 INFO CoarseGrainedSchedulerBackend$DriverEndpoint: Launching task 123 on executor id: 0 hostname: 10.1.2.97.
17/01/28 20:46:51,395 INFO TaskSetManager: Finished task 1.0 in stage 3.0 (TID 120) in 646 ms on 10.1.2.97 (1/59)
17/01/28 20:46:51,397 INFO TaskSetManager: Starting task 5.0 in stage 3.0 (TID 124, 10.1.2.97, partition 5, PROCESS_LOCAL, 5561 bytes)
17/01/28 20:46:51,397 INFO CoarseGrainedSchedulerBackend$DriverEndpoint: Launching task 124 on executor id: 0 hostname: 10.1.2.97.
17/01/28 20:46:51,398 INFO TaskSetManager: Finished task 2.0 in stage 3.0 (TID 121) in 648 ms on 10.1.2.97 (2/59)
17/01/28 20:46:51,401 INFO TaskSetManager: Starting task 6.0 in stage 3.0 (TID 125, 10.1.2.97, partition 6, PROCESS_LOCAL, 5561 bytes)
17/01/28 20:46:51,401 INFO CoarseGrainedSchedulerBackend$DriverEndpoint: Launching task 125 on executor id: 0 hostname: 10.1.2.97.
17/01/28 20:46:51,402 INFO TaskSetManager: Finished task 0.0 in stage 3.0 (TID 119) in 654 ms on 10.1.2.97 (3/59)
17/01/28 20:46:51,403 INFO TaskSetManager: Starting task 7.0 in stage 3.0 (TID 126, 10.1.2.97, partition 7, PROCESS_LOCAL, 5561 bytes)
17/01/28 20:46:51,404 INFO CoarseGrainedSchedulerBackend$DriverEndpoint: Launching task 126 on executor id: 0 hostname: 10.1.2.97.
17/01/28 20:46:51,404 INFO TaskSetManager: Finished task 3.0 in stage 3.0 (TID 122) in 653 ms on 10.1.2.97 (4/59)
17/01/28 20:46:51,484 INFO TaskSetManager: Starting task 8.0 in stage 3.0 (TID 127, 10.1.2.97, partition 8, PROCESS_LOCAL, 5561 bytes)
17/01/28 20:46:51,484 INFO CoarseGrainedSchedulerBackend$DriverEndpoint: Launching task 127 on executor id: 0 hostname: 10.1.2.97.
17/01/28 20:46:51,485 INFO TaskSetManager: Finished task 5.0 in stage 3.0 (TID 124) in 89 ms on 10.1.2.97 (5/59)
17/01/28 20:46:51,488 INFO TaskSetManager: Starting task 9.0 in stage 3.0 (TID 128, 10.1.2.97, partition 9, PROCESS_LOCAL, 5561 bytes)
17/01/28 20:46:51,488 INFO CoarseGrainedSchedulerBackend$DriverEndpoint: Launching task 128 on executor id: 0 hostname: 10.1.2.97.
17/01/28 20:46:51,489 INFO TaskSetManager: Starting task 10.0 in stage 3.0 (TID 129, 10.1.2.97, partition 10, PROCESS_LOCAL, 5561 bytes)
17/01/28 20:46:51,489 INFO CoarseGrainedSchedulerBackend$DriverEndpoint: Launching task 129 on executor id: 0 hostname: 10.1.2.97.
17/01/28 20:46:51,489 INFO TaskSetManager: Finished task 7.0 in stage 3.0 (TID 126) in 86 ms on 10.1.2.97 (6/59)
17/01/28 20:46:51,490 INFO TaskSetManager: Finished task 4.0 in stage 3.0 (TID 123) in 99 ms on 10.1.2.97 (7/59)
17/01/28 20:46:51,511 INFO TaskSetManager: Starting task 11.0 in stage 3.0 (TID 130, 10.1.2.97, partition 11, PROCESS_LOCAL, 5561 bytes)
17/01/28 20:46:51,512 INFO CoarseGrainedSchedulerBackend$DriverEndpoint: Launching task 130 on executor id: 0 hostname: 10.1.2.97.
17/01/28 20:46:51,512 INFO TaskSetManager: Finished task 6.0 in stage 3.0 (TID 125) in 112 ms on 10.1.2.97 (8/59)
17/01/28 20:46:51,567 INFO TaskSetManager: Starting task 12.0 in stage 3.0 (TID 131, 10.1.2.97, partition 12, PROCESS_LOCAL, 5561 bytes)
17/01/28 20:46:51,567 INFO CoarseGrainedSchedulerBackend$DriverEndpoint: Launching task 131 on executor id: 0 hostname: 10.1.2.97.
17/01/28 20:46:51,568 INFO TaskSetManager: Finished task 8.0 in stage 3.0 (TID 127) in 85 ms on 10.1.2.97 (9/59)
17/01/28 20:46:51,574 INFO TaskSetManager: Starting task 13.0 in stage 3.0 (TID 132, 10.1.2.97, partition 13, PROCESS_LOCAL, 5561 bytes)
17/01/28 20:46:51,575 INFO CoarseGrainedSchedulerBackend$DriverEndpoint: Launching task 132 on executor id: 0 hostname: 10.1.2.97.
17/01/28 20:46:51,575 INFO TaskSetManager: Finished task 10.0 in stage 3.0 (TID 129) in 87 ms on 10.1.2.97 (10/59)
17/01/28 20:46:51,577 INFO TaskSetManager: Starting task 14.0 in stage 3.0 (TID 133, 10.1.2.97, partition 14, PROCESS_LOCAL, 5561 bytes)
17/01/28 20:46:51,577 INFO CoarseGrainedSchedulerBackend$DriverEndpoint: Launching task 133 on executor id: 0 hostname: 10.1.2.97.
17/01/28 20:46:51,578 INFO TaskSetManager: Finished task 9.0 in stage 3.0 (TID 128) in 91 ms on 10.1.2.97 (11/59)
17/01/28 20:46:51,615 INFO TaskSetManager: Starting task 15.0 in stage 3.0 (TID 134, 10.1.2.97, partition 15, PROCESS_LOCAL, 5561 bytes)
17/01/28 20:46:51,616 INFO CoarseGrainedSchedulerBackend$DriverEndpoint: Launching task 134 on executor id: 0 hostname: 10.1.2.97.
17/01/28 20:46:51,616 INFO TaskSetManager: Finished task 11.0 in stage 3.0 (TID 130) in 105 ms on 10.1.2.97 (12/59)
17/01/28 20:46:51,650 INFO TaskSetManager: Starting task 16.0 in stage 3.0 (TID 135, 10.1.2.97, partition 16, PROCESS_LOCAL, 5561 bytes)
17/01/28 20:46:51,650 INFO CoarseGrainedSchedulerBackend$DriverEndpoint: Launching task 135 on executor id: 0 hostname: 10.1.2.97.
17/01/28 20:46:51,650 INFO TaskSetManager: Finished task 12.0 in stage 3.0 (TID 131) in 84 ms on 10.1.2.97 (13/59)
17/01/28 20:46:51,651 INFO TaskSetManager: Starting task 17.0 in stage 3.0 (TID 136, 10.1.2.97, partition 17, PROCESS_LOCAL, 5561 bytes)
17/01/28 20:46:51,651 INFO CoarseGrainedSchedulerBackend$DriverEndpoint: Launching task 136 on executor id: 0 hostname: 10.1.2.97.
17/01/28 20:46:51,652 INFO TaskSetManager: Finished task 13.0 in stage 3.0 (TID 132) in 78 ms on 10.1.2.97 (14/59)
17/01/28 20:46:51,684 INFO TaskSetManager: Starting task 18.0 in stage 3.0 (TID 137, 10.1.2.97, partition 18, PROCESS_LOCAL, 5561 bytes)
17/01/28 20:46:51,684 INFO CoarseGrainedSchedulerBackend$DriverEndpoint: Launching task 137 on executor id: 0 hostname: 10.1.2.97.
17/01/28 20:46:51,685 INFO TaskSetManager: Finished task 14.0 in stage 3.0 (TID 133) in 108 ms on 10.1.2.97 (15/59)
17/01/28 20:46:51,693 INFO TaskSetManager: Starting task 19.0 in stage 3.0 (TID 138, 10.1.2.97, partition 19, PROCESS_LOCAL, 5561 bytes)
17/01/28 20:46:51,694 INFO CoarseGrainedSchedulerBackend$DriverEndpoint: Launching task 138 on executor id: 0 hostname: 10.1.2.97.
17/01/28 20:46:51,694 INFO TaskSetManager: Finished task 15.0 in stage 3.0 (TID 134) in 79 ms on 10.1.2.97 (16/59)
17/01/28 20:46:51,728 INFO TaskSetManager: Starting task 20.0 in stage 3.0 (TID 139, 10.1.2.97, partition 20, PROCESS_LOCAL, 5561 bytes)
17/01/28 20:46:51,729 INFO CoarseGrainedSchedulerBackend$DriverEndpoint: Launching task 139 on executor id: 0 hostname: 10.1.2.97.
17/01/28 20:46:51,730 INFO TaskSetManager: Finished task 17.0 in stage 3.0 (TID 136) in 79 ms on 10.1.2.97 (17/59)
17/01/28 20:46:51,736 INFO TaskSetManager: Starting task 21.0 in stage 3.0 (TID 140, 10.1.2.97, partition 21, PROCESS_LOCAL, 5561 bytes)
17/01/28 20:46:51,736 INFO CoarseGrainedSchedulerBackend$DriverEndpoint: Launching task 140 on executor id: 0 hostname: 10.1.2.97.
17/01/28 20:46:51,737 INFO TaskSetManager: Finished task 16.0 in stage 3.0 (TID 135) in 87 ms on 10.1.2.97 (18/59)
17/01/28 20:46:51,767 INFO TaskSetManager: Starting task 22.0 in stage 3.0 (TID 141, 10.1.2.97, partition 22, PROCESS_LOCAL, 5561 bytes)
17/01/28 20:46:51,767 INFO CoarseGrainedSchedulerBackend$DriverEndpoint: Launching task 141 on executor id: 0 hostname: 10.1.2.97.
17/01/28 20:46:51,768 INFO TaskSetManager: Finished task 19.0 in stage 3.0 (TID 138) in 74 ms on 10.1.2.97 (19/59)
17/01/28 20:46:51,775 INFO TaskSetManager: Starting task 23.0 in stage 3.0 (TID 142, 10.1.2.97, partition 23, PROCESS_LOCAL, 5561 bytes)
17/01/28 20:46:51,776 INFO CoarseGrainedSchedulerBackend$DriverEndpoint: Launching task 142 on executor id: 0 hostname: 10.1.2.97.
17/01/28 20:46:51,776 INFO TaskSetManager: Finished task 18.0 in stage 3.0 (TID 137) in 93 ms on 10.1.2.97 (20/59)
17/01/28 20:46:51,830 INFO TaskSetManager: Starting task 24.0 in stage 3.0 (TID 143, 10.1.2.97, partition 24, PROCESS_LOCAL, 5561 bytes)
17/01/28 20:46:51,830 INFO CoarseGrainedSchedulerBackend$DriverEndpoint: Launching task 143 on executor id: 0 hostname: 10.1.2.97.
17/01/28 20:46:51,830 INFO TaskSetManager: Finished task 20.0 in stage 3.0 (TID 139) in 102 ms on 10.1.2.97 (21/59)
17/01/28 20:46:51,834 INFO TaskSetManager: Starting task 25.0 in stage 3.0 (TID 144, 10.1.2.97, partition 25, PROCESS_LOCAL, 5561 bytes)
17/01/28 20:46:51,834 INFO CoarseGrainedSchedulerBackend$DriverEndpoint: Launching task 144 on executor id: 0 hostname: 10.1.2.97.
17/01/28 20:46:51,834 INFO TaskSetManager: Finished task 22.0 in stage 3.0 (TID 141) in 68 ms on 10.1.2.97 (22/59)
17/01/28 20:46:51,843 INFO TaskSetManager: Starting task 27.0 in stage 3.0 (TID 145, 10.1.2.97, partition 27, PROCESS_LOCAL, 5561 bytes)
17/01/28 20:46:51,844 INFO CoarseGrainedSchedulerBackend$DriverEndpoint: Launching task 145 on executor id: 0 hostname: 10.1.2.97.
17/01/28 20:46:51,844 INFO TaskSetManager: Finished task 21.0 in stage 3.0 (TID 140) in 109 ms on 10.1.2.97 (23/59)
17/01/28 20:46:51,873 INFO TaskSetManager: Starting task 28.0 in stage 3.0 (TID 146, 10.1.2.97, partition 28, PROCESS_LOCAL, 5561 bytes)
17/01/28 20:46:51,873 INFO CoarseGrainedSchedulerBackend$DriverEndpoint: Launching task 146 on executor id: 0 hostname: 10.1.2.97.
17/01/28 20:46:51,873 INFO TaskSetManager: Finished task 23.0 in stage 3.0 (TID 142) in 98 ms on 10.1.2.97 (24/59)
17/01/28 20:46:51,904 INFO TaskSetManager: Starting task 58.0 in stage 3.0 (TID 147, 10.1.2.97, partition 58, PROCESS_LOCAL, 5561 bytes)
17/01/28 20:46:51,904 INFO CoarseGrainedSchedulerBackend$DriverEndpoint: Launching task 147 on executor id: 0 hostname: 10.1.2.97.
17/01/28 20:46:51,905 INFO TaskSetManager: Finished task 25.0 in stage 3.0 (TID 144) in 72 ms on 10.1.2.97 (25/59)
17/01/28 20:46:51,906 INFO TaskSetManager: Finished task 27.0 in stage 3.0 (TID 145) in 63 ms on 10.1.2.97 (26/59)
17/01/28 20:46:51,918 INFO TaskSetManager: Finished task 24.0 in stage 3.0 (TID 143) in 89 ms on 10.1.2.97 (27/59)
17/01/28 20:46:51,948 INFO TaskSetManager: Finished task 28.0 in stage 3.0 (TID 146) in 75 ms on 10.1.2.97 (28/59)
17/01/28 20:46:51,968 INFO TaskSetManager: Finished task 58.0 in stage 3.0 (TID 147) in 63 ms on 10.1.2.97 (29/59)
17/01/28 20:46:55,099 INFO TaskSetManager: Starting task 26.0 in stage 3.0 (TID 148, 10.1.2.97, partition 26, ANY, 5561 bytes)
17/01/28 20:46:55,100 INFO TaskSetManager: Starting task 29.0 in stage 3.0 (TID 149, 10.1.2.97, partition 29, ANY, 5561 bytes)
17/01/28 20:46:55,100 INFO TaskSetManager: Starting task 30.0 in stage 3.0 (TID 150, 10.1.2.97, partition 30, ANY, 5561 bytes)
17/01/28 20:46:55,101 INFO TaskSetManager: Starting task 31.0 in stage 3.0 (TID 151, 10.1.2.97, partition 31, ANY, 5561 bytes)
17/01/28 20:46:55,101 INFO CoarseGrainedSchedulerBackend$DriverEndpoint: Launching task 148 on executor id: 0 hostname: 10.1.2.97.
17/01/28 20:46:55,102 INFO CoarseGrainedSchedulerBackend$DriverEndpoint: Launching task 149 on executor id: 0 hostname: 10.1.2.97.
17/01/28 20:46:55,102 INFO CoarseGrainedSchedulerBackend$DriverEndpoint: Launching task 150 on executor id: 0 hostname: 10.1.2.97.
17/01/28 20:46:55,103 INFO CoarseGrainedSchedulerBackend$DriverEndpoint: Launching task 151 on executor id: 0 hostname: 10.1.2.97.
17/01/28 20:47:16,024 INFO TaskSetManager: Starting task 32.0 in stage 3.0 (TID 152, 10.1.2.97, partition 32, ANY, 5561 bytes)
17/01/28 20:47:16,024 INFO CoarseGrainedSchedulerBackend$DriverEndpoint: Launching task 152 on executor id: 0 hostname: 10.1.2.97.
17/01/28 20:47:16,025 INFO TaskSetManager: Finished task 31.0 in stage 3.0 (TID 151) in 20924 ms on 10.1.2.97 (30/59)
17/01/28 20:47:16,482 INFO TaskSetManager: Starting task 33.0 in stage 3.0 (TID 153, 10.1.2.97, partition 33, ANY, 5561 bytes)
17/01/28 20:47:16,483 INFO CoarseGrainedSchedulerBackend$DriverEndpoint: Launching task 153 on executor id: 0 hostname: 10.1.2.97.
17/01/28 20:47:16,483 INFO TaskSetManager: Finished task 30.0 in stage 3.0 (TID 150) in 21383 ms on 10.1.2.97 (31/59)
17/01/28 20:47:17,662 INFO TaskSetManager: Starting task 34.0 in stage 3.0 (TID 154, 10.1.2.97, partition 34, ANY, 5561 bytes)
17/01/28 20:47:17,663 INFO CoarseGrainedSchedulerBackend$DriverEndpoint: Launching task 154 on executor id: 0 hostname: 10.1.2.97.
17/01/28 20:47:17,664 INFO TaskSetManager: Finished task 26.0 in stage 3.0 (TID 148) in 22565 ms on 10.1.2.97 (32/59)
17/01/28 20:47:18,454 INFO TaskSetManager: Starting task 35.0 in stage 3.0 (TID 155, 10.1.2.97, partition 35, ANY, 5561 bytes)
17/01/28 20:47:18,455 INFO CoarseGrainedSchedulerBackend$DriverEndpoint: Launching task 155 on executor id: 0 hostname: 10.1.2.97.
17/01/28 20:47:18,456 INFO TaskSetManager: Finished task 29.0 in stage 3.0 (TID 149) in 23356 ms on 10.1.2.97 (33/59)
17/01/28 20:47:37,014 INFO TaskSetManager: Starting task 36.0 in stage 3.0 (TID 156, 10.1.2.97, partition 36, ANY, 5561 bytes)
17/01/28 20:47:37,015 INFO CoarseGrainedSchedulerBackend$DriverEndpoint: Launching task 156 on executor id: 0 hostname: 10.1.2.97.
17/01/28 20:47:37,015 INFO TaskSetManager: Finished task 33.0 in stage 3.0 (TID 153) in 20533 ms on 10.1.2.97 (34/59)
17/01/28 20:47:37,295 INFO TaskSetManager: Starting task 37.0 in stage 3.0 (TID 157, 10.1.2.97, partition 37, ANY, 5561 bytes)
17/01/28 20:47:37,295 INFO CoarseGrainedSchedulerBackend$DriverEndpoint: Launching task 157 on executor id: 0 hostname: 10.1.2.97.
17/01/28 20:47:37,295 INFO TaskSetManager: Finished task 32.0 in stage 3.0 (TID 152) in 21272 ms on 10.1.2.97 (35/59)
17/01/28 20:47:38,285 INFO TaskSetManager: Starting task 38.0 in stage 3.0 (TID 158, 10.1.2.97, partition 38, ANY, 5561 bytes)
17/01/28 20:47:38,285 INFO CoarseGrainedSchedulerBackend$DriverEndpoint: Launching task 158 on executor id: 0 hostname: 10.1.2.97.
17/01/28 20:47:38,286 INFO TaskSetManager: Finished task 34.0 in stage 3.0 (TID 154) in 20624 ms on 10.1.2.97 (36/59)
17/01/28 20:47:42,186 INFO TaskSetManager: Starting task 39.0 in stage 3.0 (TID 159, 10.1.2.97, partition 39, ANY, 5561 bytes)
17/01/28 20:47:42,186 INFO CoarseGrainedSchedulerBackend$DriverEndpoint: Launching task 159 on executor id: 0 hostname: 10.1.2.97.
17/01/28 20:47:42,187 INFO TaskSetManager: Finished task 35.0 in stage 3.0 (TID 155) in 23733 ms on 10.1.2.97 (37/59)
17/01/28 20:48:00,375 INFO TaskSetManager: Starting task 40.0 in stage 3.0 (TID 160, 10.1.2.97, partition 40, ANY, 5561 bytes)
17/01/28 20:48:00,375 INFO CoarseGrainedSchedulerBackend$DriverEndpoint: Launching task 160 on executor id: 0 hostname: 10.1.2.97.
17/01/28 20:48:00,376 INFO TaskSetManager: Finished task 36.0 in stage 3.0 (TID 156) in 23362 ms on 10.1.2.97 (38/59)
17/01/28 20:48:02,901 INFO TaskSetManager: Starting task 41.0 in stage 3.0 (TID 161, 10.1.2.97, partition 41, ANY, 5561 bytes)
17/01/28 20:48:02,901 INFO CoarseGrainedSchedulerBackend$DriverEndpoint: Launching task 161 on executor id: 0 hostname: 10.1.2.97.
17/01/28 20:48:02,902 INFO TaskSetManager: Finished task 37.0 in stage 3.0 (TID 157) in 25608 ms on 10.1.2.97 (39/59)
17/01/28 20:48:04,473 INFO TaskSetManager: Starting task 42.0 in stage 3.0 (TID 162, 10.1.2.97, partition 42, ANY, 5561 bytes)
17/01/28 20:48:04,474 INFO CoarseGrainedSchedulerBackend$DriverEndpoint: Launching task 162 on executor id: 0 hostname: 10.1.2.97.
17/01/28 20:48:04,474 INFO TaskSetManager: Finished task 38.0 in stage 3.0 (TID 158) in 26189 ms on 10.1.2.97 (40/59)
17/01/28 20:48:05,005 INFO TaskSetManager: Starting task 43.0 in stage 3.0 (TID 163, 10.1.2.97, partition 43, ANY, 5561 bytes)
17/01/28 20:48:05,006 INFO CoarseGrainedSchedulerBackend$DriverEndpoint: Launching task 163 on executor id: 0 hostname: 10.1.2.97.
17/01/28 20:48:05,006 INFO TaskSetManager: Finished task 39.0 in stage 3.0 (TID 159) in 22820 ms on 10.1.2.97 (41/59)
17/01/28 20:48:21,817 INFO TaskSetManager: Starting task 44.0 in stage 3.0 (TID 164, 10.1.2.97, partition 44, ANY, 5561 bytes)
17/01/28 20:48:21,817 INFO CoarseGrainedSchedulerBackend$DriverEndpoint: Launching task 164 on executor id: 0 hostname: 10.1.2.97.
17/01/28 20:48:21,818 INFO TaskSetManager: Finished task 40.0 in stage 3.0 (TID 160) in 21443 ms on 10.1.2.97 (42/59)
17/01/28 20:48:22,048 INFO TaskSetManager: Starting task 45.0 in stage 3.0 (TID 165, 10.1.2.97, partition 45, ANY, 5561 bytes)
17/01/28 20:48:22,048 INFO CoarseGrainedSchedulerBackend$DriverEndpoint: Launching task 165 on executor id: 0 hostname: 10.1.2.97.
17/01/28 20:48:22,049 INFO TaskSetManager: Finished task 41.0 in stage 3.0 (TID 161) in 19148 ms on 10.1.2.97 (43/59)
17/01/28 20:48:22,197 INFO TaskSetManager: Starting task 46.0 in stage 3.0 (TID 166, 10.1.2.97, partition 46, ANY, 5561 bytes)
17/01/28 20:48:22,197 INFO CoarseGrainedSchedulerBackend$DriverEndpoint: Launching task 166 on executor id: 0 hostname: 10.1.2.97.
17/01/28 20:48:22,197 INFO TaskSetManager: Finished task 42.0 in stage 3.0 (TID 162) in 17724 ms on 10.1.2.97 (44/59)
17/01/28 20:48:23,411 INFO TaskSetManager: Starting task 47.0 in stage 3.0 (TID 167, 10.1.2.97, partition 47, ANY, 5561 bytes)
17/01/28 20:48:23,412 INFO CoarseGrainedSchedulerBackend$DriverEndpoint: Launching task 167 on executor id: 0 hostname: 10.1.2.97.
17/01/28 20:48:23,412 INFO TaskSetManager: Finished task 43.0 in stage 3.0 (TID 163) in 18407 ms on 10.1.2.97 (45/59)
17/01/28 20:48:41,434 INFO TaskSetManager: Starting task 48.0 in stage 3.0 (TID 168, 10.1.2.97, partition 48, ANY, 5561 bytes)
17/01/28 20:48:41,434 INFO CoarseGrainedSchedulerBackend$DriverEndpoint: Launching task 168 on executor id: 0 hostname: 10.1.2.97.
17/01/28 20:48:41,435 INFO TaskSetManager: Finished task 44.0 in stage 3.0 (TID 164) in 19619 ms on 10.1.2.97 (46/59)
17/01/28 20:48:41,786 INFO TaskSetManager: Starting task 49.0 in stage 3.0 (TID 169, 10.1.2.97, partition 49, ANY, 5561 bytes)
17/01/28 20:48:41,786 INFO CoarseGrainedSchedulerBackend$DriverEndpoint: Launching task 169 on executor id: 0 hostname: 10.1.2.97.
17/01/28 20:48:41,787 INFO TaskSetManager: Finished task 45.0 in stage 3.0 (TID 165) in 19739 ms on 10.1.2.97 (47/59)
17/01/28 20:48:42,304 INFO TaskSetManager: Starting task 50.0 in stage 3.0 (TID 170, 10.1.2.97, partition 50, ANY, 5561 bytes)
17/01/28 20:48:42,305 INFO CoarseGrainedSchedulerBackend$DriverEndpoint: Launching task 170 on executor id: 0 hostname: 10.1.2.97.
17/01/28 20:48:42,305 INFO TaskSetManager: Finished task 46.0 in stage 3.0 (TID 166) in 20109 ms on 10.1.2.97 (48/59)
17/01/28 20:48:44,029 INFO TaskSetManager: Starting task 51.0 in stage 3.0 (TID 171, 10.1.2.97, partition 51, ANY, 5561 bytes)
17/01/28 20:48:44,029 INFO CoarseGrainedSchedulerBackend$DriverEndpoint: Launching task 171 on executor id: 0 hostname: 10.1.2.97.
17/01/28 20:48:44,030 INFO TaskSetManager: Finished task 47.0 in stage 3.0 (TID 167) in 20619 ms on 10.1.2.97 (49/59)
17/01/28 20:49:00,663 INFO TaskSetManager: Starting task 52.0 in stage 3.0 (TID 172, 10.1.2.97, partition 52, ANY, 5561 bytes)
17/01/28 20:49:00,663 INFO CoarseGrainedSchedulerBackend$DriverEndpoint: Launching task 172 on executor id: 0 hostname: 10.1.2.97.
17/01/28 20:49:00,664 INFO TaskSetManager: Finished task 48.0 in stage 3.0 (TID 168) in 19230 ms on 10.1.2.97 (50/59)
17/01/28 20:49:01,885 INFO TaskSetManager: Starting task 53.0 in stage 3.0 (TID 173, 10.1.2.97, partition 53, ANY, 5561 bytes)
17/01/28 20:49:01,885 INFO CoarseGrainedSchedulerBackend$DriverEndpoint: Launching task 173 on executor id: 0 hostname: 10.1.2.97.
17/01/28 20:49:01,886 INFO TaskSetManager: Finished task 50.0 in stage 3.0 (TID 170) in 19581 ms on 10.1.2.97 (51/59)
17/01/28 20:49:02,337 INFO TaskSetManager: Starting task 54.0 in stage 3.0 (TID 174, 10.1.2.97, partition 54, ANY, 5561 bytes)
17/01/28 20:49:02,337 INFO CoarseGrainedSchedulerBackend$DriverEndpoint: Launching task 174 on executor id: 0 hostname: 10.1.2.97.
17/01/28 20:49:02,338 INFO TaskSetManager: Finished task 49.0 in stage 3.0 (TID 169) in 20551 ms on 10.1.2.97 (52/59)
17/01/28 20:49:04,236 INFO TaskSetManager: Starting task 55.0 in stage 3.0 (TID 175, 10.1.2.97, partition 55, ANY, 5561 bytes)
17/01/28 20:49:04,236 INFO CoarseGrainedSchedulerBackend$DriverEndpoint: Launching task 175 on executor id: 0 hostname: 10.1.2.97.
17/01/28 20:49:04,237 INFO TaskSetManager: Finished task 51.0 in stage 3.0 (TID 171) in 20207 ms on 10.1.2.97 (53/59)
17/01/28 20:49:20,201 INFO TaskSetManager: Starting task 56.0 in stage 3.0 (TID 176, 10.1.2.97, partition 56, ANY, 5561 bytes)
17/01/28 20:49:20,201 INFO CoarseGrainedSchedulerBackend$DriverEndpoint: Launching task 176 on executor id: 0 hostname: 10.1.2.97.
17/01/28 20:49:20,202 INFO TaskSetManager: Finished task 52.0 in stage 3.0 (TID 172) in 19539 ms on 10.1.2.97 (54/59)
17/01/28 20:49:20,287 INFO TaskSetManager: Starting task 57.0 in stage 3.0 (TID 177, 10.1.2.97, partition 57, ANY, 5561 bytes)
17/01/28 20:49:20,287 INFO CoarseGrainedSchedulerBackend$DriverEndpoint: Launching task 177 on executor id: 0 hostname: 10.1.2.97.
17/01/28 20:49:20,288 INFO TaskSetManager: Finished task 53.0 in stage 3.0 (TID 173) in 18403 ms on 10.1.2.97 (55/59)
17/01/28 20:49:21,256 INFO TaskSetManager: Finished task 54.0 in stage 3.0 (TID 174) in 18920 ms on 10.1.2.97 (56/59)
17/01/28 20:49:22,747 INFO TaskSetManager: Finished task 55.0 in stage 3.0 (TID 175) in 18512 ms on 10.1.2.97 (57/59)
17/01/28 20:49:29,631 INFO TaskSetManager: Finished task 56.0 in stage 3.0 (TID 176) in 9431 ms on 10.1.2.97 (58/59)
17/01/28 20:49:29,673 INFO TaskSetManager: Finished task 57.0 in stage 3.0 (TID 177) in 9387 ms on 10.1.2.97 (59/59)
17/01/28 20:49:29,674 INFO TaskSchedulerImpl: Removed TaskSet 3.0, whose tasks have all completed, from pool 
17/01/28 20:49:29,674 INFO DAGScheduler: ShuffleMapStage 3 (treeAggregate at GradientDescent.scala:239) finished in 158.920 s
17/01/28 20:49:29,674 INFO DAGScheduler: looking for newly runnable stages
17/01/28 20:49:29,675 INFO DAGScheduler: running: Set()
17/01/28 20:49:29,675 INFO DAGScheduler: waiting: Set(ResultStage 4)
17/01/28 20:49:29,676 INFO DAGScheduler: failed: Set()
17/01/28 20:49:29,677 INFO DAGScheduler: Submitting ResultStage 4 (MapPartitionsRDD[13] at treeAggregate at GradientDescent.scala:239), which has no missing parents
17/01/28 20:49:29,682 INFO MemoryStore: Block broadcast_6 stored as values in memory (estimated size 3.1 KB, free 2.1 GB)
17/01/28 20:49:29,684 INFO MemoryStore: Block broadcast_6_piece0 stored as bytes in memory (estimated size 1893.0 B, free 2.1 GB)
17/01/28 20:49:29,684 INFO BlockManagerInfo: Added broadcast_6_piece0 in memory on 10.1.2.60:32932 (size: 1893.0 B, free: 2.1 GB)
17/01/28 20:49:29,685 INFO SparkContext: Created broadcast 6 from broadcast at DAGScheduler.scala:1012
17/01/28 20:49:29,685 INFO DAGScheduler: Submitting 7 missing tasks from ResultStage 4 (MapPartitionsRDD[13] at treeAggregate at GradientDescent.scala:239)
17/01/28 20:49:29,685 INFO TaskSchedulerImpl: Adding task set 4.0 with 7 tasks
17/01/28 20:49:29,687 INFO TaskSetManager: Starting task 0.0 in stage 4.0 (TID 178, 10.1.2.97, partition 0, NODE_LOCAL, 5227 bytes)
17/01/28 20:49:29,688 INFO TaskSetManager: Starting task 1.0 in stage 4.0 (TID 179, 10.1.2.97, partition 1, NODE_LOCAL, 5227 bytes)
17/01/28 20:49:29,688 INFO TaskSetManager: Starting task 2.0 in stage 4.0 (TID 180, 10.1.2.97, partition 2, NODE_LOCAL, 5227 bytes)
17/01/28 20:49:29,690 INFO TaskSetManager: Starting task 3.0 in stage 4.0 (TID 181, 10.1.2.97, partition 3, NODE_LOCAL, 5227 bytes)
17/01/28 20:49:29,690 INFO CoarseGrainedSchedulerBackend$DriverEndpoint: Launching task 178 on executor id: 0 hostname: 10.1.2.97.
17/01/28 20:49:29,690 INFO CoarseGrainedSchedulerBackend$DriverEndpoint: Launching task 179 on executor id: 0 hostname: 10.1.2.97.
17/01/28 20:49:29,691 INFO CoarseGrainedSchedulerBackend$DriverEndpoint: Launching task 180 on executor id: 0 hostname: 10.1.2.97.
17/01/28 20:49:29,691 INFO CoarseGrainedSchedulerBackend$DriverEndpoint: Launching task 181 on executor id: 0 hostname: 10.1.2.97.
17/01/28 20:49:29,707 INFO BlockManagerInfo: Added broadcast_6_piece0 in memory on 10.1.2.97:46198 (size: 1893.0 B, free: 89.6 MB)
17/01/28 20:49:29,733 INFO MapOutputTrackerMasterEndpoint: Asked to send map output locations for shuffle 0 to 10.1.2.97:35938
17/01/28 20:49:29,737 INFO MapOutputTrackerMaster: Size of output statuses for shuffle 0 is 197 bytes
17/01/28 20:49:29,789 INFO TaskSetManager: Starting task 4.0 in stage 4.0 (TID 182, 10.1.2.97, partition 4, NODE_LOCAL, 5227 bytes)
17/01/28 20:49:29,789 INFO CoarseGrainedSchedulerBackend$DriverEndpoint: Launching task 182 on executor id: 0 hostname: 10.1.2.97.
17/01/28 20:49:29,790 INFO TaskSetManager: Starting task 5.0 in stage 4.0 (TID 183, 10.1.2.97, partition 5, NODE_LOCAL, 5227 bytes)
17/01/28 20:49:29,790 INFO CoarseGrainedSchedulerBackend$DriverEndpoint: Launching task 183 on executor id: 0 hostname: 10.1.2.97.
17/01/28 20:49:29,791 INFO TaskSetManager: Starting task 6.0 in stage 4.0 (TID 184, 10.1.2.97, partition 6, NODE_LOCAL, 5227 bytes)
17/01/28 20:49:29,791 INFO CoarseGrainedSchedulerBackend$DriverEndpoint: Launching task 184 on executor id: 0 hostname: 10.1.2.97.
17/01/28 20:49:29,793 INFO TaskSetManager: Finished task 1.0 in stage 4.0 (TID 179) in 105 ms on 10.1.2.97 (1/7)
17/01/28 20:49:29,793 INFO TaskSetManager: Finished task 3.0 in stage 4.0 (TID 181) in 105 ms on 10.1.2.97 (2/7)
17/01/28 20:49:29,794 INFO TaskSetManager: Finished task 0.0 in stage 4.0 (TID 178) in 108 ms on 10.1.2.97 (3/7)
17/01/28 20:49:29,794 INFO TaskSetManager: Finished task 2.0 in stage 4.0 (TID 180) in 106 ms on 10.1.2.97 (4/7)
17/01/28 20:49:29,801 INFO TaskSetManager: Finished task 4.0 in stage 4.0 (TID 182) in 13 ms on 10.1.2.97 (5/7)
17/01/28 20:49:29,803 INFO TaskSetManager: Finished task 5.0 in stage 4.0 (TID 183) in 14 ms on 10.1.2.97 (6/7)
17/01/28 20:49:29,804 INFO TaskSetManager: Finished task 6.0 in stage 4.0 (TID 184) in 14 ms on 10.1.2.97 (7/7)
17/01/28 20:49:29,804 INFO TaskSchedulerImpl: Removed TaskSet 4.0, whose tasks have all completed, from pool 
17/01/28 20:49:29,805 INFO DAGScheduler: ResultStage 4 (treeAggregate at GradientDescent.scala:239) finished in 0.113 s
17/01/28 20:49:29,805 INFO DAGScheduler: Job 3 finished: treeAggregate at GradientDescent.scala:239, took 159.100424 s
17/01/28 20:49:29,808 INFO MemoryStore: Block broadcast_7 stored as values in memory (estimated size 280.0 B, free 2.1 GB)
17/01/28 20:49:29,809 INFO MemoryStore: Block broadcast_7_piece0 stored as bytes in memory (estimated size 365.0 B, free 2.1 GB)
17/01/28 20:49:29,818 INFO BlockManagerInfo: Added broadcast_7_piece0 in memory on 10.1.2.60:32932 (size: 365.0 B, free: 2.1 GB)
17/01/28 20:49:29,819 INFO SparkContext: Created broadcast 7 from broadcast at GradientDescent.scala:235
17/01/28 20:49:29,836 INFO SparkContext: Starting job: treeAggregate at GradientDescent.scala:239
17/01/28 20:49:29,838 INFO DAGScheduler: Registering RDD 16 (treeAggregate at GradientDescent.scala:239)
17/01/28 20:49:29,838 INFO DAGScheduler: Got job 4 (treeAggregate at GradientDescent.scala:239) with 7 output partitions
17/01/28 20:49:29,838 INFO DAGScheduler: Final stage: ResultStage 6 (treeAggregate at GradientDescent.scala:239)
17/01/28 20:49:29,838 INFO DAGScheduler: Parents of final stage: List(ShuffleMapStage 5)
17/01/28 20:49:29,839 INFO DAGScheduler: Missing parents: List(ShuffleMapStage 5)
17/01/28 20:49:29,842 INFO DAGScheduler: Submitting ShuffleMapStage 5 (MapPartitionsRDD[16] at treeAggregate at GradientDescent.scala:239), which has no missing parents
17/01/28 20:49:29,854 INFO MemoryStore: Block broadcast_8 stored as values in memory (estimated size 7.2 KB, free 2.1 GB)
17/01/28 20:49:29,858 INFO MemoryStore: Block broadcast_8_piece0 stored as bytes in memory (estimated size 3.7 KB, free 2.1 GB)
17/01/28 20:49:29,858 INFO BlockManagerInfo: Added broadcast_8_piece0 in memory on 10.1.2.60:32932 (size: 3.7 KB, free: 2.1 GB)
17/01/28 20:49:29,859 INFO SparkContext: Created broadcast 8 from broadcast at DAGScheduler.scala:1012
17/01/28 20:49:29,860 INFO DAGScheduler: Submitting 59 missing tasks from ShuffleMapStage 5 (MapPartitionsRDD[16] at treeAggregate at GradientDescent.scala:239)
17/01/28 20:49:29,861 INFO TaskSchedulerImpl: Adding task set 5.0 with 59 tasks
17/01/28 20:49:29,863 INFO TaskSetManager: Starting task 0.0 in stage 5.0 (TID 185, 10.1.2.97, partition 0, PROCESS_LOCAL, 5561 bytes)
17/01/28 20:49:29,863 INFO TaskSetManager: Starting task 1.0 in stage 5.0 (TID 186, 10.1.2.97, partition 1, PROCESS_LOCAL, 5561 bytes)
17/01/28 20:49:29,864 INFO TaskSetManager: Starting task 2.0 in stage 5.0 (TID 187, 10.1.2.97, partition 2, PROCESS_LOCAL, 5561 bytes)
17/01/28 20:49:29,864 INFO TaskSetManager: Starting task 3.0 in stage 5.0 (TID 188, 10.1.2.97, partition 3, PROCESS_LOCAL, 5561 bytes)
17/01/28 20:49:29,864 INFO CoarseGrainedSchedulerBackend$DriverEndpoint: Launching task 185 on executor id: 0 hostname: 10.1.2.97.
17/01/28 20:49:29,865 INFO CoarseGrainedSchedulerBackend$DriverEndpoint: Launching task 186 on executor id: 0 hostname: 10.1.2.97.
17/01/28 20:49:29,865 INFO CoarseGrainedSchedulerBackend$DriverEndpoint: Launching task 187 on executor id: 0 hostname: 10.1.2.97.
17/01/28 20:49:29,865 INFO CoarseGrainedSchedulerBackend$DriverEndpoint: Launching task 188 on executor id: 0 hostname: 10.1.2.97.
17/01/28 20:49:29,877 INFO BlockManagerInfo: Added broadcast_8_piece0 in memory on 10.1.2.97:46198 (size: 3.7 KB, free: 89.6 MB)
17/01/28 20:49:29,890 INFO BlockManagerInfo: Added broadcast_7_piece0 in memory on 10.1.2.97:46198 (size: 365.0 B, free: 89.6 MB)
17/01/28 20:49:29,970 INFO TaskSetManager: Starting task 4.0 in stage 5.0 (TID 189, 10.1.2.97, partition 4, PROCESS_LOCAL, 5561 bytes)
17/01/28 20:49:29,971 INFO CoarseGrainedSchedulerBackend$DriverEndpoint: Launching task 189 on executor id: 0 hostname: 10.1.2.97.
17/01/28 20:49:29,971 INFO TaskSetManager: Finished task 2.0 in stage 5.0 (TID 187) in 108 ms on 10.1.2.97 (1/59)
17/01/28 20:49:29,978 INFO TaskSetManager: Starting task 5.0 in stage 5.0 (TID 190, 10.1.2.97, partition 5, PROCESS_LOCAL, 5561 bytes)
17/01/28 20:49:29,979 INFO CoarseGrainedSchedulerBackend$DriverEndpoint: Launching task 190 on executor id: 0 hostname: 10.1.2.97.
17/01/28 20:49:29,979 INFO TaskSetManager: Finished task 0.0 in stage 5.0 (TID 185) in 117 ms on 10.1.2.97 (2/59)
17/01/28 20:49:29,980 INFO TaskSetManager: Starting task 6.0 in stage 5.0 (TID 191, 10.1.2.97, partition 6, PROCESS_LOCAL, 5561 bytes)
17/01/28 20:49:29,980 INFO CoarseGrainedSchedulerBackend$DriverEndpoint: Launching task 191 on executor id: 0 hostname: 10.1.2.97.
17/01/28 20:49:29,981 INFO TaskSetManager: Finished task 1.0 in stage 5.0 (TID 186) in 117 ms on 10.1.2.97 (3/59)
17/01/28 20:49:29,984 INFO TaskSetManager: Starting task 7.0 in stage 5.0 (TID 192, 10.1.2.97, partition 7, PROCESS_LOCAL, 5561 bytes)
17/01/28 20:49:29,984 INFO CoarseGrainedSchedulerBackend$DriverEndpoint: Launching task 192 on executor id: 0 hostname: 10.1.2.97.
17/01/28 20:49:29,985 INFO TaskSetManager: Finished task 3.0 in stage 5.0 (TID 188) in 121 ms on 10.1.2.97 (4/59)
17/01/28 20:49:30,048 INFO TaskSetManager: Starting task 8.0 in stage 5.0 (TID 193, 10.1.2.97, partition 8, PROCESS_LOCAL, 5561 bytes)
17/01/28 20:49:30,049 INFO CoarseGrainedSchedulerBackend$DriverEndpoint: Launching task 193 on executor id: 0 hostname: 10.1.2.97.
17/01/28 20:49:30,049 INFO TaskSetManager: Finished task 4.0 in stage 5.0 (TID 189) in 79 ms on 10.1.2.97 (5/59)
17/01/28 20:49:30,062 INFO TaskSetManager: Starting task 9.0 in stage 5.0 (TID 194, 10.1.2.97, partition 9, PROCESS_LOCAL, 5561 bytes)
17/01/28 20:49:30,062 INFO CoarseGrainedSchedulerBackend$DriverEndpoint: Launching task 194 on executor id: 0 hostname: 10.1.2.97.
17/01/28 20:49:30,063 INFO TaskSetManager: Finished task 5.0 in stage 5.0 (TID 190) in 85 ms on 10.1.2.97 (6/59)
17/01/28 20:49:30,064 INFO TaskSetManager: Starting task 10.0 in stage 5.0 (TID 195, 10.1.2.97, partition 10, PROCESS_LOCAL, 5561 bytes)
17/01/28 20:49:30,064 INFO CoarseGrainedSchedulerBackend$DriverEndpoint: Launching task 195 on executor id: 0 hostname: 10.1.2.97.
17/01/28 20:49:30,064 INFO TaskSetManager: Finished task 7.0 in stage 5.0 (TID 192) in 80 ms on 10.1.2.97 (7/59)
17/01/28 20:49:30,068 INFO TaskSetManager: Starting task 11.0 in stage 5.0 (TID 196, 10.1.2.97, partition 11, PROCESS_LOCAL, 5561 bytes)
17/01/28 20:49:30,068 INFO CoarseGrainedSchedulerBackend$DriverEndpoint: Launching task 196 on executor id: 0 hostname: 10.1.2.97.
17/01/28 20:49:30,068 INFO TaskSetManager: Finished task 6.0 in stage 5.0 (TID 191) in 88 ms on 10.1.2.97 (8/59)
17/01/28 20:49:30,125 INFO TaskSetManager: Starting task 12.0 in stage 5.0 (TID 197, 10.1.2.97, partition 12, PROCESS_LOCAL, 5561 bytes)
17/01/28 20:49:30,126 INFO CoarseGrainedSchedulerBackend$DriverEndpoint: Launching task 197 on executor id: 0 hostname: 10.1.2.97.
17/01/28 20:49:30,126 INFO TaskSetManager: Finished task 8.0 in stage 5.0 (TID 193) in 78 ms on 10.1.2.97 (9/59)
17/01/28 20:49:30,149 INFO TaskSetManager: Starting task 13.0 in stage 5.0 (TID 198, 10.1.2.97, partition 13, PROCESS_LOCAL, 5561 bytes)
17/01/28 20:49:30,149 INFO CoarseGrainedSchedulerBackend$DriverEndpoint: Launching task 198 on executor id: 0 hostname: 10.1.2.97.
17/01/28 20:49:30,149 INFO TaskSetManager: Finished task 9.0 in stage 5.0 (TID 194) in 87 ms on 10.1.2.97 (10/59)
17/01/28 20:49:30,152 INFO TaskSetManager: Starting task 14.0 in stage 5.0 (TID 199, 10.1.2.97, partition 14, PROCESS_LOCAL, 5561 bytes)
17/01/28 20:49:30,152 INFO CoarseGrainedSchedulerBackend$DriverEndpoint: Launching task 199 on executor id: 0 hostname: 10.1.2.97.
17/01/28 20:49:30,153 INFO TaskSetManager: Finished task 10.0 in stage 5.0 (TID 195) in 89 ms on 10.1.2.97 (11/59)
17/01/28 20:49:30,154 INFO TaskSetManager: Starting task 15.0 in stage 5.0 (TID 200, 10.1.2.97, partition 15, PROCESS_LOCAL, 5561 bytes)
17/01/28 20:49:30,154 INFO CoarseGrainedSchedulerBackend$DriverEndpoint: Launching task 200 on executor id: 0 hostname: 10.1.2.97.
17/01/28 20:49:30,154 INFO TaskSetManager: Finished task 11.0 in stage 5.0 (TID 196) in 87 ms on 10.1.2.97 (12/59)
17/01/28 20:49:30,199 INFO TaskSetManager: Starting task 16.0 in stage 5.0 (TID 201, 10.1.2.97, partition 16, PROCESS_LOCAL, 5561 bytes)
17/01/28 20:49:30,200 INFO CoarseGrainedSchedulerBackend$DriverEndpoint: Launching task 201 on executor id: 0 hostname: 10.1.2.97.
17/01/28 20:49:30,200 INFO TaskSetManager: Finished task 12.0 in stage 5.0 (TID 197) in 75 ms on 10.1.2.97 (13/59)
17/01/28 20:49:30,233 INFO TaskSetManager: Starting task 17.0 in stage 5.0 (TID 202, 10.1.2.97, partition 17, PROCESS_LOCAL, 5561 bytes)
17/01/28 20:49:30,233 INFO CoarseGrainedSchedulerBackend$DriverEndpoint: Launching task 202 on executor id: 0 hostname: 10.1.2.97.
17/01/28 20:49:30,233 INFO TaskSetManager: Finished task 14.0 in stage 5.0 (TID 199) in 83 ms on 10.1.2.97 (14/59)
17/01/28 20:49:30,237 INFO TaskSetManager: Starting task 18.0 in stage 5.0 (TID 203, 10.1.2.97, partition 18, PROCESS_LOCAL, 5561 bytes)
17/01/28 20:49:30,238 INFO CoarseGrainedSchedulerBackend$DriverEndpoint: Launching task 203 on executor id: 0 hostname: 10.1.2.97.
