Using properties file: /home/ubuntu/spark-2.0.0/conf/spark-defaults.conf
Adding default property: spark.driver.extraJavaOptions=-XX:+PrintGCDetails -XX:+PrintGCTimeStamps -Xms4000m -Dlog4j.configuration=file:///home/ubuntu/spark-2.0.0/conf/log4j.properties
Adding default property: spark.executor.extraJavaOptions=-XX:+PrintGCDetails -XX:+PrintGCTimeStamps -Xms4000m -Dlog4j.configuration=file:///home/ubuntu/spark-2.0.0/conf/log4j.properties
Parsed arguments:
  master                  spark://euca-10-1-2-60:7077
  deployMode              client
  executorMemory          4000m
  executorCores           null
  totalExecutorCores      null
  propertiesFile          /home/ubuntu/spark-2.0.0/conf/spark-defaults.conf
  driverMemory            4000m
  driverCores             null
  driverExtraClassPath    null
  driverExtraLibraryPath  null
  driverExtraJavaOptions  -XX:+PrintGCDetails -XX:+PrintGCTimeStamps -Xms4000m -Dlog4j.configuration=file:///home/ubuntu/spark-2.0.0/conf/log4j.properties
  supervise               false
  queue                   null
  numExecutors            1
  files                   null
  pyFiles                 null
  archives                null
  mainClass               LogRegExplicitParallelism
  primaryResource         file:///home/ubuntu/jars/log-reg-explicit-parallelism_2.11-1.0.jar
  name                    LogRegExplicitParallelism
  childArgs               [cluster 28 euca-10-1-2-60 9000 higgs_0_exp 5 4]
  jars                    null
  packages                null
  packagesExclusions      null
  repositories            null
  verbose                 true

Spark properties used, including those specified through
 --conf and those from the properties file /home/ubuntu/spark-2.0.0/conf/spark-defaults.conf:
  spark.default.parallelism -> 4
  spark.driver.memory -> 4000m
  spark.executor.extraJavaOptions -> -XX:+PrintGCDetails -XX:+PrintGCTimeStamps -Xms4000m -Dlog4j.configuration=file:///home/ubuntu/spark-2.0.0/conf/log4j.properties
  spark.driver.extraJavaOptions -> -XX:+PrintGCDetails -XX:+PrintGCTimeStamps -Xms4000m -Dlog4j.configuration=file:///home/ubuntu/spark-2.0.0/conf/log4j.properties
  spark.shuffle.spill -> false

    
Main class:
LogRegExplicitParallelism
Arguments:
cluster
28
euca-10-1-2-60
9000
higgs_0_exp
5
4
System properties:
spark.default.parallelism -> 4
spark.executor.memory -> 4000m
spark.driver.memory -> 4000m
SPARK_SUBMIT -> true
spark.executor.extraJavaOptions -> -XX:+PrintGCDetails -XX:+PrintGCTimeStamps -Xms4000m -Dlog4j.configuration=file:///home/ubuntu/spark-2.0.0/conf/log4j.properties
spark.app.name -> LogRegExplicitParallelism
spark.shuffle.spill -> false
spark.driver.extraJavaOptions -> -XX:+PrintGCDetails -XX:+PrintGCTimeStamps -Xms4000m -Dlog4j.configuration=file:///home/ubuntu/spark-2.0.0/conf/log4j.properties
spark.jars -> file:///home/ubuntu/jars/log-reg-explicit-parallelism_2.11-1.0.jar
spark.submit.deployMode -> client
spark.master -> spark://euca-10-1-2-60:7077
Classpath elements:
file:///home/ubuntu/jars/log-reg-explicit-parallelism_2.11-1.0.jar


17/01/29 02:47:35,019 INFO SparkContext: Running Spark version 2.0.0
17/01/29 02:47:35,341 WARN NativeCodeLoader: Unable to load native-hadoop library for your platform... using builtin-java classes where applicable
17/01/29 02:47:35,493 INFO SecurityManager: Changing view acls to: ubuntu
17/01/29 02:47:35,494 INFO SecurityManager: Changing modify acls to: ubuntu
17/01/29 02:47:35,494 INFO SecurityManager: Changing view acls groups to: 
17/01/29 02:47:35,495 INFO SecurityManager: Changing modify acls groups to: 
17/01/29 02:47:35,495 INFO SecurityManager: SecurityManager: authentication disabled; ui acls disabled; users  with view permissions: Set(ubuntu); groups with view permissions: Set(); users  with modify permissions: Set(ubuntu); groups with modify permissions: Set()
17/01/29 02:47:35,803 INFO Utils: Successfully started service 'sparkDriver' on port 33889.
17/01/29 02:47:35,821 INFO SparkEnv: Registering MapOutputTracker
17/01/29 02:47:35,826 WARN SortShuffleManager: spark.shuffle.spill was set to false, but this configuration is ignored as of Spark 1.6+. Shuffle will continue to spill to disk when necessary.
17/01/29 02:47:35,837 INFO SparkEnv: Registering BlockManagerMaster
17/01/29 02:47:35,850 INFO DiskBlockManager: Created local directory at /tmp/blockmgr-7693e2e6-79b6-4079-a264-d1d123742608
17/01/29 02:47:35,867 INFO MemoryStore: MemoryStore started with capacity 2.1 GB
17/01/29 02:47:35,919 INFO SparkEnv: Registering OutputCommitCoordinator
17/01/29 02:47:36,112 INFO Utils: Successfully started service 'SparkUI' on port 4040.
17/01/29 02:47:36,114 INFO SparkUI: Bound SparkUI to 10.1.2.60, and started at http://10.1.2.60:4040
17/01/29 02:47:36,148 INFO SparkContext: Added JAR file:///home/ubuntu/jars/log-reg-explicit-parallelism_2.11-1.0.jar at spark://10.1.2.60:33889/jars/log-reg-explicit-parallelism_2.11-1.0.jar with timestamp 1485658056147
17/01/29 02:47:36,228 INFO StandaloneAppClient$ClientEndpoint: Connecting to master spark://euca-10-1-2-60:7077...
17/01/29 02:47:36,281 INFO TransportClientFactory: Successfully created connection to euca-10-1-2-60/10.1.2.60:7077 after 27 ms (0 ms spent in bootstraps)
17/01/29 02:47:36,395 INFO StandaloneSchedulerBackend: Connected to Spark cluster with app ID app-20170129024736-0000
17/01/29 02:47:36,400 INFO Utils: Successfully started service 'org.apache.spark.network.netty.NettyBlockTransferService' on port 44506.
17/01/29 02:47:36,400 INFO NettyBlockTransferService: Server created on 10.1.2.60:44506
17/01/29 02:47:36,407 INFO BlockManagerMaster: Registering BlockManager BlockManagerId(driver, 10.1.2.60, 44506)
17/01/29 02:47:36,409 INFO BlockManagerMasterEndpoint: Registering block manager 10.1.2.60:44506 with 2.1 GB RAM, BlockManagerId(driver, 10.1.2.60, 44506)
17/01/29 02:47:36,411 INFO StandaloneAppClient$ClientEndpoint: Executor added: app-20170129024736-0000/0 on worker-20170129024728-10.1.2.97-32963 (10.1.2.97:32963) with 4 cores
17/01/29 02:47:36,411 INFO StandaloneSchedulerBackend: Granted executor ID app-20170129024736-0000/0 on hostPort 10.1.2.97:32963 with 4 cores, 3.9 GB RAM
17/01/29 02:47:36,413 INFO BlockManagerMaster: Registered BlockManager BlockManagerId(driver, 10.1.2.60, 44506)
17/01/29 02:47:36,473 INFO StandaloneAppClient$ClientEndpoint: Executor updated: app-20170129024736-0000/0 is now RUNNING
17/01/29 02:47:36,578 INFO StandaloneSchedulerBackend: SchedulerBackend is ready for scheduling beginning after reached minRegisteredResourcesRatio: 0.0
17/01/29 02:47:36,925 INFO MemoryStore: Block broadcast_0 stored as values in memory (estimated size 130.8 KB, free 2.1 GB)
17/01/29 02:47:37,000 INFO MemoryStore: Block broadcast_0_piece0 stored as bytes in memory (estimated size 16.5 KB, free 2.1 GB)
17/01/29 02:47:37,001 INFO BlockManagerInfo: Added broadcast_0_piece0 in memory on 10.1.2.60:44506 (size: 16.5 KB, free: 2.1 GB)
17/01/29 02:47:37,014 INFO SparkContext: Created broadcast 0 from textFile at MLUtils.scala:99
17/01/29 02:47:37,585 INFO FileInputFormat: Total input paths to process : 1
17/01/29 02:47:37,619 INFO NetworkTopology: Adding a new node: /default-rack/10.1.2.97:50010
17/01/29 02:47:37,656 INFO SparkContext: Starting job: first at GeneralizedLinearAlgorithm.scala:246
17/01/29 02:47:37,667 INFO DAGScheduler: Got job 0 (first at GeneralizedLinearAlgorithm.scala:246) with 1 output partitions
17/01/29 02:47:37,667 INFO DAGScheduler: Final stage: ResultStage 0 (first at GeneralizedLinearAlgorithm.scala:246)
17/01/29 02:47:37,668 INFO DAGScheduler: Parents of final stage: List()
17/01/29 02:47:37,674 INFO DAGScheduler: Missing parents: List()
17/01/29 02:47:37,681 INFO DAGScheduler: Submitting ResultStage 0 (MapPartitionsRDD[6] at map at GeneralizedLinearAlgorithm.scala:246), which has no missing parents
17/01/29 02:47:37,699 INFO MemoryStore: Block broadcast_1 stored as values in memory (estimated size 4.2 KB, free 2.1 GB)
17/01/29 02:47:37,701 INFO MemoryStore: Block broadcast_1_piece0 stored as bytes in memory (estimated size 2.4 KB, free 2.1 GB)
17/01/29 02:47:37,702 INFO BlockManagerInfo: Added broadcast_1_piece0 in memory on 10.1.2.60:44506 (size: 2.4 KB, free: 2.1 GB)
17/01/29 02:47:37,703 INFO SparkContext: Created broadcast 1 from broadcast at DAGScheduler.scala:1012
17/01/29 02:47:37,705 INFO DAGScheduler: Submitting 1 missing tasks from ResultStage 0 (MapPartitionsRDD[6] at map at GeneralizedLinearAlgorithm.scala:246)
17/01/29 02:47:37,707 INFO TaskSchedulerImpl: Adding task set 0.0 with 1 tasks
17/01/29 02:47:38,334 INFO CoarseGrainedSchedulerBackend$DriverEndpoint: Registered executor NettyRpcEndpointRef(null) (10.1.2.97:48696) with ID 0
17/01/29 02:47:38,359 INFO TaskSetManager: Starting task 0.0 in stage 0.0 (TID 0, 10.1.2.97, partition 0, ANY, 5454 bytes)
17/01/29 02:47:38,364 INFO CoarseGrainedSchedulerBackend$DriverEndpoint: Launching task 0 on executor id: 0 hostname: 10.1.2.97.
17/01/29 02:47:38,390 INFO BlockManagerMasterEndpoint: Registering block manager 10.1.2.97:42780 with 2.1 GB RAM, BlockManagerId(0, 10.1.2.97, 42780)
17/01/29 02:47:38,684 INFO BlockManagerInfo: Added broadcast_1_piece0 in memory on 10.1.2.97:42780 (size: 2.4 KB, free: 2.1 GB)
17/01/29 02:47:38,844 INFO BlockManagerInfo: Added broadcast_0_piece0 in memory on 10.1.2.97:42780 (size: 16.5 KB, free: 2.1 GB)
17/01/29 02:47:46,109 INFO BlockManagerInfo: Added rdd_5_0 in memory on 10.1.2.97:42780 (size: 70.0 MB, free: 2.0 GB)
17/01/29 02:47:46,166 INFO TaskSetManager: Finished task 0.0 in stage 0.0 (TID 0) in 7826 ms on 10.1.2.97 (1/1)
17/01/29 02:47:46,167 INFO TaskSchedulerImpl: Removed TaskSet 0.0, whose tasks have all completed, from pool 
17/01/29 02:47:46,171 INFO DAGScheduler: ResultStage 0 (first at GeneralizedLinearAlgorithm.scala:246) finished in 8.452 s
17/01/29 02:47:46,176 INFO DAGScheduler: Job 0 finished: first at GeneralizedLinearAlgorithm.scala:246, took 8.519556 s
17/01/29 02:47:46,187 INFO SparkContext: Starting job: count at DataValidators.scala:40
17/01/29 02:47:46,189 INFO DAGScheduler: Got job 1 (count at DataValidators.scala:40) with 59 output partitions
17/01/29 02:47:46,189 INFO DAGScheduler: Final stage: ResultStage 1 (count at DataValidators.scala:40)
17/01/29 02:47:46,189 INFO DAGScheduler: Parents of final stage: List()
17/01/29 02:47:46,192 INFO DAGScheduler: Missing parents: List()
17/01/29 02:47:46,193 INFO DAGScheduler: Submitting ResultStage 1 (MapPartitionsRDD[7] at filter at DataValidators.scala:40), which has no missing parents
17/01/29 02:47:46,214 INFO MemoryStore: Block broadcast_2 stored as values in memory (estimated size 3.9 KB, free 2.1 GB)
17/01/29 02:47:46,216 INFO MemoryStore: Block broadcast_2_piece0 stored as bytes in memory (estimated size 2.2 KB, free 2.1 GB)
17/01/29 02:47:46,217 INFO BlockManagerInfo: Added broadcast_2_piece0 in memory on 10.1.2.60:44506 (size: 2.2 KB, free: 2.1 GB)
17/01/29 02:47:46,218 INFO SparkContext: Created broadcast 2 from broadcast at DAGScheduler.scala:1012
17/01/29 02:47:46,219 INFO DAGScheduler: Submitting 59 missing tasks from ResultStage 1 (MapPartitionsRDD[7] at filter at DataValidators.scala:40)
17/01/29 02:47:46,220 INFO TaskSchedulerImpl: Adding task set 1.0 with 59 tasks
17/01/29 02:47:46,225 INFO TaskSetManager: Starting task 0.0 in stage 1.0 (TID 1, 10.1.2.97, partition 0, PROCESS_LOCAL, 5372 bytes)
17/01/29 02:47:46,228 INFO TaskSetManager: Starting task 58.0 in stage 1.0 (TID 2, 10.1.2.97, partition 58, NODE_LOCAL, 5372 bytes)
17/01/29 02:47:46,228 INFO CoarseGrainedSchedulerBackend$DriverEndpoint: Launching task 1 on executor id: 0 hostname: 10.1.2.97.
17/01/29 02:47:46,229 INFO CoarseGrainedSchedulerBackend$DriverEndpoint: Launching task 2 on executor id: 0 hostname: 10.1.2.97.
17/01/29 02:47:46,251 INFO BlockManagerInfo: Added broadcast_2_piece0 in memory on 10.1.2.97:42780 (size: 2.2 KB, free: 2.0 GB)
17/01/29 02:47:46,327 INFO TaskSetManager: Finished task 0.0 in stage 1.0 (TID 1) in 105 ms on 10.1.2.97 (1/59)
17/01/29 02:47:50,218 INFO TaskSetManager: Starting task 1.0 in stage 1.0 (TID 3, 10.1.2.97, partition 1, ANY, 5372 bytes)
17/01/29 02:47:50,221 INFO TaskSetManager: Starting task 2.0 in stage 1.0 (TID 4, 10.1.2.97, partition 2, ANY, 5372 bytes)
17/01/29 02:47:50,224 INFO TaskSetManager: Starting task 3.0 in stage 1.0 (TID 5, 10.1.2.97, partition 3, ANY, 5372 bytes)
17/01/29 02:47:50,224 INFO CoarseGrainedSchedulerBackend$DriverEndpoint: Launching task 3 on executor id: 0 hostname: 10.1.2.97.
17/01/29 02:47:50,226 INFO CoarseGrainedSchedulerBackend$DriverEndpoint: Launching task 4 on executor id: 0 hostname: 10.1.2.97.
17/01/29 02:47:50,227 INFO CoarseGrainedSchedulerBackend$DriverEndpoint: Launching task 5 on executor id: 0 hostname: 10.1.2.97.
24.513: [GC [PSYoungGen: 1024512K->123912K(1195008K)] 1024512K->123984K(3926016K), 0.0638830 secs] [Times: user=0.11 sys=0.02, real=0.06 secs] 
17/01/29 02:47:59,046 INFO BlockManagerInfo: Removed broadcast_1_piece0 on 10.1.2.60:44506 in memory (size: 2.4 KB, free: 2.1 GB)
17/01/29 02:47:59,061 INFO BlockManagerInfo: Removed broadcast_1_piece0 on 10.1.2.97:42780 in memory (size: 2.4 KB, free: 2.0 GB)
17/01/29 02:47:59,168 INFO BlockManagerInfo: Added rdd_5_58 in memory on 10.1.2.97:42780 (size: 72.8 MB, free: 1977.6 MB)
17/01/29 02:47:59,214 INFO TaskSetManager: Starting task 4.0 in stage 1.0 (TID 6, 10.1.2.97, partition 4, ANY, 5372 bytes)
17/01/29 02:47:59,215 INFO CoarseGrainedSchedulerBackend$DriverEndpoint: Launching task 6 on executor id: 0 hostname: 10.1.2.97.
17/01/29 02:47:59,215 INFO TaskSetManager: Finished task 58.0 in stage 1.0 (TID 2) in 12989 ms on 10.1.2.97 (2/59)
17/01/29 02:48:13,708 INFO BlockManagerInfo: Added rdd_5_3 in memory on 10.1.2.97:42780 (size: 69.9 MB, free: 1907.7 MB)
17/01/29 02:48:13,733 INFO TaskSetManager: Starting task 5.0 in stage 1.0 (TID 7, 10.1.2.97, partition 5, ANY, 5372 bytes)
17/01/29 02:48:13,733 INFO CoarseGrainedSchedulerBackend$DriverEndpoint: Launching task 7 on executor id: 0 hostname: 10.1.2.97.
17/01/29 02:48:13,733 INFO TaskSetManager: Finished task 3.0 in stage 1.0 (TID 5) in 23512 ms on 10.1.2.97 (3/59)
17/01/29 02:48:13,853 INFO BlockManagerInfo: Added rdd_5_1 in memory on 10.1.2.97:42780 (size: 70.0 MB, free: 1837.7 MB)
17/01/29 02:48:13,873 INFO TaskSetManager: Starting task 6.0 in stage 1.0 (TID 8, 10.1.2.97, partition 6, ANY, 5372 bytes)
17/01/29 02:48:13,873 INFO CoarseGrainedSchedulerBackend$DriverEndpoint: Launching task 8 on executor id: 0 hostname: 10.1.2.97.
17/01/29 02:48:13,873 INFO TaskSetManager: Finished task 1.0 in stage 1.0 (TID 3) in 23657 ms on 10.1.2.97 (4/59)
17/01/29 02:48:14,453 INFO BlockManagerInfo: Added rdd_5_2 in memory on 10.1.2.97:42780 (size: 69.9 MB, free: 1767.8 MB)
17/01/29 02:48:14,480 INFO TaskSetManager: Starting task 7.0 in stage 1.0 (TID 9, 10.1.2.97, partition 7, ANY, 5372 bytes)
17/01/29 02:48:14,481 INFO CoarseGrainedSchedulerBackend$DriverEndpoint: Launching task 9 on executor id: 0 hostname: 10.1.2.97.
17/01/29 02:48:14,483 INFO TaskSetManager: Finished task 2.0 in stage 1.0 (TID 4) in 24263 ms on 10.1.2.97 (5/59)
17/01/29 02:48:21,241 INFO BlockManagerInfo: Added rdd_5_4 in memory on 10.1.2.97:42780 (size: 70.0 MB, free: 1697.9 MB)
17/01/29 02:48:21,263 INFO TaskSetManager: Starting task 8.0 in stage 1.0 (TID 10, 10.1.2.97, partition 8, ANY, 5372 bytes)
17/01/29 02:48:21,263 INFO CoarseGrainedSchedulerBackend$DriverEndpoint: Launching task 10 on executor id: 0 hostname: 10.1.2.97.
17/01/29 02:48:21,264 INFO TaskSetManager: Finished task 4.0 in stage 1.0 (TID 6) in 22051 ms on 10.1.2.97 (6/59)
17/01/29 02:48:33,313 INFO BlockManagerInfo: Added rdd_5_6 in memory on 10.1.2.97:42780 (size: 69.9 MB, free: 1627.9 MB)
17/01/29 02:48:33,334 INFO TaskSetManager: Starting task 9.0 in stage 1.0 (TID 11, 10.1.2.97, partition 9, ANY, 5372 bytes)
17/01/29 02:48:33,334 INFO CoarseGrainedSchedulerBackend$DriverEndpoint: Launching task 11 on executor id: 0 hostname: 10.1.2.97.
17/01/29 02:48:33,336 INFO TaskSetManager: Finished task 6.0 in stage 1.0 (TID 8) in 19465 ms on 10.1.2.97 (7/59)
17/01/29 02:48:33,809 INFO BlockManagerInfo: Added rdd_5_5 in memory on 10.1.2.97:42780 (size: 70.0 MB, free: 1557.9 MB)
17/01/29 02:48:33,831 INFO TaskSetManager: Starting task 10.0 in stage 1.0 (TID 12, 10.1.2.97, partition 10, ANY, 5372 bytes)
17/01/29 02:48:33,831 INFO TaskSetManager: Finished task 5.0 in stage 1.0 (TID 7) in 20100 ms on 10.1.2.97 (8/59)
17/01/29 02:48:33,832 INFO CoarseGrainedSchedulerBackend$DriverEndpoint: Launching task 12 on executor id: 0 hostname: 10.1.2.97.
17/01/29 02:48:34,961 INFO BlockManagerInfo: Added rdd_5_7 in memory on 10.1.2.97:42780 (size: 70.0 MB, free: 1488.0 MB)
17/01/29 02:48:34,981 INFO TaskSetManager: Starting task 11.0 in stage 1.0 (TID 13, 10.1.2.97, partition 11, ANY, 5372 bytes)
17/01/29 02:48:34,982 INFO CoarseGrainedSchedulerBackend$DriverEndpoint: Launching task 13 on executor id: 0 hostname: 10.1.2.97.
17/01/29 02:48:34,983 INFO TaskSetManager: Finished task 7.0 in stage 1.0 (TID 9) in 20504 ms on 10.1.2.97 (9/59)
17/01/29 02:48:44,391 INFO BlockManagerInfo: Added rdd_5_8 in memory on 10.1.2.97:42780 (size: 70.0 MB, free: 1418.0 MB)
17/01/29 02:48:44,412 INFO TaskSetManager: Starting task 12.0 in stage 1.0 (TID 14, 10.1.2.97, partition 12, ANY, 5372 bytes)
17/01/29 02:48:44,412 INFO CoarseGrainedSchedulerBackend$DriverEndpoint: Launching task 14 on executor id: 0 hostname: 10.1.2.97.
17/01/29 02:48:44,415 INFO TaskSetManager: Finished task 8.0 in stage 1.0 (TID 10) in 23153 ms on 10.1.2.97 (10/59)
17/01/29 02:48:53,761 INFO BlockManagerInfo: Added rdd_5_10 in memory on 10.1.2.97:42780 (size: 70.0 MB, free: 1348.0 MB)
17/01/29 02:48:53,784 INFO TaskSetManager: Starting task 13.0 in stage 1.0 (TID 15, 10.1.2.97, partition 13, ANY, 5372 bytes)
17/01/29 02:48:53,784 INFO CoarseGrainedSchedulerBackend$DriverEndpoint: Launching task 15 on executor id: 0 hostname: 10.1.2.97.
17/01/29 02:48:53,785 INFO TaskSetManager: Finished task 10.0 in stage 1.0 (TID 12) in 19956 ms on 10.1.2.97 (11/59)
17/01/29 02:48:54,482 INFO BlockManagerInfo: Added rdd_5_9 in memory on 10.1.2.97:42780 (size: 69.9 MB, free: 1278.1 MB)
17/01/29 02:48:54,502 INFO TaskSetManager: Starting task 14.0 in stage 1.0 (TID 16, 10.1.2.97, partition 14, ANY, 5372 bytes)
17/01/29 02:48:54,502 INFO CoarseGrainedSchedulerBackend$DriverEndpoint: Launching task 16 on executor id: 0 hostname: 10.1.2.97.
17/01/29 02:48:54,502 INFO TaskSetManager: Finished task 9.0 in stage 1.0 (TID 11) in 21170 ms on 10.1.2.97 (12/59)
17/01/29 02:48:57,049 INFO BlockManagerInfo: Added rdd_5_11 in memory on 10.1.2.97:42780 (size: 69.9 MB, free: 1208.2 MB)
17/01/29 02:48:57,097 INFO TaskSetManager: Starting task 15.0 in stage 1.0 (TID 17, 10.1.2.97, partition 15, ANY, 5372 bytes)
17/01/29 02:48:57,098 INFO CoarseGrainedSchedulerBackend$DriverEndpoint: Launching task 17 on executor id: 0 hostname: 10.1.2.97.
17/01/29 02:48:57,098 INFO TaskSetManager: Finished task 11.0 in stage 1.0 (TID 13) in 22119 ms on 10.1.2.97 (13/59)
17/01/29 02:49:07,811 INFO BlockManagerInfo: Added rdd_5_12 in memory on 10.1.2.97:42780 (size: 70.0 MB, free: 1138.3 MB)
17/01/29 02:49:07,834 INFO TaskSetManager: Starting task 16.0 in stage 1.0 (TID 18, 10.1.2.97, partition 16, ANY, 5372 bytes)
17/01/29 02:49:07,834 INFO CoarseGrainedSchedulerBackend$DriverEndpoint: Launching task 18 on executor id: 0 hostname: 10.1.2.97.
17/01/29 02:49:07,836 INFO TaskSetManager: Finished task 12.0 in stage 1.0 (TID 14) in 23426 ms on 10.1.2.97 (14/59)
17/01/29 02:49:16,425 INFO BlockManagerInfo: Added rdd_5_14 in memory on 10.1.2.97:42780 (size: 69.9 MB, free: 1068.3 MB)
17/01/29 02:49:16,446 INFO TaskSetManager: Starting task 17.0 in stage 1.0 (TID 19, 10.1.2.97, partition 17, ANY, 5372 bytes)
17/01/29 02:49:16,446 INFO CoarseGrainedSchedulerBackend$DriverEndpoint: Launching task 19 on executor id: 0 hostname: 10.1.2.97.
17/01/29 02:49:16,446 INFO TaskSetManager: Finished task 14.0 in stage 1.0 (TID 16) in 21946 ms on 10.1.2.97 (15/59)
17/01/29 02:49:16,512 INFO BlockManagerInfo: Added rdd_5_13 in memory on 10.1.2.97:42780 (size: 69.9 MB, free: 998.4 MB)
17/01/29 02:49:16,533 INFO TaskSetManager: Starting task 18.0 in stage 1.0 (TID 20, 10.1.2.97, partition 18, ANY, 5372 bytes)
17/01/29 02:49:16,534 INFO CoarseGrainedSchedulerBackend$DriverEndpoint: Launching task 20 on executor id: 0 hostname: 10.1.2.97.
17/01/29 02:49:16,534 INFO TaskSetManager: Finished task 13.0 in stage 1.0 (TID 15) in 22752 ms on 10.1.2.97 (16/59)
17/01/29 02:49:18,813 INFO BlockManagerInfo: Added rdd_5_15 in memory on 10.1.2.97:42780 (size: 69.9 MB, free: 928.5 MB)
17/01/29 02:49:18,842 INFO TaskSetManager: Starting task 19.0 in stage 1.0 (TID 21, 10.1.2.97, partition 19, ANY, 5372 bytes)
17/01/29 02:49:18,843 INFO CoarseGrainedSchedulerBackend$DriverEndpoint: Launching task 21 on executor id: 0 hostname: 10.1.2.97.
17/01/29 02:49:18,844 INFO TaskSetManager: Finished task 15.0 in stage 1.0 (TID 17) in 21749 ms on 10.1.2.97 (17/59)
17/01/29 02:49:29,599 INFO BlockManagerInfo: Added rdd_5_16 in memory on 10.1.2.97:42780 (size: 70.0 MB, free: 858.5 MB)
17/01/29 02:49:29,619 INFO TaskSetManager: Starting task 20.0 in stage 1.0 (TID 22, 10.1.2.97, partition 20, ANY, 5372 bytes)
17/01/29 02:49:29,619 INFO CoarseGrainedSchedulerBackend$DriverEndpoint: Launching task 22 on executor id: 0 hostname: 10.1.2.97.
17/01/29 02:49:29,620 INFO TaskSetManager: Finished task 16.0 in stage 1.0 (TID 18) in 21787 ms on 10.1.2.97 (18/59)
17/01/29 02:49:36,333 INFO BlockManagerInfo: Added rdd_5_17 in memory on 10.1.2.97:42780 (size: 69.9 MB, free: 788.6 MB)
17/01/29 02:49:36,355 INFO TaskSetManager: Starting task 21.0 in stage 1.0 (TID 23, 10.1.2.97, partition 21, ANY, 5372 bytes)
17/01/29 02:49:36,355 INFO TaskSetManager: Finished task 17.0 in stage 1.0 (TID 19) in 19911 ms on 10.1.2.97 (19/59)
17/01/29 02:49:36,356 INFO CoarseGrainedSchedulerBackend$DriverEndpoint: Launching task 23 on executor id: 0 hostname: 10.1.2.97.
17/01/29 02:49:37,528 INFO BlockManagerInfo: Added rdd_5_18 in memory on 10.1.2.97:42780 (size: 70.0 MB, free: 718.7 MB)
17/01/29 02:49:37,549 INFO TaskSetManager: Starting task 22.0 in stage 1.0 (TID 24, 10.1.2.97, partition 22, ANY, 5372 bytes)
17/01/29 02:49:37,549 INFO CoarseGrainedSchedulerBackend$DriverEndpoint: Launching task 24 on executor id: 0 hostname: 10.1.2.97.
17/01/29 02:49:37,550 INFO TaskSetManager: Finished task 18.0 in stage 1.0 (TID 20) in 21018 ms on 10.1.2.97 (20/59)
17/01/29 02:49:39,321 INFO BlockManagerInfo: Added rdd_5_19 in memory on 10.1.2.97:42780 (size: 70.0 MB, free: 648.7 MB)
17/01/29 02:49:39,340 INFO TaskSetManager: Starting task 23.0 in stage 1.0 (TID 25, 10.1.2.97, partition 23, ANY, 5372 bytes)
17/01/29 02:49:39,340 INFO CoarseGrainedSchedulerBackend$DriverEndpoint: Launching task 25 on executor id: 0 hostname: 10.1.2.97.
17/01/29 02:49:39,341 INFO TaskSetManager: Finished task 19.0 in stage 1.0 (TID 21) in 20500 ms on 10.1.2.97 (21/59)
17/01/29 02:49:50,293 INFO BlockManagerInfo: Added rdd_5_20 in memory on 10.1.2.97:42780 (size: 69.8 MB, free: 578.9 MB)
17/01/29 02:49:50,312 INFO TaskSetManager: Starting task 24.0 in stage 1.0 (TID 26, 10.1.2.97, partition 24, ANY, 5372 bytes)
17/01/29 02:49:50,312 INFO CoarseGrainedSchedulerBackend$DriverEndpoint: Launching task 26 on executor id: 0 hostname: 10.1.2.97.
17/01/29 02:49:50,313 INFO TaskSetManager: Finished task 20.0 in stage 1.0 (TID 22) in 20694 ms on 10.1.2.97 (22/59)
17/01/29 02:49:55,567 INFO BlockManagerInfo: Added rdd_5_21 in memory on 10.1.2.97:42780 (size: 69.9 MB, free: 508.9 MB)
17/01/29 02:49:55,610 INFO TaskSetManager: Starting task 25.0 in stage 1.0 (TID 27, 10.1.2.97, partition 25, ANY, 5372 bytes)
17/01/29 02:49:55,611 INFO CoarseGrainedSchedulerBackend$DriverEndpoint: Launching task 27 on executor id: 0 hostname: 10.1.2.97.
17/01/29 02:49:55,611 INFO TaskSetManager: Finished task 21.0 in stage 1.0 (TID 23) in 19259 ms on 10.1.2.97 (23/59)
17/01/29 02:49:56,953 INFO BlockManagerInfo: Added rdd_5_22 in memory on 10.1.2.97:42780 (size: 69.8 MB, free: 439.1 MB)
17/01/29 02:49:56,971 INFO TaskSetManager: Starting task 26.0 in stage 1.0 (TID 28, 10.1.2.97, partition 26, ANY, 5372 bytes)
17/01/29 02:49:56,972 INFO CoarseGrainedSchedulerBackend$DriverEndpoint: Launching task 28 on executor id: 0 hostname: 10.1.2.97.
17/01/29 02:49:56,973 INFO TaskSetManager: Finished task 22.0 in stage 1.0 (TID 24) in 19426 ms on 10.1.2.97 (24/59)
17/01/29 02:49:58,217 INFO BlockManagerInfo: Added rdd_5_23 in memory on 10.1.2.97:42780 (size: 69.9 MB, free: 369.2 MB)
17/01/29 02:49:58,236 INFO TaskSetManager: Starting task 27.0 in stage 1.0 (TID 29, 10.1.2.97, partition 27, ANY, 5372 bytes)
17/01/29 02:49:58,237 INFO CoarseGrainedSchedulerBackend$DriverEndpoint: Launching task 29 on executor id: 0 hostname: 10.1.2.97.
17/01/29 02:49:58,238 INFO TaskSetManager: Finished task 23.0 in stage 1.0 (TID 25) in 18900 ms on 10.1.2.97 (25/59)
17/01/29 02:50:07,725 INFO BlockManagerInfo: Added rdd_5_24 in memory on 10.1.2.97:42780 (size: 69.8 MB, free: 299.4 MB)
17/01/29 02:50:07,745 INFO TaskSetManager: Starting task 28.0 in stage 1.0 (TID 30, 10.1.2.97, partition 28, ANY, 5372 bytes)
17/01/29 02:50:07,745 INFO CoarseGrainedSchedulerBackend$DriverEndpoint: Launching task 30 on executor id: 0 hostname: 10.1.2.97.
17/01/29 02:50:07,746 INFO TaskSetManager: Finished task 24.0 in stage 1.0 (TID 26) in 17434 ms on 10.1.2.97 (26/59)
17/01/29 02:50:13,201 INFO BlockManagerInfo: Added rdd_5_25 in memory on 10.1.2.97:42780 (size: 70.0 MB, free: 229.5 MB)
17/01/29 02:50:13,226 INFO TaskSetManager: Starting task 29.0 in stage 1.0 (TID 31, 10.1.2.97, partition 29, ANY, 5372 bytes)
17/01/29 02:50:13,226 INFO CoarseGrainedSchedulerBackend$DriverEndpoint: Launching task 31 on executor id: 0 hostname: 10.1.2.97.
17/01/29 02:50:13,226 INFO TaskSetManager: Finished task 25.0 in stage 1.0 (TID 27) in 17617 ms on 10.1.2.97 (27/59)
17/01/29 02:50:14,428 INFO BlockManagerInfo: Added rdd_5_26 in memory on 10.1.2.97:42780 (size: 69.9 MB, free: 159.6 MB)
17/01/29 02:50:14,451 INFO TaskSetManager: Starting task 30.0 in stage 1.0 (TID 32, 10.1.2.97, partition 30, ANY, 5372 bytes)
17/01/29 02:50:14,451 INFO CoarseGrainedSchedulerBackend$DriverEndpoint: Launching task 32 on executor id: 0 hostname: 10.1.2.97.
17/01/29 02:50:14,451 INFO TaskSetManager: Finished task 26.0 in stage 1.0 (TID 28) in 17481 ms on 10.1.2.97 (28/59)
17/01/29 02:50:16,305 INFO TaskSetManager: Starting task 31.0 in stage 1.0 (TID 33, 10.1.2.97, partition 31, ANY, 5372 bytes)
17/01/29 02:50:16,306 INFO CoarseGrainedSchedulerBackend$DriverEndpoint: Launching task 33 on executor id: 0 hostname: 10.1.2.97.
17/01/29 02:50:16,307 INFO TaskSetManager: Finished task 27.0 in stage 1.0 (TID 29) in 18072 ms on 10.1.2.97 (29/59)
17/01/29 02:50:26,541 INFO BlockManagerInfo: Added rdd_5_28 in memory on 10.1.2.97:42780 (size: 70.0 MB, free: 89.6 MB)
17/01/29 02:50:26,568 INFO TaskSetManager: Starting task 32.0 in stage 1.0 (TID 34, 10.1.2.97, partition 32, ANY, 5372 bytes)
17/01/29 02:50:26,568 INFO CoarseGrainedSchedulerBackend$DriverEndpoint: Launching task 34 on executor id: 0 hostname: 10.1.2.97.
17/01/29 02:50:26,568 INFO TaskSetManager: Finished task 28.0 in stage 1.0 (TID 30) in 18825 ms on 10.1.2.97 (30/59)
17/01/29 02:50:31,499 INFO TaskSetManager: Starting task 33.0 in stage 1.0 (TID 35, 10.1.2.97, partition 33, ANY, 5372 bytes)
17/01/29 02:50:31,499 INFO CoarseGrainedSchedulerBackend$DriverEndpoint: Launching task 35 on executor id: 0 hostname: 10.1.2.97.
17/01/29 02:50:31,500 INFO TaskSetManager: Finished task 29.0 in stage 1.0 (TID 31) in 18276 ms on 10.1.2.97 (31/59)
17/01/29 02:50:35,902 INFO TaskSetManager: Starting task 34.0 in stage 1.0 (TID 36, 10.1.2.97, partition 34, ANY, 5372 bytes)
17/01/29 02:50:35,902 INFO CoarseGrainedSchedulerBackend$DriverEndpoint: Launching task 36 on executor id: 0 hostname: 10.1.2.97.
17/01/29 02:50:35,903 INFO TaskSetManager: Finished task 31.0 in stage 1.0 (TID 33) in 19599 ms on 10.1.2.97 (32/59)
17/01/29 02:50:36,178 INFO TaskSetManager: Starting task 35.0 in stage 1.0 (TID 37, 10.1.2.97, partition 35, ANY, 5372 bytes)
17/01/29 02:50:36,179 INFO CoarseGrainedSchedulerBackend$DriverEndpoint: Launching task 37 on executor id: 0 hostname: 10.1.2.97.
17/01/29 02:50:36,179 INFO TaskSetManager: Finished task 30.0 in stage 1.0 (TID 32) in 21730 ms on 10.1.2.97 (33/59)
17/01/29 02:50:45,557 INFO TaskSetManager: Starting task 36.0 in stage 1.0 (TID 38, 10.1.2.97, partition 36, ANY, 5372 bytes)
17/01/29 02:50:45,557 INFO CoarseGrainedSchedulerBackend$DriverEndpoint: Launching task 38 on executor id: 0 hostname: 10.1.2.97.
17/01/29 02:50:45,558 INFO TaskSetManager: Finished task 32.0 in stage 1.0 (TID 34) in 18992 ms on 10.1.2.97 (34/59)
17/01/29 02:50:49,260 INFO TaskSetManager: Starting task 37.0 in stage 1.0 (TID 39, 10.1.2.97, partition 37, ANY, 5372 bytes)
17/01/29 02:50:49,260 INFO CoarseGrainedSchedulerBackend$DriverEndpoint: Launching task 39 on executor id: 0 hostname: 10.1.2.97.
17/01/29 02:50:49,261 INFO TaskSetManager: Finished task 33.0 in stage 1.0 (TID 35) in 17762 ms on 10.1.2.97 (35/59)
17/01/29 02:50:53,609 INFO TaskSetManager: Starting task 38.0 in stage 1.0 (TID 40, 10.1.2.97, partition 38, ANY, 5372 bytes)
17/01/29 02:50:53,610 INFO CoarseGrainedSchedulerBackend$DriverEndpoint: Launching task 40 on executor id: 0 hostname: 10.1.2.97.
17/01/29 02:50:53,610 INFO TaskSetManager: Finished task 34.0 in stage 1.0 (TID 36) in 17709 ms on 10.1.2.97 (36/59)
17/01/29 02:50:54,180 INFO TaskSetManager: Starting task 39.0 in stage 1.0 (TID 41, 10.1.2.97, partition 39, ANY, 5372 bytes)
17/01/29 02:50:54,181 INFO CoarseGrainedSchedulerBackend$DriverEndpoint: Launching task 41 on executor id: 0 hostname: 10.1.2.97.
17/01/29 02:50:54,182 INFO TaskSetManager: Finished task 35.0 in stage 1.0 (TID 37) in 18004 ms on 10.1.2.97 (37/59)
17/01/29 02:51:04,733 INFO TaskSetManager: Starting task 40.0 in stage 1.0 (TID 42, 10.1.2.97, partition 40, ANY, 5372 bytes)
17/01/29 02:51:04,734 INFO CoarseGrainedSchedulerBackend$DriverEndpoint: Launching task 42 on executor id: 0 hostname: 10.1.2.97.
17/01/29 02:51:04,735 INFO TaskSetManager: Finished task 36.0 in stage 1.0 (TID 38) in 19179 ms on 10.1.2.97 (38/59)
17/01/29 02:51:13,581 INFO TaskSetManager: Starting task 41.0 in stage 1.0 (TID 43, 10.1.2.97, partition 41, ANY, 5372 bytes)
17/01/29 02:51:13,582 INFO CoarseGrainedSchedulerBackend$DriverEndpoint: Launching task 43 on executor id: 0 hostname: 10.1.2.97.
17/01/29 02:51:13,582 INFO TaskSetManager: Finished task 37.0 in stage 1.0 (TID 39) in 24324 ms on 10.1.2.97 (39/59)
17/01/29 02:51:16,686 INFO TaskSetManager: Starting task 42.0 in stage 1.0 (TID 44, 10.1.2.97, partition 42, ANY, 5372 bytes)
17/01/29 02:51:16,686 INFO CoarseGrainedSchedulerBackend$DriverEndpoint: Launching task 44 on executor id: 0 hostname: 10.1.2.97.
17/01/29 02:51:16,687 INFO TaskSetManager: Finished task 39.0 in stage 1.0 (TID 41) in 22508 ms on 10.1.2.97 (40/59)
17/01/29 02:51:16,838 INFO TaskSetManager: Starting task 43.0 in stage 1.0 (TID 45, 10.1.2.97, partition 43, ANY, 5372 bytes)
17/01/29 02:51:16,838 INFO CoarseGrainedSchedulerBackend$DriverEndpoint: Launching task 45 on executor id: 0 hostname: 10.1.2.97.
17/01/29 02:51:16,839 INFO TaskSetManager: Finished task 38.0 in stage 1.0 (TID 40) in 23231 ms on 10.1.2.97 (41/59)
17/01/29 02:51:34,242 INFO TaskSetManager: Starting task 44.0 in stage 1.0 (TID 46, 10.1.2.97, partition 44, ANY, 5372 bytes)
17/01/29 02:51:34,242 INFO CoarseGrainedSchedulerBackend$DriverEndpoint: Launching task 46 on executor id: 0 hostname: 10.1.2.97.
17/01/29 02:51:34,243 INFO TaskSetManager: Finished task 40.0 in stage 1.0 (TID 42) in 29511 ms on 10.1.2.97 (42/59)
17/01/29 02:51:35,633 INFO TaskSetManager: Starting task 45.0 in stage 1.0 (TID 47, 10.1.2.97, partition 45, ANY, 5372 bytes)
17/01/29 02:51:35,634 INFO CoarseGrainedSchedulerBackend$DriverEndpoint: Launching task 47 on executor id: 0 hostname: 10.1.2.97.
17/01/29 02:51:35,634 INFO TaskSetManager: Finished task 41.0 in stage 1.0 (TID 43) in 22054 ms on 10.1.2.97 (43/59)
17/01/29 02:51:40,563 INFO TaskSetManager: Starting task 46.0 in stage 1.0 (TID 48, 10.1.2.97, partition 46, ANY, 5372 bytes)
17/01/29 02:51:40,563 INFO CoarseGrainedSchedulerBackend$DriverEndpoint: Launching task 48 on executor id: 0 hostname: 10.1.2.97.
17/01/29 02:51:40,564 INFO TaskSetManager: Finished task 43.0 in stage 1.0 (TID 45) in 23726 ms on 10.1.2.97 (44/59)
17/01/29 02:51:43,287 INFO TaskSetManager: Starting task 47.0 in stage 1.0 (TID 49, 10.1.2.97, partition 47, ANY, 5372 bytes)
17/01/29 02:51:43,287 INFO CoarseGrainedSchedulerBackend$DriverEndpoint: Launching task 49 on executor id: 0 hostname: 10.1.2.97.
17/01/29 02:51:43,288 INFO TaskSetManager: Finished task 42.0 in stage 1.0 (TID 44) in 26603 ms on 10.1.2.97 (45/59)
17/01/29 02:51:59,057 INFO TaskSetManager: Starting task 48.0 in stage 1.0 (TID 50, 10.1.2.97, partition 48, ANY, 5372 bytes)
17/01/29 02:51:59,058 INFO CoarseGrainedSchedulerBackend$DriverEndpoint: Launching task 50 on executor id: 0 hostname: 10.1.2.97.
17/01/29 02:51:59,058 INFO TaskSetManager: Finished task 44.0 in stage 1.0 (TID 46) in 24817 ms on 10.1.2.97 (46/59)
17/01/29 02:52:00,571 INFO TaskSetManager: Starting task 49.0 in stage 1.0 (TID 51, 10.1.2.97, partition 49, ANY, 5372 bytes)
17/01/29 02:52:00,571 INFO CoarseGrainedSchedulerBackend$DriverEndpoint: Launching task 51 on executor id: 0 hostname: 10.1.2.97.
17/01/29 02:52:00,572 INFO TaskSetManager: Finished task 45.0 in stage 1.0 (TID 47) in 24939 ms on 10.1.2.97 (47/59)
17/01/29 02:52:03,842 INFO TaskSetManager: Starting task 50.0 in stage 1.0 (TID 52, 10.1.2.97, partition 50, ANY, 5372 bytes)
17/01/29 02:52:03,843 INFO CoarseGrainedSchedulerBackend$DriverEndpoint: Launching task 52 on executor id: 0 hostname: 10.1.2.97.
17/01/29 02:52:03,843 INFO TaskSetManager: Finished task 47.0 in stage 1.0 (TID 49) in 20557 ms on 10.1.2.97 (48/59)
17/01/29 02:52:05,293 INFO TaskSetManager: Starting task 51.0 in stage 1.0 (TID 53, 10.1.2.97, partition 51, ANY, 5372 bytes)
17/01/29 02:52:05,294 INFO CoarseGrainedSchedulerBackend$DriverEndpoint: Launching task 53 on executor id: 0 hostname: 10.1.2.97.
17/01/29 02:52:05,294 INFO TaskSetManager: Finished task 46.0 in stage 1.0 (TID 48) in 24732 ms on 10.1.2.97 (49/59)
17/01/29 02:52:16,673 INFO TaskSetManager: Starting task 52.0 in stage 1.0 (TID 54, 10.1.2.97, partition 52, ANY, 5372 bytes)
17/01/29 02:52:16,673 INFO CoarseGrainedSchedulerBackend$DriverEndpoint: Launching task 54 on executor id: 0 hostname: 10.1.2.97.
17/01/29 02:52:16,674 INFO TaskSetManager: Finished task 48.0 in stage 1.0 (TID 50) in 17617 ms on 10.1.2.97 (50/59)
17/01/29 02:52:17,731 INFO TaskSetManager: Starting task 53.0 in stage 1.0 (TID 55, 10.1.2.97, partition 53, ANY, 5372 bytes)
17/01/29 02:52:17,731 INFO CoarseGrainedSchedulerBackend$DriverEndpoint: Launching task 55 on executor id: 0 hostname: 10.1.2.97.
17/01/29 02:52:17,732 INFO TaskSetManager: Finished task 49.0 in stage 1.0 (TID 51) in 17162 ms on 10.1.2.97 (51/59)
17/01/29 02:52:22,037 INFO TaskSetManager: Starting task 54.0 in stage 1.0 (TID 56, 10.1.2.97, partition 54, ANY, 5372 bytes)
17/01/29 02:52:22,038 INFO CoarseGrainedSchedulerBackend$DriverEndpoint: Launching task 56 on executor id: 0 hostname: 10.1.2.97.
17/01/29 02:52:22,038 INFO TaskSetManager: Finished task 50.0 in stage 1.0 (TID 52) in 18197 ms on 10.1.2.97 (52/59)
17/01/29 02:52:22,653 INFO TaskSetManager: Starting task 55.0 in stage 1.0 (TID 57, 10.1.2.97, partition 55, ANY, 5372 bytes)
17/01/29 02:52:22,653 INFO CoarseGrainedSchedulerBackend$DriverEndpoint: Launching task 57 on executor id: 0 hostname: 10.1.2.97.
17/01/29 02:52:22,654 INFO TaskSetManager: Finished task 51.0 in stage 1.0 (TID 53) in 17362 ms on 10.1.2.97 (53/59)
17/01/29 02:52:34,089 INFO TaskSetManager: Starting task 56.0 in stage 1.0 (TID 58, 10.1.2.97, partition 56, ANY, 5372 bytes)
17/01/29 02:52:34,090 INFO CoarseGrainedSchedulerBackend$DriverEndpoint: Launching task 58 on executor id: 0 hostname: 10.1.2.97.
17/01/29 02:52:34,090 INFO TaskSetManager: Finished task 52.0 in stage 1.0 (TID 54) in 17418 ms on 10.1.2.97 (54/59)
17/01/29 02:52:35,316 INFO TaskSetManager: Starting task 57.0 in stage 1.0 (TID 59, 10.1.2.97, partition 57, ANY, 5372 bytes)
17/01/29 02:52:35,316 INFO CoarseGrainedSchedulerBackend$DriverEndpoint: Launching task 59 on executor id: 0 hostname: 10.1.2.97.
17/01/29 02:52:35,317 INFO TaskSetManager: Finished task 53.0 in stage 1.0 (TID 55) in 17587 ms on 10.1.2.97 (55/59)
17/01/29 02:52:39,068 INFO TaskSetManager: Finished task 54.0 in stage 1.0 (TID 56) in 17032 ms on 10.1.2.97 (56/59)
17/01/29 02:52:39,077 INFO TaskSetManager: Finished task 55.0 in stage 1.0 (TID 57) in 16425 ms on 10.1.2.97 (57/59)
17/01/29 02:52:44,035 INFO TaskSetManager: Finished task 56.0 in stage 1.0 (TID 58) in 9946 ms on 10.1.2.97 (58/59)
17/01/29 02:52:44,528 INFO TaskSetManager: Finished task 57.0 in stage 1.0 (TID 59) in 9213 ms on 10.1.2.97 (59/59)
17/01/29 02:52:44,528 INFO TaskSchedulerImpl: Removed TaskSet 1.0, whose tasks have all completed, from pool 
17/01/29 02:52:44,529 INFO DAGScheduler: ResultStage 1 (count at DataValidators.scala:40) finished in 298.307 s
17/01/29 02:52:44,529 INFO DAGScheduler: Job 1 finished: count at DataValidators.scala:40, took 298.341811 s
17/01/29 02:52:44,540 INFO SparkContext: Starting job: count at GradientDescent.scala:209
17/01/29 02:52:44,542 INFO DAGScheduler: Got job 2 (count at GradientDescent.scala:209) with 59 output partitions
17/01/29 02:52:44,542 INFO DAGScheduler: Final stage: ResultStage 2 (count at GradientDescent.scala:209)
17/01/29 02:52:44,543 INFO DAGScheduler: Parents of final stage: List()
17/01/29 02:52:44,547 INFO DAGScheduler: Missing parents: List()
17/01/29 02:52:44,548 INFO DAGScheduler: Submitting ResultStage 2 (MapPartitionsRDD[8] at map at GeneralizedLinearAlgorithm.scala:297), which has no missing parents
17/01/29 02:52:44,559 INFO MemoryStore: Block broadcast_3 stored as values in memory (estimated size 3.9 KB, free 2.1 GB)
17/01/29 02:52:44,561 INFO MemoryStore: Block broadcast_3_piece0 stored as bytes in memory (estimated size 2.2 KB, free 2.1 GB)
17/01/29 02:52:44,562 INFO BlockManagerInfo: Added broadcast_3_piece0 in memory on 10.1.2.60:44506 (size: 2.2 KB, free: 2.1 GB)
17/01/29 02:52:44,563 INFO SparkContext: Created broadcast 3 from broadcast at DAGScheduler.scala:1012
17/01/29 02:52:44,564 INFO DAGScheduler: Submitting 59 missing tasks from ResultStage 2 (MapPartitionsRDD[8] at map at GeneralizedLinearAlgorithm.scala:297)
17/01/29 02:52:44,565 INFO TaskSchedulerImpl: Adding task set 2.0 with 59 tasks
17/01/29 02:52:44,568 INFO TaskSetManager: Starting task 0.0 in stage 2.0 (TID 60, 10.1.2.97, partition 0, PROCESS_LOCAL, 5372 bytes)
17/01/29 02:52:44,569 INFO TaskSetManager: Starting task 1.0 in stage 2.0 (TID 61, 10.1.2.97, partition 1, PROCESS_LOCAL, 5372 bytes)
17/01/29 02:52:44,569 INFO TaskSetManager: Starting task 2.0 in stage 2.0 (TID 62, 10.1.2.97, partition 2, PROCESS_LOCAL, 5372 bytes)
17/01/29 02:52:44,570 INFO TaskSetManager: Starting task 3.0 in stage 2.0 (TID 63, 10.1.2.97, partition 3, PROCESS_LOCAL, 5372 bytes)
17/01/29 02:52:44,571 INFO CoarseGrainedSchedulerBackend$DriverEndpoint: Launching task 60 on executor id: 0 hostname: 10.1.2.97.
17/01/29 02:52:44,571 INFO CoarseGrainedSchedulerBackend$DriverEndpoint: Launching task 61 on executor id: 0 hostname: 10.1.2.97.
17/01/29 02:52:44,573 INFO CoarseGrainedSchedulerBackend$DriverEndpoint: Launching task 62 on executor id: 0 hostname: 10.1.2.97.
17/01/29 02:52:44,573 INFO CoarseGrainedSchedulerBackend$DriverEndpoint: Launching task 63 on executor id: 0 hostname: 10.1.2.97.
17/01/29 02:52:44,594 INFO BlockManagerInfo: Added broadcast_3_piece0 in memory on 10.1.2.97:42780 (size: 2.2 KB, free: 89.6 MB)
17/01/29 02:52:44,636 INFO TaskSetManager: Starting task 4.0 in stage 2.0 (TID 64, 10.1.2.97, partition 4, PROCESS_LOCAL, 5372 bytes)
17/01/29 02:52:44,636 INFO CoarseGrainedSchedulerBackend$DriverEndpoint: Launching task 64 on executor id: 0 hostname: 10.1.2.97.
17/01/29 02:52:44,637 INFO TaskSetManager: Finished task 2.0 in stage 2.0 (TID 62) in 67 ms on 10.1.2.97 (1/59)
17/01/29 02:52:44,639 INFO TaskSetManager: Finished task 0.0 in stage 2.0 (TID 60) in 73 ms on 10.1.2.97 (2/59)
17/01/29 02:52:44,641 INFO TaskSetManager: Starting task 5.0 in stage 2.0 (TID 65, 10.1.2.97, partition 5, PROCESS_LOCAL, 5372 bytes)
17/01/29 02:52:44,641 INFO CoarseGrainedSchedulerBackend$DriverEndpoint: Launching task 65 on executor id: 0 hostname: 10.1.2.97.
17/01/29 02:52:44,642 INFO TaskSetManager: Finished task 3.0 in stage 2.0 (TID 63) in 72 ms on 10.1.2.97 (3/59)
17/01/29 02:52:44,644 INFO TaskSetManager: Starting task 6.0 in stage 2.0 (TID 66, 10.1.2.97, partition 6, PROCESS_LOCAL, 5372 bytes)
17/01/29 02:52:44,645 INFO CoarseGrainedSchedulerBackend$DriverEndpoint: Launching task 66 on executor id: 0 hostname: 10.1.2.97.
17/01/29 02:52:44,660 INFO TaskSetManager: Starting task 7.0 in stage 2.0 (TID 67, 10.1.2.97, partition 7, PROCESS_LOCAL, 5372 bytes)
17/01/29 02:52:44,661 INFO CoarseGrainedSchedulerBackend$DriverEndpoint: Launching task 67 on executor id: 0 hostname: 10.1.2.97.
17/01/29 02:52:44,661 INFO TaskSetManager: Finished task 1.0 in stage 2.0 (TID 61) in 93 ms on 10.1.2.97 (4/59)
17/01/29 02:52:44,676 INFO TaskSetManager: Starting task 8.0 in stage 2.0 (TID 68, 10.1.2.97, partition 8, PROCESS_LOCAL, 5372 bytes)
17/01/29 02:52:44,676 INFO CoarseGrainedSchedulerBackend$DriverEndpoint: Launching task 68 on executor id: 0 hostname: 10.1.2.97.
17/01/29 02:52:44,677 INFO TaskSetManager: Finished task 5.0 in stage 2.0 (TID 65) in 36 ms on 10.1.2.97 (5/59)
17/01/29 02:52:44,682 INFO TaskSetManager: Starting task 9.0 in stage 2.0 (TID 69, 10.1.2.97, partition 9, PROCESS_LOCAL, 5372 bytes)
17/01/29 02:52:44,682 INFO CoarseGrainedSchedulerBackend$DriverEndpoint: Launching task 69 on executor id: 0 hostname: 10.1.2.97.
17/01/29 02:52:44,682 INFO TaskSetManager: Finished task 6.0 in stage 2.0 (TID 66) in 39 ms on 10.1.2.97 (6/59)
17/01/29 02:52:44,685 INFO TaskSetManager: Starting task 10.0 in stage 2.0 (TID 70, 10.1.2.97, partition 10, PROCESS_LOCAL, 5372 bytes)
17/01/29 02:52:44,687 INFO CoarseGrainedSchedulerBackend$DriverEndpoint: Launching task 70 on executor id: 0 hostname: 10.1.2.97.
17/01/29 02:52:44,687 INFO TaskSetManager: Finished task 4.0 in stage 2.0 (TID 64) in 52 ms on 10.1.2.97 (7/59)
17/01/29 02:52:44,700 INFO TaskSetManager: Starting task 11.0 in stage 2.0 (TID 71, 10.1.2.97, partition 11, PROCESS_LOCAL, 5372 bytes)
17/01/29 02:52:44,700 INFO CoarseGrainedSchedulerBackend$DriverEndpoint: Launching task 71 on executor id: 0 hostname: 10.1.2.97.
17/01/29 02:52:44,701 INFO TaskSetManager: Finished task 7.0 in stage 2.0 (TID 67) in 40 ms on 10.1.2.97 (8/59)
17/01/29 02:52:44,710 INFO TaskSetManager: Starting task 12.0 in stage 2.0 (TID 72, 10.1.2.97, partition 12, PROCESS_LOCAL, 5372 bytes)
17/01/29 02:52:44,710 INFO TaskSetManager: Finished task 8.0 in stage 2.0 (TID 68) in 35 ms on 10.1.2.97 (9/59)
17/01/29 02:52:44,710 INFO CoarseGrainedSchedulerBackend$DriverEndpoint: Launching task 72 on executor id: 0 hostname: 10.1.2.97.
17/01/29 02:52:44,723 INFO TaskSetManager: Starting task 13.0 in stage 2.0 (TID 73, 10.1.2.97, partition 13, PROCESS_LOCAL, 5372 bytes)
17/01/29 02:52:44,724 INFO CoarseGrainedSchedulerBackend$DriverEndpoint: Launching task 73 on executor id: 0 hostname: 10.1.2.97.
17/01/29 02:52:44,724 INFO TaskSetManager: Finished task 10.0 in stage 2.0 (TID 70) in 40 ms on 10.1.2.97 (10/59)
17/01/29 02:52:44,727 INFO TaskSetManager: Starting task 14.0 in stage 2.0 (TID 74, 10.1.2.97, partition 14, PROCESS_LOCAL, 5372 bytes)
17/01/29 02:52:44,727 INFO CoarseGrainedSchedulerBackend$DriverEndpoint: Launching task 74 on executor id: 0 hostname: 10.1.2.97.
17/01/29 02:52:44,729 INFO TaskSetManager: Starting task 15.0 in stage 2.0 (TID 75, 10.1.2.97, partition 15, PROCESS_LOCAL, 5372 bytes)
17/01/29 02:52:44,729 INFO CoarseGrainedSchedulerBackend$DriverEndpoint: Launching task 75 on executor id: 0 hostname: 10.1.2.97.
17/01/29 02:52:44,729 INFO TaskSetManager: Finished task 9.0 in stage 2.0 (TID 69) in 48 ms on 10.1.2.97 (11/59)
17/01/29 02:52:44,730 INFO TaskSetManager: Finished task 11.0 in stage 2.0 (TID 71) in 31 ms on 10.1.2.97 (12/59)
17/01/29 02:52:44,746 INFO TaskSetManager: Starting task 16.0 in stage 2.0 (TID 76, 10.1.2.97, partition 16, PROCESS_LOCAL, 5372 bytes)
17/01/29 02:52:44,746 INFO CoarseGrainedSchedulerBackend$DriverEndpoint: Launching task 76 on executor id: 0 hostname: 10.1.2.97.
17/01/29 02:52:44,747 INFO TaskSetManager: Finished task 12.0 in stage 2.0 (TID 72) in 37 ms on 10.1.2.97 (13/59)
17/01/29 02:52:44,770 INFO TaskSetManager: Starting task 17.0 in stage 2.0 (TID 77, 10.1.2.97, partition 17, PROCESS_LOCAL, 5372 bytes)
17/01/29 02:52:44,770 INFO CoarseGrainedSchedulerBackend$DriverEndpoint: Launching task 77 on executor id: 0 hostname: 10.1.2.97.
17/01/29 02:52:44,770 INFO TaskSetManager: Finished task 13.0 in stage 2.0 (TID 73) in 47 ms on 10.1.2.97 (14/59)
17/01/29 02:52:44,774 INFO TaskSetManager: Starting task 18.0 in stage 2.0 (TID 78, 10.1.2.97, partition 18, PROCESS_LOCAL, 5372 bytes)
17/01/29 02:52:44,774 INFO TaskSetManager: Finished task 15.0 in stage 2.0 (TID 75) in 46 ms on 10.1.2.97 (15/59)
17/01/29 02:52:44,775 INFO CoarseGrainedSchedulerBackend$DriverEndpoint: Launching task 78 on executor id: 0 hostname: 10.1.2.97.
17/01/29 02:52:44,777 INFO TaskSetManager: Starting task 19.0 in stage 2.0 (TID 79, 10.1.2.97, partition 19, PROCESS_LOCAL, 5372 bytes)
17/01/29 02:52:44,777 INFO CoarseGrainedSchedulerBackend$DriverEndpoint: Launching task 79 on executor id: 0 hostname: 10.1.2.97.
17/01/29 02:52:44,777 INFO TaskSetManager: Finished task 14.0 in stage 2.0 (TID 74) in 51 ms on 10.1.2.97 (16/59)
17/01/29 02:52:44,795 INFO TaskSetManager: Starting task 20.0 in stage 2.0 (TID 80, 10.1.2.97, partition 20, PROCESS_LOCAL, 5372 bytes)
17/01/29 02:52:44,795 INFO CoarseGrainedSchedulerBackend$DriverEndpoint: Launching task 80 on executor id: 0 hostname: 10.1.2.97.
17/01/29 02:52:44,796 INFO TaskSetManager: Finished task 16.0 in stage 2.0 (TID 76) in 51 ms on 10.1.2.97 (17/59)
17/01/29 02:52:44,803 INFO TaskSetManager: Starting task 21.0 in stage 2.0 (TID 81, 10.1.2.97, partition 21, PROCESS_LOCAL, 5372 bytes)
17/01/29 02:52:44,803 INFO CoarseGrainedSchedulerBackend$DriverEndpoint: Launching task 81 on executor id: 0 hostname: 10.1.2.97.
17/01/29 02:52:44,804 INFO TaskSetManager: Finished task 17.0 in stage 2.0 (TID 77) in 34 ms on 10.1.2.97 (18/59)
17/01/29 02:52:44,813 INFO TaskSetManager: Starting task 22.0 in stage 2.0 (TID 82, 10.1.2.97, partition 22, PROCESS_LOCAL, 5372 bytes)
17/01/29 02:52:44,814 INFO CoarseGrainedSchedulerBackend$DriverEndpoint: Launching task 82 on executor id: 0 hostname: 10.1.2.97.
17/01/29 02:52:44,814 INFO TaskSetManager: Finished task 19.0 in stage 2.0 (TID 79) in 38 ms on 10.1.2.97 (19/59)
17/01/29 02:52:44,827 INFO TaskSetManager: Starting task 23.0 in stage 2.0 (TID 83, 10.1.2.97, partition 23, PROCESS_LOCAL, 5372 bytes)
17/01/29 02:52:44,827 INFO CoarseGrainedSchedulerBackend$DriverEndpoint: Launching task 83 on executor id: 0 hostname: 10.1.2.97.
17/01/29 02:52:44,827 INFO TaskSetManager: Finished task 18.0 in stage 2.0 (TID 78) in 54 ms on 10.1.2.97 (20/59)
17/01/29 02:52:44,833 INFO TaskSetManager: Starting task 24.0 in stage 2.0 (TID 84, 10.1.2.97, partition 24, PROCESS_LOCAL, 5372 bytes)
17/01/29 02:52:44,834 INFO CoarseGrainedSchedulerBackend$DriverEndpoint: Launching task 84 on executor id: 0 hostname: 10.1.2.97.
17/01/29 02:52:44,834 INFO TaskSetManager: Finished task 20.0 in stage 2.0 (TID 80) in 40 ms on 10.1.2.97 (21/59)
17/01/29 02:52:44,838 INFO TaskSetManager: Starting task 25.0 in stage 2.0 (TID 85, 10.1.2.97, partition 25, PROCESS_LOCAL, 5372 bytes)
17/01/29 02:52:44,838 INFO CoarseGrainedSchedulerBackend$DriverEndpoint: Launching task 85 on executor id: 0 hostname: 10.1.2.97.
17/01/29 02:52:44,839 INFO TaskSetManager: Finished task 21.0 in stage 2.0 (TID 81) in 37 ms on 10.1.2.97 (22/59)
17/01/29 02:52:44,876 INFO TaskSetManager: Starting task 26.0 in stage 2.0 (TID 86, 10.1.2.97, partition 26, PROCESS_LOCAL, 5372 bytes)
17/01/29 02:52:44,876 INFO CoarseGrainedSchedulerBackend$DriverEndpoint: Launching task 86 on executor id: 0 hostname: 10.1.2.97.
17/01/29 02:52:44,876 INFO TaskSetManager: Finished task 22.0 in stage 2.0 (TID 82) in 63 ms on 10.1.2.97 (23/59)
17/01/29 02:52:44,879 INFO TaskSetManager: Starting task 28.0 in stage 2.0 (TID 87, 10.1.2.97, partition 28, PROCESS_LOCAL, 5372 bytes)
17/01/29 02:52:44,879 INFO CoarseGrainedSchedulerBackend$DriverEndpoint: Launching task 87 on executor id: 0 hostname: 10.1.2.97.
17/01/29 02:52:44,879 INFO TaskSetManager: Finished task 24.0 in stage 2.0 (TID 84) in 46 ms on 10.1.2.97 (24/59)
17/01/29 02:52:44,887 INFO TaskSetManager: Starting task 58.0 in stage 2.0 (TID 88, 10.1.2.97, partition 58, PROCESS_LOCAL, 5372 bytes)
17/01/29 02:52:44,887 INFO CoarseGrainedSchedulerBackend$DriverEndpoint: Launching task 88 on executor id: 0 hostname: 10.1.2.97.
17/01/29 02:52:44,888 INFO TaskSetManager: Finished task 23.0 in stage 2.0 (TID 83) in 61 ms on 10.1.2.97 (25/59)
17/01/29 02:52:44,903 INFO TaskSetManager: Finished task 25.0 in stage 2.0 (TID 85) in 66 ms on 10.1.2.97 (26/59)
17/01/29 02:52:44,914 INFO TaskSetManager: Finished task 28.0 in stage 2.0 (TID 87) in 36 ms on 10.1.2.97 (27/59)
17/01/29 02:52:44,916 INFO TaskSetManager: Finished task 26.0 in stage 2.0 (TID 86) in 41 ms on 10.1.2.97 (28/59)
17/01/29 02:52:44,922 INFO TaskSetManager: Finished task 58.0 in stage 2.0 (TID 88) in 35 ms on 10.1.2.97 (29/59)
17/01/29 02:52:48,217 INFO TaskSetManager: Starting task 27.0 in stage 2.0 (TID 89, 10.1.2.97, partition 27, ANY, 5372 bytes)
17/01/29 02:52:48,217 INFO TaskSetManager: Starting task 29.0 in stage 2.0 (TID 90, 10.1.2.97, partition 29, ANY, 5372 bytes)
17/01/29 02:52:48,218 INFO TaskSetManager: Starting task 30.0 in stage 2.0 (TID 91, 10.1.2.97, partition 30, ANY, 5372 bytes)
17/01/29 02:52:48,219 INFO TaskSetManager: Starting task 31.0 in stage 2.0 (TID 92, 10.1.2.97, partition 31, ANY, 5372 bytes)
17/01/29 02:52:48,219 INFO CoarseGrainedSchedulerBackend$DriverEndpoint: Launching task 89 on executor id: 0 hostname: 10.1.2.97.
17/01/29 02:52:48,219 INFO CoarseGrainedSchedulerBackend$DriverEndpoint: Launching task 90 on executor id: 0 hostname: 10.1.2.97.
17/01/29 02:52:48,220 INFO CoarseGrainedSchedulerBackend$DriverEndpoint: Launching task 91 on executor id: 0 hostname: 10.1.2.97.
17/01/29 02:52:48,220 INFO CoarseGrainedSchedulerBackend$DriverEndpoint: Launching task 92 on executor id: 0 hostname: 10.1.2.97.
17/01/29 02:53:06,165 INFO TaskSetManager: Starting task 32.0 in stage 2.0 (TID 93, 10.1.2.97, partition 32, ANY, 5372 bytes)
17/01/29 02:53:06,165 INFO CoarseGrainedSchedulerBackend$DriverEndpoint: Launching task 93 on executor id: 0 hostname: 10.1.2.97.
17/01/29 02:53:06,165 INFO TaskSetManager: Finished task 30.0 in stage 2.0 (TID 91) in 17948 ms on 10.1.2.97 (30/59)
17/01/29 02:53:07,908 INFO TaskSetManager: Starting task 33.0 in stage 2.0 (TID 94, 10.1.2.97, partition 33, ANY, 5372 bytes)
17/01/29 02:53:07,908 INFO CoarseGrainedSchedulerBackend$DriverEndpoint: Launching task 94 on executor id: 0 hostname: 10.1.2.97.
17/01/29 02:53:07,909 INFO TaskSetManager: Finished task 27.0 in stage 2.0 (TID 89) in 19692 ms on 10.1.2.97 (31/59)
17/01/29 02:53:08,151 INFO TaskSetManager: Starting task 34.0 in stage 2.0 (TID 95, 10.1.2.97, partition 34, ANY, 5372 bytes)
17/01/29 02:53:08,151 INFO CoarseGrainedSchedulerBackend$DriverEndpoint: Launching task 95 on executor id: 0 hostname: 10.1.2.97.
17/01/29 02:53:08,152 INFO TaskSetManager: Finished task 31.0 in stage 2.0 (TID 92) in 19934 ms on 10.1.2.97 (32/59)
17/01/29 02:53:09,374 INFO TaskSetManager: Starting task 35.0 in stage 2.0 (TID 96, 10.1.2.97, partition 35, ANY, 5372 bytes)
17/01/29 02:53:09,374 INFO CoarseGrainedSchedulerBackend$DriverEndpoint: Launching task 96 on executor id: 0 hostname: 10.1.2.97.
17/01/29 02:53:09,374 INFO TaskSetManager: Finished task 29.0 in stage 2.0 (TID 90) in 21157 ms on 10.1.2.97 (33/59)
17/01/29 02:53:23,633 INFO TaskSetManager: Starting task 36.0 in stage 2.0 (TID 97, 10.1.2.97, partition 36, ANY, 5372 bytes)
17/01/29 02:53:23,633 INFO CoarseGrainedSchedulerBackend$DriverEndpoint: Launching task 97 on executor id: 0 hostname: 10.1.2.97.
17/01/29 02:53:23,634 INFO TaskSetManager: Finished task 32.0 in stage 2.0 (TID 93) in 17470 ms on 10.1.2.97 (34/59)
17/01/29 02:53:26,019 INFO TaskSetManager: Starting task 37.0 in stage 2.0 (TID 98, 10.1.2.97, partition 37, ANY, 5372 bytes)
17/01/29 02:53:26,019 INFO CoarseGrainedSchedulerBackend$DriverEndpoint: Launching task 98 on executor id: 0 hostname: 10.1.2.97.
17/01/29 02:53:26,020 INFO TaskSetManager: Finished task 33.0 in stage 2.0 (TID 94) in 18113 ms on 10.1.2.97 (35/59)
17/01/29 02:53:26,453 INFO TaskSetManager: Starting task 38.0 in stage 2.0 (TID 99, 10.1.2.97, partition 38, ANY, 5372 bytes)
17/01/29 02:53:26,453 INFO CoarseGrainedSchedulerBackend$DriverEndpoint: Launching task 99 on executor id: 0 hostname: 10.1.2.97.
17/01/29 02:53:26,454 INFO TaskSetManager: Finished task 34.0 in stage 2.0 (TID 95) in 18303 ms on 10.1.2.97 (36/59)
17/01/29 02:53:26,996 INFO TaskSetManager: Starting task 39.0 in stage 2.0 (TID 100, 10.1.2.97, partition 39, ANY, 5372 bytes)
17/01/29 02:53:26,996 INFO CoarseGrainedSchedulerBackend$DriverEndpoint: Launching task 100 on executor id: 0 hostname: 10.1.2.97.
17/01/29 02:53:26,996 INFO TaskSetManager: Finished task 35.0 in stage 2.0 (TID 96) in 17623 ms on 10.1.2.97 (37/59)
17/01/29 02:53:44,468 INFO TaskSetManager: Starting task 40.0 in stage 2.0 (TID 101, 10.1.2.97, partition 40, ANY, 5372 bytes)
17/01/29 02:53:44,468 INFO CoarseGrainedSchedulerBackend$DriverEndpoint: Launching task 101 on executor id: 0 hostname: 10.1.2.97.
17/01/29 02:53:44,469 INFO TaskSetManager: Finished task 36.0 in stage 2.0 (TID 97) in 20837 ms on 10.1.2.97 (38/59)
17/01/29 02:53:48,846 INFO TaskSetManager: Starting task 41.0 in stage 2.0 (TID 102, 10.1.2.97, partition 41, ANY, 5372 bytes)
17/01/29 02:53:48,846 INFO CoarseGrainedSchedulerBackend$DriverEndpoint: Launching task 102 on executor id: 0 hostname: 10.1.2.97.
17/01/29 02:53:48,847 INFO TaskSetManager: Finished task 38.0 in stage 2.0 (TID 99) in 22395 ms on 10.1.2.97 (39/59)
17/01/29 02:53:50,258 INFO TaskSetManager: Starting task 42.0 in stage 2.0 (TID 103, 10.1.2.97, partition 42, ANY, 5372 bytes)
17/01/29 02:53:50,258 INFO CoarseGrainedSchedulerBackend$DriverEndpoint: Launching task 103 on executor id: 0 hostname: 10.1.2.97.
17/01/29 02:53:50,259 INFO TaskSetManager: Finished task 39.0 in stage 2.0 (TID 100) in 23264 ms on 10.1.2.97 (40/59)
17/01/29 02:53:52,026 INFO TaskSetManager: Starting task 43.0 in stage 2.0 (TID 104, 10.1.2.97, partition 43, ANY, 5372 bytes)
17/01/29 02:53:52,026 INFO CoarseGrainedSchedulerBackend$DriverEndpoint: Launching task 104 on executor id: 0 hostname: 10.1.2.97.
17/01/29 02:53:52,026 INFO TaskSetManager: Finished task 37.0 in stage 2.0 (TID 98) in 26008 ms on 10.1.2.97 (41/59)
17/01/29 02:54:07,838 INFO TaskSetManager: Starting task 44.0 in stage 2.0 (TID 105, 10.1.2.97, partition 44, ANY, 5372 bytes)
17/01/29 02:54:07,839 INFO CoarseGrainedSchedulerBackend$DriverEndpoint: Launching task 105 on executor id: 0 hostname: 10.1.2.97.
17/01/29 02:54:07,839 INFO TaskSetManager: Finished task 40.0 in stage 2.0 (TID 101) in 23371 ms on 10.1.2.97 (42/59)
17/01/29 02:54:10,025 INFO TaskSetManager: Starting task 45.0 in stage 2.0 (TID 106, 10.1.2.97, partition 45, ANY, 5372 bytes)
17/01/29 02:54:10,025 INFO CoarseGrainedSchedulerBackend$DriverEndpoint: Launching task 106 on executor id: 0 hostname: 10.1.2.97.
17/01/29 02:54:10,026 INFO TaskSetManager: Finished task 41.0 in stage 2.0 (TID 102) in 21181 ms on 10.1.2.97 (43/59)
17/01/29 02:54:12,860 INFO TaskSetManager: Starting task 46.0 in stage 2.0 (TID 107, 10.1.2.97, partition 46, ANY, 5372 bytes)
17/01/29 02:54:12,860 INFO CoarseGrainedSchedulerBackend$DriverEndpoint: Launching task 107 on executor id: 0 hostname: 10.1.2.97.
17/01/29 02:54:12,860 INFO TaskSetManager: Finished task 42.0 in stage 2.0 (TID 103) in 22603 ms on 10.1.2.97 (44/59)
17/01/29 02:54:14,007 INFO TaskSetManager: Starting task 47.0 in stage 2.0 (TID 108, 10.1.2.97, partition 47, ANY, 5372 bytes)
17/01/29 02:54:14,008 INFO CoarseGrainedSchedulerBackend$DriverEndpoint: Launching task 108 on executor id: 0 hostname: 10.1.2.97.
17/01/29 02:54:14,009 INFO TaskSetManager: Finished task 43.0 in stage 2.0 (TID 104) in 21983 ms on 10.1.2.97 (45/59)
17/01/29 02:54:25,830 INFO TaskSetManager: Starting task 48.0 in stage 2.0 (TID 109, 10.1.2.97, partition 48, ANY, 5372 bytes)
17/01/29 02:54:25,830 INFO CoarseGrainedSchedulerBackend$DriverEndpoint: Launching task 109 on executor id: 0 hostname: 10.1.2.97.
17/01/29 02:54:25,831 INFO TaskSetManager: Finished task 44.0 in stage 2.0 (TID 105) in 17993 ms on 10.1.2.97 (46/59)
17/01/29 02:54:27,417 INFO TaskSetManager: Starting task 49.0 in stage 2.0 (TID 110, 10.1.2.97, partition 49, ANY, 5372 bytes)
17/01/29 02:54:27,417 INFO CoarseGrainedSchedulerBackend$DriverEndpoint: Launching task 110 on executor id: 0 hostname: 10.1.2.97.
17/01/29 02:54:27,418 INFO TaskSetManager: Finished task 45.0 in stage 2.0 (TID 106) in 17393 ms on 10.1.2.97 (47/59)
17/01/29 02:54:30,018 INFO TaskSetManager: Starting task 50.0 in stage 2.0 (TID 111, 10.1.2.97, partition 50, ANY, 5372 bytes)
17/01/29 02:54:30,018 INFO CoarseGrainedSchedulerBackend$DriverEndpoint: Launching task 111 on executor id: 0 hostname: 10.1.2.97.
17/01/29 02:54:30,020 INFO TaskSetManager: Finished task 46.0 in stage 2.0 (TID 107) in 17160 ms on 10.1.2.97 (48/59)
17/01/29 02:54:31,421 INFO TaskSetManager: Starting task 51.0 in stage 2.0 (TID 112, 10.1.2.97, partition 51, ANY, 5372 bytes)
17/01/29 02:54:31,421 INFO CoarseGrainedSchedulerBackend$DriverEndpoint: Launching task 112 on executor id: 0 hostname: 10.1.2.97.
17/01/29 02:54:31,422 INFO TaskSetManager: Finished task 47.0 in stage 2.0 (TID 108) in 17415 ms on 10.1.2.97 (49/59)
17/01/29 02:54:44,276 INFO TaskSetManager: Starting task 52.0 in stage 2.0 (TID 113, 10.1.2.97, partition 52, ANY, 5372 bytes)
17/01/29 02:54:44,276 INFO CoarseGrainedSchedulerBackend$DriverEndpoint: Launching task 113 on executor id: 0 hostname: 10.1.2.97.
17/01/29 02:54:44,277 INFO TaskSetManager: Finished task 48.0 in stage 2.0 (TID 109) in 18446 ms on 10.1.2.97 (50/59)
17/01/29 02:54:48,831 INFO TaskSetManager: Starting task 53.0 in stage 2.0 (TID 114, 10.1.2.97, partition 53, ANY, 5372 bytes)
17/01/29 02:54:48,831 INFO CoarseGrainedSchedulerBackend$DriverEndpoint: Launching task 114 on executor id: 0 hostname: 10.1.2.97.
17/01/29 02:54:48,832 INFO TaskSetManager: Finished task 49.0 in stage 2.0 (TID 110) in 21416 ms on 10.1.2.97 (51/59)
17/01/29 02:54:50,803 INFO TaskSetManager: Starting task 54.0 in stage 2.0 (TID 115, 10.1.2.97, partition 54, ANY, 5372 bytes)
17/01/29 02:54:50,803 INFO CoarseGrainedSchedulerBackend$DriverEndpoint: Launching task 115 on executor id: 0 hostname: 10.1.2.97.
17/01/29 02:54:50,804 INFO TaskSetManager: Finished task 50.0 in stage 2.0 (TID 111) in 20786 ms on 10.1.2.97 (52/59)
17/01/29 02:54:52,018 INFO TaskSetManager: Starting task 55.0 in stage 2.0 (TID 116, 10.1.2.97, partition 55, ANY, 5372 bytes)
17/01/29 02:54:52,019 INFO CoarseGrainedSchedulerBackend$DriverEndpoint: Launching task 116 on executor id: 0 hostname: 10.1.2.97.
17/01/29 02:54:52,019 INFO TaskSetManager: Finished task 51.0 in stage 2.0 (TID 112) in 20599 ms on 10.1.2.97 (53/59)
17/01/29 02:55:06,978 INFO TaskSetManager: Starting task 56.0 in stage 2.0 (TID 117, 10.1.2.97, partition 56, ANY, 5372 bytes)
17/01/29 02:55:06,979 INFO CoarseGrainedSchedulerBackend$DriverEndpoint: Launching task 117 on executor id: 0 hostname: 10.1.2.97.
17/01/29 02:55:06,979 INFO TaskSetManager: Finished task 52.0 in stage 2.0 (TID 113) in 22704 ms on 10.1.2.97 (54/59)
17/01/29 02:55:12,732 INFO TaskSetManager: Starting task 57.0 in stage 2.0 (TID 118, 10.1.2.97, partition 57, ANY, 5372 bytes)
17/01/29 02:55:12,732 INFO CoarseGrainedSchedulerBackend$DriverEndpoint: Launching task 118 on executor id: 0 hostname: 10.1.2.97.
17/01/29 02:55:12,733 INFO TaskSetManager: Finished task 54.0 in stage 2.0 (TID 115) in 21930 ms on 10.1.2.97 (55/59)
17/01/29 02:55:13,617 INFO TaskSetManager: Finished task 53.0 in stage 2.0 (TID 114) in 24787 ms on 10.1.2.97 (56/59)
17/01/29 02:55:15,141 INFO TaskSetManager: Finished task 55.0 in stage 2.0 (TID 116) in 23123 ms on 10.1.2.97 (57/59)
17/01/29 02:55:19,620 INFO TaskSetManager: Finished task 56.0 in stage 2.0 (TID 117) in 12642 ms on 10.1.2.97 (58/59)
17/01/29 02:55:20,905 INFO TaskSetManager: Finished task 57.0 in stage 2.0 (TID 118) in 8173 ms on 10.1.2.97 (59/59)
17/01/29 02:55:20,905 INFO TaskSchedulerImpl: Removed TaskSet 2.0, whose tasks have all completed, from pool 
17/01/29 02:55:20,905 INFO DAGScheduler: ResultStage 2 (count at GradientDescent.scala:209) finished in 156.339 s
17/01/29 02:55:20,906 INFO DAGScheduler: Job 2 finished: count at GradientDescent.scala:209, took 156.365308 s
17/01/29 02:55:21,137 WARN BLAS: Failed to load implementation from: com.github.fommil.netlib.NativeSystemBLAS
17/01/29 02:55:21,137 WARN BLAS: Failed to load implementation from: com.github.fommil.netlib.NativeRefBLAS
17/01/29 02:55:21,161 INFO MemoryStore: Block broadcast_4 stored as values in memory (estimated size 280.0 B, free 2.1 GB)
17/01/29 02:55:21,164 INFO MemoryStore: Block broadcast_4_piece0 stored as bytes in memory (estimated size 153.0 B, free 2.1 GB)
17/01/29 02:55:21,165 INFO BlockManagerInfo: Added broadcast_4_piece0 in memory on 10.1.2.60:44506 (size: 153.0 B, free: 2.1 GB)
17/01/29 02:55:21,166 INFO SparkContext: Created broadcast 4 from broadcast at GradientDescent.scala:235
17/01/29 02:55:21,216 INFO SparkContext: Starting job: treeAggregate at GradientDescent.scala:239
17/01/29 02:55:21,223 INFO DAGScheduler: Registering RDD 11 (treeAggregate at GradientDescent.scala:239)
17/01/29 02:55:21,223 INFO DAGScheduler: Got job 3 (treeAggregate at GradientDescent.scala:239) with 7 output partitions
17/01/29 02:55:21,223 INFO DAGScheduler: Final stage: ResultStage 4 (treeAggregate at GradientDescent.scala:239)
17/01/29 02:55:21,224 INFO DAGScheduler: Parents of final stage: List(ShuffleMapStage 3)
17/01/29 02:55:21,224 INFO DAGScheduler: Missing parents: List(ShuffleMapStage 3)
17/01/29 02:55:21,229 INFO DAGScheduler: Submitting ShuffleMapStage 3 (MapPartitionsRDD[11] at treeAggregate at GradientDescent.scala:239), which has no missing parents
17/01/29 02:55:21,253 INFO MemoryStore: Block broadcast_5 stored as values in memory (estimated size 7.2 KB, free 2.1 GB)
17/01/29 02:55:21,255 INFO MemoryStore: Block broadcast_5_piece0 stored as bytes in memory (estimated size 3.7 KB, free 2.1 GB)
17/01/29 02:55:21,256 INFO BlockManagerInfo: Added broadcast_5_piece0 in memory on 10.1.2.60:44506 (size: 3.7 KB, free: 2.1 GB)
17/01/29 02:55:21,257 INFO SparkContext: Created broadcast 5 from broadcast at DAGScheduler.scala:1012
17/01/29 02:55:21,259 INFO DAGScheduler: Submitting 59 missing tasks from ShuffleMapStage 3 (MapPartitionsRDD[11] at treeAggregate at GradientDescent.scala:239)
17/01/29 02:55:21,259 INFO TaskSchedulerImpl: Adding task set 3.0 with 59 tasks
17/01/29 02:55:21,263 INFO TaskSetManager: Starting task 0.0 in stage 3.0 (TID 119, 10.1.2.97, partition 0, PROCESS_LOCAL, 5561 bytes)
17/01/29 02:55:21,264 INFO TaskSetManager: Starting task 1.0 in stage 3.0 (TID 120, 10.1.2.97, partition 1, PROCESS_LOCAL, 5561 bytes)
17/01/29 02:55:21,265 INFO TaskSetManager: Starting task 2.0 in stage 3.0 (TID 121, 10.1.2.97, partition 2, PROCESS_LOCAL, 5561 bytes)
17/01/29 02:55:21,266 INFO TaskSetManager: Starting task 3.0 in stage 3.0 (TID 122, 10.1.2.97, partition 3, PROCESS_LOCAL, 5561 bytes)
17/01/29 02:55:21,266 INFO CoarseGrainedSchedulerBackend$DriverEndpoint: Launching task 119 on executor id: 0 hostname: 10.1.2.97.
17/01/29 02:55:21,267 INFO CoarseGrainedSchedulerBackend$DriverEndpoint: Launching task 120 on executor id: 0 hostname: 10.1.2.97.
17/01/29 02:55:21,267 INFO CoarseGrainedSchedulerBackend$DriverEndpoint: Launching task 121 on executor id: 0 hostname: 10.1.2.97.
17/01/29 02:55:21,267 INFO CoarseGrainedSchedulerBackend$DriverEndpoint: Launching task 122 on executor id: 0 hostname: 10.1.2.97.
17/01/29 02:55:21,293 INFO BlockManagerInfo: Added broadcast_5_piece0 in memory on 10.1.2.97:42780 (size: 3.7 KB, free: 89.6 MB)
17/01/29 02:55:21,713 INFO BlockManagerInfo: Added broadcast_4_piece0 in memory on 10.1.2.97:42780 (size: 153.0 B, free: 89.6 MB)
17/01/29 02:55:21,885 INFO TaskSetManager: Starting task 4.0 in stage 3.0 (TID 123, 10.1.2.97, partition 4, PROCESS_LOCAL, 5561 bytes)
17/01/29 02:55:21,886 INFO CoarseGrainedSchedulerBackend$DriverEndpoint: Launching task 123 on executor id: 0 hostname: 10.1.2.97.
17/01/29 02:55:21,887 INFO TaskSetManager: Finished task 3.0 in stage 3.0 (TID 122) in 622 ms on 10.1.2.97 (1/59)
17/01/29 02:55:21,890 INFO TaskSetManager: Starting task 5.0 in stage 3.0 (TID 124, 10.1.2.97, partition 5, PROCESS_LOCAL, 5561 bytes)
17/01/29 02:55:21,890 INFO CoarseGrainedSchedulerBackend$DriverEndpoint: Launching task 124 on executor id: 0 hostname: 10.1.2.97.
17/01/29 02:55:21,891 INFO TaskSetManager: Finished task 0.0 in stage 3.0 (TID 119) in 630 ms on 10.1.2.97 (2/59)
17/01/29 02:55:21,894 INFO TaskSetManager: Starting task 6.0 in stage 3.0 (TID 125, 10.1.2.97, partition 6, PROCESS_LOCAL, 5561 bytes)
17/01/29 02:55:21,894 INFO CoarseGrainedSchedulerBackend$DriverEndpoint: Launching task 125 on executor id: 0 hostname: 10.1.2.97.
17/01/29 02:55:21,894 INFO TaskSetManager: Finished task 2.0 in stage 3.0 (TID 121) in 630 ms on 10.1.2.97 (3/59)
17/01/29 02:55:21,895 INFO TaskSetManager: Starting task 7.0 in stage 3.0 (TID 126, 10.1.2.97, partition 7, PROCESS_LOCAL, 5561 bytes)
17/01/29 02:55:21,896 INFO CoarseGrainedSchedulerBackend$DriverEndpoint: Launching task 126 on executor id: 0 hostname: 10.1.2.97.
17/01/29 02:55:21,896 INFO TaskSetManager: Finished task 1.0 in stage 3.0 (TID 120) in 633 ms on 10.1.2.97 (4/59)
17/01/29 02:55:21,975 INFO TaskSetManager: Starting task 8.0 in stage 3.0 (TID 127, 10.1.2.97, partition 8, PROCESS_LOCAL, 5561 bytes)
17/01/29 02:55:21,975 INFO CoarseGrainedSchedulerBackend$DriverEndpoint: Launching task 127 on executor id: 0 hostname: 10.1.2.97.
17/01/29 02:55:21,975 INFO TaskSetManager: Finished task 6.0 in stage 3.0 (TID 125) in 82 ms on 10.1.2.97 (5/59)
17/01/29 02:55:21,986 INFO TaskSetManager: Starting task 9.0 in stage 3.0 (TID 128, 10.1.2.97, partition 9, PROCESS_LOCAL, 5561 bytes)
17/01/29 02:55:21,986 INFO CoarseGrainedSchedulerBackend$DriverEndpoint: Launching task 128 on executor id: 0 hostname: 10.1.2.97.
17/01/29 02:55:21,987 INFO TaskSetManager: Finished task 4.0 in stage 3.0 (TID 123) in 102 ms on 10.1.2.97 (6/59)
17/01/29 02:55:22,014 INFO TaskSetManager: Starting task 10.0 in stage 3.0 (TID 129, 10.1.2.97, partition 10, PROCESS_LOCAL, 5561 bytes)
17/01/29 02:55:22,014 INFO CoarseGrainedSchedulerBackend$DriverEndpoint: Launching task 129 on executor id: 0 hostname: 10.1.2.97.
17/01/29 02:55:22,015 INFO TaskSetManager: Finished task 5.0 in stage 3.0 (TID 124) in 126 ms on 10.1.2.97 (7/59)
17/01/29 02:55:22,018 INFO TaskSetManager: Starting task 11.0 in stage 3.0 (TID 130, 10.1.2.97, partition 11, PROCESS_LOCAL, 5561 bytes)
17/01/29 02:55:22,018 INFO CoarseGrainedSchedulerBackend$DriverEndpoint: Launching task 130 on executor id: 0 hostname: 10.1.2.97.
17/01/29 02:55:22,018 INFO TaskSetManager: Finished task 7.0 in stage 3.0 (TID 126) in 123 ms on 10.1.2.97 (8/59)
17/01/29 02:55:22,050 INFO TaskSetManager: Starting task 12.0 in stage 3.0 (TID 131, 10.1.2.97, partition 12, PROCESS_LOCAL, 5561 bytes)
17/01/29 02:55:22,050 INFO CoarseGrainedSchedulerBackend$DriverEndpoint: Launching task 131 on executor id: 0 hostname: 10.1.2.97.
17/01/29 02:55:22,050 INFO TaskSetManager: Finished task 8.0 in stage 3.0 (TID 127) in 76 ms on 10.1.2.97 (9/59)
17/01/29 02:55:22,070 INFO TaskSetManager: Starting task 13.0 in stage 3.0 (TID 132, 10.1.2.97, partition 13, PROCESS_LOCAL, 5561 bytes)
17/01/29 02:55:22,070 INFO CoarseGrainedSchedulerBackend$DriverEndpoint: Launching task 132 on executor id: 0 hostname: 10.1.2.97.
17/01/29 02:55:22,071 INFO TaskSetManager: Finished task 9.0 in stage 3.0 (TID 128) in 86 ms on 10.1.2.97 (10/59)
17/01/29 02:55:22,119 INFO TaskSetManager: Starting task 14.0 in stage 3.0 (TID 133, 10.1.2.97, partition 14, PROCESS_LOCAL, 5561 bytes)
17/01/29 02:55:22,120 INFO CoarseGrainedSchedulerBackend$DriverEndpoint: Launching task 133 on executor id: 0 hostname: 10.1.2.97.
17/01/29 02:55:22,121 INFO TaskSetManager: Finished task 11.0 in stage 3.0 (TID 130) in 103 ms on 10.1.2.97 (11/59)
17/01/29 02:55:22,125 INFO TaskSetManager: Starting task 15.0 in stage 3.0 (TID 134, 10.1.2.97, partition 15, PROCESS_LOCAL, 5561 bytes)
17/01/29 02:55:22,125 INFO CoarseGrainedSchedulerBackend$DriverEndpoint: Launching task 134 on executor id: 0 hostname: 10.1.2.97.
17/01/29 02:55:22,126 INFO TaskSetManager: Finished task 12.0 in stage 3.0 (TID 131) in 76 ms on 10.1.2.97 (12/59)
17/01/29 02:55:22,128 INFO TaskSetManager: Starting task 16.0 in stage 3.0 (TID 135, 10.1.2.97, partition 16, PROCESS_LOCAL, 5561 bytes)
17/01/29 02:55:22,129 INFO CoarseGrainedSchedulerBackend$DriverEndpoint: Launching task 135 on executor id: 0 hostname: 10.1.2.97.
17/01/29 02:55:22,129 INFO TaskSetManager: Finished task 10.0 in stage 3.0 (TID 129) in 116 ms on 10.1.2.97 (13/59)
17/01/29 02:55:22,143 INFO TaskSetManager: Starting task 17.0 in stage 3.0 (TID 136, 10.1.2.97, partition 17, PROCESS_LOCAL, 5561 bytes)
17/01/29 02:55:22,143 INFO CoarseGrainedSchedulerBackend$DriverEndpoint: Launching task 136 on executor id: 0 hostname: 10.1.2.97.
17/01/29 02:55:22,144 INFO TaskSetManager: Finished task 13.0 in stage 3.0 (TID 132) in 75 ms on 10.1.2.97 (14/59)
17/01/29 02:55:22,207 INFO TaskSetManager: Starting task 18.0 in stage 3.0 (TID 137, 10.1.2.97, partition 18, PROCESS_LOCAL, 5561 bytes)
17/01/29 02:55:22,207 INFO CoarseGrainedSchedulerBackend$DriverEndpoint: Launching task 137 on executor id: 0 hostname: 10.1.2.97.
17/01/29 02:55:22,208 INFO TaskSetManager: Finished task 17.0 in stage 3.0 (TID 136) in 64 ms on 10.1.2.97 (15/59)
17/01/29 02:55:22,211 INFO TaskSetManager: Starting task 19.0 in stage 3.0 (TID 138, 10.1.2.97, partition 19, PROCESS_LOCAL, 5561 bytes)
17/01/29 02:55:22,212 INFO CoarseGrainedSchedulerBackend$DriverEndpoint: Launching task 138 on executor id: 0 hostname: 10.1.2.97.
17/01/29 02:55:22,212 INFO TaskSetManager: Finished task 16.0 in stage 3.0 (TID 135) in 84 ms on 10.1.2.97 (16/59)
17/01/29 02:55:22,221 INFO TaskSetManager: Starting task 20.0 in stage 3.0 (TID 139, 10.1.2.97, partition 20, PROCESS_LOCAL, 5561 bytes)
17/01/29 02:55:22,221 INFO CoarseGrainedSchedulerBackend$DriverEndpoint: Launching task 139 on executor id: 0 hostname: 10.1.2.97.
17/01/29 02:55:22,222 INFO TaskSetManager: Finished task 14.0 in stage 3.0 (TID 133) in 103 ms on 10.1.2.97 (17/59)
17/01/29 02:55:22,242 INFO TaskSetManager: Starting task 21.0 in stage 3.0 (TID 140, 10.1.2.97, partition 21, PROCESS_LOCAL, 5561 bytes)
17/01/29 02:55:22,242 INFO CoarseGrainedSchedulerBackend$DriverEndpoint: Launching task 140 on executor id: 0 hostname: 10.1.2.97.
17/01/29 02:55:22,242 INFO TaskSetManager: Finished task 15.0 in stage 3.0 (TID 134) in 117 ms on 10.1.2.97 (18/59)
17/01/29 02:55:22,329 INFO TaskSetManager: Starting task 22.0 in stage 3.0 (TID 141, 10.1.2.97, partition 22, PROCESS_LOCAL, 5561 bytes)
17/01/29 02:55:22,330 INFO CoarseGrainedSchedulerBackend$DriverEndpoint: Launching task 141 on executor id: 0 hostname: 10.1.2.97.
17/01/29 02:55:22,330 INFO TaskSetManager: Finished task 19.0 in stage 3.0 (TID 138) in 119 ms on 10.1.2.97 (19/59)
17/01/29 02:55:22,332 INFO TaskSetManager: Starting task 23.0 in stage 3.0 (TID 142, 10.1.2.97, partition 23, PROCESS_LOCAL, 5561 bytes)
17/01/29 02:55:22,332 INFO CoarseGrainedSchedulerBackend$DriverEndpoint: Launching task 142 on executor id: 0 hostname: 10.1.2.97.
17/01/29 02:55:22,332 INFO TaskSetManager: Finished task 18.0 in stage 3.0 (TID 137) in 126 ms on 10.1.2.97 (20/59)
17/01/29 02:55:22,357 INFO TaskSetManager: Starting task 24.0 in stage 3.0 (TID 143, 10.1.2.97, partition 24, PROCESS_LOCAL, 5561 bytes)
17/01/29 02:55:22,357 INFO CoarseGrainedSchedulerBackend$DriverEndpoint: Launching task 143 on executor id: 0 hostname: 10.1.2.97.
17/01/29 02:55:22,357 INFO TaskSetManager: Finished task 21.0 in stage 3.0 (TID 140) in 115 ms on 10.1.2.97 (21/59)
17/01/29 02:55:22,366 INFO TaskSetManager: Starting task 25.0 in stage 3.0 (TID 144, 10.1.2.97, partition 25, PROCESS_LOCAL, 5561 bytes)
17/01/29 02:55:22,366 INFO CoarseGrainedSchedulerBackend$DriverEndpoint: Launching task 144 on executor id: 0 hostname: 10.1.2.97.
17/01/29 02:55:22,366 INFO TaskSetManager: Finished task 20.0 in stage 3.0 (TID 139) in 145 ms on 10.1.2.97 (22/59)
17/01/29 02:55:22,413 INFO TaskSetManager: Starting task 26.0 in stage 3.0 (TID 145, 10.1.2.97, partition 26, PROCESS_LOCAL, 5561 bytes)
17/01/29 02:55:22,414 INFO CoarseGrainedSchedulerBackend$DriverEndpoint: Launching task 145 on executor id: 0 hostname: 10.1.2.97.
17/01/29 02:55:22,414 INFO TaskSetManager: Finished task 22.0 in stage 3.0 (TID 141) in 85 ms on 10.1.2.97 (23/59)
17/01/29 02:55:22,418 INFO TaskSetManager: Starting task 28.0 in stage 3.0 (TID 146, 10.1.2.97, partition 28, PROCESS_LOCAL, 5561 bytes)
17/01/29 02:55:22,418 INFO CoarseGrainedSchedulerBackend$DriverEndpoint: Launching task 146 on executor id: 0 hostname: 10.1.2.97.
17/01/29 02:55:22,418 INFO TaskSetManager: Finished task 23.0 in stage 3.0 (TID 142) in 86 ms on 10.1.2.97 (24/59)
17/01/29 02:55:22,433 INFO TaskSetManager: Starting task 58.0 in stage 3.0 (TID 147, 10.1.2.97, partition 58, PROCESS_LOCAL, 5561 bytes)
17/01/29 02:55:22,434 INFO CoarseGrainedSchedulerBackend$DriverEndpoint: Launching task 147 on executor id: 0 hostname: 10.1.2.97.
17/01/29 02:55:22,434 INFO TaskSetManager: Finished task 24.0 in stage 3.0 (TID 143) in 78 ms on 10.1.2.97 (25/59)
17/01/29 02:55:22,439 INFO TaskSetManager: Finished task 25.0 in stage 3.0 (TID 144) in 72 ms on 10.1.2.97 (26/59)
17/01/29 02:55:22,471 INFO TaskSetManager: Finished task 26.0 in stage 3.0 (TID 145) in 58 ms on 10.1.2.97 (27/59)
17/01/29 02:55:22,484 INFO TaskSetManager: Finished task 28.0 in stage 3.0 (TID 146) in 67 ms on 10.1.2.97 (28/59)
17/01/29 02:55:22,505 INFO TaskSetManager: Finished task 58.0 in stage 3.0 (TID 147) in 71 ms on 10.1.2.97 (29/59)
17/01/29 02:55:26,217 INFO TaskSetManager: Starting task 27.0 in stage 3.0 (TID 148, 10.1.2.97, partition 27, ANY, 5561 bytes)
17/01/29 02:55:26,217 INFO TaskSetManager: Starting task 29.0 in stage 3.0 (TID 149, 10.1.2.97, partition 29, ANY, 5561 bytes)
17/01/29 02:55:26,218 INFO TaskSetManager: Starting task 30.0 in stage 3.0 (TID 150, 10.1.2.97, partition 30, ANY, 5561 bytes)
17/01/29 02:55:26,218 INFO TaskSetManager: Starting task 31.0 in stage 3.0 (TID 151, 10.1.2.97, partition 31, ANY, 5561 bytes)
17/01/29 02:55:26,218 INFO CoarseGrainedSchedulerBackend$DriverEndpoint: Launching task 148 on executor id: 0 hostname: 10.1.2.97.
17/01/29 02:55:26,219 INFO CoarseGrainedSchedulerBackend$DriverEndpoint: Launching task 149 on executor id: 0 hostname: 10.1.2.97.
17/01/29 02:55:26,219 INFO CoarseGrainedSchedulerBackend$DriverEndpoint: Launching task 150 on executor id: 0 hostname: 10.1.2.97.
17/01/29 02:55:26,219 INFO CoarseGrainedSchedulerBackend$DriverEndpoint: Launching task 151 on executor id: 0 hostname: 10.1.2.97.
17/01/29 02:55:44,049 INFO TaskSetManager: Starting task 32.0 in stage 3.0 (TID 152, 10.1.2.97, partition 32, ANY, 5561 bytes)
17/01/29 02:55:44,049 INFO CoarseGrainedSchedulerBackend$DriverEndpoint: Launching task 152 on executor id: 0 hostname: 10.1.2.97.
17/01/29 02:55:44,050 INFO TaskSetManager: Finished task 29.0 in stage 3.0 (TID 149) in 17832 ms on 10.1.2.97 (30/59)
17/01/29 02:55:45,090 INFO TaskSetManager: Starting task 33.0 in stage 3.0 (TID 153, 10.1.2.97, partition 33, ANY, 5561 bytes)
17/01/29 02:55:45,090 INFO CoarseGrainedSchedulerBackend$DriverEndpoint: Launching task 153 on executor id: 0 hostname: 10.1.2.97.
17/01/29 02:55:45,091 INFO TaskSetManager: Finished task 31.0 in stage 3.0 (TID 151) in 18872 ms on 10.1.2.97 (31/59)
17/01/29 02:55:45,182 INFO TaskSetManager: Starting task 34.0 in stage 3.0 (TID 154, 10.1.2.97, partition 34, ANY, 5561 bytes)
17/01/29 02:55:45,182 INFO CoarseGrainedSchedulerBackend$DriverEndpoint: Launching task 154 on executor id: 0 hostname: 10.1.2.97.
17/01/29 02:55:45,183 INFO TaskSetManager: Finished task 27.0 in stage 3.0 (TID 148) in 18966 ms on 10.1.2.97 (32/59)
17/01/29 02:55:51,681 INFO TaskSetManager: Starting task 35.0 in stage 3.0 (TID 155, 10.1.2.97, partition 35, ANY, 5561 bytes)
17/01/29 02:55:51,681 INFO CoarseGrainedSchedulerBackend$DriverEndpoint: Launching task 155 on executor id: 0 hostname: 10.1.2.97.
17/01/29 02:55:51,682 INFO TaskSetManager: Finished task 30.0 in stage 3.0 (TID 150) in 25465 ms on 10.1.2.97 (33/59)
17/01/29 02:56:01,198 INFO TaskSetManager: Starting task 36.0 in stage 3.0 (TID 156, 10.1.2.97, partition 36, ANY, 5561 bytes)
17/01/29 02:56:01,198 INFO CoarseGrainedSchedulerBackend$DriverEndpoint: Launching task 156 on executor id: 0 hostname: 10.1.2.97.
17/01/29 02:56:01,199 INFO TaskSetManager: Finished task 32.0 in stage 3.0 (TID 152) in 17151 ms on 10.1.2.97 (34/59)
17/01/29 02:56:03,589 INFO TaskSetManager: Starting task 37.0 in stage 3.0 (TID 157, 10.1.2.97, partition 37, ANY, 5561 bytes)
17/01/29 02:56:03,589 INFO CoarseGrainedSchedulerBackend$DriverEndpoint: Launching task 157 on executor id: 0 hostname: 10.1.2.97.
17/01/29 02:56:03,590 INFO TaskSetManager: Finished task 33.0 in stage 3.0 (TID 153) in 18501 ms on 10.1.2.97 (35/59)
17/01/29 02:56:06,782 INFO TaskSetManager: Starting task 38.0 in stage 3.0 (TID 158, 10.1.2.97, partition 38, ANY, 5561 bytes)
17/01/29 02:56:06,782 INFO CoarseGrainedSchedulerBackend$DriverEndpoint: Launching task 158 on executor id: 0 hostname: 10.1.2.97.
17/01/29 02:56:06,783 INFO TaskSetManager: Finished task 34.0 in stage 3.0 (TID 154) in 21601 ms on 10.1.2.97 (36/59)
17/01/29 02:56:10,630 INFO TaskSetManager: Starting task 39.0 in stage 3.0 (TID 159, 10.1.2.97, partition 39, ANY, 5561 bytes)
17/01/29 02:56:10,630 INFO CoarseGrainedSchedulerBackend$DriverEndpoint: Launching task 159 on executor id: 0 hostname: 10.1.2.97.
17/01/29 02:56:10,631 INFO TaskSetManager: Finished task 35.0 in stage 3.0 (TID 155) in 18950 ms on 10.1.2.97 (37/59)
17/01/29 02:56:20,429 INFO TaskSetManager: Starting task 40.0 in stage 3.0 (TID 160, 10.1.2.97, partition 40, ANY, 5561 bytes)
17/01/29 02:56:20,430 INFO CoarseGrainedSchedulerBackend$DriverEndpoint: Launching task 160 on executor id: 0 hostname: 10.1.2.97.
17/01/29 02:56:20,430 INFO TaskSetManager: Finished task 36.0 in stage 3.0 (TID 156) in 19233 ms on 10.1.2.97 (38/59)
17/01/29 02:56:22,108 INFO TaskSetManager: Starting task 41.0 in stage 3.0 (TID 161, 10.1.2.97, partition 41, ANY, 5561 bytes)
17/01/29 02:56:22,108 INFO CoarseGrainedSchedulerBackend$DriverEndpoint: Launching task 161 on executor id: 0 hostname: 10.1.2.97.
17/01/29 02:56:22,108 INFO TaskSetManager: Finished task 37.0 in stage 3.0 (TID 157) in 18519 ms on 10.1.2.97 (39/59)
17/01/29 02:56:25,035 INFO TaskSetManager: Starting task 42.0 in stage 3.0 (TID 162, 10.1.2.97, partition 42, ANY, 5561 bytes)
17/01/29 02:56:25,035 INFO CoarseGrainedSchedulerBackend$DriverEndpoint: Launching task 162 on executor id: 0 hostname: 10.1.2.97.
17/01/29 02:56:25,036 INFO TaskSetManager: Finished task 38.0 in stage 3.0 (TID 158) in 18255 ms on 10.1.2.97 (40/59)
17/01/29 02:56:28,339 INFO TaskSetManager: Starting task 43.0 in stage 3.0 (TID 163, 10.1.2.97, partition 43, ANY, 5561 bytes)
17/01/29 02:56:28,339 INFO CoarseGrainedSchedulerBackend$DriverEndpoint: Launching task 163 on executor id: 0 hostname: 10.1.2.97.
17/01/29 02:56:28,340 INFO TaskSetManager: Finished task 39.0 in stage 3.0 (TID 159) in 17710 ms on 10.1.2.97 (41/59)
17/01/29 02:56:40,612 INFO TaskSetManager: Starting task 44.0 in stage 3.0 (TID 164, 10.1.2.97, partition 44, ANY, 5561 bytes)
17/01/29 02:56:40,612 INFO CoarseGrainedSchedulerBackend$DriverEndpoint: Launching task 164 on executor id: 0 hostname: 10.1.2.97.
17/01/29 02:56:40,613 INFO TaskSetManager: Finished task 40.0 in stage 3.0 (TID 160) in 20183 ms on 10.1.2.97 (42/59)
17/01/29 02:56:43,008 INFO TaskSetManager: Starting task 45.0 in stage 3.0 (TID 165, 10.1.2.97, partition 45, ANY, 5561 bytes)
17/01/29 02:56:43,008 INFO CoarseGrainedSchedulerBackend$DriverEndpoint: Launching task 165 on executor id: 0 hostname: 10.1.2.97.
17/01/29 02:56:43,009 INFO TaskSetManager: Finished task 41.0 in stage 3.0 (TID 161) in 20902 ms on 10.1.2.97 (43/59)
17/01/29 02:56:43,422 INFO TaskSetManager: Starting task 46.0 in stage 3.0 (TID 166, 10.1.2.97, partition 46, ANY, 5561 bytes)
17/01/29 02:56:43,422 INFO CoarseGrainedSchedulerBackend$DriverEndpoint: Launching task 166 on executor id: 0 hostname: 10.1.2.97.
17/01/29 02:56:43,422 INFO TaskSetManager: Finished task 42.0 in stage 3.0 (TID 162) in 18387 ms on 10.1.2.97 (44/59)
17/01/29 02:56:49,706 INFO TaskSetManager: Starting task 47.0 in stage 3.0 (TID 167, 10.1.2.97, partition 47, ANY, 5561 bytes)
17/01/29 02:56:49,707 INFO CoarseGrainedSchedulerBackend$DriverEndpoint: Launching task 167 on executor id: 0 hostname: 10.1.2.97.
17/01/29 02:56:49,707 INFO TaskSetManager: Finished task 43.0 in stage 3.0 (TID 163) in 21368 ms on 10.1.2.97 (45/59)
17/01/29 02:57:02,596 INFO TaskSetManager: Starting task 48.0 in stage 3.0 (TID 168, 10.1.2.97, partition 48, ANY, 5561 bytes)
17/01/29 02:57:02,598 INFO CoarseGrainedSchedulerBackend$DriverEndpoint: Launching task 168 on executor id: 0 hostname: 10.1.2.97.
17/01/29 02:57:02,599 INFO TaskSetManager: Finished task 44.0 in stage 3.0 (TID 164) in 21988 ms on 10.1.2.97 (46/59)
17/01/29 02:57:04,593 INFO TaskSetManager: Starting task 49.0 in stage 3.0 (TID 169, 10.1.2.97, partition 49, ANY, 5561 bytes)
17/01/29 02:57:04,593 INFO CoarseGrainedSchedulerBackend$DriverEndpoint: Launching task 169 on executor id: 0 hostname: 10.1.2.97.
17/01/29 02:57:04,594 INFO TaskSetManager: Finished task 45.0 in stage 3.0 (TID 165) in 21587 ms on 10.1.2.97 (47/59)
17/01/29 02:57:05,013 INFO TaskSetManager: Starting task 50.0 in stage 3.0 (TID 170, 10.1.2.97, partition 50, ANY, 5561 bytes)
17/01/29 02:57:05,013 INFO CoarseGrainedSchedulerBackend$DriverEndpoint: Launching task 170 on executor id: 0 hostname: 10.1.2.97.
17/01/29 02:57:05,013 INFO TaskSetManager: Finished task 46.0 in stage 3.0 (TID 166) in 21592 ms on 10.1.2.97 (48/59)
17/01/29 02:57:11,642 INFO TaskSetManager: Starting task 51.0 in stage 3.0 (TID 171, 10.1.2.97, partition 51, ANY, 5561 bytes)
17/01/29 02:57:11,642 INFO CoarseGrainedSchedulerBackend$DriverEndpoint: Launching task 171 on executor id: 0 hostname: 10.1.2.97.
17/01/29 02:57:11,643 INFO TaskSetManager: Finished task 47.0 in stage 3.0 (TID 167) in 21937 ms on 10.1.2.97 (49/59)
17/01/29 02:57:20,518 INFO TaskSetManager: Starting task 52.0 in stage 3.0 (TID 172, 10.1.2.97, partition 52, ANY, 5561 bytes)
17/01/29 02:57:20,518 INFO CoarseGrainedSchedulerBackend$DriverEndpoint: Launching task 172 on executor id: 0 hostname: 10.1.2.97.
17/01/29 02:57:20,519 INFO TaskSetManager: Finished task 48.0 in stage 3.0 (TID 168) in 17923 ms on 10.1.2.97 (50/59)
17/01/29 02:57:22,638 INFO TaskSetManager: Starting task 53.0 in stage 3.0 (TID 173, 10.1.2.97, partition 53, ANY, 5561 bytes)
17/01/29 02:57:22,638 INFO CoarseGrainedSchedulerBackend$DriverEndpoint: Launching task 173 on executor id: 0 hostname: 10.1.2.97.
17/01/29 02:57:22,639 INFO TaskSetManager: Finished task 50.0 in stage 3.0 (TID 170) in 17627 ms on 10.1.2.97 (51/59)
17/01/29 02:57:23,351 INFO TaskSetManager: Starting task 54.0 in stage 3.0 (TID 174, 10.1.2.97, partition 54, ANY, 5561 bytes)
17/01/29 02:57:23,351 INFO CoarseGrainedSchedulerBackend$DriverEndpoint: Launching task 174 on executor id: 0 hostname: 10.1.2.97.
17/01/29 02:57:23,352 INFO TaskSetManager: Finished task 49.0 in stage 3.0 (TID 169) in 18759 ms on 10.1.2.97 (52/59)
17/01/29 02:57:29,607 INFO TaskSetManager: Starting task 55.0 in stage 3.0 (TID 175, 10.1.2.97, partition 55, ANY, 5561 bytes)
17/01/29 02:57:29,607 INFO CoarseGrainedSchedulerBackend$DriverEndpoint: Launching task 175 on executor id: 0 hostname: 10.1.2.97.
17/01/29 02:57:29,608 INFO TaskSetManager: Finished task 51.0 in stage 3.0 (TID 171) in 17966 ms on 10.1.2.97 (53/59)
17/01/29 02:57:42,306 INFO TaskSetManager: Starting task 56.0 in stage 3.0 (TID 176, 10.1.2.97, partition 56, ANY, 5561 bytes)
17/01/29 02:57:42,307 INFO CoarseGrainedSchedulerBackend$DriverEndpoint: Launching task 176 on executor id: 0 hostname: 10.1.2.97.
17/01/29 02:57:42,307 INFO TaskSetManager: Finished task 54.0 in stage 3.0 (TID 174) in 18956 ms on 10.1.2.97 (54/59)
17/01/29 02:57:42,570 INFO TaskSetManager: Starting task 57.0 in stage 3.0 (TID 177, 10.1.2.97, partition 57, ANY, 5561 bytes)
17/01/29 02:57:42,571 INFO CoarseGrainedSchedulerBackend$DriverEndpoint: Launching task 177 on executor id: 0 hostname: 10.1.2.97.
17/01/29 02:57:42,572 INFO TaskSetManager: Finished task 52.0 in stage 3.0 (TID 172) in 22054 ms on 10.1.2.97 (55/59)
17/01/29 02:57:43,924 INFO TaskSetManager: Finished task 53.0 in stage 3.0 (TID 173) in 21286 ms on 10.1.2.97 (56/59)
17/01/29 02:57:46,707 INFO TaskSetManager: Finished task 55.0 in stage 3.0 (TID 175) in 17101 ms on 10.1.2.97 (57/59)
17/01/29 02:57:51,435 INFO TaskSetManager: Finished task 56.0 in stage 3.0 (TID 176) in 9128 ms on 10.1.2.97 (58/59)
17/01/29 02:57:51,440 INFO TaskSetManager: Finished task 57.0 in stage 3.0 (TID 177) in 8869 ms on 10.1.2.97 (59/59)
17/01/29 02:57:51,440 INFO TaskSchedulerImpl: Removed TaskSet 3.0, whose tasks have all completed, from pool 
17/01/29 02:57:51,440 INFO DAGScheduler: ShuffleMapStage 3 (treeAggregate at GradientDescent.scala:239) finished in 150.179 s
17/01/29 02:57:51,441 INFO DAGScheduler: looking for newly runnable stages
17/01/29 02:57:51,441 INFO DAGScheduler: running: Set()
17/01/29 02:57:51,441 INFO DAGScheduler: waiting: Set(ResultStage 4)
17/01/29 02:57:51,442 INFO DAGScheduler: failed: Set()
17/01/29 02:57:51,443 INFO DAGScheduler: Submitting ResultStage 4 (MapPartitionsRDD[13] at treeAggregate at GradientDescent.scala:239), which has no missing parents
17/01/29 02:57:51,449 INFO MemoryStore: Block broadcast_6 stored as values in memory (estimated size 3.1 KB, free 2.1 GB)
17/01/29 02:57:51,451 INFO MemoryStore: Block broadcast_6_piece0 stored as bytes in memory (estimated size 1893.0 B, free 2.1 GB)
17/01/29 02:57:51,452 INFO BlockManagerInfo: Added broadcast_6_piece0 in memory on 10.1.2.60:44506 (size: 1893.0 B, free: 2.1 GB)
17/01/29 02:57:51,453 INFO SparkContext: Created broadcast 6 from broadcast at DAGScheduler.scala:1012
17/01/29 02:57:51,453 INFO DAGScheduler: Submitting 7 missing tasks from ResultStage 4 (MapPartitionsRDD[13] at treeAggregate at GradientDescent.scala:239)
17/01/29 02:57:51,453 INFO TaskSchedulerImpl: Adding task set 4.0 with 7 tasks
17/01/29 02:57:51,455 INFO TaskSetManager: Starting task 0.0 in stage 4.0 (TID 178, 10.1.2.97, partition 0, NODE_LOCAL, 5227 bytes)
17/01/29 02:57:51,455 INFO TaskSetManager: Starting task 1.0 in stage 4.0 (TID 179, 10.1.2.97, partition 1, NODE_LOCAL, 5227 bytes)
17/01/29 02:57:51,456 INFO TaskSetManager: Starting task 2.0 in stage 4.0 (TID 180, 10.1.2.97, partition 2, NODE_LOCAL, 5227 bytes)
17/01/29 02:57:51,456 INFO TaskSetManager: Starting task 3.0 in stage 4.0 (TID 181, 10.1.2.97, partition 3, NODE_LOCAL, 5227 bytes)
17/01/29 02:57:51,456 INFO CoarseGrainedSchedulerBackend$DriverEndpoint: Launching task 178 on executor id: 0 hostname: 10.1.2.97.
17/01/29 02:57:51,457 INFO CoarseGrainedSchedulerBackend$DriverEndpoint: Launching task 179 on executor id: 0 hostname: 10.1.2.97.
17/01/29 02:57:51,457 INFO CoarseGrainedSchedulerBackend$DriverEndpoint: Launching task 180 on executor id: 0 hostname: 10.1.2.97.
17/01/29 02:57:51,457 INFO CoarseGrainedSchedulerBackend$DriverEndpoint: Launching task 181 on executor id: 0 hostname: 10.1.2.97.
17/01/29 02:57:51,479 INFO BlockManagerInfo: Added broadcast_6_piece0 in memory on 10.1.2.97:42780 (size: 1893.0 B, free: 89.6 MB)
17/01/29 02:57:51,499 INFO MapOutputTrackerMasterEndpoint: Asked to send map output locations for shuffle 0 to 10.1.2.97:48696
17/01/29 02:57:51,503 INFO MapOutputTrackerMaster: Size of output statuses for shuffle 0 is 197 bytes
17/01/29 02:57:51,554 INFO TaskSetManager: Starting task 4.0 in stage 4.0 (TID 182, 10.1.2.97, partition 4, NODE_LOCAL, 5227 bytes)
17/01/29 02:57:51,554 INFO CoarseGrainedSchedulerBackend$DriverEndpoint: Launching task 182 on executor id: 0 hostname: 10.1.2.97.
17/01/29 02:57:51,555 INFO TaskSetManager: Finished task 2.0 in stage 4.0 (TID 180) in 99 ms on 10.1.2.97 (1/7)
17/01/29 02:57:51,555 INFO TaskSetManager: Starting task 5.0 in stage 4.0 (TID 183, 10.1.2.97, partition 5, NODE_LOCAL, 5227 bytes)
17/01/29 02:57:51,555 INFO CoarseGrainedSchedulerBackend$DriverEndpoint: Launching task 183 on executor id: 0 hostname: 10.1.2.97.
17/01/29 02:57:51,556 INFO TaskSetManager: Finished task 3.0 in stage 4.0 (TID 181) in 100 ms on 10.1.2.97 (2/7)
17/01/29 02:57:51,567 INFO TaskSetManager: Starting task 6.0 in stage 4.0 (TID 184, 10.1.2.97, partition 6, NODE_LOCAL, 5227 bytes)
17/01/29 02:57:51,567 INFO CoarseGrainedSchedulerBackend$DriverEndpoint: Launching task 184 on executor id: 0 hostname: 10.1.2.97.
17/01/29 02:57:51,568 INFO TaskSetManager: Finished task 1.0 in stage 4.0 (TID 179) in 112 ms on 10.1.2.97 (3/7)
17/01/29 02:57:51,569 INFO TaskSetManager: Finished task 0.0 in stage 4.0 (TID 178) in 115 ms on 10.1.2.97 (4/7)
17/01/29 02:57:51,578 INFO TaskSetManager: Finished task 5.0 in stage 4.0 (TID 183) in 23 ms on 10.1.2.97 (5/7)
17/01/29 02:57:51,581 INFO TaskSetManager: Finished task 4.0 in stage 4.0 (TID 182) in 27 ms on 10.1.2.97 (6/7)
17/01/29 02:57:51,585 INFO TaskSetManager: Finished task 6.0 in stage 4.0 (TID 184) in 18 ms on 10.1.2.97 (7/7)
17/01/29 02:57:51,585 INFO TaskSchedulerImpl: Removed TaskSet 4.0, whose tasks have all completed, from pool 
17/01/29 02:57:51,585 INFO DAGScheduler: ResultStage 4 (treeAggregate at GradientDescent.scala:239) finished in 0.127 s
17/01/29 02:57:51,586 INFO DAGScheduler: Job 3 finished: treeAggregate at GradientDescent.scala:239, took 150.369314 s
17/01/29 02:57:51,588 INFO MemoryStore: Block broadcast_7 stored as values in memory (estimated size 280.0 B, free 2.1 GB)
17/01/29 02:57:51,590 INFO MemoryStore: Block broadcast_7_piece0 stored as bytes in memory (estimated size 365.0 B, free 2.1 GB)
17/01/29 02:57:51,591 INFO BlockManagerInfo: Added broadcast_7_piece0 in memory on 10.1.2.60:44506 (size: 365.0 B, free: 2.1 GB)
17/01/29 02:57:51,591 INFO SparkContext: Created broadcast 7 from broadcast at GradientDescent.scala:235
17/01/29 02:57:51,609 INFO SparkContext: Starting job: treeAggregate at GradientDescent.scala:239
17/01/29 02:57:51,610 INFO DAGScheduler: Registering RDD 16 (treeAggregate at GradientDescent.scala:239)
17/01/29 02:57:51,611 INFO DAGScheduler: Got job 4 (treeAggregate at GradientDescent.scala:239) with 7 output partitions
17/01/29 02:57:51,611 INFO DAGScheduler: Final stage: ResultStage 6 (treeAggregate at GradientDescent.scala:239)
17/01/29 02:57:51,611 INFO DAGScheduler: Parents of final stage: List(ShuffleMapStage 5)
17/01/29 02:57:51,611 INFO DAGScheduler: Missing parents: List(ShuffleMapStage 5)
17/01/29 02:57:51,614 INFO DAGScheduler: Submitting ShuffleMapStage 5 (MapPartitionsRDD[16] at treeAggregate at GradientDescent.scala:239), which has no missing parents
17/01/29 02:57:51,627 INFO MemoryStore: Block broadcast_8 stored as values in memory (estimated size 7.2 KB, free 2.1 GB)
17/01/29 02:57:51,628 INFO MemoryStore: Block broadcast_8_piece0 stored as bytes in memory (estimated size 3.7 KB, free 2.1 GB)
17/01/29 02:57:51,629 INFO BlockManagerInfo: Added broadcast_8_piece0 in memory on 10.1.2.60:44506 (size: 3.7 KB, free: 2.1 GB)
17/01/29 02:57:51,629 INFO SparkContext: Created broadcast 8 from broadcast at DAGScheduler.scala:1012
17/01/29 02:57:51,630 INFO DAGScheduler: Submitting 59 missing tasks from ShuffleMapStage 5 (MapPartitionsRDD[16] at treeAggregate at GradientDescent.scala:239)
17/01/29 02:57:51,631 INFO TaskSchedulerImpl: Adding task set 5.0 with 59 tasks
17/01/29 02:57:51,633 INFO TaskSetManager: Starting task 0.0 in stage 5.0 (TID 185, 10.1.2.97, partition 0, PROCESS_LOCAL, 5561 bytes)
17/01/29 02:57:51,633 INFO TaskSetManager: Starting task 1.0 in stage 5.0 (TID 186, 10.1.2.97, partition 1, PROCESS_LOCAL, 5561 bytes)
17/01/29 02:57:51,634 INFO TaskSetManager: Starting task 2.0 in stage 5.0 (TID 187, 10.1.2.97, partition 2, PROCESS_LOCAL, 5561 bytes)
17/01/29 02:57:51,634 INFO TaskSetManager: Starting task 3.0 in stage 5.0 (TID 188, 10.1.2.97, partition 3, PROCESS_LOCAL, 5561 bytes)
17/01/29 02:57:51,634 INFO CoarseGrainedSchedulerBackend$DriverEndpoint: Launching task 185 on executor id: 0 hostname: 10.1.2.97.
17/01/29 02:57:51,634 INFO CoarseGrainedSchedulerBackend$DriverEndpoint: Launching task 186 on executor id: 0 hostname: 10.1.2.97.
17/01/29 02:57:51,635 INFO CoarseGrainedSchedulerBackend$DriverEndpoint: Launching task 187 on executor id: 0 hostname: 10.1.2.97.
17/01/29 02:57:51,635 INFO CoarseGrainedSchedulerBackend$DriverEndpoint: Launching task 188 on executor id: 0 hostname: 10.1.2.97.
17/01/29 02:57:51,653 INFO BlockManagerInfo: Added broadcast_8_piece0 in memory on 10.1.2.97:42780 (size: 3.7 KB, free: 89.6 MB)
17/01/29 02:57:51,667 INFO BlockManagerInfo: Added broadcast_7_piece0 in memory on 10.1.2.97:42780 (size: 365.0 B, free: 89.6 MB)
17/01/29 02:57:51,752 INFO TaskSetManager: Starting task 4.0 in stage 5.0 (TID 189, 10.1.2.97, partition 4, PROCESS_LOCAL, 5561 bytes)
17/01/29 02:57:51,752 INFO CoarseGrainedSchedulerBackend$DriverEndpoint: Launching task 189 on executor id: 0 hostname: 10.1.2.97.
17/01/29 02:57:51,752 INFO TaskSetManager: Finished task 0.0 in stage 5.0 (TID 185) in 120 ms on 10.1.2.97 (1/59)
17/01/29 02:57:51,754 INFO TaskSetManager: Starting task 5.0 in stage 5.0 (TID 190, 10.1.2.97, partition 5, PROCESS_LOCAL, 5561 bytes)
17/01/29 02:57:51,754 INFO CoarseGrainedSchedulerBackend$DriverEndpoint: Launching task 190 on executor id: 0 hostname: 10.1.2.97.
17/01/29 02:57:51,754 INFO TaskSetManager: Finished task 2.0 in stage 5.0 (TID 187) in 121 ms on 10.1.2.97 (2/59)
17/01/29 02:57:51,755 INFO TaskSetManager: Starting task 6.0 in stage 5.0 (TID 191, 10.1.2.97, partition 6, PROCESS_LOCAL, 5561 bytes)
17/01/29 02:57:51,756 INFO CoarseGrainedSchedulerBackend$DriverEndpoint: Launching task 191 on executor id: 0 hostname: 10.1.2.97.
17/01/29 02:57:51,756 INFO TaskSetManager: Finished task 3.0 in stage 5.0 (TID 188) in 122 ms on 10.1.2.97 (3/59)
17/01/29 02:57:51,757 INFO TaskSetManager: Starting task 7.0 in stage 5.0 (TID 192, 10.1.2.97, partition 7, PROCESS_LOCAL, 5561 bytes)
17/01/29 02:57:51,757 INFO CoarseGrainedSchedulerBackend$DriverEndpoint: Launching task 192 on executor id: 0 hostname: 10.1.2.97.
17/01/29 02:57:51,757 INFO TaskSetManager: Finished task 1.0 in stage 5.0 (TID 186) in 124 ms on 10.1.2.97 (4/59)
17/01/29 02:57:51,826 INFO TaskSetManager: Starting task 8.0 in stage 5.0 (TID 193, 10.1.2.97, partition 8, PROCESS_LOCAL, 5561 bytes)
17/01/29 02:57:51,827 INFO CoarseGrainedSchedulerBackend$DriverEndpoint: Launching task 193 on executor id: 0 hostname: 10.1.2.97.
17/01/29 02:57:51,827 INFO TaskSetManager: Finished task 4.0 in stage 5.0 (TID 189) in 76 ms on 10.1.2.97 (5/59)
17/01/29 02:57:51,831 INFO TaskSetManager: Starting task 9.0 in stage 5.0 (TID 194, 10.1.2.97, partition 9, PROCESS_LOCAL, 5561 bytes)
17/01/29 02:57:51,831 INFO CoarseGrainedSchedulerBackend$DriverEndpoint: Launching task 194 on executor id: 0 hostname: 10.1.2.97.
17/01/29 02:57:51,832 INFO TaskSetManager: Starting task 10.0 in stage 5.0 (TID 195, 10.1.2.97, partition 10, PROCESS_LOCAL, 5561 bytes)
17/01/29 02:57:51,832 INFO CoarseGrainedSchedulerBackend$DriverEndpoint: Launching task 195 on executor id: 0 hostname: 10.1.2.97.
17/01/29 02:57:51,833 INFO TaskSetManager: Starting task 11.0 in stage 5.0 (TID 196, 10.1.2.97, partition 11, PROCESS_LOCAL, 5561 bytes)
17/01/29 02:57:51,833 INFO CoarseGrainedSchedulerBackend$DriverEndpoint: Launching task 196 on executor id: 0 hostname: 10.1.2.97.
17/01/29 02:57:51,834 INFO TaskSetManager: Finished task 6.0 in stage 5.0 (TID 191) in 78 ms on 10.1.2.97 (6/59)
17/01/29 02:57:51,834 INFO TaskSetManager: Finished task 7.0 in stage 5.0 (TID 192) in 78 ms on 10.1.2.97 (7/59)
17/01/29 02:57:51,841 INFO TaskSetManager: Finished task 5.0 in stage 5.0 (TID 190) in 88 ms on 10.1.2.97 (8/59)
17/01/29 02:57:51,903 INFO TaskSetManager: Starting task 12.0 in stage 5.0 (TID 197, 10.1.2.97, partition 12, PROCESS_LOCAL, 5561 bytes)
17/01/29 02:57:51,903 INFO CoarseGrainedSchedulerBackend$DriverEndpoint: Launching task 197 on executor id: 0 hostname: 10.1.2.97.
17/01/29 02:57:51,904 INFO TaskSetManager: Finished task 10.0 in stage 5.0 (TID 195) in 72 ms on 10.1.2.97 (9/59)
17/01/29 02:57:51,907 INFO TaskSetManager: Starting task 13.0 in stage 5.0 (TID 198, 10.1.2.97, partition 13, PROCESS_LOCAL, 5561 bytes)
17/01/29 02:57:51,908 INFO CoarseGrainedSchedulerBackend$DriverEndpoint: Launching task 198 on executor id: 0 hostname: 10.1.2.97.
17/01/29 02:57:51,908 INFO TaskSetManager: Finished task 8.0 in stage 5.0 (TID 193) in 82 ms on 10.1.2.97 (10/59)
17/01/29 02:57:51,909 INFO TaskSetManager: Starting task 14.0 in stage 5.0 (TID 199, 10.1.2.97, partition 14, PROCESS_LOCAL, 5561 bytes)
17/01/29 02:57:51,909 INFO CoarseGrainedSchedulerBackend$DriverEndpoint: Launching task 199 on executor id: 0 hostname: 10.1.2.97.
17/01/29 02:57:51,909 INFO TaskSetManager: Finished task 11.0 in stage 5.0 (TID 196) in 77 ms on 10.1.2.97 (11/59)
17/01/29 02:57:51,910 INFO TaskSetManager: Starting task 15.0 in stage 5.0 (TID 200, 10.1.2.97, partition 15, PROCESS_LOCAL, 5561 bytes)
17/01/29 02:57:51,910 INFO CoarseGrainedSchedulerBackend$DriverEndpoint: Launching task 200 on executor id: 0 hostname: 10.1.2.97.
17/01/29 02:57:51,910 INFO TaskSetManager: Finished task 9.0 in stage 5.0 (TID 194) in 80 ms on 10.1.2.97 (12/59)
17/01/29 02:57:51,979 INFO TaskSetManager: Starting task 16.0 in stage 5.0 (TID 201, 10.1.2.97, partition 16, PROCESS_LOCAL, 5561 bytes)
17/01/29 02:57:51,979 INFO CoarseGrainedSchedulerBackend$DriverEndpoint: Launching task 201 on executor id: 0 hostname: 10.1.2.97.
17/01/29 02:57:51,980 INFO TaskSetManager: Finished task 12.0 in stage 5.0 (TID 197) in 76 ms on 10.1.2.97 (13/59)
17/01/29 02:57:51,982 INFO TaskSetManager: Starting task 17.0 in stage 5.0 (TID 202, 10.1.2.97, partition 17, PROCESS_LOCAL, 5561 bytes)
17/01/29 02:57:51,983 INFO CoarseGrainedSchedulerBackend$DriverEndpoint: Launching task 202 on executor id: 0 hostname: 10.1.2.97.
17/01/29 02:57:51,983 INFO TaskSetManager: Finished task 14.0 in stage 5.0 (TID 199) in 75 ms on 10.1.2.97 (14/59)
17/01/29 02:57:51,985 INFO TaskSetManager: Starting task 18.0 in stage 5.0 (TID 203, 10.1.2.97, partition 18, PROCESS_LOCAL, 5561 bytes)
17/01/29 02:57:51,985 INFO CoarseGrainedSchedulerBackend$DriverEndpoint: Launching task 203 on executor id: 0 hostname: 10.1.2.97.
