Using properties file: /home/ubuntu/spark-2.0.0/conf/spark-defaults.conf
Adding default property: spark.driver.extraJavaOptions=-XX:+PrintGCDetails -XX:+PrintGCTimeStamps -Xms4000m -Dlog4j.configuration=file:///home/ubuntu/spark-2.0.0/conf/log4j.properties
Adding default property: spark.executor.extraJavaOptions=-XX:+PrintGCDetails -XX:+PrintGCTimeStamps -Xms4000m -Dlog4j.configuration=file:///home/ubuntu/spark-2.0.0/conf/log4j.properties
Parsed arguments:
  master                  spark://euca-10-1-2-31:7077
  deployMode              client
  executorMemory          4000m
  executorCores           null
  totalExecutorCores      null
  propertiesFile          /home/ubuntu/spark-2.0.0/conf/spark-defaults.conf
  driverMemory            4000m
  driverCores             null
  driverExtraClassPath    null
  driverExtraLibraryPath  null
  driverExtraJavaOptions  -XX:+PrintGCDetails -XX:+PrintGCTimeStamps -Xms4000m -Dlog4j.configuration=file:///home/ubuntu/spark-2.0.0/conf/log4j.properties
  supervise               false
  queue                   null
  numExecutors            2
  files                   null
  pyFiles                 null
  archives                null
  mainClass               LogRegExplicitParallelism
  primaryResource         file:///home/ubuntu/jars/log-reg-explicit-parallelism_2.11-1.0.jar
  name                    LogRegExplicitParallelism
  childArgs               [cluster 28 euca-10-1-2-31 9000 higgs_0_exp 5 8]
  jars                    null
  packages                null
  packagesExclusions      null
  repositories            null
  verbose                 true

Spark properties used, including those specified through
 --conf and those from the properties file /home/ubuntu/spark-2.0.0/conf/spark-defaults.conf:
  spark.default.parallelism -> 8
  spark.driver.memory -> 4000m
  spark.executor.extraJavaOptions -> -XX:+PrintGCDetails -XX:+PrintGCTimeStamps -Xms4000m -Dlog4j.configuration=file:///home/ubuntu/spark-2.0.0/conf/log4j.properties
  spark.driver.extraJavaOptions -> -XX:+PrintGCDetails -XX:+PrintGCTimeStamps -Xms4000m -Dlog4j.configuration=file:///home/ubuntu/spark-2.0.0/conf/log4j.properties
  spark.shuffle.spill -> false

    
Main class:
LogRegExplicitParallelism
Arguments:
cluster
28
euca-10-1-2-31
9000
higgs_0_exp
5
8
System properties:
spark.default.parallelism -> 8
spark.executor.memory -> 4000m
spark.driver.memory -> 4000m
SPARK_SUBMIT -> true
spark.executor.extraJavaOptions -> -XX:+PrintGCDetails -XX:+PrintGCTimeStamps -Xms4000m -Dlog4j.configuration=file:///home/ubuntu/spark-2.0.0/conf/log4j.properties
spark.app.name -> LogRegExplicitParallelism
spark.shuffle.spill -> false
spark.driver.extraJavaOptions -> -XX:+PrintGCDetails -XX:+PrintGCTimeStamps -Xms4000m -Dlog4j.configuration=file:///home/ubuntu/spark-2.0.0/conf/log4j.properties
spark.jars -> file:///home/ubuntu/jars/log-reg-explicit-parallelism_2.11-1.0.jar
spark.submit.deployMode -> client
spark.master -> spark://euca-10-1-2-31:7077
Classpath elements:
file:///home/ubuntu/jars/log-reg-explicit-parallelism_2.11-1.0.jar


17/01/29 05:34:56,139 INFO SparkContext: Running Spark version 2.0.0
17/01/29 05:34:56,479 WARN NativeCodeLoader: Unable to load native-hadoop library for your platform... using builtin-java classes where applicable
17/01/29 05:34:56,641 INFO SecurityManager: Changing view acls to: ubuntu
17/01/29 05:34:56,641 INFO SecurityManager: Changing modify acls to: ubuntu
17/01/29 05:34:56,642 INFO SecurityManager: Changing view acls groups to: 
17/01/29 05:34:56,642 INFO SecurityManager: Changing modify acls groups to: 
17/01/29 05:34:56,643 INFO SecurityManager: SecurityManager: authentication disabled; ui acls disabled; users  with view permissions: Set(ubuntu); groups with view permissions: Set(); users  with modify permissions: Set(ubuntu); groups with modify permissions: Set()
17/01/29 05:34:56,959 INFO Utils: Successfully started service 'sparkDriver' on port 36083.
17/01/29 05:34:56,978 INFO SparkEnv: Registering MapOutputTracker
17/01/29 05:34:56,984 WARN SortShuffleManager: spark.shuffle.spill was set to false, but this configuration is ignored as of Spark 1.6+. Shuffle will continue to spill to disk when necessary.
17/01/29 05:34:56,996 INFO SparkEnv: Registering BlockManagerMaster
17/01/29 05:34:57,009 INFO DiskBlockManager: Created local directory at /tmp/blockmgr-afa5718f-68c1-4f80-bede-56b788d784f0
17/01/29 05:34:57,028 INFO MemoryStore: MemoryStore started with capacity 2.1 GB
17/01/29 05:34:57,082 INFO SparkEnv: Registering OutputCommitCoordinator
17/01/29 05:34:57,291 INFO Utils: Successfully started service 'SparkUI' on port 4040.
17/01/29 05:34:57,293 INFO SparkUI: Bound SparkUI to 10.1.2.31, and started at http://10.1.2.31:4040
17/01/29 05:34:57,328 INFO SparkContext: Added JAR file:///home/ubuntu/jars/log-reg-explicit-parallelism_2.11-1.0.jar at spark://10.1.2.31:36083/jars/log-reg-explicit-parallelism_2.11-1.0.jar with timestamp 1485668097327
17/01/29 05:34:57,410 INFO StandaloneAppClient$ClientEndpoint: Connecting to master spark://euca-10-1-2-31:7077...
17/01/29 05:34:57,478 INFO TransportClientFactory: Successfully created connection to euca-10-1-2-31/10.1.2.31:7077 after 24 ms (0 ms spent in bootstraps)
17/01/29 05:34:57,580 INFO StandaloneSchedulerBackend: Connected to Spark cluster with app ID app-20170129053457-0000
17/01/29 05:34:57,586 INFO Utils: Successfully started service 'org.apache.spark.network.netty.NettyBlockTransferService' on port 36114.
17/01/29 05:34:57,586 INFO NettyBlockTransferService: Server created on 10.1.2.31:36114
17/01/29 05:34:57,588 INFO BlockManagerMaster: Registering BlockManager BlockManagerId(driver, 10.1.2.31, 36114)
17/01/29 05:34:57,590 INFO BlockManagerMasterEndpoint: Registering block manager 10.1.2.31:36114 with 2.1 GB RAM, BlockManagerId(driver, 10.1.2.31, 36114)
17/01/29 05:34:57,598 INFO BlockManagerMaster: Registered BlockManager BlockManagerId(driver, 10.1.2.31, 36114)
17/01/29 05:34:57,602 INFO StandaloneAppClient$ClientEndpoint: Executor added: app-20170129053457-0000/0 on worker-20170129053447-10.1.2.60-46499 (10.1.2.60:46499) with 4 cores
17/01/29 05:34:57,602 INFO StandaloneSchedulerBackend: Granted executor ID app-20170129053457-0000/0 on hostPort 10.1.2.60:46499 with 4 cores, 3.9 GB RAM
17/01/29 05:34:57,602 INFO StandaloneAppClient$ClientEndpoint: Executor added: app-20170129053457-0000/1 on worker-20170129053447-10.1.2.152-37200 (10.1.2.152:37200) with 4 cores
17/01/29 05:34:57,603 INFO StandaloneSchedulerBackend: Granted executor ID app-20170129053457-0000/1 on hostPort 10.1.2.152:37200 with 4 cores, 3.9 GB RAM
17/01/29 05:34:57,665 INFO StandaloneAppClient$ClientEndpoint: Executor updated: app-20170129053457-0000/0 is now RUNNING
17/01/29 05:34:57,665 INFO StandaloneAppClient$ClientEndpoint: Executor updated: app-20170129053457-0000/1 is now RUNNING
17/01/29 05:34:57,775 INFO StandaloneSchedulerBackend: SchedulerBackend is ready for scheduling beginning after reached minRegisteredResourcesRatio: 0.0
17/01/29 05:34:58,131 INFO MemoryStore: Block broadcast_0 stored as values in memory (estimated size 130.8 KB, free 2.1 GB)
17/01/29 05:34:58,203 INFO MemoryStore: Block broadcast_0_piece0 stored as bytes in memory (estimated size 16.5 KB, free 2.1 GB)
17/01/29 05:34:58,206 INFO BlockManagerInfo: Added broadcast_0_piece0 in memory on 10.1.2.31:36114 (size: 16.5 KB, free: 2.1 GB)
17/01/29 05:34:58,213 INFO SparkContext: Created broadcast 0 from textFile at MLUtils.scala:99
17/01/29 05:34:58,770 INFO FileInputFormat: Total input paths to process : 1
17/01/29 05:34:58,806 INFO NetworkTopology: Adding a new node: /default-rack/10.1.2.152:50010
17/01/29 05:34:58,807 INFO NetworkTopology: Adding a new node: /default-rack/10.1.2.60:50010
17/01/29 05:34:58,844 INFO SparkContext: Starting job: first at GeneralizedLinearAlgorithm.scala:246
17/01/29 05:34:58,855 INFO DAGScheduler: Got job 0 (first at GeneralizedLinearAlgorithm.scala:246) with 1 output partitions
17/01/29 05:34:58,855 INFO DAGScheduler: Final stage: ResultStage 0 (first at GeneralizedLinearAlgorithm.scala:246)
17/01/29 05:34:58,856 INFO DAGScheduler: Parents of final stage: List()
17/01/29 05:34:58,861 INFO DAGScheduler: Missing parents: List()
17/01/29 05:34:58,878 INFO DAGScheduler: Submitting ResultStage 0 (MapPartitionsRDD[6] at map at GeneralizedLinearAlgorithm.scala:246), which has no missing parents
17/01/29 05:34:58,898 INFO MemoryStore: Block broadcast_1 stored as values in memory (estimated size 4.2 KB, free 2.1 GB)
17/01/29 05:34:58,900 INFO MemoryStore: Block broadcast_1_piece0 stored as bytes in memory (estimated size 2.4 KB, free 2.1 GB)
17/01/29 05:34:58,901 INFO BlockManagerInfo: Added broadcast_1_piece0 in memory on 10.1.2.31:36114 (size: 2.4 KB, free: 2.1 GB)
17/01/29 05:34:58,902 INFO SparkContext: Created broadcast 1 from broadcast at DAGScheduler.scala:1012
17/01/29 05:34:58,905 INFO DAGScheduler: Submitting 1 missing tasks from ResultStage 0 (MapPartitionsRDD[6] at map at GeneralizedLinearAlgorithm.scala:246)
17/01/29 05:34:58,906 INFO TaskSchedulerImpl: Adding task set 0.0 with 1 tasks
17/01/29 05:34:59,408 INFO CoarseGrainedSchedulerBackend$DriverEndpoint: Registered executor NettyRpcEndpointRef(null) (10.1.2.60:57766) with ID 0
17/01/29 05:34:59,434 INFO TaskSetManager: Starting task 0.0 in stage 0.0 (TID 0, 10.1.2.60, partition 0, ANY, 5454 bytes)
17/01/29 05:34:59,438 INFO CoarseGrainedSchedulerBackend$DriverEndpoint: Launching task 0 on executor id: 0 hostname: 10.1.2.60.
17/01/29 05:34:59,440 INFO CoarseGrainedSchedulerBackend$DriverEndpoint: Registered executor NettyRpcEndpointRef(null) (10.1.2.152:48848) with ID 1
17/01/29 05:34:59,455 INFO BlockManagerMasterEndpoint: Registering block manager 10.1.2.60:40890 with 2.1 GB RAM, BlockManagerId(0, 10.1.2.60, 40890)
17/01/29 05:34:59,481 INFO BlockManagerMasterEndpoint: Registering block manager 10.1.2.152:46814 with 2.1 GB RAM, BlockManagerId(1, 10.1.2.152, 46814)
17/01/29 05:34:59,715 INFO BlockManagerInfo: Added broadcast_1_piece0 in memory on 10.1.2.60:40890 (size: 2.4 KB, free: 2.1 GB)
17/01/29 05:34:59,861 INFO BlockManagerInfo: Added broadcast_0_piece0 in memory on 10.1.2.60:40890 (size: 16.5 KB, free: 2.1 GB)
17/01/29 05:35:06,981 INFO BlockManagerInfo: Added rdd_5_0 in memory on 10.1.2.60:40890 (size: 70.0 MB, free: 2.0 GB)
17/01/29 05:35:07,034 INFO TaskSetManager: Finished task 0.0 in stage 0.0 (TID 0) in 7615 ms on 10.1.2.60 (1/1)
17/01/29 05:35:07,035 INFO TaskSchedulerImpl: Removed TaskSet 0.0, whose tasks have all completed, from pool 
17/01/29 05:35:07,035 INFO DAGScheduler: ResultStage 0 (first at GeneralizedLinearAlgorithm.scala:246) finished in 8.119 s
17/01/29 05:35:07,041 INFO DAGScheduler: Job 0 finished: first at GeneralizedLinearAlgorithm.scala:246, took 8.196738 s
17/01/29 05:35:07,051 INFO SparkContext: Starting job: count at DataValidators.scala:40
17/01/29 05:35:07,054 INFO DAGScheduler: Got job 1 (count at DataValidators.scala:40) with 59 output partitions
17/01/29 05:35:07,054 INFO DAGScheduler: Final stage: ResultStage 1 (count at DataValidators.scala:40)
17/01/29 05:35:07,054 INFO DAGScheduler: Parents of final stage: List()
17/01/29 05:35:07,057 INFO DAGScheduler: Missing parents: List()
17/01/29 05:35:07,059 INFO DAGScheduler: Submitting ResultStage 1 (MapPartitionsRDD[7] at filter at DataValidators.scala:40), which has no missing parents
17/01/29 05:35:07,083 INFO MemoryStore: Block broadcast_2 stored as values in memory (estimated size 3.9 KB, free 2.1 GB)
17/01/29 05:35:07,085 INFO MemoryStore: Block broadcast_2_piece0 stored as bytes in memory (estimated size 2.2 KB, free 2.1 GB)
17/01/29 05:35:07,085 INFO BlockManagerInfo: Added broadcast_2_piece0 in memory on 10.1.2.31:36114 (size: 2.2 KB, free: 2.1 GB)
17/01/29 05:35:07,086 INFO SparkContext: Created broadcast 2 from broadcast at DAGScheduler.scala:1012
17/01/29 05:35:07,088 INFO DAGScheduler: Submitting 59 missing tasks from ResultStage 1 (MapPartitionsRDD[7] at filter at DataValidators.scala:40)
17/01/29 05:35:07,089 INFO TaskSchedulerImpl: Adding task set 1.0 with 59 tasks
17/01/29 05:35:07,094 INFO TaskSetManager: Starting task 0.0 in stage 1.0 (TID 1, 10.1.2.60, partition 0, PROCESS_LOCAL, 5372 bytes)
17/01/29 05:35:07,097 INFO TaskSetManager: Starting task 58.0 in stage 1.0 (TID 2, 10.1.2.152, partition 58, NODE_LOCAL, 5372 bytes)
17/01/29 05:35:07,098 INFO CoarseGrainedSchedulerBackend$DriverEndpoint: Launching task 2 on executor id: 1 hostname: 10.1.2.152.
17/01/29 05:35:07,098 INFO CoarseGrainedSchedulerBackend$DriverEndpoint: Launching task 1 on executor id: 0 hostname: 10.1.2.60.
17/01/29 05:35:07,117 INFO BlockManagerInfo: Added broadcast_2_piece0 in memory on 10.1.2.60:40890 (size: 2.2 KB, free: 2.0 GB)
17/01/29 05:35:07,165 INFO TaskSetManager: Finished task 0.0 in stage 1.0 (TID 1) in 72 ms on 10.1.2.60 (1/59)
17/01/29 05:35:07,358 INFO BlockManagerInfo: Added broadcast_2_piece0 in memory on 10.1.2.152:46814 (size: 2.2 KB, free: 2.1 GB)
17/01/29 05:35:07,509 INFO BlockManagerInfo: Added broadcast_0_piece0 in memory on 10.1.2.152:46814 (size: 16.5 KB, free: 2.1 GB)
14.862: [GC [PSYoungGen: 1024512K->156932K(1195008K)] 1024512K->157004K(3926016K), 0.0559060 secs] [Times: user=0.08 sys=0.03, real=0.06 secs] 
17/01/29 05:35:10,417 INFO TaskSetManager: Starting task 1.0 in stage 1.0 (TID 3, 10.1.2.152, partition 1, ANY, 5372 bytes)
17/01/29 05:35:10,419 INFO TaskSetManager: Starting task 2.0 in stage 1.0 (TID 4, 10.1.2.60, partition 2, ANY, 5372 bytes)
17/01/29 05:35:10,422 INFO TaskSetManager: Starting task 3.0 in stage 1.0 (TID 5, 10.1.2.152, partition 3, ANY, 5372 bytes)
17/01/29 05:35:10,424 INFO TaskSetManager: Starting task 4.0 in stage 1.0 (TID 6, 10.1.2.60, partition 4, ANY, 5372 bytes)
17/01/29 05:35:10,425 INFO TaskSetManager: Starting task 5.0 in stage 1.0 (TID 7, 10.1.2.152, partition 5, ANY, 5372 bytes)
17/01/29 05:35:10,427 INFO TaskSetManager: Starting task 6.0 in stage 1.0 (TID 8, 10.1.2.60, partition 6, ANY, 5372 bytes)
17/01/29 05:35:10,431 INFO TaskSetManager: Starting task 7.0 in stage 1.0 (TID 9, 10.1.2.60, partition 7, ANY, 5372 bytes)
17/01/29 05:35:10,432 INFO CoarseGrainedSchedulerBackend$DriverEndpoint: Launching task 3 on executor id: 1 hostname: 10.1.2.152.
17/01/29 05:35:10,433 INFO CoarseGrainedSchedulerBackend$DriverEndpoint: Launching task 5 on executor id: 1 hostname: 10.1.2.152.
17/01/29 05:35:10,433 INFO CoarseGrainedSchedulerBackend$DriverEndpoint: Launching task 7 on executor id: 1 hostname: 10.1.2.152.
17/01/29 05:35:10,434 INFO CoarseGrainedSchedulerBackend$DriverEndpoint: Launching task 4 on executor id: 0 hostname: 10.1.2.60.
17/01/29 05:35:10,435 INFO CoarseGrainedSchedulerBackend$DriverEndpoint: Launching task 6 on executor id: 0 hostname: 10.1.2.60.
17/01/29 05:35:10,436 INFO CoarseGrainedSchedulerBackend$DriverEndpoint: Launching task 8 on executor id: 0 hostname: 10.1.2.60.
17/01/29 05:35:10,437 INFO CoarseGrainedSchedulerBackend$DriverEndpoint: Launching task 9 on executor id: 0 hostname: 10.1.2.60.
17/01/29 05:35:10,478 INFO BlockManagerInfo: Removed broadcast_1_piece0 on 10.1.2.60:40890 in memory (size: 2.4 KB, free: 2.0 GB)
17/01/29 05:35:10,481 INFO BlockManagerInfo: Removed broadcast_1_piece0 on 10.1.2.31:36114 in memory (size: 2.4 KB, free: 2.1 GB)
17/01/29 05:35:27,860 INFO BlockManagerInfo: Added rdd_5_58 in memory on 10.1.2.152:46814 (size: 72.8 MB, free: 2047.6 MB)
17/01/29 05:35:27,925 INFO TaskSetManager: Starting task 8.0 in stage 1.0 (TID 10, 10.1.2.152, partition 8, ANY, 5372 bytes)
17/01/29 05:35:27,925 INFO CoarseGrainedSchedulerBackend$DriverEndpoint: Launching task 10 on executor id: 1 hostname: 10.1.2.152.
17/01/29 05:35:27,926 INFO TaskSetManager: Finished task 58.0 in stage 1.0 (TID 2) in 20830 ms on 10.1.2.152 (2/59)
17/01/29 05:35:29,689 INFO BlockManagerInfo: Added rdd_5_2 in memory on 10.1.2.60:40890 (size: 69.9 MB, free: 1980.5 MB)
17/01/29 05:35:29,787 INFO TaskSetManager: Starting task 9.0 in stage 1.0 (TID 11, 10.1.2.60, partition 9, ANY, 5372 bytes)
17/01/29 05:35:29,788 INFO CoarseGrainedSchedulerBackend$DriverEndpoint: Launching task 11 on executor id: 0 hostname: 10.1.2.60.
17/01/29 05:35:29,791 INFO TaskSetManager: Finished task 2.0 in stage 1.0 (TID 4) in 19372 ms on 10.1.2.60 (3/59)
17/01/29 05:35:30,086 INFO BlockManagerInfo: Added rdd_5_4 in memory on 10.1.2.60:40890 (size: 70.0 MB, free: 1910.5 MB)
17/01/29 05:35:30,112 INFO TaskSetManager: Finished task 4.0 in stage 1.0 (TID 6) in 19690 ms on 10.1.2.60 (4/59)
17/01/29 05:35:30,115 INFO TaskSetManager: Starting task 10.0 in stage 1.0 (TID 12, 10.1.2.60, partition 10, ANY, 5372 bytes)
17/01/29 05:35:30,116 INFO CoarseGrainedSchedulerBackend$DriverEndpoint: Launching task 12 on executor id: 0 hostname: 10.1.2.60.
17/01/29 05:35:30,437 INFO BlockManagerInfo: Added rdd_5_7 in memory on 10.1.2.60:40890 (size: 70.0 MB, free: 1840.6 MB)
17/01/29 05:35:30,461 INFO TaskSetManager: Starting task 11.0 in stage 1.0 (TID 13, 10.1.2.60, partition 11, ANY, 5372 bytes)
17/01/29 05:35:30,462 INFO CoarseGrainedSchedulerBackend$DriverEndpoint: Launching task 13 on executor id: 0 hostname: 10.1.2.60.
17/01/29 05:35:30,463 INFO BlockManagerInfo: Added rdd_5_6 in memory on 10.1.2.60:40890 (size: 69.9 MB, free: 1770.6 MB)
17/01/29 05:35:30,471 INFO TaskSetManager: Finished task 7.0 in stage 1.0 (TID 9) in 20042 ms on 10.1.2.60 (5/59)
17/01/29 05:35:30,495 INFO TaskSetManager: Starting task 12.0 in stage 1.0 (TID 14, 10.1.2.60, partition 12, ANY, 5372 bytes)
17/01/29 05:35:30,496 INFO TaskSetManager: Finished task 6.0 in stage 1.0 (TID 8) in 20069 ms on 10.1.2.60 (6/59)
17/01/29 05:35:30,496 INFO CoarseGrainedSchedulerBackend$DriverEndpoint: Launching task 14 on executor id: 0 hostname: 10.1.2.60.
17/01/29 05:35:31,068 INFO BlockManagerInfo: Added rdd_5_5 in memory on 10.1.2.152:46814 (size: 70.0 MB, free: 1977.6 MB)
17/01/29 05:35:31,094 INFO TaskSetManager: Starting task 13.0 in stage 1.0 (TID 15, 10.1.2.152, partition 13, ANY, 5372 bytes)
17/01/29 05:35:31,094 INFO CoarseGrainedSchedulerBackend$DriverEndpoint: Launching task 15 on executor id: 1 hostname: 10.1.2.152.
17/01/29 05:35:31,095 INFO TaskSetManager: Finished task 5.0 in stage 1.0 (TID 7) in 20670 ms on 10.1.2.152 (7/59)
17/01/29 05:35:31,172 INFO BlockManagerInfo: Added rdd_5_3 in memory on 10.1.2.152:46814 (size: 69.9 MB, free: 1907.7 MB)
17/01/29 05:35:31,200 INFO TaskSetManager: Starting task 14.0 in stage 1.0 (TID 16, 10.1.2.152, partition 14, ANY, 5372 bytes)
17/01/29 05:35:31,201 INFO CoarseGrainedSchedulerBackend$DriverEndpoint: Launching task 16 on executor id: 1 hostname: 10.1.2.152.
17/01/29 05:35:31,201 INFO TaskSetManager: Finished task 3.0 in stage 1.0 (TID 5) in 20781 ms on 10.1.2.152 (8/59)
17/01/29 05:35:31,212 INFO BlockManagerInfo: Added rdd_5_1 in memory on 10.1.2.152:46814 (size: 70.0 MB, free: 1837.7 MB)
17/01/29 05:35:31,247 INFO TaskSetManager: Starting task 15.0 in stage 1.0 (TID 17, 10.1.2.152, partition 15, ANY, 5372 bytes)
17/01/29 05:35:31,248 INFO TaskSetManager: Finished task 1.0 in stage 1.0 (TID 3) in 20832 ms on 10.1.2.152 (9/59)
17/01/29 05:35:31,248 INFO CoarseGrainedSchedulerBackend$DriverEndpoint: Launching task 17 on executor id: 1 hostname: 10.1.2.152.
17/01/29 05:35:45,076 INFO BlockManagerInfo: Added rdd_5_8 in memory on 10.1.2.152:46814 (size: 70.0 MB, free: 1767.8 MB)
17/01/29 05:35:45,096 INFO TaskSetManager: Starting task 16.0 in stage 1.0 (TID 18, 10.1.2.152, partition 16, ANY, 5372 bytes)
17/01/29 05:35:45,096 INFO CoarseGrainedSchedulerBackend$DriverEndpoint: Launching task 18 on executor id: 1 hostname: 10.1.2.152.
17/01/29 05:35:45,097 INFO TaskSetManager: Finished task 8.0 in stage 1.0 (TID 10) in 17175 ms on 10.1.2.152 (10/59)
17/01/29 05:35:47,722 INFO BlockManagerInfo: Added rdd_5_13 in memory on 10.1.2.152:46814 (size: 69.9 MB, free: 1697.9 MB)
17/01/29 05:35:47,741 INFO TaskSetManager: Starting task 17.0 in stage 1.0 (TID 19, 10.1.2.152, partition 17, ANY, 5372 bytes)
17/01/29 05:35:47,742 INFO CoarseGrainedSchedulerBackend$DriverEndpoint: Launching task 19 on executor id: 1 hostname: 10.1.2.152.
17/01/29 05:35:47,747 INFO TaskSetManager: Finished task 13.0 in stage 1.0 (TID 15) in 16654 ms on 10.1.2.152 (11/59)
17/01/29 05:35:48,194 INFO BlockManagerInfo: Added rdd_5_14 in memory on 10.1.2.152:46814 (size: 69.9 MB, free: 1627.9 MB)
17/01/29 05:35:48,215 INFO TaskSetManager: Starting task 18.0 in stage 1.0 (TID 20, 10.1.2.152, partition 18, ANY, 5372 bytes)
17/01/29 05:35:48,216 INFO CoarseGrainedSchedulerBackend$DriverEndpoint: Launching task 20 on executor id: 1 hostname: 10.1.2.152.
17/01/29 05:35:48,216 INFO TaskSetManager: Finished task 14.0 in stage 1.0 (TID 16) in 17018 ms on 10.1.2.152 (12/59)
17/01/29 05:35:48,598 INFO BlockManagerInfo: Added rdd_5_15 in memory on 10.1.2.152:46814 (size: 69.9 MB, free: 1558.0 MB)
17/01/29 05:35:48,618 INFO TaskSetManager: Starting task 19.0 in stage 1.0 (TID 21, 10.1.2.152, partition 19, ANY, 5372 bytes)
17/01/29 05:35:48,619 INFO CoarseGrainedSchedulerBackend$DriverEndpoint: Launching task 21 on executor id: 1 hostname: 10.1.2.152.
17/01/29 05:35:48,619 INFO TaskSetManager: Finished task 15.0 in stage 1.0 (TID 17) in 17374 ms on 10.1.2.152 (13/59)
17/01/29 05:35:48,792 INFO BlockManagerInfo: Added rdd_5_9 in memory on 10.1.2.60:40890 (size: 69.9 MB, free: 1700.7 MB)
17/01/29 05:35:48,813 INFO TaskSetManager: Starting task 20.0 in stage 1.0 (TID 22, 10.1.2.60, partition 20, ANY, 5372 bytes)
17/01/29 05:35:48,814 INFO CoarseGrainedSchedulerBackend$DriverEndpoint: Launching task 22 on executor id: 0 hostname: 10.1.2.60.
17/01/29 05:35:48,814 INFO TaskSetManager: Finished task 9.0 in stage 1.0 (TID 11) in 19030 ms on 10.1.2.60 (14/59)
17/01/29 05:35:49,361 INFO BlockManagerInfo: Added rdd_5_10 in memory on 10.1.2.60:40890 (size: 70.0 MB, free: 1630.8 MB)
17/01/29 05:35:49,382 INFO TaskSetManager: Starting task 21.0 in stage 1.0 (TID 23, 10.1.2.60, partition 21, ANY, 5372 bytes)
17/01/29 05:35:49,383 INFO CoarseGrainedSchedulerBackend$DriverEndpoint: Launching task 23 on executor id: 0 hostname: 10.1.2.60.
17/01/29 05:35:49,383 INFO TaskSetManager: Finished task 10.0 in stage 1.0 (TID 12) in 19270 ms on 10.1.2.60 (15/59)
17/01/29 05:35:49,549 INFO BlockManagerInfo: Added rdd_5_12 in memory on 10.1.2.60:40890 (size: 70.0 MB, free: 1560.8 MB)
17/01/29 05:35:49,570 INFO TaskSetManager: Starting task 22.0 in stage 1.0 (TID 24, 10.1.2.60, partition 22, ANY, 5372 bytes)
17/01/29 05:35:49,570 INFO CoarseGrainedSchedulerBackend$DriverEndpoint: Launching task 24 on executor id: 0 hostname: 10.1.2.60.
17/01/29 05:35:49,571 INFO TaskSetManager: Finished task 12.0 in stage 1.0 (TID 14) in 19077 ms on 10.1.2.60 (16/59)
17/01/29 05:35:49,752 INFO BlockManagerInfo: Added rdd_5_11 in memory on 10.1.2.60:40890 (size: 69.9 MB, free: 1490.9 MB)
17/01/29 05:35:49,772 INFO TaskSetManager: Starting task 23.0 in stage 1.0 (TID 25, 10.1.2.60, partition 23, ANY, 5372 bytes)
17/01/29 05:35:49,772 INFO CoarseGrainedSchedulerBackend$DriverEndpoint: Launching task 25 on executor id: 0 hostname: 10.1.2.60.
17/01/29 05:35:49,772 INFO TaskSetManager: Finished task 11.0 in stage 1.0 (TID 13) in 19313 ms on 10.1.2.60 (17/59)
17/01/29 05:36:01,985 INFO BlockManagerInfo: Added rdd_5_16 in memory on 10.1.2.152:46814 (size: 70.0 MB, free: 1488.0 MB)
17/01/29 05:36:02,005 INFO TaskSetManager: Starting task 24.0 in stage 1.0 (TID 26, 10.1.2.152, partition 24, ANY, 5372 bytes)
17/01/29 05:36:02,005 INFO CoarseGrainedSchedulerBackend$DriverEndpoint: Launching task 26 on executor id: 1 hostname: 10.1.2.152.
17/01/29 05:36:02,006 INFO TaskSetManager: Finished task 16.0 in stage 1.0 (TID 18) in 16910 ms on 10.1.2.152 (18/59)
17/01/29 05:36:04,906 INFO BlockManagerInfo: Added rdd_5_18 in memory on 10.1.2.152:46814 (size: 70.0 MB, free: 1418.1 MB)
17/01/29 05:36:04,927 INFO TaskSetManager: Starting task 25.0 in stage 1.0 (TID 27, 10.1.2.152, partition 25, ANY, 5372 bytes)
17/01/29 05:36:04,927 INFO CoarseGrainedSchedulerBackend$DriverEndpoint: Launching task 27 on executor id: 1 hostname: 10.1.2.152.
17/01/29 05:36:04,928 INFO TaskSetManager: Finished task 18.0 in stage 1.0 (TID 20) in 16713 ms on 10.1.2.152 (19/59)
17/01/29 05:36:05,134 INFO BlockManagerInfo: Added rdd_5_17 in memory on 10.1.2.152:46814 (size: 69.9 MB, free: 1348.2 MB)
17/01/29 05:36:05,162 INFO TaskSetManager: Starting task 26.0 in stage 1.0 (TID 28, 10.1.2.152, partition 26, ANY, 5372 bytes)
17/01/29 05:36:05,163 INFO CoarseGrainedSchedulerBackend$DriverEndpoint: Launching task 28 on executor id: 1 hostname: 10.1.2.152.
17/01/29 05:36:05,163 INFO TaskSetManager: Finished task 17.0 in stage 1.0 (TID 19) in 17424 ms on 10.1.2.152 (20/59)
17/01/29 05:36:05,524 INFO BlockManagerInfo: Added rdd_5_19 in memory on 10.1.2.152:46814 (size: 70.0 MB, free: 1278.2 MB)
17/01/29 05:36:05,543 INFO TaskSetManager: Starting task 27.0 in stage 1.0 (TID 29, 10.1.2.152, partition 27, ANY, 5372 bytes)
17/01/29 05:36:05,543 INFO CoarseGrainedSchedulerBackend$DriverEndpoint: Launching task 29 on executor id: 1 hostname: 10.1.2.152.
17/01/29 05:36:05,543 INFO TaskSetManager: Finished task 19.0 in stage 1.0 (TID 21) in 16926 ms on 10.1.2.152 (21/59)
17/01/29 05:36:05,847 INFO BlockManagerInfo: Added rdd_5_20 in memory on 10.1.2.60:40890 (size: 69.8 MB, free: 1421.1 MB)
17/01/29 05:36:05,904 INFO TaskSetManager: Starting task 28.0 in stage 1.0 (TID 30, 10.1.2.60, partition 28, ANY, 5372 bytes)
17/01/29 05:36:05,905 INFO CoarseGrainedSchedulerBackend$DriverEndpoint: Launching task 30 on executor id: 0 hostname: 10.1.2.60.
17/01/29 05:36:05,905 INFO TaskSetManager: Finished task 20.0 in stage 1.0 (TID 22) in 17094 ms on 10.1.2.60 (22/59)
17/01/29 05:36:05,955 INFO BlockManagerInfo: Added rdd_5_23 in memory on 10.1.2.60:40890 (size: 69.9 MB, free: 1351.2 MB)
17/01/29 05:36:05,980 INFO TaskSetManager: Finished task 23.0 in stage 1.0 (TID 25) in 16209 ms on 10.1.2.60 (23/59)
17/01/29 05:36:05,982 INFO TaskSetManager: Starting task 29.0 in stage 1.0 (TID 31, 10.1.2.60, partition 29, ANY, 5372 bytes)
17/01/29 05:36:05,982 INFO CoarseGrainedSchedulerBackend$DriverEndpoint: Launching task 31 on executor id: 0 hostname: 10.1.2.60.
17/01/29 05:36:06,131 INFO BlockManagerInfo: Added rdd_5_22 in memory on 10.1.2.60:40890 (size: 69.8 MB, free: 1281.3 MB)
17/01/29 05:36:06,151 INFO TaskSetManager: Starting task 30.0 in stage 1.0 (TID 32, 10.1.2.60, partition 30, ANY, 5372 bytes)
17/01/29 05:36:06,151 INFO CoarseGrainedSchedulerBackend$DriverEndpoint: Launching task 32 on executor id: 0 hostname: 10.1.2.60.
17/01/29 05:36:06,151 INFO TaskSetManager: Finished task 22.0 in stage 1.0 (TID 24) in 16583 ms on 10.1.2.60 (24/59)
17/01/29 05:36:06,178 INFO BlockManagerInfo: Added rdd_5_21 in memory on 10.1.2.60:40890 (size: 69.9 MB, free: 1211.4 MB)
17/01/29 05:36:06,202 INFO TaskSetManager: Starting task 31.0 in stage 1.0 (TID 33, 10.1.2.60, partition 31, ANY, 5372 bytes)
17/01/29 05:36:06,203 INFO CoarseGrainedSchedulerBackend$DriverEndpoint: Launching task 33 on executor id: 0 hostname: 10.1.2.60.
17/01/29 05:36:06,203 INFO TaskSetManager: Finished task 21.0 in stage 1.0 (TID 23) in 16823 ms on 10.1.2.60 (25/59)
17/01/29 05:36:21,047 INFO BlockManagerInfo: Added rdd_5_24 in memory on 10.1.2.152:46814 (size: 69.8 MB, free: 1208.4 MB)
17/01/29 05:36:21,070 INFO TaskSetManager: Starting task 32.0 in stage 1.0 (TID 34, 10.1.2.152, partition 32, ANY, 5372 bytes)
17/01/29 05:36:21,071 INFO CoarseGrainedSchedulerBackend$DriverEndpoint: Launching task 34 on executor id: 1 hostname: 10.1.2.152.
17/01/29 05:36:21,071 INFO TaskSetManager: Finished task 24.0 in stage 1.0 (TID 26) in 19068 ms on 10.1.2.152 (26/59)
17/01/29 05:36:22,414 INFO BlockManagerInfo: Added rdd_5_27 in memory on 10.1.2.152:46814 (size: 69.9 MB, free: 1138.5 MB)
17/01/29 05:36:22,463 INFO TaskSetManager: Starting task 33.0 in stage 1.0 (TID 35, 10.1.2.152, partition 33, ANY, 5372 bytes)
17/01/29 05:36:22,464 INFO CoarseGrainedSchedulerBackend$DriverEndpoint: Launching task 35 on executor id: 1 hostname: 10.1.2.152.
17/01/29 05:36:22,464 INFO TaskSetManager: Finished task 27.0 in stage 1.0 (TID 29) in 16923 ms on 10.1.2.152 (27/59)
17/01/29 05:36:23,657 INFO BlockManagerInfo: Added rdd_5_25 in memory on 10.1.2.152:46814 (size: 70.0 MB, free: 1068.6 MB)
17/01/29 05:36:23,676 INFO TaskSetManager: Starting task 34.0 in stage 1.0 (TID 36, 10.1.2.152, partition 34, ANY, 5372 bytes)
17/01/29 05:36:23,676 INFO CoarseGrainedSchedulerBackend$DriverEndpoint: Launching task 36 on executor id: 1 hostname: 10.1.2.152.
17/01/29 05:36:23,677 INFO TaskSetManager: Finished task 25.0 in stage 1.0 (TID 27) in 18751 ms on 10.1.2.152 (28/59)
17/01/29 05:36:23,787 INFO BlockManagerInfo: Added rdd_5_26 in memory on 10.1.2.152:46814 (size: 69.9 MB, free: 998.6 MB)
17/01/29 05:36:23,806 INFO TaskSetManager: Starting task 35.0 in stage 1.0 (TID 37, 10.1.2.152, partition 35, ANY, 5372 bytes)
17/01/29 05:36:23,807 INFO CoarseGrainedSchedulerBackend$DriverEndpoint: Launching task 37 on executor id: 1 hostname: 10.1.2.152.
17/01/29 05:36:23,807 INFO TaskSetManager: Finished task 26.0 in stage 1.0 (TID 28) in 18646 ms on 10.1.2.152 (29/59)
17/01/29 05:36:24,309 INFO BlockManagerInfo: Added rdd_5_28 in memory on 10.1.2.60:40890 (size: 70.0 MB, free: 1141.4 MB)
17/01/29 05:36:24,332 INFO TaskSetManager: Starting task 36.0 in stage 1.0 (TID 38, 10.1.2.60, partition 36, ANY, 5372 bytes)
17/01/29 05:36:24,332 INFO CoarseGrainedSchedulerBackend$DriverEndpoint: Launching task 38 on executor id: 0 hostname: 10.1.2.60.
17/01/29 05:36:24,333 INFO TaskSetManager: Finished task 28.0 in stage 1.0 (TID 30) in 18430 ms on 10.1.2.60 (30/59)
17/01/29 05:36:24,876 INFO BlockManagerInfo: Added rdd_5_29 in memory on 10.1.2.60:40890 (size: 69.9 MB, free: 1071.5 MB)
17/01/29 05:36:24,898 INFO TaskSetManager: Starting task 37.0 in stage 1.0 (TID 39, 10.1.2.60, partition 37, ANY, 5372 bytes)
17/01/29 05:36:24,898 INFO CoarseGrainedSchedulerBackend$DriverEndpoint: Launching task 39 on executor id: 0 hostname: 10.1.2.60.
17/01/29 05:36:24,898 INFO TaskSetManager: Finished task 29.0 in stage 1.0 (TID 31) in 18918 ms on 10.1.2.60 (31/59)
17/01/29 05:36:25,392 INFO BlockManagerInfo: Added rdd_5_30 in memory on 10.1.2.60:40890 (size: 70.0 MB, free: 1001.5 MB)
17/01/29 05:36:25,412 INFO TaskSetManager: Starting task 38.0 in stage 1.0 (TID 40, 10.1.2.60, partition 38, ANY, 5372 bytes)
17/01/29 05:36:25,412 INFO CoarseGrainedSchedulerBackend$DriverEndpoint: Launching task 40 on executor id: 0 hostname: 10.1.2.60.
17/01/29 05:36:25,412 INFO TaskSetManager: Finished task 30.0 in stage 1.0 (TID 32) in 19262 ms on 10.1.2.60 (32/59)
17/01/29 05:36:25,520 INFO BlockManagerInfo: Added rdd_5_31 in memory on 10.1.2.60:40890 (size: 69.7 MB, free: 931.8 MB)
17/01/29 05:36:25,540 INFO TaskSetManager: Starting task 39.0 in stage 1.0 (TID 41, 10.1.2.60, partition 39, ANY, 5372 bytes)
17/01/29 05:36:25,540 INFO CoarseGrainedSchedulerBackend$DriverEndpoint: Launching task 41 on executor id: 0 hostname: 10.1.2.60.
17/01/29 05:36:25,541 INFO TaskSetManager: Finished task 31.0 in stage 1.0 (TID 33) in 19340 ms on 10.1.2.60 (33/59)
17/01/29 05:36:38,273 INFO BlockManagerInfo: Added rdd_5_32 in memory on 10.1.2.152:46814 (size: 69.9 MB, free: 928.7 MB)
17/01/29 05:36:38,292 INFO TaskSetManager: Starting task 40.0 in stage 1.0 (TID 42, 10.1.2.152, partition 40, ANY, 5372 bytes)
17/01/29 05:36:38,292 INFO CoarseGrainedSchedulerBackend$DriverEndpoint: Launching task 42 on executor id: 1 hostname: 10.1.2.152.
17/01/29 05:36:38,292 INFO TaskSetManager: Finished task 32.0 in stage 1.0 (TID 34) in 17224 ms on 10.1.2.152 (34/59)
17/01/29 05:36:38,344 INFO BlockManagerInfo: Added rdd_5_33 in memory on 10.1.2.152:46814 (size: 69.9 MB, free: 858.8 MB)
17/01/29 05:36:38,365 INFO TaskSetManager: Starting task 41.0 in stage 1.0 (TID 43, 10.1.2.152, partition 41, ANY, 5372 bytes)
17/01/29 05:36:38,366 INFO CoarseGrainedSchedulerBackend$DriverEndpoint: Launching task 43 on executor id: 1 hostname: 10.1.2.152.
17/01/29 05:36:38,366 INFO TaskSetManager: Finished task 33.0 in stage 1.0 (TID 35) in 15904 ms on 10.1.2.152 (35/59)
17/01/29 05:36:40,109 INFO BlockManagerInfo: Added rdd_5_34 in memory on 10.1.2.152:46814 (size: 70.0 MB, free: 788.8 MB)
17/01/29 05:36:40,129 INFO TaskSetManager: Starting task 42.0 in stage 1.0 (TID 44, 10.1.2.152, partition 42, ANY, 5372 bytes)
17/01/29 05:36:40,129 INFO CoarseGrainedSchedulerBackend$DriverEndpoint: Launching task 44 on executor id: 1 hostname: 10.1.2.152.
17/01/29 05:36:40,130 INFO TaskSetManager: Finished task 34.0 in stage 1.0 (TID 36) in 16455 ms on 10.1.2.152 (36/59)
17/01/29 05:36:40,289 INFO BlockManagerInfo: Added rdd_5_35 in memory on 10.1.2.152:46814 (size: 70.0 MB, free: 718.8 MB)
17/01/29 05:36:40,307 INFO TaskSetManager: Starting task 43.0 in stage 1.0 (TID 45, 10.1.2.152, partition 43, ANY, 5372 bytes)
17/01/29 05:36:40,307 INFO CoarseGrainedSchedulerBackend$DriverEndpoint: Launching task 45 on executor id: 1 hostname: 10.1.2.152.
17/01/29 05:36:40,307 INFO TaskSetManager: Finished task 35.0 in stage 1.0 (TID 37) in 16502 ms on 10.1.2.152 (37/59)
17/01/29 05:36:40,961 INFO BlockManagerInfo: Added rdd_5_36 in memory on 10.1.2.60:40890 (size: 70.0 MB, free: 861.7 MB)
17/01/29 05:36:40,980 INFO TaskSetManager: Starting task 44.0 in stage 1.0 (TID 46, 10.1.2.60, partition 44, ANY, 5372 bytes)
17/01/29 05:36:40,980 INFO CoarseGrainedSchedulerBackend$DriverEndpoint: Launching task 46 on executor id: 0 hostname: 10.1.2.60.
17/01/29 05:36:40,981 INFO TaskSetManager: Finished task 36.0 in stage 1.0 (TID 38) in 16650 ms on 10.1.2.60 (38/59)
17/01/29 05:36:41,427 INFO BlockManagerInfo: Added rdd_5_38 in memory on 10.1.2.60:40890 (size: 70.0 MB, free: 791.7 MB)
17/01/29 05:36:41,443 INFO BlockManagerInfo: Added rdd_5_37 in memory on 10.1.2.60:40890 (size: 69.9 MB, free: 721.8 MB)
17/01/29 05:36:41,452 INFO TaskSetManager: Starting task 45.0 in stage 1.0 (TID 47, 10.1.2.60, partition 45, ANY, 5372 bytes)
17/01/29 05:36:41,452 INFO CoarseGrainedSchedulerBackend$DriverEndpoint: Launching task 47 on executor id: 0 hostname: 10.1.2.60.
17/01/29 05:36:41,452 INFO TaskSetManager: Finished task 38.0 in stage 1.0 (TID 40) in 16042 ms on 10.1.2.60 (39/59)
17/01/29 05:36:41,468 INFO TaskSetManager: Starting task 46.0 in stage 1.0 (TID 48, 10.1.2.60, partition 46, ANY, 5372 bytes)
17/01/29 05:36:41,468 INFO CoarseGrainedSchedulerBackend$DriverEndpoint: Launching task 48 on executor id: 0 hostname: 10.1.2.60.
17/01/29 05:36:41,468 INFO TaskSetManager: Finished task 37.0 in stage 1.0 (TID 39) in 16571 ms on 10.1.2.60 (40/59)
17/01/29 05:36:42,549 INFO BlockManagerInfo: Added rdd_5_39 in memory on 10.1.2.60:40890 (size: 70.0 MB, free: 651.8 MB)
17/01/29 05:36:42,571 INFO TaskSetManager: Starting task 47.0 in stage 1.0 (TID 49, 10.1.2.60, partition 47, ANY, 5372 bytes)
17/01/29 05:36:42,571 INFO CoarseGrainedSchedulerBackend$DriverEndpoint: Launching task 49 on executor id: 0 hostname: 10.1.2.60.
17/01/29 05:36:42,571 INFO TaskSetManager: Finished task 39.0 in stage 1.0 (TID 41) in 17032 ms on 10.1.2.60 (41/59)
17/01/29 05:36:54,799 INFO BlockManagerInfo: Added rdd_5_40 in memory on 10.1.2.152:46814 (size: 70.0 MB, free: 648.8 MB)
17/01/29 05:36:54,817 INFO TaskSetManager: Starting task 48.0 in stage 1.0 (TID 50, 10.1.2.152, partition 48, ANY, 5372 bytes)
17/01/29 05:36:54,818 INFO CoarseGrainedSchedulerBackend$DriverEndpoint: Launching task 50 on executor id: 1 hostname: 10.1.2.152.
17/01/29 05:36:54,818 INFO TaskSetManager: Finished task 40.0 in stage 1.0 (TID 42) in 16527 ms on 10.1.2.152 (42/59)
17/01/29 05:36:55,925 INFO BlockManagerInfo: Added rdd_5_41 in memory on 10.1.2.152:46814 (size: 70.0 MB, free: 578.9 MB)
17/01/29 05:36:55,986 INFO TaskSetManager: Starting task 49.0 in stage 1.0 (TID 51, 10.1.2.152, partition 49, ANY, 5372 bytes)
17/01/29 05:36:55,986 INFO CoarseGrainedSchedulerBackend$DriverEndpoint: Launching task 51 on executor id: 1 hostname: 10.1.2.152.
17/01/29 05:36:55,987 INFO TaskSetManager: Finished task 41.0 in stage 1.0 (TID 43) in 17622 ms on 10.1.2.152 (43/59)
17/01/29 05:36:57,420 INFO BlockManagerInfo: Added rdd_5_43 in memory on 10.1.2.152:46814 (size: 69.8 MB, free: 509.0 MB)
17/01/29 05:36:57,438 INFO TaskSetManager: Starting task 50.0 in stage 1.0 (TID 52, 10.1.2.152, partition 50, ANY, 5372 bytes)
17/01/29 05:36:57,439 INFO CoarseGrainedSchedulerBackend$DriverEndpoint: Launching task 52 on executor id: 1 hostname: 10.1.2.152.
17/01/29 05:36:57,439 INFO TaskSetManager: Finished task 43.0 in stage 1.0 (TID 45) in 17133 ms on 10.1.2.152 (44/59)
17/01/29 05:36:57,489 INFO BlockManagerInfo: Added rdd_5_42 in memory on 10.1.2.152:46814 (size: 69.8 MB, free: 439.2 MB)
17/01/29 05:36:57,506 INFO TaskSetManager: Starting task 51.0 in stage 1.0 (TID 53, 10.1.2.152, partition 51, ANY, 5372 bytes)
17/01/29 05:36:57,506 INFO CoarseGrainedSchedulerBackend$DriverEndpoint: Launching task 53 on executor id: 1 hostname: 10.1.2.152.
17/01/29 05:36:57,507 INFO TaskSetManager: Finished task 42.0 in stage 1.0 (TID 44) in 17378 ms on 10.1.2.152 (45/59)
17/01/29 05:37:04,629 INFO BlockManagerInfo: Added rdd_5_45 in memory on 10.1.2.60:40890 (size: 69.9 MB, free: 582.0 MB)
17/01/29 05:37:04,647 INFO TaskSetManager: Starting task 52.0 in stage 1.0 (TID 54, 10.1.2.60, partition 52, ANY, 5372 bytes)
17/01/29 05:37:04,648 INFO CoarseGrainedSchedulerBackend$DriverEndpoint: Launching task 54 on executor id: 0 hostname: 10.1.2.60.
17/01/29 05:37:04,648 INFO TaskSetManager: Finished task 45.0 in stage 1.0 (TID 47) in 23197 ms on 10.1.2.60 (46/59)
17/01/29 05:37:04,861 INFO BlockManagerInfo: Added rdd_5_44 in memory on 10.1.2.60:40890 (size: 70.0 MB, free: 512.0 MB)
17/01/29 05:37:04,879 INFO TaskSetManager: Starting task 53.0 in stage 1.0 (TID 55, 10.1.2.60, partition 53, ANY, 5372 bytes)
17/01/29 05:37:04,879 INFO CoarseGrainedSchedulerBackend$DriverEndpoint: Launching task 55 on executor id: 0 hostname: 10.1.2.60.
17/01/29 05:37:04,879 INFO TaskSetManager: Finished task 44.0 in stage 1.0 (TID 46) in 23900 ms on 10.1.2.60 (47/59)
17/01/29 05:37:05,420 INFO BlockManagerInfo: Added rdd_5_46 in memory on 10.1.2.60:40890 (size: 69.9 MB, free: 442.1 MB)
17/01/29 05:37:05,438 INFO TaskSetManager: Starting task 54.0 in stage 1.0 (TID 56, 10.1.2.60, partition 54, ANY, 5372 bytes)
17/01/29 05:37:05,439 INFO CoarseGrainedSchedulerBackend$DriverEndpoint: Launching task 56 on executor id: 0 hostname: 10.1.2.60.
17/01/29 05:37:05,439 INFO TaskSetManager: Finished task 46.0 in stage 1.0 (TID 48) in 23972 ms on 10.1.2.60 (48/59)
17/01/29 05:37:06,306 INFO BlockManagerInfo: Added rdd_5_47 in memory on 10.1.2.60:40890 (size: 70.0 MB, free: 372.1 MB)
17/01/29 05:37:06,325 INFO TaskSetManager: Starting task 55.0 in stage 1.0 (TID 57, 10.1.2.60, partition 55, ANY, 5372 bytes)
17/01/29 05:37:06,325 INFO CoarseGrainedSchedulerBackend$DriverEndpoint: Launching task 57 on executor id: 0 hostname: 10.1.2.60.
17/01/29 05:37:06,325 INFO TaskSetManager: Finished task 47.0 in stage 1.0 (TID 49) in 23755 ms on 10.1.2.60 (49/59)
17/01/29 05:37:16,747 INFO BlockManagerInfo: Added rdd_5_48 in memory on 10.1.2.152:46814 (size: 69.9 MB, free: 369.4 MB)
17/01/29 05:37:16,764 INFO TaskSetManager: Starting task 56.0 in stage 1.0 (TID 58, 10.1.2.152, partition 56, ANY, 5372 bytes)
17/01/29 05:37:16,764 INFO CoarseGrainedSchedulerBackend$DriverEndpoint: Launching task 58 on executor id: 1 hostname: 10.1.2.152.
17/01/29 05:37:16,765 INFO TaskSetManager: Finished task 48.0 in stage 1.0 (TID 50) in 21947 ms on 10.1.2.152 (50/59)
17/01/29 05:37:18,200 INFO BlockManagerInfo: Added rdd_5_50 in memory on 10.1.2.152:46814 (size: 69.9 MB, free: 299.5 MB)
17/01/29 05:37:18,219 INFO TaskSetManager: Starting task 57.0 in stage 1.0 (TID 59, 10.1.2.152, partition 57, ANY, 5372 bytes)
17/01/29 05:37:18,220 INFO CoarseGrainedSchedulerBackend$DriverEndpoint: Launching task 59 on executor id: 1 hostname: 10.1.2.152.
17/01/29 05:37:18,221 INFO TaskSetManager: Finished task 50.0 in stage 1.0 (TID 52) in 20783 ms on 10.1.2.152 (51/59)
17/01/29 05:37:18,432 INFO BlockManagerInfo: Added rdd_5_49 in memory on 10.1.2.152:46814 (size: 69.8 MB, free: 229.7 MB)
17/01/29 05:37:18,450 INFO TaskSetManager: Finished task 49.0 in stage 1.0 (TID 51) in 22465 ms on 10.1.2.152 (52/59)
17/01/29 05:37:18,912 INFO BlockManagerInfo: Added rdd_5_51 in memory on 10.1.2.152:46814 (size: 69.9 MB, free: 159.8 MB)
17/01/29 05:37:18,931 INFO TaskSetManager: Finished task 51.0 in stage 1.0 (TID 53) in 21425 ms on 10.1.2.152 (53/59)
17/01/29 05:37:24,640 INFO BlockManagerInfo: Added rdd_5_54 in memory on 10.1.2.60:40890 (size: 69.9 MB, free: 302.2 MB)
17/01/29 05:37:24,659 INFO TaskSetManager: Finished task 54.0 in stage 1.0 (TID 56) in 19221 ms on 10.1.2.60 (54/59)
17/01/29 05:37:24,946 INFO BlockManagerInfo: Added rdd_5_53 in memory on 10.1.2.60:40890 (size: 70.0 MB, free: 232.1 MB)
17/01/29 05:37:24,964 INFO TaskSetManager: Finished task 53.0 in stage 1.0 (TID 55) in 20086 ms on 10.1.2.60 (55/59)
17/01/29 05:37:25,590 INFO BlockManagerInfo: Added rdd_5_55 in memory on 10.1.2.60:40890 (size: 69.9 MB, free: 162.3 MB)
17/01/29 05:37:25,605 INFO TaskSetManager: Finished task 55.0 in stage 1.0 (TID 57) in 19281 ms on 10.1.2.60 (56/59)
17/01/29 05:37:25,615 INFO BlockManagerInfo: Added rdd_5_52 in memory on 10.1.2.60:40890 (size: 69.9 MB, free: 92.4 MB)
17/01/29 05:37:25,631 INFO TaskSetManager: Finished task 52.0 in stage 1.0 (TID 54) in 20984 ms on 10.1.2.60 (57/59)
17/01/29 05:37:25,765 INFO TaskSetManager: Finished task 56.0 in stage 1.0 (TID 58) in 9002 ms on 10.1.2.152 (58/59)
17/01/29 05:37:26,220 INFO BlockManagerInfo: Added rdd_5_57 in memory on 10.1.2.152:46814 (size: 70.1 MB, free: 89.7 MB)
17/01/29 05:37:26,237 INFO TaskSetManager: Finished task 57.0 in stage 1.0 (TID 59) in 8018 ms on 10.1.2.152 (59/59)
17/01/29 05:37:26,237 INFO TaskSchedulerImpl: Removed TaskSet 1.0, whose tasks have all completed, from pool 
17/01/29 05:37:26,239 INFO DAGScheduler: ResultStage 1 (count at DataValidators.scala:40) finished in 139.147 s
17/01/29 05:37:26,239 INFO DAGScheduler: Job 1 finished: count at DataValidators.scala:40, took 139.187488 s
17/01/29 05:37:26,250 INFO SparkContext: Starting job: count at GradientDescent.scala:209
17/01/29 05:37:26,252 INFO DAGScheduler: Got job 2 (count at GradientDescent.scala:209) with 59 output partitions
17/01/29 05:37:26,252 INFO DAGScheduler: Final stage: ResultStage 2 (count at GradientDescent.scala:209)
17/01/29 05:37:26,252 INFO DAGScheduler: Parents of final stage: List()
17/01/29 05:37:26,255 INFO DAGScheduler: Missing parents: List()
17/01/29 05:37:26,256 INFO DAGScheduler: Submitting ResultStage 2 (MapPartitionsRDD[8] at map at GeneralizedLinearAlgorithm.scala:297), which has no missing parents
17/01/29 05:37:26,262 INFO MemoryStore: Block broadcast_3 stored as values in memory (estimated size 3.9 KB, free 2.1 GB)
17/01/29 05:37:26,264 INFO MemoryStore: Block broadcast_3_piece0 stored as bytes in memory (estimated size 2.2 KB, free 2.1 GB)
17/01/29 05:37:26,265 INFO BlockManagerInfo: Added broadcast_3_piece0 in memory on 10.1.2.31:36114 (size: 2.2 KB, free: 2.1 GB)
17/01/29 05:37:26,271 INFO SparkContext: Created broadcast 3 from broadcast at DAGScheduler.scala:1012
17/01/29 05:37:26,272 INFO DAGScheduler: Submitting 59 missing tasks from ResultStage 2 (MapPartitionsRDD[8] at map at GeneralizedLinearAlgorithm.scala:297)
17/01/29 05:37:26,273 INFO TaskSchedulerImpl: Adding task set 2.0 with 59 tasks
17/01/29 05:37:26,276 INFO TaskSetManager: Starting task 0.0 in stage 2.0 (TID 60, 10.1.2.60, partition 0, PROCESS_LOCAL, 5372 bytes)
17/01/29 05:37:26,277 INFO TaskSetManager: Starting task 1.0 in stage 2.0 (TID 61, 10.1.2.152, partition 1, PROCESS_LOCAL, 5372 bytes)
17/01/29 05:37:26,278 INFO TaskSetManager: Starting task 2.0 in stage 2.0 (TID 62, 10.1.2.60, partition 2, PROCESS_LOCAL, 5372 bytes)
17/01/29 05:37:26,279 INFO TaskSetManager: Starting task 3.0 in stage 2.0 (TID 63, 10.1.2.152, partition 3, PROCESS_LOCAL, 5372 bytes)
17/01/29 05:37:26,280 INFO TaskSetManager: Starting task 4.0 in stage 2.0 (TID 64, 10.1.2.60, partition 4, PROCESS_LOCAL, 5372 bytes)
17/01/29 05:37:26,282 INFO TaskSetManager: Starting task 5.0 in stage 2.0 (TID 65, 10.1.2.152, partition 5, PROCESS_LOCAL, 5372 bytes)
17/01/29 05:37:26,283 INFO TaskSetManager: Starting task 6.0 in stage 2.0 (TID 66, 10.1.2.60, partition 6, PROCESS_LOCAL, 5372 bytes)
17/01/29 05:37:26,284 INFO TaskSetManager: Starting task 8.0 in stage 2.0 (TID 67, 10.1.2.152, partition 8, PROCESS_LOCAL, 5372 bytes)
17/01/29 05:37:26,285 INFO CoarseGrainedSchedulerBackend$DriverEndpoint: Launching task 60 on executor id: 0 hostname: 10.1.2.60.
17/01/29 05:37:26,285 INFO CoarseGrainedSchedulerBackend$DriverEndpoint: Launching task 62 on executor id: 0 hostname: 10.1.2.60.
17/01/29 05:37:26,286 INFO CoarseGrainedSchedulerBackend$DriverEndpoint: Launching task 64 on executor id: 0 hostname: 10.1.2.60.
17/01/29 05:37:26,286 INFO CoarseGrainedSchedulerBackend$DriverEndpoint: Launching task 66 on executor id: 0 hostname: 10.1.2.60.
17/01/29 05:37:26,286 INFO CoarseGrainedSchedulerBackend$DriverEndpoint: Launching task 61 on executor id: 1 hostname: 10.1.2.152.
17/01/29 05:37:26,287 INFO CoarseGrainedSchedulerBackend$DriverEndpoint: Launching task 63 on executor id: 1 hostname: 10.1.2.152.
17/01/29 05:37:26,288 INFO CoarseGrainedSchedulerBackend$DriverEndpoint: Launching task 65 on executor id: 1 hostname: 10.1.2.152.
17/01/29 05:37:26,289 INFO CoarseGrainedSchedulerBackend$DriverEndpoint: Launching task 67 on executor id: 1 hostname: 10.1.2.152.
17/01/29 05:37:26,307 INFO BlockManagerInfo: Added broadcast_3_piece0 in memory on 10.1.2.60:40890 (size: 2.2 KB, free: 92.4 MB)
17/01/29 05:37:26,313 INFO BlockManagerInfo: Added broadcast_3_piece0 in memory on 10.1.2.152:46814 (size: 2.2 KB, free: 89.7 MB)
17/01/29 05:37:26,341 INFO TaskSetManager: Starting task 7.0 in stage 2.0 (TID 68, 10.1.2.60, partition 7, PROCESS_LOCAL, 5372 bytes)
17/01/29 05:37:26,341 INFO CoarseGrainedSchedulerBackend$DriverEndpoint: Launching task 68 on executor id: 0 hostname: 10.1.2.60.
17/01/29 05:37:26,342 INFO TaskSetManager: Finished task 2.0 in stage 2.0 (TID 62) in 64 ms on 10.1.2.60 (1/59)
17/01/29 05:37:26,344 INFO TaskSetManager: Starting task 9.0 in stage 2.0 (TID 69, 10.1.2.60, partition 9, PROCESS_LOCAL, 5372 bytes)
17/01/29 05:37:26,344 INFO CoarseGrainedSchedulerBackend$DriverEndpoint: Launching task 69 on executor id: 0 hostname: 10.1.2.60.
17/01/29 05:37:26,345 INFO TaskSetManager: Finished task 4.0 in stage 2.0 (TID 64) in 66 ms on 10.1.2.60 (2/59)
17/01/29 05:37:26,347 INFO TaskSetManager: Starting task 10.0 in stage 2.0 (TID 70, 10.1.2.60, partition 10, PROCESS_LOCAL, 5372 bytes)
17/01/29 05:37:26,347 INFO CoarseGrainedSchedulerBackend$DriverEndpoint: Launching task 70 on executor id: 0 hostname: 10.1.2.60.
17/01/29 05:37:26,347 INFO TaskSetManager: Finished task 0.0 in stage 2.0 (TID 60) in 72 ms on 10.1.2.60 (3/59)
17/01/29 05:37:26,349 INFO TaskSetManager: Starting task 11.0 in stage 2.0 (TID 71, 10.1.2.60, partition 11, PROCESS_LOCAL, 5372 bytes)
17/01/29 05:37:26,349 INFO CoarseGrainedSchedulerBackend$DriverEndpoint: Launching task 71 on executor id: 0 hostname: 10.1.2.60.
17/01/29 05:37:26,350 INFO TaskSetManager: Finished task 6.0 in stage 2.0 (TID 66) in 67 ms on 10.1.2.60 (4/59)
17/01/29 05:37:26,360 INFO TaskSetManager: Starting task 13.0 in stage 2.0 (TID 72, 10.1.2.152, partition 13, PROCESS_LOCAL, 5372 bytes)
17/01/29 05:37:26,360 INFO CoarseGrainedSchedulerBackend$DriverEndpoint: Launching task 72 on executor id: 1 hostname: 10.1.2.152.
17/01/29 05:37:26,360 INFO TaskSetManager: Finished task 8.0 in stage 2.0 (TID 67) in 77 ms on 10.1.2.152 (5/59)
17/01/29 05:37:26,368 INFO TaskSetManager: Starting task 14.0 in stage 2.0 (TID 73, 10.1.2.152, partition 14, PROCESS_LOCAL, 5372 bytes)
17/01/29 05:37:26,368 INFO CoarseGrainedSchedulerBackend$DriverEndpoint: Launching task 73 on executor id: 1 hostname: 10.1.2.152.
17/01/29 05:37:26,368 INFO TaskSetManager: Finished task 1.0 in stage 2.0 (TID 61) in 92 ms on 10.1.2.152 (6/59)
17/01/29 05:37:26,371 INFO TaskSetManager: Starting task 15.0 in stage 2.0 (TID 74, 10.1.2.152, partition 15, PROCESS_LOCAL, 5372 bytes)
17/01/29 05:37:26,372 INFO CoarseGrainedSchedulerBackend$DriverEndpoint: Launching task 74 on executor id: 1 hostname: 10.1.2.152.
17/01/29 05:37:26,372 INFO TaskSetManager: Finished task 5.0 in stage 2.0 (TID 65) in 92 ms on 10.1.2.152 (7/59)
17/01/29 05:37:26,384 INFO TaskSetManager: Starting task 16.0 in stage 2.0 (TID 75, 10.1.2.152, partition 16, PROCESS_LOCAL, 5372 bytes)
17/01/29 05:37:26,384 INFO CoarseGrainedSchedulerBackend$DriverEndpoint: Launching task 75 on executor id: 1 hostname: 10.1.2.152.
17/01/29 05:37:26,384 INFO TaskSetManager: Finished task 3.0 in stage 2.0 (TID 63) in 106 ms on 10.1.2.152 (8/59)
17/01/29 05:37:26,388 INFO TaskSetManager: Starting task 12.0 in stage 2.0 (TID 76, 10.1.2.60, partition 12, PROCESS_LOCAL, 5372 bytes)
17/01/29 05:37:26,388 INFO CoarseGrainedSchedulerBackend$DriverEndpoint: Launching task 76 on executor id: 0 hostname: 10.1.2.60.
17/01/29 05:37:26,388 INFO TaskSetManager: Finished task 11.0 in stage 2.0 (TID 71) in 40 ms on 10.1.2.60 (9/59)
17/01/29 05:37:26,389 INFO TaskSetManager: Finished task 9.0 in stage 2.0 (TID 69) in 46 ms on 10.1.2.60 (10/59)
17/01/29 05:37:26,390 INFO TaskSetManager: Starting task 20.0 in stage 2.0 (TID 77, 10.1.2.60, partition 20, PROCESS_LOCAL, 5372 bytes)
17/01/29 05:37:26,391 INFO CoarseGrainedSchedulerBackend$DriverEndpoint: Launching task 77 on executor id: 0 hostname: 10.1.2.60.
17/01/29 05:37:26,392 INFO TaskSetManager: Starting task 21.0 in stage 2.0 (TID 78, 10.1.2.60, partition 21, PROCESS_LOCAL, 5372 bytes)
17/01/29 05:37:26,392 INFO CoarseGrainedSchedulerBackend$DriverEndpoint: Launching task 78 on executor id: 0 hostname: 10.1.2.60.
17/01/29 05:37:26,392 INFO TaskSetManager: Finished task 7.0 in stage 2.0 (TID 68) in 52 ms on 10.1.2.60 (11/59)
17/01/29 05:37:26,400 INFO TaskSetManager: Starting task 22.0 in stage 2.0 (TID 79, 10.1.2.60, partition 22, PROCESS_LOCAL, 5372 bytes)
17/01/29 05:37:26,400 INFO CoarseGrainedSchedulerBackend$DriverEndpoint: Launching task 79 on executor id: 0 hostname: 10.1.2.60.
17/01/29 05:37:26,400 INFO TaskSetManager: Finished task 10.0 in stage 2.0 (TID 70) in 54 ms on 10.1.2.60 (12/59)
17/01/29 05:37:26,406 INFO TaskSetManager: Starting task 17.0 in stage 2.0 (TID 80, 10.1.2.152, partition 17, PROCESS_LOCAL, 5372 bytes)
17/01/29 05:37:26,406 INFO CoarseGrainedSchedulerBackend$DriverEndpoint: Launching task 80 on executor id: 1 hostname: 10.1.2.152.
17/01/29 05:37:26,406 INFO TaskSetManager: Finished task 13.0 in stage 2.0 (TID 72) in 48 ms on 10.1.2.152 (13/59)
17/01/29 05:37:26,409 INFO TaskSetManager: Starting task 18.0 in stage 2.0 (TID 81, 10.1.2.152, partition 18, PROCESS_LOCAL, 5372 bytes)
17/01/29 05:37:26,409 INFO CoarseGrainedSchedulerBackend$DriverEndpoint: Launching task 81 on executor id: 1 hostname: 10.1.2.152.
17/01/29 05:37:26,409 INFO TaskSetManager: Finished task 14.0 in stage 2.0 (TID 73) in 42 ms on 10.1.2.152 (14/59)
17/01/29 05:37:26,412 INFO TaskSetManager: Starting task 23.0 in stage 2.0 (TID 82, 10.1.2.60, partition 23, PROCESS_LOCAL, 5372 bytes)
17/01/29 05:37:26,412 INFO CoarseGrainedSchedulerBackend$DriverEndpoint: Launching task 82 on executor id: 0 hostname: 10.1.2.60.
17/01/29 05:37:26,412 INFO TaskSetManager: Finished task 12.0 in stage 2.0 (TID 76) in 25 ms on 10.1.2.60 (15/59)
17/01/29 05:37:26,420 INFO TaskSetManager: Starting task 28.0 in stage 2.0 (TID 83, 10.1.2.60, partition 28, PROCESS_LOCAL, 5372 bytes)
17/01/29 05:37:26,420 INFO CoarseGrainedSchedulerBackend$DriverEndpoint: Launching task 83 on executor id: 0 hostname: 10.1.2.60.
17/01/29 05:37:26,420 INFO TaskSetManager: Finished task 21.0 in stage 2.0 (TID 78) in 29 ms on 10.1.2.60 (16/59)
17/01/29 05:37:26,422 INFO TaskSetManager: Starting task 29.0 in stage 2.0 (TID 84, 10.1.2.60, partition 29, PROCESS_LOCAL, 5372 bytes)
17/01/29 05:37:26,423 INFO CoarseGrainedSchedulerBackend$DriverEndpoint: Launching task 84 on executor id: 0 hostname: 10.1.2.60.
17/01/29 05:37:26,423 INFO TaskSetManager: Finished task 20.0 in stage 2.0 (TID 77) in 33 ms on 10.1.2.60 (17/59)
17/01/29 05:37:26,432 INFO TaskSetManager: Starting task 19.0 in stage 2.0 (TID 85, 10.1.2.152, partition 19, PROCESS_LOCAL, 5372 bytes)
17/01/29 05:37:26,432 INFO CoarseGrainedSchedulerBackend$DriverEndpoint: Launching task 85 on executor id: 1 hostname: 10.1.2.152.
17/01/29 05:37:26,433 INFO TaskSetManager: Finished task 16.0 in stage 2.0 (TID 75) in 50 ms on 10.1.2.152 (18/59)
17/01/29 05:37:26,435 INFO TaskSetManager: Starting task 24.0 in stage 2.0 (TID 86, 10.1.2.152, partition 24, PROCESS_LOCAL, 5372 bytes)
17/01/29 05:37:26,435 INFO CoarseGrainedSchedulerBackend$DriverEndpoint: Launching task 86 on executor id: 1 hostname: 10.1.2.152.
17/01/29 05:37:26,436 INFO TaskSetManager: Starting task 30.0 in stage 2.0 (TID 87, 10.1.2.60, partition 30, PROCESS_LOCAL, 5372 bytes)
17/01/29 05:37:26,436 INFO CoarseGrainedSchedulerBackend$DriverEndpoint: Launching task 87 on executor id: 0 hostname: 10.1.2.60.
17/01/29 05:37:26,437 INFO TaskSetManager: Finished task 15.0 in stage 2.0 (TID 74) in 67 ms on 10.1.2.152 (19/59)
17/01/29 05:37:26,437 INFO TaskSetManager: Finished task 22.0 in stage 2.0 (TID 79) in 38 ms on 10.1.2.60 (20/59)
17/01/29 05:37:26,438 INFO TaskSetManager: Starting task 31.0 in stage 2.0 (TID 88, 10.1.2.60, partition 31, PROCESS_LOCAL, 5372 bytes)
17/01/29 05:37:26,439 INFO CoarseGrainedSchedulerBackend$DriverEndpoint: Launching task 88 on executor id: 0 hostname: 10.1.2.60.
17/01/29 05:37:26,439 INFO TaskSetManager: Finished task 23.0 in stage 2.0 (TID 82) in 28 ms on 10.1.2.60 (21/59)
17/01/29 05:37:26,445 INFO TaskSetManager: Starting task 36.0 in stage 2.0 (TID 89, 10.1.2.60, partition 36, PROCESS_LOCAL, 5372 bytes)
17/01/29 05:37:26,446 INFO CoarseGrainedSchedulerBackend$DriverEndpoint: Launching task 89 on executor id: 0 hostname: 10.1.2.60.
17/01/29 05:37:26,446 INFO TaskSetManager: Finished task 28.0 in stage 2.0 (TID 83) in 27 ms on 10.1.2.60 (22/59)
17/01/29 05:37:26,448 INFO TaskSetManager: Starting task 37.0 in stage 2.0 (TID 90, 10.1.2.60, partition 37, PROCESS_LOCAL, 5372 bytes)
17/01/29 05:37:26,449 INFO CoarseGrainedSchedulerBackend$DriverEndpoint: Launching task 90 on executor id: 0 hostname: 10.1.2.60.
17/01/29 05:37:26,449 INFO TaskSetManager: Finished task 29.0 in stage 2.0 (TID 84) in 27 ms on 10.1.2.60 (23/59)
17/01/29 05:37:26,451 INFO TaskSetManager: Starting task 25.0 in stage 2.0 (TID 91, 10.1.2.152, partition 25, PROCESS_LOCAL, 5372 bytes)
17/01/29 05:37:26,451 INFO CoarseGrainedSchedulerBackend$DriverEndpoint: Launching task 91 on executor id: 1 hostname: 10.1.2.152.
17/01/29 05:37:26,452 INFO TaskSetManager: Finished task 17.0 in stage 2.0 (TID 80) in 46 ms on 10.1.2.152 (24/59)
17/01/29 05:37:26,461 INFO TaskSetManager: Starting task 38.0 in stage 2.0 (TID 92, 10.1.2.60, partition 38, PROCESS_LOCAL, 5372 bytes)
17/01/29 05:37:26,461 INFO CoarseGrainedSchedulerBackend$DriverEndpoint: Launching task 92 on executor id: 0 hostname: 10.1.2.60.
17/01/29 05:37:26,461 INFO TaskSetManager: Finished task 31.0 in stage 2.0 (TID 88) in 23 ms on 10.1.2.60 (25/59)
17/01/29 05:37:26,465 INFO TaskSetManager: Starting task 26.0 in stage 2.0 (TID 93, 10.1.2.152, partition 26, PROCESS_LOCAL, 5372 bytes)
17/01/29 05:37:26,466 INFO CoarseGrainedSchedulerBackend$DriverEndpoint: Launching task 93 on executor id: 1 hostname: 10.1.2.152.
17/01/29 05:37:26,466 INFO TaskSetManager: Finished task 18.0 in stage 2.0 (TID 81) in 58 ms on 10.1.2.152 (26/59)
17/01/29 05:37:26,472 INFO TaskSetManager: Starting task 39.0 in stage 2.0 (TID 94, 10.1.2.60, partition 39, PROCESS_LOCAL, 5372 bytes)
17/01/29 05:37:26,473 INFO CoarseGrainedSchedulerBackend$DriverEndpoint: Launching task 94 on executor id: 0 hostname: 10.1.2.60.
17/01/29 05:37:26,473 INFO TaskSetManager: Finished task 36.0 in stage 2.0 (TID 89) in 28 ms on 10.1.2.60 (27/59)
17/01/29 05:37:26,474 INFO TaskSetManager: Starting task 44.0 in stage 2.0 (TID 95, 10.1.2.60, partition 44, PROCESS_LOCAL, 5372 bytes)
17/01/29 05:37:26,474 INFO CoarseGrainedSchedulerBackend$DriverEndpoint: Launching task 95 on executor id: 0 hostname: 10.1.2.60.
17/01/29 05:37:26,475 INFO TaskSetManager: Finished task 37.0 in stage 2.0 (TID 90) in 27 ms on 10.1.2.60 (28/59)
17/01/29 05:37:26,477 INFO TaskSetManager: Starting task 45.0 in stage 2.0 (TID 96, 10.1.2.60, partition 45, PROCESS_LOCAL, 5372 bytes)
17/01/29 05:37:26,477 INFO CoarseGrainedSchedulerBackend$DriverEndpoint: Launching task 96 on executor id: 0 hostname: 10.1.2.60.
17/01/29 05:37:26,478 INFO TaskSetManager: Finished task 30.0 in stage 2.0 (TID 87) in 42 ms on 10.1.2.60 (29/59)
17/01/29 05:37:26,481 INFO TaskSetManager: Starting task 27.0 in stage 2.0 (TID 97, 10.1.2.152, partition 27, PROCESS_LOCAL, 5372 bytes)
17/01/29 05:37:26,481 INFO CoarseGrainedSchedulerBackend$DriverEndpoint: Launching task 97 on executor id: 1 hostname: 10.1.2.152.
17/01/29 05:37:26,481 INFO TaskSetManager: Finished task 19.0 in stage 2.0 (TID 85) in 50 ms on 10.1.2.152 (30/59)
17/01/29 05:37:26,484 INFO TaskSetManager: Starting task 46.0 in stage 2.0 (TID 98, 10.1.2.60, partition 46, PROCESS_LOCAL, 5372 bytes)
17/01/29 05:37:26,484 INFO CoarseGrainedSchedulerBackend$DriverEndpoint: Launching task 98 on executor id: 0 hostname: 10.1.2.60.
17/01/29 05:37:26,484 INFO TaskSetManager: Finished task 38.0 in stage 2.0 (TID 92) in 24 ms on 10.1.2.60 (31/59)
17/01/29 05:37:26,487 INFO TaskSetManager: Starting task 32.0 in stage 2.0 (TID 99, 10.1.2.152, partition 32, PROCESS_LOCAL, 5372 bytes)
17/01/29 05:37:26,487 INFO CoarseGrainedSchedulerBackend$DriverEndpoint: Launching task 99 on executor id: 1 hostname: 10.1.2.152.
17/01/29 05:37:26,488 INFO TaskSetManager: Finished task 24.0 in stage 2.0 (TID 86) in 54 ms on 10.1.2.152 (32/59)
17/01/29 05:37:26,498 INFO TaskSetManager: Starting task 47.0 in stage 2.0 (TID 100, 10.1.2.60, partition 47, PROCESS_LOCAL, 5372 bytes)
17/01/29 05:37:26,498 INFO CoarseGrainedSchedulerBackend$DriverEndpoint: Launching task 100 on executor id: 0 hostname: 10.1.2.60.
17/01/29 05:37:26,498 INFO TaskSetManager: Finished task 44.0 in stage 2.0 (TID 95) in 24 ms on 10.1.2.60 (33/59)
17/01/29 05:37:26,507 INFO TaskSetManager: Starting task 52.0 in stage 2.0 (TID 101, 10.1.2.60, partition 52, PROCESS_LOCAL, 5372 bytes)
17/01/29 05:37:26,507 INFO CoarseGrainedSchedulerBackend$DriverEndpoint: Launching task 101 on executor id: 0 hostname: 10.1.2.60.
17/01/29 05:37:26,507 INFO TaskSetManager: Finished task 46.0 in stage 2.0 (TID 98) in 24 ms on 10.1.2.60 (34/59)
17/01/29 05:37:26,511 INFO TaskSetManager: Starting task 33.0 in stage 2.0 (TID 102, 10.1.2.152, partition 33, PROCESS_LOCAL, 5372 bytes)
17/01/29 05:37:26,511 INFO CoarseGrainedSchedulerBackend$DriverEndpoint: Launching task 102 on executor id: 1 hostname: 10.1.2.152.
17/01/29 05:37:26,512 INFO TaskSetManager: Finished task 26.0 in stage 2.0 (TID 93) in 46 ms on 10.1.2.152 (35/59)
17/01/29 05:37:26,513 INFO TaskSetManager: Starting task 53.0 in stage 2.0 (TID 103, 10.1.2.60, partition 53, PROCESS_LOCAL, 5372 bytes)
17/01/29 05:37:26,513 INFO CoarseGrainedSchedulerBackend$DriverEndpoint: Launching task 103 on executor id: 0 hostname: 10.1.2.60.
17/01/29 05:37:26,514 INFO TaskSetManager: Finished task 39.0 in stage 2.0 (TID 94) in 42 ms on 10.1.2.60 (36/59)
17/01/29 05:37:26,515 INFO TaskSetManager: Starting task 34.0 in stage 2.0 (TID 104, 10.1.2.152, partition 34, PROCESS_LOCAL, 5372 bytes)
17/01/29 05:37:26,515 INFO CoarseGrainedSchedulerBackend$DriverEndpoint: Launching task 104 on executor id: 1 hostname: 10.1.2.152.
17/01/29 05:37:26,516 INFO TaskSetManager: Finished task 25.0 in stage 2.0 (TID 91) in 65 ms on 10.1.2.152 (37/59)
17/01/29 05:37:26,518 INFO TaskSetManager: Starting task 54.0 in stage 2.0 (TID 105, 10.1.2.60, partition 54, PROCESS_LOCAL, 5372 bytes)
17/01/29 05:37:26,518 INFO CoarseGrainedSchedulerBackend$DriverEndpoint: Launching task 105 on executor id: 0 hostname: 10.1.2.60.
17/01/29 05:37:26,519 INFO TaskSetManager: Finished task 45.0 in stage 2.0 (TID 96) in 42 ms on 10.1.2.60 (38/59)
17/01/29 05:37:26,521 INFO TaskSetManager: Starting task 55.0 in stage 2.0 (TID 106, 10.1.2.60, partition 55, PROCESS_LOCAL, 5372 bytes)
17/01/29 05:37:26,522 INFO CoarseGrainedSchedulerBackend$DriverEndpoint: Launching task 106 on executor id: 0 hostname: 10.1.2.60.
17/01/29 05:37:26,522 INFO TaskSetManager: Finished task 47.0 in stage 2.0 (TID 100) in 25 ms on 10.1.2.60 (39/59)
17/01/29 05:37:26,533 INFO TaskSetManager: Starting task 35.0 in stage 2.0 (TID 107, 10.1.2.152, partition 35, PROCESS_LOCAL, 5372 bytes)
17/01/29 05:37:26,533 INFO CoarseGrainedSchedulerBackend$DriverEndpoint: Launching task 107 on executor id: 1 hostname: 10.1.2.152.
17/01/29 05:37:26,534 INFO TaskSetManager: Finished task 27.0 in stage 2.0 (TID 97) in 53 ms on 10.1.2.152 (40/59)
17/01/29 05:37:26,535 INFO TaskSetManager: Finished task 53.0 in stage 2.0 (TID 103) in 23 ms on 10.1.2.60 (41/59)
17/01/29 05:37:26,538 INFO TaskSetManager: Finished task 52.0 in stage 2.0 (TID 101) in 32 ms on 10.1.2.60 (42/59)
17/01/29 05:37:26,543 INFO TaskSetManager: Finished task 54.0 in stage 2.0 (TID 105) in 26 ms on 10.1.2.60 (43/59)
17/01/29 05:37:26,544 INFO TaskSetManager: Starting task 40.0 in stage 2.0 (TID 108, 10.1.2.152, partition 40, PROCESS_LOCAL, 5372 bytes)
17/01/29 05:37:26,545 INFO CoarseGrainedSchedulerBackend$DriverEndpoint: Launching task 108 on executor id: 1 hostname: 10.1.2.152.
17/01/29 05:37:26,545 INFO TaskSetManager: Finished task 32.0 in stage 2.0 (TID 99) in 59 ms on 10.1.2.152 (44/59)
17/01/29 05:37:26,547 INFO TaskSetManager: Finished task 55.0 in stage 2.0 (TID 106) in 26 ms on 10.1.2.60 (45/59)
17/01/29 05:37:26,553 INFO TaskSetManager: Starting task 41.0 in stage 2.0 (TID 109, 10.1.2.152, partition 41, PROCESS_LOCAL, 5372 bytes)
17/01/29 05:37:26,553 INFO CoarseGrainedSchedulerBackend$DriverEndpoint: Launching task 109 on executor id: 1 hostname: 10.1.2.152.
17/01/29 05:37:26,553 INFO TaskSetManager: Finished task 33.0 in stage 2.0 (TID 102) in 43 ms on 10.1.2.152 (46/59)
17/01/29 05:37:26,554 INFO TaskSetManager: Starting task 42.0 in stage 2.0 (TID 110, 10.1.2.152, partition 42, PROCESS_LOCAL, 5372 bytes)
17/01/29 05:37:26,554 INFO CoarseGrainedSchedulerBackend$DriverEndpoint: Launching task 110 on executor id: 1 hostname: 10.1.2.152.
17/01/29 05:37:26,555 INFO TaskSetManager: Finished task 34.0 in stage 2.0 (TID 104) in 39 ms on 10.1.2.152 (47/59)
17/01/29 05:37:26,576 INFO TaskSetManager: Starting task 43.0 in stage 2.0 (TID 111, 10.1.2.152, partition 43, PROCESS_LOCAL, 5372 bytes)
17/01/29 05:37:26,576 INFO CoarseGrainedSchedulerBackend$DriverEndpoint: Launching task 111 on executor id: 1 hostname: 10.1.2.152.
17/01/29 05:37:26,577 INFO TaskSetManager: Finished task 35.0 in stage 2.0 (TID 107) in 45 ms on 10.1.2.152 (48/59)
17/01/29 05:37:26,578 INFO TaskSetManager: Starting task 48.0 in stage 2.0 (TID 112, 10.1.2.152, partition 48, PROCESS_LOCAL, 5372 bytes)
17/01/29 05:37:26,579 INFO CoarseGrainedSchedulerBackend$DriverEndpoint: Launching task 112 on executor id: 1 hostname: 10.1.2.152.
17/01/29 05:37:26,579 INFO TaskSetManager: Finished task 40.0 in stage 2.0 (TID 108) in 35 ms on 10.1.2.152 (49/59)
17/01/29 05:37:26,586 INFO TaskSetManager: Starting task 49.0 in stage 2.0 (TID 113, 10.1.2.152, partition 49, PROCESS_LOCAL, 5372 bytes)
17/01/29 05:37:26,587 INFO CoarseGrainedSchedulerBackend$DriverEndpoint: Launching task 113 on executor id: 1 hostname: 10.1.2.152.
17/01/29 05:37:26,587 INFO TaskSetManager: Finished task 41.0 in stage 2.0 (TID 109) in 35 ms on 10.1.2.152 (50/59)
17/01/29 05:37:26,591 INFO TaskSetManager: Starting task 50.0 in stage 2.0 (TID 114, 10.1.2.152, partition 50, PROCESS_LOCAL, 5372 bytes)
17/01/29 05:37:26,592 INFO CoarseGrainedSchedulerBackend$DriverEndpoint: Launching task 114 on executor id: 1 hostname: 10.1.2.152.
17/01/29 05:37:26,592 INFO TaskSetManager: Finished task 42.0 in stage 2.0 (TID 110) in 38 ms on 10.1.2.152 (51/59)
17/01/29 05:37:26,615 INFO TaskSetManager: Starting task 51.0 in stage 2.0 (TID 115, 10.1.2.152, partition 51, PROCESS_LOCAL, 5372 bytes)
17/01/29 05:37:26,616 INFO CoarseGrainedSchedulerBackend$DriverEndpoint: Launching task 115 on executor id: 1 hostname: 10.1.2.152.
17/01/29 05:37:26,616 INFO TaskSetManager: Finished task 43.0 in stage 2.0 (TID 111) in 40 ms on 10.1.2.152 (52/59)
17/01/29 05:37:26,619 INFO TaskSetManager: Starting task 57.0 in stage 2.0 (TID 116, 10.1.2.152, partition 57, PROCESS_LOCAL, 5372 bytes)
17/01/29 05:37:26,619 INFO CoarseGrainedSchedulerBackend$DriverEndpoint: Launching task 116 on executor id: 1 hostname: 10.1.2.152.
17/01/29 05:37:26,619 INFO TaskSetManager: Finished task 48.0 in stage 2.0 (TID 112) in 41 ms on 10.1.2.152 (53/59)
17/01/29 05:37:26,627 INFO TaskSetManager: Starting task 58.0 in stage 2.0 (TID 117, 10.1.2.152, partition 58, PROCESS_LOCAL, 5372 bytes)
17/01/29 05:37:26,627 INFO CoarseGrainedSchedulerBackend$DriverEndpoint: Launching task 117 on executor id: 1 hostname: 10.1.2.152.
17/01/29 05:37:26,627 INFO TaskSetManager: Finished task 49.0 in stage 2.0 (TID 113) in 41 ms on 10.1.2.152 (54/59)
17/01/29 05:37:26,650 INFO TaskSetManager: Finished task 50.0 in stage 2.0 (TID 114) in 59 ms on 10.1.2.152 (55/59)
17/01/29 05:37:26,659 INFO TaskSetManager: Finished task 51.0 in stage 2.0 (TID 115) in 44 ms on 10.1.2.152 (56/59)
17/01/29 05:37:26,660 INFO TaskSetManager: Finished task 57.0 in stage 2.0 (TID 116) in 41 ms on 10.1.2.152 (57/59)
17/01/29 05:37:26,670 INFO TaskSetManager: Finished task 58.0 in stage 2.0 (TID 117) in 44 ms on 10.1.2.152 (58/59)
17/01/29 05:37:30,398 INFO TaskSetManager: Starting task 56.0 in stage 2.0 (TID 118, 10.1.2.60, partition 56, ANY, 5372 bytes)
17/01/29 05:37:30,399 INFO CoarseGrainedSchedulerBackend$DriverEndpoint: Launching task 118 on executor id: 0 hostname: 10.1.2.60.
17/01/29 05:37:36,086 INFO TaskSetManager: Finished task 56.0 in stage 2.0 (TID 118) in 5688 ms on 10.1.2.60 (59/59)
17/01/29 05:37:36,086 INFO TaskSchedulerImpl: Removed TaskSet 2.0, whose tasks have all completed, from pool 
17/01/29 05:37:36,087 INFO DAGScheduler: ResultStage 2 (count at GradientDescent.scala:209) finished in 9.813 s
17/01/29 05:37:36,087 INFO DAGScheduler: Job 2 finished: count at GradientDescent.scala:209, took 9.836492 s
17/01/29 05:37:36,321 WARN BLAS: Failed to load implementation from: com.github.fommil.netlib.NativeSystemBLAS
17/01/29 05:37:36,321 WARN BLAS: Failed to load implementation from: com.github.fommil.netlib.NativeRefBLAS
17/01/29 05:37:36,347 INFO MemoryStore: Block broadcast_4 stored as values in memory (estimated size 280.0 B, free 2.1 GB)
17/01/29 05:37:36,350 INFO MemoryStore: Block broadcast_4_piece0 stored as bytes in memory (estimated size 153.0 B, free 2.1 GB)
17/01/29 05:37:36,351 INFO BlockManagerInfo: Added broadcast_4_piece0 in memory on 10.1.2.31:36114 (size: 153.0 B, free: 2.1 GB)
17/01/29 05:37:36,352 INFO SparkContext: Created broadcast 4 from broadcast at GradientDescent.scala:235
17/01/29 05:37:36,406 INFO SparkContext: Starting job: treeAggregate at GradientDescent.scala:239
17/01/29 05:37:36,412 INFO DAGScheduler: Registering RDD 11 (treeAggregate at GradientDescent.scala:239)
17/01/29 05:37:36,413 INFO DAGScheduler: Got job 3 (treeAggregate at GradientDescent.scala:239) with 7 output partitions
17/01/29 05:37:36,414 INFO DAGScheduler: Final stage: ResultStage 4 (treeAggregate at GradientDescent.scala:239)
17/01/29 05:37:36,414 INFO DAGScheduler: Parents of final stage: List(ShuffleMapStage 3)
17/01/29 05:37:36,414 INFO DAGScheduler: Missing parents: List(ShuffleMapStage 3)
17/01/29 05:37:36,419 INFO DAGScheduler: Submitting ShuffleMapStage 3 (MapPartitionsRDD[11] at treeAggregate at GradientDescent.scala:239), which has no missing parents
17/01/29 05:37:36,438 INFO MemoryStore: Block broadcast_5 stored as values in memory (estimated size 7.2 KB, free 2.1 GB)
17/01/29 05:37:36,440 INFO MemoryStore: Block broadcast_5_piece0 stored as bytes in memory (estimated size 3.7 KB, free 2.1 GB)
17/01/29 05:37:36,440 INFO BlockManagerInfo: Added broadcast_5_piece0 in memory on 10.1.2.31:36114 (size: 3.7 KB, free: 2.1 GB)
17/01/29 05:37:36,441 INFO SparkContext: Created broadcast 5 from broadcast at DAGScheduler.scala:1012
17/01/29 05:37:36,443 INFO DAGScheduler: Submitting 59 missing tasks from ShuffleMapStage 3 (MapPartitionsRDD[11] at treeAggregate at GradientDescent.scala:239)
17/01/29 05:37:36,444 INFO TaskSchedulerImpl: Adding task set 3.0 with 59 tasks
17/01/29 05:37:36,448 INFO TaskSetManager: Starting task 0.0 in stage 3.0 (TID 119, 10.1.2.60, partition 0, PROCESS_LOCAL, 5561 bytes)
17/01/29 05:37:36,448 INFO TaskSetManager: Starting task 1.0 in stage 3.0 (TID 120, 10.1.2.152, partition 1, PROCESS_LOCAL, 5561 bytes)
17/01/29 05:37:36,449 INFO TaskSetManager: Starting task 2.0 in stage 3.0 (TID 121, 10.1.2.60, partition 2, PROCESS_LOCAL, 5561 bytes)
17/01/29 05:37:36,449 INFO TaskSetManager: Starting task 3.0 in stage 3.0 (TID 122, 10.1.2.152, partition 3, PROCESS_LOCAL, 5561 bytes)
17/01/29 05:37:36,450 INFO TaskSetManager: Starting task 4.0 in stage 3.0 (TID 123, 10.1.2.60, partition 4, PROCESS_LOCAL, 5561 bytes)
17/01/29 05:37:36,450 INFO TaskSetManager: Starting task 5.0 in stage 3.0 (TID 124, 10.1.2.152, partition 5, PROCESS_LOCAL, 5561 bytes)
17/01/29 05:37:36,451 INFO TaskSetManager: Starting task 6.0 in stage 3.0 (TID 125, 10.1.2.60, partition 6, PROCESS_LOCAL, 5561 bytes)
17/01/29 05:37:36,452 INFO TaskSetManager: Starting task 8.0 in stage 3.0 (TID 126, 10.1.2.152, partition 8, PROCESS_LOCAL, 5561 bytes)
17/01/29 05:37:36,452 INFO CoarseGrainedSchedulerBackend$DriverEndpoint: Launching task 119 on executor id: 0 hostname: 10.1.2.60.
17/01/29 05:37:36,453 INFO CoarseGrainedSchedulerBackend$DriverEndpoint: Launching task 121 on executor id: 0 hostname: 10.1.2.60.
17/01/29 05:37:36,453 INFO CoarseGrainedSchedulerBackend$DriverEndpoint: Launching task 123 on executor id: 0 hostname: 10.1.2.60.
17/01/29 05:37:36,454 INFO CoarseGrainedSchedulerBackend$DriverEndpoint: Launching task 125 on executor id: 0 hostname: 10.1.2.60.
17/01/29 05:37:36,454 INFO CoarseGrainedSchedulerBackend$DriverEndpoint: Launching task 120 on executor id: 1 hostname: 10.1.2.152.
17/01/29 05:37:36,455 INFO CoarseGrainedSchedulerBackend$DriverEndpoint: Launching task 122 on executor id: 1 hostname: 10.1.2.152.
17/01/29 05:37:36,456 INFO CoarseGrainedSchedulerBackend$DriverEndpoint: Launching task 124 on executor id: 1 hostname: 10.1.2.152.
17/01/29 05:37:36,456 INFO CoarseGrainedSchedulerBackend$DriverEndpoint: Launching task 126 on executor id: 1 hostname: 10.1.2.152.
17/01/29 05:37:36,472 INFO BlockManagerInfo: Added broadcast_5_piece0 in memory on 10.1.2.60:40890 (size: 3.7 KB, free: 92.4 MB)
17/01/29 05:37:36,536 INFO BlockManagerInfo: Added broadcast_5_piece0 in memory on 10.1.2.152:46814 (size: 3.7 KB, free: 89.7 MB)
17/01/29 05:37:36,789 INFO BlockManagerInfo: Added broadcast_4_piece0 in memory on 10.1.2.60:40890 (size: 153.0 B, free: 92.4 MB)
17/01/29 05:37:36,835 INFO BlockManagerInfo: Added broadcast_4_piece0 in memory on 10.1.2.152:46814 (size: 153.0 B, free: 89.7 MB)
17/01/29 05:37:36,955 INFO TaskSetManager: Starting task 7.0 in stage 3.0 (TID 127, 10.1.2.60, partition 7, PROCESS_LOCAL, 5561 bytes)
17/01/29 05:37:36,955 INFO CoarseGrainedSchedulerBackend$DriverEndpoint: Launching task 127 on executor id: 0 hostname: 10.1.2.60.
17/01/29 05:37:36,956 INFO TaskSetManager: Starting task 9.0 in stage 3.0 (TID 128, 10.1.2.60, partition 9, PROCESS_LOCAL, 5561 bytes)
17/01/29 05:37:36,957 INFO CoarseGrainedSchedulerBackend$DriverEndpoint: Launching task 128 on executor id: 0 hostname: 10.1.2.60.
17/01/29 05:37:36,957 INFO TaskSetManager: Finished task 0.0 in stage 3.0 (TID 119) in 511 ms on 10.1.2.60 (1/59)
17/01/29 05:37:36,957 INFO TaskSetManager: Finished task 6.0 in stage 3.0 (TID 125) in 506 ms on 10.1.2.60 (2/59)
17/01/29 05:37:36,958 INFO TaskSetManager: Finished task 4.0 in stage 3.0 (TID 123) in 509 ms on 10.1.2.60 (3/59)
17/01/29 05:37:36,959 INFO TaskSetManager: Starting task 10.0 in stage 3.0 (TID 129, 10.1.2.60, partition 10, PROCESS_LOCAL, 5561 bytes)
17/01/29 05:37:36,959 INFO CoarseGrainedSchedulerBackend$DriverEndpoint: Launching task 129 on executor id: 0 hostname: 10.1.2.60.
17/01/29 05:37:36,960 INFO TaskSetManager: Starting task 11.0 in stage 3.0 (TID 130, 10.1.2.60, partition 11, PROCESS_LOCAL, 5561 bytes)
17/01/29 05:37:36,960 INFO CoarseGrainedSchedulerBackend$DriverEndpoint: Launching task 130 on executor id: 0 hostname: 10.1.2.60.
17/01/29 05:37:36,961 INFO TaskSetManager: Finished task 2.0 in stage 3.0 (TID 121) in 512 ms on 10.1.2.60 (4/59)
17/01/29 05:37:37,031 INFO TaskSetManager: Starting task 12.0 in stage 3.0 (TID 131, 10.1.2.60, partition 12, PROCESS_LOCAL, 5561 bytes)
17/01/29 05:37:37,031 INFO CoarseGrainedSchedulerBackend$DriverEndpoint: Launching task 131 on executor id: 0 hostname: 10.1.2.60.
17/01/29 05:37:37,031 INFO TaskSetManager: Finished task 7.0 in stage 3.0 (TID 127) in 77 ms on 10.1.2.60 (5/59)
17/01/29 05:37:37,040 INFO TaskSetManager: Starting task 13.0 in stage 3.0 (TID 132, 10.1.2.152, partition 13, PROCESS_LOCAL, 5561 bytes)
17/01/29 05:37:37,040 INFO CoarseGrainedSchedulerBackend$DriverEndpoint: Launching task 132 on executor id: 1 hostname: 10.1.2.152.
17/01/29 05:37:37,040 INFO TaskSetManager: Finished task 1.0 in stage 3.0 (TID 120) in 592 ms on 10.1.2.152 (6/59)
17/01/29 05:37:37,043 INFO TaskSetManager: Starting task 14.0 in stage 3.0 (TID 133, 10.1.2.152, partition 14, PROCESS_LOCAL, 5561 bytes)
17/01/29 05:37:37,044 INFO CoarseGrainedSchedulerBackend$DriverEndpoint: Launching task 133 on executor id: 1 hostname: 10.1.2.152.
17/01/29 05:37:37,044 INFO TaskSetManager: Finished task 8.0 in stage 3.0 (TID 126) in 593 ms on 10.1.2.152 (7/59)
17/01/29 05:37:37,045 INFO TaskSetManager: Starting task 15.0 in stage 3.0 (TID 134, 10.1.2.152, partition 15, PROCESS_LOCAL, 5561 bytes)
17/01/29 05:37:37,046 INFO CoarseGrainedSchedulerBackend$DriverEndpoint: Launching task 134 on executor id: 1 hostname: 10.1.2.152.
17/01/29 05:37:37,046 INFO TaskSetManager: Finished task 3.0 in stage 3.0 (TID 122) in 597 ms on 10.1.2.152 (8/59)
17/01/29 05:37:37,047 INFO TaskSetManager: Starting task 16.0 in stage 3.0 (TID 135, 10.1.2.152, partition 16, PROCESS_LOCAL, 5561 bytes)
17/01/29 05:37:37,047 INFO CoarseGrainedSchedulerBackend$DriverEndpoint: Launching task 135 on executor id: 1 hostname: 10.1.2.152.
17/01/29 05:37:37,047 INFO TaskSetManager: Finished task 5.0 in stage 3.0 (TID 124) in 597 ms on 10.1.2.152 (9/59)
17/01/29 05:37:37,127 INFO TaskSetManager: Starting task 17.0 in stage 3.0 (TID 136, 10.1.2.152, partition 17, PROCESS_LOCAL, 5561 bytes)
17/01/29 05:37:37,128 INFO CoarseGrainedSchedulerBackend$DriverEndpoint: Launching task 136 on executor id: 1 hostname: 10.1.2.152.
17/01/29 05:37:37,128 INFO TaskSetManager: Finished task 16.0 in stage 3.0 (TID 135) in 82 ms on 10.1.2.152 (10/59)
17/01/29 05:37:37,132 INFO TaskSetManager: Starting task 18.0 in stage 3.0 (TID 137, 10.1.2.152, partition 18, PROCESS_LOCAL, 5561 bytes)
17/01/29 05:37:37,133 INFO CoarseGrainedSchedulerBackend$DriverEndpoint: Launching task 137 on executor id: 1 hostname: 10.1.2.152.
17/01/29 05:37:37,133 INFO TaskSetManager: Finished task 15.0 in stage 3.0 (TID 134) in 88 ms on 10.1.2.152 (11/59)
17/01/29 05:37:37,134 INFO TaskSetManager: Starting task 20.0 in stage 3.0 (TID 138, 10.1.2.60, partition 20, PROCESS_LOCAL, 5561 bytes)
17/01/29 05:37:37,134 INFO CoarseGrainedSchedulerBackend$DriverEndpoint: Launching task 138 on executor id: 0 hostname: 10.1.2.60.
17/01/29 05:37:37,135 INFO TaskSetManager: Finished task 11.0 in stage 3.0 (TID 130) in 175 ms on 10.1.2.60 (12/59)
17/01/29 05:37:37,148 INFO TaskSetManager: Starting task 21.0 in stage 3.0 (TID 139, 10.1.2.60, partition 21, PROCESS_LOCAL, 5561 bytes)
17/01/29 05:37:37,148 INFO CoarseGrainedSchedulerBackend$DriverEndpoint: Launching task 139 on executor id: 0 hostname: 10.1.2.60.
17/01/29 05:37:37,148 INFO TaskSetManager: Finished task 10.0 in stage 3.0 (TID 129) in 189 ms on 10.1.2.60 (13/59)
17/01/29 05:37:37,152 INFO TaskSetManager: Starting task 22.0 in stage 3.0 (TID 140, 10.1.2.60, partition 22, PROCESS_LOCAL, 5561 bytes)
17/01/29 05:37:37,152 INFO CoarseGrainedSchedulerBackend$DriverEndpoint: Launching task 140 on executor id: 0 hostname: 10.1.2.60.
17/01/29 05:37:37,152 INFO TaskSetManager: Finished task 9.0 in stage 3.0 (TID 128) in 197 ms on 10.1.2.60 (14/59)
17/01/29 05:37:37,163 INFO TaskSetManager: Starting task 19.0 in stage 3.0 (TID 141, 10.1.2.152, partition 19, PROCESS_LOCAL, 5561 bytes)
17/01/29 05:37:37,163 INFO CoarseGrainedSchedulerBackend$DriverEndpoint: Launching task 141 on executor id: 1 hostname: 10.1.2.152.
17/01/29 05:37:37,164 INFO TaskSetManager: Finished task 13.0 in stage 3.0 (TID 132) in 124 ms on 10.1.2.152 (15/59)
17/01/29 05:37:37,197 INFO TaskSetManager: Starting task 23.0 in stage 3.0 (TID 142, 10.1.2.60, partition 23, PROCESS_LOCAL, 5561 bytes)
17/01/29 05:37:37,197 INFO CoarseGrainedSchedulerBackend$DriverEndpoint: Launching task 142 on executor id: 0 hostname: 10.1.2.60.
17/01/29 05:37:37,198 INFO TaskSetManager: Finished task 20.0 in stage 3.0 (TID 138) in 65 ms on 10.1.2.60 (16/59)
17/01/29 05:37:37,200 INFO TaskSetManager: Starting task 28.0 in stage 3.0 (TID 143, 10.1.2.60, partition 28, PROCESS_LOCAL, 5561 bytes)
17/01/29 05:37:37,201 INFO CoarseGrainedSchedulerBackend$DriverEndpoint: Launching task 143 on executor id: 0 hostname: 10.1.2.60.
17/01/29 05:37:37,201 INFO TaskSetManager: Finished task 12.0 in stage 3.0 (TID 131) in 171 ms on 10.1.2.60 (17/59)
17/01/29 05:37:37,205 INFO TaskSetManager: Starting task 24.0 in stage 3.0 (TID 144, 10.1.2.152, partition 24, PROCESS_LOCAL, 5561 bytes)
17/01/29 05:37:37,205 INFO CoarseGrainedSchedulerBackend$DriverEndpoint: Launching task 144 on executor id: 1 hostname: 10.1.2.152.
17/01/29 05:37:37,206 INFO TaskSetManager: Finished task 14.0 in stage 3.0 (TID 133) in 163 ms on 10.1.2.152 (18/59)
17/01/29 05:37:37,210 INFO TaskSetManager: Starting task 29.0 in stage 3.0 (TID 145, 10.1.2.60, partition 29, PROCESS_LOCAL, 5561 bytes)
17/01/29 05:37:37,211 INFO CoarseGrainedSchedulerBackend$DriverEndpoint: Launching task 145 on executor id: 0 hostname: 10.1.2.60.
17/01/29 05:37:37,211 INFO TaskSetManager: Finished task 22.0 in stage 3.0 (TID 140) in 60 ms on 10.1.2.60 (19/59)
17/01/29 05:37:37,228 INFO TaskSetManager: Starting task 30.0 in stage 3.0 (TID 146, 10.1.2.60, partition 30, PROCESS_LOCAL, 5561 bytes)
17/01/29 05:37:37,228 INFO CoarseGrainedSchedulerBackend$DriverEndpoint: Launching task 146 on executor id: 0 hostname: 10.1.2.60.
17/01/29 05:37:37,228 INFO TaskSetManager: Finished task 21.0 in stage 3.0 (TID 139) in 81 ms on 10.1.2.60 (20/59)
17/01/29 05:37:37,257 INFO TaskSetManager: Starting task 25.0 in stage 3.0 (TID 147, 10.1.2.152, partition 25, PROCESS_LOCAL, 5561 bytes)
17/01/29 05:37:37,257 INFO CoarseGrainedSchedulerBackend$DriverEndpoint: Launching task 147 on executor id: 1 hostname: 10.1.2.152.
17/01/29 05:37:37,257 INFO TaskSetManager: Finished task 17.0 in stage 3.0 (TID 136) in 130 ms on 10.1.2.152 (21/59)
17/01/29 05:37:37,266 INFO TaskSetManager: Starting task 31.0 in stage 3.0 (TID 148, 10.1.2.60, partition 31, PROCESS_LOCAL, 5561 bytes)
17/01/29 05:37:37,266 INFO CoarseGrainedSchedulerBackend$DriverEndpoint: Launching task 148 on executor id: 0 hostname: 10.1.2.60.
17/01/29 05:37:37,267 INFO TaskSetManager: Finished task 23.0 in stage 3.0 (TID 142) in 69 ms on 10.1.2.60 (22/59)
17/01/29 05:37:37,282 INFO TaskSetManager: Starting task 36.0 in stage 3.0 (TID 149, 10.1.2.60, partition 36, PROCESS_LOCAL, 5561 bytes)
17/01/29 05:37:37,282 INFO CoarseGrainedSchedulerBackend$DriverEndpoint: Launching task 149 on executor id: 0 hostname: 10.1.2.60.
17/01/29 05:37:37,282 INFO TaskSetManager: Finished task 28.0 in stage 3.0 (TID 143) in 82 ms on 10.1.2.60 (23/59)
17/01/29 05:37:37,283 INFO TaskSetManager: Starting task 37.0 in stage 3.0 (TID 150, 10.1.2.60, partition 37, PROCESS_LOCAL, 5561 bytes)
17/01/29 05:37:37,283 INFO CoarseGrainedSchedulerBackend$DriverEndpoint: Launching task 150 on executor id: 0 hostname: 10.1.2.60.
17/01/29 05:37:37,284 INFO TaskSetManager: Finished task 29.0 in stage 3.0 (TID 145) in 74 ms on 10.1.2.60 (24/59)
17/01/29 05:37:37,296 INFO TaskSetManager: Starting task 38.0 in stage 3.0 (TID 151, 10.1.2.60, partition 38, PROCESS_LOCAL, 5561 bytes)
17/01/29 05:37:37,296 INFO CoarseGrainedSchedulerBackend$DriverEndpoint: Launching task 151 on executor id: 0 hostname: 10.1.2.60.
17/01/29 05:37:37,296 INFO TaskSetManager: Finished task 30.0 in stage 3.0 (TID 146) in 69 ms on 10.1.2.60 (25/59)
17/01/29 05:37:37,298 INFO TaskSetManager: Starting task 26.0 in stage 3.0 (TID 152, 10.1.2.152, partition 26, PROCESS_LOCAL, 5561 bytes)
17/01/29 05:37:37,299 INFO CoarseGrainedSchedulerBackend$DriverEndpoint: Launching task 152 on executor id: 1 hostname: 10.1.2.152.
17/01/29 05:37:37,299 INFO TaskSetManager: Finished task 24.0 in stage 3.0 (TID 144) in 94 ms on 10.1.2.152 (26/59)
17/01/29 05:37:37,301 INFO TaskSetManager: Starting task 27.0 in stage 3.0 (TID 153, 10.1.2.152, partition 27, PROCESS_LOCAL, 5561 bytes)
17/01/29 05:37:37,302 INFO CoarseGrainedSchedulerBackend$DriverEndpoint: Launching task 153 on executor id: 1 hostname: 10.1.2.152.
17/01/29 05:37:37,302 INFO TaskSetManager: Finished task 18.0 in stage 3.0 (TID 137) in 170 ms on 10.1.2.152 (27/59)
17/01/29 05:37:37,321 INFO TaskSetManager: Starting task 32.0 in stage 3.0 (TID 154, 10.1.2.152, partition 32, PROCESS_LOCAL, 5561 bytes)
17/01/29 05:37:37,322 INFO CoarseGrainedSchedulerBackend$DriverEndpoint: Launching task 154 on executor id: 1 hostname: 10.1.2.152.
17/01/29 05:37:37,322 INFO TaskSetManager: Finished task 19.0 in stage 3.0 (TID 141) in 159 ms on 10.1.2.152 (28/59)
17/01/29 05:37:37,331 INFO TaskSetManager: Starting task 33.0 in stage 3.0 (TID 155, 10.1.2.152, partition 33, PROCESS_LOCAL, 5561 bytes)
17/01/29 05:37:37,331 INFO CoarseGrainedSchedulerBackend$DriverEndpoint: Launching task 155 on executor id: 1 hostname: 10.1.2.152.
17/01/29 05:37:37,331 INFO TaskSetManager: Finished task 25.0 in stage 3.0 (TID 147) in 74 ms on 10.1.2.152 (29/59)
17/01/29 05:37:37,347 INFO TaskSetManager: Starting task 39.0 in stage 3.0 (TID 156, 10.1.2.60, partition 39, PROCESS_LOCAL, 5561 bytes)
17/01/29 05:37:37,348 INFO CoarseGrainedSchedulerBackend$DriverEndpoint: Launching task 156 on executor id: 0 hostname: 10.1.2.60.
17/01/29 05:37:37,348 INFO TaskSetManager: Finished task 36.0 in stage 3.0 (TID 149) in 67 ms on 10.1.2.60 (30/59)
17/01/29 05:37:37,351 INFO TaskSetManager: Starting task 44.0 in stage 3.0 (TID 157, 10.1.2.60, partition 44, PROCESS_LOCAL, 5561 bytes)
17/01/29 05:37:37,351 INFO CoarseGrainedSchedulerBackend$DriverEndpoint: Launching task 157 on executor id: 0 hostname: 10.1.2.60.
17/01/29 05:37:37,351 INFO TaskSetManager: Finished task 31.0 in stage 3.0 (TID 148) in 85 ms on 10.1.2.60 (31/59)
17/01/29 05:37:37,361 INFO TaskSetManager: Starting task 45.0 in stage 3.0 (TID 158, 10.1.2.60, partition 45, PROCESS_LOCAL, 5561 bytes)
17/01/29 05:37:37,361 INFO CoarseGrainedSchedulerBackend$DriverEndpoint: Launching task 158 on executor id: 0 hostname: 10.1.2.60.
17/01/29 05:37:37,362 INFO TaskSetManager: Finished task 37.0 in stage 3.0 (TID 150) in 79 ms on 10.1.2.60 (32/59)
17/01/29 05:37:37,363 INFO TaskSetManager: Starting task 46.0 in stage 3.0 (TID 159, 10.1.2.60, partition 46, PROCESS_LOCAL, 5561 bytes)
17/01/29 05:37:37,363 INFO CoarseGrainedSchedulerBackend$DriverEndpoint: Launching task 159 on executor id: 0 hostname: 10.1.2.60.
17/01/29 05:37:37,363 INFO TaskSetManager: Finished task 38.0 in stage 3.0 (TID 151) in 67 ms on 10.1.2.60 (33/59)
17/01/29 05:37:37,372 INFO TaskSetManager: Starting task 34.0 in stage 3.0 (TID 160, 10.1.2.152, partition 34, PROCESS_LOCAL, 5561 bytes)
17/01/29 05:37:37,372 INFO CoarseGrainedSchedulerBackend$DriverEndpoint: Launching task 160 on executor id: 1 hostname: 10.1.2.152.
17/01/29 05:37:37,373 INFO TaskSetManager: Finished task 26.0 in stage 3.0 (TID 152) in 74 ms on 10.1.2.152 (34/59)
17/01/29 05:37:37,382 INFO TaskSetManager: Starting task 35.0 in stage 3.0 (TID 161, 10.1.2.152, partition 35, PROCESS_LOCAL, 5561 bytes)
17/01/29 05:37:37,383 INFO CoarseGrainedSchedulerBackend$DriverEndpoint: Launching task 161 on executor id: 1 hostname: 10.1.2.152.
17/01/29 05:37:37,383 INFO TaskSetManager: Finished task 32.0 in stage 3.0 (TID 154) in 62 ms on 10.1.2.152 (35/59)
17/01/29 05:37:37,384 INFO TaskSetManager: Starting task 40.0 in stage 3.0 (TID 162, 10.1.2.152, partition 40, PROCESS_LOCAL, 5561 bytes)
17/01/29 05:37:37,384 INFO CoarseGrainedSchedulerBackend$DriverEndpoint: Launching task 162 on executor id: 1 hostname: 10.1.2.152.
17/01/29 05:37:37,385 INFO TaskSetManager: Finished task 27.0 in stage 3.0 (TID 153) in 83 ms on 10.1.2.152 (36/59)
17/01/29 05:37:37,414 INFO TaskSetManager: Starting task 47.0 in stage 3.0 (TID 163, 10.1.2.60, partition 47, PROCESS_LOCAL, 5561 bytes)
17/01/29 05:37:37,415 INFO CoarseGrainedSchedulerBackend$DriverEndpoint: Launching task 163 on executor id: 0 hostname: 10.1.2.60.
17/01/29 05:37:37,415 INFO TaskSetManager: Finished task 44.0 in stage 3.0 (TID 157) in 65 ms on 10.1.2.60 (37/59)
17/01/29 05:37:37,416 INFO TaskSetManager: Starting task 52.0 in stage 3.0 (TID 164, 10.1.2.60, partition 52, PROCESS_LOCAL, 5561 bytes)
17/01/29 05:37:37,417 INFO CoarseGrainedSchedulerBackend$DriverEndpoint: Launching task 164 on executor id: 0 hostname: 10.1.2.60.
17/01/29 05:37:37,417 INFO TaskSetManager: Finished task 39.0 in stage 3.0 (TID 156) in 70 ms on 10.1.2.60 (38/59)
17/01/29 05:37:37,423 INFO TaskSetManager: Starting task 53.0 in stage 3.0 (TID 165, 10.1.2.60, partition 53, PROCESS_LOCAL, 5561 bytes)
17/01/29 05:37:37,423 INFO CoarseGrainedSchedulerBackend$DriverEndpoint: Launching task 165 on executor id: 0 hostname: 10.1.2.60.
17/01/29 05:37:37,423 INFO TaskSetManager: Finished task 45.0 in stage 3.0 (TID 158) in 62 ms on 10.1.2.60 (39/59)
17/01/29 05:37:37,441 INFO TaskSetManager: Starting task 41.0 in stage 3.0 (TID 166, 10.1.2.152, partition 41, PROCESS_LOCAL, 5561 bytes)
17/01/29 05:37:37,441 INFO CoarseGrainedSchedulerBackend$DriverEndpoint: Launching task 166 on executor id: 1 hostname: 10.1.2.152.
17/01/29 05:37:37,441 INFO TaskSetManager: Finished task 34.0 in stage 3.0 (TID 160) in 69 ms on 10.1.2.152 (40/59)
17/01/29 05:37:37,444 INFO TaskSetManager: Starting task 42.0 in stage 3.0 (TID 167, 10.1.2.152, partition 42, PROCESS_LOCAL, 5561 bytes)
17/01/29 05:37:37,444 INFO CoarseGrainedSchedulerBackend$DriverEndpoint: Launching task 167 on executor id: 1 hostname: 10.1.2.152.
17/01/29 05:37:37,444 INFO TaskSetManager: Finished task 33.0 in stage 3.0 (TID 155) in 113 ms on 10.1.2.152 (41/59)
17/01/29 05:37:37,449 INFO TaskSetManager: Starting task 54.0 in stage 3.0 (TID 168, 10.1.2.60, partition 54, PROCESS_LOCAL, 5561 bytes)
17/01/29 05:37:37,450 INFO CoarseGrainedSchedulerBackend$DriverEndpoint: Launching task 168 on executor id: 0 hostname: 10.1.2.60.
17/01/29 05:37:37,450 INFO TaskSetManager: Finished task 46.0 in stage 3.0 (TID 159) in 88 ms on 10.1.2.60 (42/59)
17/01/29 05:37:37,458 INFO TaskSetManager: Starting task 43.0 in stage 3.0 (TID 169, 10.1.2.152, partition 43, PROCESS_LOCAL, 5561 bytes)
17/01/29 05:37:37,458 INFO CoarseGrainedSchedulerBackend$DriverEndpoint: Launching task 169 on executor id: 1 hostname: 10.1.2.152.
17/01/29 05:37:37,459 INFO TaskSetManager: Finished task 35.0 in stage 3.0 (TID 161) in 76 ms on 10.1.2.152 (43/59)
17/01/29 05:37:37,482 INFO TaskSetManager: Starting task 48.0 in stage 3.0 (TID 170, 10.1.2.152, partition 48, PROCESS_LOCAL, 5561 bytes)
17/01/29 05:37:37,482 INFO CoarseGrainedSchedulerBackend$DriverEndpoint: Launching task 170 on executor id: 1 hostname: 10.1.2.152.
17/01/29 05:37:37,482 INFO TaskSetManager: Finished task 40.0 in stage 3.0 (TID 162) in 98 ms on 10.1.2.152 (44/59)
17/01/29 05:37:37,488 INFO TaskSetManager: Starting task 55.0 in stage 3.0 (TID 171, 10.1.2.60, partition 55, PROCESS_LOCAL, 5561 bytes)
17/01/29 05:37:37,488 INFO CoarseGrainedSchedulerBackend$DriverEndpoint: Launching task 171 on executor id: 0 hostname: 10.1.2.60.
17/01/29 05:37:37,488 INFO TaskSetManager: Finished task 52.0 in stage 3.0 (TID 164) in 72 ms on 10.1.2.60 (45/59)
17/01/29 05:37:37,493 INFO TaskSetManager: Finished task 53.0 in stage 3.0 (TID 165) in 70 ms on 10.1.2.60 (46/59)
17/01/29 05:37:37,495 INFO TaskSetManager: Finished task 47.0 in stage 3.0 (TID 163) in 81 ms on 10.1.2.60 (47/59)
17/01/29 05:37:37,508 INFO TaskSetManager: Finished task 54.0 in stage 3.0 (TID 168) in 59 ms on 10.1.2.60 (48/59)
17/01/29 05:37:37,514 INFO TaskSetManager: Starting task 49.0 in stage 3.0 (TID 172, 10.1.2.152, partition 49, PROCESS_LOCAL, 5561 bytes)
17/01/29 05:37:37,514 INFO CoarseGrainedSchedulerBackend$DriverEndpoint: Launching task 172 on executor id: 1 hostname: 10.1.2.152.
17/01/29 05:37:37,515 INFO TaskSetManager: Finished task 42.0 in stage 3.0 (TID 167) in 70 ms on 10.1.2.152 (49/59)
17/01/29 05:37:37,517 INFO TaskSetManager: Starting task 50.0 in stage 3.0 (TID 173, 10.1.2.152, partition 50, PROCESS_LOCAL, 5561 bytes)
17/01/29 05:37:37,518 INFO CoarseGrainedSchedulerBackend$DriverEndpoint: Launching task 173 on executor id: 1 hostname: 10.1.2.152.
17/01/29 05:37:37,518 INFO TaskSetManager: Finished task 41.0 in stage 3.0 (TID 166) in 77 ms on 10.1.2.152 (50/59)
17/01/29 05:37:37,546 INFO TaskSetManager: Finished task 55.0 in stage 3.0 (TID 171) in 59 ms on 10.1.2.60 (51/59)
17/01/29 05:37:37,554 INFO TaskSetManager: Starting task 51.0 in stage 3.0 (TID 174, 10.1.2.152, partition 51, PROCESS_LOCAL, 5561 bytes)
17/01/29 05:37:37,555 INFO CoarseGrainedSchedulerBackend$DriverEndpoint: Launching task 174 on executor id: 1 hostname: 10.1.2.152.
17/01/29 05:37:37,555 INFO TaskSetManager: Finished task 48.0 in stage 3.0 (TID 170) in 74 ms on 10.1.2.152 (52/59)
17/01/29 05:37:37,568 INFO TaskSetManager: Starting task 57.0 in stage 3.0 (TID 175, 10.1.2.152, partition 57, PROCESS_LOCAL, 5561 bytes)
17/01/29 05:37:37,568 INFO CoarseGrainedSchedulerBackend$DriverEndpoint: Launching task 175 on executor id: 1 hostname: 10.1.2.152.
17/01/29 05:37:37,568 INFO TaskSetManager: Finished task 43.0 in stage 3.0 (TID 169) in 110 ms on 10.1.2.152 (53/59)
17/01/29 05:37:37,585 INFO TaskSetManager: Starting task 58.0 in stage 3.0 (TID 176, 10.1.2.152, partition 58, PROCESS_LOCAL, 5561 bytes)
17/01/29 05:37:37,585 INFO CoarseGrainedSchedulerBackend$DriverEndpoint: Launching task 176 on executor id: 1 hostname: 10.1.2.152.
17/01/29 05:37:37,585 INFO TaskSetManager: Finished task 49.0 in stage 3.0 (TID 172) in 72 ms on 10.1.2.152 (54/59)
17/01/29 05:37:37,608 INFO TaskSetManager: Finished task 50.0 in stage 3.0 (TID 173) in 91 ms on 10.1.2.152 (55/59)
17/01/29 05:37:37,620 INFO TaskSetManager: Finished task 51.0 in stage 3.0 (TID 174) in 66 ms on 10.1.2.152 (56/59)
17/01/29 05:37:37,639 INFO TaskSetManager: Finished task 57.0 in stage 3.0 (TID 175) in 72 ms on 10.1.2.152 (57/59)
17/01/29 05:37:37,646 INFO TaskSetManager: Finished task 58.0 in stage 3.0 (TID 176) in 62 ms on 10.1.2.152 (58/59)
17/01/29 05:37:41,398 INFO TaskSetManager: Starting task 56.0 in stage 3.0 (TID 177, 10.1.2.152, partition 56, ANY, 5561 bytes)
17/01/29 05:37:41,399 INFO CoarseGrainedSchedulerBackend$DriverEndpoint: Launching task 177 on executor id: 1 hostname: 10.1.2.152.
17/01/29 05:37:47,133 INFO TaskSetManager: Finished task 56.0 in stage 3.0 (TID 177) in 5735 ms on 10.1.2.152 (59/59)
17/01/29 05:37:47,134 INFO TaskSchedulerImpl: Removed TaskSet 3.0, whose tasks have all completed, from pool 
17/01/29 05:37:47,135 INFO DAGScheduler: ShuffleMapStage 3 (treeAggregate at GradientDescent.scala:239) finished in 10.690 s
17/01/29 05:37:47,136 INFO DAGScheduler: looking for newly runnable stages
17/01/29 05:37:47,136 INFO DAGScheduler: running: Set()
17/01/29 05:37:47,137 INFO DAGScheduler: waiting: Set(ResultStage 4)
17/01/29 05:37:47,138 INFO DAGScheduler: failed: Set()
17/01/29 05:37:47,141 INFO DAGScheduler: Submitting ResultStage 4 (MapPartitionsRDD[13] at treeAggregate at GradientDescent.scala:239), which has no missing parents
17/01/29 05:37:47,147 INFO MemoryStore: Block broadcast_6 stored as values in memory (estimated size 3.1 KB, free 2.1 GB)
17/01/29 05:37:47,149 INFO MemoryStore: Block broadcast_6_piece0 stored as bytes in memory (estimated size 1893.0 B, free 2.1 GB)
17/01/29 05:37:47,149 INFO BlockManagerInfo: Added broadcast_6_piece0 in memory on 10.1.2.31:36114 (size: 1893.0 B, free: 2.1 GB)
17/01/29 05:37:47,150 INFO SparkContext: Created broadcast 6 from broadcast at DAGScheduler.scala:1012
17/01/29 05:37:47,151 INFO DAGScheduler: Submitting 7 missing tasks from ResultStage 4 (MapPartitionsRDD[13] at treeAggregate at GradientDescent.scala:239)
17/01/29 05:37:47,151 INFO TaskSchedulerImpl: Adding task set 4.0 with 7 tasks
17/01/29 05:37:47,153 INFO TaskSetManager: Starting task 0.0 in stage 4.0 (TID 178, 10.1.2.152, partition 0, NODE_LOCAL, 5227 bytes)
17/01/29 05:37:47,154 INFO TaskSetManager: Starting task 1.0 in stage 4.0 (TID 179, 10.1.2.60, partition 1, NODE_LOCAL, 5227 bytes)
17/01/29 05:37:47,154 INFO TaskSetManager: Starting task 2.0 in stage 4.0 (TID 180, 10.1.2.152, partition 2, NODE_LOCAL, 5227 bytes)
17/01/29 05:37:47,155 INFO TaskSetManager: Starting task 3.0 in stage 4.0 (TID 181, 10.1.2.60, partition 3, NODE_LOCAL, 5227 bytes)
17/01/29 05:37:47,155 INFO TaskSetManager: Starting task 4.0 in stage 4.0 (TID 182, 10.1.2.152, partition 4, NODE_LOCAL, 5227 bytes)
17/01/29 05:37:47,155 INFO TaskSetManager: Starting task 5.0 in stage 4.0 (TID 183, 10.1.2.60, partition 5, NODE_LOCAL, 5227 bytes)
17/01/29 05:37:47,156 INFO TaskSetManager: Starting task 6.0 in stage 4.0 (TID 184, 10.1.2.152, partition 6, NODE_LOCAL, 5227 bytes)
17/01/29 05:37:47,156 INFO CoarseGrainedSchedulerBackend$DriverEndpoint: Launching task 178 on executor id: 1 hostname: 10.1.2.152.
17/01/29 05:37:47,157 INFO CoarseGrainedSchedulerBackend$DriverEndpoint: Launching task 180 on executor id: 1 hostname: 10.1.2.152.
17/01/29 05:37:47,157 INFO CoarseGrainedSchedulerBackend$DriverEndpoint: Launching task 182 on executor id: 1 hostname: 10.1.2.152.
17/01/29 05:37:47,157 INFO CoarseGrainedSchedulerBackend$DriverEndpoint: Launching task 184 on executor id: 1 hostname: 10.1.2.152.
17/01/29 05:37:47,158 INFO CoarseGrainedSchedulerBackend$DriverEndpoint: Launching task 179 on executor id: 0 hostname: 10.1.2.60.
17/01/29 05:37:47,159 INFO CoarseGrainedSchedulerBackend$DriverEndpoint: Launching task 181 on executor id: 0 hostname: 10.1.2.60.
17/01/29 05:37:47,159 INFO CoarseGrainedSchedulerBackend$DriverEndpoint: Launching task 183 on executor id: 0 hostname: 10.1.2.60.
17/01/29 05:37:47,171 INFO BlockManagerInfo: Added broadcast_6_piece0 in memory on 10.1.2.152:46814 (size: 1893.0 B, free: 89.7 MB)
17/01/29 05:37:47,172 INFO BlockManagerInfo: Added broadcast_6_piece0 in memory on 10.1.2.60:40890 (size: 1893.0 B, free: 92.4 MB)
17/01/29 05:37:47,189 INFO MapOutputTrackerMasterEndpoint: Asked to send map output locations for shuffle 0 to 10.1.2.60:57766
17/01/29 05:37:47,191 INFO MapOutputTrackerMasterEndpoint: Asked to send map output locations for shuffle 0 to 10.1.2.152:48848
17/01/29 05:37:47,194 INFO MapOutputTrackerMaster: Size of output statuses for shuffle 0 is 275 bytes
17/01/29 05:37:47,265 INFO TaskSetManager: Finished task 6.0 in stage 4.0 (TID 184) in 108 ms on 10.1.2.152 (1/7)
17/01/29 05:37:47,266 INFO TaskSetManager: Finished task 4.0 in stage 4.0 (TID 182) in 111 ms on 10.1.2.152 (2/7)
17/01/29 05:37:47,267 INFO TaskSetManager: Finished task 0.0 in stage 4.0 (TID 178) in 116 ms on 10.1.2.152 (3/7)
17/01/29 05:37:47,268 INFO TaskSetManager: Finished task 2.0 in stage 4.0 (TID 180) in 114 ms on 10.1.2.152 (4/7)
17/01/29 05:37:47,289 INFO TaskSetManager: Finished task 5.0 in stage 4.0 (TID 183) in 134 ms on 10.1.2.60 (5/7)
17/01/29 05:37:47,298 INFO TaskSetManager: Finished task 3.0 in stage 4.0 (TID 181) in 143 ms on 10.1.2.60 (6/7)
17/01/29 05:37:47,300 INFO TaskSetManager: Finished task 1.0 in stage 4.0 (TID 179) in 147 ms on 10.1.2.60 (7/7)
17/01/29 05:37:47,300 INFO TaskSchedulerImpl: Removed TaskSet 4.0, whose tasks have all completed, from pool 
17/01/29 05:37:47,300 INFO DAGScheduler: ResultStage 4 (treeAggregate at GradientDescent.scala:239) finished in 0.148 s
17/01/29 05:37:47,301 INFO DAGScheduler: Job 3 finished: treeAggregate at GradientDescent.scala:239, took 10.895230 s
17/01/29 05:37:47,304 INFO MemoryStore: Block broadcast_7 stored as values in memory (estimated size 280.0 B, free 2.1 GB)
17/01/29 05:37:47,308 INFO MemoryStore: Block broadcast_7_piece0 stored as bytes in memory (estimated size 365.0 B, free 2.1 GB)
17/01/29 05:37:47,309 INFO BlockManagerInfo: Added broadcast_7_piece0 in memory on 10.1.2.31:36114 (size: 365.0 B, free: 2.1 GB)
17/01/29 05:37:47,310 INFO SparkContext: Created broadcast 7 from broadcast at GradientDescent.scala:235
17/01/29 05:37:47,330 INFO SparkContext: Starting job: treeAggregate at GradientDescent.scala:239
17/01/29 05:37:47,331 INFO DAGScheduler: Registering RDD 16 (treeAggregate at GradientDescent.scala:239)
17/01/29 05:37:47,332 INFO DAGScheduler: Got job 4 (treeAggregate at GradientDescent.scala:239) with 7 output partitions
17/01/29 05:37:47,332 INFO DAGScheduler: Final stage: ResultStage 6 (treeAggregate at GradientDescent.scala:239)
17/01/29 05:37:47,332 INFO DAGScheduler: Parents of final stage: List(ShuffleMapStage 5)
17/01/29 05:37:47,332 INFO DAGScheduler: Missing parents: List(ShuffleMapStage 5)
17/01/29 05:37:47,336 INFO DAGScheduler: Submitting ShuffleMapStage 5 (MapPartitionsRDD[16] at treeAggregate at GradientDescent.scala:239), which has no missing parents
17/01/29 05:37:47,346 INFO MemoryStore: Block broadcast_8 stored as values in memory (estimated size 7.2 KB, free 2.1 GB)
17/01/29 05:37:47,350 INFO MemoryStore: Block broadcast_8_piece0 stored as bytes in memory (estimated size 3.7 KB, free 2.1 GB)
17/01/29 05:37:47,351 INFO BlockManagerInfo: Added broadcast_8_piece0 in memory on 10.1.2.31:36114 (size: 3.7 KB, free: 2.1 GB)
17/01/29 05:37:47,352 INFO SparkContext: Created broadcast 8 from broadcast at DAGScheduler.scala:1012
17/01/29 05:37:47,353 INFO DAGScheduler: Submitting 59 missing tasks from ShuffleMapStage 5 (MapPartitionsRDD[16] at treeAggregate at GradientDescent.scala:239)
17/01/29 05:37:47,354 INFO TaskSchedulerImpl: Adding task set 5.0 with 59 tasks
17/01/29 05:37:47,356 INFO TaskSetManager: Starting task 1.0 in stage 5.0 (TID 185, 10.1.2.152, partition 1, PROCESS_LOCAL, 5561 bytes)
17/01/29 05:37:47,357 INFO TaskSetManager: Starting task 0.0 in stage 5.0 (TID 186, 10.1.2.60, partition 0, PROCESS_LOCAL, 5561 bytes)
17/01/29 05:37:47,358 INFO TaskSetManager: Starting task 3.0 in stage 5.0 (TID 187, 10.1.2.152, partition 3, PROCESS_LOCAL, 5561 bytes)
17/01/29 05:37:47,358 INFO TaskSetManager: Starting task 2.0 in stage 5.0 (TID 188, 10.1.2.60, partition 2, PROCESS_LOCAL, 5561 bytes)
17/01/29 05:37:47,359 INFO TaskSetManager: Starting task 5.0 in stage 5.0 (TID 189, 10.1.2.152, partition 5, PROCESS_LOCAL, 5561 bytes)
17/01/29 05:37:47,360 INFO TaskSetManager: Starting task 4.0 in stage 5.0 (TID 190, 10.1.2.60, partition 4, PROCESS_LOCAL, 5561 bytes)
17/01/29 05:37:47,361 INFO TaskSetManager: Starting task 8.0 in stage 5.0 (TID 191, 10.1.2.152, partition 8, PROCESS_LOCAL, 5561 bytes)
