Using properties file: /home/ubuntu/spark-2.0.0/conf/spark-defaults.conf
Adding default property: spark.driver.extraJavaOptions=-XX:+PrintGCDetails -XX:+PrintGCTimeStamps -Xms4000m -Dlog4j.configuration=file:///home/ubuntu/spark-2.0.0/conf/log4j.properties
Adding default property: spark.executor.extraJavaOptions=-XX:+PrintGCDetails -XX:+PrintGCTimeStamps -Xms4000m -Dlog4j.configuration=file:///home/ubuntu/spark-2.0.0/conf/log4j.properties
Parsed arguments:
  master                  spark://euca-10-1-2-31:7077
  deployMode              client
  executorMemory          4000m
  executorCores           null
  totalExecutorCores      null
  propertiesFile          /home/ubuntu/spark-2.0.0/conf/spark-defaults.conf
  driverMemory            4000m
  driverCores             null
  driverExtraClassPath    null
  driverExtraLibraryPath  null
  driverExtraJavaOptions  -XX:+PrintGCDetails -XX:+PrintGCTimeStamps -Xms4000m -Dlog4j.configuration=file:///home/ubuntu/spark-2.0.0/conf/log4j.properties
  supervise               false
  queue                   null
  numExecutors            2
  files                   null
  pyFiles                 null
  archives                null
  mainClass               LogRegExplicitParallelism
  primaryResource         file:///home/ubuntu/jars/log-reg-explicit-parallelism_2.11-1.0.jar
  name                    LogRegExplicitParallelism
  childArgs               [cluster 28 euca-10-1-2-31 9000 higgs_0_exp 5 8]
  jars                    null
  packages                null
  packagesExclusions      null
  repositories            null
  verbose                 true

Spark properties used, including those specified through
 --conf and those from the properties file /home/ubuntu/spark-2.0.0/conf/spark-defaults.conf:
  spark.default.parallelism -> 8
  spark.driver.memory -> 4000m
  spark.executor.extraJavaOptions -> -XX:+PrintGCDetails -XX:+PrintGCTimeStamps -Xms4000m -Dlog4j.configuration=file:///home/ubuntu/spark-2.0.0/conf/log4j.properties
  spark.driver.extraJavaOptions -> -XX:+PrintGCDetails -XX:+PrintGCTimeStamps -Xms4000m -Dlog4j.configuration=file:///home/ubuntu/spark-2.0.0/conf/log4j.properties
  spark.shuffle.spill -> false

    
Main class:
LogRegExplicitParallelism
Arguments:
cluster
28
euca-10-1-2-31
9000
higgs_0_exp
5
8
System properties:
spark.default.parallelism -> 8
spark.executor.memory -> 4000m
spark.driver.memory -> 4000m
SPARK_SUBMIT -> true
spark.executor.extraJavaOptions -> -XX:+PrintGCDetails -XX:+PrintGCTimeStamps -Xms4000m -Dlog4j.configuration=file:///home/ubuntu/spark-2.0.0/conf/log4j.properties
spark.app.name -> LogRegExplicitParallelism
spark.shuffle.spill -> false
spark.driver.extraJavaOptions -> -XX:+PrintGCDetails -XX:+PrintGCTimeStamps -Xms4000m -Dlog4j.configuration=file:///home/ubuntu/spark-2.0.0/conf/log4j.properties
spark.jars -> file:///home/ubuntu/jars/log-reg-explicit-parallelism_2.11-1.0.jar
spark.submit.deployMode -> client
spark.master -> spark://euca-10-1-2-31:7077
Classpath elements:
file:///home/ubuntu/jars/log-reg-explicit-parallelism_2.11-1.0.jar


17/01/29 04:45:50,086 INFO SparkContext: Running Spark version 2.0.0
17/01/29 04:45:50,415 WARN NativeCodeLoader: Unable to load native-hadoop library for your platform... using builtin-java classes where applicable
17/01/29 04:45:50,569 INFO SecurityManager: Changing view acls to: ubuntu
17/01/29 04:45:50,570 INFO SecurityManager: Changing modify acls to: ubuntu
17/01/29 04:45:50,571 INFO SecurityManager: Changing view acls groups to: 
17/01/29 04:45:50,571 INFO SecurityManager: Changing modify acls groups to: 
17/01/29 04:45:50,572 INFO SecurityManager: SecurityManager: authentication disabled; ui acls disabled; users  with view permissions: Set(ubuntu); groups with view permissions: Set(); users  with modify permissions: Set(ubuntu); groups with modify permissions: Set()
17/01/29 04:45:50,885 INFO Utils: Successfully started service 'sparkDriver' on port 41087.
17/01/29 04:45:50,904 INFO SparkEnv: Registering MapOutputTracker
17/01/29 04:45:50,909 WARN SortShuffleManager: spark.shuffle.spill was set to false, but this configuration is ignored as of Spark 1.6+. Shuffle will continue to spill to disk when necessary.
17/01/29 04:45:50,921 INFO SparkEnv: Registering BlockManagerMaster
17/01/29 04:45:50,933 INFO DiskBlockManager: Created local directory at /tmp/blockmgr-afeeeb57-616a-4a87-aee5-c38e539cd418
17/01/29 04:45:50,951 INFO MemoryStore: MemoryStore started with capacity 2.1 GB
17/01/29 04:45:51,003 INFO SparkEnv: Registering OutputCommitCoordinator
17/01/29 04:45:51,198 INFO Utils: Successfully started service 'SparkUI' on port 4040.
17/01/29 04:45:51,200 INFO SparkUI: Bound SparkUI to 10.1.2.31, and started at http://10.1.2.31:4040
17/01/29 04:45:51,231 INFO SparkContext: Added JAR file:///home/ubuntu/jars/log-reg-explicit-parallelism_2.11-1.0.jar at spark://10.1.2.31:41087/jars/log-reg-explicit-parallelism_2.11-1.0.jar with timestamp 1485665151231
17/01/29 04:45:51,308 INFO StandaloneAppClient$ClientEndpoint: Connecting to master spark://euca-10-1-2-31:7077...
17/01/29 04:45:51,359 INFO TransportClientFactory: Successfully created connection to euca-10-1-2-31/10.1.2.31:7077 after 25 ms (0 ms spent in bootstraps)
17/01/29 04:45:51,512 INFO StandaloneSchedulerBackend: Connected to Spark cluster with app ID app-20170129044551-0000
17/01/29 04:45:51,518 INFO Utils: Successfully started service 'org.apache.spark.network.netty.NettyBlockTransferService' on port 38380.
17/01/29 04:45:51,519 INFO NettyBlockTransferService: Server created on 10.1.2.31:38380
17/01/29 04:45:51,521 INFO BlockManagerMaster: Registering BlockManager BlockManagerId(driver, 10.1.2.31, 38380)
17/01/29 04:45:51,523 INFO BlockManagerMasterEndpoint: Registering block manager 10.1.2.31:38380 with 2.1 GB RAM, BlockManagerId(driver, 10.1.2.31, 38380)
17/01/29 04:45:51,526 INFO BlockManagerMaster: Registered BlockManager BlockManagerId(driver, 10.1.2.31, 38380)
17/01/29 04:45:51,533 INFO StandaloneAppClient$ClientEndpoint: Executor added: app-20170129044551-0000/0 on worker-20170129044535-10.1.2.60-35988 (10.1.2.60:35988) with 4 cores
17/01/29 04:45:51,534 INFO StandaloneSchedulerBackend: Granted executor ID app-20170129044551-0000/0 on hostPort 10.1.2.60:35988 with 4 cores, 3.9 GB RAM
17/01/29 04:45:51,535 INFO StandaloneAppClient$ClientEndpoint: Executor added: app-20170129044551-0000/1 on worker-20170129044535-10.1.2.152-39079 (10.1.2.152:39079) with 4 cores
17/01/29 04:45:51,535 INFO StandaloneSchedulerBackend: Granted executor ID app-20170129044551-0000/1 on hostPort 10.1.2.152:39079 with 4 cores, 3.9 GB RAM
17/01/29 04:45:51,606 INFO StandaloneAppClient$ClientEndpoint: Executor updated: app-20170129044551-0000/1 is now RUNNING
17/01/29 04:45:51,607 INFO StandaloneAppClient$ClientEndpoint: Executor updated: app-20170129044551-0000/0 is now RUNNING
17/01/29 04:45:51,720 INFO StandaloneSchedulerBackend: SchedulerBackend is ready for scheduling beginning after reached minRegisteredResourcesRatio: 0.0
17/01/29 04:45:52,119 INFO MemoryStore: Block broadcast_0 stored as values in memory (estimated size 130.8 KB, free 2.1 GB)
17/01/29 04:45:52,208 INFO MemoryStore: Block broadcast_0_piece0 stored as bytes in memory (estimated size 16.5 KB, free 2.1 GB)
17/01/29 04:45:52,211 INFO BlockManagerInfo: Added broadcast_0_piece0 in memory on 10.1.2.31:38380 (size: 16.5 KB, free: 2.1 GB)
17/01/29 04:45:52,219 INFO SparkContext: Created broadcast 0 from textFile at MLUtils.scala:99
17/01/29 04:45:52,852 INFO FileInputFormat: Total input paths to process : 1
17/01/29 04:45:52,892 INFO NetworkTopology: Adding a new node: /default-rack/10.1.2.152:50010
17/01/29 04:45:52,893 INFO NetworkTopology: Adding a new node: /default-rack/10.1.2.60:50010
17/01/29 04:45:52,933 INFO SparkContext: Starting job: first at GeneralizedLinearAlgorithm.scala:246
17/01/29 04:45:52,944 INFO DAGScheduler: Got job 0 (first at GeneralizedLinearAlgorithm.scala:246) with 1 output partitions
17/01/29 04:45:52,945 INFO DAGScheduler: Final stage: ResultStage 0 (first at GeneralizedLinearAlgorithm.scala:246)
17/01/29 04:45:52,946 INFO DAGScheduler: Parents of final stage: List()
17/01/29 04:45:52,952 INFO DAGScheduler: Missing parents: List()
17/01/29 04:45:52,959 INFO DAGScheduler: Submitting ResultStage 0 (MapPartitionsRDD[6] at map at GeneralizedLinearAlgorithm.scala:246), which has no missing parents
17/01/29 04:45:52,979 INFO MemoryStore: Block broadcast_1 stored as values in memory (estimated size 4.2 KB, free 2.1 GB)
17/01/29 04:45:52,984 INFO MemoryStore: Block broadcast_1_piece0 stored as bytes in memory (estimated size 2.4 KB, free 2.1 GB)
17/01/29 04:45:52,984 INFO BlockManagerInfo: Added broadcast_1_piece0 in memory on 10.1.2.31:38380 (size: 2.4 KB, free: 2.1 GB)
17/01/29 04:45:52,985 INFO SparkContext: Created broadcast 1 from broadcast at DAGScheduler.scala:1012
17/01/29 04:45:52,988 INFO DAGScheduler: Submitting 1 missing tasks from ResultStage 0 (MapPartitionsRDD[6] at map at GeneralizedLinearAlgorithm.scala:246)
17/01/29 04:45:52,989 INFO TaskSchedulerImpl: Adding task set 0.0 with 1 tasks
17/01/29 04:45:53,426 INFO CoarseGrainedSchedulerBackend$DriverEndpoint: Registered executor NettyRpcEndpointRef(null) (10.1.2.152:35420) with ID 1
17/01/29 04:45:53,454 INFO TaskSetManager: Starting task 0.0 in stage 0.0 (TID 0, 10.1.2.152, partition 0, ANY, 5454 bytes)
17/01/29 04:45:53,458 INFO CoarseGrainedSchedulerBackend$DriverEndpoint: Launching task 0 on executor id: 1 hostname: 10.1.2.152.
17/01/29 04:45:53,473 INFO BlockManagerMasterEndpoint: Registering block manager 10.1.2.152:33704 with 2.1 GB RAM, BlockManagerId(1, 10.1.2.152, 33704)
17/01/29 04:45:53,767 INFO BlockManagerInfo: Added broadcast_1_piece0 in memory on 10.1.2.152:33704 (size: 2.4 KB, free: 2.1 GB)
17/01/29 04:45:53,916 INFO BlockManagerInfo: Added broadcast_0_piece0 in memory on 10.1.2.152:33704 (size: 16.5 KB, free: 2.1 GB)
17/01/29 04:45:56,340 INFO CoarseGrainedSchedulerBackend$DriverEndpoint: Registered executor NettyRpcEndpointRef(null) (10.1.2.60:54172) with ID 0
17/01/29 04:45:56,390 INFO BlockManagerMasterEndpoint: Registering block manager 10.1.2.60:37320 with 2.1 GB RAM, BlockManagerId(0, 10.1.2.60, 37320)
17/01/29 04:46:01,146 INFO BlockManagerInfo: Added rdd_5_0 in memory on 10.1.2.152:33704 (size: 70.0 MB, free: 2.0 GB)
17/01/29 04:46:01,203 INFO TaskSetManager: Finished task 0.0 in stage 0.0 (TID 0) in 7770 ms on 10.1.2.152 (1/1)
17/01/29 04:46:01,204 INFO TaskSchedulerImpl: Removed TaskSet 0.0, whose tasks have all completed, from pool 
17/01/29 04:46:01,208 INFO DAGScheduler: ResultStage 0 (first at GeneralizedLinearAlgorithm.scala:246) finished in 8.209 s
17/01/29 04:46:01,213 INFO DAGScheduler: Job 0 finished: first at GeneralizedLinearAlgorithm.scala:246, took 8.280362 s
17/01/29 04:46:01,225 INFO SparkContext: Starting job: count at DataValidators.scala:40
17/01/29 04:46:01,227 INFO DAGScheduler: Got job 1 (count at DataValidators.scala:40) with 59 output partitions
17/01/29 04:46:01,227 INFO DAGScheduler: Final stage: ResultStage 1 (count at DataValidators.scala:40)
17/01/29 04:46:01,227 INFO DAGScheduler: Parents of final stage: List()
17/01/29 04:46:01,230 INFO DAGScheduler: Missing parents: List()
17/01/29 04:46:01,231 INFO DAGScheduler: Submitting ResultStage 1 (MapPartitionsRDD[7] at filter at DataValidators.scala:40), which has no missing parents
17/01/29 04:46:01,253 INFO MemoryStore: Block broadcast_2 stored as values in memory (estimated size 3.9 KB, free 2.1 GB)
17/01/29 04:46:01,256 INFO MemoryStore: Block broadcast_2_piece0 stored as bytes in memory (estimated size 2.2 KB, free 2.1 GB)
17/01/29 04:46:01,257 INFO BlockManagerInfo: Added broadcast_2_piece0 in memory on 10.1.2.31:38380 (size: 2.2 KB, free: 2.1 GB)
17/01/29 04:46:01,258 INFO SparkContext: Created broadcast 2 from broadcast at DAGScheduler.scala:1012
17/01/29 04:46:01,260 INFO DAGScheduler: Submitting 59 missing tasks from ResultStage 1 (MapPartitionsRDD[7] at filter at DataValidators.scala:40)
17/01/29 04:46:01,261 INFO TaskSchedulerImpl: Adding task set 1.0 with 59 tasks
17/01/29 04:46:01,266 INFO TaskSetManager: Starting task 0.0 in stage 1.0 (TID 1, 10.1.2.152, partition 0, PROCESS_LOCAL, 5372 bytes)
17/01/29 04:46:01,268 INFO TaskSetManager: Starting task 58.0 in stage 1.0 (TID 2, 10.1.2.60, partition 58, NODE_LOCAL, 5372 bytes)
17/01/29 04:46:01,269 INFO CoarseGrainedSchedulerBackend$DriverEndpoint: Launching task 2 on executor id: 0 hostname: 10.1.2.60.
17/01/29 04:46:01,269 INFO CoarseGrainedSchedulerBackend$DriverEndpoint: Launching task 1 on executor id: 1 hostname: 10.1.2.152.
17/01/29 04:46:01,290 INFO BlockManagerInfo: Added broadcast_2_piece0 in memory on 10.1.2.152:33704 (size: 2.2 KB, free: 2.0 GB)
17/01/29 04:46:01,341 INFO TaskSetManager: Finished task 0.0 in stage 1.0 (TID 1) in 76 ms on 10.1.2.152 (1/59)
17/01/29 04:46:01,524 INFO BlockManagerInfo: Added broadcast_2_piece0 in memory on 10.1.2.60:37320 (size: 2.2 KB, free: 2.1 GB)
17/01/29 04:46:01,670 INFO BlockManagerInfo: Added broadcast_0_piece0 in memory on 10.1.2.60:37320 (size: 16.5 KB, free: 2.1 GB)
17/01/29 04:46:04,299 INFO TaskSetManager: Starting task 1.0 in stage 1.0 (TID 3, 10.1.2.152, partition 1, ANY, 5372 bytes)
17/01/29 04:46:04,301 INFO TaskSetManager: Starting task 2.0 in stage 1.0 (TID 4, 10.1.2.60, partition 2, ANY, 5372 bytes)
17/01/29 04:46:04,303 INFO TaskSetManager: Starting task 3.0 in stage 1.0 (TID 5, 10.1.2.152, partition 3, ANY, 5372 bytes)
17/01/29 04:46:04,306 INFO TaskSetManager: Starting task 4.0 in stage 1.0 (TID 6, 10.1.2.60, partition 4, ANY, 5372 bytes)
17/01/29 04:46:04,308 INFO TaskSetManager: Starting task 5.0 in stage 1.0 (TID 7, 10.1.2.152, partition 5, ANY, 5372 bytes)
17/01/29 04:46:04,311 INFO TaskSetManager: Starting task 6.0 in stage 1.0 (TID 8, 10.1.2.60, partition 6, ANY, 5372 bytes)
17/01/29 04:46:04,313 INFO TaskSetManager: Starting task 7.0 in stage 1.0 (TID 9, 10.1.2.152, partition 7, ANY, 5372 bytes)
17/01/29 04:46:04,313 INFO CoarseGrainedSchedulerBackend$DriverEndpoint: Launching task 3 on executor id: 1 hostname: 10.1.2.152.
17/01/29 04:46:04,314 INFO CoarseGrainedSchedulerBackend$DriverEndpoint: Launching task 5 on executor id: 1 hostname: 10.1.2.152.
17/01/29 04:46:04,314 INFO CoarseGrainedSchedulerBackend$DriverEndpoint: Launching task 7 on executor id: 1 hostname: 10.1.2.152.
17/01/29 04:46:04,315 INFO CoarseGrainedSchedulerBackend$DriverEndpoint: Launching task 9 on executor id: 1 hostname: 10.1.2.152.
17/01/29 04:46:04,316 INFO CoarseGrainedSchedulerBackend$DriverEndpoint: Launching task 4 on executor id: 0 hostname: 10.1.2.60.
17/01/29 04:46:04,317 INFO CoarseGrainedSchedulerBackend$DriverEndpoint: Launching task 6 on executor id: 0 hostname: 10.1.2.60.
17/01/29 04:46:04,318 INFO CoarseGrainedSchedulerBackend$DriverEndpoint: Launching task 8 on executor id: 0 hostname: 10.1.2.60.
17.591: [GC [PSYoungGen: 1024512K->157229K(1195008K)] 1024512K->157237K(3926016K), 0.1051970 secs] [Times: user=0.13 sys=0.09, real=0.11 secs] 
17/01/29 04:46:07,218 INFO BlockManagerInfo: Removed broadcast_1_piece0 on 10.1.2.152:33704 in memory (size: 2.4 KB, free: 2.0 GB)
17/01/29 04:46:07,219 INFO BlockManagerInfo: Removed broadcast_1_piece0 on 10.1.2.31:38380 in memory (size: 2.4 KB, free: 2.1 GB)
17/01/29 04:46:22,743 INFO BlockManagerInfo: Added rdd_5_58 in memory on 10.1.2.60:37320 (size: 72.8 MB, free: 2047.6 MB)
17/01/29 04:46:22,817 INFO TaskSetManager: Starting task 8.0 in stage 1.0 (TID 10, 10.1.2.60, partition 8, ANY, 5372 bytes)
17/01/29 04:46:22,818 INFO CoarseGrainedSchedulerBackend$DriverEndpoint: Launching task 10 on executor id: 0 hostname: 10.1.2.60.
17/01/29 04:46:22,820 INFO TaskSetManager: Finished task 58.0 in stage 1.0 (TID 2) in 21551 ms on 10.1.2.60 (2/59)
17/01/29 04:46:24,071 INFO BlockManagerInfo: Added rdd_5_6 in memory on 10.1.2.60:37320 (size: 69.9 MB, free: 1977.7 MB)
17/01/29 04:46:24,100 INFO TaskSetManager: Starting task 9.0 in stage 1.0 (TID 11, 10.1.2.60, partition 9, ANY, 5372 bytes)
17/01/29 04:46:24,100 INFO CoarseGrainedSchedulerBackend$DriverEndpoint: Launching task 11 on executor id: 0 hostname: 10.1.2.60.
17/01/29 04:46:24,103 INFO TaskSetManager: Finished task 6.0 in stage 1.0 (TID 8) in 19794 ms on 10.1.2.60 (3/59)
17/01/29 04:46:25,668 INFO BlockManagerInfo: Added rdd_5_4 in memory on 10.1.2.60:37320 (size: 70.0 MB, free: 1907.7 MB)
17/01/29 04:46:25,698 INFO TaskSetManager: Starting task 10.0 in stage 1.0 (TID 12, 10.1.2.60, partition 10, ANY, 5372 bytes)
17/01/29 04:46:25,698 INFO CoarseGrainedSchedulerBackend$DriverEndpoint: Launching task 12 on executor id: 0 hostname: 10.1.2.60.
17/01/29 04:46:25,699 INFO TaskSetManager: Finished task 4.0 in stage 1.0 (TID 6) in 21394 ms on 10.1.2.60 (4/59)
17/01/29 04:46:26,211 INFO BlockManagerInfo: Added rdd_5_2 in memory on 10.1.2.60:37320 (size: 69.9 MB, free: 1837.8 MB)
17/01/29 04:46:26,232 INFO TaskSetManager: Starting task 11.0 in stage 1.0 (TID 13, 10.1.2.60, partition 11, ANY, 5372 bytes)
17/01/29 04:46:26,232 INFO CoarseGrainedSchedulerBackend$DriverEndpoint: Launching task 13 on executor id: 0 hostname: 10.1.2.60.
17/01/29 04:46:26,232 INFO TaskSetManager: Finished task 2.0 in stage 1.0 (TID 4) in 21933 ms on 10.1.2.60 (5/59)
17/01/29 04:46:26,779 INFO BlockManagerInfo: Added rdd_5_3 in memory on 10.1.2.152:33704 (size: 69.9 MB, free: 1980.5 MB)
17/01/29 04:46:26,814 INFO TaskSetManager: Starting task 12.0 in stage 1.0 (TID 14, 10.1.2.152, partition 12, ANY, 5372 bytes)
17/01/29 04:46:26,814 INFO CoarseGrainedSchedulerBackend$DriverEndpoint: Launching task 14 on executor id: 1 hostname: 10.1.2.152.
17/01/29 04:46:26,816 INFO TaskSetManager: Finished task 3.0 in stage 1.0 (TID 5) in 22515 ms on 10.1.2.152 (6/59)
17/01/29 04:46:27,156 INFO BlockManagerInfo: Added rdd_5_5 in memory on 10.1.2.152:33704 (size: 70.0 MB, free: 1910.5 MB)
17/01/29 04:46:27,180 INFO TaskSetManager: Starting task 13.0 in stage 1.0 (TID 15, 10.1.2.152, partition 13, ANY, 5372 bytes)
17/01/29 04:46:27,180 INFO CoarseGrainedSchedulerBackend$DriverEndpoint: Launching task 15 on executor id: 1 hostname: 10.1.2.152.
17/01/29 04:46:27,182 INFO TaskSetManager: Finished task 5.0 in stage 1.0 (TID 7) in 22875 ms on 10.1.2.152 (7/59)
17/01/29 04:46:27,671 INFO BlockManagerInfo: Added rdd_5_1 in memory on 10.1.2.152:33704 (size: 70.0 MB, free: 1840.5 MB)
17/01/29 04:46:27,693 INFO TaskSetManager: Starting task 14.0 in stage 1.0 (TID 16, 10.1.2.152, partition 14, ANY, 5372 bytes)
17/01/29 04:46:27,693 INFO CoarseGrainedSchedulerBackend$DriverEndpoint: Launching task 16 on executor id: 1 hostname: 10.1.2.152.
17/01/29 04:46:27,693 INFO TaskSetManager: Finished task 1.0 in stage 1.0 (TID 3) in 23396 ms on 10.1.2.152 (8/59)
17/01/29 04:46:28,102 INFO BlockManagerInfo: Added rdd_5_7 in memory on 10.1.2.152:33704 (size: 70.0 MB, free: 1770.5 MB)
17/01/29 04:46:28,126 INFO TaskSetManager: Starting task 15.0 in stage 1.0 (TID 17, 10.1.2.152, partition 15, ANY, 5372 bytes)
17/01/29 04:46:28,127 INFO CoarseGrainedSchedulerBackend$DriverEndpoint: Launching task 17 on executor id: 1 hostname: 10.1.2.152.
17/01/29 04:46:28,127 INFO TaskSetManager: Finished task 7.0 in stage 1.0 (TID 9) in 23816 ms on 10.1.2.152 (9/59)
17/01/29 04:46:42,807 INFO BlockManagerInfo: Added rdd_5_8 in memory on 10.1.2.60:37320 (size: 70.0 MB, free: 1767.9 MB)
17/01/29 04:46:42,826 INFO TaskSetManager: Starting task 16.0 in stage 1.0 (TID 18, 10.1.2.60, partition 16, ANY, 5372 bytes)
17/01/29 04:46:42,826 INFO CoarseGrainedSchedulerBackend$DriverEndpoint: Launching task 18 on executor id: 0 hostname: 10.1.2.60.
17/01/29 04:46:42,828 INFO TaskSetManager: Finished task 8.0 in stage 1.0 (TID 10) in 20012 ms on 10.1.2.60 (10/59)
17/01/29 04:46:46,172 INFO BlockManagerInfo: Added rdd_5_9 in memory on 10.1.2.60:37320 (size: 69.9 MB, free: 1697.9 MB)
17/01/29 04:46:46,191 INFO TaskSetManager: Starting task 17.0 in stage 1.0 (TID 19, 10.1.2.60, partition 17, ANY, 5372 bytes)
17/01/29 04:46:46,192 INFO CoarseGrainedSchedulerBackend$DriverEndpoint: Launching task 19 on executor id: 0 hostname: 10.1.2.60.
17/01/29 04:46:46,192 INFO TaskSetManager: Finished task 9.0 in stage 1.0 (TID 11) in 22094 ms on 10.1.2.60 (11/59)
17/01/29 04:46:46,802 INFO BlockManagerInfo: Added rdd_5_12 in memory on 10.1.2.152:33704 (size: 70.0 MB, free: 1700.6 MB)
17/01/29 04:46:46,823 INFO TaskSetManager: Starting task 18.0 in stage 1.0 (TID 20, 10.1.2.152, partition 18, ANY, 5372 bytes)
17/01/29 04:46:46,824 INFO CoarseGrainedSchedulerBackend$DriverEndpoint: Launching task 20 on executor id: 1 hostname: 10.1.2.152.
17/01/29 04:46:46,824 INFO TaskSetManager: Finished task 12.0 in stage 1.0 (TID 14) in 20012 ms on 10.1.2.152 (12/59)
17/01/29 04:46:47,049 INFO BlockManagerInfo: Added rdd_5_10 in memory on 10.1.2.60:37320 (size: 70.0 MB, free: 1628.0 MB)
17/01/29 04:46:47,065 INFO TaskSetManager: Starting task 19.0 in stage 1.0 (TID 21, 10.1.2.60, partition 19, ANY, 5372 bytes)
17/01/29 04:46:47,066 INFO CoarseGrainedSchedulerBackend$DriverEndpoint: Launching task 21 on executor id: 0 hostname: 10.1.2.60.
17/01/29 04:46:47,066 INFO TaskSetManager: Finished task 10.0 in stage 1.0 (TID 12) in 21370 ms on 10.1.2.60 (13/59)
17/01/29 04:46:47,815 INFO BlockManagerInfo: Added rdd_5_14 in memory on 10.1.2.152:33704 (size: 69.9 MB, free: 1630.7 MB)
17/01/29 04:46:47,838 INFO TaskSetManager: Starting task 20.0 in stage 1.0 (TID 22, 10.1.2.152, partition 20, ANY, 5372 bytes)
17/01/29 04:46:47,838 INFO CoarseGrainedSchedulerBackend$DriverEndpoint: Launching task 22 on executor id: 1 hostname: 10.1.2.152.
17/01/29 04:46:47,840 INFO TaskSetManager: Finished task 14.0 in stage 1.0 (TID 16) in 20149 ms on 10.1.2.152 (14/59)
17/01/29 04:46:48,011 INFO BlockManagerInfo: Added rdd_5_13 in memory on 10.1.2.152:33704 (size: 69.9 MB, free: 1560.8 MB)
17/01/29 04:46:48,031 INFO TaskSetManager: Starting task 21.0 in stage 1.0 (TID 23, 10.1.2.152, partition 21, ANY, 5372 bytes)
17/01/29 04:46:48,031 INFO CoarseGrainedSchedulerBackend$DriverEndpoint: Launching task 23 on executor id: 1 hostname: 10.1.2.152.
17/01/29 04:46:48,032 INFO TaskSetManager: Finished task 13.0 in stage 1.0 (TID 15) in 20853 ms on 10.1.2.152 (15/59)
17/01/29 04:46:49,124 INFO BlockManagerInfo: Added rdd_5_15 in memory on 10.1.2.152:33704 (size: 69.9 MB, free: 1490.8 MB)
17/01/29 04:46:49,151 INFO TaskSetManager: Starting task 22.0 in stage 1.0 (TID 24, 10.1.2.152, partition 22, ANY, 5372 bytes)
17/01/29 04:46:49,151 INFO CoarseGrainedSchedulerBackend$DriverEndpoint: Launching task 24 on executor id: 1 hostname: 10.1.2.152.
17/01/29 04:46:49,152 INFO TaskSetManager: Finished task 15.0 in stage 1.0 (TID 17) in 21027 ms on 10.1.2.152 (16/59)
17/01/29 04:46:50,285 INFO BlockManagerInfo: Added rdd_5_11 in memory on 10.1.2.60:37320 (size: 69.9 MB, free: 1558.1 MB)
17/01/29 04:46:50,309 INFO TaskSetManager: Starting task 23.0 in stage 1.0 (TID 25, 10.1.2.60, partition 23, ANY, 5372 bytes)
17/01/29 04:46:50,309 INFO CoarseGrainedSchedulerBackend$DriverEndpoint: Launching task 25 on executor id: 0 hostname: 10.1.2.60.
17/01/29 04:46:50,310 INFO TaskSetManager: Finished task 11.0 in stage 1.0 (TID 13) in 24080 ms on 10.1.2.60 (17/59)
17/01/29 04:47:05,895 INFO BlockManagerInfo: Added rdd_5_16 in memory on 10.1.2.60:37320 (size: 70.0 MB, free: 1488.1 MB)
17/01/29 04:47:05,911 INFO TaskSetManager: Starting task 24.0 in stage 1.0 (TID 26, 10.1.2.60, partition 24, ANY, 5372 bytes)
17/01/29 04:47:05,912 INFO CoarseGrainedSchedulerBackend$DriverEndpoint: Launching task 26 on executor id: 0 hostname: 10.1.2.60.
17/01/29 04:47:05,914 INFO TaskSetManager: Finished task 16.0 in stage 1.0 (TID 18) in 23089 ms on 10.1.2.60 (18/59)
17/01/29 04:47:07,819 INFO BlockManagerInfo: Added rdd_5_21 in memory on 10.1.2.152:33704 (size: 69.9 MB, free: 1420.9 MB)
17/01/29 04:47:07,839 INFO TaskSetManager: Starting task 25.0 in stage 1.0 (TID 27, 10.1.2.152, partition 25, ANY, 5372 bytes)
17/01/29 04:47:07,841 INFO CoarseGrainedSchedulerBackend$DriverEndpoint: Launching task 27 on executor id: 1 hostname: 10.1.2.152.
17/01/29 04:47:07,841 INFO TaskSetManager: Finished task 21.0 in stage 1.0 (TID 23) in 19812 ms on 10.1.2.152 (19/59)
17/01/29 04:47:08,080 INFO BlockManagerInfo: Added rdd_5_17 in memory on 10.1.2.60:37320 (size: 69.9 MB, free: 1418.2 MB)
17/01/29 04:47:08,097 INFO TaskSetManager: Starting task 26.0 in stage 1.0 (TID 28, 10.1.2.60, partition 26, ANY, 5372 bytes)
17/01/29 04:47:08,098 INFO CoarseGrainedSchedulerBackend$DriverEndpoint: Launching task 28 on executor id: 0 hostname: 10.1.2.60.
17/01/29 04:47:08,099 INFO TaskSetManager: Finished task 17.0 in stage 1.0 (TID 19) in 21908 ms on 10.1.2.60 (20/59)
17/01/29 04:47:08,297 INFO BlockManagerInfo: Added rdd_5_19 in memory on 10.1.2.60:37320 (size: 70.0 MB, free: 1348.2 MB)
17/01/29 04:47:08,316 INFO TaskSetManager: Starting task 27.0 in stage 1.0 (TID 29, 10.1.2.60, partition 27, ANY, 5372 bytes)
17/01/29 04:47:08,317 INFO CoarseGrainedSchedulerBackend$DriverEndpoint: Launching task 29 on executor id: 0 hostname: 10.1.2.60.
17/01/29 04:47:08,317 INFO TaskSetManager: Finished task 19.0 in stage 1.0 (TID 21) in 21253 ms on 10.1.2.60 (21/59)
17/01/29 04:47:08,611 INFO BlockManagerInfo: Added rdd_5_20 in memory on 10.1.2.152:33704 (size: 69.8 MB, free: 1351.0 MB)
17/01/29 04:47:08,629 INFO TaskSetManager: Starting task 28.0 in stage 1.0 (TID 30, 10.1.2.152, partition 28, ANY, 5372 bytes)
17/01/29 04:47:08,631 INFO TaskSetManager: Finished task 20.0 in stage 1.0 (TID 22) in 20795 ms on 10.1.2.152 (22/59)
17/01/29 04:47:08,632 INFO CoarseGrainedSchedulerBackend$DriverEndpoint: Launching task 30 on executor id: 1 hostname: 10.1.2.152.
17/01/29 04:47:08,774 INFO BlockManagerInfo: Added rdd_5_18 in memory on 10.1.2.152:33704 (size: 70.0 MB, free: 1281.1 MB)
17/01/29 04:47:08,792 INFO TaskSetManager: Starting task 29.0 in stage 1.0 (TID 31, 10.1.2.152, partition 29, ANY, 5372 bytes)
17/01/29 04:47:08,794 INFO CoarseGrainedSchedulerBackend$DriverEndpoint: Launching task 31 on executor id: 1 hostname: 10.1.2.152.
17/01/29 04:47:08,794 INFO TaskSetManager: Finished task 18.0 in stage 1.0 (TID 20) in 21972 ms on 10.1.2.152 (23/59)
17/01/29 04:47:10,759 INFO BlockManagerInfo: Added rdd_5_22 in memory on 10.1.2.152:33704 (size: 69.8 MB, free: 1211.2 MB)
17/01/29 04:47:10,779 INFO TaskSetManager: Starting task 30.0 in stage 1.0 (TID 32, 10.1.2.152, partition 30, ANY, 5372 bytes)
17/01/29 04:47:10,780 INFO CoarseGrainedSchedulerBackend$DriverEndpoint: Launching task 32 on executor id: 1 hostname: 10.1.2.152.
17/01/29 04:47:10,780 INFO TaskSetManager: Finished task 22.0 in stage 1.0 (TID 24) in 21630 ms on 10.1.2.152 (24/59)
17/01/29 04:47:11,001 INFO BlockManagerInfo: Added rdd_5_23 in memory on 10.1.2.60:37320 (size: 69.9 MB, free: 1278.3 MB)
17/01/29 04:47:11,019 INFO TaskSetManager: Starting task 31.0 in stage 1.0 (TID 33, 10.1.2.60, partition 31, ANY, 5372 bytes)
17/01/29 04:47:11,020 INFO CoarseGrainedSchedulerBackend$DriverEndpoint: Launching task 33 on executor id: 0 hostname: 10.1.2.60.
17/01/29 04:47:11,020 INFO TaskSetManager: Finished task 23.0 in stage 1.0 (TID 25) in 20713 ms on 10.1.2.60 (25/59)
17/01/29 04:47:24,773 INFO BlockManagerInfo: Added rdd_5_24 in memory on 10.1.2.60:37320 (size: 69.8 MB, free: 1208.6 MB)
17/01/29 04:47:24,794 INFO TaskSetManager: Starting task 32.0 in stage 1.0 (TID 34, 10.1.2.60, partition 32, ANY, 5372 bytes)
17/01/29 04:47:24,794 INFO CoarseGrainedSchedulerBackend$DriverEndpoint: Launching task 34 on executor id: 0 hostname: 10.1.2.60.
17/01/29 04:47:24,795 INFO TaskSetManager: Finished task 24.0 in stage 1.0 (TID 26) in 18884 ms on 10.1.2.60 (26/59)
17/01/29 04:47:27,226 INFO BlockManagerInfo: Added rdd_5_27 in memory on 10.1.2.60:37320 (size: 69.9 MB, free: 1138.7 MB)
17/01/29 04:47:27,250 INFO TaskSetManager: Starting task 33.0 in stage 1.0 (TID 35, 10.1.2.60, partition 33, ANY, 5372 bytes)
17/01/29 04:47:27,250 INFO CoarseGrainedSchedulerBackend$DriverEndpoint: Launching task 35 on executor id: 0 hostname: 10.1.2.60.
17/01/29 04:47:27,251 INFO TaskSetManager: Finished task 27.0 in stage 1.0 (TID 29) in 18937 ms on 10.1.2.60 (27/59)
17/01/29 04:47:27,299 INFO BlockManagerInfo: Added rdd_5_26 in memory on 10.1.2.60:37320 (size: 69.9 MB, free: 1068.7 MB)
17/01/29 04:47:27,315 INFO TaskSetManager: Starting task 34.0 in stage 1.0 (TID 36, 10.1.2.60, partition 34, ANY, 5372 bytes)
17/01/29 04:47:27,316 INFO CoarseGrainedSchedulerBackend$DriverEndpoint: Launching task 36 on executor id: 0 hostname: 10.1.2.60.
17/01/29 04:47:27,318 INFO TaskSetManager: Finished task 26.0 in stage 1.0 (TID 28) in 19222 ms on 10.1.2.60 (28/59)
17/01/29 04:47:31,017 INFO BlockManagerInfo: Added rdd_5_31 in memory on 10.1.2.60:37320 (size: 69.7 MB, free: 999.0 MB)
17/01/29 04:47:31,034 INFO TaskSetManager: Starting task 35.0 in stage 1.0 (TID 37, 10.1.2.60, partition 35, ANY, 5372 bytes)
17/01/29 04:47:31,035 INFO CoarseGrainedSchedulerBackend$DriverEndpoint: Launching task 37 on executor id: 0 hostname: 10.1.2.60.
17/01/29 04:47:31,035 INFO TaskSetManager: Finished task 31.0 in stage 1.0 (TID 33) in 20017 ms on 10.1.2.60 (29/59)
17/01/29 04:47:31,955 INFO BlockManagerInfo: Added rdd_5_25 in memory on 10.1.2.152:33704 (size: 70.0 MB, free: 1141.3 MB)
17/01/29 04:47:31,977 INFO TaskSetManager: Starting task 36.0 in stage 1.0 (TID 38, 10.1.2.152, partition 36, ANY, 5372 bytes)
17/01/29 04:47:31,978 INFO CoarseGrainedSchedulerBackend$DriverEndpoint: Launching task 38 on executor id: 1 hostname: 10.1.2.152.
17/01/29 04:47:31,980 INFO TaskSetManager: Finished task 25.0 in stage 1.0 (TID 27) in 24141 ms on 10.1.2.152 (30/59)
17/01/29 04:47:33,610 INFO BlockManagerInfo: Added rdd_5_29 in memory on 10.1.2.152:33704 (size: 69.9 MB, free: 1071.3 MB)
17/01/29 04:47:33,627 INFO TaskSetManager: Starting task 37.0 in stage 1.0 (TID 39, 10.1.2.152, partition 37, ANY, 5372 bytes)
17/01/29 04:47:33,628 INFO CoarseGrainedSchedulerBackend$DriverEndpoint: Launching task 39 on executor id: 1 hostname: 10.1.2.152.
17/01/29 04:47:33,629 INFO TaskSetManager: Finished task 29.0 in stage 1.0 (TID 31) in 24838 ms on 10.1.2.152 (31/59)
17/01/29 04:47:34,307 INFO BlockManagerInfo: Added rdd_5_30 in memory on 10.1.2.152:33704 (size: 70.0 MB, free: 1001.4 MB)
17/01/29 04:47:34,327 INFO TaskSetManager: Starting task 38.0 in stage 1.0 (TID 40, 10.1.2.152, partition 38, ANY, 5372 bytes)
17/01/29 04:47:34,327 INFO CoarseGrainedSchedulerBackend$DriverEndpoint: Launching task 40 on executor id: 1 hostname: 10.1.2.152.
17/01/29 04:47:34,327 INFO TaskSetManager: Finished task 30.0 in stage 1.0 (TID 32) in 23549 ms on 10.1.2.152 (32/59)
17/01/29 04:47:34,978 INFO BlockManagerInfo: Added rdd_5_28 in memory on 10.1.2.152:33704 (size: 70.0 MB, free: 931.4 MB)
17/01/29 04:47:34,999 INFO TaskSetManager: Starting task 39.0 in stage 1.0 (TID 41, 10.1.2.152, partition 39, ANY, 5372 bytes)
17/01/29 04:47:35,001 INFO CoarseGrainedSchedulerBackend$DriverEndpoint: Launching task 41 on executor id: 1 hostname: 10.1.2.152.
17/01/29 04:47:35,001 INFO TaskSetManager: Finished task 28.0 in stage 1.0 (TID 30) in 26373 ms on 10.1.2.152 (33/59)
17/01/29 04:47:44,369 INFO BlockManagerInfo: Added rdd_5_32 in memory on 10.1.2.60:37320 (size: 69.9 MB, free: 929.1 MB)
17/01/29 04:47:44,387 INFO TaskSetManager: Starting task 40.0 in stage 1.0 (TID 42, 10.1.2.60, partition 40, ANY, 5372 bytes)
17/01/29 04:47:44,387 INFO CoarseGrainedSchedulerBackend$DriverEndpoint: Launching task 42 on executor id: 0 hostname: 10.1.2.60.
17/01/29 04:47:44,388 INFO TaskSetManager: Finished task 32.0 in stage 1.0 (TID 34) in 19596 ms on 10.1.2.60 (34/59)
17/01/29 04:47:46,613 INFO BlockManagerInfo: Added rdd_5_34 in memory on 10.1.2.60:37320 (size: 70.0 MB, free: 859.1 MB)
17/01/29 04:47:46,632 INFO TaskSetManager: Starting task 41.0 in stage 1.0 (TID 43, 10.1.2.60, partition 41, ANY, 5372 bytes)
17/01/29 04:47:46,632 INFO CoarseGrainedSchedulerBackend$DriverEndpoint: Launching task 43 on executor id: 0 hostname: 10.1.2.60.
17/01/29 04:47:46,633 INFO TaskSetManager: Finished task 34.0 in stage 1.0 (TID 36) in 19319 ms on 10.1.2.60 (35/59)
17/01/29 04:47:46,881 INFO BlockManagerInfo: Added rdd_5_33 in memory on 10.1.2.60:37320 (size: 69.9 MB, free: 789.2 MB)
17/01/29 04:47:46,899 INFO TaskSetManager: Starting task 42.0 in stage 1.0 (TID 44, 10.1.2.60, partition 42, ANY, 5372 bytes)
17/01/29 04:47:46,900 INFO CoarseGrainedSchedulerBackend$DriverEndpoint: Launching task 44 on executor id: 0 hostname: 10.1.2.60.
17/01/29 04:47:46,900 INFO TaskSetManager: Finished task 33.0 in stage 1.0 (TID 35) in 19651 ms on 10.1.2.60 (36/59)
17/01/29 04:47:49,497 INFO BlockManagerInfo: Added rdd_5_35 in memory on 10.1.2.60:37320 (size: 70.0 MB, free: 719.2 MB)
17/01/29 04:47:49,515 INFO TaskSetManager: Starting task 43.0 in stage 1.0 (TID 45, 10.1.2.60, partition 43, ANY, 5372 bytes)
17/01/29 04:47:49,515 INFO CoarseGrainedSchedulerBackend$DriverEndpoint: Launching task 45 on executor id: 0 hostname: 10.1.2.60.
17/01/29 04:47:49,516 INFO TaskSetManager: Finished task 35.0 in stage 1.0 (TID 37) in 18483 ms on 10.1.2.60 (37/59)
17/01/29 04:47:52,179 INFO BlockManagerInfo: Added rdd_5_36 in memory on 10.1.2.152:33704 (size: 70.0 MB, free: 861.4 MB)
17/01/29 04:47:52,199 INFO TaskSetManager: Starting task 44.0 in stage 1.0 (TID 46, 10.1.2.152, partition 44, ANY, 5372 bytes)
17/01/29 04:47:52,200 INFO CoarseGrainedSchedulerBackend$DriverEndpoint: Launching task 46 on executor id: 1 hostname: 10.1.2.152.
17/01/29 04:47:52,200 INFO TaskSetManager: Finished task 36.0 in stage 1.0 (TID 38) in 20225 ms on 10.1.2.152 (38/59)
17/01/29 04:47:54,055 INFO BlockManagerInfo: Added rdd_5_38 in memory on 10.1.2.152:33704 (size: 70.0 MB, free: 791.4 MB)
17/01/29 04:47:54,074 INFO TaskSetManager: Starting task 45.0 in stage 1.0 (TID 47, 10.1.2.152, partition 45, ANY, 5372 bytes)
17/01/29 04:47:54,075 INFO CoarseGrainedSchedulerBackend$DriverEndpoint: Launching task 47 on executor id: 1 hostname: 10.1.2.152.
17/01/29 04:47:54,075 INFO TaskSetManager: Finished task 38.0 in stage 1.0 (TID 40) in 19750 ms on 10.1.2.152 (39/59)
17/01/29 04:47:55,195 INFO BlockManagerInfo: Added rdd_5_37 in memory on 10.1.2.152:33704 (size: 69.9 MB, free: 721.5 MB)
17/01/29 04:47:55,216 INFO TaskSetManager: Starting task 46.0 in stage 1.0 (TID 48, 10.1.2.152, partition 46, ANY, 5372 bytes)
17/01/29 04:47:55,216 INFO CoarseGrainedSchedulerBackend$DriverEndpoint: Launching task 48 on executor id: 1 hostname: 10.1.2.152.
17/01/29 04:47:55,216 INFO TaskSetManager: Finished task 37.0 in stage 1.0 (TID 39) in 21590 ms on 10.1.2.152 (40/59)
17/01/29 04:47:55,428 INFO BlockManagerInfo: Added rdd_5_39 in memory on 10.1.2.152:33704 (size: 70.0 MB, free: 651.5 MB)
17/01/29 04:47:55,447 INFO TaskSetManager: Starting task 47.0 in stage 1.0 (TID 49, 10.1.2.152, partition 47, ANY, 5372 bytes)
17/01/29 04:47:55,447 INFO CoarseGrainedSchedulerBackend$DriverEndpoint: Launching task 49 on executor id: 1 hostname: 10.1.2.152.
17/01/29 04:47:55,448 INFO TaskSetManager: Finished task 39.0 in stage 1.0 (TID 41) in 20449 ms on 10.1.2.152 (41/59)
17/01/29 04:48:01,946 INFO BlockManagerInfo: Added rdd_5_40 in memory on 10.1.2.60:37320 (size: 70.0 MB, free: 649.2 MB)
17/01/29 04:48:01,962 INFO TaskSetManager: Starting task 48.0 in stage 1.0 (TID 50, 10.1.2.60, partition 48, ANY, 5372 bytes)
17/01/29 04:48:01,962 INFO CoarseGrainedSchedulerBackend$DriverEndpoint: Launching task 50 on executor id: 0 hostname: 10.1.2.60.
17/01/29 04:48:01,963 INFO TaskSetManager: Finished task 40.0 in stage 1.0 (TID 42) in 17577 ms on 10.1.2.60 (42/59)
17/01/29 04:48:05,025 INFO BlockManagerInfo: Added rdd_5_42 in memory on 10.1.2.60:37320 (size: 69.8 MB, free: 579.4 MB)
17/01/29 04:48:05,044 INFO TaskSetManager: Starting task 49.0 in stage 1.0 (TID 51, 10.1.2.60, partition 49, ANY, 5372 bytes)
17/01/29 04:48:05,045 INFO CoarseGrainedSchedulerBackend$DriverEndpoint: Launching task 51 on executor id: 0 hostname: 10.1.2.60.
17/01/29 04:48:05,045 INFO TaskSetManager: Finished task 42.0 in stage 1.0 (TID 44) in 18147 ms on 10.1.2.60 (43/59)
17/01/29 04:48:07,058 INFO BlockManagerInfo: Added rdd_5_41 in memory on 10.1.2.60:37320 (size: 70.0 MB, free: 509.4 MB)
17/01/29 04:48:07,074 INFO TaskSetManager: Starting task 50.0 in stage 1.0 (TID 52, 10.1.2.60, partition 50, ANY, 5372 bytes)
17/01/29 04:48:07,075 INFO CoarseGrainedSchedulerBackend$DriverEndpoint: Launching task 52 on executor id: 0 hostname: 10.1.2.60.
17/01/29 04:48:07,075 INFO TaskSetManager: Finished task 41.0 in stage 1.0 (TID 43) in 20444 ms on 10.1.2.60 (44/59)
17/01/29 04:48:10,486 INFO BlockManagerInfo: Added rdd_5_44 in memory on 10.1.2.152:33704 (size: 70.0 MB, free: 581.5 MB)
17/01/29 04:48:10,503 INFO TaskSetManager: Starting task 51.0 in stage 1.0 (TID 53, 10.1.2.152, partition 51, ANY, 5372 bytes)
17/01/29 04:48:10,503 INFO CoarseGrainedSchedulerBackend$DriverEndpoint: Launching task 53 on executor id: 1 hostname: 10.1.2.152.
17/01/29 04:48:10,504 INFO TaskSetManager: Finished task 44.0 in stage 1.0 (TID 46) in 18305 ms on 10.1.2.152 (45/59)
17/01/29 04:48:13,299 INFO BlockManagerInfo: Added rdd_5_45 in memory on 10.1.2.152:33704 (size: 69.9 MB, free: 511.6 MB)
17/01/29 04:48:13,318 INFO TaskSetManager: Starting task 52.0 in stage 1.0 (TID 54, 10.1.2.152, partition 52, ANY, 5372 bytes)
17/01/29 04:48:13,318 INFO CoarseGrainedSchedulerBackend$DriverEndpoint: Launching task 54 on executor id: 1 hostname: 10.1.2.152.
17/01/29 04:48:13,318 INFO TaskSetManager: Finished task 45.0 in stage 1.0 (TID 47) in 19244 ms on 10.1.2.152 (46/59)
17/01/29 04:48:14,301 INFO BlockManagerInfo: Added rdd_5_43 in memory on 10.1.2.60:37320 (size: 69.8 MB, free: 439.6 MB)
17/01/29 04:48:14,317 INFO TaskSetManager: Starting task 53.0 in stage 1.0 (TID 55, 10.1.2.60, partition 53, ANY, 5372 bytes)
17/01/29 04:48:14,317 INFO CoarseGrainedSchedulerBackend$DriverEndpoint: Launching task 55 on executor id: 0 hostname: 10.1.2.60.
17/01/29 04:48:14,318 INFO TaskSetManager: Finished task 43.0 in stage 1.0 (TID 45) in 24804 ms on 10.1.2.60 (47/59)
17/01/29 04:48:15,482 INFO BlockManagerInfo: Added rdd_5_46 in memory on 10.1.2.152:33704 (size: 69.9 MB, free: 441.7 MB)
17/01/29 04:48:15,504 INFO TaskSetManager: Starting task 54.0 in stage 1.0 (TID 56, 10.1.2.152, partition 54, ANY, 5372 bytes)
17/01/29 04:48:15,504 INFO CoarseGrainedSchedulerBackend$DriverEndpoint: Launching task 56 on executor id: 1 hostname: 10.1.2.152.
17/01/29 04:48:15,504 INFO TaskSetManager: Finished task 46.0 in stage 1.0 (TID 48) in 20289 ms on 10.1.2.152 (48/59)
17/01/29 04:48:15,621 INFO BlockManagerInfo: Added rdd_5_47 in memory on 10.1.2.152:33704 (size: 70.0 MB, free: 371.7 MB)
17/01/29 04:48:15,641 INFO TaskSetManager: Starting task 55.0 in stage 1.0 (TID 57, 10.1.2.152, partition 55, ANY, 5372 bytes)
17/01/29 04:48:15,641 INFO CoarseGrainedSchedulerBackend$DriverEndpoint: Launching task 57 on executor id: 1 hostname: 10.1.2.152.
17/01/29 04:48:15,641 INFO TaskSetManager: Finished task 47.0 in stage 1.0 (TID 49) in 20195 ms on 10.1.2.152 (49/59)
17/01/29 04:48:24,083 INFO BlockManagerInfo: Added rdd_5_49 in memory on 10.1.2.60:37320 (size: 69.8 MB, free: 369.8 MB)
17/01/29 04:48:24,098 INFO TaskSetManager: Starting task 56.0 in stage 1.0 (TID 58, 10.1.2.60, partition 56, ANY, 5372 bytes)
17/01/29 04:48:24,098 INFO CoarseGrainedSchedulerBackend$DriverEndpoint: Launching task 58 on executor id: 0 hostname: 10.1.2.60.
17/01/29 04:48:24,099 INFO TaskSetManager: Finished task 49.0 in stage 1.0 (TID 51) in 19055 ms on 10.1.2.60 (50/59)
17/01/29 04:48:24,555 INFO BlockManagerInfo: Added rdd_5_48 in memory on 10.1.2.60:37320 (size: 69.9 MB, free: 299.9 MB)
17/01/29 04:48:24,577 INFO TaskSetManager: Starting task 57.0 in stage 1.0 (TID 59, 10.1.2.60, partition 57, ANY, 5372 bytes)
17/01/29 04:48:24,577 INFO CoarseGrainedSchedulerBackend$DriverEndpoint: Launching task 59 on executor id: 0 hostname: 10.1.2.60.
17/01/29 04:48:24,578 INFO TaskSetManager: Finished task 48.0 in stage 1.0 (TID 50) in 22617 ms on 10.1.2.60 (51/59)
17/01/29 04:48:25,041 INFO BlockManagerInfo: Added rdd_5_50 in memory on 10.1.2.60:37320 (size: 69.9 MB, free: 230.0 MB)
17/01/29 04:48:25,058 INFO TaskSetManager: Finished task 50.0 in stage 1.0 (TID 52) in 17984 ms on 10.1.2.60 (52/59)
17/01/29 04:48:29,278 INFO BlockManagerInfo: Added rdd_5_51 in memory on 10.1.2.152:33704 (size: 69.9 MB, free: 301.9 MB)
17/01/29 04:48:29,299 INFO TaskSetManager: Finished task 51.0 in stage 1.0 (TID 53) in 18797 ms on 10.1.2.152 (53/59)
17/01/29 04:48:31,889 INFO BlockManagerInfo: Added rdd_5_53 in memory on 10.1.2.60:37320 (size: 70.0 MB, free: 160.0 MB)
17/01/29 04:48:31,907 INFO TaskSetManager: Finished task 53.0 in stage 1.0 (TID 55) in 17590 ms on 10.1.2.60 (54/59)
17/01/29 04:48:32,251 INFO BlockManagerInfo: Added rdd_5_52 in memory on 10.1.2.152:33704 (size: 69.9 MB, free: 232.0 MB)
17/01/29 04:48:32,267 INFO TaskSetManager: Finished task 52.0 in stage 1.0 (TID 54) in 18950 ms on 10.1.2.152 (55/59)
17/01/29 04:48:32,821 INFO BlockManagerInfo: Added rdd_5_55 in memory on 10.1.2.152:33704 (size: 69.9 MB, free: 162.1 MB)
17/01/29 04:48:32,888 INFO TaskSetManager: Finished task 55.0 in stage 1.0 (TID 57) in 17248 ms on 10.1.2.152 (56/59)
17/01/29 04:48:32,897 INFO BlockManagerInfo: Added rdd_5_54 in memory on 10.1.2.152:33704 (size: 69.9 MB, free: 92.2 MB)
17/01/29 04:48:32,915 INFO TaskSetManager: Finished task 54.0 in stage 1.0 (TID 56) in 17412 ms on 10.1.2.152 (57/59)
17/01/29 04:48:37,042 INFO TaskSetManager: Finished task 57.0 in stage 1.0 (TID 59) in 12465 ms on 10.1.2.60 (58/59)
17/01/29 04:48:37,050 INFO BlockManagerInfo: Added rdd_5_56 in memory on 10.1.2.60:37320 (size: 69.9 MB, free: 90.1 MB)
17/01/29 04:48:37,066 INFO TaskSetManager: Finished task 56.0 in stage 1.0 (TID 58) in 12969 ms on 10.1.2.60 (59/59)
17/01/29 04:48:37,066 INFO TaskSchedulerImpl: Removed TaskSet 1.0, whose tasks have all completed, from pool 
17/01/29 04:48:37,066 INFO DAGScheduler: ResultStage 1 (count at DataValidators.scala:40) finished in 155.802 s
17/01/29 04:48:37,067 INFO DAGScheduler: Job 1 finished: count at DataValidators.scala:40, took 155.841986 s
17/01/29 04:48:37,077 INFO SparkContext: Starting job: count at GradientDescent.scala:209
17/01/29 04:48:37,078 INFO DAGScheduler: Got job 2 (count at GradientDescent.scala:209) with 59 output partitions
17/01/29 04:48:37,079 INFO DAGScheduler: Final stage: ResultStage 2 (count at GradientDescent.scala:209)
17/01/29 04:48:37,079 INFO DAGScheduler: Parents of final stage: List()
17/01/29 04:48:37,081 INFO DAGScheduler: Missing parents: List()
17/01/29 04:48:37,083 INFO DAGScheduler: Submitting ResultStage 2 (MapPartitionsRDD[8] at map at GeneralizedLinearAlgorithm.scala:297), which has no missing parents
17/01/29 04:48:37,089 INFO MemoryStore: Block broadcast_3 stored as values in memory (estimated size 3.9 KB, free 2.1 GB)
17/01/29 04:48:37,091 INFO MemoryStore: Block broadcast_3_piece0 stored as bytes in memory (estimated size 2.2 KB, free 2.1 GB)
17/01/29 04:48:37,092 INFO BlockManagerInfo: Added broadcast_3_piece0 in memory on 10.1.2.31:38380 (size: 2.2 KB, free: 2.1 GB)
17/01/29 04:48:37,093 INFO SparkContext: Created broadcast 3 from broadcast at DAGScheduler.scala:1012
17/01/29 04:48:37,095 INFO DAGScheduler: Submitting 59 missing tasks from ResultStage 2 (MapPartitionsRDD[8] at map at GeneralizedLinearAlgorithm.scala:297)
17/01/29 04:48:37,095 INFO TaskSchedulerImpl: Adding task set 2.0 with 59 tasks
17/01/29 04:48:37,098 INFO TaskSetManager: Starting task 2.0 in stage 2.0 (TID 60, 10.1.2.60, partition 2, PROCESS_LOCAL, 5372 bytes)
17/01/29 04:48:37,099 INFO TaskSetManager: Starting task 0.0 in stage 2.0 (TID 61, 10.1.2.152, partition 0, PROCESS_LOCAL, 5372 bytes)
17/01/29 04:48:37,100 INFO TaskSetManager: Starting task 4.0 in stage 2.0 (TID 62, 10.1.2.60, partition 4, PROCESS_LOCAL, 5372 bytes)
17/01/29 04:48:37,100 INFO TaskSetManager: Starting task 1.0 in stage 2.0 (TID 63, 10.1.2.152, partition 1, PROCESS_LOCAL, 5372 bytes)
17/01/29 04:48:37,101 INFO TaskSetManager: Starting task 6.0 in stage 2.0 (TID 64, 10.1.2.60, partition 6, PROCESS_LOCAL, 5372 bytes)
17/01/29 04:48:37,102 INFO TaskSetManager: Starting task 3.0 in stage 2.0 (TID 65, 10.1.2.152, partition 3, PROCESS_LOCAL, 5372 bytes)
17/01/29 04:48:37,103 INFO TaskSetManager: Starting task 8.0 in stage 2.0 (TID 66, 10.1.2.60, partition 8, PROCESS_LOCAL, 5372 bytes)
17/01/29 04:48:37,103 INFO TaskSetManager: Starting task 5.0 in stage 2.0 (TID 67, 10.1.2.152, partition 5, PROCESS_LOCAL, 5372 bytes)
17/01/29 04:48:37,104 INFO CoarseGrainedSchedulerBackend$DriverEndpoint: Launching task 60 on executor id: 0 hostname: 10.1.2.60.
17/01/29 04:48:37,104 INFO CoarseGrainedSchedulerBackend$DriverEndpoint: Launching task 62 on executor id: 0 hostname: 10.1.2.60.
17/01/29 04:48:37,104 INFO CoarseGrainedSchedulerBackend$DriverEndpoint: Launching task 64 on executor id: 0 hostname: 10.1.2.60.
17/01/29 04:48:37,104 INFO CoarseGrainedSchedulerBackend$DriverEndpoint: Launching task 66 on executor id: 0 hostname: 10.1.2.60.
17/01/29 04:48:37,105 INFO CoarseGrainedSchedulerBackend$DriverEndpoint: Launching task 61 on executor id: 1 hostname: 10.1.2.152.
17/01/29 04:48:37,105 INFO CoarseGrainedSchedulerBackend$DriverEndpoint: Launching task 63 on executor id: 1 hostname: 10.1.2.152.
17/01/29 04:48:37,106 INFO CoarseGrainedSchedulerBackend$DriverEndpoint: Launching task 65 on executor id: 1 hostname: 10.1.2.152.
17/01/29 04:48:37,106 INFO CoarseGrainedSchedulerBackend$DriverEndpoint: Launching task 67 on executor id: 1 hostname: 10.1.2.152.
17/01/29 04:48:37,127 INFO BlockManagerInfo: Added broadcast_3_piece0 in memory on 10.1.2.60:37320 (size: 2.2 KB, free: 90.1 MB)
17/01/29 04:48:37,132 INFO BlockManagerInfo: Added broadcast_3_piece0 in memory on 10.1.2.152:33704 (size: 2.2 KB, free: 92.2 MB)
17/01/29 04:48:37,165 INFO TaskSetManager: Starting task 7.0 in stage 2.0 (TID 68, 10.1.2.152, partition 7, PROCESS_LOCAL, 5372 bytes)
17/01/29 04:48:37,165 INFO CoarseGrainedSchedulerBackend$DriverEndpoint: Launching task 68 on executor id: 1 hostname: 10.1.2.152.
17/01/29 04:48:37,166 INFO TaskSetManager: Finished task 5.0 in stage 2.0 (TID 67) in 63 ms on 10.1.2.152 (1/59)
17/01/29 04:48:37,167 INFO TaskSetManager: Starting task 12.0 in stage 2.0 (TID 69, 10.1.2.152, partition 12, PROCESS_LOCAL, 5372 bytes)
17/01/29 04:48:37,167 INFO CoarseGrainedSchedulerBackend$DriverEndpoint: Launching task 69 on executor id: 1 hostname: 10.1.2.152.
17/01/29 04:48:37,168 INFO TaskSetManager: Finished task 1.0 in stage 2.0 (TID 63) in 68 ms on 10.1.2.152 (2/59)
17/01/29 04:48:37,170 INFO TaskSetManager: Starting task 13.0 in stage 2.0 (TID 70, 10.1.2.152, partition 13, PROCESS_LOCAL, 5372 bytes)
17/01/29 04:48:37,170 INFO CoarseGrainedSchedulerBackend$DriverEndpoint: Launching task 70 on executor id: 1 hostname: 10.1.2.152.
17/01/29 04:48:37,171 INFO TaskSetManager: Finished task 0.0 in stage 2.0 (TID 61) in 72 ms on 10.1.2.152 (3/59)
17/01/29 04:48:37,172 INFO TaskSetManager: Starting task 9.0 in stage 2.0 (TID 71, 10.1.2.60, partition 9, PROCESS_LOCAL, 5372 bytes)
17/01/29 04:48:37,173 INFO CoarseGrainedSchedulerBackend$DriverEndpoint: Launching task 71 on executor id: 0 hostname: 10.1.2.60.
17/01/29 04:48:37,174 INFO TaskSetManager: Starting task 10.0 in stage 2.0 (TID 72, 10.1.2.60, partition 10, PROCESS_LOCAL, 5372 bytes)
17/01/29 04:48:37,174 INFO CoarseGrainedSchedulerBackend$DriverEndpoint: Launching task 72 on executor id: 0 hostname: 10.1.2.60.
17/01/29 04:48:37,174 INFO TaskSetManager: Finished task 8.0 in stage 2.0 (TID 66) in 72 ms on 10.1.2.60 (4/59)
17/01/29 04:48:37,175 INFO TaskSetManager: Finished task 6.0 in stage 2.0 (TID 64) in 75 ms on 10.1.2.60 (5/59)
17/01/29 04:48:37,177 INFO TaskSetManager: Finished task 2.0 in stage 2.0 (TID 60) in 80 ms on 10.1.2.60 (6/59)
17/01/29 04:48:37,178 INFO TaskSetManager: Starting task 11.0 in stage 2.0 (TID 73, 10.1.2.60, partition 11, PROCESS_LOCAL, 5372 bytes)
17/01/29 04:48:37,180 INFO CoarseGrainedSchedulerBackend$DriverEndpoint: Launching task 73 on executor id: 0 hostname: 10.1.2.60.
17/01/29 04:48:37,181 INFO TaskSetManager: Finished task 3.0 in stage 2.0 (TID 65) in 80 ms on 10.1.2.152 (7/59)
17/01/29 04:48:37,182 INFO TaskSetManager: Starting task 14.0 in stage 2.0 (TID 74, 10.1.2.152, partition 14, PROCESS_LOCAL, 5372 bytes)
17/01/29 04:48:37,185 INFO CoarseGrainedSchedulerBackend$DriverEndpoint: Launching task 74 on executor id: 1 hostname: 10.1.2.152.
17/01/29 04:48:37,187 INFO TaskSetManager: Starting task 16.0 in stage 2.0 (TID 75, 10.1.2.60, partition 16, PROCESS_LOCAL, 5372 bytes)
17/01/29 04:48:37,187 INFO CoarseGrainedSchedulerBackend$DriverEndpoint: Launching task 75 on executor id: 0 hostname: 10.1.2.60.
17/01/29 04:48:37,187 INFO TaskSetManager: Finished task 4.0 in stage 2.0 (TID 62) in 88 ms on 10.1.2.60 (8/59)
17/01/29 04:48:37,201 INFO TaskSetManager: Finished task 13.0 in stage 2.0 (TID 70) in 32 ms on 10.1.2.152 (9/59)
17/01/29 04:48:37,203 INFO TaskSetManager: Starting task 15.0 in stage 2.0 (TID 76, 10.1.2.152, partition 15, PROCESS_LOCAL, 5372 bytes)
17/01/29 04:48:37,203 INFO CoarseGrainedSchedulerBackend$DriverEndpoint: Launching task 76 on executor id: 1 hostname: 10.1.2.152.
17/01/29 04:48:37,204 INFO TaskSetManager: Finished task 7.0 in stage 2.0 (TID 68) in 40 ms on 10.1.2.152 (10/59)
17/01/29 04:48:37,205 INFO TaskSetManager: Starting task 18.0 in stage 2.0 (TID 77, 10.1.2.152, partition 18, PROCESS_LOCAL, 5372 bytes)
17/01/29 04:48:37,205 INFO CoarseGrainedSchedulerBackend$DriverEndpoint: Launching task 77 on executor id: 1 hostname: 10.1.2.152.
17/01/29 04:48:37,208 INFO TaskSetManager: Starting task 20.0 in stage 2.0 (TID 78, 10.1.2.152, partition 20, PROCESS_LOCAL, 5372 bytes)
17/01/29 04:48:37,208 INFO CoarseGrainedSchedulerBackend$DriverEndpoint: Launching task 78 on executor id: 1 hostname: 10.1.2.152.
17/01/29 04:48:37,208 INFO TaskSetManager: Finished task 12.0 in stage 2.0 (TID 69) in 41 ms on 10.1.2.152 (11/59)
17/01/29 04:48:37,217 INFO TaskSetManager: Starting task 17.0 in stage 2.0 (TID 79, 10.1.2.60, partition 17, PROCESS_LOCAL, 5372 bytes)
17/01/29 04:48:37,217 INFO CoarseGrainedSchedulerBackend$DriverEndpoint: Launching task 79 on executor id: 0 hostname: 10.1.2.60.
17/01/29 04:48:37,218 INFO TaskSetManager: Finished task 9.0 in stage 2.0 (TID 71) in 46 ms on 10.1.2.60 (12/59)
17/01/29 04:48:37,219 INFO TaskSetManager: Finished task 14.0 in stage 2.0 (TID 74) in 37 ms on 10.1.2.152 (13/59)
17/01/29 04:48:37,221 INFO TaskSetManager: Starting task 21.0 in stage 2.0 (TID 80, 10.1.2.152, partition 21, PROCESS_LOCAL, 5372 bytes)
17/01/29 04:48:37,221 INFO CoarseGrainedSchedulerBackend$DriverEndpoint: Launching task 80 on executor id: 1 hostname: 10.1.2.152.
17/01/29 04:48:37,222 INFO TaskSetManager: Finished task 11.0 in stage 2.0 (TID 73) in 44 ms on 10.1.2.60 (14/59)
17/01/29 04:48:37,223 INFO TaskSetManager: Starting task 19.0 in stage 2.0 (TID 81, 10.1.2.60, partition 19, PROCESS_LOCAL, 5372 bytes)
17/01/29 04:48:37,224 INFO CoarseGrainedSchedulerBackend$DriverEndpoint: Launching task 81 on executor id: 0 hostname: 10.1.2.60.
17/01/29 04:48:37,224 INFO TaskSetManager: Finished task 10.0 in stage 2.0 (TID 72) in 51 ms on 10.1.2.60 (15/59)
17/01/29 04:48:37,226 INFO TaskSetManager: Starting task 23.0 in stage 2.0 (TID 82, 10.1.2.60, partition 23, PROCESS_LOCAL, 5372 bytes)
17/01/29 04:48:37,226 INFO CoarseGrainedSchedulerBackend$DriverEndpoint: Launching task 82 on executor id: 0 hostname: 10.1.2.60.
17/01/29 04:48:37,228 INFO TaskSetManager: Starting task 24.0 in stage 2.0 (TID 83, 10.1.2.60, partition 24, PROCESS_LOCAL, 5372 bytes)
17/01/29 04:48:37,228 INFO CoarseGrainedSchedulerBackend$DriverEndpoint: Launching task 83 on executor id: 0 hostname: 10.1.2.60.
17/01/29 04:48:37,228 INFO TaskSetManager: Finished task 16.0 in stage 2.0 (TID 75) in 42 ms on 10.1.2.60 (16/59)
17/01/29 04:48:37,249 INFO TaskSetManager: Starting task 26.0 in stage 2.0 (TID 84, 10.1.2.60, partition 26, PROCESS_LOCAL, 5372 bytes)
17/01/29 04:48:37,249 INFO CoarseGrainedSchedulerBackend$DriverEndpoint: Launching task 84 on executor id: 0 hostname: 10.1.2.60.
17/01/29 04:48:37,250 INFO TaskSetManager: Finished task 17.0 in stage 2.0 (TID 79) in 34 ms on 10.1.2.60 (17/59)
17/01/29 04:48:37,255 INFO TaskSetManager: Starting task 22.0 in stage 2.0 (TID 85, 10.1.2.152, partition 22, PROCESS_LOCAL, 5372 bytes)
17/01/29 04:48:37,256 INFO CoarseGrainedSchedulerBackend$DriverEndpoint: Launching task 85 on executor id: 1 hostname: 10.1.2.152.
17/01/29 04:48:37,256 INFO TaskSetManager: Finished task 21.0 in stage 2.0 (TID 80) in 36 ms on 10.1.2.152 (18/59)
17/01/29 04:48:37,258 INFO TaskSetManager: Finished task 20.0 in stage 2.0 (TID 78) in 51 ms on 10.1.2.152 (19/59)
17/01/29 04:48:37,259 INFO TaskSetManager: Starting task 25.0 in stage 2.0 (TID 86, 10.1.2.152, partition 25, PROCESS_LOCAL, 5372 bytes)
17/01/29 04:48:37,259 INFO CoarseGrainedSchedulerBackend$DriverEndpoint: Launching task 86 on executor id: 1 hostname: 10.1.2.152.
17/01/29 04:48:37,260 INFO TaskSetManager: Finished task 23.0 in stage 2.0 (TID 82) in 35 ms on 10.1.2.60 (20/59)
17/01/29 04:48:37,261 INFO TaskSetManager: Starting task 27.0 in stage 2.0 (TID 87, 10.1.2.60, partition 27, PROCESS_LOCAL, 5372 bytes)
17/01/29 04:48:37,262 INFO CoarseGrainedSchedulerBackend$DriverEndpoint: Launching task 87 on executor id: 0 hostname: 10.1.2.60.
17/01/29 04:48:37,263 INFO TaskSetManager: Starting task 28.0 in stage 2.0 (TID 88, 10.1.2.152, partition 28, PROCESS_LOCAL, 5372 bytes)
17/01/29 04:48:37,263 INFO CoarseGrainedSchedulerBackend$DriverEndpoint: Launching task 88 on executor id: 1 hostname: 10.1.2.152.
17/01/29 04:48:37,263 INFO TaskSetManager: Finished task 18.0 in stage 2.0 (TID 77) in 59 ms on 10.1.2.152 (21/59)
17/01/29 04:48:37,264 INFO TaskSetManager: Finished task 15.0 in stage 2.0 (TID 76) in 62 ms on 10.1.2.152 (22/59)
17/01/29 04:48:37,265 INFO TaskSetManager: Starting task 29.0 in stage 2.0 (TID 89, 10.1.2.152, partition 29, PROCESS_LOCAL, 5372 bytes)
17/01/29 04:48:37,266 INFO CoarseGrainedSchedulerBackend$DriverEndpoint: Launching task 89 on executor id: 1 hostname: 10.1.2.152.
17/01/29 04:48:37,273 INFO TaskSetManager: Starting task 31.0 in stage 2.0 (TID 90, 10.1.2.60, partition 31, PROCESS_LOCAL, 5372 bytes)
17/01/29 04:48:37,273 INFO CoarseGrainedSchedulerBackend$DriverEndpoint: Launching task 90 on executor id: 0 hostname: 10.1.2.60.
17/01/29 04:48:37,274 INFO TaskSetManager: Finished task 24.0 in stage 2.0 (TID 83) in 46 ms on 10.1.2.60 (23/59)
17/01/29 04:48:37,276 INFO TaskSetManager: Finished task 19.0 in stage 2.0 (TID 81) in 52 ms on 10.1.2.60 (24/59)
17/01/29 04:48:37,277 INFO TaskSetManager: Starting task 32.0 in stage 2.0 (TID 91, 10.1.2.60, partition 32, PROCESS_LOCAL, 5372 bytes)
17/01/29 04:48:37,277 INFO CoarseGrainedSchedulerBackend$DriverEndpoint: Launching task 91 on executor id: 0 hostname: 10.1.2.60.
17/01/29 04:48:37,280 INFO TaskSetManager: Starting task 33.0 in stage 2.0 (TID 92, 10.1.2.60, partition 33, PROCESS_LOCAL, 5372 bytes)
17/01/29 04:48:37,281 INFO CoarseGrainedSchedulerBackend$DriverEndpoint: Launching task 92 on executor id: 0 hostname: 10.1.2.60.
17/01/29 04:48:37,281 INFO TaskSetManager: Finished task 26.0 in stage 2.0 (TID 84) in 32 ms on 10.1.2.60 (25/59)
17/01/29 04:48:37,285 INFO TaskSetManager: Starting task 30.0 in stage 2.0 (TID 93, 10.1.2.152, partition 30, PROCESS_LOCAL, 5372 bytes)
17/01/29 04:48:37,286 INFO CoarseGrainedSchedulerBackend$DriverEndpoint: Launching task 93 on executor id: 1 hostname: 10.1.2.152.
17/01/29 04:48:37,286 INFO TaskSetManager: Finished task 22.0 in stage 2.0 (TID 85) in 31 ms on 10.1.2.152 (26/59)
17/01/29 04:48:37,290 INFO TaskSetManager: Starting task 36.0 in stage 2.0 (TID 94, 10.1.2.152, partition 36, PROCESS_LOCAL, 5372 bytes)
17/01/29 04:48:37,291 INFO CoarseGrainedSchedulerBackend$DriverEndpoint: Launching task 94 on executor id: 1 hostname: 10.1.2.152.
17/01/29 04:48:37,291 INFO TaskSetManager: Finished task 29.0 in stage 2.0 (TID 89) in 26 ms on 10.1.2.152 (27/59)
17/01/29 04:48:37,293 INFO TaskSetManager: Starting task 34.0 in stage 2.0 (TID 95, 10.1.2.60, partition 34, PROCESS_LOCAL, 5372 bytes)
17/01/29 04:48:37,300 INFO CoarseGrainedSchedulerBackend$DriverEndpoint: Launching task 95 on executor id: 0 hostname: 10.1.2.60.
17/01/29 04:48:37,300 INFO TaskSetManager: Finished task 27.0 in stage 2.0 (TID 87) in 39 ms on 10.1.2.60 (28/59)
17/01/29 04:48:37,302 INFO TaskSetManager: Starting task 37.0 in stage 2.0 (TID 96, 10.1.2.152, partition 37, PROCESS_LOCAL, 5372 bytes)
17/01/29 04:48:37,302 INFO CoarseGrainedSchedulerBackend$DriverEndpoint: Launching task 96 on executor id: 1 hostname: 10.1.2.152.
17/01/29 04:48:37,302 INFO TaskSetManager: Finished task 28.0 in stage 2.0 (TID 88) in 40 ms on 10.1.2.152 (29/59)
17/01/29 04:48:37,303 INFO TaskSetManager: Starting task 38.0 in stage 2.0 (TID 97, 10.1.2.152, partition 38, PROCESS_LOCAL, 5372 bytes)
17/01/29 04:48:37,304 INFO CoarseGrainedSchedulerBackend$DriverEndpoint: Launching task 97 on executor id: 1 hostname: 10.1.2.152.
17/01/29 04:48:37,304 INFO TaskSetManager: Finished task 25.0 in stage 2.0 (TID 86) in 46 ms on 10.1.2.152 (30/59)
17/01/29 04:48:37,306 INFO TaskSetManager: Starting task 35.0 in stage 2.0 (TID 98, 10.1.2.60, partition 35, PROCESS_LOCAL, 5372 bytes)
17/01/29 04:48:37,306 INFO CoarseGrainedSchedulerBackend$DriverEndpoint: Launching task 98 on executor id: 0 hostname: 10.1.2.60.
17/01/29 04:48:37,307 INFO TaskSetManager: Finished task 31.0 in stage 2.0 (TID 90) in 33 ms on 10.1.2.60 (31/59)
17/01/29 04:48:37,311 INFO TaskSetManager: Starting task 39.0 in stage 2.0 (TID 99, 10.1.2.152, partition 39, PROCESS_LOCAL, 5372 bytes)
17/01/29 04:48:37,311 INFO CoarseGrainedSchedulerBackend$DriverEndpoint: Launching task 99 on executor id: 1 hostname: 10.1.2.152.
17/01/29 04:48:37,311 INFO TaskSetManager: Finished task 30.0 in stage 2.0 (TID 93) in 26 ms on 10.1.2.152 (32/59)
17/01/29 04:48:37,312 INFO TaskSetManager: Starting task 40.0 in stage 2.0 (TID 100, 10.1.2.60, partition 40, PROCESS_LOCAL, 5372 bytes)
17/01/29 04:48:37,312 INFO CoarseGrainedSchedulerBackend$DriverEndpoint: Launching task 100 on executor id: 0 hostname: 10.1.2.60.
17/01/29 04:48:37,313 INFO TaskSetManager: Finished task 33.0 in stage 2.0 (TID 92) in 32 ms on 10.1.2.60 (33/59)
17/01/29 04:48:37,315 INFO TaskSetManager: Starting task 41.0 in stage 2.0 (TID 101, 10.1.2.60, partition 41, PROCESS_LOCAL, 5372 bytes)
17/01/29 04:48:37,315 INFO CoarseGrainedSchedulerBackend$DriverEndpoint: Launching task 101 on executor id: 0 hostname: 10.1.2.60.
17/01/29 04:48:37,315 INFO TaskSetManager: Finished task 32.0 in stage 2.0 (TID 91) in 39 ms on 10.1.2.60 (34/59)
17/01/29 04:48:37,320 INFO TaskSetManager: Starting task 44.0 in stage 2.0 (TID 102, 10.1.2.152, partition 44, PROCESS_LOCAL, 5372 bytes)
17/01/29 04:48:37,320 INFO CoarseGrainedSchedulerBackend$DriverEndpoint: Launching task 102 on executor id: 1 hostname: 10.1.2.152.
17/01/29 04:48:37,321 INFO TaskSetManager: Finished task 36.0 in stage 2.0 (TID 94) in 30 ms on 10.1.2.152 (35/59)
17/01/29 04:48:37,328 INFO TaskSetManager: Starting task 45.0 in stage 2.0 (TID 103, 10.1.2.152, partition 45, PROCESS_LOCAL, 5372 bytes)
17/01/29 04:48:37,328 INFO CoarseGrainedSchedulerBackend$DriverEndpoint: Launching task 103 on executor id: 1 hostname: 10.1.2.152.
17/01/29 04:48:37,329 INFO TaskSetManager: Finished task 38.0 in stage 2.0 (TID 97) in 25 ms on 10.1.2.152 (36/59)
17/01/29 04:48:37,332 INFO TaskSetManager: Starting task 42.0 in stage 2.0 (TID 104, 10.1.2.60, partition 42, PROCESS_LOCAL, 5372 bytes)
17/01/29 04:48:37,333 INFO CoarseGrainedSchedulerBackend$DriverEndpoint: Launching task 104 on executor id: 0 hostname: 10.1.2.60.
17/01/29 04:48:37,333 INFO TaskSetManager: Finished task 34.0 in stage 2.0 (TID 95) in 41 ms on 10.1.2.60 (37/59)
17/01/29 04:48:37,335 INFO TaskSetManager: Starting task 46.0 in stage 2.0 (TID 105, 10.1.2.152, partition 46, PROCESS_LOCAL, 5372 bytes)
17/01/29 04:48:37,335 INFO CoarseGrainedSchedulerBackend$DriverEndpoint: Launching task 105 on executor id: 1 hostname: 10.1.2.152.
17/01/29 04:48:37,335 INFO TaskSetManager: Finished task 37.0 in stage 2.0 (TID 96) in 34 ms on 10.1.2.152 (38/59)
17/01/29 04:48:37,336 INFO TaskSetManager: Starting task 43.0 in stage 2.0 (TID 106, 10.1.2.60, partition 43, PROCESS_LOCAL, 5372 bytes)
17/01/29 04:48:37,337 INFO CoarseGrainedSchedulerBackend$DriverEndpoint: Launching task 106 on executor id: 0 hostname: 10.1.2.60.
17/01/29 04:48:37,337 INFO TaskSetManager: Finished task 35.0 in stage 2.0 (TID 98) in 32 ms on 10.1.2.60 (39/59)
17/01/29 04:48:37,339 INFO TaskSetManager: Starting task 47.0 in stage 2.0 (TID 107, 10.1.2.152, partition 47, PROCESS_LOCAL, 5372 bytes)
17/01/29 04:48:37,339 INFO CoarseGrainedSchedulerBackend$DriverEndpoint: Launching task 107 on executor id: 1 hostname: 10.1.2.152.
17/01/29 04:48:37,340 INFO TaskSetManager: Finished task 39.0 in stage 2.0 (TID 99) in 29 ms on 10.1.2.152 (40/59)
17/01/29 04:48:37,342 INFO TaskSetManager: Starting task 48.0 in stage 2.0 (TID 108, 10.1.2.60, partition 48, PROCESS_LOCAL, 5372 bytes)
17/01/29 04:48:37,342 INFO CoarseGrainedSchedulerBackend$DriverEndpoint: Launching task 108 on executor id: 0 hostname: 10.1.2.60.
17/01/29 04:48:37,342 INFO TaskSetManager: Finished task 40.0 in stage 2.0 (TID 100) in 31 ms on 10.1.2.60 (41/59)
17/01/29 04:48:37,346 INFO TaskSetManager: Starting task 51.0 in stage 2.0 (TID 109, 10.1.2.152, partition 51, PROCESS_LOCAL, 5372 bytes)
17/01/29 04:48:37,346 INFO CoarseGrainedSchedulerBackend$DriverEndpoint: Launching task 109 on executor id: 1 hostname: 10.1.2.152.
17/01/29 04:48:37,346 INFO TaskSetManager: Finished task 44.0 in stage 2.0 (TID 102) in 27 ms on 10.1.2.152 (42/59)
17/01/29 04:48:37,349 INFO TaskSetManager: Starting task 49.0 in stage 2.0 (TID 110, 10.1.2.60, partition 49, PROCESS_LOCAL, 5372 bytes)
17/01/29 04:48:37,349 INFO CoarseGrainedSchedulerBackend$DriverEndpoint: Launching task 110 on executor id: 0 hostname: 10.1.2.60.
17/01/29 04:48:37,349 INFO TaskSetManager: Finished task 41.0 in stage 2.0 (TID 101) in 35 ms on 10.1.2.60 (43/59)
17/01/29 04:48:37,361 INFO TaskSetManager: Starting task 52.0 in stage 2.0 (TID 111, 10.1.2.152, partition 52, PROCESS_LOCAL, 5372 bytes)
17/01/29 04:48:37,361 INFO CoarseGrainedSchedulerBackend$DriverEndpoint: Launching task 111 on executor id: 1 hostname: 10.1.2.152.
17/01/29 04:48:37,361 INFO TaskSetManager: Finished task 47.0 in stage 2.0 (TID 107) in 22 ms on 10.1.2.152 (44/59)
17/01/29 04:48:37,364 INFO TaskSetManager: Starting task 50.0 in stage 2.0 (TID 112, 10.1.2.60, partition 50, PROCESS_LOCAL, 5372 bytes)
17/01/29 04:48:37,365 INFO CoarseGrainedSchedulerBackend$DriverEndpoint: Launching task 112 on executor id: 0 hostname: 10.1.2.60.
17/01/29 04:48:37,365 INFO TaskSetManager: Finished task 42.0 in stage 2.0 (TID 104) in 33 ms on 10.1.2.60 (45/59)
17/01/29 04:48:37,373 INFO TaskSetManager: Starting task 53.0 in stage 2.0 (TID 113, 10.1.2.60, partition 53, PROCESS_LOCAL, 5372 bytes)
17/01/29 04:48:37,374 INFO CoarseGrainedSchedulerBackend$DriverEndpoint: Launching task 113 on executor id: 0 hostname: 10.1.2.60.
17/01/29 04:48:37,374 INFO TaskSetManager: Finished task 48.0 in stage 2.0 (TID 108) in 33 ms on 10.1.2.60 (46/59)
17/01/29 04:48:37,376 INFO TaskSetManager: Starting task 54.0 in stage 2.0 (TID 114, 10.1.2.152, partition 54, PROCESS_LOCAL, 5372 bytes)
17/01/29 04:48:37,377 INFO CoarseGrainedSchedulerBackend$DriverEndpoint: Launching task 114 on executor id: 1 hostname: 10.1.2.152.
17/01/29 04:48:37,377 INFO TaskSetManager: Finished task 51.0 in stage 2.0 (TID 109) in 32 ms on 10.1.2.152 (47/59)
17/01/29 04:48:37,379 INFO TaskSetManager: Starting task 56.0 in stage 2.0 (TID 115, 10.1.2.60, partition 56, PROCESS_LOCAL, 5372 bytes)
17/01/29 04:48:37,380 INFO CoarseGrainedSchedulerBackend$DriverEndpoint: Launching task 115 on executor id: 0 hostname: 10.1.2.60.
17/01/29 04:48:37,380 INFO TaskSetManager: Finished task 49.0 in stage 2.0 (TID 110) in 32 ms on 10.1.2.60 (48/59)
17/01/29 04:48:37,382 INFO TaskSetManager: Starting task 55.0 in stage 2.0 (TID 116, 10.1.2.152, partition 55, PROCESS_LOCAL, 5372 bytes)
17/01/29 04:48:37,383 INFO CoarseGrainedSchedulerBackend$DriverEndpoint: Launching task 116 on executor id: 1 hostname: 10.1.2.152.
17/01/29 04:48:37,383 INFO TaskSetManager: Finished task 46.0 in stage 2.0 (TID 105) in 49 ms on 10.1.2.152 (49/59)
17/01/29 04:48:37,384 INFO TaskSetManager: Finished task 45.0 in stage 2.0 (TID 103) in 56 ms on 10.1.2.152 (50/59)
17/01/29 04:48:37,385 INFO TaskSetManager: Finished task 52.0 in stage 2.0 (TID 111) in 25 ms on 10.1.2.152 (51/59)
17/01/29 04:48:37,390 INFO TaskSetManager: Starting task 58.0 in stage 2.0 (TID 117, 10.1.2.60, partition 58, PROCESS_LOCAL, 5372 bytes)
17/01/29 04:48:37,390 INFO CoarseGrainedSchedulerBackend$DriverEndpoint: Launching task 117 on executor id: 0 hostname: 10.1.2.60.
17/01/29 04:48:37,390 INFO TaskSetManager: Finished task 43.0 in stage 2.0 (TID 106) in 54 ms on 10.1.2.60 (52/59)
17/01/29 04:48:37,394 INFO TaskSetManager: Finished task 50.0 in stage 2.0 (TID 112) in 31 ms on 10.1.2.60 (53/59)
17/01/29 04:48:37,407 INFO TaskSetManager: Finished task 54.0 in stage 2.0 (TID 114) in 31 ms on 10.1.2.152 (54/59)
17/01/29 04:48:37,409 INFO TaskSetManager: Finished task 55.0 in stage 2.0 (TID 116) in 27 ms on 10.1.2.152 (55/59)
17/01/29 04:48:37,418 INFO TaskSetManager: Finished task 53.0 in stage 2.0 (TID 113) in 46 ms on 10.1.2.60 (56/59)
17/01/29 04:48:37,419 INFO TaskSetManager: Finished task 56.0 in stage 2.0 (TID 115) in 39 ms on 10.1.2.60 (57/59)
17/01/29 04:48:37,423 INFO TaskSetManager: Finished task 58.0 in stage 2.0 (TID 117) in 34 ms on 10.1.2.60 (58/59)
17/01/29 04:48:41,297 INFO TaskSetManager: Starting task 57.0 in stage 2.0 (TID 118, 10.1.2.152, partition 57, ANY, 5372 bytes)
17/01/29 04:48:41,297 INFO CoarseGrainedSchedulerBackend$DriverEndpoint: Launching task 118 on executor id: 1 hostname: 10.1.2.152.
17/01/29 04:48:46,876 INFO TaskSetManager: Finished task 57.0 in stage 2.0 (TID 118) in 5580 ms on 10.1.2.152 (59/59)
17/01/29 04:48:46,876 INFO TaskSchedulerImpl: Removed TaskSet 2.0, whose tasks have all completed, from pool 
17/01/29 04:48:46,876 INFO DAGScheduler: ResultStage 2 (count at GradientDescent.scala:209) finished in 9.780 s
17/01/29 04:48:46,877 INFO DAGScheduler: Job 2 finished: count at GradientDescent.scala:209, took 9.799956 s
17/01/29 04:48:47,114 WARN BLAS: Failed to load implementation from: com.github.fommil.netlib.NativeSystemBLAS
17/01/29 04:48:47,114 WARN BLAS: Failed to load implementation from: com.github.fommil.netlib.NativeRefBLAS
17/01/29 04:48:47,141 INFO MemoryStore: Block broadcast_4 stored as values in memory (estimated size 280.0 B, free 2.1 GB)
17/01/29 04:48:47,144 INFO MemoryStore: Block broadcast_4_piece0 stored as bytes in memory (estimated size 153.0 B, free 2.1 GB)
17/01/29 04:48:47,145 INFO BlockManagerInfo: Added broadcast_4_piece0 in memory on 10.1.2.31:38380 (size: 153.0 B, free: 2.1 GB)
17/01/29 04:48:47,146 INFO SparkContext: Created broadcast 4 from broadcast at GradientDescent.scala:235
17/01/29 04:48:47,204 INFO SparkContext: Starting job: treeAggregate at GradientDescent.scala:239
17/01/29 04:48:47,210 INFO DAGScheduler: Registering RDD 11 (treeAggregate at GradientDescent.scala:239)
17/01/29 04:48:47,211 INFO DAGScheduler: Got job 3 (treeAggregate at GradientDescent.scala:239) with 7 output partitions
17/01/29 04:48:47,211 INFO DAGScheduler: Final stage: ResultStage 4 (treeAggregate at GradientDescent.scala:239)
17/01/29 04:48:47,211 INFO DAGScheduler: Parents of final stage: List(ShuffleMapStage 3)
17/01/29 04:48:47,211 INFO DAGScheduler: Missing parents: List(ShuffleMapStage 3)
17/01/29 04:48:47,216 INFO DAGScheduler: Submitting ShuffleMapStage 3 (MapPartitionsRDD[11] at treeAggregate at GradientDescent.scala:239), which has no missing parents
17/01/29 04:48:47,234 INFO MemoryStore: Block broadcast_5 stored as values in memory (estimated size 7.2 KB, free 2.1 GB)
17/01/29 04:48:47,236 INFO MemoryStore: Block broadcast_5_piece0 stored as bytes in memory (estimated size 3.7 KB, free 2.1 GB)
17/01/29 04:48:47,236 INFO BlockManagerInfo: Added broadcast_5_piece0 in memory on 10.1.2.31:38380 (size: 3.7 KB, free: 2.1 GB)
17/01/29 04:48:47,237 INFO SparkContext: Created broadcast 5 from broadcast at DAGScheduler.scala:1012
17/01/29 04:48:47,239 INFO DAGScheduler: Submitting 59 missing tasks from ShuffleMapStage 3 (MapPartitionsRDD[11] at treeAggregate at GradientDescent.scala:239)
17/01/29 04:48:47,240 INFO TaskSchedulerImpl: Adding task set 3.0 with 59 tasks
17/01/29 04:48:47,244 INFO TaskSetManager: Starting task 0.0 in stage 3.0 (TID 119, 10.1.2.152, partition 0, PROCESS_LOCAL, 5561 bytes)
17/01/29 04:48:47,244 INFO TaskSetManager: Starting task 2.0 in stage 3.0 (TID 120, 10.1.2.60, partition 2, PROCESS_LOCAL, 5561 bytes)
17/01/29 04:48:47,245 INFO TaskSetManager: Starting task 1.0 in stage 3.0 (TID 121, 10.1.2.152, partition 1, PROCESS_LOCAL, 5561 bytes)
17/01/29 04:48:47,245 INFO TaskSetManager: Starting task 4.0 in stage 3.0 (TID 122, 10.1.2.60, partition 4, PROCESS_LOCAL, 5561 bytes)
17/01/29 04:48:47,246 INFO TaskSetManager: Starting task 3.0 in stage 3.0 (TID 123, 10.1.2.152, partition 3, PROCESS_LOCAL, 5561 bytes)
17/01/29 04:48:47,247 INFO TaskSetManager: Starting task 6.0 in stage 3.0 (TID 124, 10.1.2.60, partition 6, PROCESS_LOCAL, 5561 bytes)
17/01/29 04:48:47,247 INFO TaskSetManager: Starting task 5.0 in stage 3.0 (TID 125, 10.1.2.152, partition 5, PROCESS_LOCAL, 5561 bytes)
17/01/29 04:48:47,248 INFO TaskSetManager: Starting task 8.0 in stage 3.0 (TID 126, 10.1.2.60, partition 8, PROCESS_LOCAL, 5561 bytes)
17/01/29 04:48:47,248 INFO CoarseGrainedSchedulerBackend$DriverEndpoint: Launching task 119 on executor id: 1 hostname: 10.1.2.152.
17/01/29 04:48:47,249 INFO CoarseGrainedSchedulerBackend$DriverEndpoint: Launching task 121 on executor id: 1 hostname: 10.1.2.152.
17/01/29 04:48:47,250 INFO CoarseGrainedSchedulerBackend$DriverEndpoint: Launching task 123 on executor id: 1 hostname: 10.1.2.152.
17/01/29 04:48:47,250 INFO CoarseGrainedSchedulerBackend$DriverEndpoint: Launching task 125 on executor id: 1 hostname: 10.1.2.152.
17/01/29 04:48:47,251 INFO CoarseGrainedSchedulerBackend$DriverEndpoint: Launching task 120 on executor id: 0 hostname: 10.1.2.60.
17/01/29 04:48:47,251 INFO CoarseGrainedSchedulerBackend$DriverEndpoint: Launching task 122 on executor id: 0 hostname: 10.1.2.60.
17/01/29 04:48:47,252 INFO CoarseGrainedSchedulerBackend$DriverEndpoint: Launching task 124 on executor id: 0 hostname: 10.1.2.60.
17/01/29 04:48:47,252 INFO CoarseGrainedSchedulerBackend$DriverEndpoint: Launching task 126 on executor id: 0 hostname: 10.1.2.60.
17/01/29 04:48:47,268 INFO BlockManagerInfo: Added broadcast_5_piece0 in memory on 10.1.2.60:37320 (size: 3.7 KB, free: 90.0 MB)
17/01/29 04:48:47,272 INFO BlockManagerInfo: Added broadcast_5_piece0 in memory on 10.1.2.152:33704 (size: 3.7 KB, free: 92.2 MB)
17/01/29 04:48:47,551 INFO BlockManagerInfo: Added broadcast_4_piece0 in memory on 10.1.2.60:37320 (size: 153.0 B, free: 90.0 MB)
17/01/29 04:48:47,560 INFO BlockManagerInfo: Added broadcast_4_piece0 in memory on 10.1.2.152:33704 (size: 153.0 B, free: 92.2 MB)
17/01/29 04:48:47,734 INFO TaskSetManager: Starting task 7.0 in stage 3.0 (TID 127, 10.1.2.152, partition 7, PROCESS_LOCAL, 5561 bytes)
17/01/29 04:48:47,735 INFO CoarseGrainedSchedulerBackend$DriverEndpoint: Launching task 127 on executor id: 1 hostname: 10.1.2.152.
17/01/29 04:48:47,736 INFO TaskSetManager: Finished task 5.0 in stage 3.0 (TID 125) in 489 ms on 10.1.2.152 (1/59)
17/01/29 04:48:47,737 INFO TaskSetManager: Starting task 12.0 in stage 3.0 (TID 128, 10.1.2.152, partition 12, PROCESS_LOCAL, 5561 bytes)
17/01/29 04:48:47,738 INFO CoarseGrainedSchedulerBackend$DriverEndpoint: Launching task 128 on executor id: 1 hostname: 10.1.2.152.
17/01/29 04:48:47,738 INFO TaskSetManager: Starting task 13.0 in stage 3.0 (TID 129, 10.1.2.152, partition 13, PROCESS_LOCAL, 5561 bytes)
17/01/29 04:48:47,739 INFO CoarseGrainedSchedulerBackend$DriverEndpoint: Launching task 129 on executor id: 1 hostname: 10.1.2.152.
17/01/29 04:48:47,740 INFO TaskSetManager: Starting task 14.0 in stage 3.0 (TID 130, 10.1.2.152, partition 14, PROCESS_LOCAL, 5561 bytes)
17/01/29 04:48:47,740 INFO CoarseGrainedSchedulerBackend$DriverEndpoint: Launching task 130 on executor id: 1 hostname: 10.1.2.152.
17/01/29 04:48:47,740 INFO TaskSetManager: Finished task 3.0 in stage 3.0 (TID 123) in 494 ms on 10.1.2.152 (2/59)
17/01/29 04:48:47,742 INFO TaskSetManager: Finished task 1.0 in stage 3.0 (TID 121) in 498 ms on 10.1.2.152 (3/59)
17/01/29 04:48:47,743 INFO TaskSetManager: Finished task 0.0 in stage 3.0 (TID 119) in 502 ms on 10.1.2.152 (4/59)
17/01/29 04:48:47,798 INFO TaskSetManager: Starting task 9.0 in stage 3.0 (TID 131, 10.1.2.60, partition 9, PROCESS_LOCAL, 5561 bytes)
17/01/29 04:48:47,799 INFO CoarseGrainedSchedulerBackend$DriverEndpoint: Launching task 131 on executor id: 0 hostname: 10.1.2.60.
17/01/29 04:48:47,799 INFO TaskSetManager: Finished task 8.0 in stage 3.0 (TID 126) in 552 ms on 10.1.2.60 (5/59)
17/01/29 04:48:47,800 INFO TaskSetManager: Starting task 10.0 in stage 3.0 (TID 132, 10.1.2.60, partition 10, PROCESS_LOCAL, 5561 bytes)
17/01/29 04:48:47,801 INFO CoarseGrainedSchedulerBackend$DriverEndpoint: Launching task 132 on executor id: 0 hostname: 10.1.2.60.
17/01/29 04:48:47,801 INFO TaskSetManager: Finished task 2.0 in stage 3.0 (TID 120) in 557 ms on 10.1.2.60 (6/59)
17/01/29 04:48:47,802 INFO TaskSetManager: Starting task 11.0 in stage 3.0 (TID 133, 10.1.2.60, partition 11, PROCESS_LOCAL, 5561 bytes)
17/01/29 04:48:47,802 INFO CoarseGrainedSchedulerBackend$DriverEndpoint: Launching task 133 on executor id: 0 hostname: 10.1.2.60.
17/01/29 04:48:47,802 INFO TaskSetManager: Finished task 4.0 in stage 3.0 (TID 122) in 557 ms on 10.1.2.60 (7/59)
17/01/29 04:48:47,803 INFO TaskSetManager: Starting task 16.0 in stage 3.0 (TID 134, 10.1.2.60, partition 16, PROCESS_LOCAL, 5561 bytes)
17/01/29 04:48:47,804 INFO CoarseGrainedSchedulerBackend$DriverEndpoint: Launching task 134 on executor id: 0 hostname: 10.1.2.60.
17/01/29 04:48:47,804 INFO TaskSetManager: Finished task 6.0 in stage 3.0 (TID 124) in 558 ms on 10.1.2.60 (8/59)
17/01/29 04:48:47,826 INFO TaskSetManager: Starting task 15.0 in stage 3.0 (TID 135, 10.1.2.152, partition 15, PROCESS_LOCAL, 5561 bytes)
17/01/29 04:48:47,826 INFO CoarseGrainedSchedulerBackend$DriverEndpoint: Launching task 135 on executor id: 1 hostname: 10.1.2.152.
17/01/29 04:48:47,827 INFO TaskSetManager: Finished task 14.0 in stage 3.0 (TID 130) in 87 ms on 10.1.2.152 (9/59)
17/01/29 04:48:47,835 INFO TaskSetManager: Starting task 18.0 in stage 3.0 (TID 136, 10.1.2.152, partition 18, PROCESS_LOCAL, 5561 bytes)
17/01/29 04:48:47,835 INFO CoarseGrainedSchedulerBackend$DriverEndpoint: Launching task 136 on executor id: 1 hostname: 10.1.2.152.
17/01/29 04:48:47,836 INFO TaskSetManager: Finished task 13.0 in stage 3.0 (TID 129) in 98 ms on 10.1.2.152 (10/59)
17/01/29 04:48:47,837 INFO TaskSetManager: Starting task 20.0 in stage 3.0 (TID 137, 10.1.2.152, partition 20, PROCESS_LOCAL, 5561 bytes)
17/01/29 04:48:47,838 INFO CoarseGrainedSchedulerBackend$DriverEndpoint: Launching task 137 on executor id: 1 hostname: 10.1.2.152.
17/01/29 04:48:47,838 INFO TaskSetManager: Finished task 7.0 in stage 3.0 (TID 127) in 104 ms on 10.1.2.152 (11/59)
17/01/29 04:48:47,864 INFO TaskSetManager: Starting task 21.0 in stage 3.0 (TID 138, 10.1.2.152, partition 21, PROCESS_LOCAL, 5561 bytes)
17/01/29 04:48:47,865 INFO CoarseGrainedSchedulerBackend$DriverEndpoint: Launching task 138 on executor id: 1 hostname: 10.1.2.152.
17/01/29 04:48:47,865 INFO TaskSetManager: Finished task 12.0 in stage 3.0 (TID 128) in 128 ms on 10.1.2.152 (12/59)
17/01/29 04:48:47,901 INFO TaskSetManager: Starting task 22.0 in stage 3.0 (TID 139, 10.1.2.152, partition 22, PROCESS_LOCAL, 5561 bytes)
17/01/29 04:48:47,901 INFO CoarseGrainedSchedulerBackend$DriverEndpoint: Launching task 139 on executor id: 1 hostname: 10.1.2.152.
17/01/29 04:48:47,902 INFO TaskSetManager: Finished task 15.0 in stage 3.0 (TID 135) in 77 ms on 10.1.2.152 (13/59)
17/01/29 04:48:47,929 INFO TaskSetManager: Starting task 25.0 in stage 3.0 (TID 140, 10.1.2.152, partition 25, PROCESS_LOCAL, 5561 bytes)
17/01/29 04:48:47,929 INFO CoarseGrainedSchedulerBackend$DriverEndpoint: Launching task 140 on executor id: 1 hostname: 10.1.2.152.
17/01/29 04:48:47,930 INFO TaskSetManager: Finished task 20.0 in stage 3.0 (TID 137) in 92 ms on 10.1.2.152 (14/59)
17/01/29 04:48:47,932 INFO TaskSetManager: Starting task 28.0 in stage 3.0 (TID 141, 10.1.2.152, partition 28, PROCESS_LOCAL, 5561 bytes)
17/01/29 04:48:47,932 INFO CoarseGrainedSchedulerBackend$DriverEndpoint: Launching task 141 on executor id: 1 hostname: 10.1.2.152.
17/01/29 04:48:47,932 INFO TaskSetManager: Finished task 18.0 in stage 3.0 (TID 136) in 97 ms on 10.1.2.152 (15/59)
17/01/29 04:48:47,934 INFO TaskSetManager: Starting task 29.0 in stage 3.0 (TID 142, 10.1.2.152, partition 29, PROCESS_LOCAL, 5561 bytes)
17/01/29 04:48:47,935 INFO CoarseGrainedSchedulerBackend$DriverEndpoint: Launching task 142 on executor id: 1 hostname: 10.1.2.152.
17/01/29 04:48:47,935 INFO TaskSetManager: Finished task 21.0 in stage 3.0 (TID 138) in 71 ms on 10.1.2.152 (16/59)
17/01/29 04:48:47,939 INFO TaskSetManager: Starting task 17.0 in stage 3.0 (TID 143, 10.1.2.60, partition 17, PROCESS_LOCAL, 5561 bytes)
17/01/29 04:48:47,939 INFO CoarseGrainedSchedulerBackend$DriverEndpoint: Launching task 143 on executor id: 0 hostname: 10.1.2.60.
17/01/29 04:48:47,940 INFO TaskSetManager: Finished task 9.0 in stage 3.0 (TID 131) in 142 ms on 10.1.2.60 (17/59)
17/01/29 04:48:47,962 INFO TaskSetManager: Starting task 19.0 in stage 3.0 (TID 144, 10.1.2.60, partition 19, PROCESS_LOCAL, 5561 bytes)
17/01/29 04:48:47,962 INFO CoarseGrainedSchedulerBackend$DriverEndpoint: Launching task 144 on executor id: 0 hostname: 10.1.2.60.
17/01/29 04:48:47,963 INFO TaskSetManager: Finished task 16.0 in stage 3.0 (TID 134) in 159 ms on 10.1.2.60 (18/59)
17/01/29 04:48:47,975 INFO TaskSetManager: Starting task 30.0 in stage 3.0 (TID 145, 10.1.2.152, partition 30, PROCESS_LOCAL, 5561 bytes)
17/01/29 04:48:47,975 INFO CoarseGrainedSchedulerBackend$DriverEndpoint: Launching task 145 on executor id: 1 hostname: 10.1.2.152.
17/01/29 04:48:47,976 INFO TaskSetManager: Finished task 22.0 in stage 3.0 (TID 139) in 75 ms on 10.1.2.152 (19/59)
17/01/29 04:48:47,977 INFO TaskSetManager: Starting task 23.0 in stage 3.0 (TID 146, 10.1.2.60, partition 23, PROCESS_LOCAL, 5561 bytes)
17/01/29 04:48:47,978 INFO CoarseGrainedSchedulerBackend$DriverEndpoint: Launching task 146 on executor id: 0 hostname: 10.1.2.60.
17/01/29 04:48:47,978 INFO TaskSetManager: Finished task 10.0 in stage 3.0 (TID 132) in 178 ms on 10.1.2.60 (20/59)
17/01/29 04:48:47,995 INFO TaskSetManager: Starting task 24.0 in stage 3.0 (TID 147, 10.1.2.60, partition 24, PROCESS_LOCAL, 5561 bytes)
17/01/29 04:48:47,995 INFO CoarseGrainedSchedulerBackend$DriverEndpoint: Launching task 147 on executor id: 0 hostname: 10.1.2.60.
17/01/29 04:48:47,995 INFO TaskSetManager: Finished task 11.0 in stage 3.0 (TID 133) in 194 ms on 10.1.2.60 (21/59)
17/01/29 04:48:47,998 INFO TaskSetManager: Starting task 36.0 in stage 3.0 (TID 148, 10.1.2.152, partition 36, PROCESS_LOCAL, 5561 bytes)
17/01/29 04:48:47,999 INFO CoarseGrainedSchedulerBackend$DriverEndpoint: Launching task 148 on executor id: 1 hostname: 10.1.2.152.
17/01/29 04:48:47,999 INFO TaskSetManager: Finished task 28.0 in stage 3.0 (TID 141) in 68 ms on 10.1.2.152 (22/59)
17/01/29 04:48:48,004 INFO TaskSetManager: Starting task 26.0 in stage 3.0 (TID 149, 10.1.2.60, partition 26, PROCESS_LOCAL, 5561 bytes)
17/01/29 04:48:48,004 INFO CoarseGrainedSchedulerBackend$DriverEndpoint: Launching task 149 on executor id: 0 hostname: 10.1.2.60.
17/01/29 04:48:48,004 INFO TaskSetManager: Finished task 17.0 in stage 3.0 (TID 143) in 65 ms on 10.1.2.60 (23/59)
17/01/29 04:48:48,018 INFO TaskSetManager: Starting task 37.0 in stage 3.0 (TID 150, 10.1.2.152, partition 37, PROCESS_LOCAL, 5561 bytes)
17/01/29 04:48:48,018 INFO CoarseGrainedSchedulerBackend$DriverEndpoint: Launching task 150 on executor id: 1 hostname: 10.1.2.152.
17/01/29 04:48:48,018 INFO TaskSetManager: Finished task 25.0 in stage 3.0 (TID 140) in 90 ms on 10.1.2.152 (24/59)
17/01/29 04:48:48,019 INFO TaskSetManager: Finished task 29.0 in stage 3.0 (TID 142) in 85 ms on 10.1.2.152 (25/59)
17/01/29 04:48:48,020 INFO TaskSetManager: Starting task 38.0 in stage 3.0 (TID 151, 10.1.2.152, partition 38, PROCESS_LOCAL, 5561 bytes)
17/01/29 04:48:48,020 INFO CoarseGrainedSchedulerBackend$DriverEndpoint: Launching task 151 on executor id: 1 hostname: 10.1.2.152.
17/01/29 04:48:48,025 INFO TaskSetManager: Starting task 27.0 in stage 3.0 (TID 152, 10.1.2.60, partition 27, PROCESS_LOCAL, 5561 bytes)
17/01/29 04:48:48,025 INFO CoarseGrainedSchedulerBackend$DriverEndpoint: Launching task 152 on executor id: 0 hostname: 10.1.2.60.
17/01/29 04:48:48,026 INFO TaskSetManager: Finished task 19.0 in stage 3.0 (TID 144) in 64 ms on 10.1.2.60 (26/59)
17/01/29 04:48:48,040 INFO TaskSetManager: Starting task 31.0 in stage 3.0 (TID 153, 10.1.2.60, partition 31, PROCESS_LOCAL, 5561 bytes)
17/01/29 04:48:48,040 INFO CoarseGrainedSchedulerBackend$DriverEndpoint: Launching task 153 on executor id: 0 hostname: 10.1.2.60.
17/01/29 04:48:48,040 INFO TaskSetManager: Finished task 23.0 in stage 3.0 (TID 146) in 63 ms on 10.1.2.60 (27/59)
17/01/29 04:48:48,055 INFO TaskSetManager: Starting task 39.0 in stage 3.0 (TID 154, 10.1.2.152, partition 39, PROCESS_LOCAL, 5561 bytes)
17/01/29 04:48:48,056 INFO CoarseGrainedSchedulerBackend$DriverEndpoint: Launching task 154 on executor id: 1 hostname: 10.1.2.152.
17/01/29 04:48:48,056 INFO TaskSetManager: Finished task 30.0 in stage 3.0 (TID 145) in 82 ms on 10.1.2.152 (28/59)
17/01/29 04:48:48,065 INFO TaskSetManager: Starting task 44.0 in stage 3.0 (TID 155, 10.1.2.152, partition 44, PROCESS_LOCAL, 5561 bytes)
17/01/29 04:48:48,065 INFO CoarseGrainedSchedulerBackend$DriverEndpoint: Launching task 155 on executor id: 1 hostname: 10.1.2.152.
17/01/29 04:48:48,066 INFO TaskSetManager: Finished task 36.0 in stage 3.0 (TID 148) in 67 ms on 10.1.2.152 (29/59)
17/01/29 04:48:48,076 INFO TaskSetManager: Starting task 32.0 in stage 3.0 (TID 156, 10.1.2.60, partition 32, PROCESS_LOCAL, 5561 bytes)
17/01/29 04:48:48,077 INFO CoarseGrainedSchedulerBackend$DriverEndpoint: Launching task 156 on executor id: 0 hostname: 10.1.2.60.
17/01/29 04:48:48,077 INFO TaskSetManager: Finished task 24.0 in stage 3.0 (TID 147) in 83 ms on 10.1.2.60 (30/59)
17/01/29 04:48:48,094 INFO TaskSetManager: Starting task 33.0 in stage 3.0 (TID 157, 10.1.2.60, partition 33, PROCESS_LOCAL, 5561 bytes)
17/01/29 04:48:48,094 INFO CoarseGrainedSchedulerBackend$DriverEndpoint: Launching task 157 on executor id: 0 hostname: 10.1.2.60.
17/01/29 04:48:48,095 INFO TaskSetManager: Finished task 27.0 in stage 3.0 (TID 152) in 70 ms on 10.1.2.60 (31/59)
17/01/29 04:48:48,102 INFO TaskSetManager: Starting task 34.0 in stage 3.0 (TID 158, 10.1.2.60, partition 34, PROCESS_LOCAL, 5561 bytes)
17/01/29 04:48:48,102 INFO CoarseGrainedSchedulerBackend$DriverEndpoint: Launching task 158 on executor id: 0 hostname: 10.1.2.60.
17/01/29 04:48:48,102 INFO TaskSetManager: Finished task 26.0 in stage 3.0 (TID 149) in 99 ms on 10.1.2.60 (32/59)
17/01/29 04:48:48,108 INFO TaskSetManager: Starting task 35.0 in stage 3.0 (TID 159, 10.1.2.60, partition 35, PROCESS_LOCAL, 5561 bytes)
17/01/29 04:48:48,109 INFO CoarseGrainedSchedulerBackend$DriverEndpoint: Launching task 159 on executor id: 0 hostname: 10.1.2.60.
17/01/29 04:48:48,109 INFO TaskSetManager: Finished task 31.0 in stage 3.0 (TID 153) in 70 ms on 10.1.2.60 (33/59)
17/01/29 04:48:48,160 INFO TaskSetManager: Starting task 40.0 in stage 3.0 (TID 160, 10.1.2.60, partition 40, PROCESS_LOCAL, 5561 bytes)
17/01/29 04:48:48,160 INFO CoarseGrainedSchedulerBackend$DriverEndpoint: Launching task 160 on executor id: 0 hostname: 10.1.2.60.
17/01/29 04:48:48,160 INFO TaskSetManager: Finished task 33.0 in stage 3.0 (TID 157) in 66 ms on 10.1.2.60 (34/59)
17/01/29 04:48:48,163 INFO TaskSetManager: Starting task 45.0 in stage 3.0 (TID 161, 10.1.2.152, partition 45, PROCESS_LOCAL, 5561 bytes)
17/01/29 04:48:48,163 INFO CoarseGrainedSchedulerBackend$DriverEndpoint: Launching task 161 on executor id: 1 hostname: 10.1.2.152.
17/01/29 04:48:48,164 INFO TaskSetManager: Finished task 38.0 in stage 3.0 (TID 151) in 145 ms on 10.1.2.152 (35/59)
17/01/29 04:48:48,179 INFO TaskSetManager: Starting task 46.0 in stage 3.0 (TID 162, 10.1.2.152, partition 46, PROCESS_LOCAL, 5561 bytes)
17/01/29 04:48:48,179 INFO CoarseGrainedSchedulerBackend$DriverEndpoint: Launching task 162 on executor id: 1 hostname: 10.1.2.152.
17/01/29 04:48:48,179 INFO TaskSetManager: Finished task 44.0 in stage 3.0 (TID 155) in 115 ms on 10.1.2.152 (36/59)
17/01/29 04:48:48,184 INFO TaskSetManager: Starting task 47.0 in stage 3.0 (TID 163, 10.1.2.152, partition 47, PROCESS_LOCAL, 5561 bytes)
17/01/29 04:48:48,184 INFO CoarseGrainedSchedulerBackend$DriverEndpoint: Launching task 163 on executor id: 1 hostname: 10.1.2.152.
17/01/29 04:48:48,185 INFO TaskSetManager: Finished task 39.0 in stage 3.0 (TID 154) in 129 ms on 10.1.2.152 (37/59)
17/01/29 04:48:48,187 INFO TaskSetManager: Starting task 41.0 in stage 3.0 (TID 164, 10.1.2.60, partition 41, PROCESS_LOCAL, 5561 bytes)
17/01/29 04:48:48,187 INFO CoarseGrainedSchedulerBackend$DriverEndpoint: Launching task 164 on executor id: 0 hostname: 10.1.2.60.
17/01/29 04:48:48,187 INFO TaskSetManager: Finished task 32.0 in stage 3.0 (TID 156) in 111 ms on 10.1.2.60 (38/59)
17/01/29 04:48:48,193 INFO TaskSetManager: Starting task 42.0 in stage 3.0 (TID 165, 10.1.2.60, partition 42, PROCESS_LOCAL, 5561 bytes)
17/01/29 04:48:48,193 INFO CoarseGrainedSchedulerBackend$DriverEndpoint: Launching task 165 on executor id: 0 hostname: 10.1.2.60.
17/01/29 04:48:48,194 INFO TaskSetManager: Finished task 35.0 in stage 3.0 (TID 159) in 86 ms on 10.1.2.60 (39/59)
17/01/29 04:48:48,195 INFO TaskSetManager: Starting task 51.0 in stage 3.0 (TID 166, 10.1.2.152, partition 51, PROCESS_LOCAL, 5561 bytes)
17/01/29 04:48:48,195 INFO CoarseGrainedSchedulerBackend$DriverEndpoint: Launching task 166 on executor id: 1 hostname: 10.1.2.152.
17/01/29 04:48:48,195 INFO TaskSetManager: Finished task 37.0 in stage 3.0 (TID 150) in 178 ms on 10.1.2.152 (40/59)
17/01/29 04:48:48,225 INFO TaskSetManager: Starting task 43.0 in stage 3.0 (TID 167, 10.1.2.60, partition 43, PROCESS_LOCAL, 5561 bytes)
17/01/29 04:48:48,225 INFO CoarseGrainedSchedulerBackend$DriverEndpoint: Launching task 167 on executor id: 0 hostname: 10.1.2.60.
17/01/29 04:48:48,226 INFO TaskSetManager: Finished task 34.0 in stage 3.0 (TID 158) in 125 ms on 10.1.2.60 (41/59)
17/01/29 04:48:48,236 INFO TaskSetManager: Starting task 52.0 in stage 3.0 (TID 168, 10.1.2.152, partition 52, PROCESS_LOCAL, 5561 bytes)
17/01/29 04:48:48,236 INFO CoarseGrainedSchedulerBackend$DriverEndpoint: Launching task 168 on executor id: 1 hostname: 10.1.2.152.
17/01/29 04:48:48,236 INFO TaskSetManager: Finished task 45.0 in stage 3.0 (TID 161) in 73 ms on 10.1.2.152 (42/59)
17/01/29 04:48:48,244 INFO TaskSetManager: Starting task 48.0 in stage 3.0 (TID 169, 10.1.2.60, partition 48, PROCESS_LOCAL, 5561 bytes)
17/01/29 04:48:48,244 INFO CoarseGrainedSchedulerBackend$DriverEndpoint: Launching task 169 on executor id: 0 hostname: 10.1.2.60.
17/01/29 04:48:48,245 INFO TaskSetManager: Finished task 41.0 in stage 3.0 (TID 164) in 59 ms on 10.1.2.60 (43/59)
17/01/29 04:48:48,278 INFO TaskSetManager: Starting task 54.0 in stage 3.0 (TID 170, 10.1.2.152, partition 54, PROCESS_LOCAL, 5561 bytes)
17/01/29 04:48:48,278 INFO CoarseGrainedSchedulerBackend$DriverEndpoint: Launching task 170 on executor id: 1 hostname: 10.1.2.152.
17/01/29 04:48:48,278 INFO TaskSetManager: Finished task 46.0 in stage 3.0 (TID 162) in 100 ms on 10.1.2.152 (44/59)
17/01/29 04:48:48,283 INFO TaskSetManager: Starting task 49.0 in stage 3.0 (TID 171, 10.1.2.60, partition 49, PROCESS_LOCAL, 5561 bytes)
17/01/29 04:48:48,283 INFO CoarseGrainedSchedulerBackend$DriverEndpoint: Launching task 171 on executor id: 0 hostname: 10.1.2.60.
17/01/29 04:48:48,284 INFO TaskSetManager: Finished task 40.0 in stage 3.0 (TID 160) in 125 ms on 10.1.2.60 (45/59)
17/01/29 04:48:48,287 INFO TaskSetManager: Starting task 50.0 in stage 3.0 (TID 172, 10.1.2.60, partition 50, PROCESS_LOCAL, 5561 bytes)
17/01/29 04:48:48,287 INFO CoarseGrainedSchedulerBackend$DriverEndpoint: Launching task 172 on executor id: 0 hostname: 10.1.2.60.
17/01/29 04:48:48,287 INFO TaskSetManager: Finished task 43.0 in stage 3.0 (TID 167) in 62 ms on 10.1.2.60 (46/59)
17/01/29 04:48:48,298 INFO TaskSetManager: Starting task 55.0 in stage 3.0 (TID 173, 10.1.2.152, partition 55, PROCESS_LOCAL, 5561 bytes)
17/01/29 04:48:48,298 INFO CoarseGrainedSchedulerBackend$DriverEndpoint: Launching task 173 on executor id: 1 hostname: 10.1.2.152.
17/01/29 04:48:48,298 INFO TaskSetManager: Finished task 51.0 in stage 3.0 (TID 166) in 104 ms on 10.1.2.152 (47/59)
17/01/29 04:48:48,300 INFO TaskSetManager: Finished task 47.0 in stage 3.0 (TID 163) in 116 ms on 10.1.2.152 (48/59)
17/01/29 04:48:48,312 INFO TaskSetManager: Starting task 53.0 in stage 3.0 (TID 174, 10.1.2.60, partition 53, PROCESS_LOCAL, 5561 bytes)
17/01/29 04:48:48,312 INFO CoarseGrainedSchedulerBackend$DriverEndpoint: Launching task 174 on executor id: 0 hostname: 10.1.2.60.
17/01/29 04:48:48,313 INFO TaskSetManager: Finished task 42.0 in stage 3.0 (TID 165) in 121 ms on 10.1.2.60 (49/59)
17/01/29 04:48:48,328 INFO TaskSetManager: Finished task 52.0 in stage 3.0 (TID 168) in 93 ms on 10.1.2.152 (50/59)
17/01/29 04:48:48,342 INFO TaskSetManager: Starting task 56.0 in stage 3.0 (TID 175, 10.1.2.60, partition 56, PROCESS_LOCAL, 5561 bytes)
17/01/29 04:48:48,342 INFO CoarseGrainedSchedulerBackend$DriverEndpoint: Launching task 175 on executor id: 0 hostname: 10.1.2.60.
17/01/29 04:48:48,343 INFO TaskSetManager: Finished task 48.0 in stage 3.0 (TID 169) in 98 ms on 10.1.2.60 (51/59)
17/01/29 04:48:48,344 INFO TaskSetManager: Finished task 54.0 in stage 3.0 (TID 170) in 67 ms on 10.1.2.152 (52/59)
17/01/29 04:48:48,356 INFO TaskSetManager: Starting task 58.0 in stage 3.0 (TID 176, 10.1.2.60, partition 58, PROCESS_LOCAL, 5561 bytes)
17/01/29 04:48:48,356 INFO CoarseGrainedSchedulerBackend$DriverEndpoint: Launching task 176 on executor id: 0 hostname: 10.1.2.60.
17/01/29 04:48:48,356 INFO TaskSetManager: Finished task 49.0 in stage 3.0 (TID 171) in 74 ms on 10.1.2.60 (53/59)
17/01/29 04:48:48,362 INFO TaskSetManager: Finished task 50.0 in stage 3.0 (TID 172) in 75 ms on 10.1.2.60 (54/59)
17/01/29 04:48:48,364 INFO TaskSetManager: Finished task 55.0 in stage 3.0 (TID 173) in 67 ms on 10.1.2.152 (55/59)
17/01/29 04:48:48,380 INFO TaskSetManager: Finished task 53.0 in stage 3.0 (TID 174) in 68 ms on 10.1.2.60 (56/59)
17/01/29 04:48:48,401 INFO TaskSetManager: Finished task 56.0 in stage 3.0 (TID 175) in 58 ms on 10.1.2.60 (57/59)
17/01/29 04:48:48,413 INFO TaskSetManager: Finished task 58.0 in stage 3.0 (TID 176) in 58 ms on 10.1.2.60 (58/59)
17/01/29 04:48:52,297 INFO TaskSetManager: Starting task 57.0 in stage 3.0 (TID 177, 10.1.2.152, partition 57, ANY, 5561 bytes)
17/01/29 04:48:52,297 INFO CoarseGrainedSchedulerBackend$DriverEndpoint: Launching task 177 on executor id: 1 hostname: 10.1.2.152.
17/01/29 04:48:57,933 INFO TaskSetManager: Finished task 57.0 in stage 3.0 (TID 177) in 5637 ms on 10.1.2.152 (59/59)
17/01/29 04:48:57,933 INFO TaskSchedulerImpl: Removed TaskSet 3.0, whose tasks have all completed, from pool 
17/01/29 04:48:57,934 INFO DAGScheduler: ShuffleMapStage 3 (treeAggregate at GradientDescent.scala:239) finished in 10.693 s
17/01/29 04:48:57,935 INFO DAGScheduler: looking for newly runnable stages
17/01/29 04:48:57,936 INFO DAGScheduler: running: Set()
17/01/29 04:48:57,936 INFO DAGScheduler: waiting: Set(ResultStage 4)
17/01/29 04:48:57,937 INFO DAGScheduler: failed: Set()
17/01/29 04:48:57,939 INFO DAGScheduler: Submitting ResultStage 4 (MapPartitionsRDD[13] at treeAggregate at GradientDescent.scala:239), which has no missing parents
17/01/29 04:48:57,945 INFO MemoryStore: Block broadcast_6 stored as values in memory (estimated size 3.1 KB, free 2.1 GB)
17/01/29 04:48:57,946 INFO MemoryStore: Block broadcast_6_piece0 stored as bytes in memory (estimated size 1893.0 B, free 2.1 GB)
17/01/29 04:48:57,947 INFO BlockManagerInfo: Added broadcast_6_piece0 in memory on 10.1.2.31:38380 (size: 1893.0 B, free: 2.1 GB)
17/01/29 04:48:57,948 INFO SparkContext: Created broadcast 6 from broadcast at DAGScheduler.scala:1012
17/01/29 04:48:57,949 INFO DAGScheduler: Submitting 7 missing tasks from ResultStage 4 (MapPartitionsRDD[13] at treeAggregate at GradientDescent.scala:239)
17/01/29 04:48:57,949 INFO TaskSchedulerImpl: Adding task set 4.0 with 7 tasks
17/01/29 04:48:57,951 INFO TaskSetManager: Starting task 0.0 in stage 4.0 (TID 178, 10.1.2.60, partition 0, NODE_LOCAL, 5227 bytes)
17/01/29 04:48:57,952 INFO TaskSetManager: Starting task 1.0 in stage 4.0 (TID 179, 10.1.2.152, partition 1, NODE_LOCAL, 5227 bytes)
17/01/29 04:48:57,952 INFO TaskSetManager: Starting task 2.0 in stage 4.0 (TID 180, 10.1.2.60, partition 2, NODE_LOCAL, 5227 bytes)
17/01/29 04:48:57,953 INFO TaskSetManager: Starting task 3.0 in stage 4.0 (TID 181, 10.1.2.152, partition 3, NODE_LOCAL, 5227 bytes)
17/01/29 04:48:57,953 INFO TaskSetManager: Starting task 4.0 in stage 4.0 (TID 182, 10.1.2.60, partition 4, NODE_LOCAL, 5227 bytes)
17/01/29 04:48:57,953 INFO TaskSetManager: Starting task 5.0 in stage 4.0 (TID 183, 10.1.2.152, partition 5, NODE_LOCAL, 5227 bytes)
17/01/29 04:48:57,954 INFO TaskSetManager: Starting task 6.0 in stage 4.0 (TID 184, 10.1.2.60, partition 6, NODE_LOCAL, 5227 bytes)
17/01/29 04:48:57,954 INFO CoarseGrainedSchedulerBackend$DriverEndpoint: Launching task 178 on executor id: 0 hostname: 10.1.2.60.
17/01/29 04:48:57,954 INFO CoarseGrainedSchedulerBackend$DriverEndpoint: Launching task 180 on executor id: 0 hostname: 10.1.2.60.
17/01/29 04:48:57,955 INFO CoarseGrainedSchedulerBackend$DriverEndpoint: Launching task 182 on executor id: 0 hostname: 10.1.2.60.
17/01/29 04:48:57,955 INFO CoarseGrainedSchedulerBackend$DriverEndpoint: Launching task 184 on executor id: 0 hostname: 10.1.2.60.
17/01/29 04:48:57,955 INFO CoarseGrainedSchedulerBackend$DriverEndpoint: Launching task 179 on executor id: 1 hostname: 10.1.2.152.
17/01/29 04:48:57,955 INFO CoarseGrainedSchedulerBackend$DriverEndpoint: Launching task 181 on executor id: 1 hostname: 10.1.2.152.
17/01/29 04:48:57,956 INFO CoarseGrainedSchedulerBackend$DriverEndpoint: Launching task 183 on executor id: 1 hostname: 10.1.2.152.
17/01/29 04:48:57,970 INFO BlockManagerInfo: Added broadcast_6_piece0 in memory on 10.1.2.152:33704 (size: 1893.0 B, free: 92.2 MB)
17/01/29 04:48:57,974 INFO BlockManagerInfo: Added broadcast_6_piece0 in memory on 10.1.2.60:37320 (size: 1893.0 B, free: 90.0 MB)
17/01/29 04:48:57,987 INFO MapOutputTrackerMasterEndpoint: Asked to send map output locations for shuffle 0 to 10.1.2.152:35420
17/01/29 04:48:57,991 INFO MapOutputTrackerMaster: Size of output statuses for shuffle 0 is 278 bytes
17/01/29 04:48:57,991 INFO MapOutputTrackerMasterEndpoint: Asked to send map output locations for shuffle 0 to 10.1.2.60:54172
17/01/29 04:48:58,073 INFO TaskSetManager: Finished task 5.0 in stage 4.0 (TID 183) in 120 ms on 10.1.2.152 (1/7)
17/01/29 04:48:58,074 INFO TaskSetManager: Finished task 3.0 in stage 4.0 (TID 181) in 122 ms on 10.1.2.152 (2/7)
17/01/29 04:48:58,075 INFO TaskSetManager: Finished task 1.0 in stage 4.0 (TID 179) in 124 ms on 10.1.2.152 (3/7)
17/01/29 04:48:58,081 INFO TaskSetManager: Finished task 2.0 in stage 4.0 (TID 180) in 129 ms on 10.1.2.60 (4/7)
17/01/29 04:48:58,081 INFO TaskSetManager: Finished task 4.0 in stage 4.0 (TID 182) in 128 ms on 10.1.2.60 (5/7)
17/01/29 04:48:58,083 INFO TaskSetManager: Finished task 0.0 in stage 4.0 (TID 178) in 133 ms on 10.1.2.60 (6/7)
17/01/29 04:48:58,084 INFO TaskSetManager: Finished task 6.0 in stage 4.0 (TID 184) in 130 ms on 10.1.2.60 (7/7)
17/01/29 04:48:58,084 INFO TaskSchedulerImpl: Removed TaskSet 4.0, whose tasks have all completed, from pool 
17/01/29 04:48:58,085 INFO DAGScheduler: ResultStage 4 (treeAggregate at GradientDescent.scala:239) finished in 0.135 s
17/01/29 04:48:58,085 INFO DAGScheduler: Job 3 finished: treeAggregate at GradientDescent.scala:239, took 10.880881 s
17/01/29 04:48:58,088 INFO MemoryStore: Block broadcast_7 stored as values in memory (estimated size 280.0 B, free 2.1 GB)
17/01/29 04:48:58,091 INFO MemoryStore: Block broadcast_7_piece0 stored as bytes in memory (estimated size 365.0 B, free 2.1 GB)
17/01/29 04:48:58,092 INFO BlockManagerInfo: Added broadcast_7_piece0 in memory on 10.1.2.31:38380 (size: 365.0 B, free: 2.1 GB)
17/01/29 04:48:58,093 INFO SparkContext: Created broadcast 7 from broadcast at GradientDescent.scala:235
17/01/29 04:48:58,111 INFO SparkContext: Starting job: treeAggregate at GradientDescent.scala:239
17/01/29 04:48:58,112 INFO DAGScheduler: Registering RDD 16 (treeAggregate at GradientDescent.scala:239)
17/01/29 04:48:58,113 INFO DAGScheduler: Got job 4 (treeAggregate at GradientDescent.scala:239) with 7 output partitions
17/01/29 04:48:58,113 INFO DAGScheduler: Final stage: ResultStage 6 (treeAggregate at GradientDescent.scala:239)
17/01/29 04:48:58,113 INFO DAGScheduler: Parents of final stage: List(ShuffleMapStage 5)
17/01/29 04:48:58,113 INFO DAGScheduler: Missing parents: List(ShuffleMapStage 5)
17/01/29 04:48:58,116 INFO DAGScheduler: Submitting ShuffleMapStage 5 (MapPartitionsRDD[16] at treeAggregate at GradientDescent.scala:239), which has no missing parents
17/01/29 04:48:58,124 INFO MemoryStore: Block broadcast_8 stored as values in memory (estimated size 7.2 KB, free 2.1 GB)
17/01/29 04:48:58,128 INFO MemoryStore: Block broadcast_8_piece0 stored as bytes in memory (estimated size 3.7 KB, free 2.1 GB)
17/01/29 04:48:58,129 INFO BlockManagerInfo: Added broadcast_8_piece0 in memory on 10.1.2.31:38380 (size: 3.7 KB, free: 2.1 GB)
17/01/29 04:48:58,130 INFO SparkContext: Created broadcast 8 from broadcast at DAGScheduler.scala:1012
17/01/29 04:48:58,130 INFO DAGScheduler: Submitting 59 missing tasks from ShuffleMapStage 5 (MapPartitionsRDD[16] at treeAggregate at GradientDescent.scala:239)
17/01/29 04:48:58,131 INFO TaskSchedulerImpl: Adding task set 5.0 with 59 tasks
17/01/29 04:48:58,133 INFO TaskSetManager: Starting task 0.0 in stage 5.0 (TID 185, 10.1.2.152, partition 0, PROCESS_LOCAL, 5561 bytes)
17/01/29 04:48:58,133 INFO TaskSetManager: Starting task 2.0 in stage 5.0 (TID 186, 10.1.2.60, partition 2, PROCESS_LOCAL, 5561 bytes)
17/01/29 04:48:58,134 INFO TaskSetManager: Starting task 1.0 in stage 5.0 (TID 187, 10.1.2.152, partition 1, PROCESS_LOCAL, 5561 bytes)
17/01/29 04:48:58,134 INFO TaskSetManager: Starting task 4.0 in stage 5.0 (TID 188, 10.1.2.60, partition 4, PROCESS_LOCAL, 5561 bytes)
17/01/29 04:48:58,135 INFO TaskSetManager: Starting task 3.0 in stage 5.0 (TID 189, 10.1.2.152, partition 3, PROCESS_LOCAL, 5561 bytes)
17/01/29 04:48:58,135 INFO TaskSetManager: Starting task 6.0 in stage 5.0 (TID 190, 10.1.2.60, partition 6, PROCESS_LOCAL, 5561 bytes)
17/01/29 04:48:58,136 INFO TaskSetManager: Starting task 5.0 in stage 5.0 (TID 191, 10.1.2.152, partition 5, PROCESS_LOCAL, 5561 bytes)
