Using properties file: /home/ubuntu/spark-2.0.0/conf/spark-defaults.conf
Adding default property: spark.driver.extraJavaOptions=-XX:+PrintGCDetails -XX:+PrintGCTimeStamps -Xms4000m -Dlog4j.configuration=file:///home/ubuntu/spark-2.0.0/conf/log4j.properties
Adding default property: spark.executor.extraJavaOptions=-XX:+PrintGCDetails -XX:+PrintGCTimeStamps -Xms4000m -Dlog4j.configuration=file:///home/ubuntu/spark-2.0.0/conf/log4j.properties
Parsed arguments:
  master                  spark://euca-10-1-2-31:7077
  deployMode              client
  executorMemory          4000m
  executorCores           null
  totalExecutorCores      null
  propertiesFile          /home/ubuntu/spark-2.0.0/conf/spark-defaults.conf
  driverMemory            4000m
  driverCores             null
  driverExtraClassPath    null
  driverExtraLibraryPath  null
  driverExtraJavaOptions  -XX:+PrintGCDetails -XX:+PrintGCTimeStamps -Xms4000m -Dlog4j.configuration=file:///home/ubuntu/spark-2.0.0/conf/log4j.properties
  supervise               false
  queue                   null
  numExecutors            2
  files                   null
  pyFiles                 null
  archives                null
  mainClass               LogRegExplicitParallelism
  primaryResource         file:///home/ubuntu/jars/log-reg-explicit-parallelism_2.11-1.0.jar
  name                    LogRegExplicitParallelism
  childArgs               [cluster 28 euca-10-1-2-31 9000 higgs_0_exp 5 8]
  jars                    null
  packages                null
  packagesExclusions      null
  repositories            null
  verbose                 true

Spark properties used, including those specified through
 --conf and those from the properties file /home/ubuntu/spark-2.0.0/conf/spark-defaults.conf:
  spark.default.parallelism -> 8
  spark.driver.memory -> 4000m
  spark.executor.extraJavaOptions -> -XX:+PrintGCDetails -XX:+PrintGCTimeStamps -Xms4000m -Dlog4j.configuration=file:///home/ubuntu/spark-2.0.0/conf/log4j.properties
  spark.driver.extraJavaOptions -> -XX:+PrintGCDetails -XX:+PrintGCTimeStamps -Xms4000m -Dlog4j.configuration=file:///home/ubuntu/spark-2.0.0/conf/log4j.properties
  spark.shuffle.spill -> false

    
Main class:
LogRegExplicitParallelism
Arguments:
cluster
28
euca-10-1-2-31
9000
higgs_0_exp
5
8
System properties:
spark.default.parallelism -> 8
spark.executor.memory -> 4000m
spark.driver.memory -> 4000m
SPARK_SUBMIT -> true
spark.executor.extraJavaOptions -> -XX:+PrintGCDetails -XX:+PrintGCTimeStamps -Xms4000m -Dlog4j.configuration=file:///home/ubuntu/spark-2.0.0/conf/log4j.properties
spark.app.name -> LogRegExplicitParallelism
spark.shuffle.spill -> false
spark.driver.extraJavaOptions -> -XX:+PrintGCDetails -XX:+PrintGCTimeStamps -Xms4000m -Dlog4j.configuration=file:///home/ubuntu/spark-2.0.0/conf/log4j.properties
spark.jars -> file:///home/ubuntu/jars/log-reg-explicit-parallelism_2.11-1.0.jar
spark.submit.deployMode -> client
spark.master -> spark://euca-10-1-2-31:7077
Classpath elements:
file:///home/ubuntu/jars/log-reg-explicit-parallelism_2.11-1.0.jar


17/01/29 05:03:21,729 INFO SparkContext: Running Spark version 2.0.0
17/01/29 05:03:22,072 WARN NativeCodeLoader: Unable to load native-hadoop library for your platform... using builtin-java classes where applicable
17/01/29 05:03:22,233 INFO SecurityManager: Changing view acls to: ubuntu
17/01/29 05:03:22,234 INFO SecurityManager: Changing modify acls to: ubuntu
17/01/29 05:03:22,235 INFO SecurityManager: Changing view acls groups to: 
17/01/29 05:03:22,235 INFO SecurityManager: Changing modify acls groups to: 
17/01/29 05:03:22,236 INFO SecurityManager: SecurityManager: authentication disabled; ui acls disabled; users  with view permissions: Set(ubuntu); groups with view permissions: Set(); users  with modify permissions: Set(ubuntu); groups with modify permissions: Set()
17/01/29 05:03:22,544 INFO Utils: Successfully started service 'sparkDriver' on port 38918.
17/01/29 05:03:22,562 INFO SparkEnv: Registering MapOutputTracker
17/01/29 05:03:22,568 WARN SortShuffleManager: spark.shuffle.spill was set to false, but this configuration is ignored as of Spark 1.6+. Shuffle will continue to spill to disk when necessary.
17/01/29 05:03:22,579 INFO SparkEnv: Registering BlockManagerMaster
17/01/29 05:03:22,591 INFO DiskBlockManager: Created local directory at /tmp/blockmgr-c1567e4a-2759-487c-bb09-083430b6f2d8
17/01/29 05:03:22,609 INFO MemoryStore: MemoryStore started with capacity 2.1 GB
17/01/29 05:03:22,663 INFO SparkEnv: Registering OutputCommitCoordinator
17/01/29 05:03:22,867 INFO Utils: Successfully started service 'SparkUI' on port 4040.
17/01/29 05:03:22,869 INFO SparkUI: Bound SparkUI to 10.1.2.31, and started at http://10.1.2.31:4040
17/01/29 05:03:22,904 INFO SparkContext: Added JAR file:///home/ubuntu/jars/log-reg-explicit-parallelism_2.11-1.0.jar at spark://10.1.2.31:38918/jars/log-reg-explicit-parallelism_2.11-1.0.jar with timestamp 1485666202903
17/01/29 05:03:22,982 INFO StandaloneAppClient$ClientEndpoint: Connecting to master spark://euca-10-1-2-31:7077...
17/01/29 05:03:23,041 INFO TransportClientFactory: Successfully created connection to euca-10-1-2-31/10.1.2.31:7077 after 23 ms (0 ms spent in bootstraps)
17/01/29 05:03:23,139 INFO StandaloneSchedulerBackend: Connected to Spark cluster with app ID app-20170129050323-0000
17/01/29 05:03:23,145 INFO Utils: Successfully started service 'org.apache.spark.network.netty.NettyBlockTransferService' on port 45152.
17/01/29 05:03:23,145 INFO NettyBlockTransferService: Server created on 10.1.2.31:45152
17/01/29 05:03:23,147 INFO BlockManagerMaster: Registering BlockManager BlockManagerId(driver, 10.1.2.31, 45152)
17/01/29 05:03:23,149 INFO BlockManagerMasterEndpoint: Registering block manager 10.1.2.31:45152 with 2.1 GB RAM, BlockManagerId(driver, 10.1.2.31, 45152)
17/01/29 05:03:23,151 INFO BlockManagerMaster: Registered BlockManager BlockManagerId(driver, 10.1.2.31, 45152)
17/01/29 05:03:23,166 INFO StandaloneAppClient$ClientEndpoint: Executor added: app-20170129050323-0000/0 on worker-20170129050312-10.1.2.152-43547 (10.1.2.152:43547) with 4 cores
17/01/29 05:03:23,167 INFO StandaloneSchedulerBackend: Granted executor ID app-20170129050323-0000/0 on hostPort 10.1.2.152:43547 with 4 cores, 3.9 GB RAM
17/01/29 05:03:23,177 INFO StandaloneAppClient$ClientEndpoint: Executor added: app-20170129050323-0000/1 on worker-20170129050312-10.1.2.60-35170 (10.1.2.60:35170) with 4 cores
17/01/29 05:03:23,178 INFO StandaloneSchedulerBackend: Granted executor ID app-20170129050323-0000/1 on hostPort 10.1.2.60:35170 with 4 cores, 3.9 GB RAM
17/01/29 05:03:23,231 INFO StandaloneAppClient$ClientEndpoint: Executor updated: app-20170129050323-0000/0 is now RUNNING
17/01/29 05:03:23,232 INFO StandaloneAppClient$ClientEndpoint: Executor updated: app-20170129050323-0000/1 is now RUNNING
17/01/29 05:03:23,330 INFO StandaloneSchedulerBackend: SchedulerBackend is ready for scheduling beginning after reached minRegisteredResourcesRatio: 0.0
17/01/29 05:03:23,715 INFO MemoryStore: Block broadcast_0 stored as values in memory (estimated size 130.8 KB, free 2.1 GB)
17/01/29 05:03:23,794 INFO MemoryStore: Block broadcast_0_piece0 stored as bytes in memory (estimated size 16.5 KB, free 2.1 GB)
17/01/29 05:03:23,796 INFO BlockManagerInfo: Added broadcast_0_piece0 in memory on 10.1.2.31:45152 (size: 16.5 KB, free: 2.1 GB)
17/01/29 05:03:23,806 INFO SparkContext: Created broadcast 0 from textFile at MLUtils.scala:99
17/01/29 05:03:24,468 INFO FileInputFormat: Total input paths to process : 1
17/01/29 05:03:24,512 INFO NetworkTopology: Adding a new node: /default-rack/10.1.2.60:50010
17/01/29 05:03:24,513 INFO NetworkTopology: Adding a new node: /default-rack/10.1.2.152:50010
17/01/29 05:03:24,551 INFO SparkContext: Starting job: first at GeneralizedLinearAlgorithm.scala:246
17/01/29 05:03:24,563 INFO DAGScheduler: Got job 0 (first at GeneralizedLinearAlgorithm.scala:246) with 1 output partitions
17/01/29 05:03:24,564 INFO DAGScheduler: Final stage: ResultStage 0 (first at GeneralizedLinearAlgorithm.scala:246)
17/01/29 05:03:24,564 INFO DAGScheduler: Parents of final stage: List()
17/01/29 05:03:24,570 INFO DAGScheduler: Missing parents: List()
17/01/29 05:03:24,589 INFO DAGScheduler: Submitting ResultStage 0 (MapPartitionsRDD[6] at map at GeneralizedLinearAlgorithm.scala:246), which has no missing parents
17/01/29 05:03:24,614 INFO MemoryStore: Block broadcast_1 stored as values in memory (estimated size 4.2 KB, free 2.1 GB)
17/01/29 05:03:24,616 INFO MemoryStore: Block broadcast_1_piece0 stored as bytes in memory (estimated size 2.4 KB, free 2.1 GB)
17/01/29 05:03:24,617 INFO BlockManagerInfo: Added broadcast_1_piece0 in memory on 10.1.2.31:45152 (size: 2.4 KB, free: 2.1 GB)
17/01/29 05:03:24,619 INFO SparkContext: Created broadcast 1 from broadcast at DAGScheduler.scala:1012
17/01/29 05:03:24,622 INFO DAGScheduler: Submitting 1 missing tasks from ResultStage 0 (MapPartitionsRDD[6] at map at GeneralizedLinearAlgorithm.scala:246)
17/01/29 05:03:24,623 INFO TaskSchedulerImpl: Adding task set 0.0 with 1 tasks
17/01/29 05:03:28,063 INFO CoarseGrainedSchedulerBackend$DriverEndpoint: Registered executor NettyRpcEndpointRef(null) (10.1.2.60:34908) with ID 1
17/01/29 05:03:28,094 INFO TaskSetManager: Starting task 0.0 in stage 0.0 (TID 0, 10.1.2.60, partition 0, ANY, 5454 bytes)
17/01/29 05:03:28,104 INFO CoarseGrainedSchedulerBackend$DriverEndpoint: Launching task 0 on executor id: 1 hostname: 10.1.2.60.
17/01/29 05:03:28,125 INFO BlockManagerMasterEndpoint: Registering block manager 10.1.2.60:34100 with 2.1 GB RAM, BlockManagerId(1, 10.1.2.60, 34100)
17/01/29 05:03:28,152 INFO CoarseGrainedSchedulerBackend$DriverEndpoint: Registered executor NettyRpcEndpointRef(null) (10.1.2.152:43022) with ID 0
17/01/29 05:03:28,199 INFO BlockManagerMasterEndpoint: Registering block manager 10.1.2.152:45056 with 2.1 GB RAM, BlockManagerId(0, 10.1.2.152, 45056)
17/01/29 05:03:28,395 INFO BlockManagerInfo: Added broadcast_1_piece0 in memory on 10.1.2.60:34100 (size: 2.4 KB, free: 2.1 GB)
17/01/29 05:03:28,542 INFO BlockManagerInfo: Added broadcast_0_piece0 in memory on 10.1.2.60:34100 (size: 16.5 KB, free: 2.1 GB)
17/01/29 05:03:35,728 INFO BlockManagerInfo: Added rdd_5_0 in memory on 10.1.2.60:34100 (size: 70.0 MB, free: 2.0 GB)
17/01/29 05:03:35,778 INFO TaskSetManager: Finished task 0.0 in stage 0.0 (TID 0) in 7705 ms on 10.1.2.60 (1/1)
17/01/29 05:03:35,781 INFO TaskSchedulerImpl: Removed TaskSet 0.0, whose tasks have all completed, from pool 
17/01/29 05:03:35,784 INFO DAGScheduler: ResultStage 0 (first at GeneralizedLinearAlgorithm.scala:246) finished in 11.148 s
17/01/29 05:03:35,788 INFO DAGScheduler: Job 0 finished: first at GeneralizedLinearAlgorithm.scala:246, took 11.236840 s
17/01/29 05:03:35,799 INFO SparkContext: Starting job: count at DataValidators.scala:40
17/01/29 05:03:35,801 INFO DAGScheduler: Got job 1 (count at DataValidators.scala:40) with 59 output partitions
17/01/29 05:03:35,801 INFO DAGScheduler: Final stage: ResultStage 1 (count at DataValidators.scala:40)
17/01/29 05:03:35,801 INFO DAGScheduler: Parents of final stage: List()
17/01/29 05:03:35,804 INFO DAGScheduler: Missing parents: List()
17/01/29 05:03:35,804 INFO DAGScheduler: Submitting ResultStage 1 (MapPartitionsRDD[7] at filter at DataValidators.scala:40), which has no missing parents
17/01/29 05:03:35,826 INFO MemoryStore: Block broadcast_2 stored as values in memory (estimated size 3.9 KB, free 2.1 GB)
17/01/29 05:03:35,828 INFO MemoryStore: Block broadcast_2_piece0 stored as bytes in memory (estimated size 2.2 KB, free 2.1 GB)
17/01/29 05:03:35,829 INFO BlockManagerInfo: Added broadcast_2_piece0 in memory on 10.1.2.31:45152 (size: 2.2 KB, free: 2.1 GB)
17/01/29 05:03:35,830 INFO SparkContext: Created broadcast 2 from broadcast at DAGScheduler.scala:1012
17/01/29 05:03:35,831 INFO DAGScheduler: Submitting 59 missing tasks from ResultStage 1 (MapPartitionsRDD[7] at filter at DataValidators.scala:40)
17/01/29 05:03:35,832 INFO TaskSchedulerImpl: Adding task set 1.0 with 59 tasks
17/01/29 05:03:35,837 INFO TaskSetManager: Starting task 0.0 in stage 1.0 (TID 1, 10.1.2.60, partition 0, PROCESS_LOCAL, 5372 bytes)
17/01/29 05:03:35,840 INFO TaskSetManager: Starting task 58.0 in stage 1.0 (TID 2, 10.1.2.60, partition 58, NODE_LOCAL, 5372 bytes)
17/01/29 05:03:35,841 INFO CoarseGrainedSchedulerBackend$DriverEndpoint: Launching task 1 on executor id: 1 hostname: 10.1.2.60.
17/01/29 05:03:35,841 INFO CoarseGrainedSchedulerBackend$DriverEndpoint: Launching task 2 on executor id: 1 hostname: 10.1.2.60.
17/01/29 05:03:35,864 INFO BlockManagerInfo: Added broadcast_2_piece0 in memory on 10.1.2.60:34100 (size: 2.2 KB, free: 2.0 GB)
17/01/29 05:03:35,919 INFO TaskSetManager: Finished task 0.0 in stage 1.0 (TID 1) in 84 ms on 10.1.2.60 (1/59)
17/01/29 05:03:38,973 INFO TaskSetManager: Starting task 1.0 in stage 1.0 (TID 3, 10.1.2.152, partition 1, ANY, 5372 bytes)
17/01/29 05:03:38,976 INFO TaskSetManager: Starting task 2.0 in stage 1.0 (TID 4, 10.1.2.60, partition 2, ANY, 5372 bytes)
17/01/29 05:03:38,980 INFO TaskSetManager: Starting task 3.0 in stage 1.0 (TID 5, 10.1.2.152, partition 3, ANY, 5372 bytes)
17/01/29 05:03:38,982 INFO TaskSetManager: Starting task 4.0 in stage 1.0 (TID 6, 10.1.2.60, partition 4, ANY, 5372 bytes)
17/01/29 05:03:38,985 INFO TaskSetManager: Starting task 5.0 in stage 1.0 (TID 7, 10.1.2.152, partition 5, ANY, 5372 bytes)
17/01/29 05:03:38,987 INFO TaskSetManager: Starting task 6.0 in stage 1.0 (TID 8, 10.1.2.60, partition 6, ANY, 5372 bytes)
17/01/29 05:03:38,990 INFO TaskSetManager: Starting task 7.0 in stage 1.0 (TID 9, 10.1.2.152, partition 7, ANY, 5372 bytes)
17/01/29 05:03:38,991 INFO CoarseGrainedSchedulerBackend$DriverEndpoint: Launching task 3 on executor id: 0 hostname: 10.1.2.152.
17/01/29 05:03:38,992 INFO CoarseGrainedSchedulerBackend$DriverEndpoint: Launching task 5 on executor id: 0 hostname: 10.1.2.152.
17/01/29 05:03:38,992 INFO CoarseGrainedSchedulerBackend$DriverEndpoint: Launching task 7 on executor id: 0 hostname: 10.1.2.152.
17/01/29 05:03:38,993 INFO CoarseGrainedSchedulerBackend$DriverEndpoint: Launching task 9 on executor id: 0 hostname: 10.1.2.152.
17/01/29 05:03:38,994 INFO CoarseGrainedSchedulerBackend$DriverEndpoint: Launching task 4 on executor id: 1 hostname: 10.1.2.60.
17/01/29 05:03:38,995 INFO CoarseGrainedSchedulerBackend$DriverEndpoint: Launching task 6 on executor id: 1 hostname: 10.1.2.60.
17/01/29 05:03:38,996 INFO CoarseGrainedSchedulerBackend$DriverEndpoint: Launching task 8 on executor id: 1 hostname: 10.1.2.60.
17/01/29 05:03:39,322 INFO BlockManagerInfo: Added broadcast_2_piece0 in memory on 10.1.2.152:45056 (size: 2.2 KB, free: 2.1 GB)
17/01/29 05:03:39,483 INFO BlockManagerInfo: Added broadcast_0_piece0 in memory on 10.1.2.152:45056 (size: 16.5 KB, free: 2.1 GB)
23.382: [GC [PSYoungGen: 1024512K->140564K(1195008K)] 1024512K->140636K(3926016K), 0.0679530 secs] [Times: user=0.13 sys=0.04, real=0.06 secs] 
17/01/29 05:03:44,601 INFO BlockManagerInfo: Removed broadcast_1_piece0 on 10.1.2.31:45152 in memory (size: 2.4 KB, free: 2.1 GB)
17/01/29 05:03:44,621 INFO BlockManagerInfo: Removed broadcast_1_piece0 on 10.1.2.60:34100 in memory (size: 2.4 KB, free: 2.0 GB)
17/01/29 05:03:49,416 INFO BlockManagerInfo: Added rdd_5_58 in memory on 10.1.2.60:34100 (size: 72.8 MB, free: 1977.6 MB)
17/01/29 05:03:49,446 INFO TaskSetManager: Starting task 8.0 in stage 1.0 (TID 10, 10.1.2.60, partition 8, ANY, 5372 bytes)
17/01/29 05:03:49,447 INFO CoarseGrainedSchedulerBackend$DriverEndpoint: Launching task 10 on executor id: 1 hostname: 10.1.2.60.
17/01/29 05:03:49,448 INFO TaskSetManager: Finished task 58.0 in stage 1.0 (TID 2) in 13610 ms on 10.1.2.60 (2/59)
17/01/29 05:03:57,714 INFO BlockManagerInfo: Added rdd_5_7 in memory on 10.1.2.152:45056 (size: 70.0 MB, free: 2.0 GB)
17/01/29 05:03:57,783 INFO TaskSetManager: Starting task 9.0 in stage 1.0 (TID 11, 10.1.2.152, partition 9, ANY, 5372 bytes)
17/01/29 05:03:57,784 INFO CoarseGrainedSchedulerBackend$DriverEndpoint: Launching task 11 on executor id: 0 hostname: 10.1.2.152.
17/01/29 05:03:57,785 INFO TaskSetManager: Finished task 7.0 in stage 1.0 (TID 9) in 18796 ms on 10.1.2.152 (3/59)
17/01/29 05:03:57,956 INFO BlockManagerInfo: Added rdd_5_3 in memory on 10.1.2.152:45056 (size: 69.9 MB, free: 1980.5 MB)
17/01/29 05:03:57,999 INFO TaskSetManager: Starting task 10.0 in stage 1.0 (TID 12, 10.1.2.152, partition 10, ANY, 5372 bytes)
17/01/29 05:03:58,003 INFO CoarseGrainedSchedulerBackend$DriverEndpoint: Launching task 12 on executor id: 0 hostname: 10.1.2.152.
17/01/29 05:03:58,003 INFO TaskSetManager: Finished task 3.0 in stage 1.0 (TID 5) in 19027 ms on 10.1.2.152 (4/59)
17/01/29 05:03:58,056 INFO BlockManagerInfo: Added rdd_5_1 in memory on 10.1.2.152:45056 (size: 70.0 MB, free: 1910.5 MB)
17/01/29 05:03:58,088 INFO TaskSetManager: Starting task 11.0 in stage 1.0 (TID 13, 10.1.2.152, partition 11, ANY, 5372 bytes)
17/01/29 05:03:58,089 INFO CoarseGrainedSchedulerBackend$DriverEndpoint: Launching task 13 on executor id: 0 hostname: 10.1.2.152.
17/01/29 05:03:58,089 INFO TaskSetManager: Finished task 1.0 in stage 1.0 (TID 3) in 19118 ms on 10.1.2.152 (5/59)
17/01/29 05:03:59,547 INFO BlockManagerInfo: Added rdd_5_5 in memory on 10.1.2.152:45056 (size: 70.0 MB, free: 1840.5 MB)
17/01/29 05:03:59,565 INFO TaskSetManager: Starting task 12.0 in stage 1.0 (TID 14, 10.1.2.152, partition 12, ANY, 5372 bytes)
17/01/29 05:03:59,565 INFO CoarseGrainedSchedulerBackend$DriverEndpoint: Launching task 14 on executor id: 0 hostname: 10.1.2.152.
17/01/29 05:03:59,566 INFO TaskSetManager: Finished task 5.0 in stage 1.0 (TID 7) in 20582 ms on 10.1.2.152 (6/59)
17/01/29 05:04:02,178 INFO BlockManagerInfo: Added rdd_5_4 in memory on 10.1.2.60:34100 (size: 70.0 MB, free: 1907.7 MB)
17/01/29 05:04:02,205 INFO TaskSetManager: Starting task 13.0 in stage 1.0 (TID 15, 10.1.2.60, partition 13, ANY, 5372 bytes)
17/01/29 05:04:02,206 INFO CoarseGrainedSchedulerBackend$DriverEndpoint: Launching task 15 on executor id: 1 hostname: 10.1.2.60.
17/01/29 05:04:02,208 INFO TaskSetManager: Finished task 4.0 in stage 1.0 (TID 6) in 23226 ms on 10.1.2.60 (7/59)
17/01/29 05:04:02,995 INFO BlockManagerInfo: Added rdd_5_2 in memory on 10.1.2.60:34100 (size: 69.9 MB, free: 1837.8 MB)
17/01/29 05:04:03,014 INFO TaskSetManager: Starting task 14.0 in stage 1.0 (TID 16, 10.1.2.60, partition 14, ANY, 5372 bytes)
17/01/29 05:04:03,014 INFO CoarseGrainedSchedulerBackend$DriverEndpoint: Launching task 16 on executor id: 1 hostname: 10.1.2.60.
17/01/29 05:04:03,015 INFO TaskSetManager: Finished task 2.0 in stage 1.0 (TID 4) in 24041 ms on 10.1.2.60 (8/59)
17/01/29 05:04:03,457 INFO BlockManagerInfo: Added rdd_5_6 in memory on 10.1.2.60:34100 (size: 69.9 MB, free: 1767.8 MB)
17/01/29 05:04:03,479 INFO TaskSetManager: Starting task 15.0 in stage 1.0 (TID 17, 10.1.2.60, partition 15, ANY, 5372 bytes)
17/01/29 05:04:03,480 INFO CoarseGrainedSchedulerBackend$DriverEndpoint: Launching task 17 on executor id: 1 hostname: 10.1.2.60.
17/01/29 05:04:03,482 INFO TaskSetManager: Finished task 6.0 in stage 1.0 (TID 8) in 24495 ms on 10.1.2.60 (9/59)
17/01/29 05:04:13,318 INFO BlockManagerInfo: Added rdd_5_8 in memory on 10.1.2.60:34100 (size: 70.0 MB, free: 1697.9 MB)
17/01/29 05:04:13,337 INFO TaskSetManager: Starting task 16.0 in stage 1.0 (TID 18, 10.1.2.60, partition 16, ANY, 5372 bytes)
17/01/29 05:04:13,337 INFO CoarseGrainedSchedulerBackend$DriverEndpoint: Launching task 18 on executor id: 1 hostname: 10.1.2.60.
17/01/29 05:04:13,338 INFO TaskSetManager: Finished task 8.0 in stage 1.0 (TID 10) in 23892 ms on 10.1.2.60 (10/59)
17/01/29 05:04:19,326 INFO BlockManagerInfo: Added rdd_5_9 in memory on 10.1.2.152:45056 (size: 69.9 MB, free: 1770.6 MB)
17/01/29 05:04:19,341 INFO TaskSetManager: Starting task 17.0 in stage 1.0 (TID 19, 10.1.2.152, partition 17, ANY, 5372 bytes)
17/01/29 05:04:19,342 INFO CoarseGrainedSchedulerBackend$DriverEndpoint: Launching task 19 on executor id: 0 hostname: 10.1.2.152.
17/01/29 05:04:19,343 INFO TaskSetManager: Finished task 9.0 in stage 1.0 (TID 11) in 21563 ms on 10.1.2.152 (11/59)
17/01/29 05:04:20,432 INFO BlockManagerInfo: Added rdd_5_10 in memory on 10.1.2.152:45056 (size: 70.0 MB, free: 1700.6 MB)
17/01/29 05:04:20,450 INFO TaskSetManager: Starting task 18.0 in stage 1.0 (TID 20, 10.1.2.152, partition 18, ANY, 5372 bytes)
17/01/29 05:04:20,450 INFO CoarseGrainedSchedulerBackend$DriverEndpoint: Launching task 20 on executor id: 0 hostname: 10.1.2.152.
17/01/29 05:04:20,452 INFO TaskSetManager: Finished task 10.0 in stage 1.0 (TID 12) in 22454 ms on 10.1.2.152 (12/59)
17/01/29 05:04:20,453 INFO BlockManagerInfo: Added rdd_5_11 in memory on 10.1.2.152:45056 (size: 69.9 MB, free: 1630.7 MB)
17/01/29 05:04:20,468 INFO TaskSetManager: Starting task 19.0 in stage 1.0 (TID 21, 10.1.2.152, partition 19, ANY, 5372 bytes)
17/01/29 05:04:20,469 INFO CoarseGrainedSchedulerBackend$DriverEndpoint: Launching task 21 on executor id: 0 hostname: 10.1.2.152.
17/01/29 05:04:20,469 INFO TaskSetManager: Finished task 11.0 in stage 1.0 (TID 13) in 22383 ms on 10.1.2.152 (13/59)
17/01/29 05:04:22,730 INFO BlockManagerInfo: Added rdd_5_12 in memory on 10.1.2.152:45056 (size: 70.0 MB, free: 1560.8 MB)
17/01/29 05:04:22,747 INFO TaskSetManager: Starting task 20.0 in stage 1.0 (TID 22, 10.1.2.152, partition 20, ANY, 5372 bytes)
17/01/29 05:04:22,747 INFO CoarseGrainedSchedulerBackend$DriverEndpoint: Launching task 22 on executor id: 0 hostname: 10.1.2.152.
17/01/29 05:04:22,748 INFO TaskSetManager: Finished task 12.0 in stage 1.0 (TID 14) in 23184 ms on 10.1.2.152 (14/59)
17/01/29 05:04:24,545 INFO BlockManagerInfo: Added rdd_5_15 in memory on 10.1.2.60:34100 (size: 69.9 MB, free: 1627.9 MB)
17/01/29 05:04:24,565 INFO TaskSetManager: Starting task 21.0 in stage 1.0 (TID 23, 10.1.2.60, partition 21, ANY, 5372 bytes)
17/01/29 05:04:24,566 INFO CoarseGrainedSchedulerBackend$DriverEndpoint: Launching task 23 on executor id: 1 hostname: 10.1.2.60.
17/01/29 05:04:24,566 INFO TaskSetManager: Finished task 15.0 in stage 1.0 (TID 17) in 21089 ms on 10.1.2.60 (15/59)
17/01/29 05:04:24,745 INFO BlockManagerInfo: Added rdd_5_13 in memory on 10.1.2.60:34100 (size: 69.9 MB, free: 1558.0 MB)
17/01/29 05:04:24,772 INFO TaskSetManager: Starting task 22.0 in stage 1.0 (TID 24, 10.1.2.60, partition 22, ANY, 5372 bytes)
17/01/29 05:04:24,772 INFO CoarseGrainedSchedulerBackend$DriverEndpoint: Launching task 24 on executor id: 1 hostname: 10.1.2.60.
17/01/29 05:04:24,772 INFO TaskSetManager: Finished task 13.0 in stage 1.0 (TID 15) in 22569 ms on 10.1.2.60 (16/59)
17/01/29 05:04:27,405 INFO BlockManagerInfo: Added rdd_5_14 in memory on 10.1.2.60:34100 (size: 69.9 MB, free: 1488.1 MB)
17/01/29 05:04:27,425 INFO TaskSetManager: Starting task 23.0 in stage 1.0 (TID 25, 10.1.2.60, partition 23, ANY, 5372 bytes)
17/01/29 05:04:27,426 INFO CoarseGrainedSchedulerBackend$DriverEndpoint: Launching task 25 on executor id: 1 hostname: 10.1.2.60.
17/01/29 05:04:27,426 INFO TaskSetManager: Finished task 14.0 in stage 1.0 (TID 16) in 24414 ms on 10.1.2.60 (17/59)
17/01/29 05:04:39,308 INFO BlockManagerInfo: Added rdd_5_17 in memory on 10.1.2.152:45056 (size: 69.9 MB, free: 1490.9 MB)
17/01/29 05:04:39,318 INFO BlockManagerInfo: Added rdd_5_18 in memory on 10.1.2.152:45056 (size: 70.0 MB, free: 1420.9 MB)
17/01/29 05:04:39,330 INFO TaskSetManager: Starting task 24.0 in stage 1.0 (TID 26, 10.1.2.152, partition 24, ANY, 5372 bytes)
17/01/29 05:04:39,331 INFO CoarseGrainedSchedulerBackend$DriverEndpoint: Launching task 26 on executor id: 0 hostname: 10.1.2.152.
17/01/29 05:04:39,331 INFO TaskSetManager: Finished task 17.0 in stage 1.0 (TID 19) in 19992 ms on 10.1.2.152 (18/59)
17/01/29 05:04:39,335 INFO TaskSetManager: Starting task 25.0 in stage 1.0 (TID 27, 10.1.2.152, partition 25, ANY, 5372 bytes)
17/01/29 05:04:39,336 INFO CoarseGrainedSchedulerBackend$DriverEndpoint: Launching task 27 on executor id: 0 hostname: 10.1.2.152.
17/01/29 05:04:39,336 INFO TaskSetManager: Finished task 18.0 in stage 1.0 (TID 20) in 18888 ms on 10.1.2.152 (19/59)
17/01/29 05:04:39,777 INFO BlockManagerInfo: Added rdd_5_16 in memory on 10.1.2.60:34100 (size: 70.0 MB, free: 1418.2 MB)
17/01/29 05:04:39,794 INFO TaskSetManager: Starting task 26.0 in stage 1.0 (TID 28, 10.1.2.60, partition 26, ANY, 5372 bytes)
17/01/29 05:04:39,795 INFO CoarseGrainedSchedulerBackend$DriverEndpoint: Launching task 28 on executor id: 1 hostname: 10.1.2.60.
17/01/29 05:04:39,795 INFO TaskSetManager: Finished task 16.0 in stage 1.0 (TID 18) in 26460 ms on 10.1.2.60 (20/59)
17/01/29 05:04:40,262 INFO BlockManagerInfo: Added rdd_5_19 in memory on 10.1.2.152:45056 (size: 70.0 MB, free: 1350.9 MB)
17/01/29 05:04:40,277 INFO TaskSetManager: Starting task 27.0 in stage 1.0 (TID 29, 10.1.2.152, partition 27, ANY, 5372 bytes)
17/01/29 05:04:40,277 INFO CoarseGrainedSchedulerBackend$DriverEndpoint: Launching task 29 on executor id: 0 hostname: 10.1.2.152.
17/01/29 05:04:40,278 INFO TaskSetManager: Finished task 19.0 in stage 1.0 (TID 21) in 19811 ms on 10.1.2.152 (21/59)
17/01/29 05:04:42,498 INFO BlockManagerInfo: Added rdd_5_20 in memory on 10.1.2.152:45056 (size: 69.8 MB, free: 1281.1 MB)
17/01/29 05:04:42,515 INFO TaskSetManager: Finished task 20.0 in stage 1.0 (TID 22) in 19770 ms on 10.1.2.152 (22/59)
17/01/29 05:04:42,518 INFO TaskSetManager: Starting task 28.0 in stage 1.0 (TID 30, 10.1.2.152, partition 28, ANY, 5372 bytes)
17/01/29 05:04:42,518 INFO CoarseGrainedSchedulerBackend$DriverEndpoint: Launching task 30 on executor id: 0 hostname: 10.1.2.152.
17/01/29 05:04:45,122 INFO BlockManagerInfo: Added rdd_5_22 in memory on 10.1.2.60:34100 (size: 69.8 MB, free: 1348.3 MB)
17/01/29 05:04:45,144 INFO TaskSetManager: Starting task 29.0 in stage 1.0 (TID 31, 10.1.2.60, partition 29, ANY, 5372 bytes)
17/01/29 05:04:45,144 INFO CoarseGrainedSchedulerBackend$DriverEndpoint: Launching task 31 on executor id: 1 hostname: 10.1.2.60.
17/01/29 05:04:45,144 INFO TaskSetManager: Finished task 22.0 in stage 1.0 (TID 24) in 20374 ms on 10.1.2.60 (23/59)
17/01/29 05:04:45,594 INFO BlockManagerInfo: Added rdd_5_21 in memory on 10.1.2.60:34100 (size: 69.9 MB, free: 1278.4 MB)
17/01/29 05:04:45,613 INFO TaskSetManager: Starting task 30.0 in stage 1.0 (TID 32, 10.1.2.60, partition 30, ANY, 5372 bytes)
17/01/29 05:04:45,614 INFO CoarseGrainedSchedulerBackend$DriverEndpoint: Launching task 32 on executor id: 1 hostname: 10.1.2.60.
17/01/29 05:04:45,614 INFO TaskSetManager: Finished task 21.0 in stage 1.0 (TID 23) in 21050 ms on 10.1.2.60 (24/59)
17/01/29 05:04:49,988 INFO BlockManagerInfo: Added rdd_5_23 in memory on 10.1.2.60:34100 (size: 69.9 MB, free: 1208.5 MB)
17/01/29 05:04:50,006 INFO TaskSetManager: Starting task 31.0 in stage 1.0 (TID 33, 10.1.2.60, partition 31, ANY, 5372 bytes)
17/01/29 05:04:50,006 INFO CoarseGrainedSchedulerBackend$DriverEndpoint: Launching task 33 on executor id: 1 hostname: 10.1.2.60.
17/01/29 05:04:50,007 INFO TaskSetManager: Finished task 23.0 in stage 1.0 (TID 25) in 22583 ms on 10.1.2.60 (25/59)
17/01/29 05:04:57,035 INFO BlockManagerInfo: Added rdd_5_25 in memory on 10.1.2.152:45056 (size: 70.0 MB, free: 1211.1 MB)
17/01/29 05:04:57,052 INFO TaskSetManager: Starting task 32.0 in stage 1.0 (TID 34, 10.1.2.152, partition 32, ANY, 5372 bytes)
17/01/29 05:04:57,052 INFO CoarseGrainedSchedulerBackend$DriverEndpoint: Launching task 34 on executor id: 0 hostname: 10.1.2.152.
17/01/29 05:04:57,052 INFO TaskSetManager: Finished task 25.0 in stage 1.0 (TID 27) in 17718 ms on 10.1.2.152 (26/59)
17/01/29 05:04:57,243 INFO BlockManagerInfo: Added rdd_5_24 in memory on 10.1.2.152:45056 (size: 69.8 MB, free: 1141.4 MB)
17/01/29 05:04:57,261 INFO TaskSetManager: Starting task 33.0 in stage 1.0 (TID 35, 10.1.2.152, partition 33, ANY, 5372 bytes)
17/01/29 05:04:57,261 INFO CoarseGrainedSchedulerBackend$DriverEndpoint: Launching task 35 on executor id: 0 hostname: 10.1.2.152.
17/01/29 05:04:57,262 INFO TaskSetManager: Finished task 24.0 in stage 1.0 (TID 26) in 17933 ms on 10.1.2.152 (27/59)
17/01/29 05:04:58,437 INFO BlockManagerInfo: Added rdd_5_27 in memory on 10.1.2.152:45056 (size: 69.9 MB, free: 1071.5 MB)
17/01/29 05:04:58,464 INFO TaskSetManager: Starting task 34.0 in stage 1.0 (TID 36, 10.1.2.152, partition 34, ANY, 5372 bytes)
17/01/29 05:04:58,465 INFO CoarseGrainedSchedulerBackend$DriverEndpoint: Launching task 36 on executor id: 0 hostname: 10.1.2.152.
17/01/29 05:04:58,465 INFO TaskSetManager: Finished task 27.0 in stage 1.0 (TID 29) in 18189 ms on 10.1.2.152 (28/59)
17/01/29 05:04:59,814 INFO BlockManagerInfo: Added rdd_5_26 in memory on 10.1.2.60:34100 (size: 69.9 MB, free: 1138.6 MB)
17/01/29 05:04:59,840 INFO TaskSetManager: Starting task 35.0 in stage 1.0 (TID 37, 10.1.2.60, partition 35, ANY, 5372 bytes)
17/01/29 05:04:59,840 INFO CoarseGrainedSchedulerBackend$DriverEndpoint: Launching task 37 on executor id: 1 hostname: 10.1.2.60.
17/01/29 05:04:59,842 INFO TaskSetManager: Finished task 26.0 in stage 1.0 (TID 28) in 20049 ms on 10.1.2.60 (29/59)
17/01/29 05:05:01,103 INFO BlockManagerInfo: Added rdd_5_28 in memory on 10.1.2.152:45056 (size: 70.0 MB, free: 1001.5 MB)
17/01/29 05:05:01,123 INFO TaskSetManager: Starting task 36.0 in stage 1.0 (TID 38, 10.1.2.152, partition 36, ANY, 5372 bytes)
17/01/29 05:05:01,124 INFO CoarseGrainedSchedulerBackend$DriverEndpoint: Launching task 38 on executor id: 0 hostname: 10.1.2.152.
17/01/29 05:05:01,124 INFO TaskSetManager: Finished task 28.0 in stage 1.0 (TID 30) in 18608 ms on 10.1.2.152 (30/59)
17/01/29 05:05:04,559 INFO BlockManagerInfo: Added rdd_5_30 in memory on 10.1.2.60:34100 (size: 70.0 MB, free: 1068.6 MB)
17/01/29 05:05:04,577 INFO TaskSetManager: Starting task 37.0 in stage 1.0 (TID 39, 10.1.2.60, partition 37, ANY, 5372 bytes)
17/01/29 05:05:04,577 INFO CoarseGrainedSchedulerBackend$DriverEndpoint: Launching task 39 on executor id: 1 hostname: 10.1.2.60.
17/01/29 05:05:04,577 INFO TaskSetManager: Finished task 30.0 in stage 1.0 (TID 32) in 18965 ms on 10.1.2.60 (31/59)
17/01/29 05:05:04,865 INFO BlockManagerInfo: Added rdd_5_29 in memory on 10.1.2.60:34100 (size: 69.9 MB, free: 998.7 MB)
17/01/29 05:05:04,882 INFO TaskSetManager: Starting task 38.0 in stage 1.0 (TID 40, 10.1.2.60, partition 38, ANY, 5372 bytes)
17/01/29 05:05:04,882 INFO CoarseGrainedSchedulerBackend$DriverEndpoint: Launching task 40 on executor id: 1 hostname: 10.1.2.60.
17/01/29 05:05:04,883 INFO TaskSetManager: Finished task 29.0 in stage 1.0 (TID 31) in 19741 ms on 10.1.2.60 (32/59)
17/01/29 05:05:13,863 INFO BlockManagerInfo: Added rdd_5_31 in memory on 10.1.2.60:34100 (size: 69.7 MB, free: 928.9 MB)
17/01/29 05:05:13,883 INFO TaskSetManager: Starting task 39.0 in stage 1.0 (TID 41, 10.1.2.60, partition 39, ANY, 5372 bytes)
17/01/29 05:05:13,883 INFO CoarseGrainedSchedulerBackend$DriverEndpoint: Launching task 41 on executor id: 1 hostname: 10.1.2.60.
17/01/29 05:05:13,883 INFO TaskSetManager: Finished task 31.0 in stage 1.0 (TID 33) in 23878 ms on 10.1.2.60 (33/59)
17/01/29 05:05:16,590 INFO BlockManagerInfo: Added rdd_5_32 in memory on 10.1.2.152:45056 (size: 69.9 MB, free: 931.6 MB)
17/01/29 05:05:16,607 INFO TaskSetManager: Starting task 40.0 in stage 1.0 (TID 42, 10.1.2.152, partition 40, ANY, 5372 bytes)
17/01/29 05:05:16,608 INFO CoarseGrainedSchedulerBackend$DriverEndpoint: Launching task 42 on executor id: 0 hostname: 10.1.2.152.
17/01/29 05:05:16,608 INFO TaskSetManager: Finished task 32.0 in stage 1.0 (TID 34) in 19558 ms on 10.1.2.152 (34/59)
17/01/29 05:05:17,155 INFO BlockManagerInfo: Added rdd_5_33 in memory on 10.1.2.152:45056 (size: 69.9 MB, free: 861.7 MB)
17/01/29 05:05:17,182 INFO TaskSetManager: Starting task 41.0 in stage 1.0 (TID 43, 10.1.2.152, partition 41, ANY, 5372 bytes)
17/01/29 05:05:17,183 INFO CoarseGrainedSchedulerBackend$DriverEndpoint: Launching task 43 on executor id: 0 hostname: 10.1.2.152.
17/01/29 05:05:17,184 INFO TaskSetManager: Finished task 33.0 in stage 1.0 (TID 35) in 19924 ms on 10.1.2.152 (35/59)
17/01/29 05:05:17,215 INFO BlockManagerInfo: Added rdd_5_34 in memory on 10.1.2.152:45056 (size: 70.0 MB, free: 791.7 MB)
17/01/29 05:05:17,235 INFO TaskSetManager: Starting task 42.0 in stage 1.0 (TID 44, 10.1.2.152, partition 42, ANY, 5372 bytes)
17/01/29 05:05:17,236 INFO CoarseGrainedSchedulerBackend$DriverEndpoint: Launching task 44 on executor id: 0 hostname: 10.1.2.152.
17/01/29 05:05:17,236 INFO TaskSetManager: Finished task 34.0 in stage 1.0 (TID 36) in 18774 ms on 10.1.2.152 (36/59)
17/01/29 05:05:19,782 INFO BlockManagerInfo: Added rdd_5_36 in memory on 10.1.2.152:45056 (size: 70.0 MB, free: 721.6 MB)
17/01/29 05:05:19,799 INFO TaskSetManager: Starting task 43.0 in stage 1.0 (TID 45, 10.1.2.152, partition 43, ANY, 5372 bytes)
17/01/29 05:05:19,799 INFO CoarseGrainedSchedulerBackend$DriverEndpoint: Launching task 45 on executor id: 0 hostname: 10.1.2.152.
17/01/29 05:05:19,800 INFO TaskSetManager: Finished task 36.0 in stage 1.0 (TID 38) in 18678 ms on 10.1.2.152 (37/59)
17/01/29 05:05:20,525 INFO BlockManagerInfo: Added rdd_5_35 in memory on 10.1.2.60:34100 (size: 70.0 MB, free: 858.9 MB)
17/01/29 05:05:20,542 INFO TaskSetManager: Starting task 44.0 in stage 1.0 (TID 46, 10.1.2.60, partition 44, ANY, 5372 bytes)
17/01/29 05:05:20,543 INFO CoarseGrainedSchedulerBackend$DriverEndpoint: Launching task 46 on executor id: 1 hostname: 10.1.2.60.
17/01/29 05:05:20,543 INFO TaskSetManager: Finished task 35.0 in stage 1.0 (TID 37) in 20704 ms on 10.1.2.60 (38/59)
17/01/29 05:05:24,045 INFO BlockManagerInfo: Added rdd_5_37 in memory on 10.1.2.60:34100 (size: 69.9 MB, free: 789.0 MB)
17/01/29 05:05:24,067 INFO TaskSetManager: Starting task 45.0 in stage 1.0 (TID 47, 10.1.2.60, partition 45, ANY, 5372 bytes)
17/01/29 05:05:24,067 INFO CoarseGrainedSchedulerBackend$DriverEndpoint: Launching task 47 on executor id: 1 hostname: 10.1.2.60.
17/01/29 05:05:24,068 INFO TaskSetManager: Finished task 37.0 in stage 1.0 (TID 39) in 19491 ms on 10.1.2.60 (39/59)
17/01/29 05:05:25,309 INFO BlockManagerInfo: Added rdd_5_38 in memory on 10.1.2.60:34100 (size: 70.0 MB, free: 719.0 MB)
17/01/29 05:05:25,326 INFO TaskSetManager: Starting task 46.0 in stage 1.0 (TID 48, 10.1.2.60, partition 46, ANY, 5372 bytes)
17/01/29 05:05:25,326 INFO CoarseGrainedSchedulerBackend$DriverEndpoint: Launching task 48 on executor id: 1 hostname: 10.1.2.60.
17/01/29 05:05:25,327 INFO TaskSetManager: Finished task 38.0 in stage 1.0 (TID 40) in 20446 ms on 10.1.2.60 (40/59)
17/01/29 05:05:38,225 INFO BlockManagerInfo: Added rdd_5_39 in memory on 10.1.2.60:34100 (size: 70.0 MB, free: 649.1 MB)
17/01/29 05:05:38,244 INFO TaskSetManager: Starting task 47.0 in stage 1.0 (TID 49, 10.1.2.60, partition 47, ANY, 5372 bytes)
17/01/29 05:05:38,244 INFO CoarseGrainedSchedulerBackend$DriverEndpoint: Launching task 49 on executor id: 1 hostname: 10.1.2.60.
17/01/29 05:05:38,244 INFO TaskSetManager: Finished task 39.0 in stage 1.0 (TID 41) in 24363 ms on 10.1.2.60 (41/59)
17/01/29 05:05:38,248 INFO BlockManagerInfo: Added rdd_5_41 in memory on 10.1.2.152:45056 (size: 70.0 MB, free: 651.7 MB)
17/01/29 05:05:38,266 INFO TaskSetManager: Starting task 48.0 in stage 1.0 (TID 50, 10.1.2.152, partition 48, ANY, 5372 bytes)
17/01/29 05:05:38,268 INFO TaskSetManager: Finished task 41.0 in stage 1.0 (TID 43) in 21086 ms on 10.1.2.152 (42/59)
17/01/29 05:05:38,268 INFO CoarseGrainedSchedulerBackend$DriverEndpoint: Launching task 50 on executor id: 0 hostname: 10.1.2.152.
17/01/29 05:05:40,297 INFO BlockManagerInfo: Added rdd_5_44 in memory on 10.1.2.60:34100 (size: 70.0 MB, free: 579.1 MB)
17/01/29 05:05:40,316 INFO TaskSetManager: Starting task 49.0 in stage 1.0 (TID 51, 10.1.2.60, partition 49, ANY, 5372 bytes)
17/01/29 05:05:40,316 INFO CoarseGrainedSchedulerBackend$DriverEndpoint: Launching task 51 on executor id: 1 hostname: 10.1.2.60.
17/01/29 05:05:40,317 INFO TaskSetManager: Finished task 44.0 in stage 1.0 (TID 46) in 19776 ms on 10.1.2.60 (43/59)
17/01/29 05:05:41,857 INFO BlockManagerInfo: Added rdd_5_40 in memory on 10.1.2.152:45056 (size: 70.0 MB, free: 581.7 MB)
17/01/29 05:05:41,876 INFO TaskSetManager: Starting task 50.0 in stage 1.0 (TID 52, 10.1.2.152, partition 50, ANY, 5372 bytes)
17/01/29 05:05:41,877 INFO TaskSetManager: Finished task 40.0 in stage 1.0 (TID 42) in 25271 ms on 10.1.2.152 (44/59)
17/01/29 05:05:41,877 INFO CoarseGrainedSchedulerBackend$DriverEndpoint: Launching task 52 on executor id: 0 hostname: 10.1.2.152.
17/01/29 05:05:42,893 INFO BlockManagerInfo: Added rdd_5_45 in memory on 10.1.2.60:34100 (size: 69.9 MB, free: 509.2 MB)
17/01/29 05:05:42,911 INFO TaskSetManager: Starting task 51.0 in stage 1.0 (TID 53, 10.1.2.60, partition 51, ANY, 5372 bytes)
17/01/29 05:05:42,912 INFO CoarseGrainedSchedulerBackend$DriverEndpoint: Launching task 53 on executor id: 1 hostname: 10.1.2.60.
17/01/29 05:05:42,912 INFO TaskSetManager: Finished task 45.0 in stage 1.0 (TID 47) in 18846 ms on 10.1.2.60 (45/59)
17/01/29 05:05:43,221 INFO BlockManagerInfo: Added rdd_5_42 in memory on 10.1.2.152:45056 (size: 69.8 MB, free: 511.9 MB)
17/01/29 05:05:43,238 INFO TaskSetManager: Starting task 52.0 in stage 1.0 (TID 54, 10.1.2.152, partition 52, ANY, 5372 bytes)
17/01/29 05:05:43,238 INFO CoarseGrainedSchedulerBackend$DriverEndpoint: Launching task 54 on executor id: 0 hostname: 10.1.2.152.
17/01/29 05:05:43,238 INFO TaskSetManager: Finished task 42.0 in stage 1.0 (TID 44) in 26004 ms on 10.1.2.152 (46/59)
17/01/29 05:05:45,154 INFO BlockManagerInfo: Added rdd_5_43 in memory on 10.1.2.152:45056 (size: 69.8 MB, free: 442.0 MB)
17/01/29 05:05:45,171 INFO TaskSetManager: Starting task 53.0 in stage 1.0 (TID 55, 10.1.2.152, partition 53, ANY, 5372 bytes)
17/01/29 05:05:45,171 INFO CoarseGrainedSchedulerBackend$DriverEndpoint: Launching task 55 on executor id: 0 hostname: 10.1.2.152.
17/01/29 05:05:45,172 INFO TaskSetManager: Finished task 43.0 in stage 1.0 (TID 45) in 25373 ms on 10.1.2.152 (47/59)
17/01/29 05:05:47,975 INFO BlockManagerInfo: Added rdd_5_46 in memory on 10.1.2.60:34100 (size: 69.9 MB, free: 439.3 MB)
17/01/29 05:05:47,993 INFO TaskSetManager: Starting task 54.0 in stage 1.0 (TID 56, 10.1.2.60, partition 54, ANY, 5372 bytes)
17/01/29 05:05:47,993 INFO CoarseGrainedSchedulerBackend$DriverEndpoint: Launching task 56 on executor id: 1 hostname: 10.1.2.60.
17/01/29 05:05:47,994 INFO TaskSetManager: Finished task 46.0 in stage 1.0 (TID 48) in 22668 ms on 10.1.2.60 (48/59)
17/01/29 05:05:57,321 INFO BlockManagerInfo: Added rdd_5_47 in memory on 10.1.2.60:34100 (size: 70.0 MB, free: 369.3 MB)
17/01/29 05:05:57,343 INFO TaskSetManager: Starting task 55.0 in stage 1.0 (TID 57, 10.1.2.60, partition 55, ANY, 5372 bytes)
17/01/29 05:05:57,344 INFO CoarseGrainedSchedulerBackend$DriverEndpoint: Launching task 57 on executor id: 1 hostname: 10.1.2.60.
17/01/29 05:05:57,344 INFO TaskSetManager: Finished task 47.0 in stage 1.0 (TID 49) in 19101 ms on 10.1.2.60 (49/59)
17/01/29 05:05:58,817 INFO BlockManagerInfo: Added rdd_5_49 in memory on 10.1.2.60:34100 (size: 69.8 MB, free: 299.5 MB)
17/01/29 05:05:58,836 INFO TaskSetManager: Starting task 56.0 in stage 1.0 (TID 58, 10.1.2.60, partition 56, ANY, 5372 bytes)
17/01/29 05:05:58,837 INFO CoarseGrainedSchedulerBackend$DriverEndpoint: Launching task 58 on executor id: 1 hostname: 10.1.2.60.
17/01/29 05:05:58,837 INFO TaskSetManager: Finished task 49.0 in stage 1.0 (TID 51) in 18522 ms on 10.1.2.60 (50/59)
17/01/29 05:05:59,070 INFO BlockManagerInfo: Added rdd_5_48 in memory on 10.1.2.152:45056 (size: 69.9 MB, free: 372.1 MB)
17/01/29 05:05:59,087 INFO TaskSetManager: Starting task 57.0 in stage 1.0 (TID 59, 10.1.2.152, partition 57, ANY, 5372 bytes)
17/01/29 05:05:59,087 INFO CoarseGrainedSchedulerBackend$DriverEndpoint: Launching task 59 on executor id: 0 hostname: 10.1.2.152.
17/01/29 05:05:59,088 INFO TaskSetManager: Finished task 48.0 in stage 1.0 (TID 50) in 20823 ms on 10.1.2.152 (51/59)
17/01/29 05:06:01,139 INFO BlockManagerInfo: Added rdd_5_51 in memory on 10.1.2.60:34100 (size: 69.9 MB, free: 229.6 MB)
17/01/29 05:06:01,161 INFO TaskSetManager: Finished task 51.0 in stage 1.0 (TID 53) in 18249 ms on 10.1.2.60 (52/59)
17/01/29 05:06:03,909 INFO BlockManagerInfo: Added rdd_5_54 in memory on 10.1.2.60:34100 (size: 69.9 MB, free: 159.7 MB)
17/01/29 05:06:03,927 INFO TaskSetManager: Finished task 54.0 in stage 1.0 (TID 56) in 15935 ms on 10.1.2.60 (53/59)
17/01/29 05:06:06,578 INFO BlockManagerInfo: Added rdd_5_50 in memory on 10.1.2.152:45056 (size: 69.9 MB, free: 302.3 MB)
17/01/29 05:06:06,594 INFO TaskSetManager: Finished task 50.0 in stage 1.0 (TID 52) in 24719 ms on 10.1.2.152 (54/59)
17/01/29 05:06:08,459 INFO TaskSetManager: Finished task 55.0 in stage 1.0 (TID 57) in 11117 ms on 10.1.2.60 (55/59)
17/01/29 05:06:08,646 INFO BlockManagerInfo: Added rdd_5_52 in memory on 10.1.2.152:45056 (size: 69.9 MB, free: 232.4 MB)
17/01/29 05:06:08,668 INFO TaskSetManager: Finished task 52.0 in stage 1.0 (TID 54) in 25431 ms on 10.1.2.152 (56/59)
17/01/29 05:06:08,828 INFO BlockManagerInfo: Added rdd_5_56 in memory on 10.1.2.60:34100 (size: 69.9 MB, free: 89.8 MB)
17/01/29 05:06:08,855 INFO TaskSetManager: Finished task 56.0 in stage 1.0 (TID 58) in 10020 ms on 10.1.2.60 (57/59)
17/01/29 05:06:10,521 INFO BlockManagerInfo: Added rdd_5_53 in memory on 10.1.2.152:45056 (size: 70.0 MB, free: 162.4 MB)
17/01/29 05:06:10,539 INFO TaskSetManager: Finished task 53.0 in stage 1.0 (TID 55) in 25368 ms on 10.1.2.152 (58/59)
17/01/29 05:06:12,127 INFO BlockManagerInfo: Added rdd_5_57 in memory on 10.1.2.152:45056 (size: 70.1 MB, free: 92.3 MB)
17/01/29 05:06:12,172 INFO TaskSetManager: Finished task 57.0 in stage 1.0 (TID 59) in 13086 ms on 10.1.2.152 (59/59)
17/01/29 05:06:12,172 INFO TaskSchedulerImpl: Removed TaskSet 1.0, whose tasks have all completed, from pool 
17/01/29 05:06:12,173 INFO DAGScheduler: ResultStage 1 (count at DataValidators.scala:40) finished in 156.339 s
17/01/29 05:06:12,175 INFO DAGScheduler: Job 1 finished: count at DataValidators.scala:40, took 156.375654 s
17/01/29 05:06:12,184 INFO SparkContext: Starting job: count at GradientDescent.scala:209
17/01/29 05:06:12,186 INFO DAGScheduler: Got job 2 (count at GradientDescent.scala:209) with 59 output partitions
17/01/29 05:06:12,186 INFO DAGScheduler: Final stage: ResultStage 2 (count at GradientDescent.scala:209)
17/01/29 05:06:12,186 INFO DAGScheduler: Parents of final stage: List()
17/01/29 05:06:12,189 INFO DAGScheduler: Missing parents: List()
17/01/29 05:06:12,190 INFO DAGScheduler: Submitting ResultStage 2 (MapPartitionsRDD[8] at map at GeneralizedLinearAlgorithm.scala:297), which has no missing parents
17/01/29 05:06:12,196 INFO MemoryStore: Block broadcast_3 stored as values in memory (estimated size 3.9 KB, free 2.1 GB)
17/01/29 05:06:12,198 INFO MemoryStore: Block broadcast_3_piece0 stored as bytes in memory (estimated size 2.2 KB, free 2.1 GB)
17/01/29 05:06:12,199 INFO BlockManagerInfo: Added broadcast_3_piece0 in memory on 10.1.2.31:45152 (size: 2.2 KB, free: 2.1 GB)
17/01/29 05:06:12,200 INFO SparkContext: Created broadcast 3 from broadcast at DAGScheduler.scala:1012
17/01/29 05:06:12,201 INFO DAGScheduler: Submitting 59 missing tasks from ResultStage 2 (MapPartitionsRDD[8] at map at GeneralizedLinearAlgorithm.scala:297)
17/01/29 05:06:12,201 INFO TaskSchedulerImpl: Adding task set 2.0 with 59 tasks
17/01/29 05:06:12,204 INFO TaskSetManager: Starting task 1.0 in stage 2.0 (TID 60, 10.1.2.152, partition 1, PROCESS_LOCAL, 5372 bytes)
17/01/29 05:06:12,205 INFO TaskSetManager: Starting task 0.0 in stage 2.0 (TID 61, 10.1.2.60, partition 0, PROCESS_LOCAL, 5372 bytes)
17/01/29 05:06:12,206 INFO TaskSetManager: Starting task 3.0 in stage 2.0 (TID 62, 10.1.2.152, partition 3, PROCESS_LOCAL, 5372 bytes)
17/01/29 05:06:12,207 INFO TaskSetManager: Starting task 2.0 in stage 2.0 (TID 63, 10.1.2.60, partition 2, PROCESS_LOCAL, 5372 bytes)
17/01/29 05:06:12,208 INFO TaskSetManager: Starting task 5.0 in stage 2.0 (TID 64, 10.1.2.152, partition 5, PROCESS_LOCAL, 5372 bytes)
17/01/29 05:06:12,209 INFO TaskSetManager: Starting task 4.0 in stage 2.0 (TID 65, 10.1.2.60, partition 4, PROCESS_LOCAL, 5372 bytes)
17/01/29 05:06:12,210 INFO TaskSetManager: Starting task 7.0 in stage 2.0 (TID 66, 10.1.2.152, partition 7, PROCESS_LOCAL, 5372 bytes)
17/01/29 05:06:12,211 INFO TaskSetManager: Starting task 6.0 in stage 2.0 (TID 67, 10.1.2.60, partition 6, PROCESS_LOCAL, 5372 bytes)
17/01/29 05:06:12,211 INFO CoarseGrainedSchedulerBackend$DriverEndpoint: Launching task 60 on executor id: 0 hostname: 10.1.2.152.
17/01/29 05:06:12,212 INFO CoarseGrainedSchedulerBackend$DriverEndpoint: Launching task 62 on executor id: 0 hostname: 10.1.2.152.
17/01/29 05:06:12,212 INFO CoarseGrainedSchedulerBackend$DriverEndpoint: Launching task 64 on executor id: 0 hostname: 10.1.2.152.
17/01/29 05:06:12,213 INFO CoarseGrainedSchedulerBackend$DriverEndpoint: Launching task 66 on executor id: 0 hostname: 10.1.2.152.
17/01/29 05:06:12,213 INFO CoarseGrainedSchedulerBackend$DriverEndpoint: Launching task 61 on executor id: 1 hostname: 10.1.2.60.
17/01/29 05:06:12,214 INFO CoarseGrainedSchedulerBackend$DriverEndpoint: Launching task 63 on executor id: 1 hostname: 10.1.2.60.
17/01/29 05:06:12,214 INFO CoarseGrainedSchedulerBackend$DriverEndpoint: Launching task 65 on executor id: 1 hostname: 10.1.2.60.
17/01/29 05:06:12,215 INFO CoarseGrainedSchedulerBackend$DriverEndpoint: Launching task 67 on executor id: 1 hostname: 10.1.2.60.
17/01/29 05:06:12,235 INFO BlockManagerInfo: Added broadcast_3_piece0 in memory on 10.1.2.60:34100 (size: 2.2 KB, free: 89.8 MB)
17/01/29 05:06:12,256 INFO BlockManagerInfo: Added broadcast_3_piece0 in memory on 10.1.2.152:45056 (size: 2.2 KB, free: 92.3 MB)
17/01/29 05:06:12,282 INFO TaskSetManager: Starting task 8.0 in stage 2.0 (TID 68, 10.1.2.60, partition 8, PROCESS_LOCAL, 5372 bytes)
17/01/29 05:06:12,283 INFO CoarseGrainedSchedulerBackend$DriverEndpoint: Launching task 68 on executor id: 1 hostname: 10.1.2.60.
17/01/29 05:06:12,283 INFO TaskSetManager: Finished task 2.0 in stage 2.0 (TID 63) in 77 ms on 10.1.2.60 (1/59)
17/01/29 05:06:12,284 INFO TaskSetManager: Starting task 13.0 in stage 2.0 (TID 69, 10.1.2.60, partition 13, PROCESS_LOCAL, 5372 bytes)
17/01/29 05:06:12,284 INFO CoarseGrainedSchedulerBackend$DriverEndpoint: Launching task 69 on executor id: 1 hostname: 10.1.2.60.
17/01/29 05:06:12,285 INFO TaskSetManager: Finished task 6.0 in stage 2.0 (TID 67) in 74 ms on 10.1.2.60 (2/59)
17/01/29 05:06:12,286 INFO TaskSetManager: Finished task 4.0 in stage 2.0 (TID 65) in 77 ms on 10.1.2.60 (3/59)
17/01/29 05:06:12,287 INFO TaskSetManager: Starting task 14.0 in stage 2.0 (TID 70, 10.1.2.60, partition 14, PROCESS_LOCAL, 5372 bytes)
17/01/29 05:06:12,287 INFO CoarseGrainedSchedulerBackend$DriverEndpoint: Launching task 70 on executor id: 1 hostname: 10.1.2.60.
17/01/29 05:06:12,289 INFO TaskSetManager: Starting task 15.0 in stage 2.0 (TID 71, 10.1.2.60, partition 15, PROCESS_LOCAL, 5372 bytes)
17/01/29 05:06:12,290 INFO CoarseGrainedSchedulerBackend$DriverEndpoint: Launching task 71 on executor id: 1 hostname: 10.1.2.60.
17/01/29 05:06:12,290 INFO TaskSetManager: Finished task 0.0 in stage 2.0 (TID 61) in 86 ms on 10.1.2.60 (4/59)
17/01/29 05:06:12,304 INFO TaskSetManager: Starting task 9.0 in stage 2.0 (TID 72, 10.1.2.152, partition 9, PROCESS_LOCAL, 5372 bytes)
17/01/29 05:06:12,304 INFO CoarseGrainedSchedulerBackend$DriverEndpoint: Launching task 72 on executor id: 0 hostname: 10.1.2.152.
17/01/29 05:06:12,304 INFO TaskSetManager: Finished task 7.0 in stage 2.0 (TID 66) in 95 ms on 10.1.2.152 (5/59)
17/01/29 05:06:12,314 INFO TaskSetManager: Starting task 16.0 in stage 2.0 (TID 73, 10.1.2.60, partition 16, PROCESS_LOCAL, 5372 bytes)
17/01/29 05:06:12,315 INFO CoarseGrainedSchedulerBackend$DriverEndpoint: Launching task 73 on executor id: 1 hostname: 10.1.2.60.
17/01/29 05:06:12,315 INFO TaskSetManager: Finished task 8.0 in stage 2.0 (TID 68) in 34 ms on 10.1.2.60 (6/59)
17/01/29 05:06:12,323 INFO TaskSetManager: Starting task 21.0 in stage 2.0 (TID 74, 10.1.2.60, partition 21, PROCESS_LOCAL, 5372 bytes)
17/01/29 05:06:12,323 INFO CoarseGrainedSchedulerBackend$DriverEndpoint: Launching task 74 on executor id: 1 hostname: 10.1.2.60.
17/01/29 05:06:12,323 INFO TaskSetManager: Finished task 15.0 in stage 2.0 (TID 71) in 35 ms on 10.1.2.60 (7/59)
17/01/29 05:06:12,332 INFO TaskSetManager: Starting task 10.0 in stage 2.0 (TID 75, 10.1.2.152, partition 10, PROCESS_LOCAL, 5372 bytes)
17/01/29 05:06:12,333 INFO CoarseGrainedSchedulerBackend$DriverEndpoint: Launching task 75 on executor id: 0 hostname: 10.1.2.152.
17/01/29 05:06:12,333 INFO TaskSetManager: Finished task 9.0 in stage 2.0 (TID 72) in 31 ms on 10.1.2.152 (8/59)
17/01/29 05:06:12,334 INFO TaskSetManager: Starting task 22.0 in stage 2.0 (TID 76, 10.1.2.60, partition 22, PROCESS_LOCAL, 5372 bytes)
17/01/29 05:06:12,335 INFO CoarseGrainedSchedulerBackend$DriverEndpoint: Launching task 76 on executor id: 1 hostname: 10.1.2.60.
17/01/29 05:06:12,335 INFO TaskSetManager: Finished task 13.0 in stage 2.0 (TID 69) in 52 ms on 10.1.2.60 (9/59)
17/01/29 05:06:12,356 INFO TaskSetManager: Starting task 23.0 in stage 2.0 (TID 77, 10.1.2.60, partition 23, PROCESS_LOCAL, 5372 bytes)
17/01/29 05:06:12,357 INFO CoarseGrainedSchedulerBackend$DriverEndpoint: Launching task 77 on executor id: 1 hostname: 10.1.2.60.
17/01/29 05:06:12,357 INFO TaskSetManager: Finished task 21.0 in stage 2.0 (TID 74) in 35 ms on 10.1.2.60 (10/59)
17/01/29 05:06:12,358 INFO TaskSetManager: Starting task 11.0 in stage 2.0 (TID 78, 10.1.2.152, partition 11, PROCESS_LOCAL, 5372 bytes)
17/01/29 05:06:12,359 INFO CoarseGrainedSchedulerBackend$DriverEndpoint: Launching task 78 on executor id: 0 hostname: 10.1.2.152.
17/01/29 05:06:12,359 INFO TaskSetManager: Finished task 10.0 in stage 2.0 (TID 75) in 28 ms on 10.1.2.152 (11/59)
17/01/29 05:06:12,362 INFO TaskSetManager: Starting task 12.0 in stage 2.0 (TID 79, 10.1.2.152, partition 12, PROCESS_LOCAL, 5372 bytes)
17/01/29 05:06:12,363 INFO CoarseGrainedSchedulerBackend$DriverEndpoint: Launching task 79 on executor id: 0 hostname: 10.1.2.152.
17/01/29 05:06:12,363 INFO TaskSetManager: Finished task 3.0 in stage 2.0 (TID 62) in 158 ms on 10.1.2.152 (12/59)
17/01/29 05:06:12,366 INFO TaskSetManager: Starting task 26.0 in stage 2.0 (TID 80, 10.1.2.60, partition 26, PROCESS_LOCAL, 5372 bytes)
17/01/29 05:06:12,366 INFO CoarseGrainedSchedulerBackend$DriverEndpoint: Launching task 80 on executor id: 1 hostname: 10.1.2.60.
17/01/29 05:06:12,366 INFO TaskSetManager: Finished task 14.0 in stage 2.0 (TID 70) in 80 ms on 10.1.2.60 (13/59)
17/01/29 05:06:12,370 INFO TaskSetManager: Starting task 29.0 in stage 2.0 (TID 81, 10.1.2.60, partition 29, PROCESS_LOCAL, 5372 bytes)
17/01/29 05:06:12,370 INFO CoarseGrainedSchedulerBackend$DriverEndpoint: Launching task 81 on executor id: 1 hostname: 10.1.2.60.
17/01/29 05:06:12,371 INFO TaskSetManager: Finished task 16.0 in stage 2.0 (TID 73) in 56 ms on 10.1.2.60 (14/59)
17/01/29 05:06:12,378 INFO TaskSetManager: Starting task 30.0 in stage 2.0 (TID 82, 10.1.2.60, partition 30, PROCESS_LOCAL, 5372 bytes)
17/01/29 05:06:12,379 INFO CoarseGrainedSchedulerBackend$DriverEndpoint: Launching task 82 on executor id: 1 hostname: 10.1.2.60.
17/01/29 05:06:12,379 INFO TaskSetManager: Finished task 22.0 in stage 2.0 (TID 76) in 46 ms on 10.1.2.60 (15/59)
17/01/29 05:06:12,381 INFO TaskSetManager: Starting task 17.0 in stage 2.0 (TID 83, 10.1.2.152, partition 17, PROCESS_LOCAL, 5372 bytes)
17/01/29 05:06:12,381 INFO CoarseGrainedSchedulerBackend$DriverEndpoint: Launching task 83 on executor id: 0 hostname: 10.1.2.152.
17/01/29 05:06:12,382 INFO TaskSetManager: Finished task 11.0 in stage 2.0 (TID 78) in 25 ms on 10.1.2.152 (16/59)
17/01/29 05:06:12,388 INFO TaskSetManager: Starting task 31.0 in stage 2.0 (TID 84, 10.1.2.60, partition 31, PROCESS_LOCAL, 5372 bytes)
17/01/29 05:06:12,389 INFO CoarseGrainedSchedulerBackend$DriverEndpoint: Launching task 84 on executor id: 1 hostname: 10.1.2.60.
17/01/29 05:06:12,389 INFO TaskSetManager: Finished task 23.0 in stage 2.0 (TID 77) in 34 ms on 10.1.2.60 (17/59)
17/01/29 05:06:12,398 INFO TaskSetManager: Starting task 35.0 in stage 2.0 (TID 85, 10.1.2.60, partition 35, PROCESS_LOCAL, 5372 bytes)
17/01/29 05:06:12,399 INFO CoarseGrainedSchedulerBackend$DriverEndpoint: Launching task 85 on executor id: 1 hostname: 10.1.2.60.
17/01/29 05:06:12,399 INFO TaskSetManager: Finished task 29.0 in stage 2.0 (TID 81) in 30 ms on 10.1.2.60 (18/59)
17/01/29 05:06:12,401 INFO TaskSetManager: Starting task 18.0 in stage 2.0 (TID 86, 10.1.2.152, partition 18, PROCESS_LOCAL, 5372 bytes)
17/01/29 05:06:12,401 INFO CoarseGrainedSchedulerBackend$DriverEndpoint: Launching task 86 on executor id: 0 hostname: 10.1.2.152.
17/01/29 05:06:12,402 INFO TaskSetManager: Finished task 12.0 in stage 2.0 (TID 79) in 40 ms on 10.1.2.152 (19/59)
17/01/29 05:06:12,418 INFO TaskSetManager: Starting task 37.0 in stage 2.0 (TID 87, 10.1.2.60, partition 37, PROCESS_LOCAL, 5372 bytes)
17/01/29 05:06:12,418 INFO CoarseGrainedSchedulerBackend$DriverEndpoint: Launching task 87 on executor id: 1 hostname: 10.1.2.60.
17/01/29 05:06:12,419 INFO TaskSetManager: Finished task 26.0 in stage 2.0 (TID 80) in 53 ms on 10.1.2.60 (20/59)
17/01/29 05:06:12,420 INFO TaskSetManager: Starting task 38.0 in stage 2.0 (TID 88, 10.1.2.60, partition 38, PROCESS_LOCAL, 5372 bytes)
17/01/29 05:06:12,420 INFO CoarseGrainedSchedulerBackend$DriverEndpoint: Launching task 88 on executor id: 1 hostname: 10.1.2.60.
17/01/29 05:06:12,421 INFO TaskSetManager: Finished task 31.0 in stage 2.0 (TID 84) in 33 ms on 10.1.2.60 (21/59)
17/01/29 05:06:12,422 INFO TaskSetManager: Starting task 39.0 in stage 2.0 (TID 89, 10.1.2.60, partition 39, PROCESS_LOCAL, 5372 bytes)
17/01/29 05:06:12,423 INFO CoarseGrainedSchedulerBackend$DriverEndpoint: Launching task 89 on executor id: 1 hostname: 10.1.2.60.
17/01/29 05:06:12,423 INFO TaskSetManager: Finished task 30.0 in stage 2.0 (TID 82) in 46 ms on 10.1.2.60 (22/59)
17/01/29 05:06:12,432 INFO TaskSetManager: Starting task 44.0 in stage 2.0 (TID 90, 10.1.2.60, partition 44, PROCESS_LOCAL, 5372 bytes)
17/01/29 05:06:12,433 INFO CoarseGrainedSchedulerBackend$DriverEndpoint: Launching task 90 on executor id: 1 hostname: 10.1.2.60.
17/01/29 05:06:12,433 INFO TaskSetManager: Finished task 35.0 in stage 2.0 (TID 85) in 36 ms on 10.1.2.60 (23/59)
17/01/29 05:06:12,435 INFO TaskSetManager: Starting task 19.0 in stage 2.0 (TID 91, 10.1.2.152, partition 19, PROCESS_LOCAL, 5372 bytes)
17/01/29 05:06:12,436 INFO CoarseGrainedSchedulerBackend$DriverEndpoint: Launching task 91 on executor id: 0 hostname: 10.1.2.152.
17/01/29 05:06:12,436 INFO TaskSetManager: Finished task 18.0 in stage 2.0 (TID 86) in 36 ms on 10.1.2.152 (24/59)
17/01/29 05:06:12,438 INFO TaskSetManager: Starting task 20.0 in stage 2.0 (TID 92, 10.1.2.152, partition 20, PROCESS_LOCAL, 5372 bytes)
17/01/29 05:06:12,439 INFO CoarseGrainedSchedulerBackend$DriverEndpoint: Launching task 92 on executor id: 0 hostname: 10.1.2.152.
17/01/29 05:06:12,439 INFO TaskSetManager: Finished task 17.0 in stage 2.0 (TID 83) in 59 ms on 10.1.2.152 (25/59)
17/01/29 05:06:12,446 INFO TaskSetManager: Starting task 24.0 in stage 2.0 (TID 93, 10.1.2.152, partition 24, PROCESS_LOCAL, 5372 bytes)
17/01/29 05:06:12,446 INFO CoarseGrainedSchedulerBackend$DriverEndpoint: Launching task 93 on executor id: 0 hostname: 10.1.2.152.
17/01/29 05:06:12,447 INFO TaskSetManager: Finished task 5.0 in stage 2.0 (TID 64) in 240 ms on 10.1.2.152 (26/59)
17/01/29 05:06:12,452 INFO TaskSetManager: Starting task 45.0 in stage 2.0 (TID 94, 10.1.2.60, partition 45, PROCESS_LOCAL, 5372 bytes)
17/01/29 05:06:12,452 INFO CoarseGrainedSchedulerBackend$DriverEndpoint: Launching task 94 on executor id: 1 hostname: 10.1.2.60.
17/01/29 05:06:12,453 INFO TaskSetManager: Finished task 38.0 in stage 2.0 (TID 88) in 33 ms on 10.1.2.60 (27/59)
17/01/29 05:06:12,454 INFO TaskSetManager: Starting task 46.0 in stage 2.0 (TID 95, 10.1.2.60, partition 46, PROCESS_LOCAL, 5372 bytes)
17/01/29 05:06:12,454 INFO CoarseGrainedSchedulerBackend$DriverEndpoint: Launching task 95 on executor id: 1 hostname: 10.1.2.60.
17/01/29 05:06:12,454 INFO TaskSetManager: Finished task 37.0 in stage 2.0 (TID 87) in 37 ms on 10.1.2.60 (28/59)
17/01/29 05:06:12,462 INFO TaskSetManager: Starting task 47.0 in stage 2.0 (TID 96, 10.1.2.60, partition 47, PROCESS_LOCAL, 5372 bytes)
17/01/29 05:06:12,462 INFO CoarseGrainedSchedulerBackend$DriverEndpoint: Launching task 96 on executor id: 1 hostname: 10.1.2.60.
17/01/29 05:06:12,463 INFO TaskSetManager: Finished task 44.0 in stage 2.0 (TID 90) in 30 ms on 10.1.2.60 (29/59)
17/01/29 05:06:12,464 INFO TaskSetManager: Starting task 49.0 in stage 2.0 (TID 97, 10.1.2.60, partition 49, PROCESS_LOCAL, 5372 bytes)
17/01/29 05:06:12,464 INFO CoarseGrainedSchedulerBackend$DriverEndpoint: Launching task 97 on executor id: 1 hostname: 10.1.2.60.
17/01/29 05:06:12,464 INFO TaskSetManager: Finished task 39.0 in stage 2.0 (TID 89) in 43 ms on 10.1.2.60 (30/59)
17/01/29 05:06:12,466 INFO TaskSetManager: Starting task 25.0 in stage 2.0 (TID 98, 10.1.2.152, partition 25, PROCESS_LOCAL, 5372 bytes)
17/01/29 05:06:12,466 INFO CoarseGrainedSchedulerBackend$DriverEndpoint: Launching task 98 on executor id: 0 hostname: 10.1.2.152.
17/01/29 05:06:12,467 INFO TaskSetManager: Finished task 19.0 in stage 2.0 (TID 91) in 31 ms on 10.1.2.152 (31/59)
17/01/29 05:06:12,473 INFO TaskSetManager: Starting task 27.0 in stage 2.0 (TID 99, 10.1.2.152, partition 27, PROCESS_LOCAL, 5372 bytes)
17/01/29 05:06:12,473 INFO CoarseGrainedSchedulerBackend$DriverEndpoint: Launching task 99 on executor id: 0 hostname: 10.1.2.152.
17/01/29 05:06:12,473 INFO TaskSetManager: Finished task 24.0 in stage 2.0 (TID 93) in 28 ms on 10.1.2.152 (32/59)
17/01/29 05:06:12,475 INFO TaskSetManager: Starting task 28.0 in stage 2.0 (TID 100, 10.1.2.152, partition 28, PROCESS_LOCAL, 5372 bytes)
17/01/29 05:06:12,476 INFO CoarseGrainedSchedulerBackend$DriverEndpoint: Launching task 100 on executor id: 0 hostname: 10.1.2.152.
17/01/29 05:06:12,476 INFO TaskSetManager: Finished task 20.0 in stage 2.0 (TID 92) in 39 ms on 10.1.2.152 (33/59)
17/01/29 05:06:12,485 INFO TaskSetManager: Starting task 51.0 in stage 2.0 (TID 101, 10.1.2.60, partition 51, PROCESS_LOCAL, 5372 bytes)
17/01/29 05:06:12,485 INFO CoarseGrainedSchedulerBackend$DriverEndpoint: Launching task 101 on executor id: 1 hostname: 10.1.2.60.
17/01/29 05:06:12,485 INFO TaskSetManager: Finished task 46.0 in stage 2.0 (TID 95) in 32 ms on 10.1.2.60 (34/59)
17/01/29 05:06:12,488 INFO TaskSetManager: Starting task 54.0 in stage 2.0 (TID 102, 10.1.2.60, partition 54, PROCESS_LOCAL, 5372 bytes)
17/01/29 05:06:12,489 INFO CoarseGrainedSchedulerBackend$DriverEndpoint: Launching task 102 on executor id: 1 hostname: 10.1.2.60.
17/01/29 05:06:12,489 INFO TaskSetManager: Finished task 45.0 in stage 2.0 (TID 94) in 38 ms on 10.1.2.60 (35/59)
17/01/29 05:06:12,495 INFO TaskSetManager: Starting task 32.0 in stage 2.0 (TID 103, 10.1.2.152, partition 32, PROCESS_LOCAL, 5372 bytes)
17/01/29 05:06:12,495 INFO CoarseGrainedSchedulerBackend$DriverEndpoint: Launching task 103 on executor id: 0 hostname: 10.1.2.152.
17/01/29 05:06:12,495 INFO TaskSetManager: Finished task 25.0 in stage 2.0 (TID 98) in 30 ms on 10.1.2.152 (36/59)
17/01/29 05:06:12,496 INFO TaskSetManager: Starting task 56.0 in stage 2.0 (TID 104, 10.1.2.60, partition 56, PROCESS_LOCAL, 5372 bytes)
17/01/29 05:06:12,497 INFO CoarseGrainedSchedulerBackend$DriverEndpoint: Launching task 104 on executor id: 1 hostname: 10.1.2.60.
17/01/29 05:06:12,497 INFO TaskSetManager: Finished task 47.0 in stage 2.0 (TID 96) in 36 ms on 10.1.2.60 (37/59)
17/01/29 05:06:12,498 INFO TaskSetManager: Starting task 33.0 in stage 2.0 (TID 105, 10.1.2.152, partition 33, PROCESS_LOCAL, 5372 bytes)
17/01/29 05:06:12,499 INFO CoarseGrainedSchedulerBackend$DriverEndpoint: Launching task 105 on executor id: 0 hostname: 10.1.2.152.
17/01/29 05:06:12,499 INFO TaskSetManager: Finished task 27.0 in stage 2.0 (TID 99) in 27 ms on 10.1.2.152 (38/59)
17/01/29 05:06:12,501 INFO TaskSetManager: Starting task 34.0 in stage 2.0 (TID 106, 10.1.2.152, partition 34, PROCESS_LOCAL, 5372 bytes)
17/01/29 05:06:12,501 INFO CoarseGrainedSchedulerBackend$DriverEndpoint: Launching task 106 on executor id: 0 hostname: 10.1.2.152.
17/01/29 05:06:12,501 INFO TaskSetManager: Finished task 28.0 in stage 2.0 (TID 100) in 26 ms on 10.1.2.152 (39/59)
17/01/29 05:06:12,515 INFO TaskSetManager: Starting task 58.0 in stage 2.0 (TID 107, 10.1.2.60, partition 58, PROCESS_LOCAL, 5372 bytes)
17/01/29 05:06:12,515 INFO CoarseGrainedSchedulerBackend$DriverEndpoint: Launching task 107 on executor id: 1 hostname: 10.1.2.60.
17/01/29 05:06:12,515 INFO TaskSetManager: Finished task 49.0 in stage 2.0 (TID 97) in 52 ms on 10.1.2.60 (40/59)
17/01/29 05:06:12,517 INFO TaskSetManager: Finished task 54.0 in stage 2.0 (TID 102) in 28 ms on 10.1.2.60 (41/59)
17/01/29 05:06:12,519 INFO TaskSetManager: Finished task 51.0 in stage 2.0 (TID 101) in 35 ms on 10.1.2.60 (42/59)
17/01/29 05:06:12,520 INFO TaskSetManager: Starting task 36.0 in stage 2.0 (TID 108, 10.1.2.152, partition 36, PROCESS_LOCAL, 5372 bytes)
17/01/29 05:06:12,520 INFO CoarseGrainedSchedulerBackend$DriverEndpoint: Launching task 108 on executor id: 0 hostname: 10.1.2.152.
17/01/29 05:06:12,521 INFO TaskSetManager: Finished task 33.0 in stage 2.0 (TID 105) in 22 ms on 10.1.2.152 (43/59)
17/01/29 05:06:12,524 INFO TaskSetManager: Starting task 40.0 in stage 2.0 (TID 109, 10.1.2.152, partition 40, PROCESS_LOCAL, 5372 bytes)
17/01/29 05:06:12,524 INFO CoarseGrainedSchedulerBackend$DriverEndpoint: Launching task 109 on executor id: 0 hostname: 10.1.2.152.
17/01/29 05:06:12,525 INFO TaskSetManager: Finished task 32.0 in stage 2.0 (TID 103) in 30 ms on 10.1.2.152 (44/59)
17/01/29 05:06:12,526 INFO TaskSetManager: Finished task 56.0 in stage 2.0 (TID 104) in 30 ms on 10.1.2.60 (45/59)
17/01/29 05:06:12,528 INFO TaskSetManager: Starting task 41.0 in stage 2.0 (TID 110, 10.1.2.152, partition 41, PROCESS_LOCAL, 5372 bytes)
17/01/29 05:06:12,528 INFO CoarseGrainedSchedulerBackend$DriverEndpoint: Launching task 110 on executor id: 0 hostname: 10.1.2.152.
17/01/29 05:06:12,528 INFO TaskSetManager: Finished task 34.0 in stage 2.0 (TID 106) in 28 ms on 10.1.2.152 (46/59)
17/01/29 05:06:12,544 INFO TaskSetManager: Starting task 42.0 in stage 2.0 (TID 111, 10.1.2.152, partition 42, PROCESS_LOCAL, 5372 bytes)
17/01/29 05:06:12,544 INFO CoarseGrainedSchedulerBackend$DriverEndpoint: Launching task 111 on executor id: 0 hostname: 10.1.2.152.
17/01/29 05:06:12,545 INFO TaskSetManager: Finished task 36.0 in stage 2.0 (TID 108) in 25 ms on 10.1.2.152 (47/59)
17/01/29 05:06:12,545 INFO TaskSetManager: Finished task 58.0 in stage 2.0 (TID 107) in 31 ms on 10.1.2.60 (48/59)
17/01/29 05:06:12,552 INFO TaskSetManager: Starting task 43.0 in stage 2.0 (TID 112, 10.1.2.152, partition 43, PROCESS_LOCAL, 5372 bytes)
17/01/29 05:06:12,552 INFO CoarseGrainedSchedulerBackend$DriverEndpoint: Launching task 112 on executor id: 0 hostname: 10.1.2.152.
17/01/29 05:06:12,553 INFO TaskSetManager: Finished task 40.0 in stage 2.0 (TID 109) in 28 ms on 10.1.2.152 (49/59)
17/01/29 05:06:12,558 INFO TaskSetManager: Starting task 48.0 in stage 2.0 (TID 113, 10.1.2.152, partition 48, PROCESS_LOCAL, 5372 bytes)
17/01/29 05:06:12,558 INFO CoarseGrainedSchedulerBackend$DriverEndpoint: Launching task 113 on executor id: 0 hostname: 10.1.2.152.
17/01/29 05:06:12,558 INFO TaskSetManager: Finished task 41.0 in stage 2.0 (TID 110) in 30 ms on 10.1.2.152 (50/59)
17/01/29 05:06:12,578 INFO TaskSetManager: Starting task 50.0 in stage 2.0 (TID 114, 10.1.2.152, partition 50, PROCESS_LOCAL, 5372 bytes)
17/01/29 05:06:12,578 INFO CoarseGrainedSchedulerBackend$DriverEndpoint: Launching task 114 on executor id: 0 hostname: 10.1.2.152.
17/01/29 05:06:12,578 INFO TaskSetManager: Finished task 43.0 in stage 2.0 (TID 112) in 26 ms on 10.1.2.152 (51/59)
17/01/29 05:06:12,581 INFO TaskSetManager: Starting task 52.0 in stage 2.0 (TID 115, 10.1.2.152, partition 52, PROCESS_LOCAL, 5372 bytes)
17/01/29 05:06:12,582 INFO CoarseGrainedSchedulerBackend$DriverEndpoint: Launching task 115 on executor id: 0 hostname: 10.1.2.152.
17/01/29 05:06:12,582 INFO TaskSetManager: Finished task 48.0 in stage 2.0 (TID 113) in 25 ms on 10.1.2.152 (52/59)
17/01/29 05:06:12,585 INFO TaskSetManager: Starting task 53.0 in stage 2.0 (TID 116, 10.1.2.152, partition 53, PROCESS_LOCAL, 5372 bytes)
17/01/29 05:06:12,585 INFO CoarseGrainedSchedulerBackend$DriverEndpoint: Launching task 116 on executor id: 0 hostname: 10.1.2.152.
17/01/29 05:06:12,585 INFO TaskSetManager: Finished task 1.0 in stage 2.0 (TID 60) in 382 ms on 10.1.2.152 (53/59)
17/01/29 05:06:12,586 INFO TaskSetManager: Starting task 57.0 in stage 2.0 (TID 117, 10.1.2.152, partition 57, PROCESS_LOCAL, 5372 bytes)
17/01/29 05:06:12,586 INFO CoarseGrainedSchedulerBackend$DriverEndpoint: Launching task 117 on executor id: 0 hostname: 10.1.2.152.
17/01/29 05:06:12,587 INFO TaskSetManager: Finished task 42.0 in stage 2.0 (TID 111) in 44 ms on 10.1.2.152 (54/59)
17/01/29 05:06:12,605 INFO TaskSetManager: Finished task 53.0 in stage 2.0 (TID 116) in 21 ms on 10.1.2.152 (55/59)
17/01/29 05:06:12,607 INFO TaskSetManager: Finished task 50.0 in stage 2.0 (TID 114) in 30 ms on 10.1.2.152 (56/59)
17/01/29 05:06:12,617 INFO TaskSetManager: Finished task 52.0 in stage 2.0 (TID 115) in 36 ms on 10.1.2.152 (57/59)
17/01/29 05:06:12,618 INFO TaskSetManager: Finished task 57.0 in stage 2.0 (TID 117) in 32 ms on 10.1.2.152 (58/59)
17/01/29 05:06:15,971 INFO TaskSetManager: Starting task 55.0 in stage 2.0 (TID 118, 10.1.2.152, partition 55, ANY, 5372 bytes)
17/01/29 05:06:15,971 INFO CoarseGrainedSchedulerBackend$DriverEndpoint: Launching task 118 on executor id: 0 hostname: 10.1.2.152.
17/01/29 05:06:21,566 INFO TaskSetManager: Finished task 55.0 in stage 2.0 (TID 118) in 5595 ms on 10.1.2.152 (59/59)
17/01/29 05:06:21,566 INFO TaskSchedulerImpl: Removed TaskSet 2.0, whose tasks have all completed, from pool 
17/01/29 05:06:21,567 INFO DAGScheduler: ResultStage 2 (count at GradientDescent.scala:209) finished in 9.363 s
17/01/29 05:06:21,567 INFO DAGScheduler: Job 2 finished: count at GradientDescent.scala:209, took 9.382745 s
17/01/29 05:06:21,849 WARN BLAS: Failed to load implementation from: com.github.fommil.netlib.NativeSystemBLAS
17/01/29 05:06:21,849 WARN BLAS: Failed to load implementation from: com.github.fommil.netlib.NativeRefBLAS
17/01/29 05:06:21,874 INFO MemoryStore: Block broadcast_4 stored as values in memory (estimated size 280.0 B, free 2.1 GB)
17/01/29 05:06:21,877 INFO MemoryStore: Block broadcast_4_piece0 stored as bytes in memory (estimated size 153.0 B, free 2.1 GB)
17/01/29 05:06:21,878 INFO BlockManagerInfo: Added broadcast_4_piece0 in memory on 10.1.2.31:45152 (size: 153.0 B, free: 2.1 GB)
17/01/29 05:06:21,879 INFO SparkContext: Created broadcast 4 from broadcast at GradientDescent.scala:235
17/01/29 05:06:21,940 INFO SparkContext: Starting job: treeAggregate at GradientDescent.scala:239
17/01/29 05:06:21,945 INFO DAGScheduler: Registering RDD 11 (treeAggregate at GradientDescent.scala:239)
17/01/29 05:06:21,946 INFO DAGScheduler: Got job 3 (treeAggregate at GradientDescent.scala:239) with 7 output partitions
17/01/29 05:06:21,946 INFO DAGScheduler: Final stage: ResultStage 4 (treeAggregate at GradientDescent.scala:239)
17/01/29 05:06:21,946 INFO DAGScheduler: Parents of final stage: List(ShuffleMapStage 3)
17/01/29 05:06:21,946 INFO DAGScheduler: Missing parents: List(ShuffleMapStage 3)
17/01/29 05:06:21,950 INFO DAGScheduler: Submitting ShuffleMapStage 3 (MapPartitionsRDD[11] at treeAggregate at GradientDescent.scala:239), which has no missing parents
17/01/29 05:06:21,970 INFO MemoryStore: Block broadcast_5 stored as values in memory (estimated size 7.2 KB, free 2.1 GB)
17/01/29 05:06:21,971 INFO MemoryStore: Block broadcast_5_piece0 stored as bytes in memory (estimated size 3.7 KB, free 2.1 GB)
17/01/29 05:06:21,972 INFO BlockManagerInfo: Added broadcast_5_piece0 in memory on 10.1.2.31:45152 (size: 3.7 KB, free: 2.1 GB)
17/01/29 05:06:21,972 INFO SparkContext: Created broadcast 5 from broadcast at DAGScheduler.scala:1012
17/01/29 05:06:21,975 INFO DAGScheduler: Submitting 59 missing tasks from ShuffleMapStage 3 (MapPartitionsRDD[11] at treeAggregate at GradientDescent.scala:239)
17/01/29 05:06:21,975 INFO TaskSchedulerImpl: Adding task set 3.0 with 59 tasks
17/01/29 05:06:21,979 INFO TaskSetManager: Starting task 0.0 in stage 3.0 (TID 119, 10.1.2.60, partition 0, PROCESS_LOCAL, 5561 bytes)
17/01/29 05:06:21,979 INFO TaskSetManager: Starting task 1.0 in stage 3.0 (TID 120, 10.1.2.152, partition 1, PROCESS_LOCAL, 5561 bytes)
17/01/29 05:06:21,980 INFO TaskSetManager: Starting task 2.0 in stage 3.0 (TID 121, 10.1.2.60, partition 2, PROCESS_LOCAL, 5561 bytes)
17/01/29 05:06:21,980 INFO TaskSetManager: Starting task 3.0 in stage 3.0 (TID 122, 10.1.2.152, partition 3, PROCESS_LOCAL, 5561 bytes)
17/01/29 05:06:21,981 INFO TaskSetManager: Starting task 4.0 in stage 3.0 (TID 123, 10.1.2.60, partition 4, PROCESS_LOCAL, 5561 bytes)
17/01/29 05:06:21,982 INFO TaskSetManager: Starting task 5.0 in stage 3.0 (TID 124, 10.1.2.152, partition 5, PROCESS_LOCAL, 5561 bytes)
17/01/29 05:06:21,982 INFO TaskSetManager: Starting task 6.0 in stage 3.0 (TID 125, 10.1.2.60, partition 6, PROCESS_LOCAL, 5561 bytes)
17/01/29 05:06:21,983 INFO TaskSetManager: Starting task 7.0 in stage 3.0 (TID 126, 10.1.2.152, partition 7, PROCESS_LOCAL, 5561 bytes)
17/01/29 05:06:21,983 INFO CoarseGrainedSchedulerBackend$DriverEndpoint: Launching task 119 on executor id: 1 hostname: 10.1.2.60.
17/01/29 05:06:21,984 INFO CoarseGrainedSchedulerBackend$DriverEndpoint: Launching task 121 on executor id: 1 hostname: 10.1.2.60.
17/01/29 05:06:21,984 INFO CoarseGrainedSchedulerBackend$DriverEndpoint: Launching task 123 on executor id: 1 hostname: 10.1.2.60.
17/01/29 05:06:21,985 INFO CoarseGrainedSchedulerBackend$DriverEndpoint: Launching task 125 on executor id: 1 hostname: 10.1.2.60.
17/01/29 05:06:21,985 INFO CoarseGrainedSchedulerBackend$DriverEndpoint: Launching task 120 on executor id: 0 hostname: 10.1.2.152.
17/01/29 05:06:21,986 INFO CoarseGrainedSchedulerBackend$DriverEndpoint: Launching task 122 on executor id: 0 hostname: 10.1.2.152.
17/01/29 05:06:21,986 INFO CoarseGrainedSchedulerBackend$DriverEndpoint: Launching task 124 on executor id: 0 hostname: 10.1.2.152.
17/01/29 05:06:21,987 INFO CoarseGrainedSchedulerBackend$DriverEndpoint: Launching task 126 on executor id: 0 hostname: 10.1.2.152.
17/01/29 05:06:22,006 INFO BlockManagerInfo: Added broadcast_5_piece0 in memory on 10.1.2.60:34100 (size: 3.7 KB, free: 89.8 MB)
17/01/29 05:06:22,007 INFO BlockManagerInfo: Added broadcast_5_piece0 in memory on 10.1.2.152:45056 (size: 3.7 KB, free: 92.3 MB)
17/01/29 05:06:22,297 INFO BlockManagerInfo: Added broadcast_4_piece0 in memory on 10.1.2.60:34100 (size: 153.0 B, free: 89.8 MB)
17/01/29 05:06:22,298 INFO BlockManagerInfo: Added broadcast_4_piece0 in memory on 10.1.2.152:45056 (size: 153.0 B, free: 92.3 MB)
17/01/29 05:06:22,482 INFO TaskSetManager: Starting task 9.0 in stage 3.0 (TID 127, 10.1.2.152, partition 9, PROCESS_LOCAL, 5561 bytes)
17/01/29 05:06:22,482 INFO CoarseGrainedSchedulerBackend$DriverEndpoint: Launching task 127 on executor id: 0 hostname: 10.1.2.152.
17/01/29 05:06:22,484 INFO TaskSetManager: Starting task 10.0 in stage 3.0 (TID 128, 10.1.2.152, partition 10, PROCESS_LOCAL, 5561 bytes)
17/01/29 05:06:22,485 INFO CoarseGrainedSchedulerBackend$DriverEndpoint: Launching task 128 on executor id: 0 hostname: 10.1.2.152.
17/01/29 05:06:22,485 INFO TaskSetManager: Finished task 1.0 in stage 3.0 (TID 120) in 506 ms on 10.1.2.152 (1/59)
17/01/29 05:06:22,485 INFO TaskSetManager: Finished task 3.0 in stage 3.0 (TID 122) in 505 ms on 10.1.2.152 (2/59)
17/01/29 05:06:22,489 INFO TaskSetManager: Starting task 11.0 in stage 3.0 (TID 129, 10.1.2.152, partition 11, PROCESS_LOCAL, 5561 bytes)
17/01/29 05:06:22,489 INFO CoarseGrainedSchedulerBackend$DriverEndpoint: Launching task 129 on executor id: 0 hostname: 10.1.2.152.
17/01/29 05:06:22,489 INFO TaskSetManager: Finished task 7.0 in stage 3.0 (TID 126) in 507 ms on 10.1.2.152 (3/59)
17/01/29 05:06:22,492 INFO TaskSetManager: Starting task 12.0 in stage 3.0 (TID 130, 10.1.2.152, partition 12, PROCESS_LOCAL, 5561 bytes)
17/01/29 05:06:22,492 INFO CoarseGrainedSchedulerBackend$DriverEndpoint: Launching task 130 on executor id: 0 hostname: 10.1.2.152.
17/01/29 05:06:22,492 INFO TaskSetManager: Finished task 5.0 in stage 3.0 (TID 124) in 511 ms on 10.1.2.152 (4/59)
17/01/29 05:06:22,540 INFO TaskSetManager: Starting task 8.0 in stage 3.0 (TID 131, 10.1.2.60, partition 8, PROCESS_LOCAL, 5561 bytes)
17/01/29 05:06:22,541 INFO CoarseGrainedSchedulerBackend$DriverEndpoint: Launching task 131 on executor id: 1 hostname: 10.1.2.60.
17/01/29 05:06:22,541 INFO TaskSetManager: Starting task 13.0 in stage 3.0 (TID 132, 10.1.2.60, partition 13, PROCESS_LOCAL, 5561 bytes)
17/01/29 05:06:22,542 INFO CoarseGrainedSchedulerBackend$DriverEndpoint: Launching task 132 on executor id: 1 hostname: 10.1.2.60.
17/01/29 05:06:22,542 INFO TaskSetManager: Starting task 14.0 in stage 3.0 (TID 133, 10.1.2.60, partition 14, PROCESS_LOCAL, 5561 bytes)
17/01/29 05:06:22,543 INFO CoarseGrainedSchedulerBackend$DriverEndpoint: Launching task 133 on executor id: 1 hostname: 10.1.2.60.
17/01/29 05:06:22,543 INFO TaskSetManager: Starting task 15.0 in stage 3.0 (TID 134, 10.1.2.60, partition 15, PROCESS_LOCAL, 5561 bytes)
17/01/29 05:06:22,544 INFO CoarseGrainedSchedulerBackend$DriverEndpoint: Launching task 134 on executor id: 1 hostname: 10.1.2.60.
17/01/29 05:06:22,545 INFO TaskSetManager: Finished task 4.0 in stage 3.0 (TID 123) in 564 ms on 10.1.2.60 (5/59)
17/01/29 05:06:22,546 INFO TaskSetManager: Finished task 0.0 in stage 3.0 (TID 119) in 568 ms on 10.1.2.60 (6/59)
17/01/29 05:06:22,548 INFO TaskSetManager: Finished task 2.0 in stage 3.0 (TID 121) in 567 ms on 10.1.2.60 (7/59)
17/01/29 05:06:22,548 INFO TaskSetManager: Finished task 6.0 in stage 3.0 (TID 125) in 566 ms on 10.1.2.60 (8/59)
17/01/29 05:06:22,559 INFO TaskSetManager: Starting task 17.0 in stage 3.0 (TID 135, 10.1.2.152, partition 17, PROCESS_LOCAL, 5561 bytes)
17/01/29 05:06:22,559 INFO CoarseGrainedSchedulerBackend$DriverEndpoint: Launching task 135 on executor id: 0 hostname: 10.1.2.152.
17/01/29 05:06:22,560 INFO TaskSetManager: Finished task 9.0 in stage 3.0 (TID 127) in 78 ms on 10.1.2.152 (9/59)
17/01/29 05:06:22,567 INFO TaskSetManager: Starting task 18.0 in stage 3.0 (TID 136, 10.1.2.152, partition 18, PROCESS_LOCAL, 5561 bytes)
17/01/29 05:06:22,567 INFO CoarseGrainedSchedulerBackend$DriverEndpoint: Launching task 136 on executor id: 0 hostname: 10.1.2.152.
17/01/29 05:06:22,568 INFO TaskSetManager: Finished task 11.0 in stage 3.0 (TID 129) in 79 ms on 10.1.2.152 (10/59)
17/01/29 05:06:22,569 INFO TaskSetManager: Starting task 19.0 in stage 3.0 (TID 137, 10.1.2.152, partition 19, PROCESS_LOCAL, 5561 bytes)
17/01/29 05:06:22,570 INFO CoarseGrainedSchedulerBackend$DriverEndpoint: Launching task 137 on executor id: 0 hostname: 10.1.2.152.
17/01/29 05:06:22,570 INFO TaskSetManager: Finished task 10.0 in stage 3.0 (TID 128) in 86 ms on 10.1.2.152 (11/59)
17/01/29 05:06:22,587 INFO TaskSetManager: Starting task 20.0 in stage 3.0 (TID 138, 10.1.2.152, partition 20, PROCESS_LOCAL, 5561 bytes)
17/01/29 05:06:22,587 INFO CoarseGrainedSchedulerBackend$DriverEndpoint: Launching task 138 on executor id: 0 hostname: 10.1.2.152.
17/01/29 05:06:22,587 INFO TaskSetManager: Finished task 12.0 in stage 3.0 (TID 130) in 96 ms on 10.1.2.152 (12/59)
17/01/29 05:06:22,625 INFO TaskSetManager: Starting task 24.0 in stage 3.0 (TID 139, 10.1.2.152, partition 24, PROCESS_LOCAL, 5561 bytes)
17/01/29 05:06:22,626 INFO CoarseGrainedSchedulerBackend$DriverEndpoint: Launching task 139 on executor id: 0 hostname: 10.1.2.152.
17/01/29 05:06:22,626 INFO TaskSetManager: Finished task 17.0 in stage 3.0 (TID 135) in 68 ms on 10.1.2.152 (13/59)
17/01/29 05:06:22,633 INFO TaskSetManager: Starting task 25.0 in stage 3.0 (TID 140, 10.1.2.152, partition 25, PROCESS_LOCAL, 5561 bytes)
17/01/29 05:06:22,634 INFO CoarseGrainedSchedulerBackend$DriverEndpoint: Launching task 140 on executor id: 0 hostname: 10.1.2.152.
17/01/29 05:06:22,634 INFO TaskSetManager: Finished task 18.0 in stage 3.0 (TID 136) in 68 ms on 10.1.2.152 (14/59)
17/01/29 05:06:22,635 INFO TaskSetManager: Starting task 27.0 in stage 3.0 (TID 141, 10.1.2.152, partition 27, PROCESS_LOCAL, 5561 bytes)
17/01/29 05:06:22,635 INFO CoarseGrainedSchedulerBackend$DriverEndpoint: Launching task 141 on executor id: 0 hostname: 10.1.2.152.
17/01/29 05:06:22,635 INFO TaskSetManager: Finished task 19.0 in stage 3.0 (TID 137) in 66 ms on 10.1.2.152 (15/59)
17/01/29 05:06:22,637 INFO TaskSetManager: Starting task 16.0 in stage 3.0 (TID 142, 10.1.2.60, partition 16, PROCESS_LOCAL, 5561 bytes)
17/01/29 05:06:22,637 INFO CoarseGrainedSchedulerBackend$DriverEndpoint: Launching task 142 on executor id: 1 hostname: 10.1.2.60.
17/01/29 05:06:22,638 INFO TaskSetManager: Finished task 8.0 in stage 3.0 (TID 131) in 98 ms on 10.1.2.60 (16/59)
17/01/29 05:06:22,639 INFO TaskSetManager: Starting task 21.0 in stage 3.0 (TID 143, 10.1.2.60, partition 21, PROCESS_LOCAL, 5561 bytes)
17/01/29 05:06:22,639 INFO CoarseGrainedSchedulerBackend$DriverEndpoint: Launching task 143 on executor id: 1 hostname: 10.1.2.60.
17/01/29 05:06:22,640 INFO TaskSetManager: Finished task 15.0 in stage 3.0 (TID 134) in 96 ms on 10.1.2.60 (17/59)
17/01/29 05:06:22,662 INFO TaskSetManager: Starting task 22.0 in stage 3.0 (TID 144, 10.1.2.60, partition 22, PROCESS_LOCAL, 5561 bytes)
17/01/29 05:06:22,662 INFO CoarseGrainedSchedulerBackend$DriverEndpoint: Launching task 144 on executor id: 1 hostname: 10.1.2.60.
17/01/29 05:06:22,663 INFO TaskSetManager: Finished task 14.0 in stage 3.0 (TID 133) in 121 ms on 10.1.2.60 (18/59)
17/01/29 05:06:22,673 INFO TaskSetManager: Starting task 28.0 in stage 3.0 (TID 145, 10.1.2.152, partition 28, PROCESS_LOCAL, 5561 bytes)
17/01/29 05:06:22,673 INFO CoarseGrainedSchedulerBackend$DriverEndpoint: Launching task 145 on executor id: 0 hostname: 10.1.2.152.
17/01/29 05:06:22,674 INFO TaskSetManager: Finished task 20.0 in stage 3.0 (TID 138) in 87 ms on 10.1.2.152 (19/59)
17/01/29 05:06:22,686 INFO TaskSetManager: Starting task 23.0 in stage 3.0 (TID 146, 10.1.2.60, partition 23, PROCESS_LOCAL, 5561 bytes)
17/01/29 05:06:22,686 INFO CoarseGrainedSchedulerBackend$DriverEndpoint: Launching task 146 on executor id: 1 hostname: 10.1.2.60.
17/01/29 05:06:22,686 INFO TaskSetManager: Finished task 13.0 in stage 3.0 (TID 132) in 145 ms on 10.1.2.60 (20/59)
17/01/29 05:06:22,690 INFO TaskSetManager: Starting task 32.0 in stage 3.0 (TID 147, 10.1.2.152, partition 32, PROCESS_LOCAL, 5561 bytes)
17/01/29 05:06:22,690 INFO CoarseGrainedSchedulerBackend$DriverEndpoint: Launching task 147 on executor id: 0 hostname: 10.1.2.152.
17/01/29 05:06:22,690 INFO TaskSetManager: Finished task 24.0 in stage 3.0 (TID 139) in 65 ms on 10.1.2.152 (21/59)
17/01/29 05:06:22,695 INFO TaskSetManager: Starting task 33.0 in stage 3.0 (TID 148, 10.1.2.152, partition 33, PROCESS_LOCAL, 5561 bytes)
17/01/29 05:06:22,695 INFO CoarseGrainedSchedulerBackend$DriverEndpoint: Launching task 148 on executor id: 0 hostname: 10.1.2.152.
17/01/29 05:06:22,696 INFO TaskSetManager: Finished task 25.0 in stage 3.0 (TID 140) in 63 ms on 10.1.2.152 (22/59)
17/01/29 05:06:22,700 INFO TaskSetManager: Starting task 34.0 in stage 3.0 (TID 149, 10.1.2.152, partition 34, PROCESS_LOCAL, 5561 bytes)
17/01/29 05:06:22,701 INFO CoarseGrainedSchedulerBackend$DriverEndpoint: Launching task 149 on executor id: 0 hostname: 10.1.2.152.
17/01/29 05:06:22,701 INFO TaskSetManager: Finished task 27.0 in stage 3.0 (TID 141) in 67 ms on 10.1.2.152 (23/59)
17/01/29 05:06:22,741 INFO TaskSetManager: Starting task 26.0 in stage 3.0 (TID 150, 10.1.2.60, partition 26, PROCESS_LOCAL, 5561 bytes)
17/01/29 05:06:22,742 INFO CoarseGrainedSchedulerBackend$DriverEndpoint: Launching task 150 on executor id: 1 hostname: 10.1.2.60.
17/01/29 05:06:22,742 INFO TaskSetManager: Finished task 21.0 in stage 3.0 (TID 143) in 103 ms on 10.1.2.60 (24/59)
17/01/29 05:06:22,743 INFO TaskSetManager: Starting task 29.0 in stage 3.0 (TID 151, 10.1.2.60, partition 29, PROCESS_LOCAL, 5561 bytes)
17/01/29 05:06:22,743 INFO CoarseGrainedSchedulerBackend$DriverEndpoint: Launching task 151 on executor id: 1 hostname: 10.1.2.60.
17/01/29 05:06:22,744 INFO TaskSetManager: Finished task 16.0 in stage 3.0 (TID 142) in 107 ms on 10.1.2.60 (25/59)
17/01/29 05:06:22,756 INFO TaskSetManager: Starting task 36.0 in stage 3.0 (TID 152, 10.1.2.152, partition 36, PROCESS_LOCAL, 5561 bytes)
17/01/29 05:06:22,756 INFO CoarseGrainedSchedulerBackend$DriverEndpoint: Launching task 152 on executor id: 0 hostname: 10.1.2.152.
17/01/29 05:06:22,756 INFO TaskSetManager: Finished task 33.0 in stage 3.0 (TID 148) in 62 ms on 10.1.2.152 (26/59)
17/01/29 05:06:22,757 INFO TaskSetManager: Starting task 40.0 in stage 3.0 (TID 153, 10.1.2.152, partition 40, PROCESS_LOCAL, 5561 bytes)
17/01/29 05:06:22,758 INFO CoarseGrainedSchedulerBackend$DriverEndpoint: Launching task 153 on executor id: 0 hostname: 10.1.2.152.
17/01/29 05:06:22,758 INFO TaskSetManager: Finished task 28.0 in stage 3.0 (TID 145) in 85 ms on 10.1.2.152 (27/59)
17/01/29 05:06:22,759 INFO TaskSetManager: Starting task 30.0 in stage 3.0 (TID 154, 10.1.2.60, partition 30, PROCESS_LOCAL, 5561 bytes)
17/01/29 05:06:22,759 INFO TaskSetManager: Finished task 23.0 in stage 3.0 (TID 146) in 74 ms on 10.1.2.60 (28/59)
17/01/29 05:06:22,759 INFO CoarseGrainedSchedulerBackend$DriverEndpoint: Launching task 154 on executor id: 1 hostname: 10.1.2.60.
17/01/29 05:06:22,760 INFO TaskSetManager: Starting task 31.0 in stage 3.0 (TID 155, 10.1.2.60, partition 31, PROCESS_LOCAL, 5561 bytes)
17/01/29 05:06:22,761 INFO CoarseGrainedSchedulerBackend$DriverEndpoint: Launching task 155 on executor id: 1 hostname: 10.1.2.60.
17/01/29 05:06:22,761 INFO TaskSetManager: Finished task 22.0 in stage 3.0 (TID 144) in 100 ms on 10.1.2.60 (29/59)
17/01/29 05:06:22,775 INFO TaskSetManager: Starting task 41.0 in stage 3.0 (TID 156, 10.1.2.152, partition 41, PROCESS_LOCAL, 5561 bytes)
17/01/29 05:06:22,775 INFO CoarseGrainedSchedulerBackend$DriverEndpoint: Launching task 156 on executor id: 0 hostname: 10.1.2.152.
17/01/29 05:06:22,775 INFO TaskSetManager: Finished task 34.0 in stage 3.0 (TID 149) in 75 ms on 10.1.2.152 (30/59)
17/01/29 05:06:22,786 INFO TaskSetManager: Starting task 42.0 in stage 3.0 (TID 157, 10.1.2.152, partition 42, PROCESS_LOCAL, 5561 bytes)
17/01/29 05:06:22,786 INFO CoarseGrainedSchedulerBackend$DriverEndpoint: Launching task 157 on executor id: 0 hostname: 10.1.2.152.
17/01/29 05:06:22,787 INFO TaskSetManager: Finished task 32.0 in stage 3.0 (TID 147) in 97 ms on 10.1.2.152 (31/59)
17/01/29 05:06:22,817 INFO TaskSetManager: Starting task 35.0 in stage 3.0 (TID 158, 10.1.2.60, partition 35, PROCESS_LOCAL, 5561 bytes)
17/01/29 05:06:22,817 INFO CoarseGrainedSchedulerBackend$DriverEndpoint: Launching task 158 on executor id: 1 hostname: 10.1.2.60.
17/01/29 05:06:22,817 INFO TaskSetManager: Finished task 29.0 in stage 3.0 (TID 151) in 74 ms on 10.1.2.60 (32/59)
17/01/29 05:06:22,819 INFO TaskSetManager: Starting task 37.0 in stage 3.0 (TID 159, 10.1.2.60, partition 37, PROCESS_LOCAL, 5561 bytes)
17/01/29 05:06:22,820 INFO CoarseGrainedSchedulerBackend$DriverEndpoint: Launching task 159 on executor id: 1 hostname: 10.1.2.60.
17/01/29 05:06:22,820 INFO TaskSetManager: Finished task 26.0 in stage 3.0 (TID 150) in 79 ms on 10.1.2.60 (33/59)
17/01/29 05:06:22,839 INFO TaskSetManager: Starting task 38.0 in stage 3.0 (TID 160, 10.1.2.60, partition 38, PROCESS_LOCAL, 5561 bytes)
17/01/29 05:06:22,839 INFO CoarseGrainedSchedulerBackend$DriverEndpoint: Launching task 160 on executor id: 1 hostname: 10.1.2.60.
17/01/29 05:06:22,840 INFO TaskSetManager: Finished task 31.0 in stage 3.0 (TID 155) in 79 ms on 10.1.2.60 (34/59)
17/01/29 05:06:22,842 INFO TaskSetManager: Starting task 39.0 in stage 3.0 (TID 161, 10.1.2.60, partition 39, PROCESS_LOCAL, 5561 bytes)
17/01/29 05:06:22,842 INFO CoarseGrainedSchedulerBackend$DriverEndpoint: Launching task 161 on executor id: 1 hostname: 10.1.2.60.
17/01/29 05:06:22,842 INFO TaskSetManager: Finished task 30.0 in stage 3.0 (TID 154) in 84 ms on 10.1.2.60 (35/59)
17/01/29 05:06:22,912 INFO TaskSetManager: Starting task 43.0 in stage 3.0 (TID 162, 10.1.2.152, partition 43, PROCESS_LOCAL, 5561 bytes)
17/01/29 05:06:22,912 INFO CoarseGrainedSchedulerBackend$DriverEndpoint: Launching task 162 on executor id: 0 hostname: 10.1.2.152.
17/01/29 05:06:22,912 INFO TaskSetManager: Finished task 41.0 in stage 3.0 (TID 156) in 138 ms on 10.1.2.152 (36/59)
17/01/29 05:06:22,913 INFO TaskSetManager: Starting task 48.0 in stage 3.0 (TID 163, 10.1.2.152, partition 48, PROCESS_LOCAL, 5561 bytes)
17/01/29 05:06:22,914 INFO CoarseGrainedSchedulerBackend$DriverEndpoint: Launching task 163 on executor id: 0 hostname: 10.1.2.152.
17/01/29 05:06:22,914 INFO TaskSetManager: Finished task 40.0 in stage 3.0 (TID 153) in 157 ms on 10.1.2.152 (37/59)
17/01/29 05:06:22,916 INFO TaskSetManager: Starting task 44.0 in stage 3.0 (TID 164, 10.1.2.60, partition 44, PROCESS_LOCAL, 5561 bytes)
17/01/29 05:06:22,917 INFO CoarseGrainedSchedulerBackend$DriverEndpoint: Launching task 164 on executor id: 1 hostname: 10.1.2.60.
17/01/29 05:06:22,917 INFO TaskSetManager: Finished task 38.0 in stage 3.0 (TID 160) in 79 ms on 10.1.2.60 (38/59)
17/01/29 05:06:22,919 INFO TaskSetManager: Starting task 50.0 in stage 3.0 (TID 165, 10.1.2.152, partition 50, PROCESS_LOCAL, 5561 bytes)
17/01/29 05:06:22,920 INFO CoarseGrainedSchedulerBackend$DriverEndpoint: Launching task 165 on executor id: 0 hostname: 10.1.2.152.
17/01/29 05:06:22,920 INFO TaskSetManager: Finished task 42.0 in stage 3.0 (TID 157) in 135 ms on 10.1.2.152 (39/59)
17/01/29 05:06:22,922 INFO TaskSetManager: Starting task 45.0 in stage 3.0 (TID 166, 10.1.2.60, partition 45, PROCESS_LOCAL, 5561 bytes)
17/01/29 05:06:22,922 INFO CoarseGrainedSchedulerBackend$DriverEndpoint: Launching task 166 on executor id: 1 hostname: 10.1.2.60.
17/01/29 05:06:22,922 INFO TaskSetManager: Finished task 37.0 in stage 3.0 (TID 159) in 103 ms on 10.1.2.60 (40/59)
17/01/29 05:06:22,928 INFO TaskSetManager: Starting task 46.0 in stage 3.0 (TID 167, 10.1.2.60, partition 46, PROCESS_LOCAL, 5561 bytes)
17/01/29 05:06:22,928 INFO TaskSetManager: Finished task 39.0 in stage 3.0 (TID 161) in 87 ms on 10.1.2.60 (41/59)
17/01/29 05:06:22,928 INFO CoarseGrainedSchedulerBackend$DriverEndpoint: Launching task 167 on executor id: 1 hostname: 10.1.2.60.
17/01/29 05:06:22,929 INFO TaskSetManager: Finished task 36.0 in stage 3.0 (TID 152) in 174 ms on 10.1.2.152 (42/59)
17/01/29 05:06:22,930 INFO TaskSetManager: Starting task 52.0 in stage 3.0 (TID 168, 10.1.2.152, partition 52, PROCESS_LOCAL, 5561 bytes)
17/01/29 05:06:22,930 INFO CoarseGrainedSchedulerBackend$DriverEndpoint: Launching task 168 on executor id: 0 hostname: 10.1.2.152.
17/01/29 05:06:22,931 INFO TaskSetManager: Starting task 47.0 in stage 3.0 (TID 169, 10.1.2.60, partition 47, PROCESS_LOCAL, 5561 bytes)
17/01/29 05:06:22,932 INFO TaskSetManager: Finished task 35.0 in stage 3.0 (TID 158) in 116 ms on 10.1.2.60 (43/59)
17/01/29 05:06:22,932 INFO CoarseGrainedSchedulerBackend$DriverEndpoint: Launching task 169 on executor id: 1 hostname: 10.1.2.60.
17/01/29 05:06:22,990 INFO TaskSetManager: Starting task 53.0 in stage 3.0 (TID 170, 10.1.2.152, partition 53, PROCESS_LOCAL, 5561 bytes)
17/01/29 05:06:22,990 INFO CoarseGrainedSchedulerBackend$DriverEndpoint: Launching task 170 on executor id: 0 hostname: 10.1.2.152.
17/01/29 05:06:22,991 INFO TaskSetManager: Finished task 52.0 in stage 3.0 (TID 168) in 61 ms on 10.1.2.152 (44/59)
17/01/29 05:06:22,998 INFO TaskSetManager: Starting task 49.0 in stage 3.0 (TID 171, 10.1.2.60, partition 49, PROCESS_LOCAL, 5561 bytes)
17/01/29 05:06:22,998 INFO TaskSetManager: Finished task 44.0 in stage 3.0 (TID 164) in 82 ms on 10.1.2.60 (45/59)
17/01/29 05:06:22,998 INFO CoarseGrainedSchedulerBackend$DriverEndpoint: Launching task 171 on executor id: 1 hostname: 10.1.2.60.
17/01/29 05:06:23,000 INFO TaskSetManager: Finished task 45.0 in stage 3.0 (TID 166) in 78 ms on 10.1.2.60 (46/59)
17/01/29 05:06:23,001 INFO TaskSetManager: Starting task 51.0 in stage 3.0 (TID 172, 10.1.2.60, partition 51, PROCESS_LOCAL, 5561 bytes)
17/01/29 05:06:23,001 INFO CoarseGrainedSchedulerBackend$DriverEndpoint: Launching task 172 on executor id: 1 hostname: 10.1.2.60.
17/01/29 05:06:23,007 INFO TaskSetManager: Starting task 57.0 in stage 3.0 (TID 173, 10.1.2.152, partition 57, PROCESS_LOCAL, 5561 bytes)
17/01/29 05:06:23,007 INFO CoarseGrainedSchedulerBackend$DriverEndpoint: Launching task 173 on executor id: 0 hostname: 10.1.2.152.
17/01/29 05:06:23,007 INFO TaskSetManager: Finished task 50.0 in stage 3.0 (TID 165) in 88 ms on 10.1.2.152 (47/59)
17/01/29 05:06:23,008 INFO TaskSetManager: Finished task 48.0 in stage 3.0 (TID 163) in 95 ms on 10.1.2.152 (48/59)
17/01/29 05:06:23,010 INFO TaskSetManager: Starting task 54.0 in stage 3.0 (TID 174, 10.1.2.60, partition 54, PROCESS_LOCAL, 5561 bytes)
17/01/29 05:06:23,010 INFO CoarseGrainedSchedulerBackend$DriverEndpoint: Launching task 174 on executor id: 1 hostname: 10.1.2.60.
17/01/29 05:06:23,011 INFO TaskSetManager: Finished task 46.0 in stage 3.0 (TID 167) in 83 ms on 10.1.2.60 (49/59)
17/01/29 05:06:23,018 INFO TaskSetManager: Finished task 43.0 in stage 3.0 (TID 162) in 107 ms on 10.1.2.152 (50/59)
17/01/29 05:06:23,023 INFO TaskSetManager: Starting task 56.0 in stage 3.0 (TID 175, 10.1.2.60, partition 56, PROCESS_LOCAL, 5561 bytes)
17/01/29 05:06:23,024 INFO CoarseGrainedSchedulerBackend$DriverEndpoint: Launching task 175 on executor id: 1 hostname: 10.1.2.60.
17/01/29 05:06:23,024 INFO TaskSetManager: Finished task 47.0 in stage 3.0 (TID 169) in 93 ms on 10.1.2.60 (51/59)
17/01/29 05:06:23,056 INFO TaskSetManager: Finished task 53.0 in stage 3.0 (TID 170) in 67 ms on 10.1.2.152 (52/59)
17/01/29 05:06:23,062 INFO TaskSetManager: Starting task 58.0 in stage 3.0 (TID 176, 10.1.2.60, partition 58, PROCESS_LOCAL, 5561 bytes)
17/01/29 05:06:23,063 INFO CoarseGrainedSchedulerBackend$DriverEndpoint: Launching task 176 on executor id: 1 hostname: 10.1.2.60.
17/01/29 05:06:23,063 INFO TaskSetManager: Finished task 51.0 in stage 3.0 (TID 172) in 63 ms on 10.1.2.60 (53/59)
17/01/29 05:06:23,079 INFO TaskSetManager: Finished task 57.0 in stage 3.0 (TID 173) in 73 ms on 10.1.2.152 (54/59)
17/01/29 05:06:23,084 INFO TaskSetManager: Finished task 54.0 in stage 3.0 (TID 174) in 75 ms on 10.1.2.60 (55/59)
17/01/29 05:06:23,086 INFO TaskSetManager: Finished task 49.0 in stage 3.0 (TID 171) in 89 ms on 10.1.2.60 (56/59)
17/01/29 05:06:23,093 INFO TaskSetManager: Finished task 56.0 in stage 3.0 (TID 175) in 70 ms on 10.1.2.60 (57/59)
17/01/29 05:06:23,131 INFO TaskSetManager: Finished task 58.0 in stage 3.0 (TID 176) in 69 ms on 10.1.2.60 (58/59)
17/01/29 05:06:26,971 INFO TaskSetManager: Starting task 55.0 in stage 3.0 (TID 177, 10.1.2.152, partition 55, ANY, 5561 bytes)
17/01/29 05:06:26,972 INFO CoarseGrainedSchedulerBackend$DriverEndpoint: Launching task 177 on executor id: 0 hostname: 10.1.2.152.
17/01/29 05:06:32,900 INFO TaskSetManager: Finished task 55.0 in stage 3.0 (TID 177) in 5930 ms on 10.1.2.152 (59/59)
17/01/29 05:06:32,901 INFO TaskSchedulerImpl: Removed TaskSet 3.0, whose tasks have all completed, from pool 
17/01/29 05:06:32,902 INFO DAGScheduler: ShuffleMapStage 3 (treeAggregate at GradientDescent.scala:239) finished in 10.926 s
17/01/29 05:06:32,903 INFO DAGScheduler: looking for newly runnable stages
17/01/29 05:06:32,903 INFO DAGScheduler: running: Set()
17/01/29 05:06:32,908 INFO DAGScheduler: waiting: Set(ResultStage 4)
17/01/29 05:06:32,909 INFO DAGScheduler: failed: Set()
17/01/29 05:06:32,911 INFO DAGScheduler: Submitting ResultStage 4 (MapPartitionsRDD[13] at treeAggregate at GradientDescent.scala:239), which has no missing parents
17/01/29 05:06:32,916 INFO MemoryStore: Block broadcast_6 stored as values in memory (estimated size 3.1 KB, free 2.1 GB)
17/01/29 05:06:32,925 INFO MemoryStore: Block broadcast_6_piece0 stored as bytes in memory (estimated size 1893.0 B, free 2.1 GB)
17/01/29 05:06:32,926 INFO BlockManagerInfo: Added broadcast_6_piece0 in memory on 10.1.2.31:45152 (size: 1893.0 B, free: 2.1 GB)
17/01/29 05:06:32,926 INFO SparkContext: Created broadcast 6 from broadcast at DAGScheduler.scala:1012
17/01/29 05:06:32,927 INFO DAGScheduler: Submitting 7 missing tasks from ResultStage 4 (MapPartitionsRDD[13] at treeAggregate at GradientDescent.scala:239)
17/01/29 05:06:32,927 INFO TaskSchedulerImpl: Adding task set 4.0 with 7 tasks
17/01/29 05:06:32,929 INFO TaskSetManager: Starting task 0.0 in stage 4.0 (TID 178, 10.1.2.60, partition 0, NODE_LOCAL, 5227 bytes)
17/01/29 05:06:32,930 INFO TaskSetManager: Starting task 1.0 in stage 4.0 (TID 179, 10.1.2.152, partition 1, NODE_LOCAL, 5227 bytes)
17/01/29 05:06:32,931 INFO TaskSetManager: Starting task 2.0 in stage 4.0 (TID 180, 10.1.2.60, partition 2, NODE_LOCAL, 5227 bytes)
17/01/29 05:06:32,932 INFO TaskSetManager: Starting task 3.0 in stage 4.0 (TID 181, 10.1.2.152, partition 3, NODE_LOCAL, 5227 bytes)
17/01/29 05:06:32,935 INFO TaskSetManager: Starting task 4.0 in stage 4.0 (TID 182, 10.1.2.60, partition 4, NODE_LOCAL, 5227 bytes)
17/01/29 05:06:32,936 INFO TaskSetManager: Starting task 5.0 in stage 4.0 (TID 183, 10.1.2.152, partition 5, NODE_LOCAL, 5227 bytes)
17/01/29 05:06:32,936 INFO TaskSetManager: Starting task 6.0 in stage 4.0 (TID 184, 10.1.2.60, partition 6, NODE_LOCAL, 5227 bytes)
17/01/29 05:06:32,937 INFO CoarseGrainedSchedulerBackend$DriverEndpoint: Launching task 178 on executor id: 1 hostname: 10.1.2.60.
17/01/29 05:06:32,937 INFO CoarseGrainedSchedulerBackend$DriverEndpoint: Launching task 180 on executor id: 1 hostname: 10.1.2.60.
17/01/29 05:06:32,937 INFO CoarseGrainedSchedulerBackend$DriverEndpoint: Launching task 182 on executor id: 1 hostname: 10.1.2.60.
17/01/29 05:06:32,938 INFO CoarseGrainedSchedulerBackend$DriverEndpoint: Launching task 184 on executor id: 1 hostname: 10.1.2.60.
17/01/29 05:06:32,938 INFO CoarseGrainedSchedulerBackend$DriverEndpoint: Launching task 179 on executor id: 0 hostname: 10.1.2.152.
17/01/29 05:06:32,939 INFO CoarseGrainedSchedulerBackend$DriverEndpoint: Launching task 181 on executor id: 0 hostname: 10.1.2.152.
17/01/29 05:06:32,939 INFO CoarseGrainedSchedulerBackend$DriverEndpoint: Launching task 183 on executor id: 0 hostname: 10.1.2.152.
17/01/29 05:06:32,958 INFO BlockManagerInfo: Added broadcast_6_piece0 in memory on 10.1.2.152:45056 (size: 1893.0 B, free: 92.3 MB)
17/01/29 05:06:32,959 INFO BlockManagerInfo: Added broadcast_6_piece0 in memory on 10.1.2.60:34100 (size: 1893.0 B, free: 89.7 MB)
17/01/29 05:06:32,977 INFO MapOutputTrackerMasterEndpoint: Asked to send map output locations for shuffle 0 to 10.1.2.152:43022
17/01/29 05:06:32,980 INFO MapOutputTrackerMasterEndpoint: Asked to send map output locations for shuffle 0 to 10.1.2.60:34908
17/01/29 05:06:32,981 INFO MapOutputTrackerMaster: Size of output statuses for shuffle 0 is 275 bytes
17/01/29 05:06:33,043 INFO TaskSetManager: Finished task 5.0 in stage 4.0 (TID 183) in 108 ms on 10.1.2.152 (1/7)
17/01/29 05:06:33,044 INFO TaskSetManager: Finished task 1.0 in stage 4.0 (TID 179) in 114 ms on 10.1.2.152 (2/7)
17/01/29 05:06:33,045 INFO TaskSetManager: Finished task 3.0 in stage 4.0 (TID 181) in 114 ms on 10.1.2.152 (3/7)
17/01/29 05:06:33,053 INFO TaskSetManager: Finished task 4.0 in stage 4.0 (TID 182) in 121 ms on 10.1.2.60 (4/7)
17/01/29 05:06:33,057 INFO TaskSetManager: Finished task 2.0 in stage 4.0 (TID 180) in 127 ms on 10.1.2.60 (5/7)
17/01/29 05:06:33,057 INFO TaskSetManager: Finished task 0.0 in stage 4.0 (TID 178) in 129 ms on 10.1.2.60 (6/7)
17/01/29 05:06:33,059 INFO TaskSetManager: Finished task 6.0 in stage 4.0 (TID 184) in 123 ms on 10.1.2.60 (7/7)
17/01/29 05:06:33,059 INFO TaskSchedulerImpl: Removed TaskSet 4.0, whose tasks have all completed, from pool 
17/01/29 05:06:33,060 INFO DAGScheduler: ResultStage 4 (treeAggregate at GradientDescent.scala:239) finished in 0.132 s
17/01/29 05:06:33,060 INFO DAGScheduler: Job 3 finished: treeAggregate at GradientDescent.scala:239, took 11.120463 s
17/01/29 05:06:33,063 INFO MemoryStore: Block broadcast_7 stored as values in memory (estimated size 280.0 B, free 2.1 GB)
17/01/29 05:06:33,065 INFO MemoryStore: Block broadcast_7_piece0 stored as bytes in memory (estimated size 365.0 B, free 2.1 GB)
17/01/29 05:06:33,065 INFO BlockManagerInfo: Added broadcast_7_piece0 in memory on 10.1.2.31:45152 (size: 365.0 B, free: 2.1 GB)
17/01/29 05:06:33,066 INFO SparkContext: Created broadcast 7 from broadcast at GradientDescent.scala:235
17/01/29 05:06:33,084 INFO SparkContext: Starting job: treeAggregate at GradientDescent.scala:239
17/01/29 05:06:33,085 INFO DAGScheduler: Registering RDD 16 (treeAggregate at GradientDescent.scala:239)
17/01/29 05:06:33,086 INFO DAGScheduler: Got job 4 (treeAggregate at GradientDescent.scala:239) with 7 output partitions
17/01/29 05:06:33,086 INFO DAGScheduler: Final stage: ResultStage 6 (treeAggregate at GradientDescent.scala:239)
17/01/29 05:06:33,086 INFO DAGScheduler: Parents of final stage: List(ShuffleMapStage 5)
17/01/29 05:06:33,086 INFO DAGScheduler: Missing parents: List(ShuffleMapStage 5)
17/01/29 05:06:33,090 INFO DAGScheduler: Submitting ShuffleMapStage 5 (MapPartitionsRDD[16] at treeAggregate at GradientDescent.scala:239), which has no missing parents
17/01/29 05:06:33,100 INFO MemoryStore: Block broadcast_8 stored as values in memory (estimated size 7.2 KB, free 2.1 GB)
17/01/29 05:06:33,101 INFO MemoryStore: Block broadcast_8_piece0 stored as bytes in memory (estimated size 3.7 KB, free 2.1 GB)
17/01/29 05:06:33,102 INFO BlockManagerInfo: Added broadcast_8_piece0 in memory on 10.1.2.31:45152 (size: 3.7 KB, free: 2.1 GB)
17/01/29 05:06:33,102 INFO SparkContext: Created broadcast 8 from broadcast at DAGScheduler.scala:1012
17/01/29 05:06:33,103 INFO DAGScheduler: Submitting 59 missing tasks from ShuffleMapStage 5 (MapPartitionsRDD[16] at treeAggregate at GradientDescent.scala:239)
17/01/29 05:06:33,104 INFO TaskSchedulerImpl: Adding task set 5.0 with 59 tasks
17/01/29 05:06:33,106 INFO TaskSetManager: Starting task 1.0 in stage 5.0 (TID 185, 10.1.2.152, partition 1, PROCESS_LOCAL, 5561 bytes)
17/01/29 05:06:33,107 INFO TaskSetManager: Starting task 0.0 in stage 5.0 (TID 186, 10.1.2.60, partition 0, PROCESS_LOCAL, 5561 bytes)
17/01/29 05:06:33,107 INFO TaskSetManager: Starting task 3.0 in stage 5.0 (TID 187, 10.1.2.152, partition 3, PROCESS_LOCAL, 5561 bytes)
17/01/29 05:06:33,107 INFO TaskSetManager: Starting task 2.0 in stage 5.0 (TID 188, 10.1.2.60, partition 2, PROCESS_LOCAL, 5561 bytes)
17/01/29 05:06:33,108 INFO TaskSetManager: Starting task 5.0 in stage 5.0 (TID 189, 10.1.2.152, partition 5, PROCESS_LOCAL, 5561 bytes)
17/01/29 05:06:33,108 INFO TaskSetManager: Starting task 4.0 in stage 5.0 (TID 190, 10.1.2.60, partition 4, PROCESS_LOCAL, 5561 bytes)
17/01/29 05:06:33,109 INFO TaskSetManager: Starting task 7.0 in stage 5.0 (TID 191, 10.1.2.152, partition 7, PROCESS_LOCAL, 5561 bytes)
