Using properties file: /home/ubuntu/spark-2.0.0/conf/spark-defaults.conf
Adding default property: spark.driver.extraJavaOptions=-XX:+PrintGCDetails -XX:+PrintGCTimeStamps -Xms4000m -Dlog4j.configuration=file:///home/ubuntu/spark-2.0.0/conf/log4j.properties
Adding default property: spark.executor.extraJavaOptions=-XX:+PrintGCDetails -XX:+PrintGCTimeStamps -Xms4000m -Dlog4j.configuration=file:///home/ubuntu/spark-2.0.0/conf/log4j.properties
Parsed arguments:
  master                  spark://euca-10-1-2-31:7077
  deployMode              client
  executorMemory          4000m
  executorCores           null
  totalExecutorCores      null
  propertiesFile          /home/ubuntu/spark-2.0.0/conf/spark-defaults.conf
  driverMemory            4000m
  driverCores             null
  driverExtraClassPath    null
  driverExtraLibraryPath  null
  driverExtraJavaOptions  -XX:+PrintGCDetails -XX:+PrintGCTimeStamps -Xms4000m -Dlog4j.configuration=file:///home/ubuntu/spark-2.0.0/conf/log4j.properties
  supervise               false
  queue                   null
  numExecutors            2
  files                   null
  pyFiles                 null
  archives                null
  mainClass               LogRegExplicitParallelism
  primaryResource         file:///home/ubuntu/jars/log-reg-explicit-parallelism_2.11-1.0.jar
  name                    LogRegExplicitParallelism
  childArgs               [cluster 28 euca-10-1-2-31 9000 higgs_0_exp 5 8]
  jars                    null
  packages                null
  packagesExclusions      null
  repositories            null
  verbose                 true

Spark properties used, including those specified through
 --conf and those from the properties file /home/ubuntu/spark-2.0.0/conf/spark-defaults.conf:
  spark.default.parallelism -> 8
  spark.driver.memory -> 4000m
  spark.executor.extraJavaOptions -> -XX:+PrintGCDetails -XX:+PrintGCTimeStamps -Xms4000m -Dlog4j.configuration=file:///home/ubuntu/spark-2.0.0/conf/log4j.properties
  spark.driver.extraJavaOptions -> -XX:+PrintGCDetails -XX:+PrintGCTimeStamps -Xms4000m -Dlog4j.configuration=file:///home/ubuntu/spark-2.0.0/conf/log4j.properties
  spark.shuffle.spill -> false

    
Main class:
LogRegExplicitParallelism
Arguments:
cluster
28
euca-10-1-2-31
9000
higgs_0_exp
5
8
System properties:
spark.default.parallelism -> 8
spark.executor.memory -> 4000m
spark.driver.memory -> 4000m
SPARK_SUBMIT -> true
spark.executor.extraJavaOptions -> -XX:+PrintGCDetails -XX:+PrintGCTimeStamps -Xms4000m -Dlog4j.configuration=file:///home/ubuntu/spark-2.0.0/conf/log4j.properties
spark.app.name -> LogRegExplicitParallelism
spark.shuffle.spill -> false
spark.driver.extraJavaOptions -> -XX:+PrintGCDetails -XX:+PrintGCTimeStamps -Xms4000m -Dlog4j.configuration=file:///home/ubuntu/spark-2.0.0/conf/log4j.properties
spark.jars -> file:///home/ubuntu/jars/log-reg-explicit-parallelism_2.11-1.0.jar
spark.submit.deployMode -> client
spark.master -> spark://euca-10-1-2-31:7077
Classpath elements:
file:///home/ubuntu/jars/log-reg-explicit-parallelism_2.11-1.0.jar


17/01/29 04:50:14,427 INFO SparkContext: Running Spark version 2.0.0
17/01/29 04:50:14,758 WARN NativeCodeLoader: Unable to load native-hadoop library for your platform... using builtin-java classes where applicable
17/01/29 04:50:14,917 INFO SecurityManager: Changing view acls to: ubuntu
17/01/29 04:50:14,917 INFO SecurityManager: Changing modify acls to: ubuntu
17/01/29 04:50:14,918 INFO SecurityManager: Changing view acls groups to: 
17/01/29 04:50:14,918 INFO SecurityManager: Changing modify acls groups to: 
17/01/29 04:50:14,919 INFO SecurityManager: SecurityManager: authentication disabled; ui acls disabled; users  with view permissions: Set(ubuntu); groups with view permissions: Set(); users  with modify permissions: Set(ubuntu); groups with modify permissions: Set()
17/01/29 04:50:15,225 INFO Utils: Successfully started service 'sparkDriver' on port 34900.
17/01/29 04:50:15,243 INFO SparkEnv: Registering MapOutputTracker
17/01/29 04:50:15,248 WARN SortShuffleManager: spark.shuffle.spill was set to false, but this configuration is ignored as of Spark 1.6+. Shuffle will continue to spill to disk when necessary.
17/01/29 04:50:15,259 INFO SparkEnv: Registering BlockManagerMaster
17/01/29 04:50:15,271 INFO DiskBlockManager: Created local directory at /tmp/blockmgr-af04d661-aa42-4235-8d45-f48547f4de88
17/01/29 04:50:15,288 INFO MemoryStore: MemoryStore started with capacity 2.1 GB
17/01/29 04:50:15,339 INFO SparkEnv: Registering OutputCommitCoordinator
17/01/29 04:50:15,533 INFO Utils: Successfully started service 'SparkUI' on port 4040.
17/01/29 04:50:15,535 INFO SparkUI: Bound SparkUI to 10.1.2.31, and started at http://10.1.2.31:4040
17/01/29 04:50:15,567 INFO SparkContext: Added JAR file:///home/ubuntu/jars/log-reg-explicit-parallelism_2.11-1.0.jar at spark://10.1.2.31:34900/jars/log-reg-explicit-parallelism_2.11-1.0.jar with timestamp 1485665415567
17/01/29 04:50:15,643 INFO StandaloneAppClient$ClientEndpoint: Connecting to master spark://euca-10-1-2-31:7077...
17/01/29 04:50:15,697 INFO TransportClientFactory: Successfully created connection to euca-10-1-2-31/10.1.2.31:7077 after 26 ms (0 ms spent in bootstraps)
17/01/29 04:50:15,810 INFO StandaloneSchedulerBackend: Connected to Spark cluster with app ID app-20170129045015-0000
17/01/29 04:50:15,816 INFO Utils: Successfully started service 'org.apache.spark.network.netty.NettyBlockTransferService' on port 36764.
17/01/29 04:50:15,817 INFO NettyBlockTransferService: Server created on 10.1.2.31:36764
17/01/29 04:50:15,819 INFO BlockManagerMaster: Registering BlockManager BlockManagerId(driver, 10.1.2.31, 36764)
17/01/29 04:50:15,821 INFO BlockManagerMasterEndpoint: Registering block manager 10.1.2.31:36764 with 2.1 GB RAM, BlockManagerId(driver, 10.1.2.31, 36764)
17/01/29 04:50:15,824 INFO BlockManagerMaster: Registered BlockManager BlockManagerId(driver, 10.1.2.31, 36764)
17/01/29 04:50:15,836 INFO StandaloneAppClient$ClientEndpoint: Executor added: app-20170129045015-0000/0 on worker-20170129045005-10.1.2.152-41497 (10.1.2.152:41497) with 4 cores
17/01/29 04:50:15,836 INFO StandaloneSchedulerBackend: Granted executor ID app-20170129045015-0000/0 on hostPort 10.1.2.152:41497 with 4 cores, 3.9 GB RAM
17/01/29 04:50:15,838 INFO StandaloneAppClient$ClientEndpoint: Executor added: app-20170129045015-0000/1 on worker-20170129045005-10.1.2.60-43116 (10.1.2.60:43116) with 4 cores
17/01/29 04:50:15,839 INFO StandaloneSchedulerBackend: Granted executor ID app-20170129045015-0000/1 on hostPort 10.1.2.60:43116 with 4 cores, 3.9 GB RAM
17/01/29 04:50:15,904 INFO StandaloneAppClient$ClientEndpoint: Executor updated: app-20170129045015-0000/1 is now RUNNING
17/01/29 04:50:15,905 INFO StandaloneAppClient$ClientEndpoint: Executor updated: app-20170129045015-0000/0 is now RUNNING
17/01/29 04:50:16,017 INFO StandaloneSchedulerBackend: SchedulerBackend is ready for scheduling beginning after reached minRegisteredResourcesRatio: 0.0
17/01/29 04:50:16,385 INFO MemoryStore: Block broadcast_0 stored as values in memory (estimated size 130.8 KB, free 2.1 GB)
17/01/29 04:50:16,461 INFO MemoryStore: Block broadcast_0_piece0 stored as bytes in memory (estimated size 16.5 KB, free 2.1 GB)
17/01/29 04:50:16,463 INFO BlockManagerInfo: Added broadcast_0_piece0 in memory on 10.1.2.31:36764 (size: 16.5 KB, free: 2.1 GB)
17/01/29 04:50:16,471 INFO SparkContext: Created broadcast 0 from textFile at MLUtils.scala:99
17/01/29 04:50:17,102 INFO FileInputFormat: Total input paths to process : 1
17/01/29 04:50:17,143 INFO NetworkTopology: Adding a new node: /default-rack/10.1.2.60:50010
17/01/29 04:50:17,143 INFO NetworkTopology: Adding a new node: /default-rack/10.1.2.152:50010
17/01/29 04:50:17,182 INFO SparkContext: Starting job: first at GeneralizedLinearAlgorithm.scala:246
17/01/29 04:50:17,194 INFO DAGScheduler: Got job 0 (first at GeneralizedLinearAlgorithm.scala:246) with 1 output partitions
17/01/29 04:50:17,194 INFO DAGScheduler: Final stage: ResultStage 0 (first at GeneralizedLinearAlgorithm.scala:246)
17/01/29 04:50:17,195 INFO DAGScheduler: Parents of final stage: List()
17/01/29 04:50:17,202 INFO DAGScheduler: Missing parents: List()
17/01/29 04:50:17,208 INFO DAGScheduler: Submitting ResultStage 0 (MapPartitionsRDD[6] at map at GeneralizedLinearAlgorithm.scala:246), which has no missing parents
17/01/29 04:50:17,229 INFO MemoryStore: Block broadcast_1 stored as values in memory (estimated size 4.2 KB, free 2.1 GB)
17/01/29 04:50:17,232 INFO MemoryStore: Block broadcast_1_piece0 stored as bytes in memory (estimated size 2.4 KB, free 2.1 GB)
17/01/29 04:50:17,233 INFO BlockManagerInfo: Added broadcast_1_piece0 in memory on 10.1.2.31:36764 (size: 2.4 KB, free: 2.1 GB)
17/01/29 04:50:17,234 INFO SparkContext: Created broadcast 1 from broadcast at DAGScheduler.scala:1012
17/01/29 04:50:17,237 INFO DAGScheduler: Submitting 1 missing tasks from ResultStage 0 (MapPartitionsRDD[6] at map at GeneralizedLinearAlgorithm.scala:246)
17/01/29 04:50:17,238 INFO TaskSchedulerImpl: Adding task set 0.0 with 1 tasks
17/01/29 04:50:17,708 INFO CoarseGrainedSchedulerBackend$DriverEndpoint: Registered executor NettyRpcEndpointRef(null) (10.1.2.60:44102) with ID 1
17/01/29 04:50:17,733 INFO TaskSetManager: Starting task 0.0 in stage 0.0 (TID 0, 10.1.2.60, partition 0, ANY, 5454 bytes)
17/01/29 04:50:17,738 INFO CoarseGrainedSchedulerBackend$DriverEndpoint: Launching task 0 on executor id: 1 hostname: 10.1.2.60.
17/01/29 04:50:17,766 INFO BlockManagerMasterEndpoint: Registering block manager 10.1.2.60:41797 with 2.1 GB RAM, BlockManagerId(1, 10.1.2.60, 41797)
17/01/29 04:50:18,059 INFO BlockManagerInfo: Added broadcast_1_piece0 in memory on 10.1.2.60:41797 (size: 2.4 KB, free: 2.1 GB)
17/01/29 04:50:18,204 INFO BlockManagerInfo: Added broadcast_0_piece0 in memory on 10.1.2.60:41797 (size: 16.5 KB, free: 2.1 GB)
17/01/29 04:50:20,718 INFO CoarseGrainedSchedulerBackend$DriverEndpoint: Registered executor NettyRpcEndpointRef(null) (10.1.2.152:58900) with ID 0
17/01/29 04:50:20,775 INFO BlockManagerMasterEndpoint: Registering block manager 10.1.2.152:44417 with 2.1 GB RAM, BlockManagerId(0, 10.1.2.152, 44417)
17/01/29 04:50:25,318 INFO BlockManagerInfo: Added rdd_5_0 in memory on 10.1.2.60:41797 (size: 70.0 MB, free: 2.0 GB)
17/01/29 04:50:25,375 INFO TaskSetManager: Finished task 0.0 in stage 0.0 (TID 0) in 7662 ms on 10.1.2.60 (1/1)
17/01/29 04:50:25,376 INFO TaskSchedulerImpl: Removed TaskSet 0.0, whose tasks have all completed, from pool 
17/01/29 04:50:25,380 INFO DAGScheduler: ResultStage 0 (first at GeneralizedLinearAlgorithm.scala:246) finished in 8.131 s
17/01/29 04:50:25,386 INFO DAGScheduler: Job 0 finished: first at GeneralizedLinearAlgorithm.scala:246, took 8.203561 s
17/01/29 04:50:25,401 INFO SparkContext: Starting job: count at DataValidators.scala:40
17/01/29 04:50:25,403 INFO DAGScheduler: Got job 1 (count at DataValidators.scala:40) with 59 output partitions
17/01/29 04:50:25,403 INFO DAGScheduler: Final stage: ResultStage 1 (count at DataValidators.scala:40)
17/01/29 04:50:25,403 INFO DAGScheduler: Parents of final stage: List()
17/01/29 04:50:25,405 INFO DAGScheduler: Missing parents: List()
17/01/29 04:50:25,406 INFO DAGScheduler: Submitting ResultStage 1 (MapPartitionsRDD[7] at filter at DataValidators.scala:40), which has no missing parents
17/01/29 04:50:25,428 INFO MemoryStore: Block broadcast_2 stored as values in memory (estimated size 3.9 KB, free 2.1 GB)
17/01/29 04:50:25,431 INFO MemoryStore: Block broadcast_2_piece0 stored as bytes in memory (estimated size 2.2 KB, free 2.1 GB)
17/01/29 04:50:25,432 INFO BlockManagerInfo: Added broadcast_2_piece0 in memory on 10.1.2.31:36764 (size: 2.2 KB, free: 2.1 GB)
17/01/29 04:50:25,433 INFO SparkContext: Created broadcast 2 from broadcast at DAGScheduler.scala:1012
17/01/29 04:50:25,435 INFO DAGScheduler: Submitting 59 missing tasks from ResultStage 1 (MapPartitionsRDD[7] at filter at DataValidators.scala:40)
17/01/29 04:50:25,435 INFO TaskSchedulerImpl: Adding task set 1.0 with 59 tasks
17/01/29 04:50:25,442 INFO TaskSetManager: Starting task 0.0 in stage 1.0 (TID 1, 10.1.2.60, partition 0, PROCESS_LOCAL, 5372 bytes)
17/01/29 04:50:25,445 INFO TaskSetManager: Starting task 58.0 in stage 1.0 (TID 2, 10.1.2.152, partition 58, NODE_LOCAL, 5372 bytes)
17/01/29 04:50:25,445 INFO CoarseGrainedSchedulerBackend$DriverEndpoint: Launching task 2 on executor id: 0 hostname: 10.1.2.152.
17/01/29 04:50:25,446 INFO CoarseGrainedSchedulerBackend$DriverEndpoint: Launching task 1 on executor id: 1 hostname: 10.1.2.60.
17/01/29 04:50:25,465 INFO BlockManagerInfo: Added broadcast_2_piece0 in memory on 10.1.2.60:41797 (size: 2.2 KB, free: 2.0 GB)
17/01/29 04:50:25,520 INFO TaskSetManager: Finished task 0.0 in stage 1.0 (TID 1) in 82 ms on 10.1.2.60 (1/59)
17/01/29 04:50:25,708 INFO BlockManagerInfo: Added broadcast_2_piece0 in memory on 10.1.2.152:44417 (size: 2.2 KB, free: 2.1 GB)
17/01/29 04:50:25,855 INFO BlockManagerInfo: Added broadcast_0_piece0 in memory on 10.1.2.152:44417 (size: 16.5 KB, free: 2.1 GB)
17/01/29 04:50:28,634 INFO TaskSetManager: Starting task 1.0 in stage 1.0 (TID 3, 10.1.2.152, partition 1, ANY, 5372 bytes)
17/01/29 04:50:28,636 INFO TaskSetManager: Starting task 2.0 in stage 1.0 (TID 4, 10.1.2.60, partition 2, ANY, 5372 bytes)
17/01/29 04:50:28,638 INFO TaskSetManager: Starting task 3.0 in stage 1.0 (TID 5, 10.1.2.152, partition 3, ANY, 5372 bytes)
17/01/29 04:50:28,640 INFO TaskSetManager: Starting task 4.0 in stage 1.0 (TID 6, 10.1.2.60, partition 4, ANY, 5372 bytes)
17/01/29 04:50:28,642 INFO TaskSetManager: Starting task 5.0 in stage 1.0 (TID 7, 10.1.2.152, partition 5, ANY, 5372 bytes)
17/01/29 04:50:28,644 INFO TaskSetManager: Starting task 6.0 in stage 1.0 (TID 8, 10.1.2.60, partition 6, ANY, 5372 bytes)
17/01/29 04:50:28,646 INFO TaskSetManager: Starting task 7.0 in stage 1.0 (TID 9, 10.1.2.60, partition 7, ANY, 5372 bytes)
17/01/29 04:50:28,646 INFO CoarseGrainedSchedulerBackend$DriverEndpoint: Launching task 3 on executor id: 0 hostname: 10.1.2.152.
17/01/29 04:50:28,647 INFO CoarseGrainedSchedulerBackend$DriverEndpoint: Launching task 5 on executor id: 0 hostname: 10.1.2.152.
17/01/29 04:50:28,648 INFO CoarseGrainedSchedulerBackend$DriverEndpoint: Launching task 7 on executor id: 0 hostname: 10.1.2.152.
17/01/29 04:50:28,649 INFO CoarseGrainedSchedulerBackend$DriverEndpoint: Launching task 4 on executor id: 1 hostname: 10.1.2.60.
17/01/29 04:50:28,649 INFO CoarseGrainedSchedulerBackend$DriverEndpoint: Launching task 6 on executor id: 1 hostname: 10.1.2.60.
17/01/29 04:50:28,650 INFO CoarseGrainedSchedulerBackend$DriverEndpoint: Launching task 8 on executor id: 1 hostname: 10.1.2.60.
17/01/29 04:50:28,651 INFO CoarseGrainedSchedulerBackend$DriverEndpoint: Launching task 9 on executor id: 1 hostname: 10.1.2.60.
23.587: [GC [PSYoungGen: 1024512K->140559K(1195008K)] 1024512K->140567K(3926016K), 0.0916040 secs] [Times: user=0.08 sys=0.08, real=0.09 secs] 
17/01/29 04:50:37,527 INFO BlockManagerInfo: Removed broadcast_1_piece0 on 10.1.2.31:36764 in memory (size: 2.4 KB, free: 2.1 GB)
17/01/29 04:50:37,538 INFO BlockManagerInfo: Removed broadcast_1_piece0 on 10.1.2.60:41797 in memory (size: 2.4 KB, free: 2.0 GB)
17/01/29 04:50:43,636 INFO BlockManagerInfo: Added rdd_5_58 in memory on 10.1.2.152:44417 (size: 72.8 MB, free: 2047.6 MB)
17/01/29 04:50:43,723 INFO TaskSetManager: Starting task 8.0 in stage 1.0 (TID 10, 10.1.2.152, partition 8, ANY, 5372 bytes)
17/01/29 04:50:43,723 INFO CoarseGrainedSchedulerBackend$DriverEndpoint: Launching task 10 on executor id: 0 hostname: 10.1.2.152.
17/01/29 04:50:43,731 INFO TaskSetManager: Finished task 58.0 in stage 1.0 (TID 2) in 18286 ms on 10.1.2.152 (2/59)
17/01/29 04:50:46,675 INFO BlockManagerInfo: Added rdd_5_3 in memory on 10.1.2.152:44417 (size: 69.9 MB, free: 1977.7 MB)
17/01/29 04:50:46,709 INFO TaskSetManager: Starting task 9.0 in stage 1.0 (TID 11, 10.1.2.152, partition 9, ANY, 5372 bytes)
17/01/29 04:50:46,711 INFO TaskSetManager: Finished task 3.0 in stage 1.0 (TID 5) in 18074 ms on 10.1.2.152 (3/59)
17/01/29 04:50:46,712 INFO CoarseGrainedSchedulerBackend$DriverEndpoint: Launching task 11 on executor id: 0 hostname: 10.1.2.152.
17/01/29 04:50:46,780 INFO BlockManagerInfo: Added rdd_5_1 in memory on 10.1.2.152:44417 (size: 70.0 MB, free: 1907.7 MB)
17/01/29 04:50:46,818 INFO TaskSetManager: Starting task 10.0 in stage 1.0 (TID 12, 10.1.2.152, partition 10, ANY, 5372 bytes)
17/01/29 04:50:46,819 INFO CoarseGrainedSchedulerBackend$DriverEndpoint: Launching task 12 on executor id: 0 hostname: 10.1.2.152.
17/01/29 04:50:46,819 INFO TaskSetManager: Finished task 1.0 in stage 1.0 (TID 3) in 18186 ms on 10.1.2.152 (4/59)
17/01/29 04:50:47,445 INFO BlockManagerInfo: Added rdd_5_5 in memory on 10.1.2.152:44417 (size: 70.0 MB, free: 1837.7 MB)
17/01/29 04:50:47,466 INFO TaskSetManager: Starting task 11.0 in stage 1.0 (TID 13, 10.1.2.152, partition 11, ANY, 5372 bytes)
17/01/29 04:50:47,466 INFO CoarseGrainedSchedulerBackend$DriverEndpoint: Launching task 13 on executor id: 0 hostname: 10.1.2.152.
17/01/29 04:50:47,466 INFO TaskSetManager: Finished task 5.0 in stage 1.0 (TID 7) in 18826 ms on 10.1.2.152 (5/59)
17/01/29 04:50:47,666 INFO BlockManagerInfo: Added rdd_5_2 in memory on 10.1.2.60:41797 (size: 69.9 MB, free: 1980.5 MB)
17/01/29 04:50:47,703 INFO TaskSetManager: Starting task 12.0 in stage 1.0 (TID 14, 10.1.2.60, partition 12, ANY, 5372 bytes)
17/01/29 04:50:47,703 INFO CoarseGrainedSchedulerBackend$DriverEndpoint: Launching task 14 on executor id: 1 hostname: 10.1.2.60.
17/01/29 04:50:47,707 INFO TaskSetManager: Finished task 2.0 in stage 1.0 (TID 4) in 19070 ms on 10.1.2.60 (6/59)
17/01/29 04:50:47,838 INFO BlockManagerInfo: Added rdd_5_6 in memory on 10.1.2.60:41797 (size: 69.9 MB, free: 1910.6 MB)
17/01/29 04:50:47,869 INFO TaskSetManager: Starting task 13.0 in stage 1.0 (TID 15, 10.1.2.60, partition 13, ANY, 5372 bytes)
17/01/29 04:50:47,870 INFO CoarseGrainedSchedulerBackend$DriverEndpoint: Launching task 15 on executor id: 1 hostname: 10.1.2.60.
17/01/29 04:50:47,870 INFO TaskSetManager: Finished task 6.0 in stage 1.0 (TID 8) in 19228 ms on 10.1.2.60 (7/59)
17/01/29 04:50:48,790 INFO BlockManagerInfo: Added rdd_5_7 in memory on 10.1.2.60:41797 (size: 70.0 MB, free: 1840.6 MB)
17/01/29 04:50:48,808 INFO TaskSetManager: Starting task 14.0 in stage 1.0 (TID 16, 10.1.2.60, partition 14, ANY, 5372 bytes)
17/01/29 04:50:48,808 INFO CoarseGrainedSchedulerBackend$DriverEndpoint: Launching task 16 on executor id: 1 hostname: 10.1.2.60.
17/01/29 04:50:48,809 INFO TaskSetManager: Finished task 7.0 in stage 1.0 (TID 9) in 20164 ms on 10.1.2.60 (8/59)
17/01/29 04:50:51,271 INFO BlockManagerInfo: Added rdd_5_4 in memory on 10.1.2.60:41797 (size: 70.0 MB, free: 1770.6 MB)
17/01/29 04:50:51,308 INFO TaskSetManager: Starting task 15.0 in stage 1.0 (TID 17, 10.1.2.60, partition 15, ANY, 5372 bytes)
17/01/29 04:50:51,309 INFO CoarseGrainedSchedulerBackend$DriverEndpoint: Launching task 17 on executor id: 1 hostname: 10.1.2.60.
17/01/29 04:50:51,309 INFO TaskSetManager: Finished task 4.0 in stage 1.0 (TID 6) in 22670 ms on 10.1.2.60 (9/59)
17/01/29 04:51:02,469 INFO BlockManagerInfo: Added rdd_5_8 in memory on 10.1.2.152:44417 (size: 70.0 MB, free: 1767.8 MB)
17/01/29 04:51:02,487 INFO TaskSetManager: Starting task 16.0 in stage 1.0 (TID 18, 10.1.2.152, partition 16, ANY, 5372 bytes)
17/01/29 04:51:02,490 INFO CoarseGrainedSchedulerBackend$DriverEndpoint: Launching task 18 on executor id: 0 hostname: 10.1.2.152.
17/01/29 04:51:02,490 INFO TaskSetManager: Finished task 8.0 in stage 1.0 (TID 10) in 18769 ms on 10.1.2.152 (10/59)
17/01/29 04:51:04,899 INFO BlockManagerInfo: Added rdd_5_10 in memory on 10.1.2.152:44417 (size: 70.0 MB, free: 1697.8 MB)
17/01/29 04:51:04,918 INFO TaskSetManager: Starting task 17.0 in stage 1.0 (TID 19, 10.1.2.152, partition 17, ANY, 5372 bytes)
17/01/29 04:51:04,919 INFO CoarseGrainedSchedulerBackend$DriverEndpoint: Launching task 19 on executor id: 0 hostname: 10.1.2.152.
17/01/29 04:51:04,919 INFO TaskSetManager: Finished task 10.0 in stage 1.0 (TID 12) in 18103 ms on 10.1.2.152 (11/59)
17/01/29 04:51:06,125 INFO BlockManagerInfo: Added rdd_5_13 in memory on 10.1.2.60:41797 (size: 69.9 MB, free: 1700.7 MB)
17/01/29 04:51:06,144 INFO TaskSetManager: Starting task 18.0 in stage 1.0 (TID 20, 10.1.2.60, partition 18, ANY, 5372 bytes)
17/01/29 04:51:06,144 INFO CoarseGrainedSchedulerBackend$DriverEndpoint: Launching task 20 on executor id: 1 hostname: 10.1.2.60.
17/01/29 04:51:06,144 INFO TaskSetManager: Finished task 13.0 in stage 1.0 (TID 15) in 18277 ms on 10.1.2.60 (12/59)
17/01/29 04:51:06,337 INFO BlockManagerInfo: Added rdd_5_9 in memory on 10.1.2.152:44417 (size: 69.9 MB, free: 1627.9 MB)
17/01/29 04:51:06,352 INFO BlockManagerInfo: Added rdd_5_11 in memory on 10.1.2.152:44417 (size: 69.9 MB, free: 1558.0 MB)
17/01/29 04:51:06,358 INFO TaskSetManager: Starting task 19.0 in stage 1.0 (TID 21, 10.1.2.152, partition 19, ANY, 5372 bytes)
17/01/29 04:51:06,359 INFO CoarseGrainedSchedulerBackend$DriverEndpoint: Launching task 21 on executor id: 0 hostname: 10.1.2.152.
17/01/29 04:51:06,359 INFO TaskSetManager: Finished task 9.0 in stage 1.0 (TID 11) in 19653 ms on 10.1.2.152 (13/59)
17/01/29 04:51:06,380 INFO TaskSetManager: Starting task 20.0 in stage 1.0 (TID 22, 10.1.2.152, partition 20, ANY, 5372 bytes)
17/01/29 04:51:06,380 INFO CoarseGrainedSchedulerBackend$DriverEndpoint: Launching task 22 on executor id: 0 hostname: 10.1.2.152.
17/01/29 04:51:06,381 INFO TaskSetManager: Finished task 11.0 in stage 1.0 (TID 13) in 18916 ms on 10.1.2.152 (14/59)
17/01/29 04:51:06,466 INFO BlockManagerInfo: Added rdd_5_14 in memory on 10.1.2.60:41797 (size: 69.9 MB, free: 1630.8 MB)
17/01/29 04:51:06,488 INFO TaskSetManager: Starting task 21.0 in stage 1.0 (TID 23, 10.1.2.60, partition 21, ANY, 5372 bytes)
17/01/29 04:51:06,490 INFO CoarseGrainedSchedulerBackend$DriverEndpoint: Launching task 23 on executor id: 1 hostname: 10.1.2.60.
17/01/29 04:51:06,490 INFO TaskSetManager: Finished task 14.0 in stage 1.0 (TID 16) in 17684 ms on 10.1.2.60 (15/59)
17/01/29 04:51:07,566 INFO BlockManagerInfo: Added rdd_5_12 in memory on 10.1.2.60:41797 (size: 70.0 MB, free: 1560.9 MB)
17/01/29 04:51:07,587 INFO TaskSetManager: Starting task 22.0 in stage 1.0 (TID 24, 10.1.2.60, partition 22, ANY, 5372 bytes)
17/01/29 04:51:07,587 INFO CoarseGrainedSchedulerBackend$DriverEndpoint: Launching task 24 on executor id: 1 hostname: 10.1.2.60.
17/01/29 04:51:07,589 INFO TaskSetManager: Finished task 12.0 in stage 1.0 (TID 14) in 19888 ms on 10.1.2.60 (16/59)
17/01/29 04:51:10,525 INFO BlockManagerInfo: Added rdd_5_15 in memory on 10.1.2.60:41797 (size: 69.9 MB, free: 1490.9 MB)
17/01/29 04:51:10,553 INFO TaskSetManager: Starting task 23.0 in stage 1.0 (TID 25, 10.1.2.60, partition 23, ANY, 5372 bytes)
17/01/29 04:51:10,554 INFO CoarseGrainedSchedulerBackend$DriverEndpoint: Launching task 25 on executor id: 1 hostname: 10.1.2.60.
17/01/29 04:51:10,554 INFO TaskSetManager: Finished task 15.0 in stage 1.0 (TID 17) in 19247 ms on 10.1.2.60 (17/59)
17/01/29 04:51:22,515 INFO BlockManagerInfo: Added rdd_5_20 in memory on 10.1.2.152:44417 (size: 69.8 MB, free: 1488.1 MB)
17/01/29 04:51:22,533 INFO TaskSetManager: Starting task 24.0 in stage 1.0 (TID 26, 10.1.2.152, partition 24, ANY, 5372 bytes)
17/01/29 04:51:22,533 INFO CoarseGrainedSchedulerBackend$DriverEndpoint: Launching task 26 on executor id: 0 hostname: 10.1.2.152.
17/01/29 04:51:22,535 INFO TaskSetManager: Finished task 20.0 in stage 1.0 (TID 22) in 16156 ms on 10.1.2.152 (18/59)
17/01/29 04:51:23,341 INFO BlockManagerInfo: Added rdd_5_21 in memory on 10.1.2.60:41797 (size: 69.9 MB, free: 1421.0 MB)
17/01/29 04:51:23,359 INFO TaskSetManager: Starting task 25.0 in stage 1.0 (TID 27, 10.1.2.60, partition 25, ANY, 5372 bytes)
17/01/29 04:51:23,359 INFO CoarseGrainedSchedulerBackend$DriverEndpoint: Launching task 27 on executor id: 1 hostname: 10.1.2.60.
17/01/29 04:51:23,360 INFO TaskSetManager: Finished task 21.0 in stage 1.0 (TID 23) in 16874 ms on 10.1.2.60 (19/59)
17/01/29 04:51:23,972 INFO BlockManagerInfo: Added rdd_5_18 in memory on 10.1.2.60:41797 (size: 70.0 MB, free: 1351.0 MB)
17/01/29 04:51:23,991 INFO TaskSetManager: Starting task 26.0 in stage 1.0 (TID 28, 10.1.2.60, partition 26, ANY, 5372 bytes)
17/01/29 04:51:23,992 INFO CoarseGrainedSchedulerBackend$DriverEndpoint: Launching task 28 on executor id: 1 hostname: 10.1.2.60.
17/01/29 04:51:23,992 INFO TaskSetManager: Finished task 18.0 in stage 1.0 (TID 20) in 17850 ms on 10.1.2.60 (20/59)
17/01/29 04:51:24,147 INFO BlockManagerInfo: Added rdd_5_16 in memory on 10.1.2.152:44417 (size: 70.0 MB, free: 1418.2 MB)
17/01/29 04:51:24,165 INFO TaskSetManager: Starting task 27.0 in stage 1.0 (TID 29, 10.1.2.152, partition 27, ANY, 5372 bytes)
17/01/29 04:51:24,166 INFO CoarseGrainedSchedulerBackend$DriverEndpoint: Launching task 29 on executor id: 0 hostname: 10.1.2.152.
17/01/29 04:51:24,167 INFO TaskSetManager: Finished task 16.0 in stage 1.0 (TID 18) in 21683 ms on 10.1.2.152 (21/59)
17/01/29 04:51:25,549 INFO BlockManagerInfo: Added rdd_5_22 in memory on 10.1.2.60:41797 (size: 69.8 MB, free: 1281.2 MB)
17/01/29 04:51:25,568 INFO TaskSetManager: Starting task 28.0 in stage 1.0 (TID 30, 10.1.2.60, partition 28, ANY, 5372 bytes)
17/01/29 04:51:25,569 INFO CoarseGrainedSchedulerBackend$DriverEndpoint: Launching task 30 on executor id: 1 hostname: 10.1.2.60.
17/01/29 04:51:25,570 INFO TaskSetManager: Finished task 22.0 in stage 1.0 (TID 24) in 17984 ms on 10.1.2.60 (22/59)
17/01/29 04:51:27,691 INFO BlockManagerInfo: Added rdd_5_19 in memory on 10.1.2.152:44417 (size: 70.0 MB, free: 1348.2 MB)
17/01/29 04:51:27,708 INFO TaskSetManager: Starting task 29.0 in stage 1.0 (TID 31, 10.1.2.152, partition 29, ANY, 5372 bytes)
17/01/29 04:51:27,708 INFO CoarseGrainedSchedulerBackend$DriverEndpoint: Launching task 31 on executor id: 0 hostname: 10.1.2.152.
17/01/29 04:51:27,709 INFO TaskSetManager: Finished task 19.0 in stage 1.0 (TID 21) in 21352 ms on 10.1.2.152 (23/59)
17/01/29 04:51:29,112 INFO BlockManagerInfo: Added rdd_5_17 in memory on 10.1.2.152:44417 (size: 69.9 MB, free: 1278.3 MB)
17/01/29 04:51:29,132 INFO TaskSetManager: Starting task 30.0 in stage 1.0 (TID 32, 10.1.2.152, partition 30, ANY, 5372 bytes)
17/01/29 04:51:29,132 INFO CoarseGrainedSchedulerBackend$DriverEndpoint: Launching task 32 on executor id: 0 hostname: 10.1.2.152.
17/01/29 04:51:29,132 INFO TaskSetManager: Finished task 17.0 in stage 1.0 (TID 19) in 24215 ms on 10.1.2.152 (24/59)
17/01/29 04:51:29,299 INFO BlockManagerInfo: Added rdd_5_23 in memory on 10.1.2.60:41797 (size: 69.9 MB, free: 1211.3 MB)
17/01/29 04:51:29,317 INFO TaskSetManager: Starting task 31.0 in stage 1.0 (TID 33, 10.1.2.60, partition 31, ANY, 5372 bytes)
17/01/29 04:51:29,318 INFO CoarseGrainedSchedulerBackend$DriverEndpoint: Launching task 33 on executor id: 1 hostname: 10.1.2.60.
17/01/29 04:51:29,319 INFO TaskSetManager: Finished task 23.0 in stage 1.0 (TID 25) in 18767 ms on 10.1.2.60 (25/59)
17/01/29 04:51:40,055 INFO BlockManagerInfo: Added rdd_5_24 in memory on 10.1.2.152:44417 (size: 69.8 MB, free: 1208.6 MB)
17/01/29 04:51:40,071 INFO TaskSetManager: Starting task 32.0 in stage 1.0 (TID 34, 10.1.2.152, partition 32, ANY, 5372 bytes)
17/01/29 04:51:40,072 INFO CoarseGrainedSchedulerBackend$DriverEndpoint: Launching task 34 on executor id: 0 hostname: 10.1.2.152.
17/01/29 04:51:40,072 INFO TaskSetManager: Finished task 24.0 in stage 1.0 (TID 26) in 17541 ms on 10.1.2.152 (26/59)
17/01/29 04:51:40,765 INFO BlockManagerInfo: Added rdd_5_25 in memory on 10.1.2.60:41797 (size: 70.0 MB, free: 1141.3 MB)
17/01/29 04:51:40,784 INFO TaskSetManager: Starting task 33.0 in stage 1.0 (TID 35, 10.1.2.60, partition 33, ANY, 5372 bytes)
17/01/29 04:51:40,785 INFO CoarseGrainedSchedulerBackend$DriverEndpoint: Launching task 35 on executor id: 1 hostname: 10.1.2.60.
17/01/29 04:51:40,787 INFO TaskSetManager: Finished task 25.0 in stage 1.0 (TID 27) in 17429 ms on 10.1.2.60 (27/59)
17/01/29 04:51:41,503 INFO BlockManagerInfo: Added rdd_5_27 in memory on 10.1.2.152:44417 (size: 69.9 MB, free: 1138.6 MB)
17/01/29 04:51:41,526 INFO TaskSetManager: Starting task 34.0 in stage 1.0 (TID 36, 10.1.2.152, partition 34, ANY, 5372 bytes)
17/01/29 04:51:41,526 INFO CoarseGrainedSchedulerBackend$DriverEndpoint: Launching task 36 on executor id: 0 hostname: 10.1.2.152.
17/01/29 04:51:41,526 INFO TaskSetManager: Finished task 27.0 in stage 1.0 (TID 29) in 17362 ms on 10.1.2.152 (28/59)
17/01/29 04:51:42,267 INFO BlockManagerInfo: Added rdd_5_26 in memory on 10.1.2.60:41797 (size: 69.9 MB, free: 1071.4 MB)
17/01/29 04:51:42,287 INFO TaskSetManager: Starting task 35.0 in stage 1.0 (TID 37, 10.1.2.60, partition 35, ANY, 5372 bytes)
17/01/29 04:51:42,288 INFO CoarseGrainedSchedulerBackend$DriverEndpoint: Launching task 37 on executor id: 1 hostname: 10.1.2.60.
17/01/29 04:51:42,289 INFO TaskSetManager: Finished task 26.0 in stage 1.0 (TID 28) in 18299 ms on 10.1.2.60 (29/59)
17/01/29 04:51:42,974 INFO BlockManagerInfo: Added rdd_5_28 in memory on 10.1.2.60:41797 (size: 70.0 MB, free: 1001.4 MB)
17/01/29 04:51:42,995 INFO TaskSetManager: Starting task 36.0 in stage 1.0 (TID 38, 10.1.2.60, partition 36, ANY, 5372 bytes)
17/01/29 04:51:42,995 INFO CoarseGrainedSchedulerBackend$DriverEndpoint: Launching task 38 on executor id: 1 hostname: 10.1.2.60.
17/01/29 04:51:42,995 INFO TaskSetManager: Finished task 28.0 in stage 1.0 (TID 30) in 17429 ms on 10.1.2.60 (30/59)
17/01/29 04:51:47,156 INFO BlockManagerInfo: Added rdd_5_31 in memory on 10.1.2.60:41797 (size: 69.7 MB, free: 931.7 MB)
17/01/29 04:51:47,176 INFO TaskSetManager: Starting task 37.0 in stage 1.0 (TID 39, 10.1.2.60, partition 37, ANY, 5372 bytes)
17/01/29 04:51:47,177 INFO TaskSetManager: Finished task 31.0 in stage 1.0 (TID 33) in 17861 ms on 10.1.2.60 (31/59)
17/01/29 04:51:47,177 INFO CoarseGrainedSchedulerBackend$DriverEndpoint: Launching task 39 on executor id: 1 hostname: 10.1.2.60.
17/01/29 04:51:49,083 INFO BlockManagerInfo: Added rdd_5_29 in memory on 10.1.2.152:44417 (size: 69.9 MB, free: 1068.7 MB)
17/01/29 04:51:49,099 INFO TaskSetManager: Starting task 38.0 in stage 1.0 (TID 40, 10.1.2.152, partition 38, ANY, 5372 bytes)
17/01/29 04:51:49,100 INFO CoarseGrainedSchedulerBackend$DriverEndpoint: Launching task 40 on executor id: 0 hostname: 10.1.2.152.
17/01/29 04:51:49,101 INFO TaskSetManager: Finished task 29.0 in stage 1.0 (TID 31) in 21393 ms on 10.1.2.152 (32/59)
17/01/29 04:51:49,307 INFO BlockManagerInfo: Added rdd_5_30 in memory on 10.1.2.152:44417 (size: 70.0 MB, free: 998.7 MB)
17/01/29 04:51:49,323 INFO TaskSetManager: Starting task 39.0 in stage 1.0 (TID 41, 10.1.2.152, partition 39, ANY, 5372 bytes)
17/01/29 04:51:49,324 INFO TaskSetManager: Finished task 30.0 in stage 1.0 (TID 32) in 20193 ms on 10.1.2.152 (33/59)
17/01/29 04:51:49,324 INFO CoarseGrainedSchedulerBackend$DriverEndpoint: Launching task 41 on executor id: 0 hostname: 10.1.2.152.
17/01/29 04:51:58,722 INFO BlockManagerInfo: Added rdd_5_33 in memory on 10.1.2.60:41797 (size: 69.9 MB, free: 861.8 MB)
17/01/29 04:51:58,740 INFO TaskSetManager: Starting task 40.0 in stage 1.0 (TID 42, 10.1.2.60, partition 40, ANY, 5372 bytes)
17/01/29 04:51:58,740 INFO CoarseGrainedSchedulerBackend$DriverEndpoint: Launching task 42 on executor id: 1 hostname: 10.1.2.60.
17/01/29 04:51:58,741 INFO TaskSetManager: Finished task 33.0 in stage 1.0 (TID 35) in 17957 ms on 10.1.2.60 (34/59)
17/01/29 04:52:00,941 INFO BlockManagerInfo: Added rdd_5_35 in memory on 10.1.2.60:41797 (size: 70.0 MB, free: 791.8 MB)
17/01/29 04:52:00,964 INFO TaskSetManager: Starting task 41.0 in stage 1.0 (TID 43, 10.1.2.60, partition 41, ANY, 5372 bytes)
17/01/29 04:52:00,965 INFO CoarseGrainedSchedulerBackend$DriverEndpoint: Launching task 43 on executor id: 1 hostname: 10.1.2.60.
17/01/29 04:52:00,966 INFO TaskSetManager: Finished task 35.0 in stage 1.0 (TID 37) in 18680 ms on 10.1.2.60 (35/59)
17/01/29 04:52:02,309 INFO BlockManagerInfo: Added rdd_5_36 in memory on 10.1.2.60:41797 (size: 70.0 MB, free: 721.8 MB)
17/01/29 04:52:02,333 INFO TaskSetManager: Starting task 42.0 in stage 1.0 (TID 44, 10.1.2.60, partition 42, ANY, 5372 bytes)
17/01/29 04:52:02,333 INFO CoarseGrainedSchedulerBackend$DriverEndpoint: Launching task 44 on executor id: 1 hostname: 10.1.2.60.
17/01/29 04:52:02,333 INFO TaskSetManager: Finished task 36.0 in stage 1.0 (TID 38) in 19339 ms on 10.1.2.60 (36/59)
17/01/29 04:52:03,205 INFO BlockManagerInfo: Added rdd_5_34 in memory on 10.1.2.152:44417 (size: 70.0 MB, free: 928.7 MB)
17/01/29 04:52:03,222 INFO TaskSetManager: Starting task 43.0 in stage 1.0 (TID 45, 10.1.2.152, partition 43, ANY, 5372 bytes)
17/01/29 04:52:03,223 INFO CoarseGrainedSchedulerBackend$DriverEndpoint: Launching task 45 on executor id: 0 hostname: 10.1.2.152.
17/01/29 04:52:03,224 INFO TaskSetManager: Finished task 34.0 in stage 1.0 (TID 36) in 21700 ms on 10.1.2.152 (37/59)
17/01/29 04:52:04,569 INFO BlockManagerInfo: Added rdd_5_32 in memory on 10.1.2.152:44417 (size: 69.9 MB, free: 858.8 MB)
17/01/29 04:52:04,585 INFO TaskSetManager: Starting task 44.0 in stage 1.0 (TID 46, 10.1.2.152, partition 44, ANY, 5372 bytes)
17/01/29 04:52:04,585 INFO CoarseGrainedSchedulerBackend$DriverEndpoint: Launching task 46 on executor id: 0 hostname: 10.1.2.152.
17/01/29 04:52:04,586 INFO TaskSetManager: Finished task 32.0 in stage 1.0 (TID 34) in 24517 ms on 10.1.2.152 (38/59)
17/01/29 04:52:04,621 INFO BlockManagerInfo: Added rdd_5_37 in memory on 10.1.2.60:41797 (size: 69.9 MB, free: 651.8 MB)
17/01/29 04:52:04,639 INFO TaskSetManager: Starting task 45.0 in stage 1.0 (TID 47, 10.1.2.60, partition 45, ANY, 5372 bytes)
17/01/29 04:52:04,640 INFO CoarseGrainedSchedulerBackend$DriverEndpoint: Launching task 47 on executor id: 1 hostname: 10.1.2.60.
17/01/29 04:52:04,641 INFO TaskSetManager: Finished task 37.0 in stage 1.0 (TID 39) in 17467 ms on 10.1.2.60 (39/59)
17/01/29 04:52:11,221 INFO BlockManagerInfo: Added rdd_5_38 in memory on 10.1.2.152:44417 (size: 70.0 MB, free: 788.8 MB)
17/01/29 04:52:11,237 INFO TaskSetManager: Starting task 46.0 in stage 1.0 (TID 48, 10.1.2.152, partition 46, ANY, 5372 bytes)
17/01/29 04:52:11,238 INFO CoarseGrainedSchedulerBackend$DriverEndpoint: Launching task 48 on executor id: 0 hostname: 10.1.2.152.
17/01/29 04:52:11,238 INFO TaskSetManager: Finished task 38.0 in stage 1.0 (TID 40) in 22140 ms on 10.1.2.152 (40/59)
17/01/29 04:52:11,676 INFO BlockManagerInfo: Added rdd_5_39 in memory on 10.1.2.152:44417 (size: 70.0 MB, free: 718.9 MB)
17/01/29 04:52:11,691 INFO TaskSetManager: Starting task 47.0 in stage 1.0 (TID 49, 10.1.2.152, partition 47, ANY, 5372 bytes)
17/01/29 04:52:11,692 INFO CoarseGrainedSchedulerBackend$DriverEndpoint: Launching task 49 on executor id: 0 hostname: 10.1.2.152.
17/01/29 04:52:11,693 INFO TaskSetManager: Finished task 39.0 in stage 1.0 (TID 41) in 22370 ms on 10.1.2.152 (41/59)
17/01/29 04:52:17,130 INFO BlockManagerInfo: Added rdd_5_40 in memory on 10.1.2.60:41797 (size: 70.0 MB, free: 581.8 MB)
17/01/29 04:52:17,152 INFO TaskSetManager: Starting task 48.0 in stage 1.0 (TID 50, 10.1.2.60, partition 48, ANY, 5372 bytes)
17/01/29 04:52:17,153 INFO TaskSetManager: Finished task 40.0 in stage 1.0 (TID 42) in 18414 ms on 10.1.2.60 (42/59)
17/01/29 04:52:17,155 INFO CoarseGrainedSchedulerBackend$DriverEndpoint: Launching task 50 on executor id: 1 hostname: 10.1.2.60.
17/01/29 04:52:17,798 INFO BlockManagerInfo: Added rdd_5_41 in memory on 10.1.2.60:41797 (size: 70.0 MB, free: 511.9 MB)
17/01/29 04:52:17,815 INFO TaskSetManager: Starting task 49.0 in stage 1.0 (TID 51, 10.1.2.60, partition 49, ANY, 5372 bytes)
17/01/29 04:52:17,815 INFO CoarseGrainedSchedulerBackend$DriverEndpoint: Launching task 51 on executor id: 1 hostname: 10.1.2.60.
17/01/29 04:52:17,816 INFO TaskSetManager: Finished task 41.0 in stage 1.0 (TID 43) in 16853 ms on 10.1.2.60 (43/59)
17/01/29 04:52:19,433 INFO BlockManagerInfo: Added rdd_5_42 in memory on 10.1.2.60:41797 (size: 69.8 MB, free: 442.1 MB)
17/01/29 04:52:19,451 INFO TaskSetManager: Starting task 50.0 in stage 1.0 (TID 52, 10.1.2.60, partition 50, ANY, 5372 bytes)
17/01/29 04:52:19,452 INFO CoarseGrainedSchedulerBackend$DriverEndpoint: Launching task 52 on executor id: 1 hostname: 10.1.2.60.
17/01/29 04:52:19,452 INFO TaskSetManager: Finished task 42.0 in stage 1.0 (TID 44) in 17120 ms on 10.1.2.60 (44/59)
17/01/29 04:52:22,282 INFO BlockManagerInfo: Added rdd_5_45 in memory on 10.1.2.60:41797 (size: 69.9 MB, free: 372.2 MB)
17/01/29 04:52:22,300 INFO TaskSetManager: Starting task 51.0 in stage 1.0 (TID 53, 10.1.2.60, partition 51, ANY, 5372 bytes)
17/01/29 04:52:22,300 INFO CoarseGrainedSchedulerBackend$DriverEndpoint: Launching task 53 on executor id: 1 hostname: 10.1.2.60.
17/01/29 04:52:22,301 INFO TaskSetManager: Finished task 45.0 in stage 1.0 (TID 47) in 17662 ms on 10.1.2.60 (45/59)
17/01/29 04:52:27,482 INFO BlockManagerInfo: Added rdd_5_44 in memory on 10.1.2.152:44417 (size: 70.0 MB, free: 648.9 MB)
17/01/29 04:52:27,503 INFO TaskSetManager: Starting task 52.0 in stage 1.0 (TID 54, 10.1.2.152, partition 52, ANY, 5372 bytes)
17/01/29 04:52:27,504 INFO CoarseGrainedSchedulerBackend$DriverEndpoint: Launching task 54 on executor id: 0 hostname: 10.1.2.152.
17/01/29 04:52:27,504 INFO TaskSetManager: Finished task 44.0 in stage 1.0 (TID 46) in 22920 ms on 10.1.2.152 (46/59)
17/01/29 04:52:30,098 INFO BlockManagerInfo: Added rdd_5_43 in memory on 10.1.2.152:44417 (size: 69.8 MB, free: 579.0 MB)
17/01/29 04:52:30,116 INFO TaskSetManager: Starting task 53.0 in stage 1.0 (TID 55, 10.1.2.152, partition 53, ANY, 5372 bytes)
17/01/29 04:52:30,116 INFO CoarseGrainedSchedulerBackend$DriverEndpoint: Launching task 55 on executor id: 0 hostname: 10.1.2.152.
17/01/29 04:52:30,117 INFO TaskSetManager: Finished task 43.0 in stage 1.0 (TID 45) in 26896 ms on 10.1.2.152 (47/59)
17/01/29 04:52:32,775 INFO BlockManagerInfo: Added rdd_5_46 in memory on 10.1.2.152:44417 (size: 69.9 MB, free: 509.1 MB)
17/01/29 04:52:32,794 INFO TaskSetManager: Starting task 54.0 in stage 1.0 (TID 56, 10.1.2.152, partition 54, ANY, 5372 bytes)
17/01/29 04:52:32,795 INFO CoarseGrainedSchedulerBackend$DriverEndpoint: Launching task 56 on executor id: 0 hostname: 10.1.2.152.
17/01/29 04:52:32,795 INFO TaskSetManager: Finished task 46.0 in stage 1.0 (TID 48) in 21559 ms on 10.1.2.152 (48/59)
17/01/29 04:52:33,274 INFO BlockManagerInfo: Added rdd_5_47 in memory on 10.1.2.152:44417 (size: 70.0 MB, free: 439.1 MB)
17/01/29 04:52:33,299 INFO TaskSetManager: Starting task 55.0 in stage 1.0 (TID 57, 10.1.2.152, partition 55, ANY, 5372 bytes)
17/01/29 04:52:33,299 INFO CoarseGrainedSchedulerBackend$DriverEndpoint: Launching task 57 on executor id: 0 hostname: 10.1.2.152.
17/01/29 04:52:33,300 INFO TaskSetManager: Finished task 47.0 in stage 1.0 (TID 49) in 21610 ms on 10.1.2.152 (49/59)
17/01/29 04:52:34,297 INFO BlockManagerInfo: Added rdd_5_48 in memory on 10.1.2.60:41797 (size: 69.9 MB, free: 302.3 MB)
17/01/29 04:52:34,315 INFO TaskSetManager: Starting task 56.0 in stage 1.0 (TID 58, 10.1.2.60, partition 56, ANY, 5372 bytes)
17/01/29 04:52:34,316 INFO CoarseGrainedSchedulerBackend$DriverEndpoint: Launching task 58 on executor id: 1 hostname: 10.1.2.60.
17/01/29 04:52:34,317 INFO TaskSetManager: Finished task 48.0 in stage 1.0 (TID 50) in 17165 ms on 10.1.2.60 (50/59)
17/01/29 04:52:35,519 INFO BlockManagerInfo: Added rdd_5_49 in memory on 10.1.2.60:41797 (size: 69.8 MB, free: 232.5 MB)
17/01/29 04:52:35,536 INFO TaskSetManager: Starting task 57.0 in stage 1.0 (TID 59, 10.1.2.60, partition 57, ANY, 5372 bytes)
17/01/29 04:52:35,537 INFO CoarseGrainedSchedulerBackend$DriverEndpoint: Launching task 59 on executor id: 1 hostname: 10.1.2.60.
17/01/29 04:52:35,538 INFO TaskSetManager: Finished task 49.0 in stage 1.0 (TID 51) in 17723 ms on 10.1.2.60 (51/59)
17/01/29 04:52:38,149 INFO BlockManagerInfo: Added rdd_5_50 in memory on 10.1.2.60:41797 (size: 69.9 MB, free: 162.6 MB)
17/01/29 04:52:38,168 INFO TaskSetManager: Finished task 50.0 in stage 1.0 (TID 52) in 18718 ms on 10.1.2.60 (52/59)
17/01/29 04:52:40,387 INFO BlockManagerInfo: Added rdd_5_51 in memory on 10.1.2.60:41797 (size: 69.9 MB, free: 92.7 MB)
17/01/29 04:52:40,408 INFO TaskSetManager: Finished task 51.0 in stage 1.0 (TID 53) in 18109 ms on 10.1.2.60 (53/59)
17/01/29 04:52:45,017 INFO TaskSetManager: Finished task 57.0 in stage 1.0 (TID 59) in 9481 ms on 10.1.2.60 (54/59)
17/01/29 04:52:45,379 INFO TaskSetManager: Finished task 56.0 in stage 1.0 (TID 58) in 11066 ms on 10.1.2.60 (55/59)
17/01/29 04:52:49,100 INFO BlockManagerInfo: Added rdd_5_52 in memory on 10.1.2.152:44417 (size: 69.9 MB, free: 369.3 MB)
17/01/29 04:52:49,116 INFO TaskSetManager: Finished task 52.0 in stage 1.0 (TID 54) in 21614 ms on 10.1.2.152 (56/59)
17/01/29 04:52:50,578 INFO BlockManagerInfo: Added rdd_5_53 in memory on 10.1.2.152:44417 (size: 70.0 MB, free: 299.3 MB)
17/01/29 04:52:50,595 INFO TaskSetManager: Finished task 53.0 in stage 1.0 (TID 55) in 20480 ms on 10.1.2.152 (57/59)
17/01/29 04:52:51,972 INFO BlockManagerInfo: Added rdd_5_55 in memory on 10.1.2.152:44417 (size: 69.9 MB, free: 229.4 MB)
17/01/29 04:52:51,994 INFO TaskSetManager: Finished task 55.0 in stage 1.0 (TID 57) in 18696 ms on 10.1.2.152 (58/59)
17/01/29 04:52:52,887 INFO BlockManagerInfo: Added rdd_5_54 in memory on 10.1.2.152:44417 (size: 69.9 MB, free: 159.5 MB)
17/01/29 04:52:52,903 INFO TaskSetManager: Finished task 54.0 in stage 1.0 (TID 56) in 20109 ms on 10.1.2.152 (59/59)
17/01/29 04:52:52,903 INFO TaskSchedulerImpl: Removed TaskSet 1.0, whose tasks have all completed, from pool 
17/01/29 04:52:52,903 INFO DAGScheduler: ResultStage 1 (count at DataValidators.scala:40) finished in 147.466 s
17/01/29 04:52:52,903 INFO DAGScheduler: Job 1 finished: count at DataValidators.scala:40, took 147.502504 s
17/01/29 04:52:52,914 INFO SparkContext: Starting job: count at GradientDescent.scala:209
17/01/29 04:52:52,916 INFO DAGScheduler: Got job 2 (count at GradientDescent.scala:209) with 59 output partitions
17/01/29 04:52:52,916 INFO DAGScheduler: Final stage: ResultStage 2 (count at GradientDescent.scala:209)
17/01/29 04:52:52,916 INFO DAGScheduler: Parents of final stage: List()
17/01/29 04:52:52,919 INFO DAGScheduler: Missing parents: List()
17/01/29 04:52:52,920 INFO DAGScheduler: Submitting ResultStage 2 (MapPartitionsRDD[8] at map at GeneralizedLinearAlgorithm.scala:297), which has no missing parents
17/01/29 04:52:52,926 INFO MemoryStore: Block broadcast_3 stored as values in memory (estimated size 3.9 KB, free 2.1 GB)
17/01/29 04:52:52,931 INFO MemoryStore: Block broadcast_3_piece0 stored as bytes in memory (estimated size 2.2 KB, free 2.1 GB)
17/01/29 04:52:52,932 INFO BlockManagerInfo: Added broadcast_3_piece0 in memory on 10.1.2.31:36764 (size: 2.2 KB, free: 2.1 GB)
17/01/29 04:52:52,933 INFO SparkContext: Created broadcast 3 from broadcast at DAGScheduler.scala:1012
17/01/29 04:52:52,935 INFO DAGScheduler: Submitting 59 missing tasks from ResultStage 2 (MapPartitionsRDD[8] at map at GeneralizedLinearAlgorithm.scala:297)
17/01/29 04:52:52,936 INFO TaskSchedulerImpl: Adding task set 2.0 with 59 tasks
17/01/29 04:52:52,939 INFO TaskSetManager: Starting task 0.0 in stage 2.0 (TID 60, 10.1.2.60, partition 0, PROCESS_LOCAL, 5372 bytes)
17/01/29 04:52:52,940 INFO TaskSetManager: Starting task 1.0 in stage 2.0 (TID 61, 10.1.2.152, partition 1, PROCESS_LOCAL, 5372 bytes)
17/01/29 04:52:52,941 INFO TaskSetManager: Starting task 2.0 in stage 2.0 (TID 62, 10.1.2.60, partition 2, PROCESS_LOCAL, 5372 bytes)
17/01/29 04:52:52,942 INFO TaskSetManager: Starting task 3.0 in stage 2.0 (TID 63, 10.1.2.152, partition 3, PROCESS_LOCAL, 5372 bytes)
17/01/29 04:52:52,942 INFO TaskSetManager: Starting task 4.0 in stage 2.0 (TID 64, 10.1.2.60, partition 4, PROCESS_LOCAL, 5372 bytes)
17/01/29 04:52:52,943 INFO TaskSetManager: Starting task 5.0 in stage 2.0 (TID 65, 10.1.2.152, partition 5, PROCESS_LOCAL, 5372 bytes)
17/01/29 04:52:52,944 INFO TaskSetManager: Starting task 6.0 in stage 2.0 (TID 66, 10.1.2.60, partition 6, PROCESS_LOCAL, 5372 bytes)
17/01/29 04:52:52,945 INFO TaskSetManager: Starting task 8.0 in stage 2.0 (TID 67, 10.1.2.152, partition 8, PROCESS_LOCAL, 5372 bytes)
17/01/29 04:52:52,945 INFO CoarseGrainedSchedulerBackend$DriverEndpoint: Launching task 60 on executor id: 1 hostname: 10.1.2.60.
17/01/29 04:52:52,946 INFO CoarseGrainedSchedulerBackend$DriverEndpoint: Launching task 62 on executor id: 1 hostname: 10.1.2.60.
17/01/29 04:52:52,947 INFO CoarseGrainedSchedulerBackend$DriverEndpoint: Launching task 64 on executor id: 1 hostname: 10.1.2.60.
17/01/29 04:52:52,947 INFO CoarseGrainedSchedulerBackend$DriverEndpoint: Launching task 66 on executor id: 1 hostname: 10.1.2.60.
17/01/29 04:52:52,948 INFO CoarseGrainedSchedulerBackend$DriverEndpoint: Launching task 61 on executor id: 0 hostname: 10.1.2.152.
17/01/29 04:52:52,948 INFO CoarseGrainedSchedulerBackend$DriverEndpoint: Launching task 63 on executor id: 0 hostname: 10.1.2.152.
17/01/29 04:52:52,949 INFO CoarseGrainedSchedulerBackend$DriverEndpoint: Launching task 65 on executor id: 0 hostname: 10.1.2.152.
17/01/29 04:52:52,951 INFO CoarseGrainedSchedulerBackend$DriverEndpoint: Launching task 67 on executor id: 0 hostname: 10.1.2.152.
17/01/29 04:52:52,967 INFO BlockManagerInfo: Added broadcast_3_piece0 in memory on 10.1.2.60:41797 (size: 2.2 KB, free: 92.7 MB)
17/01/29 04:52:53,001 INFO TaskSetManager: Starting task 7.0 in stage 2.0 (TID 68, 10.1.2.60, partition 7, PROCESS_LOCAL, 5372 bytes)
17/01/29 04:52:53,001 INFO CoarseGrainedSchedulerBackend$DriverEndpoint: Launching task 68 on executor id: 1 hostname: 10.1.2.60.
17/01/29 04:52:53,001 INFO TaskSetManager: Finished task 4.0 in stage 2.0 (TID 64) in 59 ms on 10.1.2.60 (1/59)
17/01/29 04:52:53,006 INFO BlockManagerInfo: Added broadcast_3_piece0 in memory on 10.1.2.152:44417 (size: 2.2 KB, free: 159.5 MB)
17/01/29 04:52:53,011 INFO TaskSetManager: Finished task 0.0 in stage 2.0 (TID 60) in 74 ms on 10.1.2.60 (2/59)
17/01/29 04:52:53,012 INFO TaskSetManager: Starting task 12.0 in stage 2.0 (TID 69, 10.1.2.60, partition 12, PROCESS_LOCAL, 5372 bytes)
17/01/29 04:52:53,013 INFO CoarseGrainedSchedulerBackend$DriverEndpoint: Launching task 69 on executor id: 1 hostname: 10.1.2.60.
17/01/29 04:52:53,027 INFO TaskSetManager: Starting task 13.0 in stage 2.0 (TID 70, 10.1.2.60, partition 13, PROCESS_LOCAL, 5372 bytes)
17/01/29 04:52:53,028 INFO CoarseGrainedSchedulerBackend$DriverEndpoint: Launching task 70 on executor id: 1 hostname: 10.1.2.60.
17/01/29 04:52:53,028 INFO TaskSetManager: Finished task 7.0 in stage 2.0 (TID 68) in 28 ms on 10.1.2.60 (3/59)
17/01/29 04:52:53,032 INFO TaskSetManager: Starting task 14.0 in stage 2.0 (TID 71, 10.1.2.60, partition 14, PROCESS_LOCAL, 5372 bytes)
17/01/29 04:52:53,032 INFO CoarseGrainedSchedulerBackend$DriverEndpoint: Launching task 71 on executor id: 1 hostname: 10.1.2.60.
17/01/29 04:52:53,033 INFO TaskSetManager: Finished task 2.0 in stage 2.0 (TID 62) in 92 ms on 10.1.2.60 (4/59)
17/01/29 04:52:53,043 INFO TaskSetManager: Starting task 15.0 in stage 2.0 (TID 72, 10.1.2.60, partition 15, PROCESS_LOCAL, 5372 bytes)
17/01/29 04:52:53,044 INFO CoarseGrainedSchedulerBackend$DriverEndpoint: Launching task 72 on executor id: 1 hostname: 10.1.2.60.
17/01/29 04:52:53,044 INFO TaskSetManager: Finished task 6.0 in stage 2.0 (TID 66) in 101 ms on 10.1.2.60 (5/59)
17/01/29 04:52:53,049 INFO TaskSetManager: Finished task 12.0 in stage 2.0 (TID 69) in 38 ms on 10.1.2.60 (6/59)
17/01/29 04:52:53,051 INFO TaskSetManager: Starting task 18.0 in stage 2.0 (TID 73, 10.1.2.60, partition 18, PROCESS_LOCAL, 5372 bytes)
17/01/29 04:52:53,051 INFO CoarseGrainedSchedulerBackend$DriverEndpoint: Launching task 73 on executor id: 1 hostname: 10.1.2.60.
17/01/29 04:52:53,060 INFO TaskSetManager: Starting task 9.0 in stage 2.0 (TID 74, 10.1.2.152, partition 9, PROCESS_LOCAL, 5372 bytes)
17/01/29 04:52:53,061 INFO CoarseGrainedSchedulerBackend$DriverEndpoint: Launching task 74 on executor id: 0 hostname: 10.1.2.152.
17/01/29 04:52:53,061 INFO TaskSetManager: Finished task 8.0 in stage 2.0 (TID 67) in 117 ms on 10.1.2.152 (7/59)
17/01/29 04:52:53,074 INFO TaskSetManager: Starting task 21.0 in stage 2.0 (TID 75, 10.1.2.60, partition 21, PROCESS_LOCAL, 5372 bytes)
17/01/29 04:52:53,074 INFO CoarseGrainedSchedulerBackend$DriverEndpoint: Launching task 75 on executor id: 1 hostname: 10.1.2.60.
17/01/29 04:52:53,074 INFO TaskSetManager: Finished task 13.0 in stage 2.0 (TID 70) in 47 ms on 10.1.2.60 (8/59)
17/01/29 04:52:53,078 INFO TaskSetManager: Starting task 22.0 in stage 2.0 (TID 76, 10.1.2.60, partition 22, PROCESS_LOCAL, 5372 bytes)
17/01/29 04:52:53,079 INFO CoarseGrainedSchedulerBackend$DriverEndpoint: Launching task 76 on executor id: 1 hostname: 10.1.2.60.
17/01/29 04:52:53,079 INFO TaskSetManager: Finished task 14.0 in stage 2.0 (TID 71) in 48 ms on 10.1.2.60 (9/59)
17/01/29 04:52:53,083 INFO TaskSetManager: Starting task 23.0 in stage 2.0 (TID 77, 10.1.2.60, partition 23, PROCESS_LOCAL, 5372 bytes)
17/01/29 04:52:53,083 INFO CoarseGrainedSchedulerBackend$DriverEndpoint: Launching task 77 on executor id: 1 hostname: 10.1.2.60.
17/01/29 04:52:53,083 INFO TaskSetManager: Finished task 15.0 in stage 2.0 (TID 72) in 41 ms on 10.1.2.60 (10/59)
17/01/29 04:52:53,088 INFO TaskSetManager: Starting task 10.0 in stage 2.0 (TID 78, 10.1.2.152, partition 10, PROCESS_LOCAL, 5372 bytes)
17/01/29 04:52:53,088 INFO CoarseGrainedSchedulerBackend$DriverEndpoint: Launching task 78 on executor id: 0 hostname: 10.1.2.152.
17/01/29 04:52:53,089 INFO TaskSetManager: Finished task 9.0 in stage 2.0 (TID 74) in 28 ms on 10.1.2.152 (11/59)
17/01/29 04:52:53,093 INFO TaskSetManager: Starting task 25.0 in stage 2.0 (TID 79, 10.1.2.60, partition 25, PROCESS_LOCAL, 5372 bytes)
17/01/29 04:52:53,094 INFO CoarseGrainedSchedulerBackend$DriverEndpoint: Launching task 79 on executor id: 1 hostname: 10.1.2.60.
17/01/29 04:52:53,094 INFO TaskSetManager: Finished task 18.0 in stage 2.0 (TID 73) in 43 ms on 10.1.2.60 (12/59)
17/01/29 04:52:53,098 INFO TaskSetManager: Starting task 11.0 in stage 2.0 (TID 80, 10.1.2.152, partition 11, PROCESS_LOCAL, 5372 bytes)
17/01/29 04:52:53,099 INFO CoarseGrainedSchedulerBackend$DriverEndpoint: Launching task 80 on executor id: 0 hostname: 10.1.2.152.
17/01/29 04:52:53,099 INFO TaskSetManager: Finished task 1.0 in stage 2.0 (TID 61) in 160 ms on 10.1.2.152 (13/59)
17/01/29 04:52:53,105 INFO TaskSetManager: Finished task 22.0 in stage 2.0 (TID 76) in 27 ms on 10.1.2.60 (14/59)
17/01/29 04:52:53,106 INFO TaskSetManager: Starting task 26.0 in stage 2.0 (TID 81, 10.1.2.60, partition 26, PROCESS_LOCAL, 5372 bytes)
17/01/29 04:52:53,106 INFO CoarseGrainedSchedulerBackend$DriverEndpoint: Launching task 81 on executor id: 1 hostname: 10.1.2.60.
17/01/29 04:52:53,113 INFO TaskSetManager: Starting task 28.0 in stage 2.0 (TID 82, 10.1.2.60, partition 28, PROCESS_LOCAL, 5372 bytes)
17/01/29 04:52:53,114 INFO CoarseGrainedSchedulerBackend$DriverEndpoint: Launching task 82 on executor id: 1 hostname: 10.1.2.60.
17/01/29 04:52:53,114 INFO TaskSetManager: Finished task 21.0 in stage 2.0 (TID 75) in 41 ms on 10.1.2.60 (15/59)
17/01/29 04:52:53,120 INFO TaskSetManager: Starting task 31.0 in stage 2.0 (TID 83, 10.1.2.60, partition 31, PROCESS_LOCAL, 5372 bytes)
17/01/29 04:52:53,120 INFO CoarseGrainedSchedulerBackend$DriverEndpoint: Launching task 83 on executor id: 1 hostname: 10.1.2.60.
17/01/29 04:52:53,121 INFO TaskSetManager: Starting task 16.0 in stage 2.0 (TID 84, 10.1.2.152, partition 16, PROCESS_LOCAL, 5372 bytes)
17/01/29 04:52:53,122 INFO CoarseGrainedSchedulerBackend$DriverEndpoint: Launching task 84 on executor id: 0 hostname: 10.1.2.152.
17/01/29 04:52:53,126 INFO TaskSetManager: Starting task 33.0 in stage 2.0 (TID 85, 10.1.2.60, partition 33, PROCESS_LOCAL, 5372 bytes)
17/01/29 04:52:53,126 INFO CoarseGrainedSchedulerBackend$DriverEndpoint: Launching task 85 on executor id: 1 hostname: 10.1.2.60.
17/01/29 04:52:53,127 INFO TaskSetManager: Finished task 10.0 in stage 2.0 (TID 78) in 40 ms on 10.1.2.152 (16/59)
17/01/29 04:52:53,128 INFO TaskSetManager: Finished task 25.0 in stage 2.0 (TID 79) in 35 ms on 10.1.2.60 (17/59)
17/01/29 04:52:53,128 INFO TaskSetManager: Finished task 23.0 in stage 2.0 (TID 77) in 46 ms on 10.1.2.60 (18/59)
17/01/29 04:52:53,133 INFO TaskSetManager: Starting task 17.0 in stage 2.0 (TID 86, 10.1.2.152, partition 17, PROCESS_LOCAL, 5372 bytes)
17/01/29 04:52:53,133 INFO CoarseGrainedSchedulerBackend$DriverEndpoint: Launching task 86 on executor id: 0 hostname: 10.1.2.152.
17/01/29 04:52:53,133 INFO TaskSetManager: Finished task 3.0 in stage 2.0 (TID 63) in 192 ms on 10.1.2.152 (19/59)
17/01/29 04:52:53,142 INFO TaskSetManager: Starting task 35.0 in stage 2.0 (TID 87, 10.1.2.60, partition 35, PROCESS_LOCAL, 5372 bytes)
17/01/29 04:52:53,142 INFO CoarseGrainedSchedulerBackend$DriverEndpoint: Launching task 87 on executor id: 1 hostname: 10.1.2.60.
17/01/29 04:52:53,143 INFO TaskSetManager: Finished task 26.0 in stage 2.0 (TID 81) in 37 ms on 10.1.2.60 (20/59)
17/01/29 04:52:53,145 INFO TaskSetManager: Starting task 19.0 in stage 2.0 (TID 88, 10.1.2.152, partition 19, PROCESS_LOCAL, 5372 bytes)
17/01/29 04:52:53,146 INFO CoarseGrainedSchedulerBackend$DriverEndpoint: Launching task 88 on executor id: 0 hostname: 10.1.2.152.
17/01/29 04:52:53,146 INFO TaskSetManager: Finished task 16.0 in stage 2.0 (TID 84) in 25 ms on 10.1.2.152 (21/59)
17/01/29 04:52:53,147 INFO TaskSetManager: Starting task 36.0 in stage 2.0 (TID 89, 10.1.2.60, partition 36, PROCESS_LOCAL, 5372 bytes)
17/01/29 04:52:53,148 INFO CoarseGrainedSchedulerBackend$DriverEndpoint: Launching task 89 on executor id: 1 hostname: 10.1.2.60.
17/01/29 04:52:53,148 INFO TaskSetManager: Finished task 28.0 in stage 2.0 (TID 82) in 35 ms on 10.1.2.60 (22/59)
17/01/29 04:52:53,151 INFO TaskSetManager: Starting task 37.0 in stage 2.0 (TID 90, 10.1.2.60, partition 37, PROCESS_LOCAL, 5372 bytes)
17/01/29 04:52:53,152 INFO CoarseGrainedSchedulerBackend$DriverEndpoint: Launching task 90 on executor id: 1 hostname: 10.1.2.60.
17/01/29 04:52:53,152 INFO TaskSetManager: Finished task 31.0 in stage 2.0 (TID 83) in 33 ms on 10.1.2.60 (23/59)
17/01/29 04:52:53,155 INFO TaskSetManager: Starting task 20.0 in stage 2.0 (TID 91, 10.1.2.152, partition 20, PROCESS_LOCAL, 5372 bytes)
17/01/29 04:52:53,155 INFO CoarseGrainedSchedulerBackend$DriverEndpoint: Launching task 91 on executor id: 0 hostname: 10.1.2.152.
17/01/29 04:52:53,155 INFO TaskSetManager: Finished task 11.0 in stage 2.0 (TID 80) in 57 ms on 10.1.2.152 (24/59)
17/01/29 04:52:53,158 INFO TaskSetManager: Starting task 24.0 in stage 2.0 (TID 92, 10.1.2.152, partition 24, PROCESS_LOCAL, 5372 bytes)
17/01/29 04:52:53,158 INFO CoarseGrainedSchedulerBackend$DriverEndpoint: Launching task 92 on executor id: 0 hostname: 10.1.2.152.
17/01/29 04:52:53,158 INFO TaskSetManager: Finished task 17.0 in stage 2.0 (TID 86) in 26 ms on 10.1.2.152 (25/59)
17/01/29 04:52:53,163 INFO TaskSetManager: Starting task 40.0 in stage 2.0 (TID 93, 10.1.2.60, partition 40, PROCESS_LOCAL, 5372 bytes)
17/01/29 04:52:53,164 INFO CoarseGrainedSchedulerBackend$DriverEndpoint: Launching task 93 on executor id: 1 hostname: 10.1.2.60.
17/01/29 04:52:53,164 INFO TaskSetManager: Finished task 33.0 in stage 2.0 (TID 85) in 39 ms on 10.1.2.60 (26/59)
17/01/29 04:52:53,179 INFO TaskSetManager: Starting task 41.0 in stage 2.0 (TID 94, 10.1.2.60, partition 41, PROCESS_LOCAL, 5372 bytes)
17/01/29 04:52:53,180 INFO CoarseGrainedSchedulerBackend$DriverEndpoint: Launching task 94 on executor id: 1 hostname: 10.1.2.60.
17/01/29 04:52:53,180 INFO TaskSetManager: Finished task 36.0 in stage 2.0 (TID 89) in 33 ms on 10.1.2.60 (27/59)
17/01/29 04:52:53,181 INFO TaskSetManager: Starting task 27.0 in stage 2.0 (TID 95, 10.1.2.152, partition 27, PROCESS_LOCAL, 5372 bytes)
17/01/29 04:52:53,182 INFO TaskSetManager: Finished task 19.0 in stage 2.0 (TID 88) in 36 ms on 10.1.2.152 (28/59)
17/01/29 04:52:53,182 INFO CoarseGrainedSchedulerBackend$DriverEndpoint: Launching task 95 on executor id: 0 hostname: 10.1.2.152.
17/01/29 04:52:53,183 INFO TaskSetManager: Starting task 29.0 in stage 2.0 (TID 96, 10.1.2.152, partition 29, PROCESS_LOCAL, 5372 bytes)
17/01/29 04:52:53,183 INFO CoarseGrainedSchedulerBackend$DriverEndpoint: Launching task 96 on executor id: 0 hostname: 10.1.2.152.
17/01/29 04:52:53,183 INFO TaskSetManager: Finished task 20.0 in stage 2.0 (TID 91) in 29 ms on 10.1.2.152 (29/59)
17/01/29 04:52:53,185 INFO TaskSetManager: Finished task 24.0 in stage 2.0 (TID 92) in 27 ms on 10.1.2.152 (30/59)
17/01/29 04:52:53,186 INFO TaskSetManager: Starting task 30.0 in stage 2.0 (TID 97, 10.1.2.152, partition 30, PROCESS_LOCAL, 5372 bytes)
17/01/29 04:52:53,186 INFO CoarseGrainedSchedulerBackend$DriverEndpoint: Launching task 97 on executor id: 0 hostname: 10.1.2.152.
17/01/29 04:52:53,189 INFO TaskSetManager: Starting task 42.0 in stage 2.0 (TID 98, 10.1.2.60, partition 42, PROCESS_LOCAL, 5372 bytes)
17/01/29 04:52:53,189 INFO CoarseGrainedSchedulerBackend$DriverEndpoint: Launching task 98 on executor id: 1 hostname: 10.1.2.60.
17/01/29 04:52:53,190 INFO TaskSetManager: Finished task 35.0 in stage 2.0 (TID 87) in 48 ms on 10.1.2.60 (31/59)
17/01/29 04:52:53,191 INFO TaskSetManager: Starting task 45.0 in stage 2.0 (TID 99, 10.1.2.60, partition 45, PROCESS_LOCAL, 5372 bytes)
17/01/29 04:52:53,191 INFO CoarseGrainedSchedulerBackend$DriverEndpoint: Launching task 99 on executor id: 1 hostname: 10.1.2.60.
17/01/29 04:52:53,191 INFO TaskSetManager: Finished task 37.0 in stage 2.0 (TID 90) in 40 ms on 10.1.2.60 (32/59)
17/01/29 04:52:53,198 INFO TaskSetManager: Starting task 32.0 in stage 2.0 (TID 100, 10.1.2.152, partition 32, PROCESS_LOCAL, 5372 bytes)
17/01/29 04:52:53,199 INFO CoarseGrainedSchedulerBackend$DriverEndpoint: Launching task 100 on executor id: 0 hostname: 10.1.2.152.
17/01/29 04:52:53,199 INFO TaskSetManager: Finished task 5.0 in stage 2.0 (TID 65) in 256 ms on 10.1.2.152 (33/59)
17/01/29 04:52:53,203 INFO TaskSetManager: Starting task 48.0 in stage 2.0 (TID 101, 10.1.2.60, partition 48, PROCESS_LOCAL, 5372 bytes)
17/01/29 04:52:53,204 INFO CoarseGrainedSchedulerBackend$DriverEndpoint: Launching task 101 on executor id: 1 hostname: 10.1.2.60.
17/01/29 04:52:53,204 INFO TaskSetManager: Finished task 40.0 in stage 2.0 (TID 93) in 41 ms on 10.1.2.60 (34/59)
17/01/29 04:52:53,206 INFO TaskSetManager: Starting task 34.0 in stage 2.0 (TID 102, 10.1.2.152, partition 34, PROCESS_LOCAL, 5372 bytes)
17/01/29 04:52:53,206 INFO CoarseGrainedSchedulerBackend$DriverEndpoint: Launching task 102 on executor id: 0 hostname: 10.1.2.152.
17/01/29 04:52:53,206 INFO TaskSetManager: Finished task 27.0 in stage 2.0 (TID 95) in 26 ms on 10.1.2.152 (35/59)
17/01/29 04:52:53,218 INFO TaskSetManager: Starting task 49.0 in stage 2.0 (TID 103, 10.1.2.60, partition 49, PROCESS_LOCAL, 5372 bytes)
17/01/29 04:52:53,218 INFO CoarseGrainedSchedulerBackend$DriverEndpoint: Launching task 103 on executor id: 1 hostname: 10.1.2.60.
17/01/29 04:52:53,219 INFO TaskSetManager: Finished task 41.0 in stage 2.0 (TID 94) in 39 ms on 10.1.2.60 (36/59)
17/01/29 04:52:53,222 INFO TaskSetManager: Starting task 50.0 in stage 2.0 (TID 104, 10.1.2.60, partition 50, PROCESS_LOCAL, 5372 bytes)
17/01/29 04:52:53,222 INFO CoarseGrainedSchedulerBackend$DriverEndpoint: Launching task 104 on executor id: 1 hostname: 10.1.2.60.
17/01/29 04:52:53,223 INFO TaskSetManager: Finished task 45.0 in stage 2.0 (TID 99) in 32 ms on 10.1.2.60 (37/59)
17/01/29 04:52:53,227 INFO TaskSetManager: Starting task 51.0 in stage 2.0 (TID 105, 10.1.2.60, partition 51, PROCESS_LOCAL, 5372 bytes)
17/01/29 04:52:53,227 INFO CoarseGrainedSchedulerBackend$DriverEndpoint: Launching task 105 on executor id: 1 hostname: 10.1.2.60.
17/01/29 04:52:53,228 INFO TaskSetManager: Finished task 42.0 in stage 2.0 (TID 98) in 39 ms on 10.1.2.60 (38/59)
17/01/29 04:52:53,244 INFO TaskSetManager: Finished task 49.0 in stage 2.0 (TID 103) in 26 ms on 10.1.2.60 (39/59)
17/01/29 04:52:53,246 INFO TaskSetManager: Finished task 48.0 in stage 2.0 (TID 101) in 43 ms on 10.1.2.60 (40/59)
17/01/29 04:52:53,252 INFO TaskSetManager: Starting task 38.0 in stage 2.0 (TID 106, 10.1.2.152, partition 38, PROCESS_LOCAL, 5372 bytes)
17/01/29 04:52:53,253 INFO CoarseGrainedSchedulerBackend$DriverEndpoint: Launching task 106 on executor id: 0 hostname: 10.1.2.152.
17/01/29 04:52:53,253 INFO TaskSetManager: Finished task 29.0 in stage 2.0 (TID 96) in 71 ms on 10.1.2.152 (41/59)
17/01/29 04:52:53,255 INFO TaskSetManager: Finished task 51.0 in stage 2.0 (TID 105) in 28 ms on 10.1.2.60 (42/59)
17/01/29 04:52:53,260 INFO TaskSetManager: Starting task 39.0 in stage 2.0 (TID 107, 10.1.2.152, partition 39, PROCESS_LOCAL, 5372 bytes)
17/01/29 04:52:53,260 INFO CoarseGrainedSchedulerBackend$DriverEndpoint: Launching task 107 on executor id: 0 hostname: 10.1.2.152.
17/01/29 04:52:53,261 INFO TaskSetManager: Finished task 32.0 in stage 2.0 (TID 100) in 62 ms on 10.1.2.152 (43/59)
17/01/29 04:52:53,262 INFO TaskSetManager: Starting task 43.0 in stage 2.0 (TID 108, 10.1.2.152, partition 43, PROCESS_LOCAL, 5372 bytes)
17/01/29 04:52:53,263 INFO CoarseGrainedSchedulerBackend$DriverEndpoint: Launching task 108 on executor id: 0 hostname: 10.1.2.152.
17/01/29 04:52:53,263 INFO TaskSetManager: Finished task 30.0 in stage 2.0 (TID 97) in 78 ms on 10.1.2.152 (44/59)
17/01/29 04:52:53,274 INFO TaskSetManager: Finished task 50.0 in stage 2.0 (TID 104) in 52 ms on 10.1.2.60 (45/59)
17/01/29 04:52:53,281 INFO TaskSetManager: Starting task 44.0 in stage 2.0 (TID 109, 10.1.2.152, partition 44, PROCESS_LOCAL, 5372 bytes)
17/01/29 04:52:53,281 INFO CoarseGrainedSchedulerBackend$DriverEndpoint: Launching task 109 on executor id: 0 hostname: 10.1.2.152.
17/01/29 04:52:53,282 INFO TaskSetManager: Finished task 34.0 in stage 2.0 (TID 102) in 76 ms on 10.1.2.152 (46/59)
17/01/29 04:52:53,285 INFO TaskSetManager: Starting task 46.0 in stage 2.0 (TID 110, 10.1.2.152, partition 46, PROCESS_LOCAL, 5372 bytes)
17/01/29 04:52:53,285 INFO CoarseGrainedSchedulerBackend$DriverEndpoint: Launching task 110 on executor id: 0 hostname: 10.1.2.152.
17/01/29 04:52:53,285 INFO TaskSetManager: Finished task 43.0 in stage 2.0 (TID 108) in 23 ms on 10.1.2.152 (47/59)
17/01/29 04:52:53,286 INFO TaskSetManager: Starting task 47.0 in stage 2.0 (TID 111, 10.1.2.152, partition 47, PROCESS_LOCAL, 5372 bytes)
17/01/29 04:52:53,287 INFO CoarseGrainedSchedulerBackend$DriverEndpoint: Launching task 111 on executor id: 0 hostname: 10.1.2.152.
17/01/29 04:52:53,287 INFO TaskSetManager: Finished task 38.0 in stage 2.0 (TID 106) in 35 ms on 10.1.2.152 (48/59)
17/01/29 04:52:53,293 INFO TaskSetManager: Starting task 52.0 in stage 2.0 (TID 112, 10.1.2.152, partition 52, PROCESS_LOCAL, 5372 bytes)
17/01/29 04:52:53,293 INFO CoarseGrainedSchedulerBackend$DriverEndpoint: Launching task 112 on executor id: 0 hostname: 10.1.2.152.
17/01/29 04:52:53,293 INFO TaskSetManager: Finished task 39.0 in stage 2.0 (TID 107) in 33 ms on 10.1.2.152 (49/59)
17/01/29 04:52:53,308 INFO TaskSetManager: Starting task 53.0 in stage 2.0 (TID 113, 10.1.2.152, partition 53, PROCESS_LOCAL, 5372 bytes)
17/01/29 04:52:53,309 INFO CoarseGrainedSchedulerBackend$DriverEndpoint: Launching task 113 on executor id: 0 hostname: 10.1.2.152.
17/01/29 04:52:53,309 INFO TaskSetManager: Finished task 46.0 in stage 2.0 (TID 110) in 25 ms on 10.1.2.152 (50/59)
17/01/29 04:52:53,310 INFO TaskSetManager: Starting task 54.0 in stage 2.0 (TID 114, 10.1.2.152, partition 54, PROCESS_LOCAL, 5372 bytes)
17/01/29 04:52:53,310 INFO CoarseGrainedSchedulerBackend$DriverEndpoint: Launching task 114 on executor id: 0 hostname: 10.1.2.152.
17/01/29 04:52:53,310 INFO TaskSetManager: Finished task 44.0 in stage 2.0 (TID 109) in 29 ms on 10.1.2.152 (51/59)
17/01/29 04:52:53,311 INFO TaskSetManager: Starting task 55.0 in stage 2.0 (TID 115, 10.1.2.152, partition 55, PROCESS_LOCAL, 5372 bytes)
17/01/29 04:52:53,311 INFO CoarseGrainedSchedulerBackend$DriverEndpoint: Launching task 115 on executor id: 0 hostname: 10.1.2.152.
17/01/29 04:52:53,312 INFO TaskSetManager: Finished task 47.0 in stage 2.0 (TID 111) in 25 ms on 10.1.2.152 (52/59)
17/01/29 04:52:53,323 INFO TaskSetManager: Starting task 58.0 in stage 2.0 (TID 116, 10.1.2.152, partition 58, PROCESS_LOCAL, 5372 bytes)
17/01/29 04:52:53,324 INFO CoarseGrainedSchedulerBackend$DriverEndpoint: Launching task 116 on executor id: 0 hostname: 10.1.2.152.
17/01/29 04:52:53,324 INFO TaskSetManager: Finished task 52.0 in stage 2.0 (TID 112) in 31 ms on 10.1.2.152 (53/59)
17/01/29 04:52:53,339 INFO TaskSetManager: Finished task 53.0 in stage 2.0 (TID 113) in 31 ms on 10.1.2.152 (54/59)
17/01/29 04:52:53,348 INFO TaskSetManager: Finished task 58.0 in stage 2.0 (TID 116) in 25 ms on 10.1.2.152 (55/59)
17/01/29 04:52:53,349 INFO TaskSetManager: Finished task 55.0 in stage 2.0 (TID 115) in 38 ms on 10.1.2.152 (56/59)
17/01/29 04:52:53,354 INFO TaskSetManager: Finished task 54.0 in stage 2.0 (TID 114) in 44 ms on 10.1.2.152 (57/59)
17/01/29 04:52:56,632 INFO TaskSetManager: Starting task 56.0 in stage 2.0 (TID 117, 10.1.2.60, partition 56, ANY, 5372 bytes)
17/01/29 04:52:56,633 INFO TaskSetManager: Starting task 57.0 in stage 2.0 (TID 118, 10.1.2.152, partition 57, ANY, 5372 bytes)
17/01/29 04:52:56,633 INFO CoarseGrainedSchedulerBackend$DriverEndpoint: Launching task 117 on executor id: 1 hostname: 10.1.2.60.
17/01/29 04:52:56,633 INFO CoarseGrainedSchedulerBackend$DriverEndpoint: Launching task 118 on executor id: 0 hostname: 10.1.2.152.
17/01/29 04:53:02,147 INFO BlockManagerInfo: Added rdd_5_57 in memory on 10.1.2.152:44417 (size: 70.1 MB, free: 89.4 MB)
17/01/29 04:53:02,171 INFO TaskSetManager: Finished task 57.0 in stage 2.0 (TID 118) in 5539 ms on 10.1.2.152 (58/59)
17/01/29 04:53:02,275 INFO TaskSetManager: Finished task 56.0 in stage 2.0 (TID 117) in 5643 ms on 10.1.2.60 (59/59)
17/01/29 04:53:02,275 INFO TaskSchedulerImpl: Removed TaskSet 2.0, whose tasks have all completed, from pool 
17/01/29 04:53:02,276 INFO DAGScheduler: ResultStage 2 (count at GradientDescent.scala:209) finished in 9.339 s
17/01/29 04:53:02,277 INFO DAGScheduler: Job 2 finished: count at GradientDescent.scala:209, took 9.363254 s
17/01/29 04:53:02,512 WARN BLAS: Failed to load implementation from: com.github.fommil.netlib.NativeSystemBLAS
17/01/29 04:53:02,512 WARN BLAS: Failed to load implementation from: com.github.fommil.netlib.NativeRefBLAS
17/01/29 04:53:02,535 INFO MemoryStore: Block broadcast_4 stored as values in memory (estimated size 280.0 B, free 2.1 GB)
17/01/29 04:53:02,538 INFO MemoryStore: Block broadcast_4_piece0 stored as bytes in memory (estimated size 153.0 B, free 2.1 GB)
17/01/29 04:53:02,539 INFO BlockManagerInfo: Added broadcast_4_piece0 in memory on 10.1.2.31:36764 (size: 153.0 B, free: 2.1 GB)
17/01/29 04:53:02,540 INFO SparkContext: Created broadcast 4 from broadcast at GradientDescent.scala:235
17/01/29 04:53:02,598 INFO SparkContext: Starting job: treeAggregate at GradientDescent.scala:239
17/01/29 04:53:02,607 INFO DAGScheduler: Registering RDD 11 (treeAggregate at GradientDescent.scala:239)
17/01/29 04:53:02,607 INFO DAGScheduler: Got job 3 (treeAggregate at GradientDescent.scala:239) with 7 output partitions
17/01/29 04:53:02,607 INFO DAGScheduler: Final stage: ResultStage 4 (treeAggregate at GradientDescent.scala:239)
17/01/29 04:53:02,608 INFO DAGScheduler: Parents of final stage: List(ShuffleMapStage 3)
17/01/29 04:53:02,608 INFO DAGScheduler: Missing parents: List(ShuffleMapStage 3)
17/01/29 04:53:02,614 INFO DAGScheduler: Submitting ShuffleMapStage 3 (MapPartitionsRDD[11] at treeAggregate at GradientDescent.scala:239), which has no missing parents
17/01/29 04:53:02,635 INFO MemoryStore: Block broadcast_5 stored as values in memory (estimated size 7.2 KB, free 2.1 GB)
17/01/29 04:53:02,636 INFO MemoryStore: Block broadcast_5_piece0 stored as bytes in memory (estimated size 3.7 KB, free 2.1 GB)
17/01/29 04:53:02,637 INFO BlockManagerInfo: Added broadcast_5_piece0 in memory on 10.1.2.31:36764 (size: 3.7 KB, free: 2.1 GB)
17/01/29 04:53:02,638 INFO SparkContext: Created broadcast 5 from broadcast at DAGScheduler.scala:1012
17/01/29 04:53:02,640 INFO DAGScheduler: Submitting 59 missing tasks from ShuffleMapStage 3 (MapPartitionsRDD[11] at treeAggregate at GradientDescent.scala:239)
17/01/29 04:53:02,640 INFO TaskSchedulerImpl: Adding task set 3.0 with 59 tasks
17/01/29 04:53:02,644 INFO TaskSetManager: Starting task 0.0 in stage 3.0 (TID 119, 10.1.2.60, partition 0, PROCESS_LOCAL, 5561 bytes)
17/01/29 04:53:02,644 INFO TaskSetManager: Starting task 1.0 in stage 3.0 (TID 120, 10.1.2.152, partition 1, PROCESS_LOCAL, 5561 bytes)
17/01/29 04:53:02,645 INFO TaskSetManager: Starting task 2.0 in stage 3.0 (TID 121, 10.1.2.60, partition 2, PROCESS_LOCAL, 5561 bytes)
17/01/29 04:53:02,645 INFO TaskSetManager: Starting task 3.0 in stage 3.0 (TID 122, 10.1.2.152, partition 3, PROCESS_LOCAL, 5561 bytes)
17/01/29 04:53:02,646 INFO TaskSetManager: Starting task 4.0 in stage 3.0 (TID 123, 10.1.2.60, partition 4, PROCESS_LOCAL, 5561 bytes)
17/01/29 04:53:02,646 INFO TaskSetManager: Starting task 5.0 in stage 3.0 (TID 124, 10.1.2.152, partition 5, PROCESS_LOCAL, 5561 bytes)
17/01/29 04:53:02,647 INFO TaskSetManager: Starting task 6.0 in stage 3.0 (TID 125, 10.1.2.60, partition 6, PROCESS_LOCAL, 5561 bytes)
17/01/29 04:53:02,647 INFO TaskSetManager: Starting task 8.0 in stage 3.0 (TID 126, 10.1.2.152, partition 8, PROCESS_LOCAL, 5561 bytes)
17/01/29 04:53:02,647 INFO CoarseGrainedSchedulerBackend$DriverEndpoint: Launching task 119 on executor id: 1 hostname: 10.1.2.60.
17/01/29 04:53:02,648 INFO CoarseGrainedSchedulerBackend$DriverEndpoint: Launching task 121 on executor id: 1 hostname: 10.1.2.60.
17/01/29 04:53:02,648 INFO CoarseGrainedSchedulerBackend$DriverEndpoint: Launching task 123 on executor id: 1 hostname: 10.1.2.60.
17/01/29 04:53:02,648 INFO CoarseGrainedSchedulerBackend$DriverEndpoint: Launching task 125 on executor id: 1 hostname: 10.1.2.60.
17/01/29 04:53:02,648 INFO CoarseGrainedSchedulerBackend$DriverEndpoint: Launching task 120 on executor id: 0 hostname: 10.1.2.152.
17/01/29 04:53:02,649 INFO CoarseGrainedSchedulerBackend$DriverEndpoint: Launching task 122 on executor id: 0 hostname: 10.1.2.152.
17/01/29 04:53:02,649 INFO CoarseGrainedSchedulerBackend$DriverEndpoint: Launching task 124 on executor id: 0 hostname: 10.1.2.152.
17/01/29 04:53:02,649 INFO CoarseGrainedSchedulerBackend$DriverEndpoint: Launching task 126 on executor id: 0 hostname: 10.1.2.152.
17/01/29 04:53:02,666 INFO BlockManagerInfo: Added broadcast_5_piece0 in memory on 10.1.2.152:44417 (size: 3.7 KB, free: 89.4 MB)
17/01/29 04:53:02,671 INFO BlockManagerInfo: Added broadcast_5_piece0 in memory on 10.1.2.60:41797 (size: 3.7 KB, free: 92.7 MB)
17/01/29 04:53:02,950 INFO BlockManagerInfo: Added broadcast_4_piece0 in memory on 10.1.2.152:44417 (size: 153.0 B, free: 89.4 MB)
17/01/29 04:53:02,974 INFO BlockManagerInfo: Added broadcast_4_piece0 in memory on 10.1.2.60:41797 (size: 153.0 B, free: 92.7 MB)
17/01/29 04:53:03,118 INFO TaskSetManager: Starting task 9.0 in stage 3.0 (TID 127, 10.1.2.152, partition 9, PROCESS_LOCAL, 5561 bytes)
17/01/29 04:53:03,118 INFO CoarseGrainedSchedulerBackend$DriverEndpoint: Launching task 127 on executor id: 0 hostname: 10.1.2.152.
17/01/29 04:53:03,119 INFO TaskSetManager: Starting task 10.0 in stage 3.0 (TID 128, 10.1.2.152, partition 10, PROCESS_LOCAL, 5561 bytes)
17/01/29 04:53:03,122 INFO CoarseGrainedSchedulerBackend$DriverEndpoint: Launching task 128 on executor id: 0 hostname: 10.1.2.152.
17/01/29 04:53:03,122 INFO TaskSetManager: Finished task 3.0 in stage 3.0 (TID 122) in 477 ms on 10.1.2.152 (1/59)
17/01/29 04:53:03,122 INFO TaskSetManager: Finished task 8.0 in stage 3.0 (TID 126) in 475 ms on 10.1.2.152 (2/59)
17/01/29 04:53:03,123 INFO TaskSetManager: Starting task 11.0 in stage 3.0 (TID 129, 10.1.2.152, partition 11, PROCESS_LOCAL, 5561 bytes)
17/01/29 04:53:03,124 INFO CoarseGrainedSchedulerBackend$DriverEndpoint: Launching task 129 on executor id: 0 hostname: 10.1.2.152.
17/01/29 04:53:03,124 INFO TaskSetManager: Finished task 5.0 in stage 3.0 (TID 124) in 478 ms on 10.1.2.152 (3/59)
17/01/29 04:53:03,125 INFO TaskSetManager: Starting task 16.0 in stage 3.0 (TID 130, 10.1.2.152, partition 16, PROCESS_LOCAL, 5561 bytes)
17/01/29 04:53:03,125 INFO CoarseGrainedSchedulerBackend$DriverEndpoint: Launching task 130 on executor id: 0 hostname: 10.1.2.152.
17/01/29 04:53:03,125 INFO TaskSetManager: Finished task 1.0 in stage 3.0 (TID 120) in 481 ms on 10.1.2.152 (4/59)
17/01/29 04:53:03,170 INFO TaskSetManager: Starting task 7.0 in stage 3.0 (TID 131, 10.1.2.60, partition 7, PROCESS_LOCAL, 5561 bytes)
17/01/29 04:53:03,170 INFO CoarseGrainedSchedulerBackend$DriverEndpoint: Launching task 131 on executor id: 1 hostname: 10.1.2.60.
17/01/29 04:53:03,170 INFO TaskSetManager: Finished task 4.0 in stage 3.0 (TID 123) in 525 ms on 10.1.2.60 (5/59)
17/01/29 04:53:03,172 INFO TaskSetManager: Starting task 12.0 in stage 3.0 (TID 132, 10.1.2.60, partition 12, PROCESS_LOCAL, 5561 bytes)
17/01/29 04:53:03,172 INFO CoarseGrainedSchedulerBackend$DriverEndpoint: Launching task 132 on executor id: 1 hostname: 10.1.2.60.
17/01/29 04:53:03,172 INFO TaskSetManager: Finished task 2.0 in stage 3.0 (TID 121) in 528 ms on 10.1.2.60 (6/59)
17/01/29 04:53:03,175 INFO TaskSetManager: Starting task 13.0 in stage 3.0 (TID 133, 10.1.2.60, partition 13, PROCESS_LOCAL, 5561 bytes)
17/01/29 04:53:03,176 INFO TaskSetManager: Finished task 0.0 in stage 3.0 (TID 119) in 534 ms on 10.1.2.60 (7/59)
17/01/29 04:53:03,176 INFO CoarseGrainedSchedulerBackend$DriverEndpoint: Launching task 133 on executor id: 1 hostname: 10.1.2.60.
17/01/29 04:53:03,177 INFO TaskSetManager: Finished task 6.0 in stage 3.0 (TID 125) in 531 ms on 10.1.2.60 (8/59)
17/01/29 04:53:03,178 INFO TaskSetManager: Starting task 14.0 in stage 3.0 (TID 134, 10.1.2.60, partition 14, PROCESS_LOCAL, 5561 bytes)
17/01/29 04:53:03,180 INFO CoarseGrainedSchedulerBackend$DriverEndpoint: Launching task 134 on executor id: 1 hostname: 10.1.2.60.
17/01/29 04:53:03,205 INFO TaskSetManager: Starting task 17.0 in stage 3.0 (TID 135, 10.1.2.152, partition 17, PROCESS_LOCAL, 5561 bytes)
17/01/29 04:53:03,205 INFO CoarseGrainedSchedulerBackend$DriverEndpoint: Launching task 135 on executor id: 0 hostname: 10.1.2.152.
17/01/29 04:53:03,205 INFO TaskSetManager: Finished task 9.0 in stage 3.0 (TID 127) in 88 ms on 10.1.2.152 (9/59)
17/01/29 04:53:03,208 INFO TaskSetManager: Starting task 19.0 in stage 3.0 (TID 136, 10.1.2.152, partition 19, PROCESS_LOCAL, 5561 bytes)
17/01/29 04:53:03,208 INFO CoarseGrainedSchedulerBackend$DriverEndpoint: Launching task 136 on executor id: 0 hostname: 10.1.2.152.
17/01/29 04:53:03,208 INFO TaskSetManager: Finished task 10.0 in stage 3.0 (TID 128) in 89 ms on 10.1.2.152 (10/59)
17/01/29 04:53:03,258 INFO TaskSetManager: Starting task 20.0 in stage 3.0 (TID 137, 10.1.2.152, partition 20, PROCESS_LOCAL, 5561 bytes)
17/01/29 04:53:03,259 INFO TaskSetManager: Finished task 11.0 in stage 3.0 (TID 129) in 136 ms on 10.1.2.152 (11/59)
17/01/29 04:53:03,259 INFO CoarseGrainedSchedulerBackend$DriverEndpoint: Launching task 137 on executor id: 0 hostname: 10.1.2.152.
17/01/29 04:53:03,263 INFO TaskSetManager: Starting task 24.0 in stage 3.0 (TID 138, 10.1.2.152, partition 24, PROCESS_LOCAL, 5561 bytes)
17/01/29 04:53:03,263 INFO CoarseGrainedSchedulerBackend$DriverEndpoint: Launching task 138 on executor id: 0 hostname: 10.1.2.152.
17/01/29 04:53:03,264 INFO TaskSetManager: Finished task 16.0 in stage 3.0 (TID 130) in 139 ms on 10.1.2.152 (12/59)
17/01/29 04:53:03,270 INFO TaskSetManager: Starting task 27.0 in stage 3.0 (TID 139, 10.1.2.152, partition 27, PROCESS_LOCAL, 5561 bytes)
17/01/29 04:53:03,272 INFO CoarseGrainedSchedulerBackend$DriverEndpoint: Launching task 139 on executor id: 0 hostname: 10.1.2.152.
17/01/29 04:53:03,272 INFO TaskSetManager: Finished task 19.0 in stage 3.0 (TID 136) in 65 ms on 10.1.2.152 (13/59)
17/01/29 04:53:03,274 INFO TaskSetManager: Starting task 29.0 in stage 3.0 (TID 140, 10.1.2.152, partition 29, PROCESS_LOCAL, 5561 bytes)
17/01/29 04:53:03,275 INFO CoarseGrainedSchedulerBackend$DriverEndpoint: Launching task 140 on executor id: 0 hostname: 10.1.2.152.
17/01/29 04:53:03,275 INFO TaskSetManager: Finished task 17.0 in stage 3.0 (TID 135) in 71 ms on 10.1.2.152 (14/59)
17/01/29 04:53:03,282 INFO TaskSetManager: Starting task 15.0 in stage 3.0 (TID 141, 10.1.2.60, partition 15, PROCESS_LOCAL, 5561 bytes)
17/01/29 04:53:03,282 INFO CoarseGrainedSchedulerBackend$DriverEndpoint: Launching task 141 on executor id: 1 hostname: 10.1.2.60.
17/01/29 04:53:03,283 INFO TaskSetManager: Finished task 7.0 in stage 3.0 (TID 131) in 114 ms on 10.1.2.60 (15/59)
17/01/29 04:53:03,293 INFO TaskSetManager: Starting task 18.0 in stage 3.0 (TID 142, 10.1.2.60, partition 18, PROCESS_LOCAL, 5561 bytes)
17/01/29 04:53:03,293 INFO CoarseGrainedSchedulerBackend$DriverEndpoint: Launching task 142 on executor id: 1 hostname: 10.1.2.60.
17/01/29 04:53:03,295 INFO TaskSetManager: Finished task 14.0 in stage 3.0 (TID 134) in 116 ms on 10.1.2.60 (16/59)
17/01/29 04:53:03,331 INFO TaskSetManager: Starting task 21.0 in stage 3.0 (TID 143, 10.1.2.60, partition 21, PROCESS_LOCAL, 5561 bytes)
17/01/29 04:53:03,331 INFO CoarseGrainedSchedulerBackend$DriverEndpoint: Launching task 143 on executor id: 1 hostname: 10.1.2.60.
17/01/29 04:53:03,331 INFO TaskSetManager: Finished task 12.0 in stage 3.0 (TID 132) in 160 ms on 10.1.2.60 (17/59)
17/01/29 04:53:03,333 INFO TaskSetManager: Starting task 30.0 in stage 3.0 (TID 144, 10.1.2.152, partition 30, PROCESS_LOCAL, 5561 bytes)
17/01/29 04:53:03,333 INFO CoarseGrainedSchedulerBackend$DriverEndpoint: Launching task 144 on executor id: 0 hostname: 10.1.2.152.
17/01/29 04:53:03,333 INFO TaskSetManager: Finished task 20.0 in stage 3.0 (TID 137) in 78 ms on 10.1.2.152 (18/59)
17/01/29 04:53:03,338 INFO TaskSetManager: Starting task 32.0 in stage 3.0 (TID 145, 10.1.2.152, partition 32, PROCESS_LOCAL, 5561 bytes)
17/01/29 04:53:03,338 INFO CoarseGrainedSchedulerBackend$DriverEndpoint: Launching task 145 on executor id: 0 hostname: 10.1.2.152.
17/01/29 04:53:03,339 INFO TaskSetManager: Finished task 24.0 in stage 3.0 (TID 138) in 77 ms on 10.1.2.152 (19/59)
17/01/29 04:53:03,344 INFO TaskSetManager: Starting task 34.0 in stage 3.0 (TID 146, 10.1.2.152, partition 34, PROCESS_LOCAL, 5561 bytes)
17/01/29 04:53:03,344 INFO CoarseGrainedSchedulerBackend$DriverEndpoint: Launching task 146 on executor id: 0 hostname: 10.1.2.152.
17/01/29 04:53:03,345 INFO TaskSetManager: Finished task 27.0 in stage 3.0 (TID 139) in 76 ms on 10.1.2.152 (20/59)
17/01/29 04:53:03,349 INFO TaskSetManager: Starting task 22.0 in stage 3.0 (TID 147, 10.1.2.60, partition 22, PROCESS_LOCAL, 5561 bytes)
17/01/29 04:53:03,349 INFO CoarseGrainedSchedulerBackend$DriverEndpoint: Launching task 147 on executor id: 1 hostname: 10.1.2.60.
17/01/29 04:53:03,350 INFO TaskSetManager: Finished task 13.0 in stage 3.0 (TID 133) in 174 ms on 10.1.2.60 (21/59)
17/01/29 04:53:03,353 INFO TaskSetManager: Starting task 38.0 in stage 3.0 (TID 148, 10.1.2.152, partition 38, PROCESS_LOCAL, 5561 bytes)
17/01/29 04:53:03,353 INFO CoarseGrainedSchedulerBackend$DriverEndpoint: Launching task 148 on executor id: 0 hostname: 10.1.2.152.
17/01/29 04:53:03,353 INFO TaskSetManager: Finished task 29.0 in stage 3.0 (TID 140) in 80 ms on 10.1.2.152 (22/59)
17/01/29 04:53:03,361 INFO TaskSetManager: Starting task 23.0 in stage 3.0 (TID 149, 10.1.2.60, partition 23, PROCESS_LOCAL, 5561 bytes)
17/01/29 04:53:03,361 INFO CoarseGrainedSchedulerBackend$DriverEndpoint: Launching task 149 on executor id: 1 hostname: 10.1.2.60.
17/01/29 04:53:03,362 INFO TaskSetManager: Finished task 18.0 in stage 3.0 (TID 142) in 69 ms on 10.1.2.60 (23/59)
17/01/29 04:53:03,367 INFO TaskSetManager: Starting task 25.0 in stage 3.0 (TID 150, 10.1.2.60, partition 25, PROCESS_LOCAL, 5561 bytes)
17/01/29 04:53:03,367 INFO CoarseGrainedSchedulerBackend$DriverEndpoint: Launching task 150 on executor id: 1 hostname: 10.1.2.60.
17/01/29 04:53:03,368 INFO TaskSetManager: Finished task 15.0 in stage 3.0 (TID 141) in 87 ms on 10.1.2.60 (24/59)
17/01/29 04:53:03,412 INFO TaskSetManager: Starting task 39.0 in stage 3.0 (TID 151, 10.1.2.152, partition 39, PROCESS_LOCAL, 5561 bytes)
17/01/29 04:53:03,412 INFO CoarseGrainedSchedulerBackend$DriverEndpoint: Launching task 151 on executor id: 0 hostname: 10.1.2.152.
17/01/29 04:53:03,413 INFO TaskSetManager: Finished task 30.0 in stage 3.0 (TID 144) in 80 ms on 10.1.2.152 (25/59)
17/01/29 04:53:03,415 INFO TaskSetManager: Starting task 26.0 in stage 3.0 (TID 152, 10.1.2.60, partition 26, PROCESS_LOCAL, 5561 bytes)
17/01/29 04:53:03,415 INFO CoarseGrainedSchedulerBackend$DriverEndpoint: Launching task 152 on executor id: 1 hostname: 10.1.2.60.
17/01/29 04:53:03,415 INFO TaskSetManager: Finished task 22.0 in stage 3.0 (TID 147) in 67 ms on 10.1.2.60 (26/59)
17/01/29 04:53:03,418 INFO TaskSetManager: Starting task 43.0 in stage 3.0 (TID 153, 10.1.2.152, partition 43, PROCESS_LOCAL, 5561 bytes)
17/01/29 04:53:03,418 INFO CoarseGrainedSchedulerBackend$DriverEndpoint: Launching task 153 on executor id: 0 hostname: 10.1.2.152.
17/01/29 04:53:03,419 INFO TaskSetManager: Starting task 44.0 in stage 3.0 (TID 154, 10.1.2.152, partition 44, PROCESS_LOCAL, 5561 bytes)
17/01/29 04:53:03,419 INFO CoarseGrainedSchedulerBackend$DriverEndpoint: Launching task 154 on executor id: 0 hostname: 10.1.2.152.
17/01/29 04:53:03,420 INFO TaskSetManager: Finished task 34.0 in stage 3.0 (TID 146) in 77 ms on 10.1.2.152 (27/59)
17/01/29 04:53:03,420 INFO TaskSetManager: Finished task 32.0 in stage 3.0 (TID 145) in 83 ms on 10.1.2.152 (28/59)
17/01/29 04:53:03,425 INFO TaskSetManager: Starting task 28.0 in stage 3.0 (TID 155, 10.1.2.60, partition 28, PROCESS_LOCAL, 5561 bytes)
17/01/29 04:53:03,425 INFO CoarseGrainedSchedulerBackend$DriverEndpoint: Launching task 155 on executor id: 1 hostname: 10.1.2.60.
17/01/29 04:53:03,425 INFO TaskSetManager: Finished task 21.0 in stage 3.0 (TID 143) in 95 ms on 10.1.2.60 (29/59)
17/01/29 04:53:03,435 INFO TaskSetManager: Starting task 46.0 in stage 3.0 (TID 156, 10.1.2.152, partition 46, PROCESS_LOCAL, 5561 bytes)
17/01/29 04:53:03,435 INFO CoarseGrainedSchedulerBackend$DriverEndpoint: Launching task 156 on executor id: 0 hostname: 10.1.2.152.
17/01/29 04:53:03,435 INFO TaskSetManager: Finished task 38.0 in stage 3.0 (TID 148) in 83 ms on 10.1.2.152 (30/59)
17/01/29 04:53:03,449 INFO TaskSetManager: Starting task 31.0 in stage 3.0 (TID 157, 10.1.2.60, partition 31, PROCESS_LOCAL, 5561 bytes)
17/01/29 04:53:03,450 INFO CoarseGrainedSchedulerBackend$DriverEndpoint: Launching task 157 on executor id: 1 hostname: 10.1.2.60.
17/01/29 04:53:03,450 INFO TaskSetManager: Finished task 25.0 in stage 3.0 (TID 150) in 83 ms on 10.1.2.60 (31/59)
17/01/29 04:53:03,460 INFO TaskSetManager: Starting task 33.0 in stage 3.0 (TID 158, 10.1.2.60, partition 33, PROCESS_LOCAL, 5561 bytes)
17/01/29 04:53:03,460 INFO CoarseGrainedSchedulerBackend$DriverEndpoint: Launching task 158 on executor id: 1 hostname: 10.1.2.60.
17/01/29 04:53:03,460 INFO TaskSetManager: Finished task 23.0 in stage 3.0 (TID 149) in 100 ms on 10.1.2.60 (32/59)
17/01/29 04:53:03,483 INFO TaskSetManager: Starting task 35.0 in stage 3.0 (TID 159, 10.1.2.60, partition 35, PROCESS_LOCAL, 5561 bytes)
17/01/29 04:53:03,483 INFO CoarseGrainedSchedulerBackend$DriverEndpoint: Launching task 159 on executor id: 1 hostname: 10.1.2.60.
17/01/29 04:53:03,483 INFO TaskSetManager: Finished task 26.0 in stage 3.0 (TID 152) in 69 ms on 10.1.2.60 (33/59)
17/01/29 04:53:03,485 INFO TaskSetManager: Starting task 47.0 in stage 3.0 (TID 160, 10.1.2.152, partition 47, PROCESS_LOCAL, 5561 bytes)
17/01/29 04:53:03,486 INFO CoarseGrainedSchedulerBackend$DriverEndpoint: Launching task 160 on executor id: 0 hostname: 10.1.2.152.
17/01/29 04:53:03,486 INFO TaskSetManager: Finished task 43.0 in stage 3.0 (TID 153) in 69 ms on 10.1.2.152 (34/59)
17/01/29 04:53:03,487 INFO TaskSetManager: Starting task 52.0 in stage 3.0 (TID 161, 10.1.2.152, partition 52, PROCESS_LOCAL, 5561 bytes)
17/01/29 04:53:03,487 INFO CoarseGrainedSchedulerBackend$DriverEndpoint: Launching task 161 on executor id: 0 hostname: 10.1.2.152.
17/01/29 04:53:03,487 INFO TaskSetManager: Finished task 39.0 in stage 3.0 (TID 151) in 76 ms on 10.1.2.152 (35/59)
17/01/29 04:53:03,507 INFO TaskSetManager: Starting task 36.0 in stage 3.0 (TID 162, 10.1.2.60, partition 36, PROCESS_LOCAL, 5561 bytes)
17/01/29 04:53:03,508 INFO CoarseGrainedSchedulerBackend$DriverEndpoint: Launching task 162 on executor id: 1 hostname: 10.1.2.60.
17/01/29 04:53:03,508 INFO TaskSetManager: Finished task 28.0 in stage 3.0 (TID 155) in 84 ms on 10.1.2.60 (36/59)
17/01/29 04:53:03,510 INFO TaskSetManager: Starting task 53.0 in stage 3.0 (TID 163, 10.1.2.152, partition 53, PROCESS_LOCAL, 5561 bytes)
17/01/29 04:53:03,511 INFO CoarseGrainedSchedulerBackend$DriverEndpoint: Launching task 163 on executor id: 0 hostname: 10.1.2.152.
17/01/29 04:53:03,511 INFO TaskSetManager: Finished task 44.0 in stage 3.0 (TID 154) in 92 ms on 10.1.2.152 (37/59)
17/01/29 04:53:03,514 INFO TaskSetManager: Starting task 54.0 in stage 3.0 (TID 164, 10.1.2.152, partition 54, PROCESS_LOCAL, 5561 bytes)
17/01/29 04:53:03,514 INFO CoarseGrainedSchedulerBackend$DriverEndpoint: Launching task 164 on executor id: 0 hostname: 10.1.2.152.
17/01/29 04:53:03,515 INFO TaskSetManager: Finished task 46.0 in stage 3.0 (TID 156) in 81 ms on 10.1.2.152 (38/59)
17/01/29 04:53:03,532 INFO TaskSetManager: Starting task 37.0 in stage 3.0 (TID 165, 10.1.2.60, partition 37, PROCESS_LOCAL, 5561 bytes)
17/01/29 04:53:03,532 INFO CoarseGrainedSchedulerBackend$DriverEndpoint: Launching task 165 on executor id: 1 hostname: 10.1.2.60.
17/01/29 04:53:03,533 INFO TaskSetManager: Finished task 31.0 in stage 3.0 (TID 157) in 83 ms on 10.1.2.60 (39/59)
17/01/29 04:53:03,541 INFO TaskSetManager: Starting task 40.0 in stage 3.0 (TID 166, 10.1.2.60, partition 40, PROCESS_LOCAL, 5561 bytes)
17/01/29 04:53:03,541 INFO TaskSetManager: Finished task 33.0 in stage 3.0 (TID 158) in 82 ms on 10.1.2.60 (40/59)
17/01/29 04:53:03,542 INFO CoarseGrainedSchedulerBackend$DriverEndpoint: Launching task 166 on executor id: 1 hostname: 10.1.2.60.
17/01/29 04:53:03,545 INFO TaskSetManager: Starting task 41.0 in stage 3.0 (TID 167, 10.1.2.60, partition 41, PROCESS_LOCAL, 5561 bytes)
17/01/29 04:53:03,546 INFO CoarseGrainedSchedulerBackend$DriverEndpoint: Launching task 167 on executor id: 1 hostname: 10.1.2.60.
17/01/29 04:53:03,546 INFO TaskSetManager: Finished task 35.0 in stage 3.0 (TID 159) in 64 ms on 10.1.2.60 (41/59)
17/01/29 04:53:03,555 INFO TaskSetManager: Starting task 55.0 in stage 3.0 (TID 168, 10.1.2.152, partition 55, PROCESS_LOCAL, 5561 bytes)
17/01/29 04:53:03,555 INFO CoarseGrainedSchedulerBackend$DriverEndpoint: Launching task 168 on executor id: 0 hostname: 10.1.2.152.
17/01/29 04:53:03,555 INFO TaskSetManager: Finished task 47.0 in stage 3.0 (TID 160) in 70 ms on 10.1.2.152 (42/59)
17/01/29 04:53:03,580 INFO TaskSetManager: Starting task 57.0 in stage 3.0 (TID 169, 10.1.2.152, partition 57, PROCESS_LOCAL, 5561 bytes)
17/01/29 04:53:03,581 INFO CoarseGrainedSchedulerBackend$DriverEndpoint: Launching task 169 on executor id: 0 hostname: 10.1.2.152.
17/01/29 04:53:03,582 INFO TaskSetManager: Starting task 58.0 in stage 3.0 (TID 170, 10.1.2.152, partition 58, PROCESS_LOCAL, 5561 bytes)
17/01/29 04:53:03,582 INFO CoarseGrainedSchedulerBackend$DriverEndpoint: Launching task 170 on executor id: 0 hostname: 10.1.2.152.
17/01/29 04:53:03,582 INFO TaskSetManager: Finished task 53.0 in stage 3.0 (TID 163) in 72 ms on 10.1.2.152 (43/59)
17/01/29 04:53:03,583 INFO TaskSetManager: Finished task 52.0 in stage 3.0 (TID 161) in 97 ms on 10.1.2.152 (44/59)
17/01/29 04:53:03,592 INFO TaskSetManager: Starting task 42.0 in stage 3.0 (TID 171, 10.1.2.60, partition 42, PROCESS_LOCAL, 5561 bytes)
17/01/29 04:53:03,592 INFO CoarseGrainedSchedulerBackend$DriverEndpoint: Launching task 171 on executor id: 1 hostname: 10.1.2.60.
17/01/29 04:53:03,592 INFO TaskSetManager: Finished task 36.0 in stage 3.0 (TID 162) in 85 ms on 10.1.2.60 (45/59)
17/01/29 04:53:03,604 INFO TaskSetManager: Starting task 45.0 in stage 3.0 (TID 172, 10.1.2.60, partition 45, PROCESS_LOCAL, 5561 bytes)
17/01/29 04:53:03,604 INFO CoarseGrainedSchedulerBackend$DriverEndpoint: Launching task 172 on executor id: 1 hostname: 10.1.2.60.
17/01/29 04:53:03,605 INFO TaskSetManager: Finished task 40.0 in stage 3.0 (TID 166) in 65 ms on 10.1.2.60 (46/59)
17/01/29 04:53:03,621 INFO TaskSetManager: Starting task 48.0 in stage 3.0 (TID 173, 10.1.2.60, partition 48, PROCESS_LOCAL, 5561 bytes)
17/01/29 04:53:03,621 INFO CoarseGrainedSchedulerBackend$DriverEndpoint: Launching task 173 on executor id: 1 hostname: 10.1.2.60.
17/01/29 04:53:03,622 INFO TaskSetManager: Finished task 41.0 in stage 3.0 (TID 167) in 77 ms on 10.1.2.60 (47/59)
17/01/29 04:53:03,627 INFO TaskSetManager: Starting task 49.0 in stage 3.0 (TID 174, 10.1.2.60, partition 49, PROCESS_LOCAL, 5561 bytes)
17/01/29 04:53:03,627 INFO CoarseGrainedSchedulerBackend$DriverEndpoint: Launching task 174 on executor id: 1 hostname: 10.1.2.60.
17/01/29 04:53:03,627 INFO TaskSetManager: Finished task 37.0 in stage 3.0 (TID 165) in 96 ms on 10.1.2.60 (48/59)
17/01/29 04:53:03,666 INFO TaskSetManager: Finished task 54.0 in stage 3.0 (TID 164) in 152 ms on 10.1.2.152 (49/59)
17/01/29 04:53:03,667 INFO TaskSetManager: Starting task 50.0 in stage 3.0 (TID 175, 10.1.2.60, partition 50, PROCESS_LOCAL, 5561 bytes)
17/01/29 04:53:03,667 INFO CoarseGrainedSchedulerBackend$DriverEndpoint: Launching task 175 on executor id: 1 hostname: 10.1.2.60.
17/01/29 04:53:03,668 INFO TaskSetManager: Finished task 42.0 in stage 3.0 (TID 171) in 76 ms on 10.1.2.60 (50/59)
17/01/29 04:53:03,677 INFO TaskSetManager: Finished task 55.0 in stage 3.0 (TID 168) in 122 ms on 10.1.2.152 (51/59)
17/01/29 04:53:03,678 INFO TaskSetManager: Starting task 51.0 in stage 3.0 (TID 176, 10.1.2.60, partition 51, PROCESS_LOCAL, 5561 bytes)
17/01/29 04:53:03,679 INFO CoarseGrainedSchedulerBackend$DriverEndpoint: Launching task 176 on executor id: 1 hostname: 10.1.2.60.
17/01/29 04:53:03,679 INFO TaskSetManager: Finished task 48.0 in stage 3.0 (TID 173) in 59 ms on 10.1.2.60 (52/59)
17/01/29 04:53:03,684 INFO TaskSetManager: Finished task 45.0 in stage 3.0 (TID 172) in 80 ms on 10.1.2.60 (53/59)
17/01/29 04:53:03,698 INFO TaskSetManager: Finished task 49.0 in stage 3.0 (TID 174) in 72 ms on 10.1.2.60 (54/59)
17/01/29 04:53:03,708 INFO TaskSetManager: Finished task 57.0 in stage 3.0 (TID 169) in 128 ms on 10.1.2.152 (55/59)
17/01/29 04:53:03,718 INFO TaskSetManager: Finished task 58.0 in stage 3.0 (TID 170) in 137 ms on 10.1.2.152 (56/59)
17/01/29 04:53:03,731 INFO TaskSetManager: Finished task 50.0 in stage 3.0 (TID 175) in 64 ms on 10.1.2.60 (57/59)
17/01/29 04:53:03,740 INFO TaskSetManager: Finished task 51.0 in stage 3.0 (TID 176) in 62 ms on 10.1.2.60 (58/59)
17/01/29 04:53:07,632 INFO TaskSetManager: Starting task 56.0 in stage 3.0 (TID 177, 10.1.2.152, partition 56, ANY, 5561 bytes)
17/01/29 04:53:07,632 INFO CoarseGrainedSchedulerBackend$DriverEndpoint: Launching task 177 on executor id: 0 hostname: 10.1.2.152.
17/01/29 04:53:13,236 INFO TaskSetManager: Finished task 56.0 in stage 3.0 (TID 177) in 5605 ms on 10.1.2.152 (59/59)
17/01/29 04:53:13,236 INFO TaskSchedulerImpl: Removed TaskSet 3.0, whose tasks have all completed, from pool 
17/01/29 04:53:13,237 INFO DAGScheduler: ShuffleMapStage 3 (treeAggregate at GradientDescent.scala:239) finished in 10.596 s
17/01/29 04:53:13,238 INFO DAGScheduler: looking for newly runnable stages
17/01/29 04:53:13,239 INFO DAGScheduler: running: Set()
17/01/29 04:53:13,239 INFO DAGScheduler: waiting: Set(ResultStage 4)
17/01/29 04:53:13,240 INFO DAGScheduler: failed: Set()
17/01/29 04:53:13,241 INFO DAGScheduler: Submitting ResultStage 4 (MapPartitionsRDD[13] at treeAggregate at GradientDescent.scala:239), which has no missing parents
17/01/29 04:53:13,247 INFO MemoryStore: Block broadcast_6 stored as values in memory (estimated size 3.1 KB, free 2.1 GB)
17/01/29 04:53:13,250 INFO MemoryStore: Block broadcast_6_piece0 stored as bytes in memory (estimated size 1893.0 B, free 2.1 GB)
17/01/29 04:53:13,250 INFO BlockManagerInfo: Added broadcast_6_piece0 in memory on 10.1.2.31:36764 (size: 1893.0 B, free: 2.1 GB)
17/01/29 04:53:13,252 INFO SparkContext: Created broadcast 6 from broadcast at DAGScheduler.scala:1012
17/01/29 04:53:13,252 INFO DAGScheduler: Submitting 7 missing tasks from ResultStage 4 (MapPartitionsRDD[13] at treeAggregate at GradientDescent.scala:239)
17/01/29 04:53:13,252 INFO TaskSchedulerImpl: Adding task set 4.0 with 7 tasks
17/01/29 04:53:13,256 INFO TaskSetManager: Starting task 1.0 in stage 4.0 (TID 178, 10.1.2.152, partition 1, NODE_LOCAL, 5227 bytes)
17/01/29 04:53:13,257 INFO TaskSetManager: Starting task 0.0 in stage 4.0 (TID 179, 10.1.2.60, partition 0, NODE_LOCAL, 5227 bytes)
17/01/29 04:53:13,257 INFO TaskSetManager: Starting task 2.0 in stage 4.0 (TID 180, 10.1.2.152, partition 2, NODE_LOCAL, 5227 bytes)
17/01/29 04:53:13,258 INFO TaskSetManager: Starting task 3.0 in stage 4.0 (TID 181, 10.1.2.60, partition 3, NODE_LOCAL, 5227 bytes)
17/01/29 04:53:13,258 INFO TaskSetManager: Starting task 4.0 in stage 4.0 (TID 182, 10.1.2.152, partition 4, NODE_LOCAL, 5227 bytes)
17/01/29 04:53:13,259 INFO TaskSetManager: Starting task 5.0 in stage 4.0 (TID 183, 10.1.2.60, partition 5, NODE_LOCAL, 5227 bytes)
17/01/29 04:53:13,259 INFO TaskSetManager: Starting task 6.0 in stage 4.0 (TID 184, 10.1.2.152, partition 6, NODE_LOCAL, 5227 bytes)
17/01/29 04:53:13,259 INFO CoarseGrainedSchedulerBackend$DriverEndpoint: Launching task 178 on executor id: 0 hostname: 10.1.2.152.
17/01/29 04:53:13,259 INFO CoarseGrainedSchedulerBackend$DriverEndpoint: Launching task 180 on executor id: 0 hostname: 10.1.2.152.
17/01/29 04:53:13,260 INFO CoarseGrainedSchedulerBackend$DriverEndpoint: Launching task 182 on executor id: 0 hostname: 10.1.2.152.
17/01/29 04:53:13,260 INFO CoarseGrainedSchedulerBackend$DriverEndpoint: Launching task 184 on executor id: 0 hostname: 10.1.2.152.
17/01/29 04:53:13,260 INFO CoarseGrainedSchedulerBackend$DriverEndpoint: Launching task 179 on executor id: 1 hostname: 10.1.2.60.
17/01/29 04:53:13,260 INFO CoarseGrainedSchedulerBackend$DriverEndpoint: Launching task 181 on executor id: 1 hostname: 10.1.2.60.
17/01/29 04:53:13,261 INFO CoarseGrainedSchedulerBackend$DriverEndpoint: Launching task 183 on executor id: 1 hostname: 10.1.2.60.
17/01/29 04:53:13,277 INFO BlockManagerInfo: Added broadcast_6_piece0 in memory on 10.1.2.152:44417 (size: 1893.0 B, free: 89.4 MB)
17/01/29 04:53:13,278 INFO BlockManagerInfo: Added broadcast_6_piece0 in memory on 10.1.2.60:41797 (size: 1893.0 B, free: 92.7 MB)
17/01/29 04:53:13,295 INFO MapOutputTrackerMasterEndpoint: Asked to send map output locations for shuffle 0 to 10.1.2.152:58900
17/01/29 04:53:13,296 INFO MapOutputTrackerMasterEndpoint: Asked to send map output locations for shuffle 0 to 10.1.2.60:44102
17/01/29 04:53:13,299 INFO MapOutputTrackerMaster: Size of output statuses for shuffle 0 is 268 bytes
17/01/29 04:53:13,367 INFO TaskSetManager: Finished task 1.0 in stage 4.0 (TID 178) in 112 ms on 10.1.2.152 (1/7)
17/01/29 04:53:13,368 INFO TaskSetManager: Finished task 2.0 in stage 4.0 (TID 180) in 111 ms on 10.1.2.152 (2/7)
17/01/29 04:53:13,369 INFO TaskSetManager: Finished task 6.0 in stage 4.0 (TID 184) in 110 ms on 10.1.2.152 (3/7)
17/01/29 04:53:13,370 INFO TaskSetManager: Finished task 4.0 in stage 4.0 (TID 182) in 112 ms on 10.1.2.152 (4/7)
17/01/29 04:53:13,383 INFO TaskSetManager: Finished task 5.0 in stage 4.0 (TID 183) in 125 ms on 10.1.2.60 (5/7)
17/01/29 04:53:13,384 INFO TaskSetManager: Finished task 0.0 in stage 4.0 (TID 179) in 128 ms on 10.1.2.60 (6/7)
17/01/29 04:53:13,385 INFO TaskSetManager: Finished task 3.0 in stage 4.0 (TID 181) in 128 ms on 10.1.2.60 (7/7)
17/01/29 04:53:13,386 INFO TaskSchedulerImpl: Removed TaskSet 4.0, whose tasks have all completed, from pool 
17/01/29 04:53:13,386 INFO DAGScheduler: ResultStage 4 (treeAggregate at GradientDescent.scala:239) finished in 0.131 s
17/01/29 04:53:13,387 INFO DAGScheduler: Job 3 finished: treeAggregate at GradientDescent.scala:239, took 10.788648 s
17/01/29 04:53:13,390 INFO MemoryStore: Block broadcast_7 stored as values in memory (estimated size 280.0 B, free 2.1 GB)
17/01/29 04:53:13,394 INFO MemoryStore: Block broadcast_7_piece0 stored as bytes in memory (estimated size 365.0 B, free 2.1 GB)
17/01/29 04:53:13,395 INFO BlockManagerInfo: Added broadcast_7_piece0 in memory on 10.1.2.31:36764 (size: 365.0 B, free: 2.1 GB)
17/01/29 04:53:13,395 INFO SparkContext: Created broadcast 7 from broadcast at GradientDescent.scala:235
17/01/29 04:53:13,416 INFO SparkContext: Starting job: treeAggregate at GradientDescent.scala:239
17/01/29 04:53:13,417 INFO DAGScheduler: Registering RDD 16 (treeAggregate at GradientDescent.scala:239)
17/01/29 04:53:13,418 INFO DAGScheduler: Got job 4 (treeAggregate at GradientDescent.scala:239) with 7 output partitions
17/01/29 04:53:13,418 INFO DAGScheduler: Final stage: ResultStage 6 (treeAggregate at GradientDescent.scala:239)
17/01/29 04:53:13,418 INFO DAGScheduler: Parents of final stage: List(ShuffleMapStage 5)
17/01/29 04:53:13,418 INFO DAGScheduler: Missing parents: List(ShuffleMapStage 5)
17/01/29 04:53:13,421 INFO DAGScheduler: Submitting ShuffleMapStage 5 (MapPartitionsRDD[16] at treeAggregate at GradientDescent.scala:239), which has no missing parents
17/01/29 04:53:13,430 INFO MemoryStore: Block broadcast_8 stored as values in memory (estimated size 7.2 KB, free 2.1 GB)
17/01/29 04:53:13,434 INFO MemoryStore: Block broadcast_8_piece0 stored as bytes in memory (estimated size 3.7 KB, free 2.1 GB)
17/01/29 04:53:13,435 INFO BlockManagerInfo: Added broadcast_8_piece0 in memory on 10.1.2.31:36764 (size: 3.7 KB, free: 2.1 GB)
17/01/29 04:53:13,435 INFO SparkContext: Created broadcast 8 from broadcast at DAGScheduler.scala:1012
17/01/29 04:53:13,436 INFO DAGScheduler: Submitting 59 missing tasks from ShuffleMapStage 5 (MapPartitionsRDD[16] at treeAggregate at GradientDescent.scala:239)
17/01/29 04:53:13,437 INFO TaskSchedulerImpl: Adding task set 5.0 with 59 tasks
17/01/29 04:53:13,439 INFO TaskSetManager: Starting task 1.0 in stage 5.0 (TID 185, 10.1.2.152, partition 1, PROCESS_LOCAL, 5561 bytes)
17/01/29 04:53:13,440 INFO TaskSetManager: Starting task 0.0 in stage 5.0 (TID 186, 10.1.2.60, partition 0, PROCESS_LOCAL, 5561 bytes)
17/01/29 04:53:13,441 INFO TaskSetManager: Starting task 3.0 in stage 5.0 (TID 187, 10.1.2.152, partition 3, PROCESS_LOCAL, 5561 bytes)
17/01/29 04:53:13,441 INFO TaskSetManager: Starting task 2.0 in stage 5.0 (TID 188, 10.1.2.60, partition 2, PROCESS_LOCAL, 5561 bytes)
17/01/29 04:53:13,442 INFO TaskSetManager: Starting task 5.0 in stage 5.0 (TID 189, 10.1.2.152, partition 5, PROCESS_LOCAL, 5561 bytes)
17/01/29 04:53:13,442 INFO TaskSetManager: Starting task 4.0 in stage 5.0 (TID 190, 10.1.2.60, partition 4, PROCESS_LOCAL, 5561 bytes)
17/01/29 04:53:13,443 INFO TaskSetManager: Starting task 8.0 in stage 5.0 (TID 191, 10.1.2.152, partition 8, PROCESS_LOCAL, 5561 bytes)
