Using properties file: /home/ubuntu/spark-2.0.0/conf/spark-defaults.conf
Adding default property: spark.executor.extraJavaOptions=-XX:+PrintGCDetails -XX:+PrintGCTimeStamps -Xms11500m -Dlog4j.configuration=file:///home/ubuntu/spark-2.0.0/conf/log4j.properties
Adding default property: spark.driver.extraJavaOptions=-XX:+PrintGCDetails -XX:+PrintGCTimeStamps -Xms11500m -Dlog4j.configuration=file:///home/ubuntu/spark-2.0.0/conf/log4j.properties
Parsed arguments:
  master                  spark://euca-10-1-2-152:7077
  deployMode              client
  executorMemory          11500m
  executorCores           null
  totalExecutorCores      null
  propertiesFile          /home/ubuntu/spark-2.0.0/conf/spark-defaults.conf
  driverMemory            11500m
  driverCores             null
  driverExtraClassPath    null
  driverExtraLibraryPath  null
  driverExtraJavaOptions  -XX:+PrintGCDetails -XX:+PrintGCTimeStamps -Xms11500m -Dlog4j.configuration=file:///home/ubuntu/spark-2.0.0/conf/log4j.properties
  supervise               false
  queue                   null
  numExecutors            16
  files                   null
  pyFiles                 null
  archives                null
  mainClass               LogRegExplicitParallelism
  primaryResource         file:///home/ubuntu/jars/log-reg-explicit-parallelism_2.11-1.0.jar
  name                    LogRegExplicitParallelism
  childArgs               [cluster 18 euca-10-1-2-152 9000 susy_0_exp 5 64]
  jars                    null
  packages                null
  packagesExclusions      null
  repositories            null
  verbose                 true

Spark properties used, including those specified through
 --conf and those from the properties file /home/ubuntu/spark-2.0.0/conf/spark-defaults.conf:
  spark.default.parallelism -> 64
  spark.driver.memory -> 11500m
  spark.executor.extraJavaOptions -> -XX:+PrintGCDetails -XX:+PrintGCTimeStamps -Xms11500m -Dlog4j.configuration=file:///home/ubuntu/spark-2.0.0/conf/log4j.properties
  spark.driver.extraJavaOptions -> -XX:+PrintGCDetails -XX:+PrintGCTimeStamps -Xms11500m -Dlog4j.configuration=file:///home/ubuntu/spark-2.0.0/conf/log4j.properties
  spark.shuffle.spill -> false
  spark.driver.maxResultSize -> 5g

    
Main class:
LogRegExplicitParallelism
Arguments:
cluster
18
euca-10-1-2-152
9000
susy_0_exp
5
64
System properties:
spark.default.parallelism -> 64
spark.executor.memory -> 11500m
spark.driver.memory -> 11500m
SPARK_SUBMIT -> true
spark.executor.extraJavaOptions -> -XX:+PrintGCDetails -XX:+PrintGCTimeStamps -Xms11500m -Dlog4j.configuration=file:///home/ubuntu/spark-2.0.0/conf/log4j.properties
spark.app.name -> LogRegExplicitParallelism
spark.shuffle.spill -> false
spark.driver.extraJavaOptions -> -XX:+PrintGCDetails -XX:+PrintGCTimeStamps -Xms11500m -Dlog4j.configuration=file:///home/ubuntu/spark-2.0.0/conf/log4j.properties
spark.jars -> file:///home/ubuntu/jars/log-reg-explicit-parallelism_2.11-1.0.jar
spark.submit.deployMode -> client
spark.driver.maxResultSize -> 5g
spark.master -> spark://euca-10-1-2-152:7077
Classpath elements:
file:///home/ubuntu/jars/log-reg-explicit-parallelism_2.11-1.0.jar


17/02/07 13:20:00,040 INFO SparkContext: Running Spark version 2.0.0
17/02/07 13:20:00,394 WARN NativeCodeLoader: Unable to load native-hadoop library for your platform... using builtin-java classes where applicable
17/02/07 13:20:00,557 INFO SecurityManager: Changing view acls to: ubuntu
17/02/07 13:20:00,558 INFO SecurityManager: Changing modify acls to: ubuntu
17/02/07 13:20:00,558 INFO SecurityManager: Changing view acls groups to: 
17/02/07 13:20:00,559 INFO SecurityManager: Changing modify acls groups to: 
17/02/07 13:20:00,560 INFO SecurityManager: SecurityManager: authentication disabled; ui acls disabled; users  with view permissions: Set(ubuntu); groups with view permissions: Set(); users  with modify permissions: Set(ubuntu); groups with modify permissions: Set()
17/02/07 13:20:00,870 INFO Utils: Successfully started service 'sparkDriver' on port 42032.
17/02/07 13:20:00,894 INFO SparkEnv: Registering MapOutputTracker
17/02/07 13:20:00,901 WARN SortShuffleManager: spark.shuffle.spill was set to false, but this configuration is ignored as of Spark 1.6+. Shuffle will continue to spill to disk when necessary.
17/02/07 13:20:00,914 INFO SparkEnv: Registering BlockManagerMaster
17/02/07 13:20:00,930 INFO DiskBlockManager: Created local directory at /tmp/blockmgr-a7760db5-bb80-45f8-877c-ea9f7c7a707a
17/02/07 13:20:00,951 INFO MemoryStore: MemoryStore started with capacity 6.3 GB
17/02/07 13:20:01,011 INFO SparkEnv: Registering OutputCommitCoordinator
17/02/07 13:20:01,235 INFO Utils: Successfully started service 'SparkUI' on port 4040.
17/02/07 13:20:01,237 INFO SparkUI: Bound SparkUI to 10.1.2.152, and started at http://10.1.2.152:4040
17/02/07 13:20:01,266 INFO SparkContext: Added JAR file:///home/ubuntu/jars/log-reg-explicit-parallelism_2.11-1.0.jar at spark://10.1.2.152:42032/jars/log-reg-explicit-parallelism_2.11-1.0.jar with timestamp 1486473601266
17/02/07 13:20:01,359 INFO StandaloneAppClient$ClientEndpoint: Connecting to master spark://euca-10-1-2-152:7077...
17/02/07 13:20:01,420 INFO TransportClientFactory: Successfully created connection to euca-10-1-2-152/10.1.2.152:7077 after 26 ms (0 ms spent in bootstraps)
17/02/07 13:20:01,523 INFO StandaloneSchedulerBackend: Connected to Spark cluster with app ID app-20170207132001-0000
17/02/07 13:20:01,529 INFO Utils: Successfully started service 'org.apache.spark.network.netty.NettyBlockTransferService' on port 32967.
17/02/07 13:20:01,530 INFO NettyBlockTransferService: Server created on 10.1.2.152:32967
17/02/07 13:20:01,532 INFO BlockManagerMaster: Registering BlockManager BlockManagerId(driver, 10.1.2.152, 32967)
17/02/07 13:20:01,535 INFO BlockManagerMasterEndpoint: Registering block manager 10.1.2.152:32967 with 6.3 GB RAM, BlockManagerId(driver, 10.1.2.152, 32967)
17/02/07 13:20:01,541 INFO BlockManagerMaster: Registered BlockManager BlockManagerId(driver, 10.1.2.152, 32967)
17/02/07 13:20:01,550 INFO StandaloneAppClient$ClientEndpoint: Executor added: app-20170207132001-0000/0 on worker-20170207131918-10.1.2.29-36875 (10.1.2.29:36875) with 4 cores
17/02/07 13:20:01,552 INFO StandaloneSchedulerBackend: Granted executor ID app-20170207132001-0000/0 on hostPort 10.1.2.29:36875 with 4 cores, 11.2 GB RAM
17/02/07 13:20:01,565 INFO StandaloneAppClient$ClientEndpoint: Executor added: app-20170207132001-0000/1 on worker-20170207131918-10.1.2.243-35716 (10.1.2.243:35716) with 4 cores
17/02/07 13:20:01,566 INFO StandaloneSchedulerBackend: Granted executor ID app-20170207132001-0000/1 on hostPort 10.1.2.243:35716 with 4 cores, 11.2 GB RAM
17/02/07 13:20:01,567 INFO StandaloneAppClient$ClientEndpoint: Executor added: app-20170207132001-0000/2 on worker-20170207131918-10.1.2.165-38596 (10.1.2.165:38596) with 4 cores
17/02/07 13:20:01,568 INFO StandaloneSchedulerBackend: Granted executor ID app-20170207132001-0000/2 on hostPort 10.1.2.165:38596 with 4 cores, 11.2 GB RAM
17/02/07 13:20:01,570 INFO StandaloneAppClient$ClientEndpoint: Executor added: app-20170207132001-0000/3 on worker-20170207131918-10.1.2.215-45775 (10.1.2.215:45775) with 4 cores
17/02/07 13:20:01,570 INFO StandaloneSchedulerBackend: Granted executor ID app-20170207132001-0000/3 on hostPort 10.1.2.215:45775 with 4 cores, 11.2 GB RAM
17/02/07 13:20:01,572 INFO StandaloneAppClient$ClientEndpoint: Executor added: app-20170207132001-0000/4 on worker-20170207131918-10.1.2.83-33825 (10.1.2.83:33825) with 4 cores
17/02/07 13:20:01,572 INFO StandaloneSchedulerBackend: Granted executor ID app-20170207132001-0000/4 on hostPort 10.1.2.83:33825 with 4 cores, 11.2 GB RAM
17/02/07 13:20:01,574 INFO StandaloneAppClient$ClientEndpoint: Executor added: app-20170207132001-0000/5 on worker-20170207131918-10.1.2.172-34817 (10.1.2.172:34817) with 4 cores
17/02/07 13:20:01,574 INFO StandaloneSchedulerBackend: Granted executor ID app-20170207132001-0000/5 on hostPort 10.1.2.172:34817 with 4 cores, 11.2 GB RAM
17/02/07 13:20:01,576 INFO StandaloneAppClient$ClientEndpoint: Executor added: app-20170207132001-0000/6 on worker-20170207131918-10.1.2.41-44723 (10.1.2.41:44723) with 4 cores
17/02/07 13:20:01,576 INFO StandaloneSchedulerBackend: Granted executor ID app-20170207132001-0000/6 on hostPort 10.1.2.41:44723 with 4 cores, 11.2 GB RAM
17/02/07 13:20:01,578 INFO StandaloneAppClient$ClientEndpoint: Executor added: app-20170207132001-0000/7 on worker-20170207131920-10.1.2.133-34935 (10.1.2.133:34935) with 4 cores
17/02/07 13:20:01,578 INFO StandaloneSchedulerBackend: Granted executor ID app-20170207132001-0000/7 on hostPort 10.1.2.133:34935 with 4 cores, 11.2 GB RAM
17/02/07 13:20:01,580 INFO StandaloneAppClient$ClientEndpoint: Executor added: app-20170207132001-0000/8 on worker-20170207131918-10.1.2.214-33490 (10.1.2.214:33490) with 4 cores
17/02/07 13:20:01,580 INFO StandaloneSchedulerBackend: Granted executor ID app-20170207132001-0000/8 on hostPort 10.1.2.214:33490 with 4 cores, 11.2 GB RAM
17/02/07 13:20:01,582 INFO StandaloneAppClient$ClientEndpoint: Executor added: app-20170207132001-0000/9 on worker-20170207131918-10.1.2.130-42630 (10.1.2.130:42630) with 4 cores
17/02/07 13:20:01,583 INFO StandaloneSchedulerBackend: Granted executor ID app-20170207132001-0000/9 on hostPort 10.1.2.130:42630 with 4 cores, 11.2 GB RAM
17/02/07 13:20:01,584 INFO StandaloneAppClient$ClientEndpoint: Executor added: app-20170207132001-0000/10 on worker-20170207131918-10.1.2.245-44052 (10.1.2.245:44052) with 4 cores
17/02/07 13:20:01,585 INFO StandaloneSchedulerBackend: Granted executor ID app-20170207132001-0000/10 on hostPort 10.1.2.245:44052 with 4 cores, 11.2 GB RAM
17/02/07 13:20:01,586 INFO StandaloneAppClient$ClientEndpoint: Executor added: app-20170207132001-0000/11 on worker-20170207131918-10.1.2.224-46829 (10.1.2.224:46829) with 4 cores
17/02/07 13:20:01,587 INFO StandaloneSchedulerBackend: Granted executor ID app-20170207132001-0000/11 on hostPort 10.1.2.224:46829 with 4 cores, 11.2 GB RAM
17/02/07 13:20:01,588 INFO StandaloneAppClient$ClientEndpoint: Executor added: app-20170207132001-0000/12 on worker-20170207131918-10.1.2.148-37669 (10.1.2.148:37669) with 4 cores
17/02/07 13:20:01,588 INFO StandaloneSchedulerBackend: Granted executor ID app-20170207132001-0000/12 on hostPort 10.1.2.148:37669 with 4 cores, 11.2 GB RAM
17/02/07 13:20:01,590 INFO StandaloneAppClient$ClientEndpoint: Executor added: app-20170207132001-0000/13 on worker-20170207131918-10.1.2.47-42437 (10.1.2.47:42437) with 4 cores
17/02/07 13:20:01,591 INFO StandaloneSchedulerBackend: Granted executor ID app-20170207132001-0000/13 on hostPort 10.1.2.47:42437 with 4 cores, 11.2 GB RAM
17/02/07 13:20:01,592 INFO StandaloneAppClient$ClientEndpoint: Executor added: app-20170207132001-0000/14 on worker-20170207131919-10.1.2.211-36487 (10.1.2.211:36487) with 4 cores
17/02/07 13:20:01,593 INFO StandaloneSchedulerBackend: Granted executor ID app-20170207132001-0000/14 on hostPort 10.1.2.211:36487 with 4 cores, 11.2 GB RAM
17/02/07 13:20:01,594 INFO StandaloneAppClient$ClientEndpoint: Executor added: app-20170207132001-0000/15 on worker-20170207131918-10.1.2.106-39996 (10.1.2.106:39996) with 4 cores
17/02/07 13:20:01,595 INFO StandaloneSchedulerBackend: Granted executor ID app-20170207132001-0000/15 on hostPort 10.1.2.106:39996 with 4 cores, 11.2 GB RAM
17/02/07 13:20:01,622 INFO StandaloneAppClient$ClientEndpoint: Executor updated: app-20170207132001-0000/2 is now RUNNING
17/02/07 13:20:01,636 INFO StandaloneAppClient$ClientEndpoint: Executor updated: app-20170207132001-0000/10 is now RUNNING
17/02/07 13:20:01,638 INFO StandaloneAppClient$ClientEndpoint: Executor updated: app-20170207132001-0000/6 is now RUNNING
17/02/07 13:20:01,641 INFO StandaloneAppClient$ClientEndpoint: Executor updated: app-20170207132001-0000/9 is now RUNNING
17/02/07 13:20:01,645 INFO StandaloneAppClient$ClientEndpoint: Executor updated: app-20170207132001-0000/7 is now RUNNING
17/02/07 13:20:01,648 INFO StandaloneAppClient$ClientEndpoint: Executor updated: app-20170207132001-0000/11 is now RUNNING
17/02/07 13:20:01,650 INFO StandaloneAppClient$ClientEndpoint: Executor updated: app-20170207132001-0000/3 is now RUNNING
17/02/07 13:20:01,653 INFO StandaloneAppClient$ClientEndpoint: Executor updated: app-20170207132001-0000/14 is now RUNNING
17/02/07 13:20:01,656 INFO StandaloneAppClient$ClientEndpoint: Executor updated: app-20170207132001-0000/0 is now RUNNING
17/02/07 13:20:01,659 INFO StandaloneAppClient$ClientEndpoint: Executor updated: app-20170207132001-0000/1 is now RUNNING
17/02/07 13:20:01,661 INFO StandaloneAppClient$ClientEndpoint: Executor updated: app-20170207132001-0000/5 is now RUNNING
17/02/07 13:20:01,664 INFO StandaloneAppClient$ClientEndpoint: Executor updated: app-20170207132001-0000/15 is now RUNNING
17/02/07 13:20:01,667 INFO StandaloneAppClient$ClientEndpoint: Executor updated: app-20170207132001-0000/4 is now RUNNING
17/02/07 13:20:01,669 INFO StandaloneAppClient$ClientEndpoint: Executor updated: app-20170207132001-0000/12 is now RUNNING
17/02/07 13:20:01,671 INFO StandaloneAppClient$ClientEndpoint: Executor updated: app-20170207132001-0000/13 is now RUNNING
17/02/07 13:20:01,674 INFO StandaloneAppClient$ClientEndpoint: Executor updated: app-20170207132001-0000/8 is now RUNNING
17/02/07 13:20:01,760 INFO StandaloneSchedulerBackend: SchedulerBackend is ready for scheduling beginning after reached minRegisteredResourcesRatio: 0.0
17/02/07 13:20:02,215 INFO MemoryStore: Block broadcast_0 stored as values in memory (estimated size 130.8 KB, free 6.3 GB)
17/02/07 13:20:02,284 INFO MemoryStore: Block broadcast_0_piece0 stored as bytes in memory (estimated size 16.5 KB, free 6.3 GB)
17/02/07 13:20:02,286 INFO BlockManagerInfo: Added broadcast_0_piece0 in memory on 10.1.2.152:32967 (size: 16.5 KB, free: 6.3 GB)
17/02/07 13:20:02,295 INFO SparkContext: Created broadcast 0 from textFile at MLUtils.scala:99
17/02/07 13:20:03,050 INFO FileInputFormat: Total input paths to process : 1
17/02/07 13:20:03,108 INFO NetworkTopology: Adding a new node: /default-rack/10.1.2.215:50010
17/02/07 13:20:03,109 INFO NetworkTopology: Adding a new node: /default-rack/10.1.2.165:50010
17/02/07 13:20:03,109 INFO NetworkTopology: Adding a new node: /default-rack/10.1.2.245:50010
17/02/07 13:20:03,109 INFO NetworkTopology: Adding a new node: /default-rack/10.1.2.211:50010
17/02/07 13:20:03,109 INFO NetworkTopology: Adding a new node: /default-rack/10.1.2.214:50010
17/02/07 13:20:03,109 INFO NetworkTopology: Adding a new node: /default-rack/10.1.2.47:50010
17/02/07 13:20:03,110 INFO NetworkTopology: Adding a new node: /default-rack/10.1.2.172:50010
17/02/07 13:20:03,110 INFO NetworkTopology: Adding a new node: /default-rack/10.1.2.29:50010
17/02/07 13:20:03,111 INFO NetworkTopology: Adding a new node: /default-rack/10.1.2.133:50010
17/02/07 13:20:03,111 INFO NetworkTopology: Adding a new node: /default-rack/10.1.2.224:50010
17/02/07 13:20:03,111 INFO NetworkTopology: Adding a new node: /default-rack/10.1.2.41:50010
17/02/07 13:20:03,111 INFO NetworkTopology: Adding a new node: /default-rack/10.1.2.243:50010
17/02/07 13:20:03,112 INFO NetworkTopology: Adding a new node: /default-rack/10.1.2.130:50010
17/02/07 13:20:03,112 INFO NetworkTopology: Adding a new node: /default-rack/10.1.2.148:50010
17/02/07 13:20:03,112 INFO NetworkTopology: Adding a new node: /default-rack/10.1.2.83:50010
17/02/07 13:20:03,112 INFO NetworkTopology: Adding a new node: /default-rack/10.1.2.106:50010
17/02/07 13:20:03,161 INFO SparkContext: Starting job: first at GeneralizedLinearAlgorithm.scala:246
17/02/07 13:20:03,175 INFO DAGScheduler: Got job 0 (first at GeneralizedLinearAlgorithm.scala:246) with 1 output partitions
17/02/07 13:20:03,175 INFO DAGScheduler: Final stage: ResultStage 0 (first at GeneralizedLinearAlgorithm.scala:246)
17/02/07 13:20:03,176 INFO DAGScheduler: Parents of final stage: List()
17/02/07 13:20:03,182 INFO DAGScheduler: Missing parents: List()
17/02/07 13:20:03,191 INFO DAGScheduler: Submitting ResultStage 0 (MapPartitionsRDD[6] at map at GeneralizedLinearAlgorithm.scala:246), which has no missing parents
17/02/07 13:20:03,225 INFO MemoryStore: Block broadcast_1 stored as values in memory (estimated size 4.2 KB, free 6.3 GB)
17/02/07 13:20:03,228 INFO MemoryStore: Block broadcast_1_piece0 stored as bytes in memory (estimated size 2.4 KB, free 6.3 GB)
17/02/07 13:20:03,229 INFO BlockManagerInfo: Added broadcast_1_piece0 in memory on 10.1.2.152:32967 (size: 2.4 KB, free: 6.3 GB)
17/02/07 13:20:03,230 INFO SparkContext: Created broadcast 1 from broadcast at DAGScheduler.scala:1012
17/02/07 13:20:03,240 INFO DAGScheduler: Submitting 1 missing tasks from ResultStage 0 (MapPartitionsRDD[6] at map at GeneralizedLinearAlgorithm.scala:246)
17/02/07 13:20:03,241 INFO TaskSchedulerImpl: Adding task set 0.0 with 1 tasks
17/02/07 13:20:03,546 INFO CoarseGrainedSchedulerBackend$DriverEndpoint: Registered executor NettyRpcEndpointRef(null) (10.1.2.47:36632) with ID 13
17/02/07 13:20:03,580 INFO TaskSetManager: Starting task 0.0 in stage 0.0 (TID 0, 10.1.2.47, partition 0, ANY, 5455 bytes)
17/02/07 13:20:03,589 INFO CoarseGrainedSchedulerBackend$DriverEndpoint: Launching task 0 on executor id: 13 hostname: 10.1.2.47.
17/02/07 13:20:03,608 INFO BlockManagerMasterEndpoint: Registering block manager 10.1.2.47:40115 with 6.3 GB RAM, BlockManagerId(13, 10.1.2.47, 40115)
17/02/07 13:20:03,616 INFO CoarseGrainedSchedulerBackend$DriverEndpoint: Registered executor NettyRpcEndpointRef(null) (10.1.2.106:45554) with ID 15
17/02/07 13:20:03,669 INFO CoarseGrainedSchedulerBackend$DriverEndpoint: Registered executor NettyRpcEndpointRef(null) (10.1.2.133:50434) with ID 7
17/02/07 13:20:03,671 INFO CoarseGrainedSchedulerBackend$DriverEndpoint: Registered executor NettyRpcEndpointRef(null) (10.1.2.130:52168) with ID 9
17/02/07 13:20:03,674 INFO BlockManagerMasterEndpoint: Registering block manager 10.1.2.106:38042 with 6.3 GB RAM, BlockManagerId(15, 10.1.2.106, 38042)
17/02/07 13:20:03,696 INFO CoarseGrainedSchedulerBackend$DriverEndpoint: Registered executor NettyRpcEndpointRef(null) (10.1.2.83:38414) with ID 4
17/02/07 13:20:03,699 INFO CoarseGrainedSchedulerBackend$DriverEndpoint: Registered executor NettyRpcEndpointRef(null) (10.1.2.243:48746) with ID 1
17/02/07 13:20:03,721 INFO CoarseGrainedSchedulerBackend$DriverEndpoint: Registered executor NettyRpcEndpointRef(null) (10.1.2.211:47626) with ID 14
17/02/07 13:20:03,725 INFO BlockManagerMasterEndpoint: Registering block manager 10.1.2.130:36104 with 6.3 GB RAM, BlockManagerId(9, 10.1.2.130, 36104)
17/02/07 13:20:03,729 INFO BlockManagerMasterEndpoint: Registering block manager 10.1.2.133:45449 with 6.3 GB RAM, BlockManagerId(7, 10.1.2.133, 45449)
17/02/07 13:20:03,739 INFO CoarseGrainedSchedulerBackend$DriverEndpoint: Registered executor NettyRpcEndpointRef(null) (10.1.2.41:54070) with ID 6
17/02/07 13:20:03,750 INFO CoarseGrainedSchedulerBackend$DriverEndpoint: Registered executor NettyRpcEndpointRef(null) (10.1.2.165:38006) with ID 2
17/02/07 13:20:03,751 INFO BlockManagerMasterEndpoint: Registering block manager 10.1.2.243:33377 with 6.3 GB RAM, BlockManagerId(1, 10.1.2.243, 33377)
17/02/07 13:20:03,757 INFO CoarseGrainedSchedulerBackend$DriverEndpoint: Registered executor NettyRpcEndpointRef(null) (10.1.2.215:51882) with ID 3
17/02/07 13:20:03,761 INFO BlockManagerMasterEndpoint: Registering block manager 10.1.2.83:39232 with 6.3 GB RAM, BlockManagerId(4, 10.1.2.83, 39232)
17/02/07 13:20:03,772 INFO CoarseGrainedSchedulerBackend$DriverEndpoint: Registered executor NettyRpcEndpointRef(null) (10.1.2.172:36488) with ID 5
17/02/07 13:20:03,781 INFO BlockManagerMasterEndpoint: Registering block manager 10.1.2.211:35284 with 6.3 GB RAM, BlockManagerId(14, 10.1.2.211, 35284)
17/02/07 13:20:03,783 INFO CoarseGrainedSchedulerBackend$DriverEndpoint: Registered executor NettyRpcEndpointRef(null) (10.1.2.29:47758) with ID 0
17/02/07 13:20:03,793 INFO BlockManagerMasterEndpoint: Registering block manager 10.1.2.41:46050 with 6.3 GB RAM, BlockManagerId(6, 10.1.2.41, 46050)
17/02/07 13:20:03,807 INFO CoarseGrainedSchedulerBackend$DriverEndpoint: Registered executor NettyRpcEndpointRef(null) (10.1.2.214:50568) with ID 8
17/02/07 13:20:03,815 INFO BlockManagerMasterEndpoint: Registering block manager 10.1.2.165:41549 with 6.3 GB RAM, BlockManagerId(2, 10.1.2.165, 41549)
17/02/07 13:20:03,819 INFO BlockManagerMasterEndpoint: Registering block manager 10.1.2.215:41257 with 6.3 GB RAM, BlockManagerId(3, 10.1.2.215, 41257)
17/02/07 13:20:03,830 INFO BlockManagerMasterEndpoint: Registering block manager 10.1.2.172:37669 with 6.3 GB RAM, BlockManagerId(5, 10.1.2.172, 37669)
17/02/07 13:20:03,834 INFO CoarseGrainedSchedulerBackend$DriverEndpoint: Registered executor NettyRpcEndpointRef(null) (10.1.2.245:54246) with ID 10
17/02/07 13:20:03,853 INFO BlockManagerMasterEndpoint: Registering block manager 10.1.2.29:45224 with 6.3 GB RAM, BlockManagerId(0, 10.1.2.29, 45224)
17/02/07 13:20:03,859 INFO BlockManagerMasterEndpoint: Registering block manager 10.1.2.214:44655 with 6.3 GB RAM, BlockManagerId(8, 10.1.2.214, 44655)
17/02/07 13:20:03,892 INFO BlockManagerMasterEndpoint: Registering block manager 10.1.2.245:36419 with 6.3 GB RAM, BlockManagerId(10, 10.1.2.245, 36419)
17/02/07 13:20:03,929 INFO BlockManagerInfo: Added broadcast_1_piece0 in memory on 10.1.2.47:40115 (size: 2.4 KB, free: 6.3 GB)
17/02/07 13:20:04,099 INFO BlockManagerInfo: Added broadcast_0_piece0 in memory on 10.1.2.47:40115 (size: 16.5 KB, free: 6.3 GB)
17/02/07 13:20:06,593 INFO CoarseGrainedSchedulerBackend$DriverEndpoint: Registered executor NettyRpcEndpointRef(null) (10.1.2.224:55274) with ID 11
17/02/07 13:20:06,654 INFO BlockManagerMasterEndpoint: Registering block manager 10.1.2.224:44733 with 6.3 GB RAM, BlockManagerId(11, 10.1.2.224, 44733)
17/02/07 13:20:06,716 INFO CoarseGrainedSchedulerBackend$DriverEndpoint: Registered executor NettyRpcEndpointRef(null) (10.1.2.148:53268) with ID 12
17/02/07 13:20:06,776 INFO BlockManagerMasterEndpoint: Registering block manager 10.1.2.148:41000 with 6.3 GB RAM, BlockManagerId(12, 10.1.2.148, 41000)
17/02/07 13:20:07,666 INFO BlockManagerInfo: Added rdd_5_0 in memory on 10.1.2.47:40115 (size: 22.2 MB, free: 6.3 GB)
17/02/07 13:20:07,719 INFO TaskSetManager: Finished task 0.0 in stage 0.0 (TID 0) in 4165 ms on 10.1.2.47 (1/1)
17/02/07 13:20:07,720 INFO TaskSchedulerImpl: Removed TaskSet 0.0, whose tasks have all completed, from pool 
17/02/07 13:20:07,723 INFO DAGScheduler: ResultStage 0 (first at GeneralizedLinearAlgorithm.scala:246) finished in 4.465 s
17/02/07 13:20:07,727 INFO DAGScheduler: Job 0 finished: first at GeneralizedLinearAlgorithm.scala:246, took 4.566416 s
17/02/07 13:20:07,740 INFO SparkContext: Starting job: count at DataValidators.scala:40
17/02/07 13:20:07,741 INFO DAGScheduler: Got job 1 (count at DataValidators.scala:40) with 64 output partitions
17/02/07 13:20:07,742 INFO DAGScheduler: Final stage: ResultStage 1 (count at DataValidators.scala:40)
17/02/07 13:20:07,742 INFO DAGScheduler: Parents of final stage: List()
17/02/07 13:20:07,744 INFO DAGScheduler: Missing parents: List()
17/02/07 13:20:07,745 INFO DAGScheduler: Submitting ResultStage 1 (MapPartitionsRDD[7] at filter at DataValidators.scala:40), which has no missing parents
17/02/07 13:20:07,769 INFO MemoryStore: Block broadcast_2 stored as values in memory (estimated size 3.9 KB, free 6.3 GB)
17/02/07 13:20:07,772 INFO MemoryStore: Block broadcast_2_piece0 stored as bytes in memory (estimated size 2.2 KB, free 6.3 GB)
17/02/07 13:20:07,773 INFO BlockManagerInfo: Added broadcast_2_piece0 in memory on 10.1.2.152:32967 (size: 2.2 KB, free: 6.3 GB)
17/02/07 13:20:07,774 INFO SparkContext: Created broadcast 2 from broadcast at DAGScheduler.scala:1012
17/02/07 13:20:07,776 INFO DAGScheduler: Submitting 64 missing tasks from ResultStage 1 (MapPartitionsRDD[7] at filter at DataValidators.scala:40)
17/02/07 13:20:07,776 INFO TaskSchedulerImpl: Adding task set 1.0 with 64 tasks
17/02/07 13:20:07,783 INFO TaskSetManager: Starting task 0.0 in stage 1.0 (TID 1, 10.1.2.47, partition 0, PROCESS_LOCAL, 5373 bytes)
17/02/07 13:20:07,786 INFO TaskSetManager: Starting task 17.0 in stage 1.0 (TID 2, 10.1.2.130, partition 17, NODE_LOCAL, 5373 bytes)
17/02/07 13:20:07,788 INFO TaskSetManager: Starting task 24.0 in stage 1.0 (TID 3, 10.1.2.243, partition 24, NODE_LOCAL, 5373 bytes)
17/02/07 13:20:07,790 INFO TaskSetManager: Starting task 3.0 in stage 1.0 (TID 4, 10.1.2.214, partition 3, NODE_LOCAL, 5373 bytes)
17/02/07 13:20:07,792 INFO TaskSetManager: Starting task 27.0 in stage 1.0 (TID 5, 10.1.2.106, partition 27, NODE_LOCAL, 5373 bytes)
17/02/07 13:20:07,794 INFO TaskSetManager: Starting task 38.0 in stage 1.0 (TID 6, 10.1.2.148, partition 38, NODE_LOCAL, 5373 bytes)
17/02/07 13:20:07,795 INFO TaskSetManager: Starting task 41.0 in stage 1.0 (TID 7, 10.1.2.215, partition 41, NODE_LOCAL, 5373 bytes)
17/02/07 13:20:07,797 INFO TaskSetManager: Starting task 6.0 in stage 1.0 (TID 8, 10.1.2.211, partition 6, NODE_LOCAL, 5373 bytes)
17/02/07 13:20:07,799 INFO TaskSetManager: Starting task 10.0 in stage 1.0 (TID 9, 10.1.2.41, partition 10, NODE_LOCAL, 5373 bytes)
17/02/07 13:20:07,801 INFO TaskSetManager: Starting task 13.0 in stage 1.0 (TID 10, 10.1.2.224, partition 13, NODE_LOCAL, 5373 bytes)
17/02/07 13:20:07,803 INFO TaskSetManager: Starting task 20.0 in stage 1.0 (TID 11, 10.1.2.133, partition 20, NODE_LOCAL, 5373 bytes)
17/02/07 13:20:07,805 INFO TaskSetManager: Starting task 59.0 in stage 1.0 (TID 12, 10.1.2.245, partition 59, NODE_LOCAL, 5373 bytes)
17/02/07 13:20:07,807 INFO TaskSetManager: Starting task 52.0 in stage 1.0 (TID 13, 10.1.2.29, partition 52, NODE_LOCAL, 5373 bytes)
17/02/07 13:20:07,809 INFO TaskSetManager: Starting task 55.0 in stage 1.0 (TID 14, 10.1.2.130, partition 55, NODE_LOCAL, 5373 bytes)
17/02/07 13:20:07,811 INFO TaskSetManager: Starting task 31.0 in stage 1.0 (TID 15, 10.1.2.243, partition 31, NODE_LOCAL, 5373 bytes)
17/02/07 13:20:07,812 INFO TaskSetManager: Starting task 45.0 in stage 1.0 (TID 16, 10.1.2.214, partition 45, NODE_LOCAL, 5373 bytes)
17/02/07 13:20:07,814 INFO TaskSetManager: Starting task 34.0 in stage 1.0 (TID 17, 10.1.2.106, partition 34, NODE_LOCAL, 5373 bytes)
17/02/07 13:20:07,816 INFO TaskSetManager: Starting task 48.0 in stage 1.0 (TID 18, 10.1.2.41, partition 48, NODE_LOCAL, 5373 bytes)
17/02/07 13:20:07,818 INFO TaskSetManager: Starting task 62.0 in stage 1.0 (TID 19, 10.1.2.133, partition 62, NODE_LOCAL, 5373 bytes)
17/02/07 13:20:07,820 INFO CoarseGrainedSchedulerBackend$DriverEndpoint: Launching task 2 on executor id: 9 hostname: 10.1.2.130.
17/02/07 13:20:07,821 INFO CoarseGrainedSchedulerBackend$DriverEndpoint: Launching task 14 on executor id: 9 hostname: 10.1.2.130.
17/02/07 13:20:07,822 INFO CoarseGrainedSchedulerBackend$DriverEndpoint: Launching task 3 on executor id: 1 hostname: 10.1.2.243.
17/02/07 13:20:07,823 INFO CoarseGrainedSchedulerBackend$DriverEndpoint: Launching task 15 on executor id: 1 hostname: 10.1.2.243.
17/02/07 13:20:07,823 INFO CoarseGrainedSchedulerBackend$DriverEndpoint: Launching task 4 on executor id: 8 hostname: 10.1.2.214.
17/02/07 13:20:07,824 INFO CoarseGrainedSchedulerBackend$DriverEndpoint: Launching task 16 on executor id: 8 hostname: 10.1.2.214.
17/02/07 13:20:07,825 INFO CoarseGrainedSchedulerBackend$DriverEndpoint: Launching task 5 on executor id: 15 hostname: 10.1.2.106.
17/02/07 13:20:07,826 INFO CoarseGrainedSchedulerBackend$DriverEndpoint: Launching task 17 on executor id: 15 hostname: 10.1.2.106.
17/02/07 13:20:07,826 INFO CoarseGrainedSchedulerBackend$DriverEndpoint: Launching task 6 on executor id: 12 hostname: 10.1.2.148.
17/02/07 13:20:07,827 INFO CoarseGrainedSchedulerBackend$DriverEndpoint: Launching task 7 on executor id: 3 hostname: 10.1.2.215.
17/02/07 13:20:07,828 INFO CoarseGrainedSchedulerBackend$DriverEndpoint: Launching task 8 on executor id: 14 hostname: 10.1.2.211.
17/02/07 13:20:07,829 INFO CoarseGrainedSchedulerBackend$DriverEndpoint: Launching task 1 on executor id: 13 hostname: 10.1.2.47.
17/02/07 13:20:07,830 INFO CoarseGrainedSchedulerBackend$DriverEndpoint: Launching task 9 on executor id: 6 hostname: 10.1.2.41.
17/02/07 13:20:07,830 INFO CoarseGrainedSchedulerBackend$DriverEndpoint: Launching task 18 on executor id: 6 hostname: 10.1.2.41.
17/02/07 13:20:07,831 INFO CoarseGrainedSchedulerBackend$DriverEndpoint: Launching task 10 on executor id: 11 hostname: 10.1.2.224.
17/02/07 13:20:07,832 INFO CoarseGrainedSchedulerBackend$DriverEndpoint: Launching task 11 on executor id: 7 hostname: 10.1.2.133.
17/02/07 13:20:07,832 INFO CoarseGrainedSchedulerBackend$DriverEndpoint: Launching task 19 on executor id: 7 hostname: 10.1.2.133.
17/02/07 13:20:07,835 INFO CoarseGrainedSchedulerBackend$DriverEndpoint: Launching task 12 on executor id: 10 hostname: 10.1.2.245.
17/02/07 13:20:07,836 INFO CoarseGrainedSchedulerBackend$DriverEndpoint: Launching task 13 on executor id: 0 hostname: 10.1.2.29.
17/02/07 13:20:07,850 INFO BlockManagerInfo: Added broadcast_2_piece0 in memory on 10.1.2.47:40115 (size: 2.2 KB, free: 6.3 GB)
17/02/07 13:20:07,896 INFO TaskSetManager: Finished task 0.0 in stage 1.0 (TID 1) in 114 ms on 10.1.2.47 (1/64)
17/02/07 13:20:08,179 INFO BlockManagerInfo: Added broadcast_2_piece0 in memory on 10.1.2.215:41257 (size: 2.2 KB, free: 6.3 GB)
17/02/07 13:20:08,180 INFO BlockManagerInfo: Added broadcast_2_piece0 in memory on 10.1.2.243:33377 (size: 2.2 KB, free: 6.3 GB)
17/02/07 13:20:08,181 INFO BlockManagerInfo: Added broadcast_2_piece0 in memory on 10.1.2.211:35284 (size: 2.2 KB, free: 6.3 GB)
17/02/07 13:20:08,183 INFO BlockManagerInfo: Added broadcast_2_piece0 in memory on 10.1.2.148:41000 (size: 2.2 KB, free: 6.3 GB)
17/02/07 13:20:08,185 INFO BlockManagerInfo: Added broadcast_2_piece0 in memory on 10.1.2.245:36419 (size: 2.2 KB, free: 6.3 GB)
17/02/07 13:20:08,190 INFO BlockManagerInfo: Added broadcast_2_piece0 in memory on 10.1.2.224:44733 (size: 2.2 KB, free: 6.3 GB)
17/02/07 13:20:08,192 INFO BlockManagerInfo: Added broadcast_2_piece0 in memory on 10.1.2.29:45224 (size: 2.2 KB, free: 6.3 GB)
17/02/07 13:20:08,194 INFO BlockManagerInfo: Added broadcast_2_piece0 in memory on 10.1.2.130:36104 (size: 2.2 KB, free: 6.3 GB)
17/02/07 13:20:08,195 INFO BlockManagerInfo: Added broadcast_2_piece0 in memory on 10.1.2.106:38042 (size: 2.2 KB, free: 6.3 GB)
17/02/07 13:20:08,199 INFO BlockManagerInfo: Added broadcast_2_piece0 in memory on 10.1.2.133:45449 (size: 2.2 KB, free: 6.3 GB)
17/02/07 13:20:08,209 INFO BlockManagerInfo: Added broadcast_2_piece0 in memory on 10.1.2.214:44655 (size: 2.2 KB, free: 6.3 GB)
17/02/07 13:20:08,213 INFO BlockManagerInfo: Added broadcast_2_piece0 in memory on 10.1.2.41:46050 (size: 2.2 KB, free: 6.3 GB)
17/02/07 13:20:08,364 INFO BlockManagerInfo: Added broadcast_0_piece0 in memory on 10.1.2.211:35284 (size: 16.5 KB, free: 6.3 GB)
17/02/07 13:20:08,369 INFO BlockManagerInfo: Added broadcast_0_piece0 in memory on 10.1.2.243:33377 (size: 16.5 KB, free: 6.3 GB)
17/02/07 13:20:08,375 INFO BlockManagerInfo: Added broadcast_0_piece0 in memory on 10.1.2.245:36419 (size: 16.5 KB, free: 6.3 GB)
17/02/07 13:20:08,387 INFO BlockManagerInfo: Added broadcast_0_piece0 in memory on 10.1.2.215:41257 (size: 16.5 KB, free: 6.3 GB)
17/02/07 13:20:08,388 INFO BlockManagerInfo: Added broadcast_0_piece0 in memory on 10.1.2.224:44733 (size: 16.5 KB, free: 6.3 GB)
17/02/07 13:20:08,390 INFO BlockManagerInfo: Added broadcast_0_piece0 in memory on 10.1.2.133:45449 (size: 16.5 KB, free: 6.3 GB)
17/02/07 13:20:08,397 INFO BlockManagerInfo: Added broadcast_0_piece0 in memory on 10.1.2.130:36104 (size: 16.5 KB, free: 6.3 GB)
17/02/07 13:20:08,423 INFO BlockManagerInfo: Added broadcast_0_piece0 in memory on 10.1.2.29:45224 (size: 16.5 KB, free: 6.3 GB)
17/02/07 13:20:08,427 INFO BlockManagerInfo: Added broadcast_0_piece0 in memory on 10.1.2.148:41000 (size: 16.5 KB, free: 6.3 GB)
17/02/07 13:20:08,442 INFO BlockManagerInfo: Added broadcast_0_piece0 in memory on 10.1.2.106:38042 (size: 16.5 KB, free: 6.3 GB)
17/02/07 13:20:08,450 INFO BlockManagerInfo: Added broadcast_0_piece0 in memory on 10.1.2.41:46050 (size: 16.5 KB, free: 6.3 GB)
17/02/07 13:20:08,451 INFO BlockManagerInfo: Added broadcast_0_piece0 in memory on 10.1.2.214:44655 (size: 16.5 KB, free: 6.3 GB)
17/02/07 13:20:11,349 INFO TaskSetManager: Starting task 1.0 in stage 1.0 (TID 20, 10.1.2.148, partition 1, ANY, 5373 bytes)
17/02/07 13:20:11,352 INFO TaskSetManager: Starting task 2.0 in stage 1.0 (TID 21, 10.1.2.41, partition 2, ANY, 5373 bytes)
17/02/07 13:20:11,354 INFO TaskSetManager: Starting task 4.0 in stage 1.0 (TID 22, 10.1.2.83, partition 4, ANY, 5373 bytes)
17/02/07 13:20:11,357 INFO TaskSetManager: Starting task 5.0 in stage 1.0 (TID 23, 10.1.2.130, partition 5, ANY, 5373 bytes)
17/02/07 13:20:11,359 INFO TaskSetManager: Starting task 7.0 in stage 1.0 (TID 24, 10.1.2.243, partition 7, ANY, 5373 bytes)
17/02/07 13:20:11,362 INFO TaskSetManager: Starting task 8.0 in stage 1.0 (TID 25, 10.1.2.106, partition 8, ANY, 5373 bytes)
17/02/07 13:20:11,365 INFO TaskSetManager: Starting task 9.0 in stage 1.0 (TID 26, 10.1.2.245, partition 9, ANY, 5373 bytes)
17/02/07 13:20:11,367 INFO TaskSetManager: Starting task 11.0 in stage 1.0 (TID 27, 10.1.2.133, partition 11, ANY, 5373 bytes)
17/02/07 13:20:11,369 INFO TaskSetManager: Starting task 12.0 in stage 1.0 (TID 28, 10.1.2.29, partition 12, ANY, 5373 bytes)
17/02/07 13:20:11,371 INFO TaskSetManager: Starting task 14.0 in stage 1.0 (TID 29, 10.1.2.224, partition 14, ANY, 5373 bytes)
17/02/07 13:20:11,374 INFO TaskSetManager: Starting task 15.0 in stage 1.0 (TID 30, 10.1.2.211, partition 15, ANY, 5373 bytes)
17/02/07 13:20:11,376 INFO TaskSetManager: Starting task 16.0 in stage 1.0 (TID 31, 10.1.2.165, partition 16, ANY, 5373 bytes)
17/02/07 13:20:11,379 INFO TaskSetManager: Starting task 18.0 in stage 1.0 (TID 32, 10.1.2.47, partition 18, ANY, 5373 bytes)
17/02/07 13:20:11,382 INFO TaskSetManager: Starting task 19.0 in stage 1.0 (TID 33, 10.1.2.214, partition 19, ANY, 5373 bytes)
17/02/07 13:20:11,385 INFO TaskSetManager: Starting task 21.0 in stage 1.0 (TID 34, 10.1.2.172, partition 21, ANY, 5373 bytes)
17/02/07 13:20:11,388 INFO TaskSetManager: Starting task 22.0 in stage 1.0 (TID 35, 10.1.2.215, partition 22, ANY, 5373 bytes)
17/02/07 13:20:11,393 INFO TaskSetManager: Starting task 23.0 in stage 1.0 (TID 36, 10.1.2.148, partition 23, ANY, 5373 bytes)
17/02/07 13:20:11,396 INFO TaskSetManager: Starting task 25.0 in stage 1.0 (TID 37, 10.1.2.41, partition 25, ANY, 5373 bytes)
17/02/07 13:20:11,402 INFO TaskSetManager: Starting task 26.0 in stage 1.0 (TID 38, 10.1.2.83, partition 26, ANY, 5373 bytes)
17/02/07 13:20:11,403 INFO TaskSetManager: Starting task 28.0 in stage 1.0 (TID 39, 10.1.2.130, partition 28, ANY, 5373 bytes)
17/02/07 13:20:11,405 INFO TaskSetManager: Starting task 29.0 in stage 1.0 (TID 40, 10.1.2.243, partition 29, ANY, 5373 bytes)
17/02/07 13:20:11,407 INFO TaskSetManager: Starting task 30.0 in stage 1.0 (TID 41, 10.1.2.106, partition 30, ANY, 5373 bytes)
17/02/07 13:20:11,408 INFO TaskSetManager: Starting task 32.0 in stage 1.0 (TID 42, 10.1.2.245, partition 32, ANY, 5373 bytes)
17/02/07 13:20:11,410 INFO TaskSetManager: Starting task 33.0 in stage 1.0 (TID 43, 10.1.2.133, partition 33, ANY, 5373 bytes)
17/02/07 13:20:11,412 INFO TaskSetManager: Starting task 35.0 in stage 1.0 (TID 44, 10.1.2.29, partition 35, ANY, 5373 bytes)
17/02/07 13:20:11,414 INFO TaskSetManager: Starting task 36.0 in stage 1.0 (TID 45, 10.1.2.224, partition 36, ANY, 5373 bytes)
17/02/07 13:20:11,415 INFO TaskSetManager: Starting task 37.0 in stage 1.0 (TID 46, 10.1.2.211, partition 37, ANY, 5373 bytes)
17/02/07 13:20:11,416 INFO TaskSetManager: Starting task 39.0 in stage 1.0 (TID 47, 10.1.2.165, partition 39, ANY, 5373 bytes)
17/02/07 13:20:11,417 INFO TaskSetManager: Starting task 40.0 in stage 1.0 (TID 48, 10.1.2.47, partition 40, ANY, 5373 bytes)
17/02/07 13:20:11,418 INFO TaskSetManager: Starting task 42.0 in stage 1.0 (TID 49, 10.1.2.214, partition 42, ANY, 5373 bytes)
17/02/07 13:20:11,419 INFO TaskSetManager: Starting task 43.0 in stage 1.0 (TID 50, 10.1.2.172, partition 43, ANY, 5373 bytes)
17/02/07 13:20:11,421 INFO TaskSetManager: Starting task 44.0 in stage 1.0 (TID 51, 10.1.2.215, partition 44, ANY, 5373 bytes)
17/02/07 13:20:11,422 INFO TaskSetManager: Starting task 46.0 in stage 1.0 (TID 52, 10.1.2.148, partition 46, ANY, 5373 bytes)
17/02/07 13:20:11,423 INFO TaskSetManager: Starting task 47.0 in stage 1.0 (TID 53, 10.1.2.83, partition 47, ANY, 5373 bytes)
17/02/07 13:20:11,425 INFO TaskSetManager: Starting task 49.0 in stage 1.0 (TID 54, 10.1.2.245, partition 49, ANY, 5373 bytes)
17/02/07 13:20:11,426 INFO TaskSetManager: Starting task 50.0 in stage 1.0 (TID 55, 10.1.2.29, partition 50, ANY, 5373 bytes)
17/02/07 13:20:11,427 INFO TaskSetManager: Starting task 51.0 in stage 1.0 (TID 56, 10.1.2.224, partition 51, ANY, 5373 bytes)
17/02/07 13:20:11,429 INFO TaskSetManager: Starting task 53.0 in stage 1.0 (TID 57, 10.1.2.211, partition 53, ANY, 5373 bytes)
17/02/07 13:20:11,430 INFO TaskSetManager: Starting task 54.0 in stage 1.0 (TID 58, 10.1.2.165, partition 54, ANY, 5373 bytes)
17/02/07 13:20:11,432 INFO TaskSetManager: Starting task 56.0 in stage 1.0 (TID 59, 10.1.2.47, partition 56, ANY, 5373 bytes)
17/02/07 13:20:11,433 INFO TaskSetManager: Starting task 57.0 in stage 1.0 (TID 60, 10.1.2.172, partition 57, ANY, 5373 bytes)
17/02/07 13:20:11,434 INFO TaskSetManager: Starting task 58.0 in stage 1.0 (TID 61, 10.1.2.215, partition 58, ANY, 5373 bytes)
17/02/07 13:20:11,436 INFO TaskSetManager: Starting task 60.0 in stage 1.0 (TID 62, 10.1.2.83, partition 60, ANY, 5373 bytes)
17/02/07 13:20:11,437 INFO TaskSetManager: Starting task 61.0 in stage 1.0 (TID 63, 10.1.2.165, partition 61, ANY, 5373 bytes)
17/02/07 13:20:11,439 INFO TaskSetManager: Starting task 63.0 in stage 1.0 (TID 64, 10.1.2.47, partition 63, ANY, 5373 bytes)
17/02/07 13:20:11,440 INFO CoarseGrainedSchedulerBackend$DriverEndpoint: Launching task 20 on executor id: 12 hostname: 10.1.2.148.
17/02/07 13:20:11,441 INFO CoarseGrainedSchedulerBackend$DriverEndpoint: Launching task 36 on executor id: 12 hostname: 10.1.2.148.
17/02/07 13:20:11,441 INFO CoarseGrainedSchedulerBackend$DriverEndpoint: Launching task 52 on executor id: 12 hostname: 10.1.2.148.
17/02/07 13:20:11,442 INFO CoarseGrainedSchedulerBackend$DriverEndpoint: Launching task 21 on executor id: 6 hostname: 10.1.2.41.
17/02/07 13:20:11,443 INFO CoarseGrainedSchedulerBackend$DriverEndpoint: Launching task 37 on executor id: 6 hostname: 10.1.2.41.
17/02/07 13:20:11,443 INFO CoarseGrainedSchedulerBackend$DriverEndpoint: Launching task 22 on executor id: 4 hostname: 10.1.2.83.
17/02/07 13:20:11,444 INFO CoarseGrainedSchedulerBackend$DriverEndpoint: Launching task 38 on executor id: 4 hostname: 10.1.2.83.
17/02/07 13:20:11,444 INFO CoarseGrainedSchedulerBackend$DriverEndpoint: Launching task 53 on executor id: 4 hostname: 10.1.2.83.
17/02/07 13:20:11,445 INFO CoarseGrainedSchedulerBackend$DriverEndpoint: Launching task 62 on executor id: 4 hostname: 10.1.2.83.
17/02/07 13:20:11,445 INFO CoarseGrainedSchedulerBackend$DriverEndpoint: Launching task 23 on executor id: 9 hostname: 10.1.2.130.
17/02/07 13:20:11,446 INFO CoarseGrainedSchedulerBackend$DriverEndpoint: Launching task 39 on executor id: 9 hostname: 10.1.2.130.
17/02/07 13:20:11,446 INFO CoarseGrainedSchedulerBackend$DriverEndpoint: Launching task 24 on executor id: 1 hostname: 10.1.2.243.
17/02/07 13:20:11,447 INFO CoarseGrainedSchedulerBackend$DriverEndpoint: Launching task 40 on executor id: 1 hostname: 10.1.2.243.
17/02/07 13:20:11,448 INFO CoarseGrainedSchedulerBackend$DriverEndpoint: Launching task 25 on executor id: 15 hostname: 10.1.2.106.
17/02/07 13:20:11,448 INFO CoarseGrainedSchedulerBackend$DriverEndpoint: Launching task 41 on executor id: 15 hostname: 10.1.2.106.
17/02/07 13:20:11,449 INFO CoarseGrainedSchedulerBackend$DriverEndpoint: Launching task 26 on executor id: 10 hostname: 10.1.2.245.
17/02/07 13:20:11,449 INFO CoarseGrainedSchedulerBackend$DriverEndpoint: Launching task 42 on executor id: 10 hostname: 10.1.2.245.
17/02/07 13:20:11,457 INFO CoarseGrainedSchedulerBackend$DriverEndpoint: Launching task 54 on executor id: 10 hostname: 10.1.2.245.
17/02/07 13:20:11,457 INFO CoarseGrainedSchedulerBackend$DriverEndpoint: Launching task 27 on executor id: 7 hostname: 10.1.2.133.
17/02/07 13:20:11,458 INFO CoarseGrainedSchedulerBackend$DriverEndpoint: Launching task 43 on executor id: 7 hostname: 10.1.2.133.
17/02/07 13:20:11,458 INFO CoarseGrainedSchedulerBackend$DriverEndpoint: Launching task 28 on executor id: 0 hostname: 10.1.2.29.
17/02/07 13:20:11,459 INFO CoarseGrainedSchedulerBackend$DriverEndpoint: Launching task 44 on executor id: 0 hostname: 10.1.2.29.
17/02/07 13:20:11,459 INFO CoarseGrainedSchedulerBackend$DriverEndpoint: Launching task 55 on executor id: 0 hostname: 10.1.2.29.
17/02/07 13:20:11,459 INFO CoarseGrainedSchedulerBackend$DriverEndpoint: Launching task 29 on executor id: 11 hostname: 10.1.2.224.
17/02/07 13:20:11,463 INFO CoarseGrainedSchedulerBackend$DriverEndpoint: Launching task 45 on executor id: 11 hostname: 10.1.2.224.
17/02/07 13:20:11,464 INFO CoarseGrainedSchedulerBackend$DriverEndpoint: Launching task 56 on executor id: 11 hostname: 10.1.2.224.
17/02/07 13:20:11,464 INFO CoarseGrainedSchedulerBackend$DriverEndpoint: Launching task 30 on executor id: 14 hostname: 10.1.2.211.
17/02/07 13:20:11,464 INFO CoarseGrainedSchedulerBackend$DriverEndpoint: Launching task 46 on executor id: 14 hostname: 10.1.2.211.
17/02/07 13:20:11,465 INFO CoarseGrainedSchedulerBackend$DriverEndpoint: Launching task 57 on executor id: 14 hostname: 10.1.2.211.
17/02/07 13:20:11,465 INFO CoarseGrainedSchedulerBackend$DriverEndpoint: Launching task 31 on executor id: 2 hostname: 10.1.2.165.
17/02/07 13:20:11,465 INFO CoarseGrainedSchedulerBackend$DriverEndpoint: Launching task 47 on executor id: 2 hostname: 10.1.2.165.
17/02/07 13:20:11,466 INFO CoarseGrainedSchedulerBackend$DriverEndpoint: Launching task 58 on executor id: 2 hostname: 10.1.2.165.
17/02/07 13:20:11,469 INFO CoarseGrainedSchedulerBackend$DriverEndpoint: Launching task 63 on executor id: 2 hostname: 10.1.2.165.
17/02/07 13:20:11,470 INFO CoarseGrainedSchedulerBackend$DriverEndpoint: Launching task 32 on executor id: 13 hostname: 10.1.2.47.
17/02/07 13:20:11,470 INFO CoarseGrainedSchedulerBackend$DriverEndpoint: Launching task 48 on executor id: 13 hostname: 10.1.2.47.
17/02/07 13:20:11,470 INFO CoarseGrainedSchedulerBackend$DriverEndpoint: Launching task 59 on executor id: 13 hostname: 10.1.2.47.
17/02/07 13:20:11,471 INFO CoarseGrainedSchedulerBackend$DriverEndpoint: Launching task 64 on executor id: 13 hostname: 10.1.2.47.
17/02/07 13:20:11,471 INFO CoarseGrainedSchedulerBackend$DriverEndpoint: Launching task 33 on executor id: 8 hostname: 10.1.2.214.
17/02/07 13:20:11,471 INFO CoarseGrainedSchedulerBackend$DriverEndpoint: Launching task 49 on executor id: 8 hostname: 10.1.2.214.
17/02/07 13:20:11,471 INFO CoarseGrainedSchedulerBackend$DriverEndpoint: Launching task 34 on executor id: 5 hostname: 10.1.2.172.
17/02/07 13:20:11,472 INFO CoarseGrainedSchedulerBackend$DriverEndpoint: Launching task 50 on executor id: 5 hostname: 10.1.2.172.
17/02/07 13:20:11,472 INFO CoarseGrainedSchedulerBackend$DriverEndpoint: Launching task 60 on executor id: 5 hostname: 10.1.2.172.
17/02/07 13:20:11,472 INFO CoarseGrainedSchedulerBackend$DriverEndpoint: Launching task 35 on executor id: 3 hostname: 10.1.2.215.
17/02/07 13:20:11,473 INFO CoarseGrainedSchedulerBackend$DriverEndpoint: Launching task 51 on executor id: 3 hostname: 10.1.2.215.
17/02/07 13:20:11,473 INFO CoarseGrainedSchedulerBackend$DriverEndpoint: Launching task 61 on executor id: 3 hostname: 10.1.2.215.
17/02/07 13:20:11,833 INFO BlockManagerInfo: Added broadcast_2_piece0 in memory on 10.1.2.83:39232 (size: 2.2 KB, free: 6.3 GB)
17/02/07 13:20:11,845 INFO BlockManagerInfo: Added broadcast_2_piece0 in memory on 10.1.2.172:37669 (size: 2.2 KB, free: 6.3 GB)
17/02/07 13:20:11,861 INFO BlockManagerInfo: Added broadcast_2_piece0 in memory on 10.1.2.165:41549 (size: 2.2 KB, free: 6.3 GB)
17/02/07 13:20:12,064 INFO BlockManagerInfo: Added broadcast_0_piece0 in memory on 10.1.2.83:39232 (size: 16.5 KB, free: 6.3 GB)
17/02/07 13:20:12,077 INFO BlockManagerInfo: Added broadcast_0_piece0 in memory on 10.1.2.165:41549 (size: 16.5 KB, free: 6.3 GB)
17/02/07 13:20:12,108 INFO BlockManagerInfo: Added broadcast_0_piece0 in memory on 10.1.2.172:37669 (size: 16.5 KB, free: 6.3 GB)
17/02/07 13:20:12,964 INFO BlockManagerInfo: Added rdd_5_59 in memory on 10.1.2.245:36419 (size: 22.2 MB, free: 6.3 GB)
17/02/07 13:20:13,047 INFO TaskSetManager: Finished task 59.0 in stage 1.0 (TID 12) in 5243 ms on 10.1.2.245 (2/64)
17/02/07 13:20:13,180 INFO BlockManagerInfo: Added rdd_5_20 in memory on 10.1.2.133:45449 (size: 22.2 MB, free: 6.3 GB)
17/02/07 13:20:13,234 INFO BlockManagerInfo: Added rdd_5_6 in memory on 10.1.2.211:35284 (size: 22.2 MB, free: 6.3 GB)
17/02/07 13:20:13,262 INFO TaskSetManager: Finished task 20.0 in stage 1.0 (TID 11) in 5461 ms on 10.1.2.133 (3/64)
17/02/07 13:20:13,310 INFO TaskSetManager: Finished task 6.0 in stage 1.0 (TID 8) in 5514 ms on 10.1.2.211 (4/64)
17/02/07 13:20:13,374 INFO BlockManagerInfo: Added rdd_5_41 in memory on 10.1.2.215:41257 (size: 22.2 MB, free: 6.3 GB)
17/02/07 13:20:13,456 INFO BlockManagerInfo: Added rdd_5_62 in memory on 10.1.2.133:45449 (size: 22.2 MB, free: 6.2 GB)
17/02/07 13:20:13,484 INFO TaskSetManager: Finished task 62.0 in stage 1.0 (TID 19) in 5667 ms on 10.1.2.133 (5/64)
17/02/07 13:20:13,532 INFO TaskSetManager: Finished task 41.0 in stage 1.0 (TID 7) in 5737 ms on 10.1.2.215 (6/64)
17/02/07 13:20:13,745 INFO BlockManagerInfo: Added rdd_5_17 in memory on 10.1.2.130:36104 (size: 22.2 MB, free: 6.3 GB)
17/02/07 13:20:13,820 INFO TaskSetManager: Finished task 17.0 in stage 1.0 (TID 2) in 6035 ms on 10.1.2.130 (7/64)
17/02/07 13:20:13,986 INFO BlockManagerInfo: Added rdd_5_55 in memory on 10.1.2.130:36104 (size: 22.2 MB, free: 6.2 GB)
17/02/07 13:20:14,002 INFO TaskSetManager: Finished task 55.0 in stage 1.0 (TID 14) in 6195 ms on 10.1.2.130 (8/64)
17/02/07 13:20:14,035 INFO BlockManagerInfo: Added rdd_5_45 in memory on 10.1.2.214:44655 (size: 22.2 MB, free: 6.3 GB)
17/02/07 13:20:14,099 INFO BlockManagerInfo: Added rdd_5_3 in memory on 10.1.2.214:44655 (size: 22.2 MB, free: 6.2 GB)
17/02/07 13:20:14,137 INFO BlockManagerInfo: Added rdd_5_13 in memory on 10.1.2.224:44733 (size: 22.2 MB, free: 6.3 GB)
17/02/07 13:20:14,137 INFO TaskSetManager: Finished task 3.0 in stage 1.0 (TID 4) in 6349 ms on 10.1.2.214 (9/64)
17/02/07 13:20:14,142 INFO TaskSetManager: Finished task 45.0 in stage 1.0 (TID 16) in 6331 ms on 10.1.2.214 (10/64)
17/02/07 13:20:14,193 INFO BlockManagerInfo: Added rdd_5_52 in memory on 10.1.2.29:45224 (size: 22.2 MB, free: 6.3 GB)
17/02/07 13:20:14,214 INFO TaskSetManager: Finished task 13.0 in stage 1.0 (TID 10) in 6415 ms on 10.1.2.224 (11/64)
17/02/07 13:20:14,283 INFO TaskSetManager: Finished task 52.0 in stage 1.0 (TID 13) in 6478 ms on 10.1.2.29 (12/64)
17/02/07 13:20:14,349 INFO BlockManagerInfo: Added rdd_5_38 in memory on 10.1.2.148:41000 (size: 22.2 MB, free: 6.3 GB)
17/02/07 13:20:14,388 INFO BlockManagerInfo: Added rdd_5_48 in memory on 10.1.2.41:46050 (size: 22.1 MB, free: 6.3 GB)
17/02/07 13:20:14,441 INFO TaskSetManager: Finished task 38.0 in stage 1.0 (TID 6) in 6649 ms on 10.1.2.148 (13/64)
17/02/07 13:20:14,452 INFO BlockManagerInfo: Added rdd_5_10 in memory on 10.1.2.41:46050 (size: 22.2 MB, free: 6.2 GB)
17/02/07 13:20:14,494 INFO TaskSetManager: Finished task 10.0 in stage 1.0 (TID 9) in 6697 ms on 10.1.2.41 (14/64)
17/02/07 13:20:14,499 INFO TaskSetManager: Finished task 48.0 in stage 1.0 (TID 18) in 6682 ms on 10.1.2.41 (15/64)
17/02/07 13:20:14,507 INFO BlockManagerInfo: Added rdd_5_24 in memory on 10.1.2.243:33377 (size: 22.2 MB, free: 6.3 GB)
17/02/07 13:20:14,588 INFO TaskSetManager: Finished task 24.0 in stage 1.0 (TID 3) in 6801 ms on 10.1.2.243 (16/64)
17/02/07 13:20:15,152 INFO BlockManagerInfo: Added rdd_5_33 in memory on 10.1.2.133:45449 (size: 22.2 MB, free: 6.2 GB)
17/02/07 13:20:15,157 INFO BlockManagerInfo: Added rdd_5_11 in memory on 10.1.2.133:45449 (size: 22.2 MB, free: 6.2 GB)
17/02/07 13:20:15,172 INFO TaskSetManager: Finished task 33.0 in stage 1.0 (TID 43) in 3763 ms on 10.1.2.133 (17/64)
17/02/07 13:20:15,174 INFO TaskSetManager: Finished task 11.0 in stage 1.0 (TID 27) in 3809 ms on 10.1.2.133 (18/64)
17/02/07 13:20:15,305 INFO BlockManagerInfo: Added rdd_5_27 in memory on 10.1.2.106:38042 (size: 22.1 MB, free: 6.3 GB)
17/02/07 13:20:15,310 INFO BlockManagerInfo: Added rdd_5_5 in memory on 10.1.2.130:36104 (size: 22.2 MB, free: 6.2 GB)
17/02/07 13:20:15,313 INFO BlockManagerInfo: Added rdd_5_9 in memory on 10.1.2.245:36419 (size: 22.2 MB, free: 6.2 GB)
17/02/07 13:20:15,328 INFO TaskSetManager: Finished task 9.0 in stage 1.0 (TID 26) in 3965 ms on 10.1.2.245 (19/64)
17/02/07 13:20:15,330 INFO BlockManagerInfo: Added rdd_5_49 in memory on 10.1.2.245:36419 (size: 22.2 MB, free: 6.2 GB)
17/02/07 13:20:15,330 INFO TaskSetManager: Finished task 5.0 in stage 1.0 (TID 23) in 3975 ms on 10.1.2.130 (20/64)
17/02/07 13:20:15,355 INFO TaskSetManager: Finished task 49.0 in stage 1.0 (TID 54) in 3932 ms on 10.1.2.245 (21/64)
17/02/07 13:20:15,369 INFO BlockManagerInfo: Added rdd_5_28 in memory on 10.1.2.130:36104 (size: 22.2 MB, free: 6.2 GB)
17/02/07 13:20:15,384 INFO TaskSetManager: Finished task 28.0 in stage 1.0 (TID 39) in 3982 ms on 10.1.2.130 (22/64)
17/02/07 13:20:15,390 INFO TaskSetManager: Finished task 27.0 in stage 1.0 (TID 5) in 7600 ms on 10.1.2.106 (23/64)
17/02/07 13:20:15,414 INFO BlockManagerInfo: Added rdd_5_31 in memory on 10.1.2.243:33377 (size: 22.2 MB, free: 6.2 GB)
17/02/07 13:20:15,437 INFO TaskSetManager: Finished task 31.0 in stage 1.0 (TID 15) in 7627 ms on 10.1.2.243 (24/64)
17/02/07 13:20:15,458 INFO BlockManagerInfo: Added rdd_5_32 in memory on 10.1.2.245:36419 (size: 22.2 MB, free: 6.2 GB)
17/02/07 13:20:15,470 INFO TaskSetManager: Finished task 32.0 in stage 1.0 (TID 42) in 4063 ms on 10.1.2.245 (25/64)
17/02/07 13:20:15,493 INFO BlockManagerInfo: Added rdd_5_42 in memory on 10.1.2.214:44655 (size: 22.2 MB, free: 6.2 GB)
17/02/07 13:20:15,509 INFO TaskSetManager: Finished task 42.0 in stage 1.0 (TID 49) in 4092 ms on 10.1.2.214 (26/64)
17/02/07 13:20:15,607 INFO BlockManagerInfo: Added rdd_5_25 in memory on 10.1.2.41:46050 (size: 22.2 MB, free: 6.2 GB)
17/02/07 13:20:15,624 INFO TaskSetManager: Finished task 25.0 in stage 1.0 (TID 37) in 4229 ms on 10.1.2.41 (27/64)
17/02/07 13:20:15,639 INFO BlockManagerInfo: Added rdd_5_19 in memory on 10.1.2.214:44655 (size: 22.2 MB, free: 6.2 GB)
17/02/07 13:20:15,652 INFO TaskSetManager: Finished task 19.0 in stage 1.0 (TID 33) in 4272 ms on 10.1.2.214 (28/64)
17/02/07 13:20:15,662 INFO BlockManagerInfo: Added rdd_5_34 in memory on 10.1.2.106:38042 (size: 22.2 MB, free: 6.2 GB)
17/02/07 13:20:15,673 INFO TaskSetManager: Finished task 34.0 in stage 1.0 (TID 17) in 7861 ms on 10.1.2.106 (29/64)
17/02/07 13:20:15,757 INFO BlockManagerInfo: Added rdd_5_2 in memory on 10.1.2.41:46050 (size: 22.1 MB, free: 6.2 GB)
17/02/07 13:20:15,770 INFO TaskSetManager: Finished task 2.0 in stage 1.0 (TID 21) in 4420 ms on 10.1.2.41 (30/64)
17/02/07 13:20:15,835 INFO BlockManagerInfo: Added rdd_5_15 in memory on 10.1.2.211:35284 (size: 22.1 MB, free: 6.2 GB)
17/02/07 13:20:15,841 INFO BlockManagerInfo: Added rdd_5_53 in memory on 10.1.2.211:35284 (size: 22.2 MB, free: 6.2 GB)
17/02/07 13:20:15,853 INFO TaskSetManager: Finished task 15.0 in stage 1.0 (TID 30) in 4481 ms on 10.1.2.211 (31/64)
17/02/07 13:20:15,870 INFO TaskSetManager: Finished task 53.0 in stage 1.0 (TID 57) in 4442 ms on 10.1.2.211 (32/64)
17/02/07 13:20:15,909 INFO BlockManagerInfo: Added rdd_5_37 in memory on 10.1.2.211:35284 (size: 22.2 MB, free: 6.2 GB)
17/02/07 13:20:15,922 INFO TaskSetManager: Finished task 37.0 in stage 1.0 (TID 46) in 4508 ms on 10.1.2.211 (33/64)
17/02/07 13:20:16,082 INFO BlockManagerInfo: Added rdd_5_12 in memory on 10.1.2.29:45224 (size: 22.2 MB, free: 6.2 GB)
17/02/07 13:20:16,090 INFO BlockManagerInfo: Added rdd_5_35 in memory on 10.1.2.29:45224 (size: 22.1 MB, free: 6.2 GB)
17/02/07 13:20:16,096 INFO TaskSetManager: Finished task 12.0 in stage 1.0 (TID 28) in 4728 ms on 10.1.2.29 (34/64)
17/02/07 13:20:16,113 INFO TaskSetManager: Finished task 35.0 in stage 1.0 (TID 44) in 4702 ms on 10.1.2.29 (35/64)
17/02/07 13:20:16,233 INFO BlockManagerInfo: Added rdd_5_50 in memory on 10.1.2.29:45224 (size: 22.1 MB, free: 6.2 GB)
17/02/07 13:20:16,242 INFO BlockManagerInfo: Added rdd_5_22 in memory on 10.1.2.215:41257 (size: 22.2 MB, free: 6.2 GB)
17/02/07 13:20:16,257 INFO TaskSetManager: Finished task 22.0 in stage 1.0 (TID 35) in 4871 ms on 10.1.2.215 (36/64)
17/02/07 13:20:16,258 INFO BlockManagerInfo: Added rdd_5_58 in memory on 10.1.2.215:41257 (size: 22.2 MB, free: 6.2 GB)
17/02/07 13:20:16,267 INFO TaskSetManager: Finished task 50.0 in stage 1.0 (TID 55) in 4841 ms on 10.1.2.29 (37/64)
17/02/07 13:20:16,284 INFO TaskSetManager: Finished task 58.0 in stage 1.0 (TID 61) in 4850 ms on 10.1.2.215 (38/64)
17/02/07 13:20:16,338 INFO BlockManagerInfo: Added rdd_5_46 in memory on 10.1.2.148:41000 (size: 22.1 MB, free: 6.2 GB)
17/02/07 13:20:16,343 INFO BlockManagerInfo: Added rdd_5_44 in memory on 10.1.2.215:41257 (size: 22.2 MB, free: 6.2 GB)
17/02/07 13:20:16,353 INFO TaskSetManager: Finished task 46.0 in stage 1.0 (TID 52) in 4931 ms on 10.1.2.148 (39/64)
17/02/07 13:20:16,354 INFO TaskSetManager: Finished task 44.0 in stage 1.0 (TID 51) in 4934 ms on 10.1.2.215 (40/64)
17/02/07 13:20:16,473 INFO BlockManagerInfo: Added rdd_5_23 in memory on 10.1.2.148:41000 (size: 22.2 MB, free: 6.2 GB)
17/02/07 13:20:16,485 INFO BlockManagerInfo: Added rdd_5_1 in memory on 10.1.2.148:41000 (size: 22.2 MB, free: 6.2 GB)
17/02/07 13:20:16,500 INFO TaskSetManager: Finished task 23.0 in stage 1.0 (TID 36) in 5108 ms on 10.1.2.148 (41/64)
17/02/07 13:20:16,502 INFO TaskSetManager: Finished task 1.0 in stage 1.0 (TID 20) in 5154 ms on 10.1.2.148 (42/64)
17/02/07 13:20:16,505 INFO BlockManagerInfo: Added rdd_5_7 in memory on 10.1.2.243:33377 (size: 22.2 MB, free: 6.2 GB)
17/02/07 13:20:16,521 INFO TaskSetManager: Finished task 7.0 in stage 1.0 (TID 24) in 5164 ms on 10.1.2.243 (43/64)
17/02/07 13:20:16,574 INFO BlockManagerInfo: Added rdd_5_30 in memory on 10.1.2.106:38042 (size: 22.2 MB, free: 6.2 GB)
17/02/07 13:20:16,594 INFO TaskSetManager: Finished task 30.0 in stage 1.0 (TID 41) in 5188 ms on 10.1.2.106 (44/64)
17/02/07 13:20:16,705 INFO BlockManagerInfo: Added rdd_5_8 in memory on 10.1.2.106:38042 (size: 22.2 MB, free: 6.2 GB)
17/02/07 13:20:16,713 INFO BlockManagerInfo: Added rdd_5_29 in memory on 10.1.2.243:33377 (size: 22.2 MB, free: 6.2 GB)
17/02/07 13:20:16,719 INFO TaskSetManager: Finished task 8.0 in stage 1.0 (TID 25) in 5359 ms on 10.1.2.106 (45/64)
17/02/07 13:20:16,726 INFO TaskSetManager: Finished task 29.0 in stage 1.0 (TID 40) in 5322 ms on 10.1.2.243 (46/64)
17/02/07 13:20:16,885 INFO BlockManagerInfo: Added rdd_5_18 in memory on 10.1.2.47:40115 (size: 22.2 MB, free: 6.2 GB)
17/02/07 13:20:16,920 INFO TaskSetManager: Finished task 18.0 in stage 1.0 (TID 32) in 5543 ms on 10.1.2.47 (47/64)
17/02/07 13:20:16,975 INFO BlockManagerInfo: Added rdd_5_63 in memory on 10.1.2.47:40115 (size: 22.2 MB, free: 6.2 GB)
17/02/07 13:20:17,011 INFO TaskSetManager: Finished task 63.0 in stage 1.0 (TID 64) in 5574 ms on 10.1.2.47 (48/64)
17/02/07 13:20:17,077 INFO BlockManagerInfo: Added rdd_5_56 in memory on 10.1.2.47:40115 (size: 22.2 MB, free: 6.2 GB)
17/02/07 13:20:17,089 INFO TaskSetManager: Finished task 56.0 in stage 1.0 (TID 59) in 5659 ms on 10.1.2.47 (49/64)
17/02/07 13:20:17,232 INFO BlockManagerInfo: Added rdd_5_40 in memory on 10.1.2.47:40115 (size: 22.2 MB, free: 6.2 GB)
17/02/07 13:20:17,243 INFO TaskSetManager: Finished task 40.0 in stage 1.0 (TID 48) in 5827 ms on 10.1.2.47 (50/64)
17/02/07 13:20:18,230 INFO BlockManagerInfo: Added rdd_5_57 in memory on 10.1.2.172:37669 (size: 22.2 MB, free: 6.3 GB)
17/02/07 13:20:18,234 INFO BlockManagerInfo: Added rdd_5_43 in memory on 10.1.2.172:37669 (size: 22.2 MB, free: 6.2 GB)
17/02/07 13:20:18,246 INFO BlockManagerInfo: Added rdd_5_21 in memory on 10.1.2.172:37669 (size: 22.2 MB, free: 6.2 GB)
17/02/07 13:20:18,298 INFO TaskSetManager: Finished task 21.0 in stage 1.0 (TID 34) in 6915 ms on 10.1.2.172 (51/64)
17/02/07 13:20:18,299 INFO TaskSetManager: Finished task 57.0 in stage 1.0 (TID 60) in 6867 ms on 10.1.2.172 (52/64)
17/02/07 13:20:18,301 INFO TaskSetManager: Finished task 43.0 in stage 1.0 (TID 50) in 6882 ms on 10.1.2.172 (53/64)
17/02/07 13:20:18,519 INFO BlockManagerInfo: Added rdd_5_36 in memory on 10.1.2.224:44733 (size: 22.2 MB, free: 6.2 GB)
17/02/07 13:20:18,534 INFO TaskSetManager: Finished task 36.0 in stage 1.0 (TID 45) in 7121 ms on 10.1.2.224 (54/64)
17/02/07 13:20:18,598 INFO BlockManagerInfo: Added rdd_5_14 in memory on 10.1.2.224:44733 (size: 22.2 MB, free: 6.2 GB)
17/02/07 13:20:18,611 INFO TaskSetManager: Finished task 14.0 in stage 1.0 (TID 29) in 7241 ms on 10.1.2.224 (55/64)
17/02/07 13:20:18,663 INFO BlockManagerInfo: Added rdd_5_51 in memory on 10.1.2.224:44733 (size: 22.2 MB, free: 6.2 GB)
17/02/07 13:20:18,677 INFO TaskSetManager: Finished task 51.0 in stage 1.0 (TID 56) in 7251 ms on 10.1.2.224 (56/64)
17/02/07 13:20:18,998 INFO BlockManagerInfo: Added rdd_5_60 in memory on 10.1.2.83:39232 (size: 22.1 MB, free: 6.3 GB)
17/02/07 13:20:19,063 INFO TaskSetManager: Finished task 60.0 in stage 1.0 (TID 62) in 7628 ms on 10.1.2.83 (57/64)
17/02/07 13:20:19,719 INFO BlockManagerInfo: Added rdd_5_47 in memory on 10.1.2.83:39232 (size: 22.2 MB, free: 6.2 GB)
17/02/07 13:20:19,729 INFO TaskSetManager: Finished task 47.0 in stage 1.0 (TID 53) in 8307 ms on 10.1.2.83 (58/64)
17/02/07 13:20:19,797 INFO BlockManagerInfo: Added rdd_5_39 in memory on 10.1.2.165:41549 (size: 22.1 MB, free: 6.3 GB)
17/02/07 13:20:19,831 INFO BlockManagerInfo: Added rdd_5_4 in memory on 10.1.2.83:39232 (size: 22.2 MB, free: 6.2 GB)
17/02/07 13:20:19,842 INFO TaskSetManager: Finished task 4.0 in stage 1.0 (TID 22) in 8490 ms on 10.1.2.83 (59/64)
17/02/07 13:20:19,842 INFO BlockManagerInfo: Added rdd_5_26 in memory on 10.1.2.83:39232 (size: 22.2 MB, free: 6.2 GB)
17/02/07 13:20:19,854 INFO TaskSetManager: Finished task 26.0 in stage 1.0 (TID 38) in 8454 ms on 10.1.2.83 (60/64)
17/02/07 13:20:19,889 INFO TaskSetManager: Finished task 39.0 in stage 1.0 (TID 47) in 8473 ms on 10.1.2.165 (61/64)
17/02/07 13:20:19,936 INFO BlockManagerInfo: Added rdd_5_16 in memory on 10.1.2.165:41549 (size: 22.1 MB, free: 6.2 GB)
17/02/07 13:20:19,950 INFO TaskSetManager: Finished task 16.0 in stage 1.0 (TID 31) in 8575 ms on 10.1.2.165 (62/64)
17/02/07 13:20:20,460 INFO BlockManagerInfo: Added rdd_5_54 in memory on 10.1.2.165:41549 (size: 22.2 MB, free: 6.2 GB)
17/02/07 13:20:20,475 INFO TaskSetManager: Finished task 54.0 in stage 1.0 (TID 58) in 9046 ms on 10.1.2.165 (63/64)
17/02/07 13:20:20,610 INFO BlockManagerInfo: Added rdd_5_61 in memory on 10.1.2.165:41549 (size: 22.2 MB, free: 6.2 GB)
17/02/07 13:20:20,622 INFO TaskSetManager: Finished task 61.0 in stage 1.0 (TID 63) in 9185 ms on 10.1.2.165 (64/64)
17/02/07 13:20:20,622 INFO TaskSchedulerImpl: Removed TaskSet 1.0, whose tasks have all completed, from pool 
17/02/07 13:20:20,622 INFO DAGScheduler: ResultStage 1 (count at DataValidators.scala:40) finished in 12.843 s
17/02/07 13:20:20,623 INFO DAGScheduler: Job 1 finished: count at DataValidators.scala:40, took 12.882806 s
17/02/07 13:20:20,637 INFO SparkContext: Starting job: count at GradientDescent.scala:209
17/02/07 13:20:20,638 INFO DAGScheduler: Got job 2 (count at GradientDescent.scala:209) with 64 output partitions
17/02/07 13:20:20,638 INFO DAGScheduler: Final stage: ResultStage 2 (count at GradientDescent.scala:209)
17/02/07 13:20:20,638 INFO DAGScheduler: Parents of final stage: List()
17/02/07 13:20:20,641 INFO DAGScheduler: Missing parents: List()
17/02/07 13:20:20,641 INFO DAGScheduler: Submitting ResultStage 2 (MapPartitionsRDD[8] at map at GeneralizedLinearAlgorithm.scala:297), which has no missing parents
17/02/07 13:20:20,648 INFO MemoryStore: Block broadcast_3 stored as values in memory (estimated size 3.9 KB, free 6.3 GB)
17/02/07 13:20:20,650 INFO MemoryStore: Block broadcast_3_piece0 stored as bytes in memory (estimated size 2.2 KB, free 6.3 GB)
17/02/07 13:20:20,651 INFO BlockManagerInfo: Added broadcast_3_piece0 in memory on 10.1.2.152:32967 (size: 2.2 KB, free: 6.3 GB)
17/02/07 13:20:20,652 INFO SparkContext: Created broadcast 3 from broadcast at DAGScheduler.scala:1012
17/02/07 13:20:20,653 INFO DAGScheduler: Submitting 64 missing tasks from ResultStage 2 (MapPartitionsRDD[8] at map at GeneralizedLinearAlgorithm.scala:297)
17/02/07 13:20:20,654 INFO TaskSchedulerImpl: Adding task set 2.0 with 64 tasks
17/02/07 13:20:20,657 INFO TaskSetManager: Starting task 9.0 in stage 2.0 (TID 65, 10.1.2.245, partition 9, PROCESS_LOCAL, 5373 bytes)
17/02/07 13:20:20,659 INFO TaskSetManager: Starting task 4.0 in stage 2.0 (TID 66, 10.1.2.83, partition 4, PROCESS_LOCAL, 5373 bytes)
17/02/07 13:20:20,660 INFO TaskSetManager: Starting task 13.0 in stage 2.0 (TID 67, 10.1.2.224, partition 13, PROCESS_LOCAL, 5373 bytes)
17/02/07 13:20:20,661 INFO TaskSetManager: Starting task 6.0 in stage 2.0 (TID 68, 10.1.2.211, partition 6, PROCESS_LOCAL, 5373 bytes)
17/02/07 13:20:20,662 INFO TaskSetManager: Starting task 5.0 in stage 2.0 (TID 69, 10.1.2.130, partition 5, PROCESS_LOCAL, 5373 bytes)
17/02/07 13:20:20,663 INFO TaskSetManager: Starting task 3.0 in stage 2.0 (TID 70, 10.1.2.214, partition 3, PROCESS_LOCAL, 5373 bytes)
17/02/07 13:20:20,664 INFO TaskSetManager: Starting task 2.0 in stage 2.0 (TID 71, 10.1.2.41, partition 2, PROCESS_LOCAL, 5373 bytes)
17/02/07 13:20:20,665 INFO TaskSetManager: Starting task 7.0 in stage 2.0 (TID 72, 10.1.2.243, partition 7, PROCESS_LOCAL, 5373 bytes)
17/02/07 13:20:20,666 INFO TaskSetManager: Starting task 1.0 in stage 2.0 (TID 73, 10.1.2.148, partition 1, PROCESS_LOCAL, 5373 bytes)
17/02/07 13:20:20,667 INFO TaskSetManager: Starting task 22.0 in stage 2.0 (TID 74, 10.1.2.215, partition 22, PROCESS_LOCAL, 5373 bytes)
17/02/07 13:20:20,668 INFO TaskSetManager: Starting task 0.0 in stage 2.0 (TID 75, 10.1.2.47, partition 0, PROCESS_LOCAL, 5373 bytes)
17/02/07 13:20:20,669 INFO TaskSetManager: Starting task 11.0 in stage 2.0 (TID 76, 10.1.2.133, partition 11, PROCESS_LOCAL, 5373 bytes)
17/02/07 13:20:20,670 INFO TaskSetManager: Starting task 21.0 in stage 2.0 (TID 77, 10.1.2.172, partition 21, PROCESS_LOCAL, 5373 bytes)
17/02/07 13:20:20,671 INFO TaskSetManager: Starting task 8.0 in stage 2.0 (TID 78, 10.1.2.106, partition 8, PROCESS_LOCAL, 5373 bytes)
17/02/07 13:20:20,673 INFO TaskSetManager: Starting task 16.0 in stage 2.0 (TID 79, 10.1.2.165, partition 16, PROCESS_LOCAL, 5373 bytes)
17/02/07 13:20:20,674 INFO TaskSetManager: Starting task 12.0 in stage 2.0 (TID 80, 10.1.2.29, partition 12, PROCESS_LOCAL, 5373 bytes)
17/02/07 13:20:20,675 INFO TaskSetManager: Starting task 32.0 in stage 2.0 (TID 81, 10.1.2.245, partition 32, PROCESS_LOCAL, 5373 bytes)
17/02/07 13:20:20,676 INFO TaskSetManager: Starting task 26.0 in stage 2.0 (TID 82, 10.1.2.83, partition 26, PROCESS_LOCAL, 5373 bytes)
17/02/07 13:20:20,677 INFO TaskSetManager: Starting task 14.0 in stage 2.0 (TID 83, 10.1.2.224, partition 14, PROCESS_LOCAL, 5373 bytes)
17/02/07 13:20:20,678 INFO TaskSetManager: Starting task 15.0 in stage 2.0 (TID 84, 10.1.2.211, partition 15, PROCESS_LOCAL, 5373 bytes)
17/02/07 13:20:20,679 INFO TaskSetManager: Starting task 17.0 in stage 2.0 (TID 85, 10.1.2.130, partition 17, PROCESS_LOCAL, 5373 bytes)
17/02/07 13:20:20,680 INFO TaskSetManager: Starting task 19.0 in stage 2.0 (TID 86, 10.1.2.214, partition 19, PROCESS_LOCAL, 5373 bytes)
17/02/07 13:20:20,681 INFO TaskSetManager: Starting task 10.0 in stage 2.0 (TID 87, 10.1.2.41, partition 10, PROCESS_LOCAL, 5373 bytes)
17/02/07 13:20:20,682 INFO TaskSetManager: Starting task 24.0 in stage 2.0 (TID 88, 10.1.2.243, partition 24, PROCESS_LOCAL, 5373 bytes)
17/02/07 13:20:20,683 INFO TaskSetManager: Starting task 23.0 in stage 2.0 (TID 89, 10.1.2.148, partition 23, PROCESS_LOCAL, 5373 bytes)
17/02/07 13:20:20,684 INFO TaskSetManager: Starting task 41.0 in stage 2.0 (TID 90, 10.1.2.215, partition 41, PROCESS_LOCAL, 5373 bytes)
17/02/07 13:20:20,685 INFO TaskSetManager: Starting task 18.0 in stage 2.0 (TID 91, 10.1.2.47, partition 18, PROCESS_LOCAL, 5373 bytes)
17/02/07 13:20:20,686 INFO TaskSetManager: Starting task 20.0 in stage 2.0 (TID 92, 10.1.2.133, partition 20, PROCESS_LOCAL, 5373 bytes)
17/02/07 13:20:20,687 INFO TaskSetManager: Starting task 43.0 in stage 2.0 (TID 93, 10.1.2.172, partition 43, PROCESS_LOCAL, 5373 bytes)
17/02/07 13:20:20,688 INFO TaskSetManager: Starting task 27.0 in stage 2.0 (TID 94, 10.1.2.106, partition 27, PROCESS_LOCAL, 5373 bytes)
17/02/07 13:20:20,689 INFO TaskSetManager: Starting task 39.0 in stage 2.0 (TID 95, 10.1.2.165, partition 39, PROCESS_LOCAL, 5373 bytes)
17/02/07 13:20:20,690 INFO TaskSetManager: Starting task 35.0 in stage 2.0 (TID 96, 10.1.2.29, partition 35, PROCESS_LOCAL, 5373 bytes)
17/02/07 13:20:20,691 INFO TaskSetManager: Starting task 49.0 in stage 2.0 (TID 97, 10.1.2.245, partition 49, PROCESS_LOCAL, 5373 bytes)
17/02/07 13:20:20,692 INFO TaskSetManager: Starting task 47.0 in stage 2.0 (TID 98, 10.1.2.83, partition 47, PROCESS_LOCAL, 5373 bytes)
17/02/07 13:20:20,693 INFO TaskSetManager: Starting task 36.0 in stage 2.0 (TID 99, 10.1.2.224, partition 36, PROCESS_LOCAL, 5373 bytes)
17/02/07 13:20:20,694 INFO TaskSetManager: Starting task 37.0 in stage 2.0 (TID 100, 10.1.2.211, partition 37, PROCESS_LOCAL, 5373 bytes)
17/02/07 13:20:20,694 INFO TaskSetManager: Starting task 28.0 in stage 2.0 (TID 101, 10.1.2.130, partition 28, PROCESS_LOCAL, 5373 bytes)
17/02/07 13:20:20,695 INFO TaskSetManager: Starting task 42.0 in stage 2.0 (TID 102, 10.1.2.214, partition 42, PROCESS_LOCAL, 5373 bytes)
17/02/07 13:20:20,696 INFO TaskSetManager: Starting task 25.0 in stage 2.0 (TID 103, 10.1.2.41, partition 25, PROCESS_LOCAL, 5373 bytes)
17/02/07 13:20:20,696 INFO TaskSetManager: Starting task 29.0 in stage 2.0 (TID 104, 10.1.2.243, partition 29, PROCESS_LOCAL, 5373 bytes)
17/02/07 13:20:20,697 INFO TaskSetManager: Starting task 38.0 in stage 2.0 (TID 105, 10.1.2.148, partition 38, PROCESS_LOCAL, 5373 bytes)
17/02/07 13:20:20,698 INFO TaskSetManager: Starting task 44.0 in stage 2.0 (TID 106, 10.1.2.215, partition 44, PROCESS_LOCAL, 5373 bytes)
17/02/07 13:20:20,698 INFO TaskSetManager: Starting task 40.0 in stage 2.0 (TID 107, 10.1.2.47, partition 40, PROCESS_LOCAL, 5373 bytes)
17/02/07 13:20:20,699 INFO TaskSetManager: Starting task 33.0 in stage 2.0 (TID 108, 10.1.2.133, partition 33, PROCESS_LOCAL, 5373 bytes)
17/02/07 13:20:20,700 INFO TaskSetManager: Starting task 57.0 in stage 2.0 (TID 109, 10.1.2.172, partition 57, PROCESS_LOCAL, 5373 bytes)
17/02/07 13:20:20,700 INFO TaskSetManager: Starting task 30.0 in stage 2.0 (TID 110, 10.1.2.106, partition 30, PROCESS_LOCAL, 5373 bytes)
17/02/07 13:20:20,701 INFO TaskSetManager: Starting task 54.0 in stage 2.0 (TID 111, 10.1.2.165, partition 54, PROCESS_LOCAL, 5373 bytes)
17/02/07 13:20:20,701 INFO TaskSetManager: Starting task 50.0 in stage 2.0 (TID 112, 10.1.2.29, partition 50, PROCESS_LOCAL, 5373 bytes)
17/02/07 13:20:20,702 INFO TaskSetManager: Starting task 59.0 in stage 2.0 (TID 113, 10.1.2.245, partition 59, PROCESS_LOCAL, 5373 bytes)
17/02/07 13:20:20,702 INFO TaskSetManager: Starting task 60.0 in stage 2.0 (TID 114, 10.1.2.83, partition 60, PROCESS_LOCAL, 5373 bytes)
17/02/07 13:20:20,703 INFO TaskSetManager: Starting task 51.0 in stage 2.0 (TID 115, 10.1.2.224, partition 51, PROCESS_LOCAL, 5373 bytes)
17/02/07 13:20:20,704 INFO TaskSetManager: Starting task 53.0 in stage 2.0 (TID 116, 10.1.2.211, partition 53, PROCESS_LOCAL, 5373 bytes)
17/02/07 13:20:20,704 INFO TaskSetManager: Starting task 55.0 in stage 2.0 (TID 117, 10.1.2.130, partition 55, PROCESS_LOCAL, 5373 bytes)
17/02/07 13:20:20,705 INFO TaskSetManager: Starting task 45.0 in stage 2.0 (TID 118, 10.1.2.214, partition 45, PROCESS_LOCAL, 5373 bytes)
17/02/07 13:20:20,705 INFO TaskSetManager: Starting task 48.0 in stage 2.0 (TID 119, 10.1.2.41, partition 48, PROCESS_LOCAL, 5373 bytes)
17/02/07 13:20:20,706 INFO TaskSetManager: Starting task 31.0 in stage 2.0 (TID 120, 10.1.2.243, partition 31, PROCESS_LOCAL, 5373 bytes)
17/02/07 13:20:20,707 INFO TaskSetManager: Starting task 46.0 in stage 2.0 (TID 121, 10.1.2.148, partition 46, PROCESS_LOCAL, 5373 bytes)
17/02/07 13:20:20,707 INFO TaskSetManager: Starting task 58.0 in stage 2.0 (TID 122, 10.1.2.215, partition 58, PROCESS_LOCAL, 5373 bytes)
17/02/07 13:20:20,708 INFO TaskSetManager: Starting task 56.0 in stage 2.0 (TID 123, 10.1.2.47, partition 56, PROCESS_LOCAL, 5373 bytes)
17/02/07 13:20:20,709 INFO TaskSetManager: Starting task 62.0 in stage 2.0 (TID 124, 10.1.2.133, partition 62, PROCESS_LOCAL, 5373 bytes)
17/02/07 13:20:20,709 INFO TaskSetManager: Starting task 34.0 in stage 2.0 (TID 125, 10.1.2.106, partition 34, PROCESS_LOCAL, 5373 bytes)
17/02/07 13:20:20,710 INFO TaskSetManager: Starting task 61.0 in stage 2.0 (TID 126, 10.1.2.165, partition 61, PROCESS_LOCAL, 5373 bytes)
17/02/07 13:20:20,710 INFO TaskSetManager: Starting task 52.0 in stage 2.0 (TID 127, 10.1.2.29, partition 52, PROCESS_LOCAL, 5373 bytes)
17/02/07 13:20:20,711 INFO CoarseGrainedSchedulerBackend$DriverEndpoint: Launching task 65 on executor id: 10 hostname: 10.1.2.245.
17/02/07 13:20:20,711 INFO CoarseGrainedSchedulerBackend$DriverEndpoint: Launching task 81 on executor id: 10 hostname: 10.1.2.245.
17/02/07 13:20:20,712 INFO CoarseGrainedSchedulerBackend$DriverEndpoint: Launching task 97 on executor id: 10 hostname: 10.1.2.245.
17/02/07 13:20:20,712 INFO CoarseGrainedSchedulerBackend$DriverEndpoint: Launching task 113 on executor id: 10 hostname: 10.1.2.245.
17/02/07 13:20:20,713 INFO CoarseGrainedSchedulerBackend$DriverEndpoint: Launching task 66 on executor id: 4 hostname: 10.1.2.83.
17/02/07 13:20:20,713 INFO CoarseGrainedSchedulerBackend$DriverEndpoint: Launching task 82 on executor id: 4 hostname: 10.1.2.83.
17/02/07 13:20:20,714 INFO CoarseGrainedSchedulerBackend$DriverEndpoint: Launching task 98 on executor id: 4 hostname: 10.1.2.83.
17/02/07 13:20:20,714 INFO CoarseGrainedSchedulerBackend$DriverEndpoint: Launching task 114 on executor id: 4 hostname: 10.1.2.83.
17/02/07 13:20:20,715 INFO CoarseGrainedSchedulerBackend$DriverEndpoint: Launching task 67 on executor id: 11 hostname: 10.1.2.224.
17/02/07 13:20:20,715 INFO CoarseGrainedSchedulerBackend$DriverEndpoint: Launching task 83 on executor id: 11 hostname: 10.1.2.224.
17/02/07 13:20:20,717 INFO CoarseGrainedSchedulerBackend$DriverEndpoint: Launching task 99 on executor id: 11 hostname: 10.1.2.224.
17/02/07 13:20:20,717 INFO CoarseGrainedSchedulerBackend$DriverEndpoint: Launching task 115 on executor id: 11 hostname: 10.1.2.224.
17/02/07 13:20:20,719 INFO CoarseGrainedSchedulerBackend$DriverEndpoint: Launching task 68 on executor id: 14 hostname: 10.1.2.211.
17/02/07 13:20:20,721 INFO CoarseGrainedSchedulerBackend$DriverEndpoint: Launching task 84 on executor id: 14 hostname: 10.1.2.211.
17/02/07 13:20:20,721 INFO CoarseGrainedSchedulerBackend$DriverEndpoint: Launching task 100 on executor id: 14 hostname: 10.1.2.211.
17/02/07 13:20:20,721 INFO CoarseGrainedSchedulerBackend$DriverEndpoint: Launching task 116 on executor id: 14 hostname: 10.1.2.211.
17/02/07 13:20:20,722 INFO CoarseGrainedSchedulerBackend$DriverEndpoint: Launching task 69 on executor id: 9 hostname: 10.1.2.130.
17/02/07 13:20:20,722 INFO CoarseGrainedSchedulerBackend$DriverEndpoint: Launching task 85 on executor id: 9 hostname: 10.1.2.130.
17/02/07 13:20:20,722 INFO CoarseGrainedSchedulerBackend$DriverEndpoint: Launching task 101 on executor id: 9 hostname: 10.1.2.130.
17/02/07 13:20:20,722 INFO CoarseGrainedSchedulerBackend$DriverEndpoint: Launching task 117 on executor id: 9 hostname: 10.1.2.130.
17/02/07 13:20:20,723 INFO CoarseGrainedSchedulerBackend$DriverEndpoint: Launching task 70 on executor id: 8 hostname: 10.1.2.214.
17/02/07 13:20:20,723 INFO CoarseGrainedSchedulerBackend$DriverEndpoint: Launching task 86 on executor id: 8 hostname: 10.1.2.214.
17/02/07 13:20:20,723 INFO CoarseGrainedSchedulerBackend$DriverEndpoint: Launching task 102 on executor id: 8 hostname: 10.1.2.214.
17/02/07 13:20:20,724 INFO CoarseGrainedSchedulerBackend$DriverEndpoint: Launching task 118 on executor id: 8 hostname: 10.1.2.214.
17/02/07 13:20:20,724 INFO CoarseGrainedSchedulerBackend$DriverEndpoint: Launching task 71 on executor id: 6 hostname: 10.1.2.41.
17/02/07 13:20:20,725 INFO CoarseGrainedSchedulerBackend$DriverEndpoint: Launching task 87 on executor id: 6 hostname: 10.1.2.41.
17/02/07 13:20:20,726 INFO CoarseGrainedSchedulerBackend$DriverEndpoint: Launching task 103 on executor id: 6 hostname: 10.1.2.41.
17/02/07 13:20:20,727 INFO CoarseGrainedSchedulerBackend$DriverEndpoint: Launching task 119 on executor id: 6 hostname: 10.1.2.41.
17/02/07 13:20:20,727 INFO CoarseGrainedSchedulerBackend$DriverEndpoint: Launching task 72 on executor id: 1 hostname: 10.1.2.243.
17/02/07 13:20:20,728 INFO CoarseGrainedSchedulerBackend$DriverEndpoint: Launching task 88 on executor id: 1 hostname: 10.1.2.243.
17/02/07 13:20:20,729 INFO CoarseGrainedSchedulerBackend$DriverEndpoint: Launching task 104 on executor id: 1 hostname: 10.1.2.243.
17/02/07 13:20:20,729 INFO CoarseGrainedSchedulerBackend$DriverEndpoint: Launching task 120 on executor id: 1 hostname: 10.1.2.243.
17/02/07 13:20:20,730 INFO CoarseGrainedSchedulerBackend$DriverEndpoint: Launching task 73 on executor id: 12 hostname: 10.1.2.148.
17/02/07 13:20:20,732 INFO CoarseGrainedSchedulerBackend$DriverEndpoint: Launching task 89 on executor id: 12 hostname: 10.1.2.148.
17/02/07 13:20:20,732 INFO CoarseGrainedSchedulerBackend$DriverEndpoint: Launching task 105 on executor id: 12 hostname: 10.1.2.148.
17/02/07 13:20:20,733 INFO CoarseGrainedSchedulerBackend$DriverEndpoint: Launching task 121 on executor id: 12 hostname: 10.1.2.148.
17/02/07 13:20:20,734 INFO CoarseGrainedSchedulerBackend$DriverEndpoint: Launching task 74 on executor id: 3 hostname: 10.1.2.215.
17/02/07 13:20:20,734 INFO CoarseGrainedSchedulerBackend$DriverEndpoint: Launching task 90 on executor id: 3 hostname: 10.1.2.215.
17/02/07 13:20:20,735 INFO CoarseGrainedSchedulerBackend$DriverEndpoint: Launching task 106 on executor id: 3 hostname: 10.1.2.215.
17/02/07 13:20:20,735 INFO CoarseGrainedSchedulerBackend$DriverEndpoint: Launching task 122 on executor id: 3 hostname: 10.1.2.215.
17/02/07 13:20:20,735 INFO CoarseGrainedSchedulerBackend$DriverEndpoint: Launching task 75 on executor id: 13 hostname: 10.1.2.47.
17/02/07 13:20:20,736 INFO CoarseGrainedSchedulerBackend$DriverEndpoint: Launching task 91 on executor id: 13 hostname: 10.1.2.47.
17/02/07 13:20:20,736 INFO CoarseGrainedSchedulerBackend$DriverEndpoint: Launching task 107 on executor id: 13 hostname: 10.1.2.47.
17/02/07 13:20:20,737 INFO CoarseGrainedSchedulerBackend$DriverEndpoint: Launching task 123 on executor id: 13 hostname: 10.1.2.47.
17/02/07 13:20:20,737 INFO CoarseGrainedSchedulerBackend$DriverEndpoint: Launching task 76 on executor id: 7 hostname: 10.1.2.133.
17/02/07 13:20:20,737 INFO CoarseGrainedSchedulerBackend$DriverEndpoint: Launching task 92 on executor id: 7 hostname: 10.1.2.133.
17/02/07 13:20:20,738 INFO CoarseGrainedSchedulerBackend$DriverEndpoint: Launching task 108 on executor id: 7 hostname: 10.1.2.133.
17/02/07 13:20:20,739 INFO BlockManagerInfo: Added broadcast_3_piece0 in memory on 10.1.2.83:39232 (size: 2.2 KB, free: 6.2 GB)
17/02/07 13:20:20,739 INFO CoarseGrainedSchedulerBackend$DriverEndpoint: Launching task 124 on executor id: 7 hostname: 10.1.2.133.
17/02/07 13:20:20,740 INFO BlockManagerInfo: Added broadcast_3_piece0 in memory on 10.1.2.245:36419 (size: 2.2 KB, free: 6.2 GB)
17/02/07 13:20:20,740 INFO CoarseGrainedSchedulerBackend$DriverEndpoint: Launching task 77 on executor id: 5 hostname: 10.1.2.172.
17/02/07 13:20:20,741 INFO CoarseGrainedSchedulerBackend$DriverEndpoint: Launching task 93 on executor id: 5 hostname: 10.1.2.172.
17/02/07 13:20:20,741 INFO CoarseGrainedSchedulerBackend$DriverEndpoint: Launching task 109 on executor id: 5 hostname: 10.1.2.172.
17/02/07 13:20:20,742 INFO CoarseGrainedSchedulerBackend$DriverEndpoint: Launching task 78 on executor id: 15 hostname: 10.1.2.106.
17/02/07 13:20:20,743 INFO CoarseGrainedSchedulerBackend$DriverEndpoint: Launching task 94 on executor id: 15 hostname: 10.1.2.106.
17/02/07 13:20:20,743 INFO BlockManagerInfo: Added broadcast_3_piece0 in memory on 10.1.2.224:44733 (size: 2.2 KB, free: 6.2 GB)
17/02/07 13:20:20,744 INFO CoarseGrainedSchedulerBackend$DriverEndpoint: Launching task 110 on executor id: 15 hostname: 10.1.2.106.
17/02/07 13:20:20,745 INFO CoarseGrainedSchedulerBackend$DriverEndpoint: Launching task 125 on executor id: 15 hostname: 10.1.2.106.
17/02/07 13:20:20,746 INFO CoarseGrainedSchedulerBackend$DriverEndpoint: Launching task 79 on executor id: 2 hostname: 10.1.2.165.
17/02/07 13:20:20,746 INFO CoarseGrainedSchedulerBackend$DriverEndpoint: Launching task 95 on executor id: 2 hostname: 10.1.2.165.
17/02/07 13:20:20,747 INFO CoarseGrainedSchedulerBackend$DriverEndpoint: Launching task 111 on executor id: 2 hostname: 10.1.2.165.
17/02/07 13:20:20,747 INFO CoarseGrainedSchedulerBackend$DriverEndpoint: Launching task 126 on executor id: 2 hostname: 10.1.2.165.
17/02/07 13:20:20,747 INFO CoarseGrainedSchedulerBackend$DriverEndpoint: Launching task 80 on executor id: 0 hostname: 10.1.2.29.
17/02/07 13:20:20,748 INFO CoarseGrainedSchedulerBackend$DriverEndpoint: Launching task 96 on executor id: 0 hostname: 10.1.2.29.
17/02/07 13:20:20,748 INFO CoarseGrainedSchedulerBackend$DriverEndpoint: Launching task 112 on executor id: 0 hostname: 10.1.2.29.
17/02/07 13:20:20,750 INFO CoarseGrainedSchedulerBackend$DriverEndpoint: Launching task 127 on executor id: 0 hostname: 10.1.2.29.
17/02/07 13:20:20,766 INFO BlockManagerInfo: Added broadcast_3_piece0 in memory on 10.1.2.211:35284 (size: 2.2 KB, free: 6.2 GB)
17/02/07 13:20:20,768 INFO BlockManagerInfo: Added broadcast_3_piece0 in memory on 10.1.2.133:45449 (size: 2.2 KB, free: 6.2 GB)
17/02/07 13:20:20,783 INFO TaskSetManager: Finished task 26.0 in stage 2.0 (TID 82) in 108 ms on 10.1.2.83 (1/64)
17/02/07 13:20:20,789 INFO TaskSetManager: Finished task 9.0 in stage 2.0 (TID 65) in 133 ms on 10.1.2.245 (2/64)
17/02/07 13:20:20,801 INFO TaskSetManager: Finished task 4.0 in stage 2.0 (TID 66) in 142 ms on 10.1.2.83 (3/64)
17/02/07 13:20:20,801 INFO BlockManagerInfo: Added broadcast_3_piece0 in memory on 10.1.2.47:40115 (size: 2.2 KB, free: 6.2 GB)
17/02/07 13:20:20,802 INFO TaskSetManager: Finished task 47.0 in stage 2.0 (TID 98) in 111 ms on 10.1.2.83 (4/64)
17/02/07 13:20:20,805 INFO TaskSetManager: Finished task 60.0 in stage 2.0 (TID 114) in 103 ms on 10.1.2.83 (5/64)
17/02/07 13:20:20,808 INFO TaskSetManager: Finished task 13.0 in stage 2.0 (TID 67) in 149 ms on 10.1.2.224 (6/64)
17/02/07 13:20:20,808 INFO BlockManagerInfo: Added broadcast_3_piece0 in memory on 10.1.2.29:45224 (size: 2.2 KB, free: 6.2 GB)
17/02/07 13:20:20,810 INFO TaskSetManager: Finished task 36.0 in stage 2.0 (TID 99) in 117 ms on 10.1.2.224 (7/64)
17/02/07 13:20:20,820 INFO BlockManagerInfo: Added broadcast_3_piece0 in memory on 10.1.2.215:41257 (size: 2.2 KB, free: 6.2 GB)
17/02/07 13:20:20,821 INFO BlockManagerInfo: Added broadcast_3_piece0 in memory on 10.1.2.214:44655 (size: 2.2 KB, free: 6.2 GB)
17/02/07 13:20:20,827 INFO BlockManagerInfo: Added broadcast_3_piece0 in memory on 10.1.2.148:41000 (size: 2.2 KB, free: 6.2 GB)
17/02/07 13:20:20,828 INFO BlockManagerInfo: Added broadcast_3_piece0 in memory on 10.1.2.165:41549 (size: 2.2 KB, free: 6.2 GB)
17/02/07 13:20:20,829 INFO BlockManagerInfo: Added broadcast_3_piece0 in memory on 10.1.2.106:38042 (size: 2.2 KB, free: 6.2 GB)
17/02/07 13:20:20,830 INFO BlockManagerInfo: Added broadcast_3_piece0 in memory on 10.1.2.243:33377 (size: 2.2 KB, free: 6.2 GB)
17/02/07 13:20:20,831 INFO TaskSetManager: Finished task 53.0 in stage 2.0 (TID 116) in 128 ms on 10.1.2.211 (8/64)
17/02/07 13:20:20,832 INFO BlockManagerInfo: Added broadcast_3_piece0 in memory on 10.1.2.41:46050 (size: 2.2 KB, free: 6.2 GB)
17/02/07 13:20:20,833 INFO TaskSetManager: Finished task 37.0 in stage 2.0 (TID 100) in 140 ms on 10.1.2.211 (9/64)
17/02/07 13:20:20,834 INFO BlockManagerInfo: Added broadcast_3_piece0 in memory on 10.1.2.130:36104 (size: 2.2 KB, free: 6.2 GB)
17/02/07 13:20:20,834 INFO TaskSetManager: Starting task 63.0 in stage 2.0 (TID 128, 10.1.2.47, partition 63, PROCESS_LOCAL, 5373 bytes)
17/02/07 13:20:20,834 INFO CoarseGrainedSchedulerBackend$DriverEndpoint: Launching task 128 on executor id: 13 hostname: 10.1.2.47.
17/02/07 13:20:20,835 INFO TaskSetManager: Finished task 0.0 in stage 2.0 (TID 75) in 168 ms on 10.1.2.47 (10/64)
17/02/07 13:20:20,836 INFO TaskSetManager: Finished task 18.0 in stage 2.0 (TID 91) in 152 ms on 10.1.2.47 (11/64)
17/02/07 13:20:20,837 INFO TaskSetManager: Finished task 40.0 in stage 2.0 (TID 107) in 139 ms on 10.1.2.47 (12/64)
17/02/07 13:20:20,838 INFO BlockManagerInfo: Added broadcast_3_piece0 in memory on 10.1.2.172:37669 (size: 2.2 KB, free: 6.2 GB)
17/02/07 13:20:20,838 INFO TaskSetManager: Finished task 6.0 in stage 2.0 (TID 68) in 178 ms on 10.1.2.211 (13/64)
17/02/07 13:20:20,839 INFO TaskSetManager: Finished task 56.0 in stage 2.0 (TID 123) in 132 ms on 10.1.2.47 (14/64)
17/02/07 13:20:20,840 INFO TaskSetManager: Finished task 33.0 in stage 2.0 (TID 108) in 141 ms on 10.1.2.133 (15/64)
17/02/07 13:20:20,841 INFO TaskSetManager: Finished task 62.0 in stage 2.0 (TID 124) in 132 ms on 10.1.2.133 (16/64)
17/02/07 13:20:20,842 INFO TaskSetManager: Finished task 11.0 in stage 2.0 (TID 76) in 173 ms on 10.1.2.133 (17/64)
17/02/07 13:20:20,843 INFO TaskSetManager: Finished task 51.0 in stage 2.0 (TID 115) in 140 ms on 10.1.2.224 (18/64)
17/02/07 13:20:20,843 INFO TaskSetManager: Finished task 20.0 in stage 2.0 (TID 92) in 158 ms on 10.1.2.133 (19/64)
17/02/07 13:20:20,844 INFO TaskSetManager: Finished task 15.0 in stage 2.0 (TID 84) in 167 ms on 10.1.2.211 (20/64)
17/02/07 13:20:20,856 INFO TaskSetManager: Finished task 52.0 in stage 2.0 (TID 127) in 145 ms on 10.1.2.29 (21/64)
17/02/07 13:20:20,857 INFO TaskSetManager: Finished task 63.0 in stage 2.0 (TID 128) in 23 ms on 10.1.2.47 (22/64)
17/02/07 13:20:20,859 INFO TaskSetManager: Finished task 14.0 in stage 2.0 (TID 83) in 183 ms on 10.1.2.224 (23/64)
17/02/07 13:20:20,866 INFO TaskSetManager: Finished task 49.0 in stage 2.0 (TID 97) in 176 ms on 10.1.2.245 (24/64)
17/02/07 13:20:20,868 INFO TaskSetManager: Finished task 41.0 in stage 2.0 (TID 90) in 185 ms on 10.1.2.215 (25/64)
17/02/07 13:20:20,869 INFO TaskSetManager: Finished task 50.0 in stage 2.0 (TID 112) in 168 ms on 10.1.2.29 (26/64)
17/02/07 13:20:20,870 INFO TaskSetManager: Finished task 24.0 in stage 2.0 (TID 88) in 189 ms on 10.1.2.243 (27/64)
17/02/07 13:20:20,872 INFO TaskSetManager: Finished task 54.0 in stage 2.0 (TID 111) in 172 ms on 10.1.2.165 (28/64)
17/02/07 13:20:20,873 INFO TaskSetManager: Finished task 31.0 in stage 2.0 (TID 120) in 167 ms on 10.1.2.243 (29/64)
17/02/07 13:20:20,875 INFO TaskSetManager: Finished task 5.0 in stage 2.0 (TID 69) in 213 ms on 10.1.2.130 (30/64)
17/02/07 13:20:20,875 INFO TaskSetManager: Finished task 16.0 in stage 2.0 (TID 79) in 203 ms on 10.1.2.165 (31/64)
17/02/07 13:20:20,877 INFO TaskSetManager: Finished task 42.0 in stage 2.0 (TID 102) in 182 ms on 10.1.2.214 (32/64)
17/02/07 13:20:20,878 INFO TaskSetManager: Finished task 58.0 in stage 2.0 (TID 122) in 171 ms on 10.1.2.215 (33/64)
17/02/07 13:20:20,879 INFO TaskSetManager: Finished task 3.0 in stage 2.0 (TID 70) in 217 ms on 10.1.2.214 (34/64)
17/02/07 13:20:20,880 INFO TaskSetManager: Finished task 55.0 in stage 2.0 (TID 117) in 175 ms on 10.1.2.130 (35/64)
17/02/07 13:20:20,881 INFO TaskSetManager: Finished task 39.0 in stage 2.0 (TID 95) in 193 ms on 10.1.2.165 (36/64)
17/02/07 13:20:20,882 INFO TaskSetManager: Finished task 28.0 in stage 2.0 (TID 101) in 188 ms on 10.1.2.130 (37/64)
17/02/07 13:20:20,884 INFO TaskSetManager: Finished task 45.0 in stage 2.0 (TID 118) in 180 ms on 10.1.2.214 (38/64)
17/02/07 13:20:20,885 INFO TaskSetManager: Finished task 61.0 in stage 2.0 (TID 126) in 176 ms on 10.1.2.165 (39/64)
17/02/07 13:20:20,887 INFO TaskSetManager: Finished task 8.0 in stage 2.0 (TID 78) in 216 ms on 10.1.2.106 (40/64)
17/02/07 13:20:20,887 INFO TaskSetManager: Finished task 22.0 in stage 2.0 (TID 74) in 221 ms on 10.1.2.215 (41/64)
17/02/07 13:20:20,888 INFO TaskSetManager: Finished task 19.0 in stage 2.0 (TID 86) in 209 ms on 10.1.2.214 (42/64)
17/02/07 13:20:20,890 INFO TaskSetManager: Finished task 34.0 in stage 2.0 (TID 125) in 181 ms on 10.1.2.106 (43/64)
17/02/07 13:20:20,890 INFO TaskSetManager: Finished task 44.0 in stage 2.0 (TID 106) in 193 ms on 10.1.2.215 (44/64)
17/02/07 13:20:20,893 INFO TaskSetManager: Finished task 21.0 in stage 2.0 (TID 77) in 223 ms on 10.1.2.172 (45/64)
17/02/07 13:20:20,894 INFO TaskSetManager: Finished task 43.0 in stage 2.0 (TID 93) in 208 ms on 10.1.2.172 (46/64)
17/02/07 13:20:20,895 INFO TaskSetManager: Finished task 23.0 in stage 2.0 (TID 89) in 212 ms on 10.1.2.148 (47/64)
17/02/07 13:20:20,895 INFO TaskSetManager: Finished task 57.0 in stage 2.0 (TID 109) in 196 ms on 10.1.2.172 (48/64)
17/02/07 13:20:20,895 INFO TaskSetManager: Finished task 46.0 in stage 2.0 (TID 121) in 189 ms on 10.1.2.148 (49/64)
17/02/07 13:20:20,896 INFO TaskSetManager: Finished task 29.0 in stage 2.0 (TID 104) in 199 ms on 10.1.2.243 (50/64)
17/02/07 13:20:20,896 INFO TaskSetManager: Finished task 27.0 in stage 2.0 (TID 94) in 209 ms on 10.1.2.106 (51/64)
17/02/07 13:20:20,897 INFO TaskSetManager: Finished task 17.0 in stage 2.0 (TID 85) in 219 ms on 10.1.2.130 (52/64)
17/02/07 13:20:20,899 INFO TaskSetManager: Finished task 30.0 in stage 2.0 (TID 110) in 199 ms on 10.1.2.106 (53/64)
17/02/07 13:20:20,906 INFO TaskSetManager: Finished task 10.0 in stage 2.0 (TID 87) in 225 ms on 10.1.2.41 (54/64)
17/02/07 13:20:20,907 INFO TaskSetManager: Finished task 2.0 in stage 2.0 (TID 71) in 244 ms on 10.1.2.41 (55/64)
17/02/07 13:20:20,908 INFO TaskSetManager: Finished task 35.0 in stage 2.0 (TID 96) in 219 ms on 10.1.2.29 (56/64)
17/02/07 13:20:20,923 INFO TaskSetManager: Finished task 32.0 in stage 2.0 (TID 81) in 249 ms on 10.1.2.245 (57/64)
17/02/07 13:20:20,935 INFO TaskSetManager: Finished task 59.0 in stage 2.0 (TID 113) in 234 ms on 10.1.2.245 (58/64)
17/02/07 13:20:20,940 INFO TaskSetManager: Finished task 38.0 in stage 2.0 (TID 105) in 243 ms on 10.1.2.148 (59/64)
17/02/07 13:20:20,968 INFO TaskSetManager: Finished task 7.0 in stage 2.0 (TID 72) in 304 ms on 10.1.2.243 (60/64)
17/02/07 13:20:20,971 INFO TaskSetManager: Finished task 12.0 in stage 2.0 (TID 80) in 298 ms on 10.1.2.29 (61/64)
17/02/07 13:20:20,975 INFO TaskSetManager: Finished task 1.0 in stage 2.0 (TID 73) in 310 ms on 10.1.2.148 (62/64)
17/02/07 13:20:20,979 INFO TaskSetManager: Finished task 25.0 in stage 2.0 (TID 103) in 284 ms on 10.1.2.41 (63/64)
17/02/07 13:20:20,992 INFO TaskSetManager: Finished task 48.0 in stage 2.0 (TID 119) in 287 ms on 10.1.2.41 (64/64)
17/02/07 13:20:20,992 INFO TaskSchedulerImpl: Removed TaskSet 2.0, whose tasks have all completed, from pool 
17/02/07 13:20:20,992 INFO DAGScheduler: ResultStage 2 (count at GradientDescent.scala:209) finished in 0.337 s
17/02/07 13:20:20,993 INFO DAGScheduler: Job 2 finished: count at GradientDescent.scala:209, took 0.356027 s
17/02/07 13:20:21,351 WARN BLAS: Failed to load implementation from: com.github.fommil.netlib.NativeSystemBLAS
17/02/07 13:20:21,351 WARN BLAS: Failed to load implementation from: com.github.fommil.netlib.NativeRefBLAS
17/02/07 13:20:21,381 INFO MemoryStore: Block broadcast_4 stored as values in memory (estimated size 200.0 B, free 6.3 GB)
17/02/07 13:20:21,385 INFO MemoryStore: Block broadcast_4_piece0 stored as bytes in memory (estimated size 153.0 B, free 6.3 GB)
17/02/07 13:20:21,386 INFO BlockManagerInfo: Added broadcast_4_piece0 in memory on 10.1.2.152:32967 (size: 153.0 B, free: 6.3 GB)
17/02/07 13:20:21,387 INFO SparkContext: Created broadcast 4 from broadcast at GradientDescent.scala:235
17/02/07 13:20:21,441 INFO SparkContext: Starting job: treeAggregate at GradientDescent.scala:239
17/02/07 13:20:21,447 INFO DAGScheduler: Registering RDD 11 (treeAggregate at GradientDescent.scala:239)
17/02/07 13:20:21,448 INFO DAGScheduler: Got job 3 (treeAggregate at GradientDescent.scala:239) with 8 output partitions
17/02/07 13:20:21,448 INFO DAGScheduler: Final stage: ResultStage 4 (treeAggregate at GradientDescent.scala:239)
17/02/07 13:20:21,448 INFO DAGScheduler: Parents of final stage: List(ShuffleMapStage 3)
17/02/07 13:20:21,449 INFO DAGScheduler: Missing parents: List(ShuffleMapStage 3)
17/02/07 13:20:21,452 INFO DAGScheduler: Submitting ShuffleMapStage 3 (MapPartitionsRDD[11] at treeAggregate at GradientDescent.scala:239), which has no missing parents
17/02/07 13:20:21,470 INFO MemoryStore: Block broadcast_5 stored as values in memory (estimated size 7.1 KB, free 6.3 GB)
17/02/07 13:20:21,472 INFO MemoryStore: Block broadcast_5_piece0 stored as bytes in memory (estimated size 3.7 KB, free 6.3 GB)
17/02/07 13:20:21,473 INFO BlockManagerInfo: Added broadcast_5_piece0 in memory on 10.1.2.152:32967 (size: 3.7 KB, free: 6.3 GB)
17/02/07 13:20:21,474 INFO SparkContext: Created broadcast 5 from broadcast at DAGScheduler.scala:1012
17/02/07 13:20:21,476 INFO DAGScheduler: Submitting 64 missing tasks from ShuffleMapStage 3 (MapPartitionsRDD[11] at treeAggregate at GradientDescent.scala:239)
17/02/07 13:20:21,476 INFO TaskSchedulerImpl: Adding task set 3.0 with 64 tasks
17/02/07 13:20:21,481 INFO TaskSetManager: Starting task 3.0 in stage 3.0 (TID 129, 10.1.2.214, partition 3, PROCESS_LOCAL, 5562 bytes)
17/02/07 13:20:21,481 INFO TaskSetManager: Starting task 6.0 in stage 3.0 (TID 130, 10.1.2.211, partition 6, PROCESS_LOCAL, 5562 bytes)
17/02/07 13:20:21,482 INFO TaskSetManager: Starting task 9.0 in stage 3.0 (TID 131, 10.1.2.245, partition 9, PROCESS_LOCAL, 5562 bytes)
17/02/07 13:20:21,482 INFO TaskSetManager: Starting task 4.0 in stage 3.0 (TID 132, 10.1.2.83, partition 4, PROCESS_LOCAL, 5562 bytes)
17/02/07 13:20:21,483 INFO TaskSetManager: Starting task 2.0 in stage 3.0 (TID 133, 10.1.2.41, partition 2, PROCESS_LOCAL, 5562 bytes)
17/02/07 13:20:21,484 INFO TaskSetManager: Starting task 11.0 in stage 3.0 (TID 134, 10.1.2.133, partition 11, PROCESS_LOCAL, 5562 bytes)
17/02/07 13:20:21,484 INFO TaskSetManager: Starting task 21.0 in stage 3.0 (TID 135, 10.1.2.172, partition 21, PROCESS_LOCAL, 5562 bytes)
17/02/07 13:20:21,485 INFO TaskSetManager: Starting task 0.0 in stage 3.0 (TID 136, 10.1.2.47, partition 0, PROCESS_LOCAL, 5562 bytes)
17/02/07 13:20:21,486 INFO TaskSetManager: Starting task 8.0 in stage 3.0 (TID 137, 10.1.2.106, partition 8, PROCESS_LOCAL, 5562 bytes)
17/02/07 13:20:21,487 INFO TaskSetManager: Starting task 1.0 in stage 3.0 (TID 138, 10.1.2.148, partition 1, PROCESS_LOCAL, 5562 bytes)
17/02/07 13:20:21,487 INFO TaskSetManager: Starting task 12.0 in stage 3.0 (TID 139, 10.1.2.29, partition 12, PROCESS_LOCAL, 5562 bytes)
17/02/07 13:20:21,488 INFO TaskSetManager: Starting task 7.0 in stage 3.0 (TID 140, 10.1.2.243, partition 7, PROCESS_LOCAL, 5562 bytes)
17/02/07 13:20:21,489 INFO TaskSetManager: Starting task 5.0 in stage 3.0 (TID 141, 10.1.2.130, partition 5, PROCESS_LOCAL, 5562 bytes)
17/02/07 13:20:21,489 INFO TaskSetManager: Starting task 22.0 in stage 3.0 (TID 142, 10.1.2.215, partition 22, PROCESS_LOCAL, 5562 bytes)
17/02/07 13:20:21,490 INFO TaskSetManager: Starting task 16.0 in stage 3.0 (TID 143, 10.1.2.165, partition 16, PROCESS_LOCAL, 5562 bytes)
17/02/07 13:20:21,490 INFO TaskSetManager: Starting task 13.0 in stage 3.0 (TID 144, 10.1.2.224, partition 13, PROCESS_LOCAL, 5562 bytes)
17/02/07 13:20:21,491 INFO TaskSetManager: Starting task 19.0 in stage 3.0 (TID 145, 10.1.2.214, partition 19, PROCESS_LOCAL, 5562 bytes)
17/02/07 13:20:21,492 INFO TaskSetManager: Starting task 15.0 in stage 3.0 (TID 146, 10.1.2.211, partition 15, PROCESS_LOCAL, 5562 bytes)
17/02/07 13:20:21,492 INFO TaskSetManager: Starting task 32.0 in stage 3.0 (TID 147, 10.1.2.245, partition 32, PROCESS_LOCAL, 5562 bytes)
17/02/07 13:20:21,493 INFO TaskSetManager: Starting task 26.0 in stage 3.0 (TID 148, 10.1.2.83, partition 26, PROCESS_LOCAL, 5562 bytes)
17/02/07 13:20:21,493 INFO TaskSetManager: Starting task 10.0 in stage 3.0 (TID 149, 10.1.2.41, partition 10, PROCESS_LOCAL, 5562 bytes)
17/02/07 13:20:21,494 INFO TaskSetManager: Starting task 20.0 in stage 3.0 (TID 150, 10.1.2.133, partition 20, PROCESS_LOCAL, 5562 bytes)
17/02/07 13:20:21,494 INFO TaskSetManager: Starting task 43.0 in stage 3.0 (TID 151, 10.1.2.172, partition 43, PROCESS_LOCAL, 5562 bytes)
17/02/07 13:20:21,495 INFO TaskSetManager: Starting task 18.0 in stage 3.0 (TID 152, 10.1.2.47, partition 18, PROCESS_LOCAL, 5562 bytes)
17/02/07 13:20:21,496 INFO TaskSetManager: Starting task 27.0 in stage 3.0 (TID 153, 10.1.2.106, partition 27, PROCESS_LOCAL, 5562 bytes)
17/02/07 13:20:21,496 INFO TaskSetManager: Starting task 23.0 in stage 3.0 (TID 154, 10.1.2.148, partition 23, PROCESS_LOCAL, 5562 bytes)
17/02/07 13:20:21,497 INFO TaskSetManager: Starting task 35.0 in stage 3.0 (TID 155, 10.1.2.29, partition 35, PROCESS_LOCAL, 5562 bytes)
17/02/07 13:20:21,497 INFO TaskSetManager: Starting task 24.0 in stage 3.0 (TID 156, 10.1.2.243, partition 24, PROCESS_LOCAL, 5562 bytes)
17/02/07 13:20:21,498 INFO TaskSetManager: Starting task 17.0 in stage 3.0 (TID 157, 10.1.2.130, partition 17, PROCESS_LOCAL, 5562 bytes)
17/02/07 13:20:21,498 INFO TaskSetManager: Starting task 41.0 in stage 3.0 (TID 158, 10.1.2.215, partition 41, PROCESS_LOCAL, 5562 bytes)
17/02/07 13:20:21,499 INFO TaskSetManager: Starting task 39.0 in stage 3.0 (TID 159, 10.1.2.165, partition 39, PROCESS_LOCAL, 5562 bytes)
17/02/07 13:20:21,500 INFO TaskSetManager: Starting task 14.0 in stage 3.0 (TID 160, 10.1.2.224, partition 14, PROCESS_LOCAL, 5562 bytes)
17/02/07 13:20:21,500 INFO TaskSetManager: Starting task 42.0 in stage 3.0 (TID 161, 10.1.2.214, partition 42, PROCESS_LOCAL, 5562 bytes)
17/02/07 13:20:21,501 INFO TaskSetManager: Starting task 37.0 in stage 3.0 (TID 162, 10.1.2.211, partition 37, PROCESS_LOCAL, 5562 bytes)
17/02/07 13:20:21,501 INFO TaskSetManager: Starting task 49.0 in stage 3.0 (TID 163, 10.1.2.245, partition 49, PROCESS_LOCAL, 5562 bytes)
17/02/07 13:20:21,502 INFO TaskSetManager: Starting task 47.0 in stage 3.0 (TID 164, 10.1.2.83, partition 47, PROCESS_LOCAL, 5562 bytes)
17/02/07 13:20:21,503 INFO TaskSetManager: Starting task 25.0 in stage 3.0 (TID 165, 10.1.2.41, partition 25, PROCESS_LOCAL, 5562 bytes)
17/02/07 13:20:21,503 INFO TaskSetManager: Starting task 33.0 in stage 3.0 (TID 166, 10.1.2.133, partition 33, PROCESS_LOCAL, 5562 bytes)
17/02/07 13:20:21,504 INFO TaskSetManager: Starting task 57.0 in stage 3.0 (TID 167, 10.1.2.172, partition 57, PROCESS_LOCAL, 5562 bytes)
17/02/07 13:20:21,504 INFO TaskSetManager: Starting task 40.0 in stage 3.0 (TID 168, 10.1.2.47, partition 40, PROCESS_LOCAL, 5562 bytes)
17/02/07 13:20:21,505 INFO TaskSetManager: Starting task 30.0 in stage 3.0 (TID 169, 10.1.2.106, partition 30, PROCESS_LOCAL, 5562 bytes)
17/02/07 13:20:21,505 INFO TaskSetManager: Starting task 38.0 in stage 3.0 (TID 170, 10.1.2.148, partition 38, PROCESS_LOCAL, 5562 bytes)
17/02/07 13:20:21,506 INFO TaskSetManager: Starting task 50.0 in stage 3.0 (TID 171, 10.1.2.29, partition 50, PROCESS_LOCAL, 5562 bytes)
17/02/07 13:20:21,506 INFO TaskSetManager: Starting task 29.0 in stage 3.0 (TID 172, 10.1.2.243, partition 29, PROCESS_LOCAL, 5562 bytes)
17/02/07 13:20:21,507 INFO TaskSetManager: Starting task 28.0 in stage 3.0 (TID 173, 10.1.2.130, partition 28, PROCESS_LOCAL, 5562 bytes)
17/02/07 13:20:21,508 INFO TaskSetManager: Starting task 44.0 in stage 3.0 (TID 174, 10.1.2.215, partition 44, PROCESS_LOCAL, 5562 bytes)
17/02/07 13:20:21,508 INFO TaskSetManager: Starting task 54.0 in stage 3.0 (TID 175, 10.1.2.165, partition 54, PROCESS_LOCAL, 5562 bytes)
17/02/07 13:20:21,509 INFO TaskSetManager: Starting task 36.0 in stage 3.0 (TID 176, 10.1.2.224, partition 36, PROCESS_LOCAL, 5562 bytes)
17/02/07 13:20:21,509 INFO TaskSetManager: Starting task 45.0 in stage 3.0 (TID 177, 10.1.2.214, partition 45, PROCESS_LOCAL, 5562 bytes)
17/02/07 13:20:21,510 INFO TaskSetManager: Starting task 53.0 in stage 3.0 (TID 178, 10.1.2.211, partition 53, PROCESS_LOCAL, 5562 bytes)
17/02/07 13:20:21,511 INFO TaskSetManager: Starting task 59.0 in stage 3.0 (TID 179, 10.1.2.245, partition 59, PROCESS_LOCAL, 5562 bytes)
17/02/07 13:20:21,511 INFO TaskSetManager: Starting task 60.0 in stage 3.0 (TID 180, 10.1.2.83, partition 60, PROCESS_LOCAL, 5562 bytes)
17/02/07 13:20:21,512 INFO TaskSetManager: Starting task 48.0 in stage 3.0 (TID 181, 10.1.2.41, partition 48, PROCESS_LOCAL, 5562 bytes)
17/02/07 13:20:21,512 INFO TaskSetManager: Starting task 62.0 in stage 3.0 (TID 182, 10.1.2.133, partition 62, PROCESS_LOCAL, 5562 bytes)
17/02/07 13:20:21,513 INFO TaskSetManager: Starting task 56.0 in stage 3.0 (TID 183, 10.1.2.47, partition 56, PROCESS_LOCAL, 5562 bytes)
17/02/07 13:20:21,514 INFO TaskSetManager: Starting task 34.0 in stage 3.0 (TID 184, 10.1.2.106, partition 34, PROCESS_LOCAL, 5562 bytes)
17/02/07 13:20:21,514 INFO TaskSetManager: Starting task 46.0 in stage 3.0 (TID 185, 10.1.2.148, partition 46, PROCESS_LOCAL, 5562 bytes)
17/02/07 13:20:21,515 INFO TaskSetManager: Starting task 52.0 in stage 3.0 (TID 186, 10.1.2.29, partition 52, PROCESS_LOCAL, 5562 bytes)
17/02/07 13:20:21,515 INFO TaskSetManager: Starting task 31.0 in stage 3.0 (TID 187, 10.1.2.243, partition 31, PROCESS_LOCAL, 5562 bytes)
17/02/07 13:20:21,516 INFO TaskSetManager: Starting task 55.0 in stage 3.0 (TID 188, 10.1.2.130, partition 55, PROCESS_LOCAL, 5562 bytes)
17/02/07 13:20:21,517 INFO TaskSetManager: Starting task 58.0 in stage 3.0 (TID 189, 10.1.2.215, partition 58, PROCESS_LOCAL, 5562 bytes)
17/02/07 13:20:21,517 INFO TaskSetManager: Starting task 61.0 in stage 3.0 (TID 190, 10.1.2.165, partition 61, PROCESS_LOCAL, 5562 bytes)
17/02/07 13:20:21,518 INFO TaskSetManager: Starting task 51.0 in stage 3.0 (TID 191, 10.1.2.224, partition 51, PROCESS_LOCAL, 5562 bytes)
17/02/07 13:20:21,518 INFO CoarseGrainedSchedulerBackend$DriverEndpoint: Launching task 129 on executor id: 8 hostname: 10.1.2.214.
17/02/07 13:20:21,519 INFO CoarseGrainedSchedulerBackend$DriverEndpoint: Launching task 145 on executor id: 8 hostname: 10.1.2.214.
17/02/07 13:20:21,519 INFO CoarseGrainedSchedulerBackend$DriverEndpoint: Launching task 161 on executor id: 8 hostname: 10.1.2.214.
17/02/07 13:20:21,520 INFO CoarseGrainedSchedulerBackend$DriverEndpoint: Launching task 177 on executor id: 8 hostname: 10.1.2.214.
17/02/07 13:20:21,520 INFO CoarseGrainedSchedulerBackend$DriverEndpoint: Launching task 130 on executor id: 14 hostname: 10.1.2.211.
